Workbook

Sheet Dashboard
B2: Reading dashboard
B3: Your goal for the year, what you are reading, and your books by month and genre.
B4: Year | C4: 2026 | E4: Goal (books) | F4: 45
B6: ="Books in "&Dashboard!$C$4 | C6: Goal | D6: Pages | E6: Average rating | F6: Reading now | G6: Want to read
B7: =COUNTIFS(Books!$G$6:$G$1005,"Finished",Books!$I$6:$I$1005,">="&DATE(Dashboard!$C$4,1,1),Books!$I$6:$I$1005,"<="&DATE(Dashboard!$C$4,12,31)) | C7: =IF(N($F$4)=0,"",$F$4) | D7: =SUMIFS(Books!$F$6:$F$1005,Books!$G$6:$G$1005,"Finished",Books!$I$6:$I$1005,">="&DATE(Dashboard!$C$4,1,1),Books!$I$6:$I$1005,"<="&DATE(Dashboard!$C$4,12,31)) | E7: =IFERROR(AVERAGEIFS(Books!$J$6:$J$1005,Books!$G$6:$G$1005,"Finished",Books!$I$6:$I$1005,">="&DATE(Dashboard!$C$4,1,1),Books!$I$6:$I$1005,"<="&DATE(Dashboard!$C$4,12,31)),"") | F7: =COUNTIF(Books!$G$6:$G$1005,"Reading") | G7: =COUNTIF(Books!$G$6:$G$1005,"Want to read")
B9: =IF(N($F$4)=0,"",REPT("█",MIN(30,MAX(0,ROUND((MIN(1,COUNTIFS(Books!$G$6:$G$1005,"Finished",Books!$I$6:$I$1005,">="&DATE(Dashboard!$C$4,1,1),Books!$I$6:$I$1005,"<="&DATE(Dashboard!$C$4,12,31))/$F$4))*30,0))))&REPT("░",30-MIN(30,MAX(0,ROUND((MIN(1,COUNTIFS(Books!$G$6:$G$1005,"Finished",Books!$I$6:$I$1005,">="&DATE(Dashboard!$C$4,1,1),Books!$I$6:$I$1005,"<="&DATE(Dashboard!$C$4,12,31))/$F$4))*30,0))))) | F9: =IF(N($F$4)=0,"",IF(COUNTIFS(Books!$G$6:$G$1005,"Finished",Books!$I$6:$I$1005,">="&DATE(Dashboard!$C$4,1,1),Books!$I$6:$I$1005,"<="&DATE(Dashboard!$C$4,12,31))>=ROUND($F$4*IF(Dashboard!$C$4<YEAR(TODAY()),1,IF(Dashboard!$C$4>YEAR(TODAY()),0,(TODAY()-DATE(Dashboard!$C$4,1,1)+1)/(DATE(Dashboard!$C$4,12,31)-DATE(Dashboard!$C$4,1,1)+1))),0)+1,"Ahead by "&(COUNTIFS(Books!$G$6:$G$1005,"Finished",Books!$I$6:$I$1005,">="&DATE(Dashboard!$C$4,1,1),Books!$I$6:$I$1005,"<="&DATE(Dashboard!$C$4,12,31))-ROUND($F$4*IF(Dashboard!$C$4<YEAR(TODAY()),1,IF(Dashboard!$C$4>YEAR(TODAY()),0,(TODAY()-DATE(Dashboard!$C$4,1,1)+1)/(DATE(Dashboard!$C$4,12,31)-DATE(Dashboard!$C$4,1,1)+1))),0))&IF(COUNTIFS(Books!$G$6:$G$1005,"Finished",Books!$I$6:$I$1005,">="&DATE(Dashboard!$C$4,1,1),Books!$I$6:$I$1005,"<="&DATE(Dashboard!$C$4,12,31))-ROUND($F$4*IF(Dashboard!$C$4<YEAR(TODAY()),1,IF(Dashboard!$C$4>YEAR(TODAY()),0,(TODAY()-DATE(Dashboard!$C$4,1,1)+1)/(DATE(Dashboard!$C$4,12,31)-DATE(Dashboard!$C$4,1,1)+1))),0)=1," book"," books"),IF(COUNTIFS(Books!$G$6:$G$1005,"Finished",Books!$I$6:$I$1005,">="&DATE(Dashboard!$C$4,1,1),Books!$I$6:$I$1005,"<="&DATE(Dashboard!$C$4,12,31))<=ROUND($F$4*IF(Dashboard!$C$4<YEAR(TODAY()),1,IF(Dashboard!$C$4>YEAR(TODAY()),0,(TODAY()-DATE(Dashboard!$C$4,1,1)+1)/(DATE(Dashboard!$C$4,12,31)-DATE(Dashboard!$C$4,1,1)+1))),0)-1,"Behind by "&(ROUND($F$4*IF(Dashboard!$C$4<YEAR(TODAY()),1,IF(Dashboard!$C$4>YEAR(TODAY()),0,(TODAY()-DATE(Dashboard!$C$4,1,1)+1)/(DATE(Dashboard!$C$4,12,31)-DATE(Dashboard!$C$4,1,1)+1))),0)-COUNTIFS(Books!$G$6:$G$1005,"Finished",Books!$I$6:$I$1005,">="&DATE(Dashboard!$C$4,1,1),Books!$I$6:$I$1005,"<="&DATE(Dashboard!$C$4,12,31)))&IF(ROUND($F$4*IF(Dashboard!$C$4<YEAR(TODAY()),1,IF(Dashboard!$C$4>YEAR(TODAY()),0,(TODAY()-DATE(Dashboard!$C$4,1,1)+1)/(DATE(Dashboard!$C$4,12,31)-DATE(Dashboard!$C$4,1,1)+1))),0)-COUNTIFS(Books!$G$6:$G$1005,"Finished",Books!$I$6:$I$1005,">="&DATE(Dashboard!$C$4,1,1),Books!$I$6:$I$1005,"<="&DATE(Dashboard!$C$4,12,31))=1," book"," books"),"On track")))
B11: Month | C11: Books | D11: Pages | I11: Genre | J11: Books | K11: Pages | L11: Rating
B12: Jan | C12: =COUNTIFS(Books!$G$6:$G$1005,"Finished",Books!$I$6:$I$1005,">="&DATE(Dashboard!$C$4,1,1),Books!$I$6:$I$1005,"<="&EOMONTH(DATE(Dashboard!$C$4,1,1),0)) | D12: =SUMIFS(Books!$F$6:$F$1005,Books!$G$6:$G$1005,"Finished",Books!$I$6:$I$1005,">="&DATE(Dashboard!$C$4,1,1),Books!$I$6:$I$1005,"<="&EOMONTH(DATE(Dashboard!$C$4,1,1),0)) | I12: =IF(Settings!B6="","",Settings!B6) | J12: =IF(I12="","",COUNTIFS(Books!$G$6:$G$1005,"Finished",Books!$I$6:$I$1005,">="&DATE(Dashboard!$C$4,1,1),Books!$I$6:$I$1005,"<="&DATE(Dashboard!$C$4,12,31),Books!$D$6:$D$1005,I12)) | K12: =IF(I12="","",SUMIFS(Books!$F$6:$F$1005,Books!$G$6:$G$1005,"Finished",Books!$I$6:$I$1005,">="&DATE(Dashboard!$C$4,1,1),Books!$I$6:$I$1005,"<="&DATE(Dashboard!$C$4,12,31),Books!$D$6:$D$1005,I12)) | L12: =IF(OR(I12="",N(J12)=0),"",AVERAGEIFS(Books!$J$6:$J$1005,Books!$G$6:$G$1005,"Finished",Books!$I$6:$I$1005,">="&DATE(Dashboard!$C$4,1,1),Books!$I$6:$I$1005,"<="&DATE(Dashboard!$C$4,12,31),Books!$D$6:$D$1005,I12))
B13: Feb | C13: =COUNTIFS(Books!$G$6:$G$1005,"Finished",Books!$I$6:$I$1005,">="&DATE(Dashboard!$C$4,2,1),Books!$I$6:$I$1005,"<="&EOMONTH(DATE(Dashboard!$C$4,2,1),0)) | D13: =SUMIFS(Books!$F$6:$F$1005,Books!$G$6:$G$1005,"Finished",Books!$I$6:$I$1005,">="&DATE(Dashboard!$C$4,2,1),Books!$I$6:$I$1005,"<="&EOMONTH(DATE(Dashboard!$C$4,2,1),0)) | I13: =IF(Settings!B7="","",Settings!B7) | J13: =IF(I13="","",COUNTIFS(Books!$G$6:$G$1005,"Finished",Books!$I$6:$I$1005,">="&DATE(Dashboard!$C$4,1,1),Books!$I$6:$I$1005,"<="&DATE(Dashboard!$C$4,12,31),Books!$D$6:$D$1005,I13)) | K13: =IF(I13="","",SUMIFS(Books!$F$6:$F$1005,Books!$G$6:$G$1005,"Finished",Books!$I$6:$I$1005,">="&DATE(Dashboard!$C$4,1,1),Books!$I$6:$I$1005,"<="&DATE(Dashboard!$C$4,12,31),Books!$D$6:$D$1005,I13)) | L13: =IF(OR(I13="",N(J13)=0),"",AVERAGEIFS(Books!$J$6:$J$1005,Books!$G$6:$G$1005,"Finished",Books!$I$6:$I$1005,">="&DATE(Dashboard!$C$4,1,1),Books!$I$6:$I$1005,"<="&DATE(Dashboard!$C$4,12,31),Books!$D$6:$D$1005,I13))
B14: Mar | C14: =COUNTIFS(Books!$G$6:$G$1005,"Finished",Books!$I$6:$I$1005,">="&DATE(Dashboard!$C$4,3,1),Books!$I$6:$I$1005,"<="&EOMONTH(DATE(Dashboard!$C$4,3,1),0)) | D14: =SUMIFS(Books!$F$6:$F$1005,Books!$G$6:$G$1005,"Finished",Books!$I$6:$I$1005,">="&DATE(Dashboard!$C$4,3,1),Books!$I$6:$I$1005,"<="&EOMONTH(DATE(Dashboard!$C$4,3,1),0)) | I14: =IF(Settings!B8="","",Settings!B8) | J14: =IF(I14="","",COUNTIFS(Books!$G$6:$G$1005,"Finished",Books!$I$6:$I$1005,">="&DATE(Dashboard!$C$4,1,1),Books!$I$6:$I$1005,"<="&DATE(Dashboard!$C$4,12,31),Books!$D$6:$D$1005,I14)) | K14: =IF(I14="","",SUMIFS(Books!$F$6:$F$1005,Books!$G$6:$G$1005,"Finished",Books!$I$6:$I$1005,">="&DATE(Dashboard!$C$4,1,1),Books!$I$6:$I$1005,"<="&DATE(Dashboard!$C$4,12,31),Books!$D$6:$D$1005,I14)) | L14: =IF(OR(I14="",N(J14)=0),"",AVERAGEIFS(Books!$J$6:$J$1005,Books!$G$6:$G$1005,"Finished",Books!$I$6:$I$1005,">="&DATE(Dashboard!$C$4,1,1),Books!$I$6:$I$1005,"<="&DATE(Dashboard!$C$4,12,31),Books!$D$6:$D$1005,I14))
B15: Apr | C15: =COUNTIFS(Books!$G$6:$G$1005,"Finished",Books!$I$6:$I$1005,">="&DATE(Dashboard!$C$4,4,1),Books!$I$6:$I$1005,"<="&EOMONTH(DATE(Dashboard!$C$4,4,1),0)) | D15: =SUMIFS(Books!$F$6:$F$1005,Books!$G$6:$G$1005,"Finished",Books!$I$6:$I$1005,">="&DATE(Dashboard!$C$4,4,1),Books!$I$6:$I$1005,"<="&EOMONTH(DATE(Dashboard!$C$4,4,1),0)) | I15: =IF(Settings!B9="","",Settings!B9) | J15: =IF(I15="","",COUNTIFS(Books!$G$6:$G$1005,"Finished",Books!$I$6:$I$1005,">="&DATE(Dashboard!$C$4,1,1),Books!$I$6:$I$1005,"<="&DATE(Dashboard!$C$4,12,31),Books!$D$6:$D$1005,I15)) | K15: =IF(I15="","",SUMIFS(Books!$F$6:$F$1005,Books!$G$6:$G$1005,"Finished",Books!$I$6:$I$1005,">="&DATE(Dashboard!$C$4,1,1),Books!$I$6:$I$1005,"<="&DATE(Dashboard!$C$4,12,31),Books!$D$6:$D$1005,I15)) | L15: =IF(OR(I15="",N(J15)=0),"",AVERAGEIFS(Books!$J$6:$J$1005,Books!$G$6:$G$1005,"Finished",Books!$I$6:$I$1005,">="&DATE(Dashboard!$C$4,1,1),Books!$I$6:$I$1005,"<="&DATE(Dashboard!$C$4,12,31),Books!$D$6:$D$1005,I15))
B16: May | C16: =COUNTIFS(Books!$G$6:$G$1005,"Finished",Books!$I$6:$I$1005,">="&DATE(Dashboard!$C$4,5,1),Books!$I$6:$I$1005,"<="&EOMONTH(DATE(Dashboard!$C$4,5,1),0)) | D16: =SUMIFS(Books!$F$6:$F$1005,Books!$G$6:$G$1005,"Finished",Books!$I$6:$I$1005,">="&DATE(Dashboard!$C$4,5,1),Books!$I$6:$I$1005,"<="&EOMONTH(DATE(Dashboard!$C$4,5,1),0)) | I16: =IF(Settings!B10="","",Settings!B10) | J16: =IF(I16="","",COUNTIFS(Books!$G$6:$G$1005,"Finished",Books!$I$6:$I$1005,">="&DATE(Dashboard!$C$4,1,1),Books!$I$6:$I$1005,"<="&DATE(Dashboard!$C$4,12,31),Books!$D$6:$D$1005,I16)) | K16: =IF(I16="","",SUMIFS(Books!$F$6:$F$1005,Books!$G$6:$G$1005,"Finished",Books!$I$6:$I$1005,">="&DATE(Dashboard!$C$4,1,1),Books!$I$6:$I$1005,"<="&DATE(Dashboard!$C$4,12,31),Books!$D$6:$D$1005,I16)) | L16: =IF(OR(I16="",N(J16)=0),"",AVERAGEIFS(Books!$J$6:$J$1005,Books!$G$6:$G$1005,"Finished",Books!$I$6:$I$1005,">="&DATE(Dashboard!$C$4,1,1),Books!$I$6:$I$1005,"<="&DATE(Dashboard!$C$4,12,31),Books!$D$6:$D$1005,I16))
B17: Jun | C17: =COUNTIFS(Books!$G$6:$G$1005,"Finished",Books!$I$6:$I$1005,">="&DATE(Dashboard!$C$4,6,1),Books!$I$6:$I$1005,"<="&EOMONTH(DATE(Dashboard!$C$4,6,1),0)) | D17: =SUMIFS(Books!$F$6:$F$1005,Books!$G$6:$G$1005,"Finished",Books!$I$6:$I$1005,">="&DATE(Dashboard!$C$4,6,1),Books!$I$6:$I$1005,"<="&EOMONTH(DATE(Dashboard!$C$4,6,1),0)) | I17: =IF(Settings!B11="","",Settings!B11) | J17: =IF(I17="","",COUNTIFS(Books!$G$6:$G$1005,"Finished",Books!$I$6:$I$1005,">="&DATE(Dashboard!$C$4,1,1),Books!$I$6:$I$1005,"<="&DATE(Dashboard!$C$4,12,31),Books!$D$6:$D$1005,I17)) | K17: =IF(I17="","",SUMIFS(Books!$F$6:$F$1005,Books!$G$6:$G$1005,"Finished",Books!$I$6:$I$1005,">="&DATE(Dashboard!$C$4,1,1),Books!$I$6:$I$1005,"<="&DATE(Dashboard!$C$4,12,31),Books!$D$6:$D$1005,I17)) | L17: =IF(OR(I17="",N(J17)=0),"",AVERAGEIFS(Books!$J$6:$J$1005,Books!$G$6:$G$1005,"Finished",Books!$I$6:$I$1005,">="&DATE(Dashboard!$C$4,1,1),Books!$I$6:$I$1005,"<="&DATE(Dashboard!$C$4,12,31),Books!$D$6:$D$1005,I17))
B18: Jul | C18: =COUNTIFS(Books!$G$6:$G$1005,"Finished",Books!$I$6:$I$1005,">="&DATE(Dashboard!$C$4,7,1),Books!$I$6:$I$1005,"<="&EOMONTH(DATE(Dashboard!$C$4,7,1),0)) | D18: =SUMIFS(Books!$F$6:$F$1005,Books!$G$6:$G$1005,"Finished",Books!$I$6:$I$1005,">="&DATE(Dashboard!$C$4,7,1),Books!$I$6:$I$1005,"<="&EOMONTH(DATE(Dashboard!$C$4,7,1),0)) | I18: =IF(Settings!B12="","",Settings!B12) | J18: =IF(I18="","",COUNTIFS(Books!$G$6:$G$1005,"Finished",Books!$I$6:$I$1005,">="&DATE(Dashboard!$C$4,1,1),Books!$I$6:$I$1005,"<="&DATE(Dashboard!$C$4,12,31),Books!$D$6:$D$1005,I18)) | K18: =IF(I18="","",SUMIFS(Books!$F$6:$F$1005,Books!$G$6:$G$1005,"Finished",Books!$I$6:$I$1005,">="&DATE(Dashboard!$C$4,1,1),Books!$I$6:$I$1005,"<="&DATE(Dashboard!$C$4,12,31),Books!$D$6:$D$1005,I18)) | L18: =IF(OR(I18="",N(J18)=0),"",AVERAGEIFS(Books!$J$6:$J$1005,Books!$G$6:$G$1005,"Finished",Books!$I$6:$I$1005,">="&DATE(Dashboard!$C$4,1,1),Books!$I$6:$I$1005,"<="&DATE(Dashboard!$C$4,12,31),Books!$D$6:$D$1005,I18))
B19: Aug | C19: =COUNTIFS(Books!$G$6:$G$1005,"Finished",Books!$I$6:$I$1005,">="&DATE(Dashboard!$C$4,8,1),Books!$I$6:$I$1005,"<="&EOMONTH(DATE(Dashboard!$C$4,8,1),0)) | D19: =SUMIFS(Books!$F$6:$F$1005,Books!$G$6:$G$1005,"Finished",Books!$I$6:$I$1005,">="&DATE(Dashboard!$C$4,8,1),Books!$I$6:$I$1005,"<="&EOMONTH(DATE(Dashboard!$C$4,8,1),0)) | I19: =IF(Settings!B13="","",Settings!B13) | J19: =IF(I19="","",COUNTIFS(Books!$G$6:$G$1005,"Finished",Books!$I$6:$I$1005,">="&DATE(Dashboard!$C$4,1,1),Books!$I$6:$I$1005,"<="&DATE(Dashboard!$C$4,12,31),Books!$D$6:$D$1005,I19)) | K19: =IF(I19="","",SUMIFS(Books!$F$6:$F$1005,Books!$G$6:$G$1005,"Finished",Books!$I$6:$I$1005,">="&DATE(Dashboard!$C$4,1,1),Books!$I$6:$I$1005,"<="&DATE(Dashboard!$C$4,12,31),Books!$D$6:$D$1005,I19)) | L19: =IF(OR(I19="",N(J19)=0),"",AVERAGEIFS(Books!$J$6:$J$1005,Books!$G$6:$G$1005,"Finished",Books!$I$6:$I$1005,">="&DATE(Dashboard!$C$4,1,1),Books!$I$6:$I$1005,"<="&DATE(Dashboard!$C$4,12,31),Books!$D$6:$D$1005,I19))
B20: Sep | C20: =COUNTIFS(Books!$G$6:$G$1005,"Finished",Books!$I$6:$I$1005,">="&DATE(Dashboard!$C$4,9,1),Books!$I$6:$I$1005,"<="&EOMONTH(DATE(Dashboard!$C$4,9,1),0)) | D20: =SUMIFS(Books!$F$6:$F$1005,Books!$G$6:$G$1005,"Finished",Books!$I$6:$I$1005,">="&DATE(Dashboard!$C$4,9,1),Books!$I$6:$I$1005,"<="&EOMONTH(DATE(Dashboard!$C$4,9,1),0)) | I20: =IF(Settings!B14="","",Settings!B14) | J20: =IF(I20="","",COUNTIFS(Books!$G$6:$G$1005,"Finished",Books!$I$6:$I$1005,">="&DATE(Dashboard!$C$4,1,1),Books!$I$6:$I$1005,"<="&DATE(Dashboard!$C$4,12,31),Books!$D$6:$D$1005,I20)) | K20: =IF(I20="","",SUMIFS(Books!$F$6:$F$1005,Books!$G$6:$G$1005,"Finished",Books!$I$6:$I$1005,">="&DATE(Dashboard!$C$4,1,1),Books!$I$6:$I$1005,"<="&DATE(Dashboard!$C$4,12,31),Books!$D$6:$D$1005,I20)) | L20: =IF(OR(I20="",N(J20)=0),"",AVERAGEIFS(Books!$J$6:$J$1005,Books!$G$6:$G$1005,"Finished",Books!$I$6:$I$1005,">="&DATE(Dashboard!$C$4,1,1),Books!$I$6:$I$1005,"<="&DATE(Dashboard!$C$4,12,31),Books!$D$6:$D$1005,I20))
B21: Oct | C21: =COUNTIFS(Books!$G$6:$G$1005,"Finished",Books!$I$6:$I$1005,">="&DATE(Dashboard!$C$4,10,1),Books!$I$6:$I$1005,"<="&EOMONTH(DATE(Dashboard!$C$4,10,1),0)) | D21: =SUMIFS(Books!$F$6:$F$1005,Books!$G$6:$G$1005,"Finished",Books!$I$6:$I$1005,">="&DATE(Dashboard!$C$4,10,1),Books!$I$6:$I$1005,"<="&EOMONTH(DATE(Dashboard!$C$4,10,1),0)) | I21: =IF(Settings!B15="","",Settings!B15) | J21: =IF(I21="","",COUNTIFS(Books!$G$6:$G$1005,"Finished",Books!$I$6:$I$1005,">="&DATE(Dashboard!$C$4,1,1),Books!$I$6:$I$1005,"<="&DATE(Dashboard!$C$4,12,31),Books!$D$6:$D$1005,I21)) | K21: =IF(I21="","",SUMIFS(Books!$F$6:$F$1005,Books!$G$6:$G$1005,"Finished",Books!$I$6:$I$1005,">="&DATE(Dashboard!$C$4,1,1),Books!$I$6:$I$1005,"<="&DATE(Dashboard!$C$4,12,31),Books!$D$6:$D$1005,I21)) | L21: =IF(OR(I21="",N(J21)=0),"",AVERAGEIFS(Books!$J$6:$J$1005,Books!$G$6:$G$1005,"Finished",Books!$I$6:$I$1005,">="&DATE(Dashboard!$C$4,1,1),Books!$I$6:$I$1005,"<="&DATE(Dashboard!$C$4,12,31),Books!$D$6:$D$1005,I21))
B22: Nov | C22: =COUNTIFS(Books!$G$6:$G$1005,"Finished",Books!$I$6:$I$1005,">="&DATE(Dashboard!$C$4,11,1),Books!$I$6:$I$1005,"<="&EOMONTH(DATE(Dashboard!$C$4,11,1),0)) | D22: =SUMIFS(Books!$F$6:$F$1005,Books!$G$6:$G$1005,"Finished",Books!$I$6:$I$1005,">="&DATE(Dashboard!$C$4,11,1),Books!$I$6:$I$1005,"<="&EOMONTH(DATE(Dashboard!$C$4,11,1),0)) | I22: =IF(Settings!B16="","",Settings!B16) | J22: =IF(I22="","",COUNTIFS(Books!$G$6:$G$1005,"Finished",Books!$I$6:$I$1005,">="&DATE(Dashboard!$C$4,1,1),Books!$I$6:$I$1005,"<="&DATE(Dashboard!$C$4,12,31),Books!$D$6:$D$1005,I22)) | K22: =IF(I22="","",SUMIFS(Books!$F$6:$F$1005,Books!$G$6:$G$1005,"Finished",Books!$I$6:$I$1005,">="&DATE(Dashboard!$C$4,1,1),Books!$I$6:$I$1005,"<="&DATE(Dashboard!$C$4,12,31),Books!$D$6:$D$1005,I22)) | L22: =IF(OR(I22="",N(J22)=0),"",AVERAGEIFS(Books!$J$6:$J$1005,Books!$G$6:$G$1005,"Finished",Books!$I$6:$I$1005,">="&DATE(Dashboard!$C$4,1,1),Books!$I$6:$I$1005,"<="&DATE(Dashboard!$C$4,12,31),Books!$D$6:$D$1005,I22))
B23: Dec | C23: =COUNTIFS(Books!$G$6:$G$1005,"Finished",Books!$I$6:$I$1005,">="&DATE(Dashboard!$C$4,12,1),Books!$I$6:$I$1005,"<="&EOMONTH(DATE(Dashboard!$C$4,12,1),0)) | D23: =SUMIFS(Books!$F$6:$F$1005,Books!$G$6:$G$1005,"Finished",Books!$I$6:$I$1005,">="&DATE(Dashboard!$C$4,12,1),Books!$I$6:$I$1005,"<="&EOMONTH(DATE(Dashboard!$C$4,12,1),0)) | I23: =IF(Settings!B17="","",Settings!B17) | J23: =IF(I23="","",COUNTIFS(Books!$G$6:$G$1005,"Finished",Books!$I$6:$I$1005,">="&DATE(Dashboard!$C$4,1,1),Books!$I$6:$I$1005,"<="&DATE(Dashboard!$C$4,12,31),Books!$D$6:$D$1005,I23)) | K23: =IF(I23="","",SUMIFS(Books!$F$6:$F$1005,Books!$G$6:$G$1005,"Finished",Books!$I$6:$I$1005,">="&DATE(Dashboard!$C$4,1,1),Books!$I$6:$I$1005,"<="&DATE(Dashboard!$C$4,12,31),Books!$D$6:$D$1005,I23)) | L23: =IF(OR(I23="",N(J23)=0),"",AVERAGEIFS(Books!$J$6:$J$1005,Books!$G$6:$G$1005,"Finished",Books!$I$6:$I$1005,">="&DATE(Dashboard!$C$4,1,1),Books!$I$6:$I$1005,"<="&DATE(Dashboard!$C$4,12,31),Books!$D$6:$D$1005,I23))
B26: Reading now | D26: Author | F26: Started | G26: Days | I26: Five stars this year | J26: Author
B27: =IF(O27="","",INDEX(Books!$B$6:$B$1005,MATCH(O27,Books!$P$6:$P$1005,0))) | D27: =IF(O27="","",INDEX(Books!$C$6:$C$1005,MATCH(O27,Books!$P$6:$P$1005,0))) | F27: =IF(O27="","",INT(O27)) | G27: =IF(O27="","",TODAY()-INT(O27)+1) | I27: =IF(P27="","",INDEX(Books!$B$6:$B$1005,MATCH(P27,Books!$Q$6:$Q$1005,0))) | J27: =IF(P27="","",INDEX(Books!$C$6:$C$1005,MATCH(P27,Books!$Q$6:$Q$1005,0))) | O27: =IFERROR(SMALL(Books!$P$6:$P$1005,1),"") | P27: =IFERROR(LARGE(Books!$Q$6:$Q$1005,1),"")
B28: =IF(O28="","",INDEX(Books!$B$6:$B$1005,MATCH(O28,Books!$P$6:$P$1005,0))) | D28: =IF(O28="","",INDEX(Books!$C$6:$C$1005,MATCH(O28,Books!$P$6:$P$1005,0))) | F28: =IF(O28="","",INT(O28)) | G28: =IF(O28="","",TODAY()-INT(O28)+1) | I28: =IF(P28="","",INDEX(Books!$B$6:$B$1005,MATCH(P28,Books!$Q$6:$Q$1005,0))) | J28: =IF(P28="","",INDEX(Books!$C$6:$C$1005,MATCH(P28,Books!$Q$6:$Q$1005,0))) | O28: =IFERROR(SMALL(Books!$P$6:$P$1005,2),"") | P28: =IFERROR(LARGE(Books!$Q$6:$Q$1005,2),"")
B29: =IF(O29="","",INDEX(Books!$B$6:$B$1005,MATCH(O29,Books!$P$6:$P$1005,0))) | D29: =IF(O29="","",INDEX(Books!$C$6:$C$1005,MATCH(O29,Books!$P$6:$P$1005,0))) | F29: =IF(O29="","",INT(O29)) | G29: =IF(O29="","",TODAY()-INT(O29)+1) | I29: =IF(P29="","",INDEX(Books!$B$6:$B$1005,MATCH(P29,Books!$Q$6:$Q$1005,0))) | J29: =IF(P29="","",INDEX(Books!$C$6:$C$1005,MATCH(P29,Books!$Q$6:$Q$1005,0))) | O29: =IFERROR(SMALL(Books!$P$6:$P$1005,3),"") | P29: =IFERROR(LARGE(Books!$Q$6:$Q$1005,3),"")
B30: =IF(O30="","",INDEX(Books!$B$6:$B$1005,MATCH(O30,Books!$P$6:$P$1005,0))) | D30: =IF(O30="","",INDEX(Books!$C$6:$C$1005,MATCH(O30,Books!$P$6:$P$1005,0))) | F30: =IF(O30="","",INT(O30)) | G30: =IF(O30="","",TODAY()-INT(O30)+1) | I30: =IF(P30="","",INDEX(Books!$B$6:$B$1005,MATCH(P30,Books!$Q$6:$Q$1005,0))) | J30: =IF(P30="","",INDEX(Books!$C$6:$C$1005,MATCH(P30,Books!$Q$6:$Q$1005,0))) | O30: =IFERROR(SMALL(Books!$P$6:$P$1005,4),"") | P30: =IFERROR(LARGE(Books!$Q$6:$Q$1005,4),"")
I31: =IF(P31="","",INDEX(Books!$B$6:$B$1005,MATCH(P31,Books!$Q$6:$Q$1005,0))) | J31: =IF(P31="","",INDEX(Books!$C$6:$C$1005,MATCH(P31,Books!$Q$6:$Q$1005,0))) | P31: =IFERROR(LARGE(Books!$Q$6:$Q$1005,5),"")
I32: =IF(P32="","",INDEX(Books!$B$6:$B$1005,MATCH(P32,Books!$Q$6:$Q$1005,0))) | J32: =IF(P32="","",INDEX(Books!$C$6:$C$1005,MATCH(P32,Books!$Q$6:$Q$1005,0))) | P32: =IFERROR(LARGE(Books!$Q$6:$Q$1005,6),"")

Sheet Books
B2: Books
B3: One line per book: the ones you read, are reading, and want to read.
B5: Title | C5: Author | D5: Genre | E5: Format | F5: Pages | G5: Status | H5: Started | I5: Finished | J5: Rating | K5: Days | L5: Pages a day | M5: Note
B6: The Salt Archive | C6: Ines Holloway | D6: Romance | E6: Paper | F6: 432 | G6: Finished | H6: 46024 | I6: 46032 | J6: 4 | K6: =IF(OR(H6="",I6=""),"",I6-H6+1) | L6: =IF(OR(K6="",N(F6)=0),"",F6/K6) | M6: Could not put it down | N6: =IF(AND(G6="Finished",I6<>""),IF(YEAR(I6)=Dashboard!$C$4,I6+ROW()/10000000,""),"") | O6: =IF(B6="","",IFERROR(MATCH(D6,Settings!$B$6:$B$17,0),12)) | P6: =IF(AND(G6="Reading",B6<>""),IF(H6="",TODAY(),H6)+ROW()/10000000,"") | Q6: =IF(AND(N6<>"",N(J6)=5),N6,"")
B7: The Paper Machine | C7: Anika Rook | D7: Poetry | E7: Paper | F7: 378 | G7: Finished | H7: 46033 | I7: 46041 | J7: 3 | K7: =IF(OR(H7="",I7=""),"",I7-H7+1) | L7: =IF(OR(K7="",N(F7)=0),"",F7/K7) | N7: =IF(AND(G7="Finished",I7<>""),IF(YEAR(I7)=Dashboard!$C$4,I7+ROW()/10000000,""),"") | O7: =IF(B7="","",IFERROR(MATCH(D7,Settings!$B$6:$B$17,0),12)) | P7: =IF(AND(G7="Reading",B7<>""),IF(H7="",TODAY(),H7)+ROW()/10000000,"") | Q7: =IF(AND(N7<>"",N(J7)=5),N7,"")
B8: Last Harbour | C8: Elena Castell | D8: Fiction | E8: Paper | F8: 406 | G8: Finished | H8: 46041 | I8: 46046 | J8: 4 | K8: =IF(OR(H8="",I8=""),"",I8-H8+1) | L8: =IF(OR(K8="",N(F8)=0),"",F8/K8) | N8: =IF(AND(G8="Finished",I8<>""),IF(YEAR(I8)=Dashboard!$C$4,I8+ROW()/10000000,""),"") | O8: =IF(B8="","",IFERROR(MATCH(D8,Settings!$B$6:$B$17,0),12)) | P8: =IF(AND(G8="Reading",B8<>""),IF(H8="",TODAY(),H8)+ROW()/10000000,"") | Q8: =IF(AND(N8<>"",N(J8)=5),N8,"")
B9: The Garden of Winter | C9: Anika Albescu | D9: Science fiction | E9: Audio | F9: 501 | G9: Finished | H9: 46047 | I9: 46056 | J9: 4 | K9: =IF(OR(H9="",I9=""),"",I9-H9+1) | L9: =IF(OR(K9="",N(F9)=0),"",F9/K9) | M9: Could not put it down | N9: =IF(AND(G9="Finished",I9<>""),IF(YEAR(I9)=Dashboard!$C$4,I9+ROW()/10000000,""),"") | O9: =IF(B9="","",IFERROR(MATCH(D9,Settings!$B$6:$B$17,0),12)) | P9: =IF(AND(G9="Reading",B9<>""),IF(H9="",TODAY(),H9)+ROW()/10000000,"") | Q9: =IF(AND(N9<>"",N(J9)=5),N9,"")
B10: The Copper Machine | C10: Ines Holloway | D10: Fantasy | E10: Paper | F10: 348 | G10: Finished | H10: 46058 | I10: 46066 | J10: 4 | K10: =IF(OR(H10="",I10=""),"",I10-H10+1) | L10: =IF(OR(K10="",N(F10)=0),"",F10/K10) | M10: Book club pick | N10: =IF(AND(G10="Finished",I10<>""),IF(YEAR(I10)=Dashboard!$C$4,I10+ROW()/10000000,""),"") | O10: =IF(B10="","",IFERROR(MATCH(D10,Settings!$B$6:$B$17,0),12)) | P10: =IF(AND(G10="Reading",B10<>""),IF(H10="",TODAY(),H10)+ROW()/10000000,"") | Q10: =IF(AND(N10<>"",N(J10)=5),N10,"")
B11: The Garden of Small Hours | C11: Jude Okafor | D11: Fantasy | E11: Paper | F11: 408 | G11: Finished | H11: 46068 | I11: 46077 | J11: 4 | K11: =IF(OR(H11="",I11=""),"",I11-H11+1) | L11: =IF(OR(K11="",N(F11)=0),"",F11/K11) | M11: Book club pick | N11: =IF(AND(G11="Finished",I11<>""),IF(YEAR(I11)=Dashboard!$C$4,I11+ROW()/10000000,""),"") | O11: =IF(B11="","",IFERROR(MATCH(D11,Settings!$B$6:$B$17,0),12)) | P11: =IF(AND(G11="Reading",B11<>""),IF(H11="",TODAY(),H11)+ROW()/10000000,"") | Q11: =IF(AND(N11<>"",N(J11)=5),N11,"")
B12: The Silver House | C12: Wren Albescu | D12: Mystery | E12: Paper | F12: 425 | G12: Finished | H12: 46079 | I12: 46087 | J12: 4 | K12: =IF(OR(H12="",I12=""),"",I12-H12+1) | L12: =IF(OR(K12="",N(F12)=0),"",F12/K12) | M12: Slow start, great ending | N12: =IF(AND(G12="Finished",I12<>""),IF(YEAR(I12)=Dashboard!$C$4,I12+ROW()/10000000,""),"") | O12: =IF(B12="","",IFERROR(MATCH(D12,Settings!$B$6:$B$17,0),12)) | P12: =IF(AND(G12="Reading",B12<>""),IF(H12="",TODAY(),H12)+ROW()/10000000,"") | Q12: =IF(AND(N12<>"",N(J12)=5),N12,"")
B13: The Silver Orchard | C13: Colm Castell | D13: Poetry | E13: Paper | F13: 193 | G13: Finished | H13: 46089 | I13: 46092 | J13: 5 | K13: =IF(OR(H13="",I13=""),"",I13-H13+1) | L13: =IF(OR(K13="",N(F13)=0),"",F13/K13) | N13: =IF(AND(G13="Finished",I13<>""),IF(YEAR(I13)=Dashboard!$C$4,I13+ROW()/10000000,""),"") | O13: =IF(B13="","",IFERROR(MATCH(D13,Settings!$B$6:$B$17,0),12)) | P13: =IF(AND(G13="Reading",B13<>""),IF(H13="",TODAY(),H13)+ROW()/10000000,"") | Q13: =IF(AND(N13<>"",N(J13)=5),N13,"")
B14: The Machine of Borrowed Time | C14: Maren Brandt | D14: Historical fiction | E14: Paper | F14: 355 | G14: Finished | H14: 46092 | I14: 46097 | J14: 4 | K14: =IF(OR(H14="",I14=""),"",I14-H14+1) | L14: =IF(OR(K14="",N(F14)=0),"",F14/K14) | N14: =IF(AND(G14="Finished",I14<>""),IF(YEAR(I14)=Dashboard!$C$4,I14+ROW()/10000000,""),"") | O14: =IF(B14="","",IFERROR(MATCH(D14,Settings!$B$6:$B$17,0),12)) | P14: =IF(AND(G14="Reading",B14<>""),IF(H14="",TODAY(),H14)+ROW()/10000000,"") | Q14: =IF(AND(N14<>"",N(J14)=5),N14,"")
B15: Crooked Orchard | C15: Mira Albescu | D15: Fiction | E15: Paper | F15: 339 | G15: Finished | H15: 46098 | I15: 46103 | J15: 4 | K15: =IF(OR(H15="",I15=""),"",I15-H15+1) | L15: =IF(OR(K15="",N(F15)=0),"",F15/K15) | M15: Book club pick | N15: =IF(AND(G15="Finished",I15<>""),IF(YEAR(I15)=Dashboard!$C$4,I15+ROW()/10000000,""),"") | O15: =IF(B15="","",IFERROR(MATCH(D15,Settings!$B$6:$B$17,0),12)) | P15: =IF(AND(G15="Reading",B15<>""),IF(H15="",TODAY(),H15)+ROW()/10000000,"") | Q15: =IF(AND(N15<>"",N(J15)=5),N15,"")
B16: The Painted Harbour | C16: Nadia Marlowe | D16: Mystery | E16: Paper | F16: 475 | G16: Finished | H16: 46103 | I16: 46109 | J16: 3 | K16: =IF(OR(H16="",I16=""),"",I16-H16+1) | L16: =IF(OR(K16="",N(F16)=0),"",F16/K16) | M16: Could not put it down | N16: =IF(AND(G16="Finished",I16<>""),IF(YEAR(I16)=Dashboard!$C$4,I16+ROW()/10000000,""),"") | O16: =IF(B16="","",IFERROR(MATCH(D16,Settings!$B$6:$B$17,0),12)) | P16: =IF(AND(G16="Reading",B16<>""),IF(H16="",TODAY(),H16)+ROW()/10000000,"") | Q16: =IF(AND(N16<>"",N(J16)=5),N16,"")
B17: The Copper House | C17: Nadia Castell | D17: Mystery | E17: Paper | F17: 291 | G17: Finished | H17: 46110 | I17: 46115 | J17: 4 | K17: =IF(OR(H17="",I17=""),"",I17-H17+1) | L17: =IF(OR(K17="",N(F17)=0),"",F17/K17) | M17: Could not put it down | N17: =IF(AND(G17="Finished",I17<>""),IF(YEAR(I17)=Dashboard!$C$4,I17+ROW()/10000000,""),"") | O17: =IF(B17="","",IFERROR(MATCH(D17,Settings!$B$6:$B$17,0),12)) | P17: =IF(AND(G17="Reading",B17<>""),IF(H17="",TODAY(),H17)+ROW()/10000000,"") | Q17: =IF(AND(N17<>"",N(J17)=5),N17,"")
B18: Winter Tide | C18: Otto Albescu | D18: Fantasy | E18: Audio | F18: 240 | G18: Finished | H18: 46116 | I18: 46120 | J18: 3 | K18: =IF(OR(H18="",I18=""),"",I18-H18+1) | L18: =IF(OR(K18="",N(F18)=0),"",F18/K18) | M18: Lent to a friend | N18: =IF(AND(G18="Finished",I18<>""),IF(YEAR(I18)=Dashboard!$C$4,I18+ROW()/10000000,""),"") | O18: =IF(B18="","",IFERROR(MATCH(D18,Settings!$B$6:$B$17,0),12)) | P18: =IF(AND(G18="Reading",B18<>""),IF(H18="",TODAY(),H18)+ROW()/10000000,"") | Q18: =IF(AND(N18<>"",N(J18)=5),N18,"")
B19: The River of Small Hours | C19: Elena Holloway | D19: Mystery | E19: Paper | F19: 315 | G19: Finished | H19: 46122 | I19: 46129 | J19: 3 | K19: =IF(OR(H19="",I19=""),"",I19-H19+1) | L19: =IF(OR(K19="",N(F19)=0),"",F19/K19) | N19: =IF(AND(G19="Finished",I19<>""),IF(YEAR(I19)=Dashboard!$C$4,I19+ROW()/10000000,""),"") | O19: =IF(B19="","",IFERROR(MATCH(D19,Settings!$B$6:$B$17,0),12)) | P19: =IF(AND(G19="Reading",B19<>""),IF(H19="",TODAY(),H19)+ROW()/10000000,"") | Q19: =IF(AND(N19<>"",N(J19)=5),N19,"")
B20: The Island of Glass | C20: Colm Lindqvist | D20: Fiction | E20: Paper | F20: 508 | G20: Finished | H20: 46130 | I20: 46139 | J20: 4 | K20: =IF(OR(H20="",I20=""),"",I20-H20+1) | L20: =IF(OR(K20="",N(F20)=0),"",F20/K20) | N20: =IF(AND(G20="Finished",I20<>""),IF(YEAR(I20)=Dashboard!$C$4,I20+ROW()/10000000,""),"") | O20: =IF(B20="","",IFERROR(MATCH(D20,Settings!$B$6:$B$17,0),12)) | P20: =IF(AND(G20="Reading",B20<>""),IF(H20="",TODAY(),H20)+ROW()/10000000,"") | Q20: =IF(AND(N20<>"",N(J20)=5),N20,"")
B21: Drowned Machine | C21: Rafe Brandt | D21: Romance | E21: Audio | F21: 411 | G21: Finished | H21: 46141 | I21: 46149 | J21: 3 | K21: =IF(OR(H21="",I21=""),"",I21-H21+1) | L21: =IF(OR(K21="",N(F21)=0),"",F21/K21) | N21: =IF(AND(G21="Finished",I21<>""),IF(YEAR(I21)=Dashboard!$C$4,I21+ROW()/10000000,""),"") | O21: =IF(B21="","",IFERROR(MATCH(D21,Settings!$B$6:$B$17,0),12)) | P21: =IF(AND(G21="Reading",B21<>""),IF(H21="",TODAY(),H21)+ROW()/10000000,"") | Q21: =IF(AND(N21<>"",N(J21)=5),N21,"")
B22: The Kingdom of Other Rooms | C22: Wren Albescu | D22: Non-fiction | E22: Paper | F22: 306 | G22: Finished | H22: 46149 | I22: 46154 | J22: 5 | K22: =IF(OR(H22="",I22=""),"",I22-H22+1) | L22: =IF(OR(K22="",N(F22)=0),"",F22/K22) | M22: Book club pick | N22: =IF(AND(G22="Finished",I22<>""),IF(YEAR(I22)=Dashboard!$C$4,I22+ROW()/10000000,""),"") | O22: =IF(B22="","",IFERROR(MATCH(D22,Settings!$B$6:$B$17,0),12)) | P22: =IF(AND(G22="Reading",B22<>""),IF(H22="",TODAY(),H22)+ROW()/10000000,"") | Q22: =IF(AND(N22<>"",N(J22)=5),N22,"")
B23: The Lighthouse of Small Hours | C23: Wren Okafor | D23: Historical fiction | E23: Ebook | F23: 445 | G23: Did not finish | H23: 46155 | K23: =IF(OR(H23="",I23=""),"",I23-H23+1) | L23: =IF(OR(K23="",N(F23)=0),"",F23/K23) | M23: Not for me | N23: =IF(AND(G23="Finished",I23<>""),IF(YEAR(I23)=Dashboard!$C$4,I23+ROW()/10000000,""),"") | O23: =IF(B23="","",IFERROR(MATCH(D23,Settings!$B$6:$B$17,0),12)) | P23: =IF(AND(G23="Reading",B23<>""),IF(H23="",TODAY(),H23)+ROW()/10000000,"") | Q23: =IF(AND(N23<>"",N(J23)=5),N23,"")
B24: The Promise of Small Hours | C24: Jude Marlowe | D24: Mystery | E24: Audio | F24: 511 | G24: Finished | H24: 46162 | I24: 46170 | J24: 5 | K24: =IF(OR(H24="",I24=""),"",I24-H24+1) | L24: =IF(OR(K24="",N(F24)=0),"",F24/K24) | M24: Read it on holiday | N24: =IF(AND(G24="Finished",I24<>""),IF(YEAR(I24)=Dashboard!$C$4,I24+ROW()/10000000,""),"") | O24: =IF(B24="","",IFERROR(MATCH(D24,Settings!$B$6:$B$17,0),12)) | P24: =IF(AND(G24="Reading",B24<>""),IF(H24="",TODAY(),H24)+ROW()/10000000,"") | Q24: =IF(AND(N24<>"",N(J24)=5),N24,"")
B25: The Lantern Harbour | C25: Silas Delacroix-Park | D25: Biography | E25: Paper | F25: 276 | G25: Finished | H25: 46170 | I25: 46174 | J25: 3 | K25: =IF(OR(H25="",I25=""),"",I25-H25+1) | L25: =IF(OR(K25="",N(F25)=0),"",F25/K25) | N25: =IF(AND(G25="Finished",I25<>""),IF(YEAR(I25)=Dashboard!$C$4,I25+ROW()/10000000,""),"") | O25: =IF(B25="","",IFERROR(MATCH(D25,Settings!$B$6:$B$17,0),12)) | P25: =IF(AND(G25="Reading",B25<>""),IF(H25="",TODAY(),H25)+ROW()/10000000,"") | Q25: =IF(AND(N25<>"",N(J25)=5),N25,"")
B26: Midnight Orchard | C26: Tomas Okafor | D26: Biography | E26: Audio | F26: 347 | G26: Finished | H26: 46176 | I26: 46184 | J26: 3 | K26: =IF(OR(H26="",I26=""),"",I26-H26+1) | L26: =IF(OR(K26="",N(F26)=0),"",F26/K26) | N26: =IF(AND(G26="Finished",I26<>""),IF(YEAR(I26)=Dashboard!$C$4,I26+ROW()/10000000,""),"") | O26: =IF(B26="","",IFERROR(MATCH(D26,Settings!$B$6:$B$17,0),12)) | P26: =IF(AND(G26="Reading",B26<>""),IF(H26="",TODAY(),H26)+ROW()/10000000,"") | Q26: =IF(AND(N26<>"",N(J26)=5),N26,"")
B27: The River of Borrowed Time | C27: Ines Holloway | D27: Romance | E27: Ebook | F27: 292 | G27: Finished | H27: 46186 | I27: 46191 | J27: 4 | K27: =IF(OR(H27="",I27=""),"",I27-H27+1) | L27: =IF(OR(K27="",N(F27)=0),"",F27/K27) | M27: Could not put it down | N27: =IF(AND(G27="Finished",I27<>""),IF(YEAR(I27)=Dashboard!$C$4,I27+ROW()/10000000,""),"") | O27: =IF(B27="","",IFERROR(MATCH(D27,Settings!$B$6:$B$17,0),12)) | P27: =IF(AND(G27="Reading",B27<>""),IF(H27="",TODAY(),H27)+ROW()/10000000,"") | Q27: =IF(AND(N27<>"",N(J27)=5),N27,"")
B28: The Wild Orchestra | C28: Colm Holloway | D28: Self-help | E28: Paper | F28: 269 | G28: Finished | H28: 46191 | I28: 46196 | J28: 4 | K28: =IF(OR(H28="",I28=""),"",I28-H28+1) | L28: =IF(OR(K28="",N(F28)=0),"",F28/K28) | M28: Lent to a friend | N28: =IF(AND(G28="Finished",I28<>""),IF(YEAR(I28)=Dashboard!$C$4,I28+ROW()/10000000,""),"") | O28: =IF(B28="","",IFERROR(MATCH(D28,Settings!$B$6:$B$17,0),12)) | P28: =IF(AND(G28="Reading",B28<>""),IF(H28="",TODAY(),H28)+ROW()/10000000,"") | Q28: =IF(AND(N28<>"",N(J28)=5),N28,"")
B29: The Salt Kingdom | C29: Otto Thorne | D29: Fiction | E29: Audio | F29: 406 | G29: Finished | H29: 46196 | I29: 46205 | J29: 2 | K29: =IF(OR(H29="",I29=""),"",I29-H29+1) | L29: =IF(OR(K29="",N(F29)=0),"",F29/K29) | N29: =IF(AND(G29="Finished",I29<>""),IF(YEAR(I29)=Dashboard!$C$4,I29+ROW()/10000000,""),"") | O29: =IF(B29="","",IFERROR(MATCH(D29,Settings!$B$6:$B$17,0),12)) | P29: =IF(AND(G29="Reading",B29<>""),IF(H29="",TODAY(),H29)+ROW()/10000000,"") | Q29: =IF(AND(N29<>"",N(J29)=5),N29,"")
B30: Northern Harbour | C30: Colm Quill | D30: Mystery | E30: Ebook | F30: 295 | G30: Finished | H30: 46207 | I30: 46212 | J30: 4 | K30: =IF(OR(H30="",I30=""),"",I30-H30+1) | L30: =IF(OR(K30="",N(F30)=0),"",F30/K30) | N30: =IF(AND(G30="Finished",I30<>""),IF(YEAR(I30)=Dashboard!$C$4,I30+ROW()/10000000,""),"") | O30: =IF(B30="","",IFERROR(MATCH(D30,Settings!$B$6:$B$17,0),12)) | P30: =IF(AND(G30="Reading",B30<>""),IF(H30="",TODAY(),H30)+ROW()/10000000,"") | Q30: =IF(AND(N30<>"",N(J30)=5),N30,"")
B31: The Ferry of Lost Things | C31: Otto Marlowe | D31: Historical fiction | E31: Audio | F31: 438 | G31: Finished | H31: 46212 | I31: 46219 | J31: 2 | K31: =IF(OR(H31="",I31=""),"",I31-H31+1) | L31: =IF(OR(K31="",N(F31)=0),"",F31/K31) | N31: =IF(AND(G31="Finished",I31<>""),IF(YEAR(I31)=Dashboard!$C$4,I31+ROW()/10000000,""),"") | O31: =IF(B31="","",IFERROR(MATCH(D31,Settings!$B$6:$B$17,0),12)) | P31: =IF(AND(G31="Reading",B31<>""),IF(H31="",TODAY(),H31)+ROW()/10000000,"") | Q31: =IF(AND(N31<>"",N(J31)=5),N31,"")
B32: The Silver Island | C32: Anika Castell | D32: Historical fiction | E32: Audio | F32: 289 | G32: Finished | H32: 46220 | I32: 46224 | J32: 4 | K32: =IF(OR(H32="",I32=""),"",I32-H32+1) | L32: =IF(OR(K32="",N(F32)=0),"",F32/K32) | N32: =IF(AND(G32="Finished",I32<>""),IF(YEAR(I32)=Dashboard!$C$4,I32+ROW()/10000000,""),"") | O32: =IF(B32="","",IFERROR(MATCH(D32,Settings!$B$6:$B$17,0),12)) | P32: =IF(AND(G32="Reading",B32<>""),IF(H32="",TODAY(),H32)+ROW()/10000000,"") | Q32: =IF(AND(N32<>"",N(J32)=5),N32,"")
B33: Glass Promise | C33: Otto Lindqvist | D33: Mystery | E33: Audio | F33: 332 | G33: Finished | H33: 46226 | I33: 46233 | J33: 3 | K33: =IF(OR(H33="",I33=""),"",I33-H33+1) | L33: =IF(OR(K33="",N(F33)=0),"",F33/K33) | M33: Read it on holiday | N33: =IF(AND(G33="Finished",I33<>""),IF(YEAR(I33)=Dashboard!$C$4,I33+ROW()/10000000,""),"") | O33: =IF(B33="","",IFERROR(MATCH(D33,Settings!$B$6:$B$17,0),12)) | P33: =IF(AND(G33="Reading",B33<>""),IF(H33="",TODAY(),H33)+ROW()/10000000,"") | Q33: =IF(AND(N33<>"",N(J33)=5),N33,"")
B34: The Drowned Bookshop | C34: Colm Fennimore | D34: Poetry | E34: Ebook | F34: 348 | G34: Finished | H34: 46234 | I34: 46240 | J34: 5 | K34: =IF(OR(H34="",I34=""),"",I34-H34+1) | L34: =IF(OR(K34="",N(F34)=0),"",F34/K34) | M34: Book club pick | N34: =IF(AND(G34="Finished",I34<>""),IF(YEAR(I34)=Dashboard!$C$4,I34+ROW()/10000000,""),"") | O34: =IF(B34="","",IFERROR(MATCH(D34,Settings!$B$6:$B$17,0),12)) | P34: =IF(AND(G34="Reading",B34<>""),IF(H34="",TODAY(),H34)+ROW()/10000000,"") | Q34: =IF(AND(N34<>"",N(J34)=5),N34,"")
B35: Midnight Garden | C35: Ines Varga | D35: Fiction | E35: Ebook | F35: 369 | G35: Finished | H35: 46242 | I35: 46247 | J35: 4 | K35: =IF(OR(H35="",I35=""),"",I35-H35+1) | L35: =IF(OR(K35="",N(F35)=0),"",F35/K35) | M35: Lent to a friend | N35: =IF(AND(G35="Finished",I35<>""),IF(YEAR(I35)=Dashboard!$C$4,I35+ROW()/10000000,""),"") | O35: =IF(B35="","",IFERROR(MATCH(D35,Settings!$B$6:$B$17,0),12)) | P35: =IF(AND(G35="Reading",B35<>""),IF(H35="",TODAY(),H35)+ROW()/10000000,"") | Q35: =IF(AND(N35<>"",N(J35)=5),N35,"")
B36: The Daughter of Ash | C36: Elena Brandt | D36: Historical fiction | E36: Audio | F36: 438 | G36: Finished | H36: 46247 | I36: 46253 | J36: 3 | K36: =IF(OR(H36="",I36=""),"",I36-H36+1) | L36: =IF(OR(K36="",N(F36)=0),"",F36/K36) | M36: Slow start, great ending | N36: =IF(AND(G36="Finished",I36<>""),IF(YEAR(I36)=Dashboard!$C$4,I36+ROW()/10000000,""),"") | O36: =IF(B36="","",IFERROR(MATCH(D36,Settings!$B$6:$B$17,0),12)) | P36: =IF(AND(G36="Reading",B36<>""),IF(H36="",TODAY(),H36)+ROW()/10000000,"") | Q36: =IF(AND(N36<>"",N(J36)=5),N36,"")
B37: Lantern Promise | C37: Colm Okafor | D37: Fantasy | E37: Audio | F37: 428 | G37: Finished | H37: 46254 | I37: 46262 | J37: 5 | K37: =IF(OR(H37="",I37=""),"",I37-H37+1) | L37: =IF(OR(K37="",N(F37)=0),"",F37/K37) | N37: =IF(AND(G37="Finished",I37<>""),IF(YEAR(I37)=Dashboard!$C$4,I37+ROW()/10000000,""),"") | O37: =IF(B37="","",IFERROR(MATCH(D37,Settings!$B$6:$B$17,0),12)) | P37: =IF(AND(G37="Reading",B37<>""),IF(H37="",TODAY(),H37)+ROW()/10000000,"") | Q37: =IF(AND(N37<>"",N(J37)=5),N37,"")
B38: The Lighthouse of Other Rooms | C38: Elena Lindqvist | D38: Self-help | E38: Audio | F38: 259 | G38: Finished | H38: 46263 | I38: 46269 | J38: 5 | K38: =IF(OR(H38="",I38=""),"",I38-H38+1) | L38: =IF(OR(K38="",N(F38)=0),"",F38/K38) | M38: Could not put it down | N38: =IF(AND(G38="Finished",I38<>""),IF(YEAR(I38)=Dashboard!$C$4,I38+ROW()/10000000,""),"") | O38: =IF(B38="","",IFERROR(MATCH(D38,Settings!$B$6:$B$17,0),12)) | P38: =IF(AND(G38="Reading",B38<>""),IF(H38="",TODAY(),H38)+ROW()/10000000,"") | Q38: =IF(AND(N38<>"",N(J38)=5),N38,"")
B39: The Lantern Clockmaker | C39: Wren Delacroix-Park | D39: Romance | E39: Paper | F39: 216 | G39: Finished | H39: 46270 | I39: 46275 | J39: 4 | K39: =IF(OR(H39="",I39=""),"",I39-H39+1) | L39: =IF(OR(K39="",N(F39)=0),"",F39/K39) | N39: =IF(AND(G39="Finished",I39<>""),IF(YEAR(I39)=Dashboard!$C$4,I39+ROW()/10000000,""),"") | O39: =IF(B39="","",IFERROR(MATCH(D39,Settings!$B$6:$B$17,0),12)) | P39: =IF(AND(G39="Reading",B39<>""),IF(H39="",TODAY(),H39)+ROW()/10000000,"") | Q39: =IF(AND(N39<>"",N(J39)=5),N39,"")
B40: The House of Northern Lights | C40: Mira Brandt | D40: Science fiction | E40: Audio | F40: 323 | G40: Finished | H40: 46275 | I40: 46282 | J40: 4 | K40: =IF(OR(H40="",I40=""),"",I40-H40+1) | L40: =IF(OR(K40="",N(F40)=0),"",F40/K40) | M40: Slow start, great ending | N40: =IF(AND(G40="Finished",I40<>""),IF(YEAR(I40)=Dashboard!$C$4,I40+ROW()/10000000,""),"") | O40: =IF(B40="","",IFERROR(MATCH(D40,Settings!$B$6:$B$17,0),12)) | P40: =IF(AND(G40="Reading",B40<>""),IF(H40="",TODAY(),H40)+ROW()/10000000,"") | Q40: =IF(AND(N40<>"",N(J40)=5),N40,"")
B41: Midnight Summer | C41: Mira Delacroix-Park | D41: Mystery | E41: Paper | F41: 412 | G41: Reading | H41: 46287 | K41: =IF(OR(H41="",I41=""),"",I41-H41+1) | L41: =IF(OR(K41="",N(F41)=0),"",F41/K41) | N41: =IF(AND(G41="Finished",I41<>""),IF(YEAR(I41)=Dashboard!$C$4,I41+ROW()/10000000,""),"") | O41: =IF(B41="","",IFERROR(MATCH(D41,Settings!$B$6:$B$17,0),12)) | P41: =IF(AND(G41="Reading",B41<>""),IF(H41="",TODAY(),H41)+ROW()/10000000,"") | Q41: =IF(AND(N41<>"",N(J41)=5),N41,"")
B42: Paper Machine | C42: Otto Lindqvist | D42: Mystery | E42: Paper | F42: 268 | G42: Reading | H42: 46291 | K42: =IF(OR(H42="",I42=""),"",I42-H42+1) | L42: =IF(OR(K42="",N(F42)=0),"",F42/K42) | N42: =IF(AND(G42="Finished",I42<>""),IF(YEAR(I42)=Dashboard!$C$4,I42+ROW()/10000000,""),"") | O42: =IF(B42="","",IFERROR(MATCH(D42,Settings!$B$6:$B$17,0),12)) | P42: =IF(AND(G42="Reading",B42<>""),IF(H42="",TODAY(),H42)+ROW()/10000000,"") | Q42: =IF(AND(N42<>"",N(J42)=5),N42,"")
...

Sheet Bookshelf
B2: ="Bookshelf "&Dashboard!$C$4
B3: Every book you finish in the year on the Dashboard, in the order you finished them and in the colour of its genre. The shelves hold 100 books.
B4: =COUNT(Books!$N$6:$N$1005)&IF(COUNT(Books!$N$6:$N$1005)=1," book"," books")&" in "&Dashboard!$C$4
B5: =IF(B7="","",INDEX(Books!$B$6:$B$1005,MATCH(B7,Books!$N$6:$N$1005,0))) | C5: =IF(C7="","",INDEX(Books!$B$6:$B$1005,MATCH(C7,Books!$N$6:$N$1005,0))) | D5: =IF(D7="","",INDEX(Books!$B$6:$B$1005,MATCH(D7,Books!$N$6:$N$1005,0))) | E5: =IF(E7="","",INDEX(Books!$B$6:$B$1005,MATCH(E7,Books!$N$6:$N$1005,0))) | F5: =IF(F7="","",INDEX(Books!$B$6:$B$1005,MATCH(F7,Books!$N$6:$N$1005,0))) | G5: =IF(G7="","",INDEX(Books!$B$6:$B$1005,MATCH(G7,Books!$N$6:$N$1005,0))) | H5: =IF(H7="","",INDEX(Books!$B$6:$B$1005,MATCH(H7,Books!$N$6:$N$1005,0))) | I5: =IF(I7="","",INDEX(Books!$B$6:$B$1005,MATCH(I7,Books!$N$6:$N$1005,0))) | ... U5: =IF(U7="","",INDEX(Books!$B$6:$B$1005,MATCH(U7,Books!$N$6:$N$1005,0)))
B7: =IFERROR(SMALL(Books!$N$6:$N$1005,1),"") | C7: =IFERROR(SMALL(Books!$N$6:$N$1005,2),"") | D7: =IFERROR(SMALL(Books!$N$6:$N$1005,3),"") | E7: =IFERROR(SMALL(Books!$N$6:$N$1005,4),"") | F7: =IFERROR(SMALL(Books!$N$6:$N$1005,5),"") | G7: =IFERROR(SMALL(Books!$N$6:$N$1005,6),"") | H7: =IFERROR(SMALL(Books!$N$6:$N$1005,7),"") | I7: =IFERROR(SMALL(Books!$N$6:$N$1005,8),"") | J7: =IFERROR(SMALL(Books!$N$6:$N$1005,9),"") | K7: =IFERROR(SMALL(Books!$N$6:$N$1005,10),"") | L7: =IFERROR(SMALL(Books!$N$6:$N$1005,11),"") | M7: =IFERROR(SMALL(Books!$N$6:$N$1005,12),"") | N7: =IFERROR(SMALL(Books!$N$6:$N$1005,13),"") | O7: =IFERROR(SMALL(Books!$N$6:$N$1005,14),"") | P7: =IFERROR(SMALL(Books!$N$6:$N$1005,15),"") | Q7: =IFERROR(SMALL(Books!$N$6:$N$1005,16),"") | R7: =IFERROR(SMALL(Books!$N$6:$N$1005,17),"") | S7: =IFERROR(SMALL(Books!$N$6:$N$1005,18),"") | T7: =IFERROR(SMALL(Books!$N$6:$N$1005,19),"") | U7: =IFERROR(SMALL(Books!$N$6:$N$1005,20),"") | Y7: =IF(B7="",0,INDEX(Books!$O$6:$O$1005,MATCH(B7,Books!$N$6:$N$1005,0))) | Z7: =IF(C7="",0,INDEX(Books!$O$6:$O$1005,MATCH(C7,Books!$N$6:$N$1005,0))) | AA7: =IF(D7="",0,INDEX(Books!$O$6:$O$1005,MATCH(D7,Books!$N$6:$N$1005,0))) | AB7: =IF(E7="",0,INDEX(Books!$O$6:$O$1005,MATCH(E7,Books!$N$6:$N$1005,0))) | AC7: =IF(F7="",0,INDEX(Books!$O$6:$O$1005,MATCH(F7,Books!$N$6:$N$1005,0))) | AD7: =IF(G7="",0,INDEX(Books!$O$6:$O$1005,MATCH(G7,Books!$N$6:$N$1005,0))) | AE7: =IF(H7="",0,INDEX(Books!$O$6:$O$1005,MATCH(H7,Books!$N$6:$N$1005,0))) | AF7: =IF(I7="",0,INDEX(Books!$O$6:$O$1005,MATCH(I7,Books!$N$6:$N$1005,0))) | ... AR7: =IF(U7="",0,INDEX(Books!$O$6:$O$1005,MATCH(U7,Books!$N$6:$N$1005,0)))
B9: =IF(B11="","",INDEX(Books!$B$6:$B$1005,MATCH(B11,Books!$N$6:$N$1005,0))) | C9: =IF(C11="","",INDEX(Books!$B$6:$B$1005,MATCH(C11,Books!$N$6:$N$1005,0))) | D9: =IF(D11="","",INDEX(Books!$B$6:$B$1005,MATCH(D11,Books!$N$6:$N$1005,0))) | E9: =IF(E11="","",INDEX(Books!$B$6:$B$1005,MATCH(E11,Books!$N$6:$N$1005,0))) | F9: =IF(F11="","",INDEX(Books!$B$6:$B$1005,MATCH(F11,Books!$N$6:$N$1005,0))) | G9: =IF(G11="","",INDEX(Books!$B$6:$B$1005,MATCH(G11,Books!$N$6:$N$1005,0))) | H9: =IF(H11="","",INDEX(Books!$B$6:$B$1005,MATCH(H11,Books!$N$6:$N$1005,0))) | I9: =IF(I11="","",INDEX(Books!$B$6:$B$1005,MATCH(I11,Books!$N$6:$N$1005,0))) | ... U9: =IF(U11="","",INDEX(Books!$B$6:$B$1005,MATCH(U11,Books!$N$6:$N$1005,0)))
B11: =IFERROR(SMALL(Books!$N$6:$N$1005,21),"") | C11: =IFERROR(SMALL(Books!$N$6:$N$1005,22),"") | D11: =IFERROR(SMALL(Books!$N$6:$N$1005,23),"") | E11: =IFERROR(SMALL(Books!$N$6:$N$1005,24),"") | F11: =IFERROR(SMALL(Books!$N$6:$N$1005,25),"") | G11: =IFERROR(SMALL(Books!$N$6:$N$1005,26),"") | H11: =IFERROR(SMALL(Books!$N$6:$N$1005,27),"") | I11: =IFERROR(SMALL(Books!$N$6:$N$1005,28),"") | J11: =IFERROR(SMALL(Books!$N$6:$N$1005,29),"") | K11: =IFERROR(SMALL(Books!$N$6:$N$1005,30),"") | L11: =IFERROR(SMALL(Books!$N$6:$N$1005,31),"") | M11: =IFERROR(SMALL(Books!$N$6:$N$1005,32),"") | N11: =IFERROR(SMALL(Books!$N$6:$N$1005,33),"") | O11: =IFERROR(SMALL(Books!$N$6:$N$1005,34),"") | P11: =IFERROR(SMALL(Books!$N$6:$N$1005,35),"") | Q11: =IFERROR(SMALL(Books!$N$6:$N$1005,36),"") | R11: =IFERROR(SMALL(Books!$N$6:$N$1005,37),"") | S11: =IFERROR(SMALL(Books!$N$6:$N$1005,38),"") | T11: =IFERROR(SMALL(Books!$N$6:$N$1005,39),"") | U11: =IFERROR(SMALL(Books!$N$6:$N$1005,40),"") | Y11: =IF(B11="",0,INDEX(Books!$O$6:$O$1005,MATCH(B11,Books!$N$6:$N$1005,0))) | Z11: =IF(C11="",0,INDEX(Books!$O$6:$O$1005,MATCH(C11,Books!$N$6:$N$1005,0))) | AA11: =IF(D11="",0,INDEX(Books!$O$6:$O$1005,MATCH(D11,Books!$N$6:$N$1005,0))) | AB11: =IF(E11="",0,INDEX(Books!$O$6:$O$1005,MATCH(E11,Books!$N$6:$N$1005,0))) | AC11: =IF(F11="",0,INDEX(Books!$O$6:$O$1005,MATCH(F11,Books!$N$6:$N$1005,0))) | AD11: =IF(G11="",0,INDEX(Books!$O$6:$O$1005,MATCH(G11,Books!$N$6:$N$1005,0))) | AE11: =IF(H11="",0,INDEX(Books!$O$6:$O$1005,MATCH(H11,Books!$N$6:$N$1005,0))) | AF11: =IF(I11="",0,INDEX(Books!$O$6:$O$1005,MATCH(I11,Books!$N$6:$N$1005,0))) | ... AR11: =IF(U11="",0,INDEX(Books!$O$6:$O$1005,MATCH(U11,Books!$N$6:$N$1005,0)))
B13: =IF(B15="","",INDEX(Books!$B$6:$B$1005,MATCH(B15,Books!$N$6:$N$1005,0))) | C13: =IF(C15="","",INDEX(Books!$B$6:$B$1005,MATCH(C15,Books!$N$6:$N$1005,0))) | D13: =IF(D15="","",INDEX(Books!$B$6:$B$1005,MATCH(D15,Books!$N$6:$N$1005,0))) | E13: =IF(E15="","",INDEX(Books!$B$6:$B$1005,MATCH(E15,Books!$N$6:$N$1005,0))) | F13: =IF(F15="","",INDEX(Books!$B$6:$B$1005,MATCH(F15,Books!$N$6:$N$1005,0))) | G13: =IF(G15="","",INDEX(Books!$B$6:$B$1005,MATCH(G15,Books!$N$6:$N$1005,0))) | H13: =IF(H15="","",INDEX(Books!$B$6:$B$1005,MATCH(H15,Books!$N$6:$N$1005,0))) | I13: =IF(I15="","",INDEX(Books!$B$6:$B$1005,MATCH(I15,Books!$N$6:$N$1005,0))) | ... U13: =IF(U15="","",INDEX(Books!$B$6:$B$1005,MATCH(U15,Books!$N$6:$N$1005,0)))
B15: =IFERROR(SMALL(Books!$N$6:$N$1005,41),"") | C15: =IFERROR(SMALL(Books!$N$6:$N$1005,42),"") | D15: =IFERROR(SMALL(Books!$N$6:$N$1005,43),"") | E15: =IFERROR(SMALL(Books!$N$6:$N$1005,44),"") | F15: =IFERROR(SMALL(Books!$N$6:$N$1005,45),"") | G15: =IFERROR(SMALL(Books!$N$6:$N$1005,46),"") | H15: =IFERROR(SMALL(Books!$N$6:$N$1005,47),"") | I15: =IFERROR(SMALL(Books!$N$6:$N$1005,48),"") | J15: =IFERROR(SMALL(Books!$N$6:$N$1005,49),"") | K15: =IFERROR(SMALL(Books!$N$6:$N$1005,50),"") | L15: =IFERROR(SMALL(Books!$N$6:$N$1005,51),"") | M15: =IFERROR(SMALL(Books!$N$6:$N$1005,52),"") | N15: =IFERROR(SMALL(Books!$N$6:$N$1005,53),"") | O15: =IFERROR(SMALL(Books!$N$6:$N$1005,54),"") | P15: =IFERROR(SMALL(Books!$N$6:$N$1005,55),"") | Q15: =IFERROR(SMALL(Books!$N$6:$N$1005,56),"") | R15: =IFERROR(SMALL(Books!$N$6:$N$1005,57),"") | S15: =IFERROR(SMALL(Books!$N$6:$N$1005,58),"") | T15: =IFERROR(SMALL(Books!$N$6:$N$1005,59),"") | U15: =IFERROR(SMALL(Books!$N$6:$N$1005,60),"") | Y15: =IF(B15="",0,INDEX(Books!$O$6:$O$1005,MATCH(B15,Books!$N$6:$N$1005,0))) | Z15: =IF(C15="",0,INDEX(Books!$O$6:$O$1005,MATCH(C15,Books!$N$6:$N$1005,0))) | AA15: =IF(D15="",0,INDEX(Books!$O$6:$O$1005,MATCH(D15,Books!$N$6:$N$1005,0))) | AB15: =IF(E15="",0,INDEX(Books!$O$6:$O$1005,MATCH(E15,Books!$N$6:$N$1005,0))) | AC15: =IF(F15="",0,INDEX(Books!$O$6:$O$1005,MATCH(F15,Books!$N$6:$N$1005,0))) | AD15: =IF(G15="",0,INDEX(Books!$O$6:$O$1005,MATCH(G15,Books!$N$6:$N$1005,0))) | AE15: =IF(H15="",0,INDEX(Books!$O$6:$O$1005,MATCH(H15,Books!$N$6:$N$1005,0))) | AF15: =IF(I15="",0,INDEX(Books!$O$6:$O$1005,MATCH(I15,Books!$N$6:$N$1005,0))) | ... AR15: =IF(U15="",0,INDEX(Books!$O$6:$O$1005,MATCH(U15,Books!$N$6:$N$1005,0)))
B17: =IF(B19="","",INDEX(Books!$B$6:$B$1005,MATCH(B19,Books!$N$6:$N$1005,0))) | C17: =IF(C19="","",INDEX(Books!$B$6:$B$1005,MATCH(C19,Books!$N$6:$N$1005,0))) | D17: =IF(D19="","",INDEX(Books!$B$6:$B$1005,MATCH(D19,Books!$N$6:$N$1005,0))) | E17: =IF(E19="","",INDEX(Books!$B$6:$B$1005,MATCH(E19,Books!$N$6:$N$1005,0))) | F17: =IF(F19="","",INDEX(Books!$B$6:$B$1005,MATCH(F19,Books!$N$6:$N$1005,0))) | G17: =IF(G19="","",INDEX(Books!$B$6:$B$1005,MATCH(G19,Books!$N$6:$N$1005,0))) | H17: =IF(H19="","",INDEX(Books!$B$6:$B$1005,MATCH(H19,Books!$N$6:$N$1005,0))) | I17: =IF(I19="","",INDEX(Books!$B$6:$B$1005,MATCH(I19,Books!$N$6:$N$1005,0))) | ... U17: =IF(U19="","",INDEX(Books!$B$6:$B$1005,MATCH(U19,Books!$N$6:$N$1005,0)))
B19: =IFERROR(SMALL(Books!$N$6:$N$1005,61),"") | C19: =IFERROR(SMALL(Books!$N$6:$N$1005,62),"") | D19: =IFERROR(SMALL(Books!$N$6:$N$1005,63),"") | E19: =IFERROR(SMALL(Books!$N$6:$N$1005,64),"") | F19: =IFERROR(SMALL(Books!$N$6:$N$1005,65),"") | G19: =IFERROR(SMALL(Books!$N$6:$N$1005,66),"") | H19: =IFERROR(SMALL(Books!$N$6:$N$1005,67),"") | I19: =IFERROR(SMALL(Books!$N$6:$N$1005,68),"") | J19: =IFERROR(SMALL(Books!$N$6:$N$1005,69),"") | K19: =IFERROR(SMALL(Books!$N$6:$N$1005,70),"") | L19: =IFERROR(SMALL(Books!$N$6:$N$1005,71),"") | M19: =IFERROR(SMALL(Books!$N$6:$N$1005,72),"") | N19: =IFERROR(SMALL(Books!$N$6:$N$1005,73),"") | O19: =IFERROR(SMALL(Books!$N$6:$N$1005,74),"") | P19: =IFERROR(SMALL(Books!$N$6:$N$1005,75),"") | Q19: =IFERROR(SMALL(Books!$N$6:$N$1005,76),"") | R19: =IFERROR(SMALL(Books!$N$6:$N$1005,77),"") | S19: =IFERROR(SMALL(Books!$N$6:$N$1005,78),"") | T19: =IFERROR(SMALL(Books!$N$6:$N$1005,79),"") | U19: =IFERROR(SMALL(Books!$N$6:$N$1005,80),"") | Y19: =IF(B19="",0,INDEX(Books!$O$6:$O$1005,MATCH(B19,Books!$N$6:$N$1005,0))) | Z19: =IF(C19="",0,INDEX(Books!$O$6:$O$1005,MATCH(C19,Books!$N$6:$N$1005,0))) | AA19: =IF(D19="",0,INDEX(Books!$O$6:$O$1005,MATCH(D19,Books!$N$6:$N$1005,0))) | AB19: =IF(E19="",0,INDEX(Books!$O$6:$O$1005,MATCH(E19,Books!$N$6:$N$1005,0))) | AC19: =IF(F19="",0,INDEX(Books!$O$6:$O$1005,MATCH(F19,Books!$N$6:$N$1005,0))) | AD19: =IF(G19="",0,INDEX(Books!$O$6:$O$1005,MATCH(G19,Books!$N$6:$N$1005,0))) | AE19: =IF(H19="",0,INDEX(Books!$O$6:$O$1005,MATCH(H19,Books!$N$6:$N$1005,0))) | AF19: =IF(I19="",0,INDEX(Books!$O$6:$O$1005,MATCH(I19,Books!$N$6:$N$1005,0))) | ... AR19: =IF(U19="",0,INDEX(Books!$O$6:$O$1005,MATCH(U19,Books!$N$6:$N$1005,0)))
B21: =IF(B23="","",INDEX(Books!$B$6:$B$1005,MATCH(B23,Books!$N$6:$N$1005,0))) | C21: =IF(C23="","",INDEX(Books!$B$6:$B$1005,MATCH(C23,Books!$N$6:$N$1005,0))) | D21: =IF(D23="","",INDEX(Books!$B$6:$B$1005,MATCH(D23,Books!$N$6:$N$1005,0))) | E21: =IF(E23="","",INDEX(Books!$B$6:$B$1005,MATCH(E23,Books!$N$6:$N$1005,0))) | F21: =IF(F23="","",INDEX(Books!$B$6:$B$1005,MATCH(F23,Books!$N$6:$N$1005,0))) | G21: =IF(G23="","",INDEX(Books!$B$6:$B$1005,MATCH(G23,Books!$N$6:$N$1005,0))) | H21: =IF(H23="","",INDEX(Books!$B$6:$B$1005,MATCH(H23,Books!$N$6:$N$1005,0))) | I21: =IF(I23="","",INDEX(Books!$B$6:$B$1005,MATCH(I23,Books!$N$6:$N$1005,0))) | ... U21: =IF(U23="","",INDEX(Books!$B$6:$B$1005,MATCH(U23,Books!$N$6:$N$1005,0)))
B23: =IFERROR(SMALL(Books!$N$6:$N$1005,81),"") | C23: =IFERROR(SMALL(Books!$N$6:$N$1005,82),"") | D23: =IFERROR(SMALL(Books!$N$6:$N$1005,83),"") | E23: =IFERROR(SMALL(Books!$N$6:$N$1005,84),"") | F23: =IFERROR(SMALL(Books!$N$6:$N$1005,85),"") | G23: =IFERROR(SMALL(Books!$N$6:$N$1005,86),"") | H23: =IFERROR(SMALL(Books!$N$6:$N$1005,87),"") | I23: =IFERROR(SMALL(Books!$N$6:$N$1005,88),"") | J23: =IFERROR(SMALL(Books!$N$6:$N$1005,89),"") | K23: =IFERROR(SMALL(Books!$N$6:$N$1005,90),"") | L23: =IFERROR(SMALL(Books!$N$6:$N$1005,91),"") | M23: =IFERROR(SMALL(Books!$N$6:$N$1005,92),"") | N23: =IFERROR(SMALL(Books!$N$6:$N$1005,93),"") | O23: =IFERROR(SMALL(Books!$N$6:$N$1005,94),"") | P23: =IFERROR(SMALL(Books!$N$6:$N$1005,95),"") | Q23: =IFERROR(SMALL(Books!$N$6:$N$1005,96),"") | R23: =IFERROR(SMALL(Books!$N$6:$N$1005,97),"") | S23: =IFERROR(SMALL(Books!$N$6:$N$1005,98),"") | T23: =IFERROR(SMALL(Books!$N$6:$N$1005,99),"") | U23: =IFERROR(SMALL(Books!$N$6:$N$1005,100),"") | Y23: =IF(B23="",0,INDEX(Books!$O$6:$O$1005,MATCH(B23,Books!$N$6:$N$1005,0))) | Z23: =IF(C23="",0,INDEX(Books!$O$6:$O$1005,MATCH(C23,Books!$N$6:$N$1005,0))) | AA23: =IF(D23="",0,INDEX(Books!$O$6:$O$1005,MATCH(D23,Books!$N$6:$N$1005,0))) | AB23: =IF(E23="",0,INDEX(Books!$O$6:$O$1005,MATCH(E23,Books!$N$6:$N$1005,0))) | AC23: =IF(F23="",0,INDEX(Books!$O$6:$O$1005,MATCH(F23,Books!$N$6:$N$1005,0))) | AD23: =IF(G23="",0,INDEX(Books!$O$6:$O$1005,MATCH(G23,Books!$N$6:$N$1005,0))) | AE23: =IF(H23="",0,INDEX(Books!$O$6:$O$1005,MATCH(H23,Books!$N$6:$N$1005,0))) | AF23: =IF(I23="",0,INDEX(Books!$O$6:$O$1005,MATCH(I23,Books!$N$6:$N$1005,0))) | ... AR23: =IF(U23="",0,INDEX(Books!$O$6:$O$1005,MATCH(U23,Books!$N$6:$N$1005,0)))

Sheet Settings
B2: Settings
B3: Your genres and their colours on the bookshelf.
B5: Genre | C5: Colour
B6: Fiction | E6: Rename the genres to the ones you read. Each place on the list keeps its colour.
B7: Fantasy | E7: A book with a genre that is not on the list gets the last colour.
B8: Mystery
B9: Romance
B10: Science fiction
B11: Historical fiction
B12: Non-fiction
B13: Biography
B14: Self-help
B15: Poetry
B16: Classics
B17: Other

Sheet Start Here
B2: Start here
B3: Type only in the yellow cells. Everything else is calculated.
B5: 1 | C5: Dashboard: the year and how many books you want to read in it.
B7: 2 | C7: Books: one line per book, with its author, genre, format and pages.
B9: 3 | C9: When you start a book, set it to Reading with the date. When you finish, set Finished, the date and a rating.
B11: 4 | C11: Books you want to read go in the same list, as Want to read.
B13: 5 | C13: Dashboard and Bookshelf: your goal, your months and genres, and shelves for 100 books that fill up as you read.
C16: Ahead or behind compares your finished books with where the goal says you should be today.
C18: The example books and authors are made up. Delete them and add your own.
C20: Works in Google Sheets and Microsoft Excel.
