Workbook

Sheet Dashboard
M1: =TODAY()-WEEKDAY(TODAY(),3)
B2: Content planner | M2: =MAX(Stats!C16:N16)
B3: ="The week of "&DAY($M$1)&" "&CHOOSE(MONTH($M$1),"Jan","Feb","Mar","Apr","May","Jun","Jul","Aug","Sep","Oct","Nov","Dec")&", and "&CHOOSE(MONTH(TODAY()),"January","February","March","April","May","June","July","August","September","October","November","December")&" so far."
B4: This week | C4: Next 7 days | D4: Late | E4: Ideas | G4: Published this month | H4: Reach this month | I4: Rate this month | J4: Followers
B5: =COUNTIFS(Posts!$B$6:$B$805,">="&$M$1,Posts!$B$6:$B$805,"<"&($M$1+7))-COUNTIFS(Posts!$B$6:$B$805,">="&$M$1,Posts!$B$6:$B$805,"<"&($M$1+7),Posts!$H$6:$H$805,"Idea") | C5: =COUNTIFS(Posts!$B$6:$B$805,">="&TODAY(),Posts!$B$6:$B$805,"<"&(TODAY()+7),Posts!$H$6:$H$805,"Scheduled")+COUNTIFS(Posts!$B$6:$B$805,">="&TODAY(),Posts!$B$6:$B$805,"<"&(TODAY()+7),Posts!$H$6:$H$805,"Draft") | D5: =SUM(Posts!$V$6:$V$805) | E5: =COUNTIF(Posts!$H$6:$H$805,"Idea") | G5: =COUNTIFS(Posts!$H$6:$H$805,"Published",Posts!$T$6:$T$805,(YEAR(TODAY())*100+MONTH(TODAY()))) | H5: =SUMIFS(Posts!$J$6:$J$805,Posts!$H$6:$H$805,"Published",Posts!$T$6:$T$805,(YEAR(TODAY())*100+MONTH(TODAY()))) | I5: =IF(H5=0,"",SUMIFS(Posts!$O$6:$O$805,Posts!$H$6:$H$805,"Published",Posts!$T$6:$T$805,(YEAR(TODAY())*100+MONTH(TODAY())),Posts!$J$6:$J$805,">0")/H5) | J5: =IF($M$2=0,"",INDEX(Stats!$C$15:$N$15,$M$2))
B7: Coming up | C7: Platform | D7: Post | E7: Status | G7: Platform | H7: This week | I7: Goal a week | J7: Rate
B8: =IF(N8="","",INT(N8/10000000)) | C8: =IF(N8="","",IF(INDEX(Posts!$D$1:$D$805,MOD(N8,1000))="","",INDEX(Posts!$D$1:$D$805,MOD(N8,1000)))) | D8: =IF(N8="","",IF(INDEX(Posts!$G$1:$G$805,MOD(N8,1000))="",IF(INDEX(Posts!$E$1:$E$805,MOD(N8,1000))="","",INDEX(Posts!$E$1:$E$805,MOD(N8,1000))),INDEX(Posts!$G$1:$G$805,MOD(N8,1000)))) | E8: =IF(N8="","",IF(INDEX(Posts!$H$1:$H$805,MOD(N8,1000))="","",INDEX(Posts!$H$1:$H$805,MOD(N8,1000)))) | G8: =IF(Settings!$B$10="","",Settings!$B$10) | H8: =IF(G8="","",COUNTIFS(Posts!$D$6:$D$805,G8,Posts!$B$6:$B$805,">="&$M$1,Posts!$B$6:$B$805,"<"&($M$1+7))-COUNTIFS(Posts!$D$6:$D$805,G8,Posts!$B$6:$B$805,">="&$M$1,Posts!$B$6:$B$805,"<"&($M$1+7),Posts!$H$6:$H$805,"Idea")) | I8: =IF(G8="","",N(Settings!$D$10)) | J8: =IF(G8="","",IF(SUMIFS(Posts!$J$6:$J$805,Posts!$D$6:$D$805,G8,Posts!$H$6:$H$805,"Published",Posts!$T$6:$T$805,(YEAR(TODAY())*100+MONTH(TODAY())))=0,"",SUMIFS(Posts!$O$6:$O$805,Posts!$D$6:$D$805,G8,Posts!$H$6:$H$805,"Published",Posts!$T$6:$T$805,(YEAR(TODAY())*100+MONTH(TODAY())),Posts!$J$6:$J$805,">0")/SUMIFS(Posts!$J$6:$J$805,Posts!$D$6:$D$805,G8,Posts!$H$6:$H$805,"Published",Posts!$T$6:$T$805,(YEAR(TODAY())*100+MONTH(TODAY()))))) | N8: =IFERROR(SMALL(Posts!$U$6:$U$805,1),"")
B9: =IF(N9="","",INT(N9/10000000)) | C9: =IF(N9="","",IF(INDEX(Posts!$D$1:$D$805,MOD(N9,1000))="","",INDEX(Posts!$D$1:$D$805,MOD(N9,1000)))) | D9: =IF(N9="","",IF(INDEX(Posts!$G$1:$G$805,MOD(N9,1000))="",IF(INDEX(Posts!$E$1:$E$805,MOD(N9,1000))="","",INDEX(Posts!$E$1:$E$805,MOD(N9,1000))),INDEX(Posts!$G$1:$G$805,MOD(N9,1000)))) | E9: =IF(N9="","",IF(INDEX(Posts!$H$1:$H$805,MOD(N9,1000))="","",INDEX(Posts!$H$1:$H$805,MOD(N9,1000)))) | G9: =IF(Settings!$B$11="","",Settings!$B$11) | H9: =IF(G9="","",COUNTIFS(Posts!$D$6:$D$805,G9,Posts!$B$6:$B$805,">="&$M$1,Posts!$B$6:$B$805,"<"&($M$1+7))-COUNTIFS(Posts!$D$6:$D$805,G9,Posts!$B$6:$B$805,">="&$M$1,Posts!$B$6:$B$805,"<"&($M$1+7),Posts!$H$6:$H$805,"Idea")) | I9: =IF(G9="","",N(Settings!$D$11)) | J9: =IF(G9="","",IF(SUMIFS(Posts!$J$6:$J$805,Posts!$D$6:$D$805,G9,Posts!$H$6:$H$805,"Published",Posts!$T$6:$T$805,(YEAR(TODAY())*100+MONTH(TODAY())))=0,"",SUMIFS(Posts!$O$6:$O$805,Posts!$D$6:$D$805,G9,Posts!$H$6:$H$805,"Published",Posts!$T$6:$T$805,(YEAR(TODAY())*100+MONTH(TODAY())),Posts!$J$6:$J$805,">0")/SUMIFS(Posts!$J$6:$J$805,Posts!$D$6:$D$805,G9,Posts!$H$6:$H$805,"Published",Posts!$T$6:$T$805,(YEAR(TODAY())*100+MONTH(TODAY()))))) | N9: =IFERROR(SMALL(Posts!$U$6:$U$805,2),"")
B10: =IF(N10="","",INT(N10/10000000)) | C10: =IF(N10="","",IF(INDEX(Posts!$D$1:$D$805,MOD(N10,1000))="","",INDEX(Posts!$D$1:$D$805,MOD(N10,1000)))) | D10: =IF(N10="","",IF(INDEX(Posts!$G$1:$G$805,MOD(N10,1000))="",IF(INDEX(Posts!$E$1:$E$805,MOD(N10,1000))="","",INDEX(Posts!$E$1:$E$805,MOD(N10,1000))),INDEX(Posts!$G$1:$G$805,MOD(N10,1000)))) | E10: =IF(N10="","",IF(INDEX(Posts!$H$1:$H$805,MOD(N10,1000))="","",INDEX(Posts!$H$1:$H$805,MOD(N10,1000)))) | G10: =IF(Settings!$B$12="","",Settings!$B$12) | H10: =IF(G10="","",COUNTIFS(Posts!$D$6:$D$805,G10,Posts!$B$6:$B$805,">="&$M$1,Posts!$B$6:$B$805,"<"&($M$1+7))-COUNTIFS(Posts!$D$6:$D$805,G10,Posts!$B$6:$B$805,">="&$M$1,Posts!$B$6:$B$805,"<"&($M$1+7),Posts!$H$6:$H$805,"Idea")) | I10: =IF(G10="","",N(Settings!$D$12)) | J10: =IF(G10="","",IF(SUMIFS(Posts!$J$6:$J$805,Posts!$D$6:$D$805,G10,Posts!$H$6:$H$805,"Published",Posts!$T$6:$T$805,(YEAR(TODAY())*100+MONTH(TODAY())))=0,"",SUMIFS(Posts!$O$6:$O$805,Posts!$D$6:$D$805,G10,Posts!$H$6:$H$805,"Published",Posts!$T$6:$T$805,(YEAR(TODAY())*100+MONTH(TODAY())),Posts!$J$6:$J$805,">0")/SUMIFS(Posts!$J$6:$J$805,Posts!$D$6:$D$805,G10,Posts!$H$6:$H$805,"Published",Posts!$T$6:$T$805,(YEAR(TODAY())*100+MONTH(TODAY()))))) | N10: =IFERROR(SMALL(Posts!$U$6:$U$805,3),"")
B11: =IF(N11="","",INT(N11/10000000)) | C11: =IF(N11="","",IF(INDEX(Posts!$D$1:$D$805,MOD(N11,1000))="","",INDEX(Posts!$D$1:$D$805,MOD(N11,1000)))) | D11: =IF(N11="","",IF(INDEX(Posts!$G$1:$G$805,MOD(N11,1000))="",IF(INDEX(Posts!$E$1:$E$805,MOD(N11,1000))="","",INDEX(Posts!$E$1:$E$805,MOD(N11,1000))),INDEX(Posts!$G$1:$G$805,MOD(N11,1000)))) | E11: =IF(N11="","",IF(INDEX(Posts!$H$1:$H$805,MOD(N11,1000))="","",INDEX(Posts!$H$1:$H$805,MOD(N11,1000)))) | G11: =IF(Settings!$B$13="","",Settings!$B$13) | H11: =IF(G11="","",COUNTIFS(Posts!$D$6:$D$805,G11,Posts!$B$6:$B$805,">="&$M$1,Posts!$B$6:$B$805,"<"&($M$1+7))-COUNTIFS(Posts!$D$6:$D$805,G11,Posts!$B$6:$B$805,">="&$M$1,Posts!$B$6:$B$805,"<"&($M$1+7),Posts!$H$6:$H$805,"Idea")) | I11: =IF(G11="","",N(Settings!$D$13)) | J11: =IF(G11="","",IF(SUMIFS(Posts!$J$6:$J$805,Posts!$D$6:$D$805,G11,Posts!$H$6:$H$805,"Published",Posts!$T$6:$T$805,(YEAR(TODAY())*100+MONTH(TODAY())))=0,"",SUMIFS(Posts!$O$6:$O$805,Posts!$D$6:$D$805,G11,Posts!$H$6:$H$805,"Published",Posts!$T$6:$T$805,(YEAR(TODAY())*100+MONTH(TODAY())),Posts!$J$6:$J$805,">0")/SUMIFS(Posts!$J$6:$J$805,Posts!$D$6:$D$805,G11,Posts!$H$6:$H$805,"Published",Posts!$T$6:$T$805,(YEAR(TODAY())*100+MONTH(TODAY()))))) | N11: =IFERROR(SMALL(Posts!$U$6:$U$805,4),"")
B12: =IF(N12="","",INT(N12/10000000)) | C12: =IF(N12="","",IF(INDEX(Posts!$D$1:$D$805,MOD(N12,1000))="","",INDEX(Posts!$D$1:$D$805,MOD(N12,1000)))) | D12: =IF(N12="","",IF(INDEX(Posts!$G$1:$G$805,MOD(N12,1000))="",IF(INDEX(Posts!$E$1:$E$805,MOD(N12,1000))="","",INDEX(Posts!$E$1:$E$805,MOD(N12,1000))),INDEX(Posts!$G$1:$G$805,MOD(N12,1000)))) | E12: =IF(N12="","",IF(INDEX(Posts!$H$1:$H$805,MOD(N12,1000))="","",INDEX(Posts!$H$1:$H$805,MOD(N12,1000)))) | G12: =IF(Settings!$B$14="","",Settings!$B$14) | H12: =IF(G12="","",COUNTIFS(Posts!$D$6:$D$805,G12,Posts!$B$6:$B$805,">="&$M$1,Posts!$B$6:$B$805,"<"&($M$1+7))-COUNTIFS(Posts!$D$6:$D$805,G12,Posts!$B$6:$B$805,">="&$M$1,Posts!$B$6:$B$805,"<"&($M$1+7),Posts!$H$6:$H$805,"Idea")) | I12: =IF(G12="","",N(Settings!$D$14)) | J12: =IF(G12="","",IF(SUMIFS(Posts!$J$6:$J$805,Posts!$D$6:$D$805,G12,Posts!$H$6:$H$805,"Published",Posts!$T$6:$T$805,(YEAR(TODAY())*100+MONTH(TODAY())))=0,"",SUMIFS(Posts!$O$6:$O$805,Posts!$D$6:$D$805,G12,Posts!$H$6:$H$805,"Published",Posts!$T$6:$T$805,(YEAR(TODAY())*100+MONTH(TODAY())),Posts!$J$6:$J$805,">0")/SUMIFS(Posts!$J$6:$J$805,Posts!$D$6:$D$805,G12,Posts!$H$6:$H$805,"Published",Posts!$T$6:$T$805,(YEAR(TODAY())*100+MONTH(TODAY()))))) | N12: =IFERROR(SMALL(Posts!$U$6:$U$805,5),"")
B13: =IF(N13="","",INT(N13/10000000)) | C13: =IF(N13="","",IF(INDEX(Posts!$D$1:$D$805,MOD(N13,1000))="","",INDEX(Posts!$D$1:$D$805,MOD(N13,1000)))) | D13: =IF(N13="","",IF(INDEX(Posts!$G$1:$G$805,MOD(N13,1000))="",IF(INDEX(Posts!$E$1:$E$805,MOD(N13,1000))="","",INDEX(Posts!$E$1:$E$805,MOD(N13,1000))),INDEX(Posts!$G$1:$G$805,MOD(N13,1000)))) | E13: =IF(N13="","",IF(INDEX(Posts!$H$1:$H$805,MOD(N13,1000))="","",INDEX(Posts!$H$1:$H$805,MOD(N13,1000)))) | G13: =IF(Settings!$B$15="","",Settings!$B$15) | H13: =IF(G13="","",COUNTIFS(Posts!$D$6:$D$805,G13,Posts!$B$6:$B$805,">="&$M$1,Posts!$B$6:$B$805,"<"&($M$1+7))-COUNTIFS(Posts!$D$6:$D$805,G13,Posts!$B$6:$B$805,">="&$M$1,Posts!$B$6:$B$805,"<"&($M$1+7),Posts!$H$6:$H$805,"Idea")) | I13: =IF(G13="","",N(Settings!$D$15)) | J13: =IF(G13="","",IF(SUMIFS(Posts!$J$6:$J$805,Posts!$D$6:$D$805,G13,Posts!$H$6:$H$805,"Published",Posts!$T$6:$T$805,(YEAR(TODAY())*100+MONTH(TODAY())))=0,"",SUMIFS(Posts!$O$6:$O$805,Posts!$D$6:$D$805,G13,Posts!$H$6:$H$805,"Published",Posts!$T$6:$T$805,(YEAR(TODAY())*100+MONTH(TODAY())),Posts!$J$6:$J$805,">0")/SUMIFS(Posts!$J$6:$J$805,Posts!$D$6:$D$805,G13,Posts!$H$6:$H$805,"Published",Posts!$T$6:$T$805,(YEAR(TODAY())*100+MONTH(TODAY()))))) | N13: =IFERROR(SMALL(Posts!$U$6:$U$805,6),"")
B14: =IF(N14="","",INT(N14/10000000)) | C14: =IF(N14="","",IF(INDEX(Posts!$D$1:$D$805,MOD(N14,1000))="","",INDEX(Posts!$D$1:$D$805,MOD(N14,1000)))) | D14: =IF(N14="","",IF(INDEX(Posts!$G$1:$G$805,MOD(N14,1000))="",IF(INDEX(Posts!$E$1:$E$805,MOD(N14,1000))="","",INDEX(Posts!$E$1:$E$805,MOD(N14,1000))),INDEX(Posts!$G$1:$G$805,MOD(N14,1000)))) | E14: =IF(N14="","",IF(INDEX(Posts!$H$1:$H$805,MOD(N14,1000))="","",INDEX(Posts!$H$1:$H$805,MOD(N14,1000)))) | G14: =IF(Settings!$B$16="","",Settings!$B$16) | H14: =IF(G14="","",COUNTIFS(Posts!$D$6:$D$805,G14,Posts!$B$6:$B$805,">="&$M$1,Posts!$B$6:$B$805,"<"&($M$1+7))-COUNTIFS(Posts!$D$6:$D$805,G14,Posts!$B$6:$B$805,">="&$M$1,Posts!$B$6:$B$805,"<"&($M$1+7),Posts!$H$6:$H$805,"Idea")) | I14: =IF(G14="","",N(Settings!$D$16)) | J14: =IF(G14="","",IF(SUMIFS(Posts!$J$6:$J$805,Posts!$D$6:$D$805,G14,Posts!$H$6:$H$805,"Published",Posts!$T$6:$T$805,(YEAR(TODAY())*100+MONTH(TODAY())))=0,"",SUMIFS(Posts!$O$6:$O$805,Posts!$D$6:$D$805,G14,Posts!$H$6:$H$805,"Published",Posts!$T$6:$T$805,(YEAR(TODAY())*100+MONTH(TODAY())),Posts!$J$6:$J$805,">0")/SUMIFS(Posts!$J$6:$J$805,Posts!$D$6:$D$805,G14,Posts!$H$6:$H$805,"Published",Posts!$T$6:$T$805,(YEAR(TODAY())*100+MONTH(TODAY()))))) | N14: =IFERROR(SMALL(Posts!$U$6:$U$805,7),"")
B15: =IF(N15="","",INT(N15/10000000)) | C15: =IF(N15="","",IF(INDEX(Posts!$D$1:$D$805,MOD(N15,1000))="","",INDEX(Posts!$D$1:$D$805,MOD(N15,1000)))) | D15: =IF(N15="","",IF(INDEX(Posts!$G$1:$G$805,MOD(N15,1000))="",IF(INDEX(Posts!$E$1:$E$805,MOD(N15,1000))="","",INDEX(Posts!$E$1:$E$805,MOD(N15,1000))),INDEX(Posts!$G$1:$G$805,MOD(N15,1000)))) | E15: =IF(N15="","",IF(INDEX(Posts!$H$1:$H$805,MOD(N15,1000))="","",INDEX(Posts!$H$1:$H$805,MOD(N15,1000)))) | G15: =IF(Settings!$B$17="","",Settings!$B$17) | H15: =IF(G15="","",COUNTIFS(Posts!$D$6:$D$805,G15,Posts!$B$6:$B$805,">="&$M$1,Posts!$B$6:$B$805,"<"&($M$1+7))-COUNTIFS(Posts!$D$6:$D$805,G15,Posts!$B$6:$B$805,">="&$M$1,Posts!$B$6:$B$805,"<"&($M$1+7),Posts!$H$6:$H$805,"Idea")) | I15: =IF(G15="","",N(Settings!$D$17)) | J15: =IF(G15="","",IF(SUMIFS(Posts!$J$6:$J$805,Posts!$D$6:$D$805,G15,Posts!$H$6:$H$805,"Published",Posts!$T$6:$T$805,(YEAR(TODAY())*100+MONTH(TODAY())))=0,"",SUMIFS(Posts!$O$6:$O$805,Posts!$D$6:$D$805,G15,Posts!$H$6:$H$805,"Published",Posts!$T$6:$T$805,(YEAR(TODAY())*100+MONTH(TODAY())),Posts!$J$6:$J$805,">0")/SUMIFS(Posts!$J$6:$J$805,Posts!$D$6:$D$805,G15,Posts!$H$6:$H$805,"Published",Posts!$T$6:$T$805,(YEAR(TODAY())*100+MONTH(TODAY()))))) | N15: =IFERROR(SMALL(Posts!$U$6:$U$805,8),"")
B16: =IF(N16="","",INT(N16/10000000)) | C16: =IF(N16="","",IF(INDEX(Posts!$D$1:$D$805,MOD(N16,1000))="","",INDEX(Posts!$D$1:$D$805,MOD(N16,1000)))) | D16: =IF(N16="","",IF(INDEX(Posts!$G$1:$G$805,MOD(N16,1000))="",IF(INDEX(Posts!$E$1:$E$805,MOD(N16,1000))="","",INDEX(Posts!$E$1:$E$805,MOD(N16,1000))),INDEX(Posts!$G$1:$G$805,MOD(N16,1000)))) | E16: =IF(N16="","",IF(INDEX(Posts!$H$1:$H$805,MOD(N16,1000))="","",INDEX(Posts!$H$1:$H$805,MOD(N16,1000)))) | N16: =IFERROR(SMALL(Posts!$U$6:$U$805,9),"")
B17: =IF(N17="","",INT(N17/10000000)) | C17: =IF(N17="","",IF(INDEX(Posts!$D$1:$D$805,MOD(N17,1000))="","",INDEX(Posts!$D$1:$D$805,MOD(N17,1000)))) | D17: =IF(N17="","",IF(INDEX(Posts!$G$1:$G$805,MOD(N17,1000))="",IF(INDEX(Posts!$E$1:$E$805,MOD(N17,1000))="","",INDEX(Posts!$E$1:$E$805,MOD(N17,1000))),INDEX(Posts!$G$1:$G$805,MOD(N17,1000)))) | E17: =IF(N17="","",IF(INDEX(Posts!$H$1:$H$805,MOD(N17,1000))="","",INDEX(Posts!$H$1:$H$805,MOD(N17,1000)))) | N17: =IFERROR(SMALL(Posts!$U$6:$U$805,10),"")
B19: Week of | C19: Published | D19: Reach | G19: Best this month | H19: Platform | I19: Interactions | J19: Rate
B20: =($M$1-49) | C20: =COUNTIFS(Posts!$S$6:$S$805,B20,Posts!$H$6:$H$805,"Published") | D20: =SUMIFS(Posts!$J$6:$J$805,Posts!$S$6:$S$805,B20,Posts!$H$6:$H$805,"Published") | G20: =IF(O20="","",IF(INDEX(Posts!$G$1:$G$805,1000-MOD(O20,1000))="",IF(INDEX(Posts!$E$1:$E$805,1000-MOD(O20,1000))="","",INDEX(Posts!$E$1:$E$805,1000-MOD(O20,1000))),INDEX(Posts!$G$1:$G$805,1000-MOD(O20,1000)))) | H20: =IF(O20="","",IF(INDEX(Posts!$D$1:$D$805,1000-MOD(O20,1000))="","",INDEX(Posts!$D$1:$D$805,1000-MOD(O20,1000)))) | I20: =IF(O20="","",INDEX(Posts!$O$1:$O$805,1000-MOD(O20,1000))) | J20: =IF(O20="","",IF(INDEX(Posts!$P$1:$P$805,1000-MOD(O20,1000))="","",INDEX(Posts!$P$1:$P$805,1000-MOD(O20,1000)))) | O20: =IFERROR(LARGE(Posts!$W$6:$W$805,1),"")
B21: =($M$1-42) | C21: =COUNTIFS(Posts!$S$6:$S$805,B21,Posts!$H$6:$H$805,"Published") | D21: =SUMIFS(Posts!$J$6:$J$805,Posts!$S$6:$S$805,B21,Posts!$H$6:$H$805,"Published") | G21: =IF(O21="","",IF(INDEX(Posts!$G$1:$G$805,1000-MOD(O21,1000))="",IF(INDEX(Posts!$E$1:$E$805,1000-MOD(O21,1000))="","",INDEX(Posts!$E$1:$E$805,1000-MOD(O21,1000))),INDEX(Posts!$G$1:$G$805,1000-MOD(O21,1000)))) | H21: =IF(O21="","",IF(INDEX(Posts!$D$1:$D$805,1000-MOD(O21,1000))="","",INDEX(Posts!$D$1:$D$805,1000-MOD(O21,1000)))) | I21: =IF(O21="","",INDEX(Posts!$O$1:$O$805,1000-MOD(O21,1000))) | J21: =IF(O21="","",IF(INDEX(Posts!$P$1:$P$805,1000-MOD(O21,1000))="","",INDEX(Posts!$P$1:$P$805,1000-MOD(O21,1000)))) | O21: =IFERROR(LARGE(Posts!$W$6:$W$805,2),"")
B22: =($M$1-35) | C22: =COUNTIFS(Posts!$S$6:$S$805,B22,Posts!$H$6:$H$805,"Published") | D22: =SUMIFS(Posts!$J$6:$J$805,Posts!$S$6:$S$805,B22,Posts!$H$6:$H$805,"Published") | G22: =IF(O22="","",IF(INDEX(Posts!$G$1:$G$805,1000-MOD(O22,1000))="",IF(INDEX(Posts!$E$1:$E$805,1000-MOD(O22,1000))="","",INDEX(Posts!$E$1:$E$805,1000-MOD(O22,1000))),INDEX(Posts!$G$1:$G$805,1000-MOD(O22,1000)))) | H22: =IF(O22="","",IF(INDEX(Posts!$D$1:$D$805,1000-MOD(O22,1000))="","",INDEX(Posts!$D$1:$D$805,1000-MOD(O22,1000)))) | I22: =IF(O22="","",INDEX(Posts!$O$1:$O$805,1000-MOD(O22,1000))) | J22: =IF(O22="","",IF(INDEX(Posts!$P$1:$P$805,1000-MOD(O22,1000))="","",INDEX(Posts!$P$1:$P$805,1000-MOD(O22,1000)))) | O22: =IFERROR(LARGE(Posts!$W$6:$W$805,3),"")
B23: =($M$1-28) | C23: =COUNTIFS(Posts!$S$6:$S$805,B23,Posts!$H$6:$H$805,"Published") | D23: =SUMIFS(Posts!$J$6:$J$805,Posts!$S$6:$S$805,B23,Posts!$H$6:$H$805,"Published") | G23: =IF(O23="","",IF(INDEX(Posts!$G$1:$G$805,1000-MOD(O23,1000))="",IF(INDEX(Posts!$E$1:$E$805,1000-MOD(O23,1000))="","",INDEX(Posts!$E$1:$E$805,1000-MOD(O23,1000))),INDEX(Posts!$G$1:$G$805,1000-MOD(O23,1000)))) | H23: =IF(O23="","",IF(INDEX(Posts!$D$1:$D$805,1000-MOD(O23,1000))="","",INDEX(Posts!$D$1:$D$805,1000-MOD(O23,1000)))) | I23: =IF(O23="","",INDEX(Posts!$O$1:$O$805,1000-MOD(O23,1000))) | J23: =IF(O23="","",IF(INDEX(Posts!$P$1:$P$805,1000-MOD(O23,1000))="","",INDEX(Posts!$P$1:$P$805,1000-MOD(O23,1000)))) | O23: =IFERROR(LARGE(Posts!$W$6:$W$805,4),"")
B24: =($M$1-21) | C24: =COUNTIFS(Posts!$S$6:$S$805,B24,Posts!$H$6:$H$805,"Published") | D24: =SUMIFS(Posts!$J$6:$J$805,Posts!$S$6:$S$805,B24,Posts!$H$6:$H$805,"Published") | G24: =IF(O24="","",IF(INDEX(Posts!$G$1:$G$805,1000-MOD(O24,1000))="",IF(INDEX(Posts!$E$1:$E$805,1000-MOD(O24,1000))="","",INDEX(Posts!$E$1:$E$805,1000-MOD(O24,1000))),INDEX(Posts!$G$1:$G$805,1000-MOD(O24,1000)))) | H24: =IF(O24="","",IF(INDEX(Posts!$D$1:$D$805,1000-MOD(O24,1000))="","",INDEX(Posts!$D$1:$D$805,1000-MOD(O24,1000)))) | I24: =IF(O24="","",INDEX(Posts!$O$1:$O$805,1000-MOD(O24,1000))) | J24: =IF(O24="","",IF(INDEX(Posts!$P$1:$P$805,1000-MOD(O24,1000))="","",INDEX(Posts!$P$1:$P$805,1000-MOD(O24,1000)))) | O24: =IFERROR(LARGE(Posts!$W$6:$W$805,5),"")
B25: =($M$1-14) | C25: =COUNTIFS(Posts!$S$6:$S$805,B25,Posts!$H$6:$H$805,"Published") | D25: =SUMIFS(Posts!$J$6:$J$805,Posts!$S$6:$S$805,B25,Posts!$H$6:$H$805,"Published")
B26: =($M$1-7) | C26: =COUNTIFS(Posts!$S$6:$S$805,B26,Posts!$H$6:$H$805,"Published") | D26: =SUMIFS(Posts!$J$6:$J$805,Posts!$S$6:$S$805,B26,Posts!$H$6:$H$805,"Published")
B27: =($M$1-0) | C27: =COUNTIFS(Posts!$S$6:$S$805,B27,Posts!$H$6:$H$805,"Published") | D27: =SUMIFS(Posts!$J$6:$J$805,Posts!$S$6:$S$805,B27,Posts!$H$6:$H$805,"Published")

Sheet Calendar
AL1: =(Settings!$C$5-WEEKDAY(Settings!$C$5,3))
B2: =CHOOSE(MONTH(Settings!$C$5),"January","February","March","April","May","June","July","August","September","October","November","December")&" "&YEAR(Settings!$C$5)
B3: The posts planned for each day, with the short name of the platform. Settings shows another month.
B5: Monday | C5: Tuesday | D5: Wednesday | E5: Thursday | F5: Friday | G5: Saturday | H5: Sunday
B6: =IF(MONTH(((Settings!$C$5-WEEKDAY(Settings!$C$5,3))+0))<>MONTH(Settings!$C$5),"",DAY(((Settings!$C$5-WEEKDAY(Settings!$C$5,3))+0))&IF(J6="","",CHAR(10)&IF(IFERROR(INDEX(Settings!$C$10:$C$17,MATCH(INDEX(Posts!$D$1:$D$805,J6),Settings!$B$10:$B$17,0)),"")="",INDEX(Posts!$D$1:$D$805,J6),IFERROR(INDEX(Settings!$C$10:$C$17,MATCH(INDEX(Posts!$D$1:$D$805,J6),Settings!$B$10:$B$17,0)),""))&": "&IF(INDEX(Posts!$G$1:$G$805,J6)="",INDEX(Posts!$E$1:$E$805,J6),INDEX(Posts!$G$1:$G$805,J6)))&IF(K6="","",CHAR(10)&IF(IFERROR(INDEX(Settings!$C$10:$C$17,MATCH(INDEX(Posts!$D$1:$D$805,K6),Settings!$B$10:$B$17,0)),"")="",INDEX(Posts!$D$1:$D$805,K6),IFERROR(INDEX(Settings!$C$10:$C$17,MATCH(INDEX(Posts!$D$1:$D$805,K6),Settings!$B$10:$B$17,0)),""))&": "&IF(INDEX(Posts!$G$1:$G$805,K6)="",INDEX(Posts!$E$1:$E$805,K6),INDEX(Posts!$G$1:$G$805,K6)))&IF(L6="","",CHAR(10)&IF(IFERROR(INDEX(Settings!$C$10:$C$17,MATCH(INDEX(Posts!$D$1:$D$805,L6),Settings!$B$10:$B$17,0)),"")="",INDEX(Posts!$D$1:$D$805,L6),IFERROR(INDEX(Settings!$C$10:$C$17,MATCH(INDEX(Posts!$D$1:$D$805,L6),Settings!$B$10:$B$17,0)),""))&": "&IF(INDEX(Posts!$G$1:$G$805,L6)="",INDEX(Posts!$E$1:$E$805,L6),INDEX(Posts!$G$1:$G$805,L6)))&IF(M6>3,CHAR(10)&"and "&(M6-3)&" more","")) | C6: =IF(MONTH(((Settings!$C$5-WEEKDAY(Settings!$C$5,3))+1))<>MONTH(Settings!$C$5),"",DAY(((Settings!$C$5-WEEKDAY(Settings!$C$5,3))+1))&IF(N6="","",CHAR(10)&IF(IFERROR(INDEX(Settings!$C$10:$C$17,MATCH(INDEX(Posts!$D$1:$D$805,N6),Settings!$B$10:$B$17,0)),"")="",INDEX(Posts!$D$1:$D$805,N6),IFERROR(INDEX(Settings!$C$10:$C$17,MATCH(INDEX(Posts!$D$1:$D$805,N6),Settings!$B$10:$B$17,0)),""))&": "&IF(INDEX(Posts!$G$1:$G$805,N6)="",INDEX(Posts!$E$1:$E$805,N6),INDEX(Posts!$G$1:$G$805,N6)))&IF(O6="","",CHAR(10)&IF(IFERROR(INDEX(Settings!$C$10:$C$17,MATCH(INDEX(Posts!$D$1:$D$805,O6),Settings!$B$10:$B$17,0)),"")="",INDEX(Posts!$D$1:$D$805,O6),IFERROR(INDEX(Settings!$C$10:$C$17,MATCH(INDEX(Posts!$D$1:$D$805,O6),Settings!$B$10:$B$17,0)),""))&": "&IF(INDEX(Posts!$G$1:$G$805,O6)="",INDEX(Posts!$E$1:$E$805,O6),INDEX(Posts!$G$1:$G$805,O6)))&IF(P6="","",CHAR(10)&IF(IFERROR(INDEX(Settings!$C$10:$C$17,MATCH(INDEX(Posts!$D$1:$D$805,P6),Settings!$B$10:$B$17,0)),"")="",INDEX(Posts!$D$1:$D$805,P6),IFERROR(INDEX(Settings!$C$10:$C$17,MATCH(INDEX(Posts!$D$1:$D$805,P6),Settings!$B$10:$B$17,0)),""))&": "&IF(INDEX(Posts!$G$1:$G$805,P6)="",INDEX(Posts!$E$1:$E$805,P6),INDEX(Posts!$G$1:$G$805,P6)))&IF(Q6>3,CHAR(10)&"and "&(Q6-3)&" more","")) | D6: =IF(MONTH(((Settings!$C$5-WEEKDAY(Settings!$C$5,3))+2))<>MONTH(Settings!$C$5),"",DAY(((Settings!$C$5-WEEKDAY(Settings!$C$5,3))+2))&IF(R6="","",CHAR(10)&IF(IFERROR(INDEX(Settings!$C$10:$C$17,MATCH(INDEX(Posts!$D$1:$D$805,R6),Settings!$B$10:$B$17,0)),"")="",INDEX(Posts!$D$1:$D$805,R6),IFERROR(INDEX(Settings!$C$10:$C$17,MATCH(INDEX(Posts!$D$1:$D$805,R6),Settings!$B$10:$B$17,0)),""))&": "&IF(INDEX(Posts!$G$1:$G$805,R6)="",INDEX(Posts!$E$1:$E$805,R6),INDEX(Posts!$G$1:$G$805,R6)))&IF(S6="","",CHAR(10)&IF(IFERROR(INDEX(Settings!$C$10:$C$17,MATCH(INDEX(Posts!$D$1:$D$805,S6),Settings!$B$10:$B$17,0)),"")="",INDEX(Posts!$D$1:$D$805,S6),IFERROR(INDEX(Settings!$C$10:$C$17,MATCH(INDEX(Posts!$D$1:$D$805,S6),Settings!$B$10:$B$17,0)),""))&": "&IF(INDEX(Posts!$G$1:$G$805,S6)="",INDEX(Posts!$E$1:$E$805,S6),INDEX(Posts!$G$1:$G$805,S6)))&IF(T6="","",CHAR(10)&IF(IFERROR(INDEX(Settings!$C$10:$C$17,MATCH(INDEX(Posts!$D$1:$D$805,T6),Settings!$B$10:$B$17,0)),"")="",INDEX(Posts!$D$1:$D$805,T6),IFERROR(INDEX(Settings!$C$10:$C$17,MATCH(INDEX(Posts!$D$1:$D$805,T6),Settings!$B$10:$B$17,0)),""))&": "&IF(INDEX(Posts!$G$1:$G$805,T6)="",INDEX(Posts!$E$1:$E$805,T6),INDEX(Posts!$G$1:$G$805,T6)))&IF(U6>3,CHAR(10)&"and "&(U6-3)&" more","")) | E6: =IF(MONTH(((Settings!$C$5-WEEKDAY(Settings!$C$5,3))+3))<>MONTH(Settings!$C$5),"",DAY(((Settings!$C$5-WEEKDAY(Settings!$C$5,3))+3))&IF(V6="","",CHAR(10)&IF(IFERROR(INDEX(Settings!$C$10:$C$17,MATCH(INDEX(Posts!$D$1:$D$805,V6),Settings!$B$10:$B$17,0)),"")="",INDEX(Posts!$D$1:$D$805,V6),IFERROR(INDEX(Settings!$C$10:$C$17,MATCH(INDEX(Posts!$D$1:$D$805,V6),Settings!$B$10:$B$17,0)),""))&": "&IF(INDEX(Posts!$G$1:$G$805,V6)="",INDEX(Posts!$E$1:$E$805,V6),INDEX(Posts!$G$1:$G$805,V6)))&IF(W6="","",CHAR(10)&IF(IFERROR(INDEX(Settings!$C$10:$C$17,MATCH(INDEX(Posts!$D$1:$D$805,W6),Settings!$B$10:$B$17,0)),"")="",INDEX(Posts!$D$1:$D$805,W6),IFERROR(INDEX(Settings!$C$10:$C$17,MATCH(INDEX(Posts!$D$1:$D$805,W6),Settings!$B$10:$B$17,0)),""))&": "&IF(INDEX(Posts!$G$1:$G$805,W6)="",INDEX(Posts!$E$1:$E$805,W6),INDEX(Posts!$G$1:$G$805,W6)))&IF(X6="","",CHAR(10)&IF(IFERROR(INDEX(Settings!$C$10:$C$17,MATCH(INDEX(Posts!$D$1:$D$805,X6),Settings!$B$10:$B$17,0)),"")="",INDEX(Posts!$D$1:$D$805,X6),IFERROR(INDEX(Settings!$C$10:$C$17,MATCH(INDEX(Posts!$D$1:$D$805,X6),Settings!$B$10:$B$17,0)),""))&": "&IF(INDEX(Posts!$G$1:$G$805,X6)="",INDEX(Posts!$E$1:$E$805,X6),INDEX(Posts!$G$1:$G$805,X6)))&IF(Y6>3,CHAR(10)&"and "&(Y6-3)&" more","")) | F6: =IF(MONTH(((Settings!$C$5-WEEKDAY(Settings!$C$5,3))+4))<>MONTH(Settings!$C$5),"",DAY(((Settings!$C$5-WEEKDAY(Settings!$C$5,3))+4))&IF(Z6="","",CHAR(10)&IF(IFERROR(INDEX(Settings!$C$10:$C$17,MATCH(INDEX(Posts!$D$1:$D$805,Z6),Settings!$B$10:$B$17,0)),"")="",INDEX(Posts!$D$1:$D$805,Z6),IFERROR(INDEX(Settings!$C$10:$C$17,MATCH(INDEX(Posts!$D$1:$D$805,Z6),Settings!$B$10:$B$17,0)),""))&": "&IF(INDEX(Posts!$G$1:$G$805,Z6)="",INDEX(Posts!$E$1:$E$805,Z6),INDEX(Posts!$G$1:$G$805,Z6)))&IF(AA6="","",CHAR(10)&IF(IFERROR(INDEX(Settings!$C$10:$C$17,MATCH(INDEX(Posts!$D$1:$D$805,AA6),Settings!$B$10:$B$17,0)),"")="",INDEX(Posts!$D$1:$D$805,AA6),IFERROR(INDEX(Settings!$C$10:$C$17,MATCH(INDEX(Posts!$D$1:$D$805,AA6),Settings!$B$10:$B$17,0)),""))&": "&IF(INDEX(Posts!$G$1:$G$805,AA6)="",INDEX(Posts!$E$1:$E$805,AA6),INDEX(Posts!$G$1:$G$805,AA6)))&IF(AB6="","",CHAR(10)&IF(IFERROR(INDEX(Settings!$C$10:$C$17,MATCH(INDEX(Posts!$D$1:$D$805,AB6),Settings!$B$10:$B$17,0)),"")="",INDEX(Posts!$D$1:$D$805,AB6),IFERROR(INDEX(Settings!$C$10:$C$17,MATCH(INDEX(Posts!$D$1:$D$805,AB6),Settings!$B$10:$B$17,0)),""))&": "&IF(INDEX(Posts!$G$1:$G$805,AB6)="",INDEX(Posts!$E$1:$E$805,AB6),INDEX(Posts!$G$1:$G$805,AB6)))&IF(AC6>3,CHAR(10)&"and "&(AC6-3)&" more","")) | G6: =IF(MONTH(((Settings!$C$5-WEEKDAY(Settings!$C$5,3))+5))<>MONTH(Settings!$C$5),"",DAY(((Settings!$C$5-WEEKDAY(Settings!$C$5,3))+5))&IF(AD6="","",CHAR(10)&IF(IFERROR(INDEX(Settings!$C$10:$C$17,MATCH(INDEX(Posts!$D$1:$D$805,AD6),Settings!$B$10:$B$17,0)),"")="",INDEX(Posts!$D$1:$D$805,AD6),IFERROR(INDEX(Settings!$C$10:$C$17,MATCH(INDEX(Posts!$D$1:$D$805,AD6),Settings!$B$10:$B$17,0)),""))&": "&IF(INDEX(Posts!$G$1:$G$805,AD6)="",INDEX(Posts!$E$1:$E$805,AD6),INDEX(Posts!$G$1:$G$805,AD6)))&IF(AE6="","",CHAR(10)&IF(IFERROR(INDEX(Settings!$C$10:$C$17,MATCH(INDEX(Posts!$D$1:$D$805,AE6),Settings!$B$10:$B$17,0)),"")="",INDEX(Posts!$D$1:$D$805,AE6),IFERROR(INDEX(Settings!$C$10:$C$17,MATCH(INDEX(Posts!$D$1:$D$805,AE6),Settings!$B$10:$B$17,0)),""))&": "&IF(INDEX(Posts!$G$1:$G$805,AE6)="",INDEX(Posts!$E$1:$E$805,AE6),INDEX(Posts!$G$1:$G$805,AE6)))&IF(AF6="","",CHAR(10)&IF(IFERROR(INDEX(Settings!$C$10:$C$17,MATCH(INDEX(Posts!$D$1:$D$805,AF6),Settings!$B$10:$B$17,0)),"")="",INDEX(Posts!$D$1:$D$805,AF6),IFERROR(INDEX(Settings!$C$10:$C$17,MATCH(INDEX(Posts!$D$1:$D$805,AF6),Settings!$B$10:$B$17,0)),""))&": "&IF(INDEX(Posts!$G$1:$G$805,AF6)="",INDEX(Posts!$E$1:$E$805,AF6),INDEX(Posts!$G$1:$G$805,AF6)))&IF(AG6>3,CHAR(10)&"and "&(AG6-3)&" more","")) | H6: =IF(MONTH(((Settings!$C$5-WEEKDAY(Settings!$C$5,3))+6))<>MONTH(Settings!$C$5),"",DAY(((Settings!$C$5-WEEKDAY(Settings!$C$5,3))+6))&IF(AH6="","",CHAR(10)&IF(IFERROR(INDEX(Settings!$C$10:$C$17,MATCH(INDEX(Posts!$D$1:$D$805,AH6),Settings!$B$10:$B$17,0)),"")="",INDEX(Posts!$D$1:$D$805,AH6),IFERROR(INDEX(Settings!$C$10:$C$17,MATCH(INDEX(Posts!$D$1:$D$805,AH6),Settings!$B$10:$B$17,0)),""))&": "&IF(INDEX(Posts!$G$1:$G$805,AH6)="",INDEX(Posts!$E$1:$E$805,AH6),INDEX(Posts!$G$1:$G$805,AH6)))&IF(AI6="","",CHAR(10)&IF(IFERROR(INDEX(Settings!$C$10:$C$17,MATCH(INDEX(Posts!$D$1:$D$805,AI6),Settings!$B$10:$B$17,0)),"")="",INDEX(Posts!$D$1:$D$805,AI6),IFERROR(INDEX(Settings!$C$10:$C$17,MATCH(INDEX(Posts!$D$1:$D$805,AI6),Settings!$B$10:$B$17,0)),""))&": "&IF(INDEX(Posts!$G$1:$G$805,AI6)="",INDEX(Posts!$E$1:$E$805,AI6),INDEX(Posts!$G$1:$G$805,AI6)))&IF(AJ6="","",CHAR(10)&IF(IFERROR(INDEX(Settings!$C$10:$C$17,MATCH(INDEX(Posts!$D$1:$D$805,AJ6),Settings!$B$10:$B$17,0)),"")="",INDEX(Posts!$D$1:$D$805,AJ6),IFERROR(INDEX(Settings!$C$10:$C$17,MATCH(INDEX(Posts!$D$1:$D$805,AJ6),Settings!$B$10:$B$17,0)),""))&": "&IF(INDEX(Posts!$G$1:$G$805,AJ6)="",INDEX(Posts!$E$1:$E$805,AJ6),INDEX(Posts!$G$1:$G$805,AJ6)))&IF(AK6>3,CHAR(10)&"and "&(AK6-3)&" more","")) | J6: =IFERROR(IF(INT(SMALL(Posts!$R$6:$R$805,COUNTIF(Posts!$R$6:$R$805,"<"&((Settings!$C$5-WEEKDAY(Settings!$C$5,3))+0)*10000000)+1)/10000000)=((Settings!$C$5-WEEKDAY(Settings!$C$5,3))+0),MOD(SMALL(Posts!$R$6:$R$805,COUNTIF(Posts!$R$6:$R$805,"<"&((Settings!$C$5-WEEKDAY(Settings!$C$5,3))+0)*10000000)+1),1000),""),"") | K6: =IFERROR(IF(INT(SMALL(Posts!$R$6:$R$805,COUNTIF(Posts!$R$6:$R$805,"<"&((Settings!$C$5-WEEKDAY(Settings!$C$5,3))+0)*10000000)+2)/10000000)=((Settings!$C$5-WEEKDAY(Settings!$C$5,3))+0),MOD(SMALL(Posts!$R$6:$R$805,COUNTIF(Posts!$R$6:$R$805,"<"&((Settings!$C$5-WEEKDAY(Settings!$C$5,3))+0)*10000000)+2),1000),""),"") | L6: =IFERROR(IF(INT(SMALL(Posts!$R$6:$R$805,COUNTIF(Posts!$R$6:$R$805,"<"&((Settings!$C$5-WEEKDAY(Settings!$C$5,3))+0)*10000000)+3)/10000000)=((Settings!$C$5-WEEKDAY(Settings!$C$5,3))+0),MOD(SMALL(Posts!$R$6:$R$805,COUNTIF(Posts!$R$6:$R$805,"<"&((Settings!$C$5-WEEKDAY(Settings!$C$5,3))+0)*10000000)+3),1000),""),"") | M6: =COUNTIFS(Posts!$R$6:$R$805,">="&((Settings!$C$5-WEEKDAY(Settings!$C$5,3))+0)*10000000,Posts!$R$6:$R$805,"<"&(((Settings!$C$5-WEEKDAY(Settings!$C$5,3))+0)+1)*10000000) | N6: =IFERROR(IF(INT(SMALL(Posts!$R$6:$R$805,COUNTIF(Posts!$R$6:$R$805,"<"&((Settings!$C$5-WEEKDAY(Settings!$C$5,3))+1)*10000000)+1)/10000000)=((Settings!$C$5-WEEKDAY(Settings!$C$5,3))+1),MOD(SMALL(Posts!$R$6:$R$805,COUNTIF(Posts!$R$6:$R$805,"<"&((Settings!$C$5-WEEKDAY(Settings!$C$5,3))+1)*10000000)+1),1000),""),"") | O6: =IFERROR(IF(INT(SMALL(Posts!$R$6:$R$805,COUNTIF(Posts!$R$6:$R$805,"<"&((Settings!$C$5-WEEKDAY(Settings!$C$5,3))+1)*10000000)+2)/10000000)=((Settings!$C$5-WEEKDAY(Settings!$C$5,3))+1),MOD(SMALL(Posts!$R$6:$R$805,COUNTIF(Posts!$R$6:$R$805,"<"&((Settings!$C$5-WEEKDAY(Settings!$C$5,3))+1)*10000000)+2),1000),""),"") | P6: =IFERROR(IF(INT(SMALL(Posts!$R$6:$R$805,COUNTIF(Posts!$R$6:$R$805,"<"&((Settings!$C$5-WEEKDAY(Settings!$C$5,3))+1)*10000000)+3)/10000000)=((Settings!$C$5-WEEKDAY(Settings!$C$5,3))+1),MOD(SMALL(Posts!$R$6:$R$805,COUNTIF(Posts!$R$6:$R$805,"<"&((Settings!$C$5-WEEKDAY(Settings!$C$5,3))+1)*10000000)+3),1000),""),"") | Q6: =COUNTIFS(Posts!$R$6:$R$805,">="&((Settings!$C$5-WEEKDAY(Settings!$C$5,3))+1)*10000000,Posts!$R$6:$R$805,"<"&(((Settings!$C$5-WEEKDAY(Settings!$C$5,3))+1)+1)*10000000) | R6: =IFERROR(IF(INT(SMALL(Posts!$R$6:$R$805,COUNTIF(Posts!$R$6:$R$805,"<"&((Settings!$C$5-WEEKDAY(Settings!$C$5,3))+2)*10000000)+1)/10000000)=((Settings!$C$5-WEEKDAY(Settings!$C$5,3))+2),MOD(SMALL(Posts!$R$6:$R$805,COUNTIF(Posts!$R$6:$R$805,"<"&((Settings!$C$5-WEEKDAY(Settings!$C$5,3))+2)*10000000)+1),1000),""),"") | S6: =IFERROR(IF(INT(SMALL(Posts!$R$6:$R$805,COUNTIF(Posts!$R$6:$R$805,"<"&((Settings!$C$5-WEEKDAY(Settings!$C$5,3))+2)*10000000)+2)/10000000)=((Settings!$C$5-WEEKDAY(Settings!$C$5,3))+2),MOD(SMALL(Posts!$R$6:$R$805,COUNTIF(Posts!$R$6:$R$805,"<"&((Settings!$C$5-WEEKDAY(Settings!$C$5,3))+2)*10000000)+2),1000),""),"") | T6: =IFERROR(IF(INT(SMALL(Posts!$R$6:$R$805,COUNTIF(Posts!$R$6:$R$805,"<"&((Settings!$C$5-WEEKDAY(Settings!$C$5,3))+2)*10000000)+3)/10000000)=((Settings!$C$5-WEEKDAY(Settings!$C$5,3))+2),MOD(SMALL(Posts!$R$6:$R$805,COUNTIF(Posts!$R$6:$R$805,"<"&((Settings!$C$5-WEEKDAY(Settings!$C$5,3))+2)*10000000)+3),1000),""),"") | U6: =COUNTIFS(Posts!$R$6:$R$805,">="&((Settings!$C$5-WEEKDAY(Settings!$C$5,3))+2)*10000000,Posts!$R$6:$R$805,"<"&(((Settings!$C$5-WEEKDAY(Settings!$C$5,3))+2)+1)*10000000) | V6: =IFERROR(IF(INT(SMALL(Posts!$R$6:$R$805,COUNTIF(Posts!$R$6:$R$805,"<"&((Settings!$C$5-WEEKDAY(Settings!$C$5,3))+3)*10000000)+1)/10000000)=((Settings!$C$5-WEEKDAY(Settings!$C$5,3))+3),MOD(SMALL(Posts!$R$6:$R$805,COUNTIF(Posts!$R$6:$R$805,"<"&((Settings!$C$5-WEEKDAY(Settings!$C$5,3))+3)*10000000)+1),1000),""),"") | W6: =IFERROR(IF(INT(SMALL(Posts!$R$6:$R$805,COUNTIF(Posts!$R$6:$R$805,"<"&((Settings!$C$5-WEEKDAY(Settings!$C$5,3))+3)*10000000)+2)/10000000)=((Settings!$C$5-WEEKDAY(Settings!$C$5,3))+3),MOD(SMALL(Posts!$R$6:$R$805,COUNTIF(Posts!$R$6:$R$805,"<"&((Settings!$C$5-WEEKDAY(Settings!$C$5,3))+3)*10000000)+2),1000),""),"") | X6: =IFERROR(IF(INT(SMALL(Posts!$R$6:$R$805,COUNTIF(Posts!$R$6:$R$805,"<"&((Settings!$C$5-WEEKDAY(Settings!$C$5,3))+3)*10000000)+3)/10000000)=((Settings!$C$5-WEEKDAY(Settings!$C$5,3))+3),MOD(SMALL(Posts!$R$6:$R$805,COUNTIF(Posts!$R$6:$R$805,"<"&((Settings!$C$5-WEEKDAY(Settings!$C$5,3))+3)*10000000)+3),1000),""),"") | Y6: =COUNTIFS(Posts!$R$6:$R$805,">="&((Settings!$C$5-WEEKDAY(Settings!$C$5,3))+3)*10000000,Posts!$R$6:$R$805,"<"&(((Settings!$C$5-WEEKDAY(Settings!$C$5,3))+3)+1)*10000000) | Z6: =IFERROR(IF(INT(SMALL(Posts!$R$6:$R$805,COUNTIF(Posts!$R$6:$R$805,"<"&((Settings!$C$5-WEEKDAY(Settings!$C$5,3))+4)*10000000)+1)/10000000)=((Settings!$C$5-WEEKDAY(Settings!$C$5,3))+4),MOD(SMALL(Posts!$R$6:$R$805,COUNTIF(Posts!$R$6:$R$805,"<"&((Settings!$C$5-WEEKDAY(Settings!$C$5,3))+4)*10000000)+1),1000),""),"") | AA6: =IFERROR(IF(INT(SMALL(Posts!$R$6:$R$805,COUNTIF(Posts!$R$6:$R$805,"<"&((Settings!$C$5-WEEKDAY(Settings!$C$5,3))+4)*10000000)+2)/10000000)=((Settings!$C$5-WEEKDAY(Settings!$C$5,3))+4),MOD(SMALL(Posts!$R$6:$R$805,COUNTIF(Posts!$R$6:$R$805,"<"&((Settings!$C$5-WEEKDAY(Settings!$C$5,3))+4)*10000000)+2),1000),""),"") | AB6: =IFERROR(IF(INT(SMALL(Posts!$R$6:$R$805,COUNTIF(Posts!$R$6:$R$805,"<"&((Settings!$C$5-WEEKDAY(Settings!$C$5,3))+4)*10000000)+3)/10000000)=((Settings!$C$5-WEEKDAY(Settings!$C$5,3))+4),MOD(SMALL(Posts!$R$6:$R$805,COUNTIF(Posts!$R$6:$R$805,"<"&((Settings!$C$5-WEEKDAY(Settings!$C$5,3))+4)*10000000)+3),1000),""),"") | AC6: =COUNTIFS(Posts!$R$6:$R$805,">="&((Settings!$C$5-WEEKDAY(Settings!$C$5,3))+4)*10000000,Posts!$R$6:$R$805,"<"&(((Settings!$C$5-WEEKDAY(Settings!$C$5,3))+4)+1)*10000000) | AD6: =IFERROR(IF(INT(SMALL(Posts!$R$6:$R$805,COUNTIF(Posts!$R$6:$R$805,"<"&((Settings!$C$5-WEEKDAY(Settings!$C$5,3))+5)*10000000)+1)/10000000)=((Settings!$C$5-WEEKDAY(Settings!$C$5,3))+5),MOD(SMALL(Posts!$R$6:$R$805,COUNTIF(Posts!$R$6:$R$805,"<"&((Settings!$C$5-WEEKDAY(Settings!$C$5,3))+5)*10000000)+1),1000),""),"") | AE6: =IFERROR(IF(INT(SMALL(Posts!$R$6:$R$805,COUNTIF(Posts!$R$6:$R$805,"<"&((Settings!$C$5-WEEKDAY(Settings!$C$5,3))+5)*10000000)+2)/10000000)=((Settings!$C$5-WEEKDAY(Settings!$C$5,3))+5),MOD(SMALL(Posts!$R$6:$R$805,COUNTIF(Posts!$R$6:$R$805,"<"&((Settings!$C$5-WEEKDAY(Settings!$C$5,3))+5)*10000000)+2),1000),""),"") | AF6: =IFERROR(IF(INT(SMALL(Posts!$R$6:$R$805,COUNTIF(Posts!$R$6:$R$805,"<"&((Settings!$C$5-WEEKDAY(Settings!$C$5,3))+5)*10000000)+3)/10000000)=((Settings!$C$5-WEEKDAY(Settings!$C$5,3))+5),MOD(SMALL(Posts!$R$6:$R$805,COUNTIF(Posts!$R$6:$R$805,"<"&((Settings!$C$5-WEEKDAY(Settings!$C$5,3))+5)*10000000)+3),1000),""),"") | AG6: =COUNTIFS(Posts!$R$6:$R$805,">="&((Settings!$C$5-WEEKDAY(Settings!$C$5,3))+5)*10000000,Posts!$R$6:$R$805,"<"&(((Settings!$C$5-WEEKDAY(Settings!$C$5,3))+5)+1)*10000000) | AH6: =IFERROR(IF(INT(SMALL(Posts!$R$6:$R$805,COUNTIF(Posts!$R$6:$R$805,"<"&((Settings!$C$5-WEEKDAY(Settings!$C$5,3))+6)*10000000)+1)/10000000)=((Settings!$C$5-WEEKDAY(Settings!$C$5,3))+6),MOD(SMALL(Posts!$R$6:$R$805,COUNTIF(Posts!$R$6:$R$805,"<"&((Settings!$C$5-WEEKDAY(Settings!$C$5,3))+6)*10000000)+1),1000),""),"") | AI6: =IFERROR(IF(INT(SMALL(Posts!$R$6:$R$805,COUNTIF(Posts!$R$6:$R$805,"<"&((Settings!$C$5-WEEKDAY(Settings!$C$5,3))+6)*10000000)+2)/10000000)=((Settings!$C$5-WEEKDAY(Settings!$C$5,3))+6),MOD(SMALL(Posts!$R$6:$R$805,COUNTIF(Posts!$R$6:$R$805,"<"&((Settings!$C$5-WEEKDAY(Settings!$C$5,3))+6)*10000000)+2),1000),""),"") | AJ6: =IFERROR(IF(INT(SMALL(Posts!$R$6:$R$805,COUNTIF(Posts!$R$6:$R$805,"<"&((Settings!$C$5-WEEKDAY(Settings!$C$5,3))+6)*10000000)+3)/10000000)=((Settings!$C$5-WEEKDAY(Settings!$C$5,3))+6),MOD(SMALL(Posts!$R$6:$R$805,COUNTIF(Posts!$R$6:$R$805,"<"&((Settings!$C$5-WEEKDAY(Settings!$C$5,3))+6)*10000000)+3),1000),""),"") | AK6: =COUNTIFS(Posts!$R$6:$R$805,">="&((Settings!$C$5-WEEKDAY(Settings!$C$5,3))+6)*10000000,Posts!$R$6:$R$805,"<"&(((Settings!$C$5-WEEKDAY(Settings!$C$5,3))+6)+1)*10000000)
B7: =IF(MONTH(((Settings!$C$5-WEEKDAY(Settings!$C$5,3))+7))<>MONTH(Settings!$C$5),"",DAY(((Settings!$C$5-WEEKDAY(Settings!$C$5,3))+7))&IF(J7="","",CHAR(10)&IF(IFERROR(INDEX(Settings!$C$10:$C$17,MATCH(INDEX(Posts!$D$1:$D$805,J7),Settings!$B$10:$B$17,0)),"")="",INDEX(Posts!$D$1:$D$805,J7),IFERROR(INDEX(Settings!$C$10:$C$17,MATCH(INDEX(Posts!$D$1:$D$805,J7),Settings!$B$10:$B$17,0)),""))&": "&IF(INDEX(Posts!$G$1:$G$805,J7)="",INDEX(Posts!$E$1:$E$805,J7),INDEX(Posts!$G$1:$G$805,J7)))&IF(K7="","",CHAR(10)&IF(IFERROR(INDEX(Settings!$C$10:$C$17,MATCH(INDEX(Posts!$D$1:$D$805,K7),Settings!$B$10:$B$17,0)),"")="",INDEX(Posts!$D$1:$D$805,K7),IFERROR(INDEX(Settings!$C$10:$C$17,MATCH(INDEX(Posts!$D$1:$D$805,K7),Settings!$B$10:$B$17,0)),""))&": "&IF(INDEX(Posts!$G$1:$G$805,K7)="",INDEX(Posts!$E$1:$E$805,K7),INDEX(Posts!$G$1:$G$805,K7)))&IF(L7="","",CHAR(10)&IF(IFERROR(INDEX(Settings!$C$10:$C$17,MATCH(INDEX(Posts!$D$1:$D$805,L7),Settings!$B$10:$B$17,0)),"")="",INDEX(Posts!$D$1:$D$805,L7),IFERROR(INDEX(Settings!$C$10:$C$17,MATCH(INDEX(Posts!$D$1:$D$805,L7),Settings!$B$10:$B$17,0)),""))&": "&IF(INDEX(Posts!$G$1:$G$805,L7)="",INDEX(Posts!$E$1:$E$805,L7),INDEX(Posts!$G$1:$G$805,L7)))&IF(M7>3,CHAR(10)&"and "&(M7-3)&" more","")) | C7: =IF(MONTH(((Settings!$C$5-WEEKDAY(Settings!$C$5,3))+8))<>MONTH(Settings!$C$5),"",DAY(((Settings!$C$5-WEEKDAY(Settings!$C$5,3))+8))&IF(N7="","",CHAR(10)&IF(IFERROR(INDEX(Settings!$C$10:$C$17,MATCH(INDEX(Posts!$D$1:$D$805,N7),Settings!$B$10:$B$17,0)),"")="",INDEX(Posts!$D$1:$D$805,N7),IFERROR(INDEX(Settings!$C$10:$C$17,MATCH(INDEX(Posts!$D$1:$D$805,N7),Settings!$B$10:$B$17,0)),""))&": "&IF(INDEX(Posts!$G$1:$G$805,N7)="",INDEX(Posts!$E$1:$E$805,N7),INDEX(Posts!$G$1:$G$805,N7)))&IF(O7="","",CHAR(10)&IF(IFERROR(INDEX(Settings!$C$10:$C$17,MATCH(INDEX(Posts!$D$1:$D$805,O7),Settings!$B$10:$B$17,0)),"")="",INDEX(Posts!$D$1:$D$805,O7),IFERROR(INDEX(Settings!$C$10:$C$17,MATCH(INDEX(Posts!$D$1:$D$805,O7),Settings!$B$10:$B$17,0)),""))&": "&IF(INDEX(Posts!$G$1:$G$805,O7)="",INDEX(Posts!$E$1:$E$805,O7),INDEX(Posts!$G$1:$G$805,O7)))&IF(P7="","",CHAR(10)&IF(IFERROR(INDEX(Settings!$C$10:$C$17,MATCH(INDEX(Posts!$D$1:$D$805,P7),Settings!$B$10:$B$17,0)),"")="",INDEX(Posts!$D$1:$D$805,P7),IFERROR(INDEX(Settings!$C$10:$C$17,MATCH(INDEX(Posts!$D$1:$D$805,P7),Settings!$B$10:$B$17,0)),""))&": "&IF(INDEX(Posts!$G$1:$G$805,P7)="",INDEX(Posts!$E$1:$E$805,P7),INDEX(Posts!$G$1:$G$805,P7)))&IF(Q7>3,CHAR(10)&"and "&(Q7-3)&" more","")) | D7: =IF(MONTH(((Settings!$C$5-WEEKDAY(Settings!$C$5,3))+9))<>MONTH(Settings!$C$5),"",DAY(((Settings!$C$5-WEEKDAY(Settings!$C$5,3))+9))&IF(R7="","",CHAR(10)&IF(IFERROR(INDEX(Settings!$C$10:$C$17,MATCH(INDEX(Posts!$D$1:$D$805,R7),Settings!$B$10:$B$17,0)),"")="",INDEX(Posts!$D$1:$D$805,R7),IFERROR(INDEX(Settings!$C$10:$C$17,MATCH(INDEX(Posts!$D$1:$D$805,R7),Settings!$B$10:$B$17,0)),""))&": "&IF(INDEX(Posts!$G$1:$G$805,R7)="",INDEX(Posts!$E$1:$E$805,R7),INDEX(Posts!$G$1:$G$805,R7)))&IF(S7="","",CHAR(10)&IF(IFERROR(INDEX(Settings!$C$10:$C$17,MATCH(INDEX(Posts!$D$1:$D$805,S7),Settings!$B$10:$B$17,0)),"")="",INDEX(Posts!$D$1:$D$805,S7),IFERROR(INDEX(Settings!$C$10:$C$17,MATCH(INDEX(Posts!$D$1:$D$805,S7),Settings!$B$10:$B$17,0)),""))&": "&IF(INDEX(Posts!$G$1:$G$805,S7)="",INDEX(Posts!$E$1:$E$805,S7),INDEX(Posts!$G$1:$G$805,S7)))&IF(T7="","",CHAR(10)&IF(IFERROR(INDEX(Settings!$C$10:$C$17,MATCH(INDEX(Posts!$D$1:$D$805,T7),Settings!$B$10:$B$17,0)),"")="",INDEX(Posts!$D$1:$D$805,T7),IFERROR(INDEX(Settings!$C$10:$C$17,MATCH(INDEX(Posts!$D$1:$D$805,T7),Settings!$B$10:$B$17,0)),""))&": "&IF(INDEX(Posts!$G$1:$G$805,T7)="",INDEX(Posts!$E$1:$E$805,T7),INDEX(Posts!$G$1:$G$805,T7)))&IF(U7>3,CHAR(10)&"and "&(U7-3)&" more","")) | E7: =IF(MONTH(((Settings!$C$5-WEEKDAY(Settings!$C$5,3))+10))<>MONTH(Settings!$C$5),"",DAY(((Settings!$C$5-WEEKDAY(Settings!$C$5,3))+10))&IF(V7="","",CHAR(10)&IF(IFERROR(INDEX(Settings!$C$10:$C$17,MATCH(INDEX(Posts!$D$1:$D$805,V7),Settings!$B$10:$B$17,0)),"")="",INDEX(Posts!$D$1:$D$805,V7),IFERROR(INDEX(Settings!$C$10:$C$17,MATCH(INDEX(Posts!$D$1:$D$805,V7),Settings!$B$10:$B$17,0)),""))&": "&IF(INDEX(Posts!$G$1:$G$805,V7)="",INDEX(Posts!$E$1:$E$805,V7),INDEX(Posts!$G$1:$G$805,V7)))&IF(W7="","",CHAR(10)&IF(IFERROR(INDEX(Settings!$C$10:$C$17,MATCH(INDEX(Posts!$D$1:$D$805,W7),Settings!$B$10:$B$17,0)),"")="",INDEX(Posts!$D$1:$D$805,W7),IFERROR(INDEX(Settings!$C$10:$C$17,MATCH(INDEX(Posts!$D$1:$D$805,W7),Settings!$B$10:$B$17,0)),""))&": "&IF(INDEX(Posts!$G$1:$G$805,W7)="",INDEX(Posts!$E$1:$E$805,W7),INDEX(Posts!$G$1:$G$805,W7)))&IF(X7="","",CHAR(10)&IF(IFERROR(INDEX(Settings!$C$10:$C$17,MATCH(INDEX(Posts!$D$1:$D$805,X7),Settings!$B$10:$B$17,0)),"")="",INDEX(Posts!$D$1:$D$805,X7),IFERROR(INDEX(Settings!$C$10:$C$17,MATCH(INDEX(Posts!$D$1:$D$805,X7),Settings!$B$10:$B$17,0)),""))&": "&IF(INDEX(Posts!$G$1:$G$805,X7)="",INDEX(Posts!$E$1:$E$805,X7),INDEX(Posts!$G$1:$G$805,X7)))&IF(Y7>3,CHAR(10)&"and "&(Y7-3)&" more","")) | F7: =IF(MONTH(((Settings!$C$5-WEEKDAY(Settings!$C$5,3))+11))<>MONTH(Settings!$C$5),"",DAY(((Settings!$C$5-WEEKDAY(Settings!$C$5,3))+11))&IF(Z7="","",CHAR(10)&IF(IFERROR(INDEX(Settings!$C$10:$C$17,MATCH(INDEX(Posts!$D$1:$D$805,Z7),Settings!$B$10:$B$17,0)),"")="",INDEX(Posts!$D$1:$D$805,Z7),IFERROR(INDEX(Settings!$C$10:$C$17,MATCH(INDEX(Posts!$D$1:$D$805,Z7),Settings!$B$10:$B$17,0)),""))&": "&IF(INDEX(Posts!$G$1:$G$805,Z7)="",INDEX(Posts!$E$1:$E$805,Z7),INDEX(Posts!$G$1:$G$805,Z7)))&IF(AA7="","",CHAR(10)&IF(IFERROR(INDEX(Settings!$C$10:$C$17,MATCH(INDEX(Posts!$D$1:$D$805,AA7),Settings!$B$10:$B$17,0)),"")="",INDEX(Posts!$D$1:$D$805,AA7),IFERROR(INDEX(Settings!$C$10:$C$17,MATCH(INDEX(Posts!$D$1:$D$805,AA7),Settings!$B$10:$B$17,0)),""))&": "&IF(INDEX(Posts!$G$1:$G$805,AA7)="",INDEX(Posts!$E$1:$E$805,AA7),INDEX(Posts!$G$1:$G$805,AA7)))&IF(AB7="","",CHAR(10)&IF(IFERROR(INDEX(Settings!$C$10:$C$17,MATCH(INDEX(Posts!$D$1:$D$805,AB7),Settings!$B$10:$B$17,0)),"")="",INDEX(Posts!$D$1:$D$805,AB7),IFERROR(INDEX(Settings!$C$10:$C$17,MATCH(INDEX(Posts!$D$1:$D$805,AB7),Settings!$B$10:$B$17,0)),""))&": "&IF(INDEX(Posts!$G$1:$G$805,AB7)="",INDEX(Posts!$E$1:$E$805,AB7),INDEX(Posts!$G$1:$G$805,AB7)))&IF(AC7>3,CHAR(10)&"and "&(AC7-3)&" more","")) | G7: =IF(MONTH(((Settings!$C$5-WEEKDAY(Settings!$C$5,3))+12))<>MONTH(Settings!$C$5),"",DAY(((Settings!$C$5-WEEKDAY(Settings!$C$5,3))+12))&IF(AD7="","",CHAR(10)&IF(IFERROR(INDEX(Settings!$C$10:$C$17,MATCH(INDEX(Posts!$D$1:$D$805,AD7),Settings!$B$10:$B$17,0)),"")="",INDEX(Posts!$D$1:$D$805,AD7),IFERROR(INDEX(Settings!$C$10:$C$17,MATCH(INDEX(Posts!$D$1:$D$805,AD7),Settings!$B$10:$B$17,0)),""))&": "&IF(INDEX(Posts!$G$1:$G$805,AD7)="",INDEX(Posts!$E$1:$E$805,AD7),INDEX(Posts!$G$1:$G$805,AD7)))&IF(AE7="","",CHAR(10)&IF(IFERROR(INDEX(Settings!$C$10:$C$17,MATCH(INDEX(Posts!$D$1:$D$805,AE7),Settings!$B$10:$B$17,0)),"")="",INDEX(Posts!$D$1:$D$805,AE7),IFERROR(INDEX(Settings!$C$10:$C$17,MATCH(INDEX(Posts!$D$1:$D$805,AE7),Settings!$B$10:$B$17,0)),""))&": "&IF(INDEX(Posts!$G$1:$G$805,AE7)="",INDEX(Posts!$E$1:$E$805,AE7),INDEX(Posts!$G$1:$G$805,AE7)))&IF(AF7="","",CHAR(10)&IF(IFERROR(INDEX(Settings!$C$10:$C$17,MATCH(INDEX(Posts!$D$1:$D$805,AF7),Settings!$B$10:$B$17,0)),"")="",INDEX(Posts!$D$1:$D$805,AF7),IFERROR(INDEX(Settings!$C$10:$C$17,MATCH(INDEX(Posts!$D$1:$D$805,AF7),Settings!$B$10:$B$17,0)),""))&": "&IF(INDEX(Posts!$G$1:$G$805,AF7)="",INDEX(Posts!$E$1:$E$805,AF7),INDEX(Posts!$G$1:$G$805,AF7)))&IF(AG7>3,CHAR(10)&"and "&(AG7-3)&" more","")) | H7: =IF(MONTH(((Settings!$C$5-WEEKDAY(Settings!$C$5,3))+13))<>MONTH(Settings!$C$5),"",DAY(((Settings!$C$5-WEEKDAY(Settings!$C$5,3))+13))&IF(AH7="","",CHAR(10)&IF(IFERROR(INDEX(Settings!$C$10:$C$17,MATCH(INDEX(Posts!$D$1:$D$805,AH7),Settings!$B$10:$B$17,0)),"")="",INDEX(Posts!$D$1:$D$805,AH7),IFERROR(INDEX(Settings!$C$10:$C$17,MATCH(INDEX(Posts!$D$1:$D$805,AH7),Settings!$B$10:$B$17,0)),""))&": "&IF(INDEX(Posts!$G$1:$G$805,AH7)="",INDEX(Posts!$E$1:$E$805,AH7),INDEX(Posts!$G$1:$G$805,AH7)))&IF(AI7="","",CHAR(10)&IF(IFERROR(INDEX(Settings!$C$10:$C$17,MATCH(INDEX(Posts!$D$1:$D$805,AI7),Settings!$B$10:$B$17,0)),"")="",INDEX(Posts!$D$1:$D$805,AI7),IFERROR(INDEX(Settings!$C$10:$C$17,MATCH(INDEX(Posts!$D$1:$D$805,AI7),Settings!$B$10:$B$17,0)),""))&": "&IF(INDEX(Posts!$G$1:$G$805,AI7)="",INDEX(Posts!$E$1:$E$805,AI7),INDEX(Posts!$G$1:$G$805,AI7)))&IF(AJ7="","",CHAR(10)&IF(IFERROR(INDEX(Settings!$C$10:$C$17,MATCH(INDEX(Posts!$D$1:$D$805,AJ7),Settings!$B$10:$B$17,0)),"")="",INDEX(Posts!$D$1:$D$805,AJ7),IFERROR(INDEX(Settings!$C$10:$C$17,MATCH(INDEX(Posts!$D$1:$D$805,AJ7),Settings!$B$10:$B$17,0)),""))&": "&IF(INDEX(Posts!$G$1:$G$805,AJ7)="",INDEX(Posts!$E$1:$E$805,AJ7),INDEX(Posts!$G$1:$G$805,AJ7)))&IF(AK7>3,CHAR(10)&"and "&(AK7-3)&" more","")) | J7: =IFERROR(IF(INT(SMALL(Posts!$R$6:$R$805,COUNTIF(Posts!$R$6:$R$805,"<"&((Settings!$C$5-WEEKDAY(Settings!$C$5,3))+7)*10000000)+1)/10000000)=((Settings!$C$5-WEEKDAY(Settings!$C$5,3))+7),MOD(SMALL(Posts!$R$6:$R$805,COUNTIF(Posts!$R$6:$R$805,"<"&((Settings!$C$5-WEEKDAY(Settings!$C$5,3))+7)*10000000)+1),1000),""),"") | K7: =IFERROR(IF(INT(SMALL(Posts!$R$6:$R$805,COUNTIF(Posts!$R$6:$R$805,"<"&((Settings!$C$5-WEEKDAY(Settings!$C$5,3))+7)*10000000)+2)/10000000)=((Settings!$C$5-WEEKDAY(Settings!$C$5,3))+7),MOD(SMALL(Posts!$R$6:$R$805,COUNTIF(Posts!$R$6:$R$805,"<"&((Settings!$C$5-WEEKDAY(Settings!$C$5,3))+7)*10000000)+2),1000),""),"") | L7: =IFERROR(IF(INT(SMALL(Posts!$R$6:$R$805,COUNTIF(Posts!$R$6:$R$805,"<"&((Settings!$C$5-WEEKDAY(Settings!$C$5,3))+7)*10000000)+3)/10000000)=((Settings!$C$5-WEEKDAY(Settings!$C$5,3))+7),MOD(SMALL(Posts!$R$6:$R$805,COUNTIF(Posts!$R$6:$R$805,"<"&((Settings!$C$5-WEEKDAY(Settings!$C$5,3))+7)*10000000)+3),1000),""),"") | M7: =COUNTIFS(Posts!$R$6:$R$805,">="&((Settings!$C$5-WEEKDAY(Settings!$C$5,3))+7)*10000000,Posts!$R$6:$R$805,"<"&(((Settings!$C$5-WEEKDAY(Settings!$C$5,3))+7)+1)*10000000) | N7: =IFERROR(IF(INT(SMALL(Posts!$R$6:$R$805,COUNTIF(Posts!$R$6:$R$805,"<"&((Settings!$C$5-WEEKDAY(Settings!$C$5,3))+8)*10000000)+1)/10000000)=((Settings!$C$5-WEEKDAY(Settings!$C$5,3))+8),MOD(SMALL(Posts!$R$6:$R$805,COUNTIF(Posts!$R$6:$R$805,"<"&((Settings!$C$5-WEEKDAY(Settings!$C$5,3))+8)*10000000)+1),1000),""),"") | O7: =IFERROR(IF(INT(SMALL(Posts!$R$6:$R$805,COUNTIF(Posts!$R$6:$R$805,"<"&((Settings!$C$5-WEEKDAY(Settings!$C$5,3))+8)*10000000)+2)/10000000)=((Settings!$C$5-WEEKDAY(Settings!$C$5,3))+8),MOD(SMALL(Posts!$R$6:$R$805,COUNTIF(Posts!$R$6:$R$805,"<"&((Settings!$C$5-WEEKDAY(Settings!$C$5,3))+8)*10000000)+2),1000),""),"") | P7: =IFERROR(IF(INT(SMALL(Posts!$R$6:$R$805,COUNTIF(Posts!$R$6:$R$805,"<"&((Settings!$C$5-WEEKDAY(Settings!$C$5,3))+8)*10000000)+3)/10000000)=((Settings!$C$5-WEEKDAY(Settings!$C$5,3))+8),MOD(SMALL(Posts!$R$6:$R$805,COUNTIF(Posts!$R$6:$R$805,"<"&((Settings!$C$5-WEEKDAY(Settings!$C$5,3))+8)*10000000)+3),1000),""),"") | Q7: =COUNTIFS(Posts!$R$6:$R$805,">="&((Settings!$C$5-WEEKDAY(Settings!$C$5,3))+8)*10000000,Posts!$R$6:$R$805,"<"&(((Settings!$C$5-WEEKDAY(Settings!$C$5,3))+8)+1)*10000000) | R7: =IFERROR(IF(INT(SMALL(Posts!$R$6:$R$805,COUNTIF(Posts!$R$6:$R$805,"<"&((Settings!$C$5-WEEKDAY(Settings!$C$5,3))+9)*10000000)+1)/10000000)=((Settings!$C$5-WEEKDAY(Settings!$C$5,3))+9),MOD(SMALL(Posts!$R$6:$R$805,COUNTIF(Posts!$R$6:$R$805,"<"&((Settings!$C$5-WEEKDAY(Settings!$C$5,3))+9)*10000000)+1),1000),""),"") | S7: =IFERROR(IF(INT(SMALL(Posts!$R$6:$R$805,COUNTIF(Posts!$R$6:$R$805,"<"&((Settings!$C$5-WEEKDAY(Settings!$C$5,3))+9)*10000000)+2)/10000000)=((Settings!$C$5-WEEKDAY(Settings!$C$5,3))+9),MOD(SMALL(Posts!$R$6:$R$805,COUNTIF(Posts!$R$6:$R$805,"<"&((Settings!$C$5-WEEKDAY(Settings!$C$5,3))+9)*10000000)+2),1000),""),"") | T7: =IFERROR(IF(INT(SMALL(Posts!$R$6:$R$805,COUNTIF(Posts!$R$6:$R$805,"<"&((Settings!$C$5-WEEKDAY(Settings!$C$5,3))+9)*10000000)+3)/10000000)=((Settings!$C$5-WEEKDAY(Settings!$C$5,3))+9),MOD(SMALL(Posts!$R$6:$R$805,COUNTIF(Posts!$R$6:$R$805,"<"&((Settings!$C$5-WEEKDAY(Settings!$C$5,3))+9)*10000000)+3),1000),""),"") | U7: =COUNTIFS(Posts!$R$6:$R$805,">="&((Settings!$C$5-WEEKDAY(Settings!$C$5,3))+9)*10000000,Posts!$R$6:$R$805,"<"&(((Settings!$C$5-WEEKDAY(Settings!$C$5,3))+9)+1)*10000000) | V7: =IFERROR(IF(INT(SMALL(Posts!$R$6:$R$805,COUNTIF(Posts!$R$6:$R$805,"<"&((Settings!$C$5-WEEKDAY(Settings!$C$5,3))+10)*10000000)+1)/10000000)=((Settings!$C$5-WEEKDAY(Settings!$C$5,3))+10),MOD(SMALL(Posts!$R$6:$R$805,COUNTIF(Posts!$R$6:$R$805,"<"&((Settings!$C$5-WEEKDAY(Settings!$C$5,3))+10)*10000000)+1),1000),""),"") | W7: =IFERROR(IF(INT(SMALL(Posts!$R$6:$R$805,COUNTIF(Posts!$R$6:$R$805,"<"&((Settings!$C$5-WEEKDAY(Settings!$C$5,3))+10)*10000000)+2)/10000000)=((Settings!$C$5-WEEKDAY(Settings!$C$5,3))+10),MOD(SMALL(Posts!$R$6:$R$805,COUNTIF(Posts!$R$6:$R$805,"<"&((Settings!$C$5-WEEKDAY(Settings!$C$5,3))+10)*10000000)+2),1000),""),"") | X7: =IFERROR(IF(INT(SMALL(Posts!$R$6:$R$805,COUNTIF(Posts!$R$6:$R$805,"<"&((Settings!$C$5-WEEKDAY(Settings!$C$5,3))+10)*10000000)+3)/10000000)=((Settings!$C$5-WEEKDAY(Settings!$C$5,3))+10),MOD(SMALL(Posts!$R$6:$R$805,COUNTIF(Posts!$R$6:$R$805,"<"&((Settings!$C$5-WEEKDAY(Settings!$C$5,3))+10)*10000000)+3),1000),""),"") | Y7: =COUNTIFS(Posts!$R$6:$R$805,">="&((Settings!$C$5-WEEKDAY(Settings!$C$5,3))+10)*10000000,Posts!$R$6:$R$805,"<"&(((Settings!$C$5-WEEKDAY(Settings!$C$5,3))+10)+1)*10000000) | Z7: =IFERROR(IF(INT(SMALL(Posts!$R$6:$R$805,COUNTIF(Posts!$R$6:$R$805,"<"&((Settings!$C$5-WEEKDAY(Settings!$C$5,3))+11)*10000000)+1)/10000000)=((Settings!$C$5-WEEKDAY(Settings!$C$5,3))+11),MOD(SMALL(Posts!$R$6:$R$805,COUNTIF(Posts!$R$6:$R$805,"<"&((Settings!$C$5-WEEKDAY(Settings!$C$5,3))+11)*10000000)+1),1000),""),"") | AA7: =IFERROR(IF(INT(SMALL(Posts!$R$6:$R$805,COUNTIF(Posts!$R$6:$R$805,"<"&((Settings!$C$5-WEEKDAY(Settings!$C$5,3))+11)*10000000)+2)/10000000)=((Settings!$C$5-WEEKDAY(Settings!$C$5,3))+11),MOD(SMALL(Posts!$R$6:$R$805,COUNTIF(Posts!$R$6:$R$805,"<"&((Settings!$C$5-WEEKDAY(Settings!$C$5,3))+11)*10000000)+2),1000),""),"") | AB7: =IFERROR(IF(INT(SMALL(Posts!$R$6:$R$805,COUNTIF(Posts!$R$6:$R$805,"<"&((Settings!$C$5-WEEKDAY(Settings!$C$5,3))+11)*10000000)+3)/10000000)=((Settings!$C$5-WEEKDAY(Settings!$C$5,3))+11),MOD(SMALL(Posts!$R$6:$R$805,COUNTIF(Posts!$R$6:$R$805,"<"&((Settings!$C$5-WEEKDAY(Settings!$C$5,3))+11)*10000000)+3),1000),""),"") | AC7: =COUNTIFS(Posts!$R$6:$R$805,">="&((Settings!$C$5-WEEKDAY(Settings!$C$5,3))+11)*10000000,Posts!$R$6:$R$805,"<"&(((Settings!$C$5-WEEKDAY(Settings!$C$5,3))+11)+1)*10000000) | AD7: =IFERROR(IF(INT(SMALL(Posts!$R$6:$R$805,COUNTIF(Posts!$R$6:$R$805,"<"&((Settings!$C$5-WEEKDAY(Settings!$C$5,3))+12)*10000000)+1)/10000000)=((Settings!$C$5-WEEKDAY(Settings!$C$5,3))+12),MOD(SMALL(Posts!$R$6:$R$805,COUNTIF(Posts!$R$6:$R$805,"<"&((Settings!$C$5-WEEKDAY(Settings!$C$5,3))+12)*10000000)+1),1000),""),"") | AE7: =IFERROR(IF(INT(SMALL(Posts!$R$6:$R$805,COUNTIF(Posts!$R$6:$R$805,"<"&((Settings!$C$5-WEEKDAY(Settings!$C$5,3))+12)*10000000)+2)/10000000)=((Settings!$C$5-WEEKDAY(Settings!$C$5,3))+12),MOD(SMALL(Posts!$R$6:$R$805,COUNTIF(Posts!$R$6:$R$805,"<"&((Settings!$C$5-WEEKDAY(Settings!$C$5,3))+12)*10000000)+2),1000),""),"") | AF7: =IFERROR(IF(INT(SMALL(Posts!$R$6:$R$805,COUNTIF(Posts!$R$6:$R$805,"<"&((Settings!$C$5-WEEKDAY(Settings!$C$5,3))+12)*10000000)+3)/10000000)=((Settings!$C$5-WEEKDAY(Settings!$C$5,3))+12),MOD(SMALL(Posts!$R$6:$R$805,COUNTIF(Posts!$R$6:$R$805,"<"&((Settings!$C$5-WEEKDAY(Settings!$C$5,3))+12)*10000000)+3),1000),""),"") | AG7: =COUNTIFS(Posts!$R$6:$R$805,">="&((Settings!$C$5-WEEKDAY(Settings!$C$5,3))+12)*10000000,Posts!$R$6:$R$805,"<"&(((Settings!$C$5-WEEKDAY(Settings!$C$5,3))+12)+1)*10000000) | AH7: =IFERROR(IF(INT(SMALL(Posts!$R$6:$R$805,COUNTIF(Posts!$R$6:$R$805,"<"&((Settings!$C$5-WEEKDAY(Settings!$C$5,3))+13)*10000000)+1)/10000000)=((Settings!$C$5-WEEKDAY(Settings!$C$5,3))+13),MOD(SMALL(Posts!$R$6:$R$805,COUNTIF(Posts!$R$6:$R$805,"<"&((Settings!$C$5-WEEKDAY(Settings!$C$5,3))+13)*10000000)+1),1000),""),"") | AI7: =IFERROR(IF(INT(SMALL(Posts!$R$6:$R$805,COUNTIF(Posts!$R$6:$R$805,"<"&((Settings!$C$5-WEEKDAY(Settings!$C$5,3))+13)*10000000)+2)/10000000)=((Settings!$C$5-WEEKDAY(Settings!$C$5,3))+13),MOD(SMALL(Posts!$R$6:$R$805,COUNTIF(Posts!$R$6:$R$805,"<"&((Settings!$C$5-WEEKDAY(Settings!$C$5,3))+13)*10000000)+2),1000),""),"") | AJ7: =IFERROR(IF(INT(SMALL(Posts!$R$6:$R$805,COUNTIF(Posts!$R$6:$R$805,"<"&((Settings!$C$5-WEEKDAY(Settings!$C$5,3))+13)*10000000)+3)/10000000)=((Settings!$C$5-WEEKDAY(Settings!$C$5,3))+13),MOD(SMALL(Posts!$R$6:$R$805,COUNTIF(Posts!$R$6:$R$805,"<"&((Settings!$C$5-WEEKDAY(Settings!$C$5,3))+13)*10000000)+3),1000),""),"") | AK7: =COUNTIFS(Posts!$R$6:$R$805,">="&((Settings!$C$5-WEEKDAY(Settings!$C$5,3))+13)*10000000,Posts!$R$6:$R$805,"<"&(((Settings!$C$5-WEEKDAY(Settings!$C$5,3))+13)+1)*10000000)
