Workbook

Sheet Dashboard
M1: =Settings!$C$5
B2: Batches and best before
B3: What to sell first, what to buy, and how much goes to waste.
B4: In stock | C4: Use soon | D4: Past its date | E4: Waste this month | G4: Made this month | H4: Cost of waste | I4: To buy | J4: Pantry going off
B5: =SUMIFS(Batches!$K$6:$K$505,Batches!$M$6:$M$505,"In stock")+SUMIFS(Batches!$K$6:$K$505,Batches!$M$6:$M$505,"Use soon") | C5: =SUMIFS(Batches!$K$6:$K$505,Batches!$M$6:$M$505,"Use soon") | D5: =SUMIFS(Batches!$K$6:$K$505,Batches!$M$6:$M$505,"Past its date") | E5: =IF(SUMIFS(Batches!$D$6:$D$505,Batches!$R$6:$R$505,(YEAR(TODAY())*100+MONTH(TODAY())))=0,"",SUMIFS(Batches!$G$6:$G$505,Batches!$R$6:$R$505,(YEAR(TODAY())*100+MONTH(TODAY())))/SUMIFS(Batches!$D$6:$D$505,Batches!$R$6:$R$505,(YEAR(TODAY())*100+MONTH(TODAY())))) | G5: =SUMIFS(Batches!$D$6:$D$505,Batches!$R$6:$R$505,(YEAR(TODAY())*100+MONTH(TODAY()))) | H5: =SUMIFS(Batches!$S$6:$S$505,Batches!$R$6:$R$505,(YEAR(TODAY())*100+MONTH(TODAY()))) | I5: =COUNTIF(Ingredients!$L$6:$L$105,"Buy more") | J5: =COUNTIF(Purchases!$K$6:$K$405,"Past its date")+COUNTIF(Purchases!$K$6:$K$405,"Use soon")
B7: Sell first | C7: Batch | D7: Left | E7: =Settings!$C$7 | G7: To buy | H7: Left | I7: Buy more at | J7: Unit
B8: =IF(N8="","",INDEX(Batches!$C$1:$C$505,MOD(N8,1000))) | C8: =IF(N8="","",INDEX(Batches!$I$1:$I$505,MOD(N8,1000))) | D8: =IF(N8="","",INDEX(Batches!$K$1:$K$505,MOD(N8,1000))) | E8: =IF(N8="","",INDEX(Batches!$J$1:$J$505,MOD(N8,1000))) | G8: =IF(O8="","",INDEX(Ingredients!$B$1:$B$105,O8)) | H8: =IF(O8="","",INDEX(Ingredients!$K$1:$K$105,O8)) | I8: =IF(O8="","",N(INDEX(Ingredients!$F$1:$F$105,O8))) | J8: =IF(O8="","",INDEX(Ingredients!$C$1:$C$105,O8)) | N8: =IFERROR(SMALL(Batches!$T$6:$T$505,1),"") | O8: =IFERROR(SMALL(Ingredients!$AR$6:$AR$105,1),"")
B9: =IF(N9="","",INDEX(Batches!$C$1:$C$505,MOD(N9,1000))) | C9: =IF(N9="","",INDEX(Batches!$I$1:$I$505,MOD(N9,1000))) | D9: =IF(N9="","",INDEX(Batches!$K$1:$K$505,MOD(N9,1000))) | E9: =IF(N9="","",INDEX(Batches!$J$1:$J$505,MOD(N9,1000))) | G9: =IF(O9="","",INDEX(Ingredients!$B$1:$B$105,O9)) | H9: =IF(O9="","",INDEX(Ingredients!$K$1:$K$105,O9)) | I9: =IF(O9="","",N(INDEX(Ingredients!$F$1:$F$105,O9))) | J9: =IF(O9="","",INDEX(Ingredients!$C$1:$C$105,O9)) | N9: =IFERROR(SMALL(Batches!$T$6:$T$505,2),"") | O9: =IFERROR(SMALL(Ingredients!$AR$6:$AR$105,2),"")
B10: =IF(N10="","",INDEX(Batches!$C$1:$C$505,MOD(N10,1000))) | C10: =IF(N10="","",INDEX(Batches!$I$1:$I$505,MOD(N10,1000))) | D10: =IF(N10="","",INDEX(Batches!$K$1:$K$505,MOD(N10,1000))) | E10: =IF(N10="","",INDEX(Batches!$J$1:$J$505,MOD(N10,1000))) | G10: =IF(O10="","",INDEX(Ingredients!$B$1:$B$105,O10)) | H10: =IF(O10="","",INDEX(Ingredients!$K$1:$K$105,O10)) | I10: =IF(O10="","",N(INDEX(Ingredients!$F$1:$F$105,O10))) | J10: =IF(O10="","",INDEX(Ingredients!$C$1:$C$105,O10)) | N10: =IFERROR(SMALL(Batches!$T$6:$T$505,3),"") | O10: =IFERROR(SMALL(Ingredients!$AR$6:$AR$105,3),"")
B11: =IF(N11="","",INDEX(Batches!$C$1:$C$505,MOD(N11,1000))) | C11: =IF(N11="","",INDEX(Batches!$I$1:$I$505,MOD(N11,1000))) | D11: =IF(N11="","",INDEX(Batches!$K$1:$K$505,MOD(N11,1000))) | E11: =IF(N11="","",INDEX(Batches!$J$1:$J$505,MOD(N11,1000))) | G11: =IF(O11="","",INDEX(Ingredients!$B$1:$B$105,O11)) | H11: =IF(O11="","",INDEX(Ingredients!$K$1:$K$105,O11)) | I11: =IF(O11="","",N(INDEX(Ingredients!$F$1:$F$105,O11))) | J11: =IF(O11="","",INDEX(Ingredients!$C$1:$C$105,O11)) | N11: =IFERROR(SMALL(Batches!$T$6:$T$505,4),"") | O11: =IFERROR(SMALL(Ingredients!$AR$6:$AR$105,4),"")
B12: =IF(N12="","",INDEX(Batches!$C$1:$C$505,MOD(N12,1000))) | C12: =IF(N12="","",INDEX(Batches!$I$1:$I$505,MOD(N12,1000))) | D12: =IF(N12="","",INDEX(Batches!$K$1:$K$505,MOD(N12,1000))) | E12: =IF(N12="","",INDEX(Batches!$J$1:$J$505,MOD(N12,1000))) | N12: =IFERROR(SMALL(Batches!$T$6:$T$505,5),"")
B13: =IF(N13="","",INDEX(Batches!$C$1:$C$505,MOD(N13,1000))) | C13: =IF(N13="","",INDEX(Batches!$I$1:$I$505,MOD(N13,1000))) | D13: =IF(N13="","",INDEX(Batches!$K$1:$K$505,MOD(N13,1000))) | E13: =IF(N13="","",INDEX(Batches!$J$1:$J$505,MOD(N13,1000))) | G13: Pantry | H13: Lot | I13: Date on pack | J13: Status | N13: =IFERROR(SMALL(Batches!$T$6:$T$505,6),"")
B14: =IF(N14="","",INDEX(Batches!$C$1:$C$505,MOD(N14,1000))) | C14: =IF(N14="","",INDEX(Batches!$I$1:$I$505,MOD(N14,1000))) | D14: =IF(N14="","",INDEX(Batches!$K$1:$K$505,MOD(N14,1000))) | E14: =IF(N14="","",INDEX(Batches!$J$1:$J$505,MOD(N14,1000))) | G14: =IF(O14="","",INDEX(Purchases!$C$1:$C$405,MOD(O14,1000))) | H14: =IF(O14="","",INDEX(Purchases!$G$1:$G$405,MOD(O14,1000))) | I14: =IF(O14="","",INDEX(Purchases!$H$1:$H$405,MOD(O14,1000))) | J14: =IF(O14="","",INDEX(Purchases!$K$1:$K$405,MOD(O14,1000))) | N14: =IFERROR(SMALL(Batches!$T$6:$T$505,7),"") | O14: =IFERROR(SMALL(Purchases!$L$6:$L$405,1),"")
B15: =IF(N15="","",INDEX(Batches!$C$1:$C$505,MOD(N15,1000))) | C15: =IF(N15="","",INDEX(Batches!$I$1:$I$505,MOD(N15,1000))) | D15: =IF(N15="","",INDEX(Batches!$K$1:$K$505,MOD(N15,1000))) | E15: =IF(N15="","",INDEX(Batches!$J$1:$J$505,MOD(N15,1000))) | G15: =IF(O15="","",INDEX(Purchases!$C$1:$C$405,MOD(O15,1000))) | H15: =IF(O15="","",INDEX(Purchases!$G$1:$G$405,MOD(O15,1000))) | I15: =IF(O15="","",INDEX(Purchases!$H$1:$H$405,MOD(O15,1000))) | J15: =IF(O15="","",INDEX(Purchases!$K$1:$K$405,MOD(O15,1000))) | N15: =IFERROR(SMALL(Batches!$T$6:$T$505,8),"") | O15: =IFERROR(SMALL(Purchases!$L$6:$L$405,2),"")
B16: =IF(N16="","",INDEX(Batches!$C$1:$C$505,MOD(N16,1000))) | C16: =IF(N16="","",INDEX(Batches!$I$1:$I$505,MOD(N16,1000))) | D16: =IF(N16="","",INDEX(Batches!$K$1:$K$505,MOD(N16,1000))) | E16: =IF(N16="","",INDEX(Batches!$J$1:$J$505,MOD(N16,1000))) | G16: =IF(O16="","",INDEX(Purchases!$C$1:$C$405,MOD(O16,1000))) | H16: =IF(O16="","",INDEX(Purchases!$G$1:$G$405,MOD(O16,1000))) | I16: =IF(O16="","",INDEX(Purchases!$H$1:$H$405,MOD(O16,1000))) | J16: =IF(O16="","",INDEX(Purchases!$K$1:$K$405,MOD(O16,1000))) | N16: =IFERROR(SMALL(Batches!$T$6:$T$505,9),"") | O16: =IFERROR(SMALL(Purchases!$L$6:$L$405,3),"")
B17: =IF(N17="","",INDEX(Batches!$C$1:$C$505,MOD(N17,1000))) | C17: =IF(N17="","",INDEX(Batches!$I$1:$I$505,MOD(N17,1000))) | D17: =IF(N17="","",INDEX(Batches!$K$1:$K$505,MOD(N17,1000))) | E17: =IF(N17="","",INDEX(Batches!$J$1:$J$505,MOD(N17,1000))) | G17: =IF(O17="","",INDEX(Purchases!$C$1:$C$405,MOD(O17,1000))) | H17: =IF(O17="","",INDEX(Purchases!$G$1:$G$405,MOD(O17,1000))) | I17: =IF(O17="","",INDEX(Purchases!$H$1:$H$405,MOD(O17,1000))) | J17: =IF(O17="","",INDEX(Purchases!$K$1:$K$405,MOD(O17,1000))) | N17: =IFERROR(SMALL(Batches!$T$6:$T$505,10),"") | O17: =IFERROR(SMALL(Purchases!$L$6:$L$405,4),"")
B19: Month made | C19: Made | D19: Wasted | E19: Waste
B20: =CHOOSE(MONTH(DATE(YEAR(TODAY()),MONTH(TODAY())-11,1)),"Jan","Feb","Mar","Apr","May","Jun","Jul","Aug","Sep","Oct","Nov","Dec")&" "&YEAR(DATE(YEAR(TODAY()),MONTH(TODAY())-11,1)) | C20: =SUMIFS(Batches!$D$6:$D$505,Batches!$R$6:$R$505,M20) | D20: =SUMIFS(Batches!$G$6:$G$505,Batches!$R$6:$R$505,M20) | E20: =IF(C20=0,"",D20/C20) | M20: =YEAR(DATE(YEAR(TODAY()),MONTH(TODAY())-11,1))*100+MONTH(DATE(YEAR(TODAY()),MONTH(TODAY())-11,1))
B21: =CHOOSE(MONTH(DATE(YEAR(TODAY()),MONTH(TODAY())-10,1)),"Jan","Feb","Mar","Apr","May","Jun","Jul","Aug","Sep","Oct","Nov","Dec")&" "&YEAR(DATE(YEAR(TODAY()),MONTH(TODAY())-10,1)) | C21: =SUMIFS(Batches!$D$6:$D$505,Batches!$R$6:$R$505,M21) | D21: =SUMIFS(Batches!$G$6:$G$505,Batches!$R$6:$R$505,M21) | E21: =IF(C21=0,"",D21/C21) | M21: =YEAR(DATE(YEAR(TODAY()),MONTH(TODAY())-10,1))*100+MONTH(DATE(YEAR(TODAY()),MONTH(TODAY())-10,1))
B22: =CHOOSE(MONTH(DATE(YEAR(TODAY()),MONTH(TODAY())-9,1)),"Jan","Feb","Mar","Apr","May","Jun","Jul","Aug","Sep","Oct","Nov","Dec")&" "&YEAR(DATE(YEAR(TODAY()),MONTH(TODAY())-9,1)) | C22: =SUMIFS(Batches!$D$6:$D$505,Batches!$R$6:$R$505,M22) | D22: =SUMIFS(Batches!$G$6:$G$505,Batches!$R$6:$R$505,M22) | E22: =IF(C22=0,"",D22/C22) | M22: =YEAR(DATE(YEAR(TODAY()),MONTH(TODAY())-9,1))*100+MONTH(DATE(YEAR(TODAY()),MONTH(TODAY())-9,1))
B23: =CHOOSE(MONTH(DATE(YEAR(TODAY()),MONTH(TODAY())-8,1)),"Jan","Feb","Mar","Apr","May","Jun","Jul","Aug","Sep","Oct","Nov","Dec")&" "&YEAR(DATE(YEAR(TODAY()),MONTH(TODAY())-8,1)) | C23: =SUMIFS(Batches!$D$6:$D$505,Batches!$R$6:$R$505,M23) | D23: =SUMIFS(Batches!$G$6:$G$505,Batches!$R$6:$R$505,M23) | E23: =IF(C23=0,"",D23/C23) | M23: =YEAR(DATE(YEAR(TODAY()),MONTH(TODAY())-8,1))*100+MONTH(DATE(YEAR(TODAY()),MONTH(TODAY())-8,1))
B24: =CHOOSE(MONTH(DATE(YEAR(TODAY()),MONTH(TODAY())-7,1)),"Jan","Feb","Mar","Apr","May","Jun","Jul","Aug","Sep","Oct","Nov","Dec")&" "&YEAR(DATE(YEAR(TODAY()),MONTH(TODAY())-7,1)) | C24: =SUMIFS(Batches!$D$6:$D$505,Batches!$R$6:$R$505,M24) | D24: =SUMIFS(Batches!$G$6:$G$505,Batches!$R$6:$R$505,M24) | E24: =IF(C24=0,"",D24/C24) | M24: =YEAR(DATE(YEAR(TODAY()),MONTH(TODAY())-7,1))*100+MONTH(DATE(YEAR(TODAY()),MONTH(TODAY())-7,1))
B25: =CHOOSE(MONTH(DATE(YEAR(TODAY()),MONTH(TODAY())-6,1)),"Jan","Feb","Mar","Apr","May","Jun","Jul","Aug","Sep","Oct","Nov","Dec")&" "&YEAR(DATE(YEAR(TODAY()),MONTH(TODAY())-6,1)) | C25: =SUMIFS(Batches!$D$6:$D$505,Batches!$R$6:$R$505,M25) | D25: =SUMIFS(Batches!$G$6:$G$505,Batches!$R$6:$R$505,M25) | E25: =IF(C25=0,"",D25/C25) | M25: =YEAR(DATE(YEAR(TODAY()),MONTH(TODAY())-6,1))*100+MONTH(DATE(YEAR(TODAY()),MONTH(TODAY())-6,1))
B26: =CHOOSE(MONTH(DATE(YEAR(TODAY()),MONTH(TODAY())-5,1)),"Jan","Feb","Mar","Apr","May","Jun","Jul","Aug","Sep","Oct","Nov","Dec")&" "&YEAR(DATE(YEAR(TODAY()),MONTH(TODAY())-5,1)) | C26: =SUMIFS(Batches!$D$6:$D$505,Batches!$R$6:$R$505,M26) | D26: =SUMIFS(Batches!$G$6:$G$505,Batches!$R$6:$R$505,M26) | E26: =IF(C26=0,"",D26/C26) | M26: =YEAR(DATE(YEAR(TODAY()),MONTH(TODAY())-5,1))*100+MONTH(DATE(YEAR(TODAY()),MONTH(TODAY())-5,1))
B27: =CHOOSE(MONTH(DATE(YEAR(TODAY()),MONTH(TODAY())-4,1)),"Jan","Feb","Mar","Apr","May","Jun","Jul","Aug","Sep","Oct","Nov","Dec")&" "&YEAR(DATE(YEAR(TODAY()),MONTH(TODAY())-4,1)) | C27: =SUMIFS(Batches!$D$6:$D$505,Batches!$R$6:$R$505,M27) | D27: =SUMIFS(Batches!$G$6:$G$505,Batches!$R$6:$R$505,M27) | E27: =IF(C27=0,"",D27/C27) | M27: =YEAR(DATE(YEAR(TODAY()),MONTH(TODAY())-4,1))*100+MONTH(DATE(YEAR(TODAY()),MONTH(TODAY())-4,1))
B28: =CHOOSE(MONTH(DATE(YEAR(TODAY()),MONTH(TODAY())-3,1)),"Jan","Feb","Mar","Apr","May","Jun","Jul","Aug","Sep","Oct","Nov","Dec")&" "&YEAR(DATE(YEAR(TODAY()),MONTH(TODAY())-3,1)) | C28: =SUMIFS(Batches!$D$6:$D$505,Batches!$R$6:$R$505,M28) | D28: =SUMIFS(Batches!$G$6:$G$505,Batches!$R$6:$R$505,M28) | E28: =IF(C28=0,"",D28/C28) | M28: =YEAR(DATE(YEAR(TODAY()),MONTH(TODAY())-3,1))*100+MONTH(DATE(YEAR(TODAY()),MONTH(TODAY())-3,1))
B29: =CHOOSE(MONTH(DATE(YEAR(TODAY()),MONTH(TODAY())-2,1)),"Jan","Feb","Mar","Apr","May","Jun","Jul","Aug","Sep","Oct","Nov","Dec")&" "&YEAR(DATE(YEAR(TODAY()),MONTH(TODAY())-2,1)) | C29: =SUMIFS(Batches!$D$6:$D$505,Batches!$R$6:$R$505,M29) | D29: =SUMIFS(Batches!$G$6:$G$505,Batches!$R$6:$R$505,M29) | E29: =IF(C29=0,"",D29/C29) | M29: =YEAR(DATE(YEAR(TODAY()),MONTH(TODAY())-2,1))*100+MONTH(DATE(YEAR(TODAY()),MONTH(TODAY())-2,1))
B30: =CHOOSE(MONTH(DATE(YEAR(TODAY()),MONTH(TODAY())-1,1)),"Jan","Feb","Mar","Apr","May","Jun","Jul","Aug","Sep","Oct","Nov","Dec")&" "&YEAR(DATE(YEAR(TODAY()),MONTH(TODAY())-1,1)) | C30: =SUMIFS(Batches!$D$6:$D$505,Batches!$R$6:$R$505,M30) | D30: =SUMIFS(Batches!$G$6:$G$505,Batches!$R$6:$R$505,M30) | E30: =IF(C30=0,"",D30/C30) | M30: =YEAR(DATE(YEAR(TODAY()),MONTH(TODAY())-1,1))*100+MONTH(DATE(YEAR(TODAY()),MONTH(TODAY())-1,1))
B31: =CHOOSE(MONTH(DATE(YEAR(TODAY()),MONTH(TODAY())-0,1)),"Jan","Feb","Mar","Apr","May","Jun","Jul","Aug","Sep","Oct","Nov","Dec")&" "&YEAR(DATE(YEAR(TODAY()),MONTH(TODAY())-0,1)) | C31: =SUMIFS(Batches!$D$6:$D$505,Batches!$R$6:$R$505,M31) | D31: =SUMIFS(Batches!$G$6:$G$505,Batches!$R$6:$R$505,M31) | E31: =IF(C31=0,"",D31/C31) | M31: =YEAR(DATE(YEAR(TODAY()),MONTH(TODAY())-0,1))*100+MONTH(DATE(YEAR(TODAY()),MONTH(TODAY())-0,1))

Sheet Batches
B2: Batches
B3: One line for each batch you make. Update what was sold, given away and thrown out.
B5: Made on | C5: Product | D5: Made | E5: Sold | F5: Given or used | G5: Wasted | H5: Notes | I5: Batch code | J5: =Settings!$C$7 | K5: Left | L5: Days left | M5: Status | N5: Cost
B6: 45990 | C6: Chocolate chip cookies | D6: 8 | E6: 8 | F6: 0 | G6: 0 | I6: =IF(OR(C6="",NOT(ISNUMBER(B6))),"",UPPER(IF(IFERROR(IF(INDEX(Products!$C$6:$C$45,MATCH(C6,Products!$B$6:$B$45,0))="","",INDEX(Products!$C$6:$C$45,MATCH(C6,Products!$B$6:$B$45,0))),"")="",LEFT(SUBSTITUTE(C6," ",""),3),IFERROR(IF(INDEX(Products!$C$6:$C$45,MATCH(C6,Products!$B$6:$B$45,0))="","",INDEX(Products!$C$6:$C$45,MATCH(C6,Products!$B$6:$B$45,0))),"")))&"-"&RIGHT(YEAR(B6),2)&RIGHT("0"&MONTH(B6),2)&RIGHT("0"&DAY(B6),2)&"-"&COUNTIFS(C$6:C6,C6,B$6:B6,B6)) | J6: =IF(OR(C6="",NOT(ISNUMBER(B6)),N(P6)=0),"",B6+P6) | K6: =IF(C6="","",N(D6)-N(E6)-N(F6)-N(G6)) | L6: =IF(OR(C6="",N(K6)<=0,NOT(ISNUMBER(J6))),"",J6-TODAY()) | M6: =IF(C6="","",IF(N(K6)<=0,"Sold out",IF(NOT(ISNUMBER(J6)),"In stock",IF(J6<TODAY(),"Past its date",IF(J6-TODAY()<=Settings!$C$5,"Use soon","In stock"))))) | N6: =IF(C6="","",N(D6)*Q6) | P6: =IF(C6="",0,IFERROR(N(INDEX(Products!$E$6:$E$45,MATCH(C6,Products!$B$6:$B$45,0))),0)) | Q6: =IF(C6="",0,IFERROR(N(INDEX(Products!$I$6:$I$45,MATCH(C6,Products!$B$6:$B$45,0))),0)) | R6: =IF(OR(C6="",NOT(ISNUMBER(B6))),"",YEAR(B6)*100+MONTH(B6)) | S6: =N(G6)*Q6 | T6: =IF(OR(M6="",M6="Sold out",NOT(ISNUMBER(J6))),"",J6*1000+ROW())
B7: 45995 | C7: Lemon drizzle loaf | D7: 4 | E7: 3 | F7: 0 | G7: 1 | I7: =IF(OR(C7="",NOT(ISNUMBER(B7))),"",UPPER(IF(IFERROR(IF(INDEX(Products!$C$6:$C$45,MATCH(C7,Products!$B$6:$B$45,0))="","",INDEX(Products!$C$6:$C$45,MATCH(C7,Products!$B$6:$B$45,0))),"")="",LEFT(SUBSTITUTE(C7," ",""),3),IFERROR(IF(INDEX(Products!$C$6:$C$45,MATCH(C7,Products!$B$6:$B$45,0))="","",INDEX(Products!$C$6:$C$45,MATCH(C7,Products!$B$6:$B$45,0))),"")))&"-"&RIGHT(YEAR(B7),2)&RIGHT("0"&MONTH(B7),2)&RIGHT("0"&DAY(B7),2)&"-"&COUNTIFS(C$6:C7,C7,B$6:B7,B7)) | J7: =IF(OR(C7="",NOT(ISNUMBER(B7)),N(P7)=0),"",B7+P7) | K7: =IF(C7="","",N(D7)-N(E7)-N(F7)-N(G7)) | L7: =IF(OR(C7="",N(K7)<=0,NOT(ISNUMBER(J7))),"",J7-TODAY()) | M7: =IF(C7="","",IF(N(K7)<=0,"Sold out",IF(NOT(ISNUMBER(J7)),"In stock",IF(J7<TODAY(),"Past its date",IF(J7-TODAY()<=Settings!$C$5,"Use soon","In stock"))))) | N7: =IF(C7="","",N(D7)*Q7) | P7: =IF(C7="",0,IFERROR(N(INDEX(Products!$E$6:$E$45,MATCH(C7,Products!$B$6:$B$45,0))),0)) | Q7: =IF(C7="",0,IFERROR(N(INDEX(Products!$I$6:$I$45,MATCH(C7,Products!$B$6:$B$45,0))),0)) | R7: =IF(OR(C7="",NOT(ISNUMBER(B7))),"",YEAR(B7)*100+MONTH(B7)) | S7: =N(G7)*Q7 | T7: =IF(OR(M7="",M7="Sold out",NOT(ISNUMBER(J7))),"",J7*1000+ROW())
B8: 46005 | C8: Sourdough loaf | D8: 4 | E8: 4 | F8: 0 | G8: 0 | I8: =IF(OR(C8="",NOT(ISNUMBER(B8))),"",UPPER(IF(IFERROR(IF(INDEX(Products!$C$6:$C$45,MATCH(C8,Products!$B$6:$B$45,0))="","",INDEX(Products!$C$6:$C$45,MATCH(C8,Products!$B$6:$B$45,0))),"")="",LEFT(SUBSTITUTE(C8," ",""),3),IFERROR(IF(INDEX(Products!$C$6:$C$45,MATCH(C8,Products!$B$6:$B$45,0))="","",INDEX(Products!$C$6:$C$45,MATCH(C8,Products!$B$6:$B$45,0))),"")))&"-"&RIGHT(YEAR(B8),2)&RIGHT("0"&MONTH(B8),2)&RIGHT("0"&DAY(B8),2)&"-"&COUNTIFS(C$6:C8,C8,B$6:B8,B8)) | J8: =IF(OR(C8="",NOT(ISNUMBER(B8)),N(P8)=0),"",B8+P8) | K8: =IF(C8="","",N(D8)-N(E8)-N(F8)-N(G8)) | L8: =IF(OR(C8="",N(K8)<=0,NOT(ISNUMBER(J8))),"",J8-TODAY()) | M8: =IF(C8="","",IF(N(K8)<=0,"Sold out",IF(NOT(ISNUMBER(J8)),"In stock",IF(J8<TODAY(),"Past its date",IF(J8-TODAY()<=Settings!$C$5,"Use soon","In stock"))))) | N8: =IF(C8="","",N(D8)*Q8) | P8: =IF(C8="",0,IFERROR(N(INDEX(Products!$E$6:$E$45,MATCH(C8,Products!$B$6:$B$45,0))),0)) | Q8: =IF(C8="",0,IFERROR(N(INDEX(Products!$I$6:$I$45,MATCH(C8,Products!$B$6:$B$45,0))),0)) | R8: =IF(OR(C8="",NOT(ISNUMBER(B8))),"",YEAR(B8)*100+MONTH(B8)) | S8: =N(G8)*Q8 | T8: =IF(OR(M8="",M8="Sold out",NOT(ISNUMBER(J8))),"",J8*1000+ROW())
B9: 46010 | C9: Cinnamon rolls | D9: 12 | E9: 9 | F9: 0 | G9: 3 | I9: =IF(OR(C9="",NOT(ISNUMBER(B9))),"",UPPER(IF(IFERROR(IF(INDEX(Products!$C$6:$C$45,MATCH(C9,Products!$B$6:$B$45,0))="","",INDEX(Products!$C$6:$C$45,MATCH(C9,Products!$B$6:$B$45,0))),"")="",LEFT(SUBSTITUTE(C9," ",""),3),IFERROR(IF(INDEX(Products!$C$6:$C$45,MATCH(C9,Products!$B$6:$B$45,0))="","",INDEX(Products!$C$6:$C$45,MATCH(C9,Products!$B$6:$B$45,0))),"")))&"-"&RIGHT(YEAR(B9),2)&RIGHT("0"&MONTH(B9),2)&RIGHT("0"&DAY(B9),2)&"-"&COUNTIFS(C$6:C9,C9,B$6:B9,B9)) | J9: =IF(OR(C9="",NOT(ISNUMBER(B9)),N(P9)=0),"",B9+P9) | K9: =IF(C9="","",N(D9)-N(E9)-N(F9)-N(G9)) | L9: =IF(OR(C9="",N(K9)<=0,NOT(ISNUMBER(J9))),"",J9-TODAY()) | M9: =IF(C9="","",IF(N(K9)<=0,"Sold out",IF(NOT(ISNUMBER(J9)),"In stock",IF(J9<TODAY(),"Past its date",IF(J9-TODAY()<=Settings!$C$5,"Use soon","In stock"))))) | N9: =IF(C9="","",N(D9)*Q9) | P9: =IF(C9="",0,IFERROR(N(INDEX(Products!$E$6:$E$45,MATCH(C9,Products!$B$6:$B$45,0))),0)) | Q9: =IF(C9="",0,IFERROR(N(INDEX(Products!$I$6:$I$45,MATCH(C9,Products!$B$6:$B$45,0))),0)) | R9: =IF(OR(C9="",NOT(ISNUMBER(B9))),"",YEAR(B9)*100+MONTH(B9)) | S9: =N(G9)*Q9 | T9: =IF(OR(M9="",M9="Sold out",NOT(ISNUMBER(J9))),"",J9*1000+ROW())
B10: 46013 | C10: Strawberry jam | D10: 12 | E10: 12 | F10: 0 | G10: 0 | I10: =IF(OR(C10="",NOT(ISNUMBER(B10))),"",UPPER(IF(IFERROR(IF(INDEX(Products!$C$6:$C$45,MATCH(C10,Products!$B$6:$B$45,0))="","",INDEX(Products!$C$6:$C$45,MATCH(C10,Products!$B$6:$B$45,0))),"")="",LEFT(SUBSTITUTE(C10," ",""),3),IFERROR(IF(INDEX(Products!$C$6:$C$45,MATCH(C10,Products!$B$6:$B$45,0))="","",INDEX(Products!$C$6:$C$45,MATCH(C10,Products!$B$6:$B$45,0))),"")))&"-"&RIGHT(YEAR(B10),2)&RIGHT("0"&MONTH(B10),2)&RIGHT("0"&DAY(B10),2)&"-"&COUNTIFS(C$6:C10,C10,B$6:B10,B10)) | J10: =IF(OR(C10="",NOT(ISNUMBER(B10)),N(P10)=0),"",B10+P10) | K10: =IF(C10="","",N(D10)-N(E10)-N(F10)-N(G10)) | L10: =IF(OR(C10="",N(K10)<=0,NOT(ISNUMBER(J10))),"",J10-TODAY()) | M10: =IF(C10="","",IF(N(K10)<=0,"Sold out",IF(NOT(ISNUMBER(J10)),"In stock",IF(J10<TODAY(),"Past its date",IF(J10-TODAY()<=Settings!$C$5,"Use soon","In stock"))))) | N10: =IF(C10="","",N(D10)*Q10) | P10: =IF(C10="",0,IFERROR(N(INDEX(Products!$E$6:$E$45,MATCH(C10,Products!$B$6:$B$45,0))),0)) | Q10: =IF(C10="",0,IFERROR(N(INDEX(Products!$I$6:$I$45,MATCH(C10,Products!$B$6:$B$45,0))),0)) | R10: =IF(OR(C10="",NOT(ISNUMBER(B10))),"",YEAR(B10)*100+MONTH(B10)) | S10: =N(G10)*Q10 | T10: =IF(OR(M10="",M10="Sold out",NOT(ISNUMBER(J10))),"",J10*1000+ROW())
B11: 46025 | C11: Lemon drizzle loaf | D11: 4 | E11: 3 | F11: 0 | G11: 1 | I11: =IF(OR(C11="",NOT(ISNUMBER(B11))),"",UPPER(IF(IFERROR(IF(INDEX(Products!$C$6:$C$45,MATCH(C11,Products!$B$6:$B$45,0))="","",INDEX(Products!$C$6:$C$45,MATCH(C11,Products!$B$6:$B$45,0))),"")="",LEFT(SUBSTITUTE(C11," ",""),3),IFERROR(IF(INDEX(Products!$C$6:$C$45,MATCH(C11,Products!$B$6:$B$45,0))="","",INDEX(Products!$C$6:$C$45,MATCH(C11,Products!$B$6:$B$45,0))),"")))&"-"&RIGHT(YEAR(B11),2)&RIGHT("0"&MONTH(B11),2)&RIGHT("0"&DAY(B11),2)&"-"&COUNTIFS(C$6:C11,C11,B$6:B11,B11)) | J11: =IF(OR(C11="",NOT(ISNUMBER(B11)),N(P11)=0),"",B11+P11) | K11: =IF(C11="","",N(D11)-N(E11)-N(F11)-N(G11)) | L11: =IF(OR(C11="",N(K11)<=0,NOT(ISNUMBER(J11))),"",J11-TODAY()) | M11: =IF(C11="","",IF(N(K11)<=0,"Sold out",IF(NOT(ISNUMBER(J11)),"In stock",IF(J11<TODAY(),"Past its date",IF(J11-TODAY()<=Settings!$C$5,"Use soon","In stock"))))) | N11: =IF(C11="","",N(D11)*Q11) | P11: =IF(C11="",0,IFERROR(N(INDEX(Products!$E$6:$E$45,MATCH(C11,Products!$B$6:$B$45,0))),0)) | Q11: =IF(C11="",0,IFERROR(N(INDEX(Products!$I$6:$I$45,MATCH(C11,Products!$B$6:$B$45,0))),0)) | R11: =IF(OR(C11="",NOT(ISNUMBER(B11))),"",YEAR(B11)*100+MONTH(B11)) | S11: =N(G11)*Q11 | T11: =IF(OR(M11="",M11="Sold out",NOT(ISNUMBER(J11))),"",J11*1000+ROW())
B12: 46030 | C12: Brownies | D12: 16 | E12: 14 | F12: 0 | G12: 2 | I12: =IF(OR(C12="",NOT(ISNUMBER(B12))),"",UPPER(IF(IFERROR(IF(INDEX(Products!$C$6:$C$45,MATCH(C12,Products!$B$6:$B$45,0))="","",INDEX(Products!$C$6:$C$45,MATCH(C12,Products!$B$6:$B$45,0))),"")="",LEFT(SUBSTITUTE(C12," ",""),3),IFERROR(IF(INDEX(Products!$C$6:$C$45,MATCH(C12,Products!$B$6:$B$45,0))="","",INDEX(Products!$C$6:$C$45,MATCH(C12,Products!$B$6:$B$45,0))),"")))&"-"&RIGHT(YEAR(B12),2)&RIGHT("0"&MONTH(B12),2)&RIGHT("0"&DAY(B12),2)&"-"&COUNTIFS(C$6:C12,C12,B$6:B12,B12)) | J12: =IF(OR(C12="",NOT(ISNUMBER(B12)),N(P12)=0),"",B12+P12) | K12: =IF(C12="","",N(D12)-N(E12)-N(F12)-N(G12)) | L12: =IF(OR(C12="",N(K12)<=0,NOT(ISNUMBER(J12))),"",J12-TODAY()) | M12: =IF(C12="","",IF(N(K12)<=0,"Sold out",IF(NOT(ISNUMBER(J12)),"In stock",IF(J12<TODAY(),"Past its date",IF(J12-TODAY()<=Settings!$C$5,"Use soon","In stock"))))) | N12: =IF(C12="","",N(D12)*Q12) | P12: =IF(C12="",0,IFERROR(N(INDEX(Products!$E$6:$E$45,MATCH(C12,Products!$B$6:$B$45,0))),0)) | Q12: =IF(C12="",0,IFERROR(N(INDEX(Products!$I$6:$I$45,MATCH(C12,Products!$B$6:$B$45,0))),0)) | R12: =IF(OR(C12="",NOT(ISNUMBER(B12))),"",YEAR(B12)*100+MONTH(B12)) | S12: =N(G12)*Q12 | T12: =IF(OR(M12="",M12="Sold out",NOT(ISNUMBER(J12))),"",J12*1000+ROW())
B13: 46040 | C13: Cinnamon rolls | D13: 12 | E13: 9 | F13: 0 | G13: 3 | I13: =IF(OR(C13="",NOT(ISNUMBER(B13))),"",UPPER(IF(IFERROR(IF(INDEX(Products!$C$6:$C$45,MATCH(C13,Products!$B$6:$B$45,0))="","",INDEX(Products!$C$6:$C$45,MATCH(C13,Products!$B$6:$B$45,0))),"")="",LEFT(SUBSTITUTE(C13," ",""),3),IFERROR(IF(INDEX(Products!$C$6:$C$45,MATCH(C13,Products!$B$6:$B$45,0))="","",INDEX(Products!$C$6:$C$45,MATCH(C13,Products!$B$6:$B$45,0))),"")))&"-"&RIGHT(YEAR(B13),2)&RIGHT("0"&MONTH(B13),2)&RIGHT("0"&DAY(B13),2)&"-"&COUNTIFS(C$6:C13,C13,B$6:B13,B13)) | J13: =IF(OR(C13="",NOT(ISNUMBER(B13)),N(P13)=0),"",B13+P13) | K13: =IF(C13="","",N(D13)-N(E13)-N(F13)-N(G13)) | L13: =IF(OR(C13="",N(K13)<=0,NOT(ISNUMBER(J13))),"",J13-TODAY()) | M13: =IF(C13="","",IF(N(K13)<=0,"Sold out",IF(NOT(ISNUMBER(J13)),"In stock",IF(J13<TODAY(),"Past its date",IF(J13-TODAY()<=Settings!$C$5,"Use soon","In stock"))))) | N13: =IF(C13="","",N(D13)*Q13) | P13: =IF(C13="",0,IFERROR(N(INDEX(Products!$E$6:$E$45,MATCH(C13,Products!$B$6:$B$45,0))),0)) | Q13: =IF(C13="",0,IFERROR(N(INDEX(Products!$I$6:$I$45,MATCH(C13,Products!$B$6:$B$45,0))),0)) | R13: =IF(OR(C13="",NOT(ISNUMBER(B13))),"",YEAR(B13)*100+MONTH(B13)) | S13: =N(G13)*Q13 | T13: =IF(OR(M13="",M13="Sold out",NOT(ISNUMBER(J13))),"",J13*1000+ROW())
B14: 46041 | C14: Granola | D14: 10 | E14: 9 | F14: 1 | G14: 0 | I14: =IF(OR(C14="",NOT(ISNUMBER(B14))),"",UPPER(IF(IFERROR(IF(INDEX(Products!$C$6:$C$45,MATCH(C14,Products!$B$6:$B$45,0))="","",INDEX(Products!$C$6:$C$45,MATCH(C14,Products!$B$6:$B$45,0))),"")="",LEFT(SUBSTITUTE(C14," ",""),3),IFERROR(IF(INDEX(Products!$C$6:$C$45,MATCH(C14,Products!$B$6:$B$45,0))="","",INDEX(Products!$C$6:$C$45,MATCH(C14,Products!$B$6:$B$45,0))),"")))&"-"&RIGHT(YEAR(B14),2)&RIGHT("0"&MONTH(B14),2)&RIGHT("0"&DAY(B14),2)&"-"&COUNTIFS(C$6:C14,C14,B$6:B14,B14)) | J14: =IF(OR(C14="",NOT(ISNUMBER(B14)),N(P14)=0),"",B14+P14) | K14: =IF(C14="","",N(D14)-N(E14)-N(F14)-N(G14)) | L14: =IF(OR(C14="",N(K14)<=0,NOT(ISNUMBER(J14))),"",J14-TODAY()) | M14: =IF(C14="","",IF(N(K14)<=0,"Sold out",IF(NOT(ISNUMBER(J14)),"In stock",IF(J14<TODAY(),"Past its date",IF(J14-TODAY()<=Settings!$C$5,"Use soon","In stock"))))) | N14: =IF(C14="","",N(D14)*Q14) | P14: =IF(C14="",0,IFERROR(N(INDEX(Products!$E$6:$E$45,MATCH(C14,Products!$B$6:$B$45,0))),0)) | Q14: =IF(C14="",0,IFERROR(N(INDEX(Products!$I$6:$I$45,MATCH(C14,Products!$B$6:$B$45,0))),0)) | R14: =IF(OR(C14="",NOT(ISNUMBER(B14))),"",YEAR(B14)*100+MONTH(B14)) | S14: =N(G14)*Q14 | T14: =IF(OR(M14="",M14="Sold out",NOT(ISNUMBER(J14))),"",J14*1000+ROW())
B15: 46050 | C15: Chocolate chip cookies | D15: 8 | E15: 8 | F15: 0 | G15: 0 | I15: =IF(OR(C15="",NOT(ISNUMBER(B15))),"",UPPER(IF(IFERROR(IF(INDEX(Products!$C$6:$C$45,MATCH(C15,Products!$B$6:$B$45,0))="","",INDEX(Products!$C$6:$C$45,MATCH(C15,Products!$B$6:$B$45,0))),"")="",LEFT(SUBSTITUTE(C15," ",""),3),IFERROR(IF(INDEX(Products!$C$6:$C$45,MATCH(C15,Products!$B$6:$B$45,0))="","",INDEX(Products!$C$6:$C$45,MATCH(C15,Products!$B$6:$B$45,0))),"")))&"-"&RIGHT(YEAR(B15),2)&RIGHT("0"&MONTH(B15),2)&RIGHT("0"&DAY(B15),2)&"-"&COUNTIFS(C$6:C15,C15,B$6:B15,B15)) | J15: =IF(OR(C15="",NOT(ISNUMBER(B15)),N(P15)=0),"",B15+P15) | K15: =IF(C15="","",N(D15)-N(E15)-N(F15)-N(G15)) | L15: =IF(OR(C15="",N(K15)<=0,NOT(ISNUMBER(J15))),"",J15-TODAY()) | M15: =IF(C15="","",IF(N(K15)<=0,"Sold out",IF(NOT(ISNUMBER(J15)),"In stock",IF(J15<TODAY(),"Past its date",IF(J15-TODAY()<=Settings!$C$5,"Use soon","In stock"))))) | N15: =IF(C15="","",N(D15)*Q15) | P15: =IF(C15="",0,IFERROR(N(INDEX(Products!$E$6:$E$45,MATCH(C15,Products!$B$6:$B$45,0))),0)) | Q15: =IF(C15="",0,IFERROR(N(INDEX(Products!$I$6:$I$45,MATCH(C15,Products!$B$6:$B$45,0))),0)) | R15: =IF(OR(C15="",NOT(ISNUMBER(B15))),"",YEAR(B15)*100+MONTH(B15)) | S15: =N(G15)*Q15 | T15: =IF(OR(M15="",M15="Sold out",NOT(ISNUMBER(J15))),"",J15*1000+ROW())
B16: 46060 | C16: Brownies | D16: 16 | E16: 15 | F16: 0 | G16: 1 | I16: =IF(OR(C16="",NOT(ISNUMBER(B16))),"",UPPER(IF(IFERROR(IF(INDEX(Products!$C$6:$C$45,MATCH(C16,Products!$B$6:$B$45,0))="","",INDEX(Products!$C$6:$C$45,MATCH(C16,Products!$B$6:$B$45,0))),"")="",LEFT(SUBSTITUTE(C16," ",""),3),IFERROR(IF(INDEX(Products!$C$6:$C$45,MATCH(C16,Products!$B$6:$B$45,0))="","",INDEX(Products!$C$6:$C$45,MATCH(C16,Products!$B$6:$B$45,0))),"")))&"-"&RIGHT(YEAR(B16),2)&RIGHT("0"&MONTH(B16),2)&RIGHT("0"&DAY(B16),2)&"-"&COUNTIFS(C$6:C16,C16,B$6:B16,B16)) | J16: =IF(OR(C16="",NOT(ISNUMBER(B16)),N(P16)=0),"",B16+P16) | K16: =IF(C16="","",N(D16)-N(E16)-N(F16)-N(G16)) | L16: =IF(OR(C16="",N(K16)<=0,NOT(ISNUMBER(J16))),"",J16-TODAY()) | M16: =IF(C16="","",IF(N(K16)<=0,"Sold out",IF(NOT(ISNUMBER(J16)),"In stock",IF(J16<TODAY(),"Past its date",IF(J16-TODAY()<=Settings!$C$5,"Use soon","In stock"))))) | N16: =IF(C16="","",N(D16)*Q16) | P16: =IF(C16="",0,IFERROR(N(INDEX(Products!$E$6:$E$45,MATCH(C16,Products!$B$6:$B$45,0))),0)) | Q16: =IF(C16="",0,IFERROR(N(INDEX(Products!$I$6:$I$45,MATCH(C16,Products!$B$6:$B$45,0))),0)) | R16: =IF(OR(C16="",NOT(ISNUMBER(B16))),"",YEAR(B16)*100+MONTH(B16)) | S16: =N(G16)*Q16 | T16: =IF(OR(M16="",M16="Sold out",NOT(ISNUMBER(J16))),"",J16*1000+ROW())
B17: 46065 | C17: Sourdough loaf | D17: 4 | E17: 4 | F17: 0 | G17: 0 | I17: =IF(OR(C17="",NOT(ISNUMBER(B17))),"",UPPER(IF(IFERROR(IF(INDEX(Products!$C$6:$C$45,MATCH(C17,Products!$B$6:$B$45,0))="","",INDEX(Products!$C$6:$C$45,MATCH(C17,Products!$B$6:$B$45,0))),"")="",LEFT(SUBSTITUTE(C17," ",""),3),IFERROR(IF(INDEX(Products!$C$6:$C$45,MATCH(C17,Products!$B$6:$B$45,0))="","",INDEX(Products!$C$6:$C$45,MATCH(C17,Products!$B$6:$B$45,0))),"")))&"-"&RIGHT(YEAR(B17),2)&RIGHT("0"&MONTH(B17),2)&RIGHT("0"&DAY(B17),2)&"-"&COUNTIFS(C$6:C17,C17,B$6:B17,B17)) | J17: =IF(OR(C17="",NOT(ISNUMBER(B17)),N(P17)=0),"",B17+P17) | K17: =IF(C17="","",N(D17)-N(E17)-N(F17)-N(G17)) | L17: =IF(OR(C17="",N(K17)<=0,NOT(ISNUMBER(J17))),"",J17-TODAY()) | M17: =IF(C17="","",IF(N(K17)<=0,"Sold out",IF(NOT(ISNUMBER(J17)),"In stock",IF(J17<TODAY(),"Past its date",IF(J17-TODAY()<=Settings!$C$5,"Use soon","In stock"))))) | N17: =IF(C17="","",N(D17)*Q17) | P17: =IF(C17="",0,IFERROR(N(INDEX(Products!$E$6:$E$45,MATCH(C17,Products!$B$6:$B$45,0))),0)) | Q17: =IF(C17="",0,IFERROR(N(INDEX(Products!$I$6:$I$45,MATCH(C17,Products!$B$6:$B$45,0))),0)) | R17: =IF(OR(C17="",NOT(ISNUMBER(B17))),"",YEAR(B17)*100+MONTH(B17)) | S17: =N(G17)*Q17 | T17: =IF(OR(M17="",M17="Sold out",NOT(ISNUMBER(J17))),"",J17*1000+ROW())
... B42: 46245 | C42: Sourdough loaf | D42: 4 | E42: 4 | F42: 0 | G42: 0 | I42: =IF(OR(C42="",NOT(ISNUMBER(B42))),"",UPPER(IF(IFERROR(IF(INDEX(Products!$C$6:$C$45,MATCH(C42,Products!$B$6:$B$45,0))="","",INDEX(Products!$C$6:$C$45,MATCH(C42,Products!$B$6:$B$45,0))),"")="",LEFT(SUBSTITUTE(C42," ",""),3),IFERROR(IF(INDEX(Products!$C$6:$C$45,MATCH(C42,Products!$B$6:$B$45,0))="","",INDEX(Products!$C$6:$C$45,MATCH(C42,Products!$B$6:$B$45,0))),"")))&"-"&RIGHT(YEAR(B42),2)&RIGHT("0"&MONTH(B42),2)&RIGHT("0"&DAY(B42),2)&"-"&COUNTIFS(C$6:C42,C42,B$6:B42,B42)) | J42: =IF(OR(C42="",NOT(ISNUMBER(B42)),N(P42)=0),"",B42+P42) | K42: =IF(C42="","",N(D42)-N(E42)-N(F42)-N(G42)) | L42: =IF(OR(C42="",N(K42)<=0,NOT(ISNUMBER(J42))),"",J42-TODAY()) | M42: =IF(C42="","",IF(N(K42)<=0,"Sold out",IF(NOT(ISNUMBER(J42)),"In stock",IF(J42<TODAY(),"Past its date",IF(J42-TODAY()<=Settings!$C$5,"Use soon","In stock"))))) | N42: =IF(C42="","",N(D42)*Q42) | P42: =IF(C42="",0,IFERROR(N(INDEX(Products!$E$6:$E$45,MATCH(C42,Products!$B$6:$B$45,0))),0)) | Q42: =IF(C42="",0,IFERROR(N(INDEX(Products!$I$6:$I$45,MATCH(C42,Products!$B$6:$B$45,0))),0)) | R42: =IF(OR(C42="",NOT(ISNUMBER(B42))),"",YEAR(B42)*100+MONTH(B42)) | S42: =N(G42)*Q42 | T42: =IF(OR(M42="",M42="Sold out",NOT(ISNUMBER(J42))),"",J42*1000+ROW())
B43: 46253 | C43: Strawberry jam | D43: 12 | E43: 7 | F43: 1 | G43: 0 | H43: Strawberries lot B-2207 | I43: =IF(OR(C43="",NOT(ISNUMBER(B43))),"",UPPER(IF(IFERROR(IF(INDEX(Products!$C$6:$C$45,MATCH(C43,Products!$B$6:$B$45,0))="","",INDEX(Products!$C$6:$C$45,MATCH(C43,Products!$B$6:$B$45,0))),"")="",LEFT(SUBSTITUTE(C43," ",""),3),IFERROR(IF(INDEX(Products!$C$6:$C$45,MATCH(C43,Products!$B$6:$B$45,0))="","",INDEX(Products!$C$6:$C$45,MATCH(C43,Products!$B$6:$B$45,0))),"")))&"-"&RIGHT(YEAR(B43),2)&RIGHT("0"&MONTH(B43),2)&RIGHT("0"&DAY(B43),2)&"-"&COUNTIFS(C$6:C43,C43,B$6:B43,B43)) | J43: =IF(OR(C43="",NOT(ISNUMBER(B43)),N(P43)=0),"",B43+P43) | K43: =IF(C43="","",N(D43)-N(E43)-N(F43)-N(G43)) | L43: =IF(OR(C43="",N(K43)<=0,NOT(ISNUMBER(J43))),"",J43-TODAY()) | M43: =IF(C43="","",IF(N(K43)<=0,"Sold out",IF(NOT(ISNUMBER(J43)),"In stock",IF(J43<TODAY(),"Past its date",IF(J43-TODAY()<=Settings!$C$5,"Use soon","In stock"))))) | N43: =IF(C43="","",N(D43)*Q43) | P43: =IF(C43="",0,IFERROR(N(INDEX(Products!$E$6:$E$45,MATCH(C43,Products!$B$6:$B$45,0))),0)) | Q43: =IF(C43="",0,IFERROR(N(INDEX(Products!$I$6:$I$45,MATCH(C43,Products!$B$6:$B$45,0))),0)) | R43: =IF(OR(C43="",NOT(ISNUMBER(B43))),"",YEAR(B43)*100+MONTH(B43)) | S43: =N(G43)*Q43 | T43: =IF(OR(M43="",M43="Sold out",NOT(ISNUMBER(J43))),"",J43*1000+ROW())
B44: 46258 | C44: Dog biscuits | D44: 10 | E44: 8 | F44: 0 | G44: 0 | I44: =IF(OR(C44="",NOT(ISNUMBER(B44))),"",UPPER(IF(IFERROR(IF(INDEX(Products!$C$6:$C$45,MATCH(C44,Products!$B$6:$B$45,0))="","",INDEX(Products!$C$6:$C$45,MATCH(C44,Products!$B$6:$B$45,0))),"")="",LEFT(SUBSTITUTE(C44," ",""),3),IFERROR(IF(INDEX(Products!$C$6:$C$45,MATCH(C44,Products!$B$6:$B$45,0))="","",INDEX(Products!$C$6:$C$45,MATCH(C44,Products!$B$6:$B$45,0))),"")))&"-"&RIGHT(YEAR(B44),2)&RIGHT("0"&MONTH(B44),2)&RIGHT("0"&DAY(B44),2)&"-"&COUNTIFS(C$6:C44,C44,B$6:B44,B44)) | J44: =IF(OR(C44="",NOT(ISNUMBER(B44)),N(P44)=0),"",B44+P44) | K44: =IF(C44="","",N(D44)-N(E44)-N(F44)-N(G44)) | L44: =IF(OR(C44="",N(K44)<=0,NOT(ISNUMBER(J44))),"",J44-TODAY()) | M44: =IF(C44="","",IF(N(K44)<=0,"Sold out",IF(NOT(ISNUMBER(J44)),"In stock",IF(J44<TODAY(),"Past its date",IF(J44-TODAY()<=Settings!$C$5,"Use soon","In stock"))))) | N44: =IF(C44="","",N(D44)*Q44) | P44: =IF(C44="",0,IFERROR(N(INDEX(Products!$E$6:$E$45,MATCH(C44,Products!$B$6:$B$45,0))),0)) | Q44: =IF(C44="",0,IFERROR(N(INDEX(Products!$I$6:$I$45,MATCH(C44,Products!$B$6:$B$45,0))),0)) | R44: =IF(OR(C44="",NOT(ISNUMBER(B44))),"",YEAR(B44)*100+MONTH(B44)) | S44: =N(G44)*Q44 | T44: =IF(OR(M44="",M44="Sold out",NOT(ISNUMBER(J44))),"",J44*1000+ROW())
B45: 46260 | C45: Chocolate chip cookies | D45: 8 | E45: 8 | F45: 0 | G45: 0 | I45: =IF(OR(C45="",NOT(ISNUMBER(B45))),"",UPPER(IF(IFERROR(IF(INDEX(Products!$C$6:$C$45,MATCH(C45,Products!$B$6:$B$45,0))="","",INDEX(Products!$C$6:$C$45,MATCH(C45,Products!$B$6:$B$45,0))),"")="",LEFT(SUBSTITUTE(C45," ",""),3),IFERROR(IF(INDEX(Products!$C$6:$C$45,MATCH(C45,Products!$B$6:$B$45,0))="","",INDEX(Products!$C$6:$C$45,MATCH(C45,Products!$B$6:$B$45,0))),"")))&"-"&RIGHT(YEAR(B45),2)&RIGHT("0"&MONTH(B45),2)&RIGHT("0"&DAY(B45),2)&"-"&COUNTIFS(C$6:C45,C45,B$6:B45,B45)) | J45: =IF(OR(C45="",NOT(ISNUMBER(B45)),N(P45)=0),"",B45+P45) | K45: =IF(C45="","",N(D45)-N(E45)-N(F45)-N(G45)) | L45: =IF(OR(C45="",N(K45)<=0,NOT(ISNUMBER(J45))),"",J45-TODAY()) | M45: =IF(C45="","",IF(N(K45)<=0,"Sold out",IF(NOT(ISNUMBER(J45)),"In stock",IF(J45<TODAY(),"Past its date",IF(J45-TODAY()<=Settings!$C$5,"Use soon","In stock"))))) | N45: =IF(C45="","",N(D45)*Q45) | P45: =IF(C45="",0,IFERROR(N(INDEX(Products!$E$6:$E$45,MATCH(C45,Products!$B$6:$B$45,0))),0)) | Q45: =IF(C45="",0,IFERROR(N(INDEX(Products!$I$6:$I$45,MATCH(C45,Products!$B$6:$B$45,0))),0)) | R45: =IF(OR(C45="",NOT(ISNUMBER(B45))),"",YEAR(B45)*100+MONTH(B45)) | S45: =N(G45)*Q45 | T45: =IF(OR(M45="",M45="Sold out",NOT(ISNUMBER(J45))),"",J45*1000+ROW())
B46: 46265 | C46: Lemon drizzle loaf | D46: 4 | E46: 3 | F46: 0 | G46: 1 | I46: =IF(OR(C46="",NOT(ISNUMBER(B46))),"",UPPER(IF(IFERROR(IF(INDEX(Products!$C$6:$C$45,MATCH(C46,Products!$B$6:$B$45,0))="","",INDEX(Products!$C$6:$C$45,MATCH(C46,Products!$B$6:$B$45,0))),"")="",LEFT(SUBSTITUTE(C46," ",""),3),IFERROR(IF(INDEX(Products!$C$6:$C$45,MATCH(C46,Products!$B$6:$B$45,0))="","",INDEX(Products!$C$6:$C$45,MATCH(C46,Products!$B$6:$B$45,0))),"")))&"-"&RIGHT(YEAR(B46),2)&RIGHT("0"&MONTH(B46),2)&RIGHT("0"&DAY(B46),2)&"-"&COUNTIFS(C$6:C46,C46,B$6:B46,B46)) | J46: =IF(OR(C46="",NOT(ISNUMBER(B46)),N(P46)=0),"",B46+P46) | K46: =IF(C46="","",N(D46)-N(E46)-N(F46)-N(G46)) | L46: =IF(OR(C46="",N(K46)<=0,NOT(ISNUMBER(J46))),"",J46-TODAY()) | M46: =IF(C46="","",IF(N(K46)<=0,"Sold out",IF(NOT(ISNUMBER(J46)),"In stock",IF(J46<TODAY(),"Past its date",IF(J46-TODAY()<=Settings!$C$5,"Use soon","In stock"))))) | N46: =IF(C46="","",N(D46)*Q46) | P46: =IF(C46="",0,IFERROR(N(INDEX(Products!$E$6:$E$45,MATCH(C46,Products!$B$6:$B$45,0))),0)) | Q46: =IF(C46="",0,IFERROR(N(INDEX(Products!$I$6:$I$45,MATCH(C46,Products!$B$6:$B$45,0))),0)) | R46: =IF(OR(C46="",NOT(ISNUMBER(B46))),"",YEAR(B46)*100+MONTH(B46)) | S46: =N(G46)*Q46 | T46: =IF(OR(M46="",M46="Sold out",NOT(ISNUMBER(J46))),"",J46*1000+ROW())
B47: 46273 | C47: Granola | D47: 10 | E47: 6 | F47: 0 | G47: 0 | I47: =IF(OR(C47="",NOT(ISNUMBER(B47))),"",UPPER(IF(IFERROR(IF(INDEX(Products!$C$6:$C$45,MATCH(C47,Products!$B$6:$B$45,0))="","",INDEX(Products!$C$6:$C$45,MATCH(C47,Products!$B$6:$B$45,0))),"")="",LEFT(SUBSTITUTE(C47," ",""),3),IFERROR(IF(INDEX(Products!$C$6:$C$45,MATCH(C47,Products!$B$6:$B$45,0))="","",INDEX(Products!$C$6:$C$45,MATCH(C47,Products!$B$6:$B$45,0))),"")))&"-"&RIGHT(YEAR(B47),2)&RIGHT("0"&MONTH(B47),2)&RIGHT("0"&DAY(B47),2)&"-"&COUNTIFS(C$6:C47,C47,B$6:B47,B47)) | J47: =IF(OR(C47="",NOT(ISNUMBER(B47)),N(P47)=0),"",B47+P47) | K47: =IF(C47="","",N(D47)-N(E47)-N(F47)-N(G47)) | L47: =IF(OR(C47="",N(K47)<=0,NOT(ISNUMBER(J47))),"",J47-TODAY()) | M47: =IF(C47="","",IF(N(K47)<=0,"Sold out",IF(NOT(ISNUMBER(J47)),"In stock",IF(J47<TODAY(),"Past its date",IF(J47-TODAY()<=Settings!$C$5,"Use soon","In stock"))))) | N47: =IF(C47="","",N(D47)*Q47) | P47: =IF(C47="",0,IFERROR(N(INDEX(Products!$E$6:$E$45,MATCH(C47,Products!$B$6:$B$45,0))),0)) | Q47: =IF(C47="",0,IFERROR(N(INDEX(Products!$I$6:$I$45,MATCH(C47,Products!$B$6:$B$45,0))),0)) | R47: =IF(OR(C47="",NOT(ISNUMBER(B47))),"",YEAR(B47)*100+MONTH(B47)) | S47: =N(G47)*Q47 | T47: =IF(OR(M47="",M47="Sold out",NOT(ISNUMBER(J47))),"",J47*1000+ROW())
B48: 46275 | C48: Sourdough loaf | D48: 4 | E48: 4 | F48: 0 | G48: 0 | I48: =IF(OR(C48="",NOT(ISNUMBER(B48))),"",UPPER(IF(IFERROR(IF(INDEX(Products!$C$6:$C$45,MATCH(C48,Products!$B$6:$B$45,0))="","",INDEX(Products!$C$6:$C$45,MATCH(C48,Products!$B$6:$B$45,0))),"")="",LEFT(SUBSTITUTE(C48," ",""),3),IFERROR(IF(INDEX(Products!$C$6:$C$45,MATCH(C48,Products!$B$6:$B$45,0))="","",INDEX(Products!$C$6:$C$45,MATCH(C48,Products!$B$6:$B$45,0))),"")))&"-"&RIGHT(YEAR(B48),2)&RIGHT("0"&MONTH(B48),2)&RIGHT("0"&DAY(B48),2)&"-"&COUNTIFS(C$6:C48,C48,B$6:B48,B48)) | J48: =IF(OR(C48="",NOT(ISNUMBER(B48)),N(P48)=0),"",B48+P48) | K48: =IF(C48="","",N(D48)-N(E48)-N(F48)-N(G48)) | L48: =IF(OR(C48="",N(K48)<=0,NOT(ISNUMBER(J48))),"",J48-TODAY()) | M48: =IF(C48="","",IF(N(K48)<=0,"Sold out",IF(NOT(ISNUMBER(J48)),"In stock",IF(J48<TODAY(),"Past its date",IF(J48-TODAY()<=Settings!$C$5,"Use soon","In stock"))))) | N48: =IF(C48="","",N(D48)*Q48) | P48: =IF(C48="",0,IFERROR(N(INDEX(Products!$E$6:$E$45,MATCH(C48,Products!$B$6:$B$45,0))),0)) | Q48: =IF(C48="",0,IFERROR(N(INDEX(Products!$I$6:$I$45,MATCH(C48,Products!$B$6:$B$45,0))),0)) | R48: =IF(OR(C48="",NOT(ISNUMBER(B48))),"",YEAR(B48)*100+MONTH(B48)) | S48: =N(G48)*Q48 | T48: =IF(OR(M48="",M48="Sold out",NOT(ISNUMBER(J48))),"",J48*1000+ROW())
B49: 46280 | C49: Cinnamon rolls | D49: 12 | E49: 9 | F49: 0 | G49: 3 | I49: =IF(OR(C49="",NOT(ISNUMBER(B49))),"",UPPER(IF(IFERROR(IF(INDEX(Products!$C$6:$C$45,MATCH(C49,Products!$B$6:$B$45,0))="","",INDEX(Products!$C$6:$C$45,MATCH(C49,Products!$B$6:$B$45,0))),"")="",LEFT(SUBSTITUTE(C49," ",""),3),IFERROR(IF(INDEX(Products!$C$6:$C$45,MATCH(C49,Products!$B$6:$B$45,0))="","",INDEX(Products!$C$6:$C$45,MATCH(C49,Products!$B$6:$B$45,0))),"")))&"-"&RIGHT(YEAR(B49),2)&RIGHT("0"&MONTH(B49),2)&RIGHT("0"&DAY(B49),2)&"-"&COUNTIFS(C$6:C49,C49,B$6:B49,B49)) | J49: =IF(OR(C49="",NOT(ISNUMBER(B49)),N(P49)=0),"",B49+P49) | K49: =IF(C49="","",N(D49)-N(E49)-N(F49)-N(G49)) | L49: =IF(OR(C49="",N(K49)<=0,NOT(ISNUMBER(J49))),"",J49-TODAY()) | M49: =IF(C49="","",IF(N(K49)<=0,"Sold out",IF(NOT(ISNUMBER(J49)),"In stock",IF(J49<TODAY(),"Past its date",IF(J49-TODAY()<=Settings!$C$5,"Use soon","In stock"))))) | N49: =IF(C49="","",N(D49)*Q49) | P49: =IF(C49="",0,IFERROR(N(INDEX(Products!$E$6:$E$45,MATCH(C49,Products!$B$6:$B$45,0))),0)) | Q49: =IF(C49="",0,IFERROR(N(INDEX(Products!$I$6:$I$45,MATCH(C49,Products!$B$6:$B$45,0))),0)) | R49: =IF(OR(C49="",NOT(ISNUMBER(B49))),"",YEAR(B49)*100+MONTH(B49)) | S49: =N(G49)*Q49 | T49: =IF(OR(M49="",M49="Sold out",NOT(ISNUMBER(J49))),"",J49*1000+ROW())
B50: 46285 | C50: Brownies | D50: 16 | E50: 13 | F50: 0 | G50: 3 | I50: =IF(OR(C50="",NOT(ISNUMBER(B50))),"",UPPER(IF(IFERROR(IF(INDEX(Products!$C$6:$C$45,MATCH(C50,Products!$B$6:$B$45,0))="","",INDEX(Products!$C$6:$C$45,MATCH(C50,Products!$B$6:$B$45,0))),"")="",LEFT(SUBSTITUTE(C50," ",""),3),IFERROR(IF(INDEX(Products!$C$6:$C$45,MATCH(C50,Products!$B$6:$B$45,0))="","",INDEX(Products!$C$6:$C$45,MATCH(C50,Products!$B$6:$B$45,0))),"")))&"-"&RIGHT(YEAR(B50),2)&RIGHT("0"&MONTH(B50),2)&RIGHT("0"&DAY(B50),2)&"-"&COUNTIFS(C$6:C50,C50,B$6:B50,B50)) | J50: =IF(OR(C50="",NOT(ISNUMBER(B50)),N(P50)=0),"",B50+P50) | K50: =IF(C50="","",N(D50)-N(E50)-N(F50)-N(G50)) | L50: =IF(OR(C50="",N(K50)<=0,NOT(ISNUMBER(J50))),"",J50-TODAY()) | M50: =IF(C50="","",IF(N(K50)<=0,"Sold out",IF(NOT(ISNUMBER(J50)),"In stock",IF(J50<TODAY(),"Past its date",IF(J50-TODAY()<=Settings!$C$5,"Use soon","In stock"))))) | N50: =IF(C50="","",N(D50)*Q50) | P50: =IF(C50="",0,IFERROR(N(INDEX(Products!$E$6:$E$45,MATCH(C50,Products!$B$6:$B$45,0))),0)) | Q50: =IF(C50="",0,IFERROR(N(INDEX(Products!$I$6:$I$45,MATCH(C50,Products!$B$6:$B$45,0))),0)) | R50: =IF(OR(C50="",NOT(ISNUMBER(B50))),"",YEAR(B50)*100+MONTH(B50)) | S50: =N(G50)*Q50 | T50: =IF(OR(M50="",M50="Sold out",NOT(ISNUMBER(J50))),"",J50*1000+ROW())
B51: 46289 | C51: Brownies | D51: 16 | E51: 10 | F51: 2 | G51: 0 | I51: =IF(OR(C51="",NOT(ISNUMBER(B51))),"",UPPER(IF(IFERROR(IF(INDEX(Products!$C$6:$C$45,MATCH(C51,Products!$B$6:$B$45,0))="","",INDEX(Products!$C$6:$C$45,MATCH(C51,Products!$B$6:$B$45,0))),"")="",LEFT(SUBSTITUTE(C51," ",""),3),IFERROR(IF(INDEX(Products!$C$6:$C$45,MATCH(C51,Products!$B$6:$B$45,0))="","",INDEX(Products!$C$6:$C$45,MATCH(C51,Products!$B$6:$B$45,0))),"")))&"-"&RIGHT(YEAR(B51),2)&RIGHT("0"&MONTH(B51),2)&RIGHT("0"&DAY(B51),2)&"-"&COUNTIFS(C$6:C51,C51,B$6:B51,B51)) | J51: =IF(OR(C51="",NOT(ISNUMBER(B51)),N(P51)=0),"",B51+P51) | K51: =IF(C51="","",N(D51)-N(E51)-N(F51)-N(G51)) | L51: =IF(OR(C51="",N(K51)<=0,NOT(ISNUMBER(J51))),"",J51-TODAY()) | M51: =IF(C51="","",IF(N(K51)<=0,"Sold out",IF(NOT(ISNUMBER(J51)),"In stock",IF(J51<TODAY(),"Past its date",IF(J51-TODAY()<=Settings!$C$5,"Use soon","In stock"))))) | N51: =IF(C51="","",N(D51)*Q51) | P51: =IF(C51="",0,IFERROR(N(INDEX(Products!$E$6:$E$45,MATCH(C51,Products!$B$6:$B$45,0))),0)) | Q51: =IF(C51="",0,IFERROR(N(INDEX(Products!$I$6:$I$45,MATCH(C51,Products!$B$6:$B$45,0))),0)) | R51: =IF(OR(C51="",NOT(ISNUMBER(B51))),"",YEAR(B51)*100+MONTH(B51)) | S51: =N(G51)*Q51 | T51: =IF(OR(M51="",M51="Sold out",NOT(ISNUMBER(J51))),"",J51*1000+ROW())
B52: 46290 | C52: Lemon drizzle loaf | D52: 4 | E52: 2 | F52: 0 | G52: 0 | I52: =IF(OR(C52="",NOT(ISNUMBER(B52))),"",UPPER(IF(IFERROR(IF(INDEX(Products!$C$6:$C$45,MATCH(C52,Products!$B$6:$B$45,0))="","",INDEX(Products!$C$6:$C$45,MATCH(C52,Products!$B$6:$B$45,0))),"")="",LEFT(SUBSTITUTE(C52," ",""),3),IFERROR(IF(INDEX(Products!$C$6:$C$45,MATCH(C52,Products!$B$6:$B$45,0))="","",INDEX(Products!$C$6:$C$45,MATCH(C52,Products!$B$6:$B$45,0))),"")))&"-"&RIGHT(YEAR(B52),2)&RIGHT("0"&MONTH(B52),2)&RIGHT("0"&DAY(B52),2)&"-"&COUNTIFS(C$6:C52,C52,B$6:B52,B52)) | J52: =IF(OR(C52="",NOT(ISNUMBER(B52)),N(P52)=0),"",B52+P52) | K52: =IF(C52="","",N(D52)-N(E52)-N(F52)-N(G52)) | L52: =IF(OR(C52="",N(K52)<=0,NOT(ISNUMBER(J52))),"",J52-TODAY()) | M52: =IF(C52="","",IF(N(K52)<=0,"Sold out",IF(NOT(ISNUMBER(J52)),"In stock",IF(J52<TODAY(),"Past its date",IF(J52-TODAY()<=Settings!$C$5,"Use soon","In stock"))))) | N52: =IF(C52="","",N(D52)*Q52) | P52: =IF(C52="",0,IFERROR(N(INDEX(Products!$E$6:$E$45,MATCH(C52,Products!$B$6:$B$45,0))),0)) | Q52: =IF(C52="",0,IFERROR(N(INDEX(Products!$I$6:$I$45,MATCH(C52,Products!$B$6:$B$45,0))),0)) | R52: =IF(OR(C52="",NOT(ISNUMBER(B52))),"",YEAR(B52)*100+MONTH(B52)) | S52: =N(G52)*Q52 | T52: =IF(OR(M52="",M52="Sold out",NOT(ISNUMBER(J52))),"",J52*1000+ROW())
B53: 46290 | C53: Cinnamon rolls | D53: 24 | E53: 20 | F53: 0 | G53: 4 | H53: Double batch for the market | I53: =IF(OR(C53="",NOT(ISNUMBER(B53))),"",UPPER(IF(IFERROR(IF(INDEX(Products!$C$6:$C$45,MATCH(C53,Products!$B$6:$B$45,0))="","",INDEX(Products!$C$6:$C$45,MATCH(C53,Products!$B$6:$B$45,0))),"")="",LEFT(SUBSTITUTE(C53," ",""),3),IFERROR(IF(INDEX(Products!$C$6:$C$45,MATCH(C53,Products!$B$6:$B$45,0))="","",INDEX(Products!$C$6:$C$45,MATCH(C53,Products!$B$6:$B$45,0))),"")))&"-"&RIGHT(YEAR(B53),2)&RIGHT("0"&MONTH(B53),2)&RIGHT("0"&DAY(B53),2)&"-"&COUNTIFS(C$6:C53,C53,B$6:B53,B53)) | J53: =IF(OR(C53="",NOT(ISNUMBER(B53)),N(P53)=0),"",B53+P53) | K53: =IF(C53="","",N(D53)-N(E53)-N(F53)-N(G53)) | L53: =IF(OR(C53="",N(K53)<=0,NOT(ISNUMBER(J53))),"",J53-TODAY()) | M53: =IF(C53="","",IF(N(K53)<=0,"Sold out",IF(NOT(ISNUMBER(J53)),"In stock",IF(J53<TODAY(),"Past its date",IF(J53-TODAY()<=Settings!$C$5,"Use soon","In stock"))))) | N53: =IF(C53="","",N(D53)*Q53) | P53: =IF(C53="",0,IFERROR(N(INDEX(Products!$E$6:$E$45,MATCH(C53,Products!$B$6:$B$45,0))),0)) | Q53: =IF(C53="",0,IFERROR(N(INDEX(Products!$I$6:$I$45,MATCH(C53,Products!$B$6:$B$45,0))),0)) | R53: =IF(OR(C53="",NOT(ISNUMBER(B53))),"",YEAR(B53)*100+MONTH(B53)) | S53: =N(G53)*Q53 | T53: =IF(OR(M53="",M53="Sold out",NOT(ISNUMBER(J53))),"",J53*1000+ROW())
B54: 46291 | C54: Chocolate chip cookies | D54: 8 | E54: 5 | F54: 0 | G54: 0 | I54: =IF(OR(C54="",NOT(ISNUMBER(B54))),"",UPPER(IF(IFERROR(IF(INDEX(Products!$C$6:$C$45,MATCH(C54,Products!$B$6:$B$45,0))="","",INDEX(Products!$C$6:$C$45,MATCH(C54,Products!$B$6:$B$45,0))),"")="",LEFT(SUBSTITUTE(C54," ",""),3),IFERROR(IF(INDEX(Products!$C$6:$C$45,MATCH(C54,Products!$B$6:$B$45,0))="","",INDEX(Products!$C$6:$C$45,MATCH(C54,Products!$B$6:$B$45,0))),"")))&"-"&RIGHT(YEAR(B54),2)&RIGHT("0"&MONTH(B54),2)&RIGHT("0"&DAY(B54),2)&"-"&COUNTIFS(C$6:C54,C54,B$6:B54,B54)) | J54: =IF(OR(C54="",NOT(ISNUMBER(B54)),N(P54)=0),"",B54+P54) | K54: =IF(C54="","",N(D54)-N(E54)-N(F54)-N(G54)) | L54: =IF(OR(C54="",N(K54)<=0,NOT(ISNUMBER(J54))),"",J54-TODAY()) | M54: =IF(C54="","",IF(N(K54)<=0,"Sold out",IF(NOT(ISNUMBER(J54)),"In stock",IF(J54<TODAY(),"Past its date",IF(J54-TODAY()<=Settings!$C$5,"Use soon","In stock"))))) | N54: =IF(C54="","",N(D54)*Q54) | P54: =IF(C54="",0,IFERROR(N(INDEX(Products!$E$6:$E$45,MATCH(C54,Products!$B$6:$B$45,0))),0)) | Q54: =IF(C54="",0,IFERROR(N(INDEX(Products!$I$6:$I$45,MATCH(C54,Products!$B$6:$B$45,0))),0)) | R54: =IF(OR(C54="",NOT(ISNUMBER(B54))),"",YEAR(B54)*100+MONTH(B54)) | S54: =N(G54)*Q54 | T54: =IF(OR(M54="",M54="Sold out",NOT(ISNUMBER(J54))),"",J54*1000+ROW())
B55: 46291 | C55: Cinnamon rolls | D55: 12 | E55: 9 | F55: 0 | G55: 0 | I55: =IF(OR(C55="",NOT(ISNUMBER(B55))),"",UPPER(IF(IFERROR(IF(INDEX(Products!$C$6:$C$45,MATCH(C55,Products!$B$6:$B$45,0))="","",INDEX(Products!$C$6:$C$45,MATCH(C55,Products!$B$6:$B$45,0))),"")="",LEFT(SUBSTITUTE(C55," ",""),3),IFERROR(IF(INDEX(Products!$C$6:$C$45,MATCH(C55,Products!$B$6:$B$45,0))="","",INDEX(Products!$C$6:$C$45,MATCH(C55,Products!$B$6:$B$45,0))),"")))&"-"&RIGHT(YEAR(B55),2)&RIGHT("0"&MONTH(B55),2)&RIGHT("0"&DAY(B55),2)&"-"&COUNTIFS(C$6:C55,C55,B$6:B55,B55)) | J55: =IF(OR(C55="",NOT(ISNUMBER(B55)),N(P55)=0),"",B55+P55) | K55: =IF(C55="","",N(D55)-N(E55)-N(F55)-N(G55)) | L55: =IF(OR(C55="",N(K55)<=0,NOT(ISNUMBER(J55))),"",J55-TODAY()) | M55: =IF(C55="","",IF(N(K55)<=0,"Sold out",IF(NOT(ISNUMBER(J55)),"In stock",IF(J55<TODAY(),"Past its date",IF(J55-TODAY()<=Settings!$C$5,"Use soon","In stock"))))) | N55: =IF(C55="","",N(D55)*Q55) | P55: =IF(C55="",0,IFERROR(N(INDEX(Products!$E$6:$E$45,MATCH(C55,Products!$B$6:$B$45,0))),0)) | Q55: =IF(C55="",0,IFERROR(N(INDEX(Products!$I$6:$I$45,MATCH(C55,Products!$B$6:$B$45,0))),0)) | R55: =IF(OR(C55="",NOT(ISNUMBER(B55))),"",YEAR(B55)*100+MONTH(B55)) | S55: =N(G55)*Q55 | T55: =IF(OR(M55="",M55="Sold out",NOT(ISNUMBER(J55))),"",J55*1000+ROW())
B56: 46292 | C56: Sourdough loaf | D56: 4 | E56: 3 | F56: 0 | G56: 0 | I56: =IF(OR(C56="",NOT(ISNUMBER(B56))),"",UPPER(IF(IFERROR(IF(INDEX(Products!$C$6:$C$45,MATCH(C56,Products!$B$6:$B$45,0))="","",INDEX(Products!$C$6:$C$45,MATCH(C56,Products!$B$6:$B$45,0))),"")="",LEFT(SUBSTITUTE(C56," ",""),3),IFERROR(IF(INDEX(Products!$C$6:$C$45,MATCH(C56,Products!$B$6:$B$45,0))="","",INDEX(Products!$C$6:$C$45,MATCH(C56,Products!$B$6:$B$45,0))),"")))&"-"&RIGHT(YEAR(B56),2)&RIGHT("0"&MONTH(B56),2)&RIGHT("0"&DAY(B56),2)&"-"&COUNTIFS(C$6:C56,C56,B$6:B56,B56)) | J56: =IF(OR(C56="",NOT(ISNUMBER(B56)),N(P56)=0),"",B56+P56) | K56: =IF(C56="","",N(D56)-N(E56)-N(F56)-N(G56)) | L56: =IF(OR(C56="",N(K56)<=0,NOT(ISNUMBER(J56))),"",J56-TODAY()) | M56: =IF(C56="","",IF(N(K56)<=0,"Sold out",IF(NOT(ISNUMBER(J56)),"In stock",IF(J56<TODAY(),"Past its date",IF(J56-TODAY()<=Settings!$C$5,"Use soon","In stock"))))) | N56: =IF(C56="","",N(D56)*Q56) | P56: =IF(C56="",0,IFERROR(N(INDEX(Products!$E$6:$E$45,MATCH(C56,Products!$B$6:$B$45,0))),0)) | Q56: =IF(C56="",0,IFERROR(N(INDEX(Products!$I$6:$I$45,MATCH(C56,Products!$B$6:$B$45,0))),0)) | R56: =IF(OR(C56="",NOT(ISNUMBER(B56))),"",YEAR(B56)*100+MONTH(B56)) | S56: =N(G56)*Q56 | T56: =IF(OR(M56="",M56="Sold out",NOT(ISNUMBER(J56))),"",J56*1000+ROW())
I57: =IF(OR(C57="",NOT(ISNUMBER(B57))),"",UPPER(IF(IFERROR(IF(INDEX(Products!$C$6:$C$45,MATCH(C57,Products!$B$6:$B$45,0))="","",INDEX(Products!$C$6:$C$45,MATCH(C57,Products!$B$6:$B$45,0))),"")="",LEFT(SUBSTITUTE(C57," ",""),3),IFERROR(IF(INDEX(Products!$C$6:$C$45,MATCH(C57,Products!$B$6:$B$45,0))="","",INDEX(Products!$C$6:$C$45,MATCH(C57,Products!$B$6:$B$45,0))),"")))&"-"&RIGHT(YEAR(B57),2)&RIGHT("0"&MONTH(B57),2)&RIGHT("0"&DAY(B57),2)&"-"&COUNTIFS(C$6:C57,C57,B$6:B57,B57)) | J57: =IF(OR(C57="",NOT(ISNUMBER(B57)),N(P57)=0),"",B57+P57) | K57: =IF(C57="","",N(D57)-N(E57)-N(F57)-N(G57)) | L57: =IF(OR(C57="",N(K57)<=0,NOT(ISNUMBER(J57))),"",J57-TODAY()) | M57: =IF(C57="","",IF(N(K57)<=0,"Sold out",IF(NOT(ISNUMBER(J57)),"In stock",IF(J57<TODAY(),"Past its date",IF(J57-TODAY()<=Settings!$C$5,"Use soon","In stock"))))) | N57: =IF(C57="","",N(D57)*Q57) | P57: =IF(C57="",0,IFERROR(N(INDEX(Products!$E$6:$E$45,MATCH(C57,Products!$B$6:$B$45,0))),0)) | Q57: =IF(C57="",0,IFERROR(N(INDEX(Products!$I$6:$I$45,MATCH(C57,Products!$B$6:$B$45,0))),0)) | R57: =IF(OR(C57="",NOT(ISNUMBER(B57))),"",YEAR(B57)*100+MONTH(B57)) | S57: =N(G57)*Q57 | T57: =IF(OR(M57="",M57="Sold out",NOT(ISNUMBER(J57))),"",J57*1000+ROW())
I58: =IF(OR(C58="",NOT(ISNUMBER(B58))),"",UPPER(IF(IFERROR(IF(INDEX(Products!$C$6:$C$45,MATCH(C58,Products!$B$6:$B$45,0))="","",INDEX(Products!$C$6:$C$45,MATCH(C58,Products!$B$6:$B$45,0))),"")="",LEFT(SUBSTITUTE(C58," ",""),3),IFERROR(IF(INDEX(Products!$C$6:$C$45,MATCH(C58,Products!$B$6:$B$45,0))="","",INDEX(Products!$C$6:$C$45,MATCH(C58,Products!$B$6:$B$45,0))),"")))&"-"&RIGHT(YEAR(B58),2)&RIGHT("0"&MONTH(B58),2)&RIGHT("0"&DAY(B58),2)&"-"&COUNTIFS(C$6:C58,C58,B$6:B58,B58)) | J58: =IF(OR(C58="",NOT(ISNUMBER(B58)),N(P58)=0),"",B58+P58) | K58: =IF(C58="","",N(D58)-N(E58)-N(F58)-N(G58)) | L58: =IF(OR(C58="",N(K58)<=0,NOT(ISNUMBER(J58))),"",J58-TODAY()) | M58: =IF(C58="","",IF(N(K58)<=0,"Sold out",IF(NOT(ISNUMBER(J58)),"In stock",IF(J58<TODAY(),"Past its date",IF(J58-TODAY()<=Settings!$C$5,"Use soon","In stock"))))) | N58: =IF(C58="","",N(D58)*Q58) | P58: =IF(C58="",0,IFERROR(N(INDEX(Products!$E$6:$E$45,MATCH(C58,Products!$B$6:$B$45,0))),0)) | Q58: =IF(C58="",0,IFERROR(N(INDEX(Products!$I$6:$I$45,MATCH(C58,Products!$B$6:$B$45,0))),0)) | R58: =IF(OR(C58="",NOT(ISNUMBER(B58))),"",YEAR(B58)*100+MONTH(B58)) | S58: =N(G58)*Q58 | T58: =IF(OR(M58="",M58="Sold out",NOT(ISNUMBER(J58))),"",J58*1000+ROW())
I59: =IF(OR(C59="",NOT(ISNUMBER(B59))),"",UPPER(IF(IFERROR(IF(INDEX(Products!$C$6:$C$45,MATCH(C59,Products!$B$6:$B$45,0))="","",INDEX(Products!$C$6:$C$45,MATCH(C59,Products!$B$6:$B$45,0))),"")="",LEFT(SUBSTITUTE(C59," ",""),3),IFERROR(IF(INDEX(Products!$C$6:$C$45,MATCH(C59,Products!$B$6:$B$45,0))="","",INDEX(Products!$C$6:$C$45,MATCH(C59,Products!$B$6:$B$45,0))),"")))&"-"&RIGHT(YEAR(B59),2)&RIGHT("0"&MONTH(B59),2)&RIGHT("0"&DAY(B59),2)&"-"&COUNTIFS(C$6:C59,C59,B$6:B59,B59)) | J59: =IF(OR(C59="",NOT(ISNUMBER(B59)),N(P59)=0),"",B59+P59) | K59: =IF(C59="","",N(D59)-N(E59)-N(F59)-N(G59)) | L59: =IF(OR(C59="",N(K59)<=0,NOT(ISNUMBER(J59))),"",J59-TODAY()) | M59: =IF(C59="","",IF(N(K59)<=0,"Sold out",IF(NOT(ISNUMBER(J59)),"In stock",IF(J59<TODAY(),"Past its date",IF(J59-TODAY()<=Settings!$C$5,"Use soon","In stock"))))) | N59: =IF(C59="","",N(D59)*Q59) | P59: =IF(C59="",0,IFERROR(N(INDEX(Products!$E$6:$E$45,MATCH(C59,Products!$B$6:$B$45,0))),0)) | Q59: =IF(C59="",0,IFERROR(N(INDEX(Products!$I$6:$I$45,MATCH(C59,Products!$B$6:$B$45,0))),0)) | R59: =IF(OR(C59="",NOT(ISNUMBER(B59))),"",YEAR(B59)*100+MONTH(B59)) | S59: =N(G59)*Q59 | T59: =IF(OR(M59="",M59="Sold out",NOT(ISNUMBER(J59))),"",J59*1000+ROW())
I60: =IF(OR(C60="",NOT(ISNUMBER(B60))),"",UPPER(IF(IFERROR(IF(INDEX(Products!$C$6:$C$45,MATCH(C60,Products!$B$6:$B$45,0))="","",INDEX(Products!$C$6:$C$45,MATCH(C60,Products!$B$6:$B$45,0))),"")="",LEFT(SUBSTITUTE(C60," ",""),3),IFERROR(IF(INDEX(Products!$C$6:$C$45,MATCH(C60,Products!$B$6:$B$45,0))="","",INDEX(Products!$C$6:$C$45,MATCH(C60,Products!$B$6:$B$45,0))),"")))&"-"&RIGHT(YEAR(B60),2)&RIGHT("0"&MONTH(B60),2)&RIGHT("0"&DAY(B60),2)&"-"&COUNTIFS(C$6:C60,C60,B$6:B60,B60)) | J60: =IF(OR(C60="",NOT(ISNUMBER(B60)),N(P60)=0),"",B60+P60) | K60: =IF(C60="","",N(D60)-N(E60)-N(F60)-N(G60)) | L60: =IF(OR(C60="",N(K60)<=0,NOT(ISNUMBER(J60))),"",J60-TODAY()) | M60: =IF(C60="","",IF(N(K60)<=0,"Sold out",IF(NOT(ISNUMBER(J60)),"In stock",IF(J60<TODAY(),"Past its date",IF(J60-TODAY()<=Settings!$C$5,"Use soon","In stock"))))) | N60: =IF(C60="","",N(D60)*Q60) | P60: =IF(C60="",0,IFERROR(N(INDEX(Products!$E$6:$E$45,MATCH(C60,Products!$B$6:$B$45,0))),0)) | Q60: =IF(C60="",0,IFERROR(N(INDEX(Products!$I$6:$I$45,MATCH(C60,Products!$B$6:$B$45,0))),0)) | R60: =IF(OR(C60="",NOT(ISNUMBER(B60))),"",YEAR(B60)*100+MONTH(B60)) | S60: =N(G60)*Q60 | T60: =IF(OR(M60="",M60="Sold out",NOT(ISNUMBER(J60))),"",J60*1000+ROW())
I61: =IF(OR(C61="",NOT(ISNUMBER(B61))),"",UPPER(IF(IFERROR(IF(INDEX(Products!$C$6:$C$45,MATCH(C61,Products!$B$6:$B$45,0))="","",INDEX(Products!$C$6:$C$45,MATCH(C61,Products!$B$6:$B$45,0))),"")="",LEFT(SUBSTITUTE(C61," ",""),3),IFERROR(IF(INDEX(Products!$C$6:$C$45,MATCH(C61,Products!$B$6:$B$45,0))="","",INDEX(Products!$C$6:$C$45,MATCH(C61,Products!$B$6:$B$45,0))),"")))&"-"&RIGHT(YEAR(B61),2)&RIGHT("0"&MONTH(B61),2)&RIGHT("0"&DAY(B61),2)&"-"&COUNTIFS(C$6:C61,C61,B$6:B61,B61)) | J61: =IF(OR(C61="",NOT(ISNUMBER(B61)),N(P61)=0),"",B61+P61) | K61: =IF(C61="","",N(D61)-N(E61)-N(F61)-N(G61)) | L61: =IF(OR(C61="",N(K61)<=0,NOT(ISNUMBER(J61))),"",J61-TODAY()) | M61: =IF(C61="","",IF(N(K61)<=0,"Sold out",IF(NOT(ISNUMBER(J61)),"In stock",IF(J61<TODAY(),"Past its date",IF(J61-TODAY()<=Settings!$C$5,"Use soon","In stock"))))) | N61: =IF(C61="","",N(D61)*Q61) | P61: =IF(C61="",0,IFERROR(N(INDEX(Products!$E$6:$E$45,MATCH(C61,Products!$B$6:$B$45,0))),0)) | Q61: =IF(C61="",0,IFERROR(N(INDEX(Products!$I$6:$I$45,MATCH(C61,Products!$B$6:$B$45,0))),0)) | R61: =IF(OR(C61="",NOT(ISNUMBER(B61))),"",YEAR(B61)*100+MONTH(B61)) | S61: =N(G61)*Q61 | T61: =IF(OR(M61="",M61="Sold out",NOT(ISNUMBER(J61))),"",J61*1000+ROW())
I62: =IF(OR(C62="",NOT(ISNUMBER(B62))),"",UPPER(IF(IFERROR(IF(INDEX(Products!$C$6:$C$45,MATCH(C62,Products!$B$6:$B$45,0))="","",INDEX(Products!$C$6:$C$45,MATCH(C62,Products!$B$6:$B$45,0))),"")="",LEFT(SUBSTITUTE(C62," ",""),3),IFERROR(IF(INDEX(Products!$C$6:$C$45,MATCH(C62,Products!$B$6:$B$45,0))="","",INDEX(Products!$C$6:$C$45,MATCH(C62,Products!$B$6:$B$45,0))),"")))&"-"&RIGHT(YEAR(B62),2)&RIGHT("0"&MONTH(B62),2)&RIGHT("0"&DAY(B62),2)&"-"&COUNTIFS(C$6:C62,C62,B$6:B62,B62)) | J62: =IF(OR(C62="",NOT(ISNUMBER(B62)),N(P62)=0),"",B62+P62) | K62: =IF(C62="","",N(D62)-N(E62)-N(F62)-N(G62)) | L62: =IF(OR(C62="",N(K62)<=0,NOT(ISNUMBER(J62))),"",J62-TODAY()) | M62: =IF(C62="","",IF(N(K62)<=0,"Sold out",IF(NOT(ISNUMBER(J62)),"In stock",IF(J62<TODAY(),"Past its date",IF(J62-TODAY()<=Settings!$C$5,"Use soon","In stock"))))) | N62: =IF(C62="","",N(D62)*Q62) | P62: =IF(C62="",0,IFERROR(N(INDEX(Products!$E$6:$E$45,MATCH(C62,Products!$B$6:$B$45,0))),0)) | Q62: =IF(C62="",0,IFERROR(N(INDEX(Products!$I$6:$I$45,MATCH(C62,Products!$B$6:$B$45,0))),0)) | R62: =IF(OR(C62="",NOT(ISNUMBER(B62))),"",YEAR(B62)*100+MONTH(B62)) | S62: =N(G62)*Q62 | T62: =IF(OR(M62="",M62="Sold out",NOT(ISNUMBER(J62))),"",J62*1000+ROW())
I63: =IF(OR(C63="",NOT(ISNUMBER(B63))),"",UPPER(IF(IFERROR(IF(INDEX(Products!$C$6:$C$45,MATCH(C63,Products!$B$6:$B$45,0))="","",INDEX(Products!$C$6:$C$45,MATCH(C63,Products!$B$6:$B$45,0))),"")="",LEFT(SUBSTITUTE(C63," ",""),3),IFERROR(IF(INDEX(Products!$C$6:$C$45,MATCH(C63,Products!$B$6:$B$45,0))="","",INDEX(Products!$C$6:$C$45,MATCH(C63,Products!$B$6:$B$45,0))),"")))&"-"&RIGHT(YEAR(B63),2)&RIGHT("0"&MONTH(B63),2)&RIGHT("0"&DAY(B63),2)&"-"&COUNTIFS(C$6:C63,C63,B$6:B63,B63)) | J63: =IF(OR(C63="",NOT(ISNUMBER(B63)),N(P63)=0),"",B63+P63) | K63: =IF(C63="","",N(D63)-N(E63)-N(F63)-N(G63)) | L63: =IF(OR(C63="",N(K63)<=0,NOT(ISNUMBER(J63))),"",J63-TODAY()) | M63: =IF(C63="","",IF(N(K63)<=0,"Sold out",IF(NOT(ISNUMBER(J63)),"In stock",IF(J63<TODAY(),"Past its date",IF(J63-TODAY()<=Settings!$C$5,"Use soon","In stock"))))) | N63: =IF(C63="","",N(D63)*Q63) | P63: =IF(C63="",0,IFERROR(N(INDEX(Products!$E$6:$E$45,MATCH(C63,Products!$B$6:$B$45,0))),0)) | Q63: =IF(C63="",0,IFERROR(N(INDEX(Products!$I$6:$I$45,MATCH(C63,Products!$B$6:$B$45,0))),0)) | R63: =IF(OR(C63="",NOT(ISNUMBER(B63))),"",YEAR(B63)*100+MONTH(B63)) | S63: =N(G63)*Q63 | T63: =IF(OR(M63="",M63="Sold out",NOT(ISNUMBER(J63))),"",J63*1000+ROW())
I64: =IF(OR(C64="",NOT(ISNUMBER(B64))),"",UPPER(IF(IFERROR(IF(INDEX(Products!$C$6:$C$45,MATCH(C64,Products!$B$6:$B$45,0))="","",INDEX(Products!$C$6:$C$45,MATCH(C64,Products!$B$6:$B$45,0))),"")="",LEFT(SUBSTITUTE(C64," ",""),3),IFERROR(IF(INDEX(Products!$C$6:$C$45,MATCH(C64,Products!$B$6:$B$45,0))="","",INDEX(Products!$C$6:$C$45,MATCH(C64,Products!$B$6:$B$45,0))),"")))&"-"&RIGHT(YEAR(B64),2)&RIGHT("0"&MONTH(B64),2)&RIGHT("0"&DAY(B64),2)&"-"&COUNTIFS(C$6:C64,C64,B$6:B64,B64)) | J64: =IF(OR(C64="",NOT(ISNUMBER(B64)),N(P64)=0),"",B64+P64) | K64: =IF(C64="","",N(D64)-N(E64)-N(F64)-N(G64)) | L64: =IF(OR(C64="",N(K64)<=0,NOT(ISNUMBER(J64))),"",J64-TODAY()) | M64: =IF(C64="","",IF(N(K64)<=0,"Sold out",IF(NOT(ISNUMBER(J64)),"In stock",IF(J64<TODAY(),"Past its date",IF(J64-TODAY()<=Settings!$C$5,"Use soon","In stock"))))) | N64: =IF(C64="","",N(D64)*Q64) | P64: =IF(C64="",0,IFERROR(N(INDEX(Products!$E$6:$E$45,MATCH(C64,Products!$B$6:$B$45,0))),0)) | Q64: =IF(C64="",0,IFERROR(N(INDEX(Products!$I$6:$I$45,MATCH(C64,Products!$B$6:$B$45,0))),0)) | R64: =IF(OR(C64="",NOT(ISNUMBER(B64))),"",YEAR(B64)*100+MONTH(B64)) | S64: =N(G64)*Q64 | T64: =IF(OR(M64="",M64="Sold out",NOT(ISNUMBER(J64))),"",J64*1000+ROW())
I65: =IF(OR(C65="",NOT(ISNUMBER(B65))),"",UPPER(IF(IFERROR(IF(INDEX(Products!$C$6:$C$45,MATCH(C65,Products!$B$6:$B$45,0))="","",INDEX(Products!$C$6:$C$45,MATCH(C65,Products!$B$6:$B$45,0))),"")="",LEFT(SUBSTITUTE(C65," ",""),3),IFERROR(IF(INDEX(Products!$C$6:$C$45,MATCH(C65,Products!$B$6:$B$45,0))="","",INDEX(Products!$C$6:$C$45,MATCH(C65,Products!$B$6:$B$45,0))),"")))&"-"&RIGHT(YEAR(B65),2)&RIGHT("0"&MONTH(B65),2)&RIGHT("0"&DAY(B65),2)&"-"&COUNTIFS(C$6:C65,C65,B$6:B65,B65)) | J65: =IF(OR(C65="",NOT(ISNUMBER(B65)),N(P65)=0),"",B65+P65) | K65: =IF(C65="","",N(D65)-N(E65)-N(F65)-N(G65)) | L65: =IF(OR(C65="",N(K65)<=0,NOT(ISNUMBER(J65))),"",J65-TODAY()) | M65: =IF(C65="","",IF(N(K65)<=0,"Sold out",IF(NOT(ISNUMBER(J65)),"In stock",IF(J65<TODAY(),"Past its date",IF(J65-TODAY()<=Settings!$C$5,"Use soon","In stock"))))) | N65: =IF(C65="","",N(D65)*Q65) | P65: =IF(C65="",0,IFERROR(N(INDEX(Products!$E$6:$E$45,MATCH(C65,Products!$B$6:$B$45,0))),0)) | Q65: =IF(C65="",0,IFERROR(N(INDEX(Products!$I$6:$I$45,MATCH(C65,Products!$B$6:$B$45,0))),0)) | R65: =IF(OR(C65="",NOT(ISNUMBER(B65))),"",YEAR(B65)*100+MONTH(B65)) | S65: =N(G65)*Q65 | T65: =IF(OR(M65="",M65="Sold out",NOT(ISNUMBER(J65))),"",J65*1000+ROW())
I66: =IF(OR(C66="",NOT(ISNUMBER(B66))),"",UPPER(IF(IFERROR(IF(INDEX(Products!$C$6:$C$45,MATCH(C66,Products!$B$6:$B$45,0))="","",INDEX(Products!$C$6:$C$45,MATCH(C66,Products!$B$6:$B$45,0))),"")="",LEFT(SUBSTITUTE(C66," ",""),3),IFERROR(IF(INDEX(Products!$C$6:$C$45,MATCH(C66,Products!$B$6:$B$45,0))="","",INDEX(Products!$C$6:$C$45,MATCH(C66,Products!$B$6:$B$45,0))),"")))&"-"&RIGHT(YEAR(B66),2)&RIGHT("0"&MONTH(B66),2)&RIGHT("0"&DAY(B66),2)&"-"&COUNTIFS(C$6:C66,C66,B$6:B66,B66)) | J66: =IF(OR(C66="",NOT(ISNUMBER(B66)),N(P66)=0),"",B66+P66) | K66: =IF(C66="","",N(D66)-N(E66)-N(F66)-N(G66)) | L66: =IF(OR(C66="",N(K66)<=0,NOT(ISNUMBER(J66))),"",J66-TODAY()) | M66: =IF(C66="","",IF(N(K66)<=0,"Sold out",IF(NOT(ISNUMBER(J66)),"In stock",IF(J66<TODAY(),"Past its date",IF(J66-TODAY()<=Settings!$C$5,"Use soon","In stock"))))) | N66: =IF(C66="","",N(D66)*Q66) | P66: =IF(C66="",0,IFERROR(N(INDEX(Products!$E$6:$E$45,MATCH(C66,Products!$B$6:$B$45,0))),0)) | Q66: =IF(C66="",0,IFERROR(N(INDEX(Products!$I$6:$I$45,MATCH(C66,Products!$B$6:$B$45,0))),0)) | R66: =IF(OR(C66="",NOT(ISNUMBER(B66))),"",YEAR(B66)*100+MONTH(B66)) | S66: =N(G66)*Q66 | T66: =IF(OR(M66="",M66="Sold out",NOT(ISNUMBER(J66))),"",J66*1000+ROW())
...

Sheet Label
B2: Labels for batch | D2: CCC-260926-1 | H2: =IFERROR(MATCH(D2,Batches!$I$6:$I$505,0)+5,"")
B3: Pick a batch in the yellow box, then print and cut along the lines. | H3: =IF(H2="","",INDEX(Batches!$C$1:$C$505,H2))
H4: =IF(H2="","",INDEX(Batches!$B$1:$B$505,H2))
B5: =IF($H$3="","",$H$3) | D5: =IF($H$3="","",$H$3) | H5: =IF(H2="","",INDEX(Batches!$J$1:$J$505,H2))
B6: =$H$31 | D6: =$H$31 | H6: =IF(H3="","",IFERROR(IF(INDEX(Products!$G$6:$G$45,MATCH(H3,Products!$B$6:$B$45,0))="","",INDEX(Products!$G$6:$G$45,MATCH(H3,Products!$B$6:$B$45,0))),""))
B7: =IF($H$7="","","Contains: "&$H$7&".") | D7: =IF($H$7="","","Contains: "&$H$7&".") | H7: =IF(H3="","",IFERROR(IF(INDEX(Products!$L$6:$L$45,MATCH(H3,Products!$B$6:$B$45,0))="","",INDEX(Products!$L$6:$L$45,MATCH(H3,Products!$B$6:$B$45,0))),""))
B8: =IF($H$3="","",IF($H$6="","","Net weight: "&$H$6&" ")&"Batch: "&$H$8) | D8: =IF($H$3="","",IF($H$6="","","Net weight: "&$H$6&" ")&"Batch: "&$H$8) | H8: =IF(H2="","",INDEX(Batches!$I$1:$I$505,H2))
