Workbook

Sheet Week plan
B2: Week plan
B3: Pick a recipe for each meal. The grocery list builds itself from this plan.
B5: First day | C5: 46293 | D5: Type the date of the first day. The other days follow.
B7: Meal | C7: =$C$5+0 | D7: =$C$5+1 | E7: =$C$5+2 | F7: =$C$5+3 | G7: =$C$5+4 | H7: =$C$5+5 | I7: =$C$5+6
B8: People | C8: 4 | D8: 4 | E8: 4 | F8: 4 | G8: 4 | H8: 2 | I8: 4
B9: Breakfast | C9: Overnight oats | D9: Scrambled eggs on toast | E9: Overnight oats | F9: Scrambled eggs on toast | G9: Overnight oats | H9: Veggie omelette | I9: Scrambled eggs on toast | Z9: =IF(C9="",0,N(C$8)) | AA9: =IF(D9="",0,N(D$8)) | AB9: =IF(E9="",0,N(E$8)) | AC9: =IF(F9="",0,N(F$8)) | AD9: =IF(G9="",0,N(G$8)) | AE9: =IF(H9="",0,N(H$8)) | AF9: =IF(I9="",0,N(I$8)) | AH9: =IF(C9="","",IF(COUNTIF(Recipes!$B$6:$B$105,C9)>0,"recipe","other")) | AI9: =IF(D9="","",IF(COUNTIF(Recipes!$B$6:$B$105,D9)>0,"recipe","other")) | AJ9: =IF(E9="","",IF(COUNTIF(Recipes!$B$6:$B$105,E9)>0,"recipe","other")) | AK9: =IF(F9="","",IF(COUNTIF(Recipes!$B$6:$B$105,F9)>0,"recipe","other")) | AL9: =IF(G9="","",IF(COUNTIF(Recipes!$B$6:$B$105,G9)>0,"recipe","other")) | AM9: =IF(H9="","",IF(COUNTIF(Recipes!$B$6:$B$105,H9)>0,"recipe","other")) | AN9: =IF(I9="","",IF(COUNTIF(Recipes!$B$6:$B$105,I9)>0,"recipe","other"))
B10: Lunch | C10: Lentil soup | D10: Lentil soup | E10: Tuna pasta salad | F10: Chicken Caesar wraps | G10: Tuna pasta salad | H10: Leftovers | I10: Chicken Caesar wraps | Z10: =IF(C10="",0,N(C$8)) | AA10: =IF(D10="",0,N(D$8)) | AB10: =IF(E10="",0,N(E$8)) | AC10: =IF(F10="",0,N(F$8)) | AD10: =IF(G10="",0,N(G$8)) | AE10: =IF(H10="",0,N(H$8)) | AF10: =IF(I10="",0,N(I$8)) | AH10: =IF(C10="","",IF(COUNTIF(Recipes!$B$6:$B$105,C10)>0,"recipe","other")) | AI10: =IF(D10="","",IF(COUNTIF(Recipes!$B$6:$B$105,D10)>0,"recipe","other")) | AJ10: =IF(E10="","",IF(COUNTIF(Recipes!$B$6:$B$105,E10)>0,"recipe","other")) | AK10: =IF(F10="","",IF(COUNTIF(Recipes!$B$6:$B$105,F10)>0,"recipe","other")) | AL10: =IF(G10="","",IF(COUNTIF(Recipes!$B$6:$B$105,G10)>0,"recipe","other")) | AM10: =IF(H10="","",IF(COUNTIF(Recipes!$B$6:$B$105,H10)>0,"recipe","other")) | AN10: =IF(I10="","",IF(COUNTIF(Recipes!$B$6:$B$105,I10)>0,"recipe","other"))
B11: Dinner | C11: Chicken stir fry with rice | D11: Spaghetti bolognese | E11: Black bean tacos | F11: Sheet pan salmon and potatoes | G11: Homemade pizza | H11: Eating out | I11: Spaghetti bolognese | Z11: =IF(C11="",0,N(C$8)) | AA11: =IF(D11="",0,N(D$8)) | AB11: =IF(E11="",0,N(E$8)) | AC11: =IF(F11="",0,N(F$8)) | AD11: =IF(G11="",0,N(G$8)) | AE11: =IF(H11="",0,N(H$8)) | AF11: =IF(I11="",0,N(I$8)) | AH11: =IF(C11="","",IF(COUNTIF(Recipes!$B$6:$B$105,C11)>0,"recipe","other")) | AI11: =IF(D11="","",IF(COUNTIF(Recipes!$B$6:$B$105,D11)>0,"recipe","other")) | AJ11: =IF(E11="","",IF(COUNTIF(Recipes!$B$6:$B$105,E11)>0,"recipe","other")) | AK11: =IF(F11="","",IF(COUNTIF(Recipes!$B$6:$B$105,F11)>0,"recipe","other")) | AL11: =IF(G11="","",IF(COUNTIF(Recipes!$B$6:$B$105,G11)>0,"recipe","other")) | AM11: =IF(H11="","",IF(COUNTIF(Recipes!$B$6:$B$105,H11)>0,"recipe","other")) | AN11: =IF(I11="","",IF(COUNTIF(Recipes!$B$6:$B$105,I11)>0,"recipe","other"))
B12: Snack | C12: Apple and peanut butter | D12: Yogurt and berries | E12: Apple and peanut butter | F12: Yogurt and berries | I12: Apple and peanut butter | Z12: =IF(C12="",0,N(C$8)) | AA12: =IF(D12="",0,N(D$8)) | AB12: =IF(E12="",0,N(E$8)) | AC12: =IF(F12="",0,N(F$8)) | AD12: =IF(G12="",0,N(G$8)) | AE12: =IF(H12="",0,N(H$8)) | AF12: =IF(I12="",0,N(I$8)) | AH12: =IF(C12="","",IF(COUNTIF(Recipes!$B$6:$B$105,C12)>0,"recipe","other")) | AI12: =IF(D12="","",IF(COUNTIF(Recipes!$B$6:$B$105,D12)>0,"recipe","other")) | AJ12: =IF(E12="","",IF(COUNTIF(Recipes!$B$6:$B$105,E12)>0,"recipe","other")) | AK12: =IF(F12="","",IF(COUNTIF(Recipes!$B$6:$B$105,F12)>0,"recipe","other")) | AL12: =IF(G12="","",IF(COUNTIF(Recipes!$B$6:$B$105,G12)>0,"recipe","other")) | AM12: =IF(H12="","",IF(COUNTIF(Recipes!$B$6:$B$105,H12)>0,"recipe","other")) | AN12: =IF(I12="","",IF(COUNTIF(Recipes!$B$6:$B$105,I12)>0,"recipe","other"))
B13: Prep notes | C13: Cook the soup for two days | E13: Move the salmon to the fridge | I13: Plan next week
C15: Meals planned | D15: Recipes to cook | E15: Items to buy | F15: Shopping cost | G15: Per person per day
C16: =COUNTIF(C9:I12,"?*") | D16: =COUNTIFS(Recipes!$G$6:$G$105,">0") | E16: =COUNTIFS(Pantry!$L$6:$L$305,">0") | F16: =SUM(Pantry!$M$6:$M$305) | G16: =IF(SUM(C8:I8)=0,0,F16/SUM(C8:I8))
B18: Checks | C18: =IF(COUNTIFS(Ingredients!$E$6:$E$1005,"Add to Pantry")=0,"Every ingredient is in the Pantry",IF(COUNTIFS(Ingredients!$E$6:$E$1005,"Add to Pantry")=1,"1 ingredient line is not in the Pantry yet, so the list leaves it out",COUNTIFS(Ingredients!$E$6:$E$1005,"Add to Pantry")&" ingredient lines are not in the Pantry yet, so the list leaves them out"))
C19: =IF(COUNTIFS(Recipes!$G$6:$G$105,">0",Recipes!$J$6:$J$105,0)=0,"Every planned recipe has its ingredients",IF(COUNTIFS(Recipes!$G$6:$G$105,">0",Recipes!$J$6:$J$105,0)=1,"1 planned recipe has",COUNTIFS(Recipes!$G$6:$G$105,">0",Recipes!$J$6:$J$105,0)&" planned recipes have")&" no ingredients yet")
C20: =IF(COUNTIFS(Pantry!$L$6:$L$305,">0",Pantry!$G$6:$G$305,"")=0,"Every item on the list has a price",IF(COUNTIFS(Pantry!$L$6:$L$305,">0",Pantry!$G$6:$G$305,"")=1,"1 item on the list has",COUNTIFS(Pantry!$L$6:$L$305,">0",Pantry!$G$6:$G$305,"")&" items on the list have")&" no price yet, so the cost is too low")
C22: Cooking this week
C23: Recipe | E23: Times | F23: Servings | G23: Minutes | H23: Cost per serving
C24: =IF(AP24="","",INDEX(Recipes!$B$1:$B$105,AP24)) | E24: =IF(AP24="","",INDEX(Recipes!$G$1:$G$105,AP24)) | F24: =IF(AP24="","",INDEX(Recipes!$H$1:$H$105,AP24)) | G24: =IF(AP24="","",IF(INDEX(Recipes!$E$1:$E$105,AP24)="","",INDEX(Recipes!$E$1:$E$105,AP24))) | H24: =IF(AP24="","",INDEX(Recipes!$I$1:$I$105,AP24)) | AP24: =IFERROR(SMALL(Recipes!$K$6:$K$105,1),"")
C25: =IF(AP25="","",INDEX(Recipes!$B$1:$B$105,AP25)) | E25: =IF(AP25="","",INDEX(Recipes!$G$1:$G$105,AP25)) | F25: =IF(AP25="","",INDEX(Recipes!$H$1:$H$105,AP25)) | G25: =IF(AP25="","",IF(INDEX(Recipes!$E$1:$E$105,AP25)="","",INDEX(Recipes!$E$1:$E$105,AP25))) | H25: =IF(AP25="","",INDEX(Recipes!$I$1:$I$105,AP25)) | AP25: =IFERROR(SMALL(Recipes!$K$6:$K$105,2),"")
C26: =IF(AP26="","",INDEX(Recipes!$B$1:$B$105,AP26)) | E26: =IF(AP26="","",INDEX(Recipes!$G$1:$G$105,AP26)) | F26: =IF(AP26="","",INDEX(Recipes!$H$1:$H$105,AP26)) | G26: =IF(AP26="","",IF(INDEX(Recipes!$E$1:$E$105,AP26)="","",INDEX(Recipes!$E$1:$E$105,AP26))) | H26: =IF(AP26="","",INDEX(Recipes!$I$1:$I$105,AP26)) | AP26: =IFERROR(SMALL(Recipes!$K$6:$K$105,3),"")
C27: =IF(AP27="","",INDEX(Recipes!$B$1:$B$105,AP27)) | E27: =IF(AP27="","",INDEX(Recipes!$G$1:$G$105,AP27)) | F27: =IF(AP27="","",INDEX(Recipes!$H$1:$H$105,AP27)) | G27: =IF(AP27="","",IF(INDEX(Recipes!$E$1:$E$105,AP27)="","",INDEX(Recipes!$E$1:$E$105,AP27))) | H27: =IF(AP27="","",INDEX(Recipes!$I$1:$I$105,AP27)) | AP27: =IFERROR(SMALL(Recipes!$K$6:$K$105,4),"")
C28: =IF(AP28="","",INDEX(Recipes!$B$1:$B$105,AP28)) | E28: =IF(AP28="","",INDEX(Recipes!$G$1:$G$105,AP28)) | F28: =IF(AP28="","",INDEX(Recipes!$H$1:$H$105,AP28)) | G28: =IF(AP28="","",IF(INDEX(Recipes!$E$1:$E$105,AP28)="","",INDEX(Recipes!$E$1:$E$105,AP28))) | H28: =IF(AP28="","",INDEX(Recipes!$I$1:$I$105,AP28)) | AP28: =IFERROR(SMALL(Recipes!$K$6:$K$105,5),"")
C29: =IF(AP29="","",INDEX(Recipes!$B$1:$B$105,AP29)) | E29: =IF(AP29="","",INDEX(Recipes!$G$1:$G$105,AP29)) | F29: =IF(AP29="","",INDEX(Recipes!$H$1:$H$105,AP29)) | G29: =IF(AP29="","",IF(INDEX(Recipes!$E$1:$E$105,AP29)="","",INDEX(Recipes!$E$1:$E$105,AP29))) | H29: =IF(AP29="","",INDEX(Recipes!$I$1:$I$105,AP29)) | AP29: =IFERROR(SMALL(Recipes!$K$6:$K$105,6),"")
C30: =IF(AP30="","",INDEX(Recipes!$B$1:$B$105,AP30)) | E30: =IF(AP30="","",INDEX(Recipes!$G$1:$G$105,AP30)) | F30: =IF(AP30="","",INDEX(Recipes!$H$1:$H$105,AP30)) | G30: =IF(AP30="","",IF(INDEX(Recipes!$E$1:$E$105,AP30)="","",INDEX(Recipes!$E$1:$E$105,AP30))) | H30: =IF(AP30="","",INDEX(Recipes!$I$1:$I$105,AP30)) | AP30: =IFERROR(SMALL(Recipes!$K$6:$K$105,7),"")
C31: =IF(AP31="","",INDEX(Recipes!$B$1:$B$105,AP31)) | E31: =IF(AP31="","",INDEX(Recipes!$G$1:$G$105,AP31)) | F31: =IF(AP31="","",INDEX(Recipes!$H$1:$H$105,AP31)) | G31: =IF(AP31="","",IF(INDEX(Recipes!$E$1:$E$105,AP31)="","",INDEX(Recipes!$E$1:$E$105,AP31))) | H31: =IF(AP31="","",INDEX(Recipes!$I$1:$I$105,AP31)) | AP31: =IFERROR(SMALL(Recipes!$K$6:$K$105,8),"")
C32: =IF(AP32="","",INDEX(Recipes!$B$1:$B$105,AP32)) | E32: =IF(AP32="","",INDEX(Recipes!$G$1:$G$105,AP32)) | F32: =IF(AP32="","",INDEX(Recipes!$H$1:$H$105,AP32)) | G32: =IF(AP32="","",IF(INDEX(Recipes!$E$1:$E$105,AP32)="","",INDEX(Recipes!$E$1:$E$105,AP32))) | H32: =IF(AP32="","",INDEX(Recipes!$I$1:$I$105,AP32)) | AP32: =IFERROR(SMALL(Recipes!$K$6:$K$105,9),"")
C33: =IF(AP33="","",INDEX(Recipes!$B$1:$B$105,AP33)) | E33: =IF(AP33="","",INDEX(Recipes!$G$1:$G$105,AP33)) | F33: =IF(AP33="","",INDEX(Recipes!$H$1:$H$105,AP33)) | G33: =IF(AP33="","",IF(INDEX(Recipes!$E$1:$E$105,AP33)="","",INDEX(Recipes!$E$1:$E$105,AP33))) | H33: =IF(AP33="","",INDEX(Recipes!$I$1:$I$105,AP33)) | AP33: =IFERROR(SMALL(Recipes!$K$6:$K$105,10),"")
C34: =IF(AP34="","",INDEX(Recipes!$B$1:$B$105,AP34)) | E34: =IF(AP34="","",INDEX(Recipes!$G$1:$G$105,AP34)) | F34: =IF(AP34="","",INDEX(Recipes!$H$1:$H$105,AP34)) | G34: =IF(AP34="","",IF(INDEX(Recipes!$E$1:$E$105,AP34)="","",INDEX(Recipes!$E$1:$E$105,AP34))) | H34: =IF(AP34="","",INDEX(Recipes!$I$1:$I$105,AP34)) | AP34: =IFERROR(SMALL(Recipes!$K$6:$K$105,11),"")
C35: =IF(AP35="","",INDEX(Recipes!$B$1:$B$105,AP35)) | E35: =IF(AP35="","",INDEX(Recipes!$G$1:$G$105,AP35)) | F35: =IF(AP35="","",INDEX(Recipes!$H$1:$H$105,AP35)) | G35: =IF(AP35="","",IF(INDEX(Recipes!$E$1:$E$105,AP35)="","",INDEX(Recipes!$E$1:$E$105,AP35))) | H35: =IF(AP35="","",INDEX(Recipes!$I$1:$I$105,AP35)) | AP35: =IFERROR(SMALL(Recipes!$K$6:$K$105,12),"")
C36: =IF(AP36="","",INDEX(Recipes!$B$1:$B$105,AP36)) | E36: =IF(AP36="","",INDEX(Recipes!$G$1:$G$105,AP36)) | F36: =IF(AP36="","",INDEX(Recipes!$H$1:$H$105,AP36)) | G36: =IF(AP36="","",IF(INDEX(Recipes!$E$1:$E$105,AP36)="","",INDEX(Recipes!$E$1:$E$105,AP36))) | H36: =IF(AP36="","",INDEX(Recipes!$I$1:$I$105,AP36)) | AP36: =IFERROR(SMALL(Recipes!$K$6:$K$105,13),"")
C37: =IF(AP37="","",INDEX(Recipes!$B$1:$B$105,AP37)) | E37: =IF(AP37="","",INDEX(Recipes!$G$1:$G$105,AP37)) | F37: =IF(AP37="","",INDEX(Recipes!$H$1:$H$105,AP37)) | G37: =IF(AP37="","",IF(INDEX(Recipes!$E$1:$E$105,AP37)="","",INDEX(Recipes!$E$1:$E$105,AP37))) | H37: =IF(AP37="","",INDEX(Recipes!$I$1:$I$105,AP37)) | AP37: =IFERROR(SMALL(Recipes!$K$6:$K$105,14),"")
C38: =IF(AP38="","",INDEX(Recipes!$B$1:$B$105,AP38)) | E38: =IF(AP38="","",INDEX(Recipes!$G$1:$G$105,AP38)) | F38: =IF(AP38="","",INDEX(Recipes!$H$1:$H$105,AP38)) | G38: =IF(AP38="","",IF(INDEX(Recipes!$E$1:$E$105,AP38)="","",INDEX(Recipes!$E$1:$E$105,AP38))) | H38: =IF(AP38="","",INDEX(Recipes!$I$1:$I$105,AP38)) | AP38: =IFERROR(SMALL(Recipes!$K$6:$K$105,15),"")

Sheet Grocery list
B2: Grocery list
B3: What the week needs, minus what you have at home, in the order of the store.
B5: Week of | C5: ='Week plan'!C5 | E5: Total | F5: =SUM(Pantry!$M$6:$M$305)
B7: Section | C7: Item | D7: Buy | E7: Pack | F7: Cost | G7: Got it
B8: =IF(J8="","",IF(K8=K7,"",K8)) | C8: =IF(J8="","",INDEX(Pantry!$B$6:$B$305,J8)) | D8: =IF(J8="","",INDEX(Pantry!$L$6:$L$305,J8)) | E8: =IF(J8="","",INDEX(Pantry!$E$6:$E$305,J8)&"") | F8: =IF(J8="","",INDEX(Pantry!$M$6:$M$305,J8)) | I8: =IFERROR(SMALL(Pantry!$O$6:$O$305,1),"") | J8: =IF(I8="","",MATCH(I8,Pantry!$O$6:$O$305,0)) | K8: =IF(J8="","",IF(INDEX(Pantry!$D$6:$D$305,J8)&""="","Other",INDEX(Pantry!$D$6:$D$305,J8)&""))
B9: =IF(J9="","",IF(K9=K8,"",K9)) | C9: =IF(J9="","",INDEX(Pantry!$B$6:$B$305,J9)) | D9: =IF(J9="","",INDEX(Pantry!$L$6:$L$305,J9)) | E9: =IF(J9="","",INDEX(Pantry!$E$6:$E$305,J9)&"") | F9: =IF(J9="","",INDEX(Pantry!$M$6:$M$305,J9)) | I9: =IFERROR(SMALL(Pantry!$O$6:$O$305,2),"") | J9: =IF(I9="","",MATCH(I9,Pantry!$O$6:$O$305,0)) | K9: =IF(J9="","",IF(INDEX(Pantry!$D$6:$D$305,J9)&""="","Other",INDEX(Pantry!$D$6:$D$305,J9)&""))
B10: =IF(J10="","",IF(K10=K9,"",K10)) | C10: =IF(J10="","",INDEX(Pantry!$B$6:$B$305,J10)) | D10: =IF(J10="","",INDEX(Pantry!$L$6:$L$305,J10)) | E10: =IF(J10="","",INDEX(Pantry!$E$6:$E$305,J10)&"") | F10: =IF(J10="","",INDEX(Pantry!$M$6:$M$305,J10)) | I10: =IFERROR(SMALL(Pantry!$O$6:$O$305,3),"") | J10: =IF(I10="","",MATCH(I10,Pantry!$O$6:$O$305,0)) | K10: =IF(J10="","",IF(INDEX(Pantry!$D$6:$D$305,J10)&""="","Other",INDEX(Pantry!$D$6:$D$305,J10)&""))
B11: =IF(J11="","",IF(K11=K10,"",K11)) | C11: =IF(J11="","",INDEX(Pantry!$B$6:$B$305,J11)) | D11: =IF(J11="","",INDEX(Pantry!$L$6:$L$305,J11)) | E11: =IF(J11="","",INDEX(Pantry!$E$6:$E$305,J11)&"") | F11: =IF(J11="","",INDEX(Pantry!$M$6:$M$305,J11)) | I11: =IFERROR(SMALL(Pantry!$O$6:$O$305,4),"") | J11: =IF(I11="","",MATCH(I11,Pantry!$O$6:$O$305,0)) | K11: =IF(J11="","",IF(INDEX(Pantry!$D$6:$D$305,J11)&""="","Other",INDEX(Pantry!$D$6:$D$305,J11)&""))
B12: =IF(J12="","",IF(K12=K11,"",K12)) | C12: =IF(J12="","",INDEX(Pantry!$B$6:$B$305,J12)) | D12: =IF(J12="","",INDEX(Pantry!$L$6:$L$305,J12)) | E12: =IF(J12="","",INDEX(Pantry!$E$6:$E$305,J12)&"") | F12: =IF(J12="","",INDEX(Pantry!$M$6:$M$305,J12)) | I12: =IFERROR(SMALL(Pantry!$O$6:$O$305,5),"") | J12: =IF(I12="","",MATCH(I12,Pantry!$O$6:$O$305,0)) | K12: =IF(J12="","",IF(INDEX(Pantry!$D$6:$D$305,J12)&""="","Other",INDEX(Pantry!$D$6:$D$305,J12)&""))
B13: =IF(J13="","",IF(K13=K12,"",K13)) | C13: =IF(J13="","",INDEX(Pantry!$B$6:$B$305,J13)) | D13: =IF(J13="","",INDEX(Pantry!$L$6:$L$305,J13)) | E13: =IF(J13="","",INDEX(Pantry!$E$6:$E$305,J13)&"") | F13: =IF(J13="","",INDEX(Pantry!$M$6:$M$305,J13)) | I13: =IFERROR(SMALL(Pantry!$O$6:$O$305,6),"") | J13: =IF(I13="","",MATCH(I13,Pantry!$O$6:$O$305,0)) | K13: =IF(J13="","",IF(INDEX(Pantry!$D$6:$D$305,J13)&""="","Other",INDEX(Pantry!$D$6:$D$305,J13)&""))
B14: =IF(J14="","",IF(K14=K13,"",K14)) | C14: =IF(J14="","",INDEX(Pantry!$B$6:$B$305,J14)) | D14: =IF(J14="","",INDEX(Pantry!$L$6:$L$305,J14)) | E14: =IF(J14="","",INDEX(Pantry!$E$6:$E$305,J14)&"") | F14: =IF(J14="","",INDEX(Pantry!$M$6:$M$305,J14)) | I14: =IFERROR(SMALL(Pantry!$O$6:$O$305,7),"") | J14: =IF(I14="","",MATCH(I14,Pantry!$O$6:$O$305,0)) | K14: =IF(J14="","",IF(INDEX(Pantry!$D$6:$D$305,J14)&""="","Other",INDEX(Pantry!$D$6:$D$305,J14)&""))
B15: =IF(J15="","",IF(K15=K14,"",K15)) | C15: =IF(J15="","",INDEX(Pantry!$B$6:$B$305,J15)) | D15: =IF(J15="","",INDEX(Pantry!$L$6:$L$305,J15)) | E15: =IF(J15="","",INDEX(Pantry!$E$6:$E$305,J15)&"") | F15: =IF(J15="","",INDEX(Pantry!$M$6:$M$305,J15)) | I15: =IFERROR(SMALL(Pantry!$O$6:$O$305,8),"") | J15: =IF(I15="","",MATCH(I15,Pantry!$O$6:$O$305,0)) | K15: =IF(J15="","",IF(INDEX(Pantry!$D$6:$D$305,J15)&""="","Other",INDEX(Pantry!$D$6:$D$305,J15)&""))
B16: =IF(J16="","",IF(K16=K15,"",K16)) | C16: =IF(J16="","",INDEX(Pantry!$B$6:$B$305,J16)) | D16: =IF(J16="","",INDEX(Pantry!$L$6:$L$305,J16)) | E16: =IF(J16="","",INDEX(Pantry!$E$6:$E$305,J16)&"") | F16: =IF(J16="","",INDEX(Pantry!$M$6:$M$305,J16)) | I16: =IFERROR(SMALL(Pantry!$O$6:$O$305,9),"") | J16: =IF(I16="","",MATCH(I16,Pantry!$O$6:$O$305,0)) | K16: =IF(J16="","",IF(INDEX(Pantry!$D$6:$D$305,J16)&""="","Other",INDEX(Pantry!$D$6:$D$305,J16)&""))
B17: =IF(J17="","",IF(K17=K16,"",K17)) | C17: =IF(J17="","",INDEX(Pantry!$B$6:$B$305,J17)) | D17: =IF(J17="","",INDEX(Pantry!$L$6:$L$305,J17)) | E17: =IF(J17="","",INDEX(Pantry!$E$6:$E$305,J17)&"") | F17: =IF(J17="","",INDEX(Pantry!$M$6:$M$305,J17)) | I17: =IFERROR(SMALL(Pantry!$O$6:$O$305,10),"") | J17: =IF(I17="","",MATCH(I17,Pantry!$O$6:$O$305,0)) | K17: =IF(J17="","",IF(INDEX(Pantry!$D$6:$D$305,J17)&""="","Other",INDEX(Pantry!$D$6:$D$305,J17)&""))
B18: =IF(J18="","",IF(K18=K17,"",K18)) | C18: =IF(J18="","",INDEX(Pantry!$B$6:$B$305,J18)) | D18: =IF(J18="","",INDEX(Pantry!$L$6:$L$305,J18)) | E18: =IF(J18="","",INDEX(Pantry!$E$6:$E$305,J18)&"") | F18: =IF(J18="","",INDEX(Pantry!$M$6:$M$305,J18)) | I18: =IFERROR(SMALL(Pantry!$O$6:$O$305,11),"") | J18: =IF(I18="","",MATCH(I18,Pantry!$O$6:$O$305,0)) | K18: =IF(J18="","",IF(INDEX(Pantry!$D$6:$D$305,J18)&""="","Other",INDEX(Pantry!$D$6:$D$305,J18)&""))
B19: =IF(J19="","",IF(K19=K18,"",K19)) | C19: =IF(J19="","",INDEX(Pantry!$B$6:$B$305,J19)) | D19: =IF(J19="","",INDEX(Pantry!$L$6:$L$305,J19)) | E19: =IF(J19="","",INDEX(Pantry!$E$6:$E$305,J19)&"") | F19: =IF(J19="","",INDEX(Pantry!$M$6:$M$305,J19)) | I19: =IFERROR(SMALL(Pantry!$O$6:$O$305,12),"") | J19: =IF(I19="","",MATCH(I19,Pantry!$O$6:$O$305,0)) | K19: =IF(J19="","",IF(INDEX(Pantry!$D$6:$D$305,J19)&""="","Other",INDEX(Pantry!$D$6:$D$305,J19)&""))
B20: =IF(J20="","",IF(K20=K19,"",K20)) | C20: =IF(J20="","",INDEX(Pantry!$B$6:$B$305,J20)) | D20: =IF(J20="","",INDEX(Pantry!$L$6:$L$305,J20)) | E20: =IF(J20="","",INDEX(Pantry!$E$6:$E$305,J20)&"") | F20: =IF(J20="","",INDEX(Pantry!$M$6:$M$305,J20)) | I20: =IFERROR(SMALL(Pantry!$O$6:$O$305,13),"") | J20: =IF(I20="","",MATCH(I20,Pantry!$O$6:$O$305,0)) | K20: =IF(J20="","",IF(INDEX(Pantry!$D$6:$D$305,J20)&""="","Other",INDEX(Pantry!$D$6:$D$305,J20)&""))
B21: =IF(J21="","",IF(K21=K20,"",K21)) | C21: =IF(J21="","",INDEX(Pantry!$B$6:$B$305,J21)) | D21: =IF(J21="","",INDEX(Pantry!$L$6:$L$305,J21)) | E21: =IF(J21="","",INDEX(Pantry!$E$6:$E$305,J21)&"") | F21: =IF(J21="","",INDEX(Pantry!$M$6:$M$305,J21)) | I21: =IFERROR(SMALL(Pantry!$O$6:$O$305,14),"") | J21: =IF(I21="","",MATCH(I21,Pantry!$O$6:$O$305,0)) | K21: =IF(J21="","",IF(INDEX(Pantry!$D$6:$D$305,J21)&""="","Other",INDEX(Pantry!$D$6:$D$305,J21)&""))
B22: =IF(J22="","",IF(K22=K21,"",K22)) | C22: =IF(J22="","",INDEX(Pantry!$B$6:$B$305,J22)) | D22: =IF(J22="","",INDEX(Pantry!$L$6:$L$305,J22)) | E22: =IF(J22="","",INDEX(Pantry!$E$6:$E$305,J22)&"") | F22: =IF(J22="","",INDEX(Pantry!$M$6:$M$305,J22)) | I22: =IFERROR(SMALL(Pantry!$O$6:$O$305,15),"") | J22: =IF(I22="","",MATCH(I22,Pantry!$O$6:$O$305,0)) | K22: =IF(J22="","",IF(INDEX(Pantry!$D$6:$D$305,J22)&""="","Other",INDEX(Pantry!$D$6:$D$305,J22)&""))
B23: =IF(J23="","",IF(K23=K22,"",K23)) | C23: =IF(J23="","",INDEX(Pantry!$B$6:$B$305,J23)) | D23: =IF(J23="","",INDEX(Pantry!$L$6:$L$305,J23)) | E23: =IF(J23="","",INDEX(Pantry!$E$6:$E$305,J23)&"") | F23: =IF(J23="","",INDEX(Pantry!$M$6:$M$305,J23)) | I23: =IFERROR(SMALL(Pantry!$O$6:$O$305,16),"") | J23: =IF(I23="","",MATCH(I23,Pantry!$O$6:$O$305,0)) | K23: =IF(J23="","",IF(INDEX(Pantry!$D$6:$D$305,J23)&""="","Other",INDEX(Pantry!$D$6:$D$305,J23)&""))
B24: =IF(J24="","",IF(K24=K23,"",K24)) | C24: =IF(J24="","",INDEX(Pantry!$B$6:$B$305,J24)) | D24: =IF(J24="","",INDEX(Pantry!$L$6:$L$305,J24)) | E24: =IF(J24="","",INDEX(Pantry!$E$6:$E$305,J24)&"") | F24: =IF(J24="","",INDEX(Pantry!$M$6:$M$305,J24)) | I24: =IFERROR(SMALL(Pantry!$O$6:$O$305,17),"") | J24: =IF(I24="","",MATCH(I24,Pantry!$O$6:$O$305,0)) | K24: =IF(J24="","",IF(INDEX(Pantry!$D$6:$D$305,J24)&""="","Other",INDEX(Pantry!$D$6:$D$305,J24)&""))
B25: =IF(J25="","",IF(K25=K24,"",K25)) | C25: =IF(J25="","",INDEX(Pantry!$B$6:$B$305,J25)) | D25: =IF(J25="","",INDEX(Pantry!$L$6:$L$305,J25)) | E25: =IF(J25="","",INDEX(Pantry!$E$6:$E$305,J25)&"") | F25: =IF(J25="","",INDEX(Pantry!$M$6:$M$305,J25)) | I25: =IFERROR(SMALL(Pantry!$O$6:$O$305,18),"") | J25: =IF(I25="","",MATCH(I25,Pantry!$O$6:$O$305,0)) | K25: =IF(J25="","",IF(INDEX(Pantry!$D$6:$D$305,J25)&""="","Other",INDEX(Pantry!$D$6:$D$305,J25)&""))
B26: =IF(J26="","",IF(K26=K25,"",K26)) | C26: =IF(J26="","",INDEX(Pantry!$B$6:$B$305,J26)) | D26: =IF(J26="","",INDEX(Pantry!$L$6:$L$305,J26)) | E26: =IF(J26="","",INDEX(Pantry!$E$6:$E$305,J26)&"") | F26: =IF(J26="","",INDEX(Pantry!$M$6:$M$305,J26)) | I26: =IFERROR(SMALL(Pantry!$O$6:$O$305,19),"") | J26: =IF(I26="","",MATCH(I26,Pantry!$O$6:$O$305,0)) | K26: =IF(J26="","",IF(INDEX(Pantry!$D$6:$D$305,J26)&""="","Other",INDEX(Pantry!$D$6:$D$305,J26)&""))
B27: =IF(J27="","",IF(K27=K26,"",K27)) | C27: =IF(J27="","",INDEX(Pantry!$B$6:$B$305,J27)) | D27: =IF(J27="","",INDEX(Pantry!$L$6:$L$305,J27)) | E27: =IF(J27="","",INDEX(Pantry!$E$6:$E$305,J27)&"") | F27: =IF(J27="","",INDEX(Pantry!$M$6:$M$305,J27)) | I27: =IFERROR(SMALL(Pantry!$O$6:$O$305,20),"") | J27: =IF(I27="","",MATCH(I27,Pantry!$O$6:$O$305,0)) | K27: =IF(J27="","",IF(INDEX(Pantry!$D$6:$D$305,J27)&""="","Other",INDEX(Pantry!$D$6:$D$305,J27)&""))
B28: =IF(J28="","",IF(K28=K27,"",K28)) | C28: =IF(J28="","",INDEX(Pantry!$B$6:$B$305,J28)) | D28: =IF(J28="","",INDEX(Pantry!$L$6:$L$305,J28)) | E28: =IF(J28="","",INDEX(Pantry!$E$6:$E$305,J28)&"") | F28: =IF(J28="","",INDEX(Pantry!$M$6:$M$305,J28)) | I28: =IFERROR(SMALL(Pantry!$O$6:$O$305,21),"") | J28: =IF(I28="","",MATCH(I28,Pantry!$O$6:$O$305,0)) | K28: =IF(J28="","",IF(INDEX(Pantry!$D$6:$D$305,J28)&""="","Other",INDEX(Pantry!$D$6:$D$305,J28)&""))
B29: =IF(J29="","",IF(K29=K28,"",K29)) | C29: =IF(J29="","",INDEX(Pantry!$B$6:$B$305,J29)) | D29: =IF(J29="","",INDEX(Pantry!$L$6:$L$305,J29)) | E29: =IF(J29="","",INDEX(Pantry!$E$6:$E$305,J29)&"") | F29: =IF(J29="","",INDEX(Pantry!$M$6:$M$305,J29)) | I29: =IFERROR(SMALL(Pantry!$O$6:$O$305,22),"") | J29: =IF(I29="","",MATCH(I29,Pantry!$O$6:$O$305,0)) | K29: =IF(J29="","",IF(INDEX(Pantry!$D$6:$D$305,J29)&""="","Other",INDEX(Pantry!$D$6:$D$305,J29)&""))
B30: =IF(J30="","",IF(K30=K29,"",K30)) | C30: =IF(J30="","",INDEX(Pantry!$B$6:$B$305,J30)) | D30: =IF(J30="","",INDEX(Pantry!$L$6:$L$305,J30)) | E30: =IF(J30="","",INDEX(Pantry!$E$6:$E$305,J30)&"") | F30: =IF(J30="","",INDEX(Pantry!$M$6:$M$305,J30)) | I30: =IFERROR(SMALL(Pantry!$O$6:$O$305,23),"") | J30: =IF(I30="","",MATCH(I30,Pantry!$O$6:$O$305,0)) | K30: =IF(J30="","",IF(INDEX(Pantry!$D$6:$D$305,J30)&""="","Other",INDEX(Pantry!$D$6:$D$305,J30)&""))
B31: =IF(J31="","",IF(K31=K30,"",K31)) | C31: =IF(J31="","",INDEX(Pantry!$B$6:$B$305,J31)) | D31: =IF(J31="","",INDEX(Pantry!$L$6:$L$305,J31)) | E31: =IF(J31="","",INDEX(Pantry!$E$6:$E$305,J31)&"") | F31: =IF(J31="","",INDEX(Pantry!$M$6:$M$305,J31)) | I31: =IFERROR(SMALL(Pantry!$O$6:$O$305,24),"") | J31: =IF(I31="","",MATCH(I31,Pantry!$O$6:$O$305,0)) | K31: =IF(J31="","",IF(INDEX(Pantry!$D$6:$D$305,J31)&""="","Other",INDEX(Pantry!$D$6:$D$305,J31)&""))
B32: =IF(J32="","",IF(K32=K31,"",K32)) | C32: =IF(J32="","",INDEX(Pantry!$B$6:$B$305,J32)) | D32: =IF(J32="","",INDEX(Pantry!$L$6:$L$305,J32)) | E32: =IF(J32="","",INDEX(Pantry!$E$6:$E$305,J32)&"") | F32: =IF(J32="","",INDEX(Pantry!$M$6:$M$305,J32)) | I32: =IFERROR(SMALL(Pantry!$O$6:$O$305,25),"") | J32: =IF(I32="","",MATCH(I32,Pantry!$O$6:$O$305,0)) | K32: =IF(J32="","",IF(INDEX(Pantry!$D$6:$D$305,J32)&""="","Other",INDEX(Pantry!$D$6:$D$305,J32)&""))
B33: =IF(J33="","",IF(K33=K32,"",K33)) | C33: =IF(J33="","",INDEX(Pantry!$B$6:$B$305,J33)) | D33: =IF(J33="","",INDEX(Pantry!$L$6:$L$305,J33)) | E33: =IF(J33="","",INDEX(Pantry!$E$6:$E$305,J33)&"") | F33: =IF(J33="","",INDEX(Pantry!$M$6:$M$305,J33)) | I33: =IFERROR(SMALL(Pantry!$O$6:$O$305,26),"") | J33: =IF(I33="","",MATCH(I33,Pantry!$O$6:$O$305,0)) | K33: =IF(J33="","",IF(INDEX(Pantry!$D$6:$D$305,J33)&""="","Other",INDEX(Pantry!$D$6:$D$305,J33)&""))
B34: =IF(J34="","",IF(K34=K33,"",K34)) | C34: =IF(J34="","",INDEX(Pantry!$B$6:$B$305,J34)) | D34: =IF(J34="","",INDEX(Pantry!$L$6:$L$305,J34)) | E34: =IF(J34="","",INDEX(Pantry!$E$6:$E$305,J34)&"") | F34: =IF(J34="","",INDEX(Pantry!$M$6:$M$305,J34)) | I34: =IFERROR(SMALL(Pantry!$O$6:$O$305,27),"") | J34: =IF(I34="","",MATCH(I34,Pantry!$O$6:$O$305,0)) | K34: =IF(J34="","",IF(INDEX(Pantry!$D$6:$D$305,J34)&""="","Other",INDEX(Pantry!$D$6:$D$305,J34)&""))
B35: =IF(J35="","",IF(K35=K34,"",K35)) | C35: =IF(J35="","",INDEX(Pantry!$B$6:$B$305,J35)) | D35: =IF(J35="","",INDEX(Pantry!$L$6:$L$305,J35)) | E35: =IF(J35="","",INDEX(Pantry!$E$6:$E$305,J35)&"") | F35: =IF(J35="","",INDEX(Pantry!$M$6:$M$305,J35)) | I35: =IFERROR(SMALL(Pantry!$O$6:$O$305,28),"") | J35: =IF(I35="","",MATCH(I35,Pantry!$O$6:$O$305,0)) | K35: =IF(J35="","",IF(INDEX(Pantry!$D$6:$D$305,J35)&""="","Other",INDEX(Pantry!$D$6:$D$305,J35)&""))
B36: =IF(J36="","",IF(K36=K35,"",K36)) | C36: =IF(J36="","",INDEX(Pantry!$B$6:$B$305,J36)) | D36: =IF(J36="","",INDEX(Pantry!$L$6:$L$305,J36)) | E36: =IF(J36="","",INDEX(Pantry!$E$6:$E$305,J36)&"") | F36: =IF(J36="","",INDEX(Pantry!$M$6:$M$305,J36)) | I36: =IFERROR(SMALL(Pantry!$O$6:$O$305,29),"") | J36: =IF(I36="","",MATCH(I36,Pantry!$O$6:$O$305,0)) | K36: =IF(J36="","",IF(INDEX(Pantry!$D$6:$D$305,J36)&""="","Other",INDEX(Pantry!$D$6:$D$305,J36)&""))
B37: =IF(J37="","",IF(K37=K36,"",K37)) | C37: =IF(J37="","",INDEX(Pantry!$B$6:$B$305,J37)) | D37: =IF(J37="","",INDEX(Pantry!$L$6:$L$305,J37)) | E37: =IF(J37="","",INDEX(Pantry!$E$6:$E$305,J37)&"") | F37: =IF(J37="","",INDEX(Pantry!$M$6:$M$305,J37)) | I37: =IFERROR(SMALL(Pantry!$O$6:$O$305,30),"") | J37: =IF(I37="","",MATCH(I37,Pantry!$O$6:$O$305,0)) | K37: =IF(J37="","",IF(INDEX(Pantry!$D$6:$D$305,J37)&""="","Other",INDEX(Pantry!$D$6:$D$305,J37)&""))
B38: =IF(J38="","",IF(K38=K37,"",K38)) | C38: =IF(J38="","",INDEX(Pantry!$B$6:$B$305,J38)) | D38: =IF(J38="","",INDEX(Pantry!$L$6:$L$305,J38)) | E38: =IF(J38="","",INDEX(Pantry!$E$6:$E$305,J38)&"") | F38: =IF(J38="","",INDEX(Pantry!$M$6:$M$305,J38)) | I38: =IFERROR(SMALL(Pantry!$O$6:$O$305,31),"") | J38: =IF(I38="","",MATCH(I38,Pantry!$O$6:$O$305,0)) | K38: =IF(J38="","",IF(INDEX(Pantry!$D$6:$D$305,J38)&""="","Other",INDEX(Pantry!$D$6:$D$305,J38)&""))
B39: =IF(J39="","",IF(K39=K38,"",K39)) | C39: =IF(J39="","",INDEX(Pantry!$B$6:$B$305,J39)) | D39: =IF(J39="","",INDEX(Pantry!$L$6:$L$305,J39)) | E39: =IF(J39="","",INDEX(Pantry!$E$6:$E$305,J39)&"") | F39: =IF(J39="","",INDEX(Pantry!$M$6:$M$305,J39)) | I39: =IFERROR(SMALL(Pantry!$O$6:$O$305,32),"") | J39: =IF(I39="","",MATCH(I39,Pantry!$O$6:$O$305,0)) | K39: =IF(J39="","",IF(INDEX(Pantry!$D$6:$D$305,J39)&""="","Other",INDEX(Pantry!$D$6:$D$305,J39)&""))
B40: =IF(J40="","",IF(K40=K39,"",K40)) | C40: =IF(J40="","",INDEX(Pantry!$B$6:$B$305,J40)) | D40: =IF(J40="","",INDEX(Pantry!$L$6:$L$305,J40)) | E40: =IF(J40="","",INDEX(Pantry!$E$6:$E$305,J40)&"") | F40: =IF(J40="","",INDEX(Pantry!$M$6:$M$305,J40)) | I40: =IFERROR(SMALL(Pantry!$O$6:$O$305,33),"") | J40: =IF(I40="","",MATCH(I40,Pantry!$O$6:$O$305,0)) | K40: =IF(J40="","",IF(INDEX(Pantry!$D$6:$D$305,J40)&""="","Other",INDEX(Pantry!$D$6:$D$305,J40)&""))
B41: =IF(J41="","",IF(K41=K40,"",K41)) | C41: =IF(J41="","",INDEX(Pantry!$B$6:$B$305,J41)) | D41: =IF(J41="","",INDEX(Pantry!$L$6:$L$305,J41)) | E41: =IF(J41="","",INDEX(Pantry!$E$6:$E$305,J41)&"") | F41: =IF(J41="","",INDEX(Pantry!$M$6:$M$305,J41)) | I41: =IFERROR(SMALL(Pantry!$O$6:$O$305,34),"") | J41: =IF(I41="","",MATCH(I41,Pantry!$O$6:$O$305,0)) | K41: =IF(J41="","",IF(INDEX(Pantry!$D$6:$D$305,J41)&""="","Other",INDEX(Pantry!$D$6:$D$305,J41)&""))
B42: =IF(J42="","",IF(K42=K41,"",K42)) | C42: =IF(J42="","",INDEX(Pantry!$B$6:$B$305,J42)) | D42: =IF(J42="","",INDEX(Pantry!$L$6:$L$305,J42)) | E42: =IF(J42="","",INDEX(Pantry!$E$6:$E$305,J42)&"") | F42: =IF(J42="","",INDEX(Pantry!$M$6:$M$305,J42)) | I42: =IFERROR(SMALL(Pantry!$O$6:$O$305,35),"") | J42: =IF(I42="","",MATCH(I42,Pantry!$O$6:$O$305,0)) | K42: =IF(J42="","",IF(INDEX(Pantry!$D$6:$D$305,J42)&""="","Other",INDEX(Pantry!$D$6:$D$305,J42)&""))
B43: =IF(J43="","",IF(K43=K42,"",K43)) | C43: =IF(J43="","",INDEX(Pantry!$B$6:$B$305,J43)) | D43: =IF(J43="","",INDEX(Pantry!$L$6:$L$305,J43)) | E43: =IF(J43="","",INDEX(Pantry!$E$6:$E$305,J43)&"") | F43: =IF(J43="","",INDEX(Pantry!$M$6:$M$305,J43)) | I43: =IFERROR(SMALL(Pantry!$O$6:$O$305,36),"") | J43: =IF(I43="","",MATCH(I43,Pantry!$O$6:$O$305,0)) | K43: =IF(J43="","",IF(INDEX(Pantry!$D$6:$D$305,J43)&""="","Other",INDEX(Pantry!$D$6:$D$305,J43)&""))
...

Sheet Recipes
B2: Recipes
B3: One line per recipe. Its ingredients go on the Ingredients tab.
B5: Recipe | C5: Meal | D5: Serves | E5: Minutes | F5: Link or notes | G5: Times this week | H5: Servings this week | I5: Cost per serving | J5: Ingredients
B6: Overnight oats | C6: Breakfast | D6: 1 | E6: 5 | F6: Make it the night before | G6: =IF(B6="","",COUNTIFS('Week plan'!$C$9:$I$12,B6)) | H6: =IF(B6="","",SUMIFS('Week plan'!$Z$9:$AF$12,'Week plan'!$C$9:$I$12,B6)) | I6: =IF(B6="","",ROUND(SUMIFS(Ingredients!$F$6:$F$1005,Ingredients!$B$6:$B$1005,B6)/IF(N(D6)>0,D6,1),2)) | J6: =IF(B6="","",COUNTIFS(Ingredients!$B$6:$B$1005,B6)) | K6: =IF(N(G6)>0,ROW(),"")
B7: Scrambled eggs on toast | C7: Breakfast | D7: 2 | E7: 10 | G7: =IF(B7="","",COUNTIFS('Week plan'!$C$9:$I$12,B7)) | H7: =IF(B7="","",SUMIFS('Week plan'!$Z$9:$AF$12,'Week plan'!$C$9:$I$12,B7)) | I7: =IF(B7="","",ROUND(SUMIFS(Ingredients!$F$6:$F$1005,Ingredients!$B$6:$B$1005,B7)/IF(N(D7)>0,D7,1),2)) | J7: =IF(B7="","",COUNTIFS(Ingredients!$B$6:$B$1005,B7)) | K7: =IF(N(G7)>0,ROW(),"")
B8: Veggie omelette | C8: Breakfast | D8: 1 | E8: 15 | G8: =IF(B8="","",COUNTIFS('Week plan'!$C$9:$I$12,B8)) | H8: =IF(B8="","",SUMIFS('Week plan'!$Z$9:$AF$12,'Week plan'!$C$9:$I$12,B8)) | I8: =IF(B8="","",ROUND(SUMIFS(Ingredients!$F$6:$F$1005,Ingredients!$B$6:$B$1005,B8)/IF(N(D8)>0,D8,1),2)) | J8: =IF(B8="","",COUNTIFS(Ingredients!$B$6:$B$1005,B8)) | K8: =IF(N(G8)>0,ROW(),"")
B9: Pancakes | C9: Breakfast | D9: 4 | E9: 25 | F9: Weekend breakfast | G9: =IF(B9="","",COUNTIFS('Week plan'!$C$9:$I$12,B9)) | H9: =IF(B9="","",SUMIFS('Week plan'!$Z$9:$AF$12,'Week plan'!$C$9:$I$12,B9)) | I9: =IF(B9="","",ROUND(SUMIFS(Ingredients!$F$6:$F$1005,Ingredients!$B$6:$B$1005,B9)/IF(N(D9)>0,D9,1),2)) | J9: =IF(B9="","",COUNTIFS(Ingredients!$B$6:$B$1005,B9)) | K9: =IF(N(G9)>0,ROW(),"")
B10: Chicken stir fry with rice | C10: Dinner | D10: 4 | E10: 30 | G10: =IF(B10="","",COUNTIFS('Week plan'!$C$9:$I$12,B10)) | H10: =IF(B10="","",SUMIFS('Week plan'!$Z$9:$AF$12,'Week plan'!$C$9:$I$12,B10)) | I10: =IF(B10="","",ROUND(SUMIFS(Ingredients!$F$6:$F$1005,Ingredients!$B$6:$B$1005,B10)/IF(N(D10)>0,D10,1),2)) | J10: =IF(B10="","",COUNTIFS(Ingredients!$B$6:$B$1005,B10)) | K10: =IF(N(G10)>0,ROW(),"")
B11: Spaghetti bolognese | C11: Dinner | D11: 4 | E11: 45 | F11: Freezes well | G11: =IF(B11="","",COUNTIFS('Week plan'!$C$9:$I$12,B11)) | H11: =IF(B11="","",SUMIFS('Week plan'!$Z$9:$AF$12,'Week plan'!$C$9:$I$12,B11)) | I11: =IF(B11="","",ROUND(SUMIFS(Ingredients!$F$6:$F$1005,Ingredients!$B$6:$B$1005,B11)/IF(N(D11)>0,D11,1),2)) | J11: =IF(B11="","",COUNTIFS(Ingredients!$B$6:$B$1005,B11)) | K11: =IF(N(G11)>0,ROW(),"")
B12: Sheet pan salmon and potatoes | C12: Dinner | D12: 2 | E12: 35 | G12: =IF(B12="","",COUNTIFS('Week plan'!$C$9:$I$12,B12)) | H12: =IF(B12="","",SUMIFS('Week plan'!$Z$9:$AF$12,'Week plan'!$C$9:$I$12,B12)) | I12: =IF(B12="","",ROUND(SUMIFS(Ingredients!$F$6:$F$1005,Ingredients!$B$6:$B$1005,B12)/IF(N(D12)>0,D12,1),2)) | J12: =IF(B12="","",COUNTIFS(Ingredients!$B$6:$B$1005,B12)) | K12: =IF(N(G12)>0,ROW(),"")
B13: Black bean tacos | C13: Dinner | D13: 4 | E13: 20 | G13: =IF(B13="","",COUNTIFS('Week plan'!$C$9:$I$12,B13)) | H13: =IF(B13="","",SUMIFS('Week plan'!$Z$9:$AF$12,'Week plan'!$C$9:$I$12,B13)) | I13: =IF(B13="","",ROUND(SUMIFS(Ingredients!$F$6:$F$1005,Ingredients!$B$6:$B$1005,B13)/IF(N(D13)>0,D13,1),2)) | J13: =IF(B13="","",COUNTIFS(Ingredients!$B$6:$B$1005,B13)) | K13: =IF(N(G13)>0,ROW(),"")
B14: Homemade pizza | C14: Dinner | D14: 4 | E14: 30 | F14: Friday night | G14: =IF(B14="","",COUNTIFS('Week plan'!$C$9:$I$12,B14)) | H14: =IF(B14="","",SUMIFS('Week plan'!$Z$9:$AF$12,'Week plan'!$C$9:$I$12,B14)) | I14: =IF(B14="","",ROUND(SUMIFS(Ingredients!$F$6:$F$1005,Ingredients!$B$6:$B$1005,B14)/IF(N(D14)>0,D14,1),2)) | J14: =IF(B14="","",COUNTIFS(Ingredients!$B$6:$B$1005,B14)) | K14: =IF(N(G14)>0,ROW(),"")
B15: Beef chili | C15: Dinner | D15: 6 | E15: 60 | F15: Double it and freeze half | G15: =IF(B15="","",COUNTIFS('Week plan'!$C$9:$I$12,B15)) | H15: =IF(B15="","",SUMIFS('Week plan'!$Z$9:$AF$12,'Week plan'!$C$9:$I$12,B15)) | I15: =IF(B15="","",ROUND(SUMIFS(Ingredients!$F$6:$F$1005,Ingredients!$B$6:$B$1005,B15)/IF(N(D15)>0,D15,1),2)) | J15: =IF(B15="","",COUNTIFS(Ingredients!$B$6:$B$1005,B15)) | K15: =IF(N(G15)>0,ROW(),"")
B16: Chicken Caesar wraps | C16: Lunch | D16: 2 | E16: 15 | G16: =IF(B16="","",COUNTIFS('Week plan'!$C$9:$I$12,B16)) | H16: =IF(B16="","",SUMIFS('Week plan'!$Z$9:$AF$12,'Week plan'!$C$9:$I$12,B16)) | I16: =IF(B16="","",ROUND(SUMIFS(Ingredients!$F$6:$F$1005,Ingredients!$B$6:$B$1005,B16)/IF(N(D16)>0,D16,1),2)) | J16: =IF(B16="","",COUNTIFS(Ingredients!$B$6:$B$1005,B16)) | K16: =IF(N(G16)>0,ROW(),"")
B17: Lentil soup | C17: Lunch | D17: 6 | E17: 45 | F17: Freezes well | G17: =IF(B17="","",COUNTIFS('Week plan'!$C$9:$I$12,B17)) | H17: =IF(B17="","",SUMIFS('Week plan'!$Z$9:$AF$12,'Week plan'!$C$9:$I$12,B17)) | I17: =IF(B17="","",ROUND(SUMIFS(Ingredients!$F$6:$F$1005,Ingredients!$B$6:$B$1005,B17)/IF(N(D17)>0,D17,1),2)) | J17: =IF(B17="","",COUNTIFS(Ingredients!$B$6:$B$1005,B17)) | K17: =IF(N(G17)>0,ROW(),"")
B18: Tuna pasta salad | C18: Lunch | D18: 4 | E18: 20 | G18: =IF(B18="","",COUNTIFS('Week plan'!$C$9:$I$12,B18)) | H18: =IF(B18="","",SUMIFS('Week plan'!$Z$9:$AF$12,'Week plan'!$C$9:$I$12,B18)) | I18: =IF(B18="","",ROUND(SUMIFS(Ingredients!$F$6:$F$1005,Ingredients!$B$6:$B$1005,B18)/IF(N(D18)>0,D18,1),2)) | J18: =IF(B18="","",COUNTIFS(Ingredients!$B$6:$B$1005,B18)) | K18: =IF(N(G18)>0,ROW(),"")
B19: Yogurt and berries | C19: Snack | D19: 1 | E19: 2 | G19: =IF(B19="","",COUNTIFS('Week plan'!$C$9:$I$12,B19)) | H19: =IF(B19="","",SUMIFS('Week plan'!$Z$9:$AF$12,'Week plan'!$C$9:$I$12,B19)) | I19: =IF(B19="","",ROUND(SUMIFS(Ingredients!$F$6:$F$1005,Ingredients!$B$6:$B$1005,B19)/IF(N(D19)>0,D19,1),2)) | J19: =IF(B19="","",COUNTIFS(Ingredients!$B$6:$B$1005,B19)) | K19: =IF(N(G19)>0,ROW(),"")
B20: Apple and peanut butter | C20: Snack | D20: 1 | E20: 2 | G20: =IF(B20="","",COUNTIFS('Week plan'!$C$9:$I$12,B20)) | H20: =IF(B20="","",SUMIFS('Week plan'!$Z$9:$AF$12,'Week plan'!$C$9:$I$12,B20)) | I20: =IF(B20="","",ROUND(SUMIFS(Ingredients!$F$6:$F$1005,Ingredients!$B$6:$B$1005,B20)/IF(N(D20)>0,D20,1),2)) | J20: =IF(B20="","",COUNTIFS(Ingredients!$B$6:$B$1005,B20)) | K20: =IF(N(G20)>0,ROW(),"")
G21: =IF(B21="","",COUNTIFS('Week plan'!$C$9:$I$12,B21)) | H21: =IF(B21="","",SUMIFS('Week plan'!$Z$9:$AF$12,'Week plan'!$C$9:$I$12,B21)) | I21: =IF(B21="","",ROUND(SUMIFS(Ingredients!$F$6:$F$1005,Ingredients!$B$6:$B$1005,B21)/IF(N(D21)>0,D21,1),2)) | J21: =IF(B21="","",COUNTIFS(Ingredients!$B$6:$B$1005,B21)) | K21: =IF(N(G21)>0,ROW(),"")
G22: =IF(B22="","",COUNTIFS('Week plan'!$C$9:$I$12,B22)) | H22: =IF(B22="","",SUMIFS('Week plan'!$Z$9:$AF$12,'Week plan'!$C$9:$I$12,B22)) | I22: =IF(B22="","",ROUND(SUMIFS(Ingredients!$F$6:$F$1005,Ingredients!$B$6:$B$1005,B22)/IF(N(D22)>0,D22,1),2)) | J22: =IF(B22="","",COUNTIFS(Ingredients!$B$6:$B$1005,B22)) | K22: =IF(N(G22)>0,ROW(),"")
G23: =IF(B23="","",COUNTIFS('Week plan'!$C$9:$I$12,B23)) | H23: =IF(B23="","",SUMIFS('Week plan'!$Z$9:$AF$12,'Week plan'!$C$9:$I$12,B23)) | I23: =IF(B23="","",ROUND(SUMIFS(Ingredients!$F$6:$F$1005,Ingredients!$B$6:$B$1005,B23)/IF(N(D23)>0,D23,1),2)) | J23: =IF(B23="","",COUNTIFS(Ingredients!$B$6:$B$1005,B23)) | K23: =IF(N(G23)>0,ROW(),"")
G24: =IF(B24="","",COUNTIFS('Week plan'!$C$9:$I$12,B24)) | H24: =IF(B24="","",SUMIFS('Week plan'!$Z$9:$AF$12,'Week plan'!$C$9:$I$12,B24)) | I24: =IF(B24="","",ROUND(SUMIFS(Ingredients!$F$6:$F$1005,Ingredients!$B$6:$B$1005,B24)/IF(N(D24)>0,D24,1),2)) | J24: =IF(B24="","",COUNTIFS(Ingredients!$B$6:$B$1005,B24)) | K24: =IF(N(G24)>0,ROW(),"")
G25: =IF(B25="","",COUNTIFS('Week plan'!$C$9:$I$12,B25)) | H25: =IF(B25="","",SUMIFS('Week plan'!$Z$9:$AF$12,'Week plan'!$C$9:$I$12,B25)) | I25: =IF(B25="","",ROUND(SUMIFS(Ingredients!$F$6:$F$1005,Ingredients!$B$6:$B$1005,B25)/IF(N(D25)>0,D25,1),2)) | J25: =IF(B25="","",COUNTIFS(Ingredients!$B$6:$B$1005,B25)) | K25: =IF(N(G25)>0,ROW(),"")
G26: =IF(B26="","",COUNTIFS('Week plan'!$C$9:$I$12,B26)) | H26: =IF(B26="","",SUMIFS('Week plan'!$Z$9:$AF$12,'Week plan'!$C$9:$I$12,B26)) | I26: =IF(B26="","",ROUND(SUMIFS(Ingredients!$F$6:$F$1005,Ingredients!$B$6:$B$1005,B26)/IF(N(D26)>0,D26,1),2)) | J26: =IF(B26="","",COUNTIFS(Ingredients!$B$6:$B$1005,B26)) | K26: =IF(N(G26)>0,ROW(),"")
G27: =IF(B27="","",COUNTIFS('Week plan'!$C$9:$I$12,B27)) | H27: =IF(B27="","",SUMIFS('Week plan'!$Z$9:$AF$12,'Week plan'!$C$9:$I$12,B27)) | I27: =IF(B27="","",ROUND(SUMIFS(Ingredients!$F$6:$F$1005,Ingredients!$B$6:$B$1005,B27)/IF(N(D27)>0,D27,1),2)) | J27: =IF(B27="","",COUNTIFS(Ingredients!$B$6:$B$1005,B27)) | K27: =IF(N(G27)>0,ROW(),"")
G28: =IF(B28="","",COUNTIFS('Week plan'!$C$9:$I$12,B28)) | H28: =IF(B28="","",SUMIFS('Week plan'!$Z$9:$AF$12,'Week plan'!$C$9:$I$12,B28)) | I28: =IF(B28="","",ROUND(SUMIFS(Ingredients!$F$6:$F$1005,Ingredients!$B$6:$B$1005,B28)/IF(N(D28)>0,D28,1),2)) | J28: =IF(B28="","",COUNTIFS(Ingredients!$B$6:$B$1005,B28)) | K28: =IF(N(G28)>0,ROW(),"")
G29: =IF(B29="","",COUNTIFS('Week plan'!$C$9:$I$12,B29)) | H29: =IF(B29="","",SUMIFS('Week plan'!$Z$9:$AF$12,'Week plan'!$C$9:$I$12,B29)) | I29: =IF(B29="","",ROUND(SUMIFS(Ingredients!$F$6:$F$1005,Ingredients!$B$6:$B$1005,B29)/IF(N(D29)>0,D29,1),2)) | J29: =IF(B29="","",COUNTIFS(Ingredients!$B$6:$B$1005,B29)) | K29: =IF(N(G29)>0,ROW(),"")
G30: =IF(B30="","",COUNTIFS('Week plan'!$C$9:$I$12,B30)) | H30: =IF(B30="","",SUMIFS('Week plan'!$Z$9:$AF$12,'Week plan'!$C$9:$I$12,B30)) | I30: =IF(B30="","",ROUND(SUMIFS(Ingredients!$F$6:$F$1005,Ingredients!$B$6:$B$1005,B30)/IF(N(D30)>0,D30,1),2)) | J30: =IF(B30="","",COUNTIFS(Ingredients!$B$6:$B$1005,B30)) | K30: =IF(N(G30)>0,ROW(),"")
G31: =IF(B31="","",COUNTIFS('Week plan'!$C$9:$I$12,B31)) | H31: =IF(B31="","",SUMIFS('Week plan'!$Z$9:$AF$12,'Week plan'!$C$9:$I$12,B31)) | I31: =IF(B31="","",ROUND(SUMIFS(Ingredients!$F$6:$F$1005,Ingredients!$B$6:$B$1005,B31)/IF(N(D31)>0,D31,1),2)) | J31: =IF(B31="","",COUNTIFS(Ingredients!$B$6:$B$1005,B31)) | K31: =IF(N(G31)>0,ROW(),"")
G32: =IF(B32="","",COUNTIFS('Week plan'!$C$9:$I$12,B32)) | H32: =IF(B32="","",SUMIFS('Week plan'!$Z$9:$AF$12,'Week plan'!$C$9:$I$12,B32)) | I32: =IF(B32="","",ROUND(SUMIFS(Ingredients!$F$6:$F$1005,Ingredients!$B$6:$B$1005,B32)/IF(N(D32)>0,D32,1),2)) | J32: =IF(B32="","",COUNTIFS(Ingredients!$B$6:$B$1005,B32)) | K32: =IF(N(G32)>0,ROW(),"")
... G105: =IF(B105="","",COUNTIFS('Week plan'!$C$9:$I$12,B105)) | H105: =IF(B105="","",SUMIFS('Week plan'!$Z$9:$AF$12,'Week plan'!$C$9:$I$12,B105)) | I105: =IF(B105="","",ROUND(SUMIFS(Ingredients!$F$6:$F$1005,Ingredients!$B$6:$B$1005,B105)/IF(N(D105)>0,D105,1),2)) | J105: =IF(B105="","",COUNTIFS(Ingredients!$B$6:$B$1005,B105)) | K105: =IF(N(G105)>0,ROW(),"")

Sheet Ingredients
B2: Ingredients
B3: One line per ingredient of each recipe, in the unit the Pantry uses.
B5: Recipe | C5: Ingredient | D5: Quantity | E5: Unit | F5: Cost | G5: This week
B6: Overnight oats | C6: Rolled oats | D6: 0.5 | E6: =IF(C6="","",IFERROR(INDEX(Pantry!$C$6:$C$305,MATCH(C6,Pantry!$B$6:$B$305,0))&"","Add to Pantry")) | F6: =IF(OR(C6="",E6="Add to Pantry"),"",ROUND(N(D6)*INDEX(Pantry!$N$6:$N$305,MATCH(C6,Pantry!$B$6:$B$305,0)),2)) | G6: =IF(OR(B6="",C6=""),"",IFERROR(ROUND(N(D6)*N(INDEX(Recipes!$H$6:$H$105,MATCH(B6,Recipes!$B$6:$B$105,0)))/IF(N(INDEX(Recipes!$D$6:$D$105,MATCH(B6,Recipes!$B$6:$B$105,0)))>0,INDEX(Recipes!$D$6:$D$105,MATCH(B6,Recipes!$B$6:$B$105,0)),1),2),0))
B7: Overnight oats | C7: Milk | D7: 0.5 | E7: =IF(C7="","",IFERROR(INDEX(Pantry!$C$6:$C$305,MATCH(C7,Pantry!$B$6:$B$305,0))&"","Add to Pantry")) | F7: =IF(OR(C7="",E7="Add to Pantry"),"",ROUND(N(D7)*INDEX(Pantry!$N$6:$N$305,MATCH(C7,Pantry!$B$6:$B$305,0)),2)) | G7: =IF(OR(B7="",C7=""),"",IFERROR(ROUND(N(D7)*N(INDEX(Recipes!$H$6:$H$105,MATCH(B7,Recipes!$B$6:$B$105,0)))/IF(N(INDEX(Recipes!$D$6:$D$105,MATCH(B7,Recipes!$B$6:$B$105,0)))>0,INDEX(Recipes!$D$6:$D$105,MATCH(B7,Recipes!$B$6:$B$105,0)),1),2),0))
B8: Overnight oats | C8: Greek yogurt | D8: 2 | E8: =IF(C8="","",IFERROR(INDEX(Pantry!$C$6:$C$305,MATCH(C8,Pantry!$B$6:$B$305,0))&"","Add to Pantry")) | F8: =IF(OR(C8="",E8="Add to Pantry"),"",ROUND(N(D8)*INDEX(Pantry!$N$6:$N$305,MATCH(C8,Pantry!$B$6:$B$305,0)),2)) | G8: =IF(OR(B8="",C8=""),"",IFERROR(ROUND(N(D8)*N(INDEX(Recipes!$H$6:$H$105,MATCH(B8,Recipes!$B$6:$B$105,0)))/IF(N(INDEX(Recipes!$D$6:$D$105,MATCH(B8,Recipes!$B$6:$B$105,0)))>0,INDEX(Recipes!$D$6:$D$105,MATCH(B8,Recipes!$B$6:$B$105,0)),1),2),0))
B9: Overnight oats | C9: Frozen berries | D9: 0.5 | E9: =IF(C9="","",IFERROR(INDEX(Pantry!$C$6:$C$305,MATCH(C9,Pantry!$B$6:$B$305,0))&"","Add to Pantry")) | F9: =IF(OR(C9="",E9="Add to Pantry"),"",ROUND(N(D9)*INDEX(Pantry!$N$6:$N$305,MATCH(C9,Pantry!$B$6:$B$305,0)),2)) | G9: =IF(OR(B9="",C9=""),"",IFERROR(ROUND(N(D9)*N(INDEX(Recipes!$H$6:$H$105,MATCH(B9,Recipes!$B$6:$B$105,0)))/IF(N(INDEX(Recipes!$D$6:$D$105,MATCH(B9,Recipes!$B$6:$B$105,0)))>0,INDEX(Recipes!$D$6:$D$105,MATCH(B9,Recipes!$B$6:$B$105,0)),1),2),0))
B10: Overnight oats | C10: Honey | D10: 1 | E10: =IF(C10="","",IFERROR(INDEX(Pantry!$C$6:$C$305,MATCH(C10,Pantry!$B$6:$B$305,0))&"","Add to Pantry")) | F10: =IF(OR(C10="",E10="Add to Pantry"),"",ROUND(N(D10)*INDEX(Pantry!$N$6:$N$305,MATCH(C10,Pantry!$B$6:$B$305,0)),2)) | G10: =IF(OR(B10="",C10=""),"",IFERROR(ROUND(N(D10)*N(INDEX(Recipes!$H$6:$H$105,MATCH(B10,Recipes!$B$6:$B$105,0)))/IF(N(INDEX(Recipes!$D$6:$D$105,MATCH(B10,Recipes!$B$6:$B$105,0)))>0,INDEX(Recipes!$D$6:$D$105,MATCH(B10,Recipes!$B$6:$B$105,0)),1),2),0))
B11: Scrambled eggs on toast | C11: Eggs | D11: 4 | E11: =IF(C11="","",IFERROR(INDEX(Pantry!$C$6:$C$305,MATCH(C11,Pantry!$B$6:$B$305,0))&"","Add to Pantry")) | F11: =IF(OR(C11="",E11="Add to Pantry"),"",ROUND(N(D11)*INDEX(Pantry!$N$6:$N$305,MATCH(C11,Pantry!$B$6:$B$305,0)),2)) | G11: =IF(OR(B11="",C11=""),"",IFERROR(ROUND(N(D11)*N(INDEX(Recipes!$H$6:$H$105,MATCH(B11,Recipes!$B$6:$B$105,0)))/IF(N(INDEX(Recipes!$D$6:$D$105,MATCH(B11,Recipes!$B$6:$B$105,0)))>0,INDEX(Recipes!$D$6:$D$105,MATCH(B11,Recipes!$B$6:$B$105,0)),1),2),0))
B12: Scrambled eggs on toast | C12: Sliced bread | D12: 4 | E12: =IF(C12="","",IFERROR(INDEX(Pantry!$C$6:$C$305,MATCH(C12,Pantry!$B$6:$B$305,0))&"","Add to Pantry")) | F12: =IF(OR(C12="",E12="Add to Pantry"),"",ROUND(N(D12)*INDEX(Pantry!$N$6:$N$305,MATCH(C12,Pantry!$B$6:$B$305,0)),2)) | G12: =IF(OR(B12="",C12=""),"",IFERROR(ROUND(N(D12)*N(INDEX(Recipes!$H$6:$H$105,MATCH(B12,Recipes!$B$6:$B$105,0)))/IF(N(INDEX(Recipes!$D$6:$D$105,MATCH(B12,Recipes!$B$6:$B$105,0)))>0,INDEX(Recipes!$D$6:$D$105,MATCH(B12,Recipes!$B$6:$B$105,0)),1),2),0))
B13: Scrambled eggs on toast | C13: Butter | D13: 1 | E13: =IF(C13="","",IFERROR(INDEX(Pantry!$C$6:$C$305,MATCH(C13,Pantry!$B$6:$B$305,0))&"","Add to Pantry")) | F13: =IF(OR(C13="",E13="Add to Pantry"),"",ROUND(N(D13)*INDEX(Pantry!$N$6:$N$305,MATCH(C13,Pantry!$B$6:$B$305,0)),2)) | G13: =IF(OR(B13="",C13=""),"",IFERROR(ROUND(N(D13)*N(INDEX(Recipes!$H$6:$H$105,MATCH(B13,Recipes!$B$6:$B$105,0)))/IF(N(INDEX(Recipes!$D$6:$D$105,MATCH(B13,Recipes!$B$6:$B$105,0)))>0,INDEX(Recipes!$D$6:$D$105,MATCH(B13,Recipes!$B$6:$B$105,0)),1),2),0))
B14: Veggie omelette | C14: Eggs | D14: 3 | E14: =IF(C14="","",IFERROR(INDEX(Pantry!$C$6:$C$305,MATCH(C14,Pantry!$B$6:$B$305,0))&"","Add to Pantry")) | F14: =IF(OR(C14="",E14="Add to Pantry"),"",ROUND(N(D14)*INDEX(Pantry!$N$6:$N$305,MATCH(C14,Pantry!$B$6:$B$305,0)),2)) | G14: =IF(OR(B14="",C14=""),"",IFERROR(ROUND(N(D14)*N(INDEX(Recipes!$H$6:$H$105,MATCH(B14,Recipes!$B$6:$B$105,0)))/IF(N(INDEX(Recipes!$D$6:$D$105,MATCH(B14,Recipes!$B$6:$B$105,0)))>0,INDEX(Recipes!$D$6:$D$105,MATCH(B14,Recipes!$B$6:$B$105,0)),1),2),0))
B15: Veggie omelette | C15: Bell pepper | D15: 0.5 | E15: =IF(C15="","",IFERROR(INDEX(Pantry!$C$6:$C$305,MATCH(C15,Pantry!$B$6:$B$305,0))&"","Add to Pantry")) | F15: =IF(OR(C15="",E15="Add to Pantry"),"",ROUND(N(D15)*INDEX(Pantry!$N$6:$N$305,MATCH(C15,Pantry!$B$6:$B$305,0)),2)) | G15: =IF(OR(B15="",C15=""),"",IFERROR(ROUND(N(D15)*N(INDEX(Recipes!$H$6:$H$105,MATCH(B15,Recipes!$B$6:$B$105,0)))/IF(N(INDEX(Recipes!$D$6:$D$105,MATCH(B15,Recipes!$B$6:$B$105,0)))>0,INDEX(Recipes!$D$6:$D$105,MATCH(B15,Recipes!$B$6:$B$105,0)),1),2),0))
B16: Veggie omelette | C16: Spinach | D16: 1 | E16: =IF(C16="","",IFERROR(INDEX(Pantry!$C$6:$C$305,MATCH(C16,Pantry!$B$6:$B$305,0))&"","Add to Pantry")) | F16: =IF(OR(C16="",E16="Add to Pantry"),"",ROUND(N(D16)*INDEX(Pantry!$N$6:$N$305,MATCH(C16,Pantry!$B$6:$B$305,0)),2)) | G16: =IF(OR(B16="",C16=""),"",IFERROR(ROUND(N(D16)*N(INDEX(Recipes!$H$6:$H$105,MATCH(B16,Recipes!$B$6:$B$105,0)))/IF(N(INDEX(Recipes!$D$6:$D$105,MATCH(B16,Recipes!$B$6:$B$105,0)))>0,INDEX(Recipes!$D$6:$D$105,MATCH(B16,Recipes!$B$6:$B$105,0)),1),2),0))
B17: Veggie omelette | C17: Cheddar | D17: 1 | E17: =IF(C17="","",IFERROR(INDEX(Pantry!$C$6:$C$305,MATCH(C17,Pantry!$B$6:$B$305,0))&"","Add to Pantry")) | F17: =IF(OR(C17="",E17="Add to Pantry"),"",ROUND(N(D17)*INDEX(Pantry!$N$6:$N$305,MATCH(C17,Pantry!$B$6:$B$305,0)),2)) | G17: =IF(OR(B17="",C17=""),"",IFERROR(ROUND(N(D17)*N(INDEX(Recipes!$H$6:$H$105,MATCH(B17,Recipes!$B$6:$B$105,0)))/IF(N(INDEX(Recipes!$D$6:$D$105,MATCH(B17,Recipes!$B$6:$B$105,0)))>0,INDEX(Recipes!$D$6:$D$105,MATCH(B17,Recipes!$B$6:$B$105,0)),1),2),0))
... B83: Apple and peanut butter | C83: Peanut butter | D83: 2 | E83: =IF(C83="","",IFERROR(INDEX(Pantry!$C$6:$C$305,MATCH(C83,Pantry!$B$6:$B$305,0))&"","Add to Pantry")) | F83: =IF(OR(C83="",E83="Add to Pantry"),"",ROUND(N(D83)*INDEX(Pantry!$N$6:$N$305,MATCH(C83,Pantry!$B$6:$B$305,0)),2)) | G83: =IF(OR(B83="",C83=""),"",IFERROR(ROUND(N(D83)*N(INDEX(Recipes!$H$6:$H$105,MATCH(B83,Recipes!$B$6:$B$105,0)))/IF(N(INDEX(Recipes!$D$6:$D$105,MATCH(B83,Recipes!$B$6:$B$105,0)))>0,INDEX(Recipes!$D$6:$D$105,MATCH(B83,Recipes!$B$6:$B$105,0)),1),2),0))
E84: =IF(C84="","",IFERROR(INDEX(Pantry!$C$6:$C$305,MATCH(C84,Pantry!$B$6:$B$305,0))&"","Add to Pantry")) | F84: =IF(OR(C84="",E84="Add to Pantry"),"",ROUND(N(D84)*INDEX(Pantry!$N$6:$N$305,MATCH(C84,Pantry!$B$6:$B$305,0)),2)) | G84: =IF(OR(B84="",C84=""),"",IFERROR(ROUND(N(D84)*N(INDEX(Recipes!$H$6:$H$105,MATCH(B84,Recipes!$B$6:$B$105,0)))/IF(N(INDEX(Recipes!$D$6:$D$105,MATCH(B84,Recipes!$B$6:$B$105,0)))>0,INDEX(Recipes!$D$6:$D$105,MATCH(B84,Recipes!$B$6:$B$105,0)),1),2),0))
E85: =IF(C85="","",IFERROR(INDEX(Pantry!$C$6:$C$305,MATCH(C85,Pantry!$B$6:$B$305,0))&"","Add to Pantry")) | F85: =IF(OR(C85="",E85="Add to Pantry"),"",ROUND(N(D85)*INDEX(Pantry!$N$6:$N$305,MATCH(C85,Pantry!$B$6:$B$305,0)),2)) | G85: =IF(OR(B85="",C85=""),"",IFERROR(ROUND(N(D85)*N(INDEX(Recipes!$H$6:$H$105,MATCH(B85,Recipes!$B$6:$B$105,0)))/IF(N(INDEX(Recipes!$D$6:$D$105,MATCH(B85,Recipes!$B$6:$B$105,0)))>0,INDEX(Recipes!$D$6:$D$105,MATCH(B85,Recipes!$B$6:$B$105,0)),1),2),0))
E86: =IF(C86="","",IFERROR(INDEX(Pantry!$C$6:$C$305,MATCH(C86,Pantry!$B$6:$B$305,0))&"","Add to Pantry")) | F86: =IF(OR(C86="",E86="Add to Pantry"),"",ROUND(N(D86)*INDEX(Pantry!$N$6:$N$305,MATCH(C86,Pantry!$B$6:$B$305,0)),2)) | G86: =IF(OR(B86="",C86=""),"",IFERROR(ROUND(N(D86)*N(INDEX(Recipes!$H$6:$H$105,MATCH(B86,Recipes!$B$6:$B$105,0)))/IF(N(INDEX(Recipes!$D$6:$D$105,MATCH(B86,Recipes!$B$6:$B$105,0)))>0,INDEX(Recipes!$D$6:$D$105,MATCH(B86,Recipes!$B$6:$B$105,0)),1),2),0))
E87: =IF(C87="","",IFERROR(INDEX(Pantry!$C$6:$C$305,MATCH(C87,Pantry!$B$6:$B$305,0))&"","Add to Pantry")) | F87: =IF(OR(C87="",E87="Add to Pantry"),"",ROUND(N(D87)*INDEX(Pantry!$N$6:$N$305,MATCH(C87,Pantry!$B$6:$B$305,0)),2)) | G87: =IF(OR(B87="",C87=""),"",IFERROR(ROUND(N(D87)*N(INDEX(Recipes!$H$6:$H$105,MATCH(B87,Recipes!$B$6:$B$105,0)))/IF(N(INDEX(Recipes!$D$6:$D$105,MATCH(B87,Recipes!$B$6:$B$105,0)))>0,INDEX(Recipes!$D$6:$D$105,MATCH(B87,Recipes!$B$6:$B$105,0)),1),2),0))
E88: =IF(C88="","",IFERROR(INDEX(Pantry!$C$6:$C$305,MATCH(C88,Pantry!$B$6:$B$305,0))&"","Add to Pantry")) | F88: =IF(OR(C88="",E88="Add to Pantry"),"",ROUND(N(D88)*INDEX(Pantry!$N$6:$N$305,MATCH(C88,Pantry!$B$6:$B$305,0)),2)) | G88: =IF(OR(B88="",C88=""),"",IFERROR(ROUND(N(D88)*N(INDEX(Recipes!$H$6:$H$105,MATCH(B88,Recipes!$B$6:$B$105,0)))/IF(N(INDEX(Recipes!$D$6:$D$105,MATCH(B88,Recipes!$B$6:$B$105,0)))>0,INDEX(Recipes!$D$6:$D$105,MATCH(B88,Recipes!$B$6:$B$105,0)),1),2),0))
E89: =IF(C89="","",IFERROR(INDEX(Pantry!$C$6:$C$305,MATCH(C89,Pantry!$B$6:$B$305,0))&"","Add to Pantry")) | F89: =IF(OR(C89="",E89="Add to Pantry"),"",ROUND(N(D89)*INDEX(Pantry!$N$6:$N$305,MATCH(C89,Pantry!$B$6:$B$305,0)),2)) | G89: =IF(OR(B89="",C89=""),"",IFERROR(ROUND(N(D89)*N(INDEX(Recipes!$H$6:$H$105,MATCH(B89,Recipes!$B$6:$B$105,0)))/IF(N(INDEX(Recipes!$D$6:$D$105,MATCH(B89,Recipes!$B$6:$B$105,0)))>0,INDEX(Recipes!$D$6:$D$105,MATCH(B89,Recipes!$B$6:$B$105,0)),1),2),0))
E90: =IF(C90="","",IFERROR(INDEX(Pantry!$C$6:$C$305,MATCH(C90,Pantry!$B$6:$B$305,0))&"","Add to Pantry")) | F90: =IF(OR(C90="",E90="Add to Pantry"),"",ROUND(N(D90)*INDEX(Pantry!$N$6:$N$305,MATCH(C90,Pantry!$B$6:$B$305,0)),2)) | G90: =IF(OR(B90="",C90=""),"",IFERROR(ROUND(N(D90)*N(INDEX(Recipes!$H$6:$H$105,MATCH(B90,Recipes!$B$6:$B$105,0)))/IF(N(INDEX(Recipes!$D$6:$D$105,MATCH(B90,Recipes!$B$6:$B$105,0)))>0,INDEX(Recipes!$D$6:$D$105,MATCH(B90,Recipes!$B$6:$B$105,0)),1),2),0))
E91: =IF(C91="","",IFERROR(INDEX(Pantry!$C$6:$C$305,MATCH(C91,Pantry!$B$6:$B$305,0))&"","Add to Pantry")) | F91: =IF(OR(C91="",E91="Add to Pantry"),"",ROUND(N(D91)*INDEX(Pantry!$N$6:$N$305,MATCH(C91,Pantry!$B$6:$B$305,0)),2)) | G91: =IF(OR(B91="",C91=""),"",IFERROR(ROUND(N(D91)*N(INDEX(Recipes!$H$6:$H$105,MATCH(B91,Recipes!$B$6:$B$105,0)))/IF(N(INDEX(Recipes!$D$6:$D$105,MATCH(B91,Recipes!$B$6:$B$105,0)))>0,INDEX(Recipes!$D$6:$D$105,MATCH(B91,Recipes!$B$6:$B$105,0)),1),2),0))
E92: =IF(C92="","",IFERROR(INDEX(Pantry!$C$6:$C$305,MATCH(C92,Pantry!$B$6:$B$305,0))&"","Add to Pantry")) | F92: =IF(OR(C92="",E92="Add to Pantry"),"",ROUND(N(D92)*INDEX(Pantry!$N$6:$N$305,MATCH(C92,Pantry!$B$6:$B$305,0)),2)) | G92: =IF(OR(B92="",C92=""),"",IFERROR(ROUND(N(D92)*N(INDEX(Recipes!$H$6:$H$105,MATCH(B92,Recipes!$B$6:$B$105,0)))/IF(N(INDEX(Recipes!$D$6:$D$105,MATCH(B92,Recipes!$B$6:$B$105,0)))>0,INDEX(Recipes!$D$6:$D$105,MATCH(B92,Recipes!$B$6:$B$105,0)),1),2),0))
E93: =IF(C93="","",IFERROR(INDEX(Pantry!$C$6:$C$305,MATCH(C93,Pantry!$B$6:$B$305,0))&"","Add to Pantry")) | F93: =IF(OR(C93="",E93="Add to Pantry"),"",ROUND(N(D93)*INDEX(Pantry!$N$6:$N$305,MATCH(C93,Pantry!$B$6:$B$305,0)),2)) | G93: =IF(OR(B93="",C93=""),"",IFERROR(ROUND(N(D93)*N(INDEX(Recipes!$H$6:$H$105,MATCH(B93,Recipes!$B$6:$B$105,0)))/IF(N(INDEX(Recipes!$D$6:$D$105,MATCH(B93,Recipes!$B$6:$B$105,0)))>0,INDEX(Recipes!$D$6:$D$105,MATCH(B93,Recipes!$B$6:$B$105,0)),1),2),0))
E94: =IF(C94="","",IFERROR(INDEX(Pantry!$C$6:$C$305,MATCH(C94,Pantry!$B$6:$B$305,0))&"","Add to Pantry")) | F94: =IF(OR(C94="",E94="Add to Pantry"),"",ROUND(N(D94)*INDEX(Pantry!$N$6:$N$305,MATCH(C94,Pantry!$B$6:$B$305,0)),2)) | G94: =IF(OR(B94="",C94=""),"",IFERROR(ROUND(N(D94)*N(INDEX(Recipes!$H$6:$H$105,MATCH(B94,Recipes!$B$6:$B$105,0)))/IF(N(INDEX(Recipes!$D$6:$D$105,MATCH(B94,Recipes!$B$6:$B$105,0)))>0,INDEX(Recipes!$D$6:$D$105,MATCH(B94,Recipes!$B$6:$B$105,0)),1),2),0))
E95: =IF(C95="","",IFERROR(INDEX(Pantry!$C$6:$C$305,MATCH(C95,Pantry!$B$6:$B$305,0))&"","Add to Pantry")) | F95: =IF(OR(C95="",E95="Add to Pantry"),"",ROUND(N(D95)*INDEX(Pantry!$N$6:$N$305,MATCH(C95,Pantry!$B$6:$B$305,0)),2)) | G95: =IF(OR(B95="",C95=""),"",IFERROR(ROUND(N(D95)*N(INDEX(Recipes!$H$6:$H$105,MATCH(B95,Recipes!$B$6:$B$105,0)))/IF(N(INDEX(Recipes!$D$6:$D$105,MATCH(B95,Recipes!$B$6:$B$105,0)))>0,INDEX(Recipes!$D$6:$D$105,MATCH(B95,Recipes!$B$6:$B$105,0)),1),2),0))
... E1005: =IF(C1005="","",IFERROR(INDEX(Pantry!$C$6:$C$305,MATCH(C1005,Pantry!$B$6:$B$305,0))&"","Add to Pantry")) | F1005: =IF(OR(C1005="",E1005="Add to Pantry"),"",ROUND(N(D1005)*INDEX(Pantry!$N$6:$N$305,MATCH(C1005,Pantry!$B$6:$B$305,0)),2)) | G1005: =IF(OR(B1005="",C1005=""),"",IFERROR(ROUND(N(D1005)*N(INDEX(Recipes!$H$6:$H$105,MATCH(B1005,Recipes!$B$6:$B$105,0)))/IF(N(INDEX(Recipes!$D$6:$D$105,MATCH(B1005,Recipes!$B$6:$B$105,0)))>0,INDEX(Recipes!$D$6:$D$105,MATCH(B1005,Recipes!$B$6:$B$105,0)),1),2),0))

Sheet Pantry
B2: Pantry
B3: Every food you buy, with its unit, store section, pack and price, and what you have at home.
B5: Item | C5: Unit | D5: Store section | E5: Pack | F5: Units in a pack | G5: Pack price | H5: Have at home | I5: Extra packs | J5: Needed this week | K5: Still needed | L5: Packs to buy | M5: Cost
B6: Onion | C6: each | D6: Fruit and vegetables | E6: bag of 6 | F6: 6 | G6: 3.49 | H6: 1 | J6: =IF(B6="","",ROUND(SUMIFS(Ingredients!$G$6:$G$1005,Ingredients!$C$6:$C$1005,B6),2)) | K6: =IF(B6="","",MAX(0,ROUND(J6-N(H6),2))) | L6: =IF(B6="","",IF(N(K6)=0,0,ROUNDUP(ROUND(K6/IF(N(F6)>0,F6,1),6),0))+N(I6)) | M6: =IF(B6="","",L6*N(G6)) | N6: =IF(B6="","",N(G6)/IF(N(F6)>0,F6,1)) | O6: =IF(OR(B6="",N(L6)=0),"",IFERROR(MATCH(D6,Settings!$B$6:$B$17,0),13)*1000+ROW())
B7: Garlic | C7: clove | D7: Fruit and vegetables | E7: bulb | F7: 10 | G7: 0.6 | H7: 4 | J7: =IF(B7="","",ROUND(SUMIFS(Ingredients!$G$6:$G$1005,Ingredients!$C$6:$C$1005,B7),2)) | K7: =IF(B7="","",MAX(0,ROUND(J7-N(H7),2))) | L7: =IF(B7="","",IF(N(K7)=0,0,ROUNDUP(ROUND(K7/IF(N(F7)>0,F7,1),6),0))+N(I7)) | M7: =IF(B7="","",L7*N(G7)) | N7: =IF(B7="","",N(G7)/IF(N(F7)>0,F7,1)) | O7: =IF(OR(B7="",N(L7)=0),"",IFERROR(MATCH(D7,Settings!$B$6:$B$17,0),13)*1000+ROW())
B8: Carrot | C8: each | D8: Fruit and vegetables | E8: 2 lb bag | F8: 12 | G8: 1.49 | J8: =IF(B8="","",ROUND(SUMIFS(Ingredients!$G$6:$G$1005,Ingredients!$C$6:$C$1005,B8),2)) | K8: =IF(B8="","",MAX(0,ROUND(J8-N(H8),2))) | L8: =IF(B8="","",IF(N(K8)=0,0,ROUNDUP(ROUND(K8/IF(N(F8)>0,F8,1),6),0))+N(I8)) | M8: =IF(B8="","",L8*N(G8)) | N8: =IF(B8="","",N(G8)/IF(N(F8)>0,F8,1)) | O8: =IF(OR(B8="",N(L8)=0),"",IFERROR(MATCH(D8,Settings!$B$6:$B$17,0),13)*1000+ROW())
B9: Celery | C9: stalk | D9: Fruit and vegetables | E9: bunch | F9: 8 | G9: 1.99 | J9: =IF(B9="","",ROUND(SUMIFS(Ingredients!$G$6:$G$1005,Ingredients!$C$6:$C$1005,B9),2)) | K9: =IF(B9="","",MAX(0,ROUND(J9-N(H9),2))) | L9: =IF(B9="","",IF(N(K9)=0,0,ROUNDUP(ROUND(K9/IF(N(F9)>0,F9,1),6),0))+N(I9)) | M9: =IF(B9="","",L9*N(G9)) | N9: =IF(B9="","",N(G9)/IF(N(F9)>0,F9,1)) | O9: =IF(OR(B9="",N(L9)=0),"",IFERROR(MATCH(D9,Settings!$B$6:$B$17,0),13)*1000+ROW())
B10: Bell pepper | C10: each | D10: Fruit and vegetables | E10: each | F10: 1 | G10: 1 | J10: =IF(B10="","",ROUND(SUMIFS(Ingredients!$G$6:$G$1005,Ingredients!$C$6:$C$1005,B10),2)) | K10: =IF(B10="","",MAX(0,ROUND(J10-N(H10),2))) | L10: =IF(B10="","",IF(N(K10)=0,0,ROUNDUP(ROUND(K10/IF(N(F10)>0,F10,1),6),0))+N(I10)) | M10: =IF(B10="","",L10*N(G10)) | N10: =IF(B10="","",N(G10)/IF(N(F10)>0,F10,1)) | O10: =IF(OR(B10="",N(L10)=0),"",IFERROR(MATCH(D10,Settings!$B$6:$B$17,0),13)*1000+ROW())
B11: Broccoli | C11: head | D11: Fruit and vegetables | E11: each | F11: 1 | G11: 1.99 | J11: =IF(B11="","",ROUND(SUMIFS(Ingredients!$G$6:$G$1005,Ingredients!$C$6:$C$1005,B11),2)) | K11: =IF(B11="","",MAX(0,ROUND(J11-N(H11),2))) | L11: =IF(B11="","",IF(N(K11)=0,0,ROUNDUP(ROUND(K11/IF(N(F11)>0,F11,1),6),0))+N(I11)) | M11: =IF(B11="","",L11*N(G11)) | N11: =IF(B11="","",N(G11)/IF(N(F11)>0,F11,1)) | O11: =IF(OR(B11="",N(L11)=0),"",IFERROR(MATCH(D11,Settings!$B$6:$B$17,0),13)*1000+ROW())
B12: Baby potatoes | C12: lb | D12: Fruit and vegetables | E12: 1.5 lb bag | F12: 1.5 | G12: 3.49 | J12: =IF(B12="","",ROUND(SUMIFS(Ingredients!$G$6:$G$1005,Ingredients!$C$6:$C$1005,B12),2)) | K12: =IF(B12="","",MAX(0,ROUND(J12-N(H12),2))) | L12: =IF(B12="","",IF(N(K12)=0,0,ROUNDUP(ROUND(K12/IF(N(F12)>0,F12,1),6),0))+N(I12)) | M12: =IF(B12="","",L12*N(G12)) | N12: =IF(B12="","",N(G12)/IF(N(F12)>0,F12,1)) | O12: =IF(OR(B12="",N(L12)=0),"",IFERROR(MATCH(D12,Settings!$B$6:$B$17,0),13)*1000+ROW())
B13: Green beans | C13: lb | D13: Fruit and vegetables | E13: 1 lb bag | F13: 1 | G13: 2.29 | J13: =IF(B13="","",ROUND(SUMIFS(Ingredients!$G$6:$G$1005,Ingredients!$C$6:$C$1005,B13),2)) | K13: =IF(B13="","",MAX(0,ROUND(J13-N(H13),2))) | L13: =IF(B13="","",IF(N(K13)=0,0,ROUNDUP(ROUND(K13/IF(N(F13)>0,F13,1),6),0))+N(I13)) | M13: =IF(B13="","",L13*N(G13)) | N13: =IF(B13="","",N(G13)/IF(N(F13)>0,F13,1)) | O13: =IF(OR(B13="",N(L13)=0),"",IFERROR(MATCH(D13,Settings!$B$6:$B$17,0),13)*1000+ROW())
B14: Lemon | C14: each | D14: Fruit and vegetables | E14: each | F14: 1 | G14: 0.69 | J14: =IF(B14="","",ROUND(SUMIFS(Ingredients!$G$6:$G$1005,Ingredients!$C$6:$C$1005,B14),2)) | K14: =IF(B14="","",MAX(0,ROUND(J14-N(H14),2))) | L14: =IF(B14="","",IF(N(K14)=0,0,ROUNDUP(ROUND(K14/IF(N(F14)>0,F14,1),6),0))+N(I14)) | M14: =IF(B14="","",L14*N(G14)) | N14: =IF(B14="","",N(G14)/IF(N(F14)>0,F14,1)) | O14: =IF(OR(B14="",N(L14)=0),"",IFERROR(MATCH(D14,Settings!$B$6:$B$17,0),13)*1000+ROW())
B15: Lime | C15: each | D15: Fruit and vegetables | E15: each | F15: 1 | G15: 0.35 | J15: =IF(B15="","",ROUND(SUMIFS(Ingredients!$G$6:$G$1005,Ingredients!$C$6:$C$1005,B15),2)) | K15: =IF(B15="","",MAX(0,ROUND(J15-N(H15),2))) | L15: =IF(B15="","",IF(N(K15)=0,0,ROUNDUP(ROUND(K15/IF(N(F15)>0,F15,1),6),0))+N(I15)) | M15: =IF(B15="","",L15*N(G15)) | N15: =IF(B15="","",N(G15)/IF(N(F15)>0,F15,1)) | O15: =IF(OR(B15="",N(L15)=0),"",IFERROR(MATCH(D15,Settings!$B$6:$B$17,0),13)*1000+ROW())
B16: Avocado | C16: each | D16: Fruit and vegetables | E16: each | F16: 1 | G16: 1.25 | J16: =IF(B16="","",ROUND(SUMIFS(Ingredients!$G$6:$G$1005,Ingredients!$C$6:$C$1005,B16),2)) | K16: =IF(B16="","",MAX(0,ROUND(J16-N(H16),2))) | L16: =IF(B16="","",IF(N(K16)=0,0,ROUNDUP(ROUND(K16/IF(N(F16)>0,F16,1),6),0))+N(I16)) | M16: =IF(B16="","",L16*N(G16)) | N16: =IF(B16="","",N(G16)/IF(N(F16)>0,F16,1)) | O16: =IF(OR(B16="",N(L16)=0),"",IFERROR(MATCH(D16,Settings!$B$6:$B$17,0),13)*1000+ROW())
B17: Tomato | C17: each | D17: Fruit and vegetables | E17: each | F17: 1 | G17: 0.6 | J17: =IF(B17="","",ROUND(SUMIFS(Ingredients!$G$6:$G$1005,Ingredients!$C$6:$C$1005,B17),2)) | K17: =IF(B17="","",MAX(0,ROUND(J17-N(H17),2))) | L17: =IF(B17="","",IF(N(K17)=0,0,ROUNDUP(ROUND(K17/IF(N(F17)>0,F17,1),6),0))+N(I17)) | M17: =IF(B17="","",L17*N(G17)) | N17: =IF(B17="","",N(G17)/IF(N(F17)>0,F17,1)) | O17: =IF(OR(B17="",N(L17)=0),"",IFERROR(MATCH(D17,Settings!$B$6:$B$17,0),13)*1000+ROW())
B18: Cherry tomatoes | C18: oz | D18: Fruit and vegetables | E18: 10 oz box | F18: 10 | G18: 2.99 | J18: =IF(B18="","",ROUND(SUMIFS(Ingredients!$G$6:$G$1005,Ingredients!$C$6:$C$1005,B18),2)) | K18: =IF(B18="","",MAX(0,ROUND(J18-N(H18),2))) | L18: =IF(B18="","",IF(N(K18)=0,0,ROUNDUP(ROUND(K18/IF(N(F18)>0,F18,1),6),0))+N(I18)) | M18: =IF(B18="","",L18*N(G18)) | N18: =IF(B18="","",N(G18)/IF(N(F18)>0,F18,1)) | O18: =IF(OR(B18="",N(L18)=0),"",IFERROR(MATCH(D18,Settings!$B$6:$B$17,0),13)*1000+ROW())
B19: Cucumber | C19: each | D19: Fruit and vegetables | E19: each | F19: 1 | G19: 0.79 | J19: =IF(B19="","",ROUND(SUMIFS(Ingredients!$G$6:$G$1005,Ingredients!$C$6:$C$1005,B19),2)) | K19: =IF(B19="","",MAX(0,ROUND(J19-N(H19),2))) | L19: =IF(B19="","",IF(N(K19)=0,0,ROUNDUP(ROUND(K19/IF(N(F19)>0,F19,1),6),0))+N(I19)) | M19: =IF(B19="","",L19*N(G19)) | N19: =IF(B19="","",N(G19)/IF(N(F19)>0,F19,1)) | O19: =IF(OR(B19="",N(L19)=0),"",IFERROR(MATCH(D19,Settings!$B$6:$B$17,0),13)*1000+ROW())
... B21: Romaine hearts | C21: each | D21: Fruit and vegetables | E21: pack of 3 | F21: 3 | G21: 3.49 | J21: =IF(B21="","",ROUND(SUMIFS(Ingredients!$G$6:$G$1005,Ingredients!$C$6:$C$1005,B21),2)) | K21: =IF(B21="","",MAX(0,ROUND(J21-N(H21),2))) | L21: =IF(B21="","",IF(N(K21)=0,0,ROUNDUP(ROUND(K21/IF(N(F21)>0,F21,1),6),0))+N(I21)) | M21: =IF(B21="","",L21*N(G21)) | N21: =IF(B21="","",N(G21)/IF(N(F21)>0,F21,1)) | O21: =IF(OR(B21="",N(L21)=0),"",IFERROR(MATCH(D21,Settings!$B$6:$B$17,0),13)*1000+ROW())
B22: Apple | C22: each | D22: Fruit and vegetables | E22: bag of 6 | F22: 6 | G22: 4.49 | H22: 2 | J22: =IF(B22="","",ROUND(SUMIFS(Ingredients!$G$6:$G$1005,Ingredients!$C$6:$C$1005,B22),2)) | K22: =IF(B22="","",MAX(0,ROUND(J22-N(H22),2))) | L22: =IF(B22="","",IF(N(K22)=0,0,ROUNDUP(ROUND(K22/IF(N(F22)>0,F22,1),6),0))+N(I22)) | M22: =IF(B22="","",L22*N(G22)) | N22: =IF(B22="","",N(G22)/IF(N(F22)>0,F22,1)) | O22: =IF(OR(B22="",N(L22)=0),"",IFERROR(MATCH(D22,Settings!$B$6:$B$17,0),13)*1000+ROW())
