Workbook

Sheet Dashboard
AK1: =MATCH(C4,{"January","February","March","April","May","June","July","August","September","October","November","December"},0)
B2: =IF(Housemates!$C$4="","House bills","House bills: "&Housemates!$C$4) | AK2: =DATE(E4,AK1,1)
B3: Pick a month: what everyone paid and shared, who owes whom, and the bills due. | AK3: =EOMONTH(AK2,0)
B4: Month | C4: September | D4: Year | E4: 2026
B6: Spent this month | C6: Still to pay | D6: Late bills | E6: Next bill
B7: =SUMIFS(Payments!$D$6:$D$605,Payments!$B$6:$B$605,">="&$AK$2,Payments!$B$6:$B$605,"<="&$AK$3,Payments!$C$6:$C$605,"<>Paying back") | C7: =SUMIFS(Bills!$D$6:$D$25,Bills!$U$6:$U$25,1,Bills!$W$6:$W$25,0) | D7: =COUNTIFS(Bills!$U$6:$U$25,1,Bills!$W$6:$W$25,0,Bills!$V$6:$V$25,"<"&TODAY()) | E7: =IFERROR(INDEX(Bills!$B$6:$B$25,MATCH(MIN(Bills!$AI$6:$AI$25),Bills!$AI$6:$AI$25,0))&", "&DAY(INT(MIN(Bills!$AI$6:$AI$25)))&" "&CHOOSE(MONTH(INT(MIN(Bills!$AI$6:$AI$25))),"Jan","Feb","Mar","Apr","May","Jun","Jul","Aug","Sep","Oct","Nov","Dec"),"None")
B9: Housemate | C9: Paid this month | D9: Share this month | E9: Balance | F9: Status | H9: Settle up | I9: Amount
B10: =IF(Housemates!B8="","",Housemates!B8) | C10: =IF(B10="","",SUMIFS(Payments!$D$6:$D$605,Payments!$E$6:$E$605,B10,Payments!$B$6:$B$605,">="&$AK$2,Payments!$B$6:$B$605,"<="&$AK$3,Payments!$C$6:$C$605,"<>Paying back")) | D10: =IF(B10="","",SUMIFS(Payments!$AB$6:$AB$605,Payments!$B$6:$B$605,">="&$AK$2,Payments!$B$6:$B$605,"<="&$AK$3,Payments!$C$6:$C$605,"<>Paying back")) | E10: =IF(B10="","",ROUND(SUMIFS(Payments!$D$6:$D$605,Payments!$E$6:$E$605,B10,Payments!$B$6:$B$605,"<="&$AK$3)-SUMIFS(Payments!$AB$6:$AB$605,Payments!$B$6:$B$605,"<="&$AK$3),2)) | F10: =IF(B10="","",IF(ABS(E10)<0.005,"Settled",IF(E10>0,"Gets back "&FIXED(E10,2),"Owes "&FIXED(-E10,2)))) | H10: =IF(N(AA71)<0.01,"Everyone is settled",INDEX($B$10:$B$17,AA73)&" pays "&INDEX($B$10:$B$17,AA72)) | I10: =IF(N(AA71)<0.01,"",AA71)
B11: =IF(Housemates!B9="","",Housemates!B9) | C11: =IF(B11="","",SUMIFS(Payments!$D$6:$D$605,Payments!$E$6:$E$605,B11,Payments!$B$6:$B$605,">="&$AK$2,Payments!$B$6:$B$605,"<="&$AK$3,Payments!$C$6:$C$605,"<>Paying back")) | D11: =IF(B11="","",SUMIFS(Payments!$AC$6:$AC$605,Payments!$B$6:$B$605,">="&$AK$2,Payments!$B$6:$B$605,"<="&$AK$3,Payments!$C$6:$C$605,"<>Paying back")) | E11: =IF(B11="","",ROUND(SUMIFS(Payments!$D$6:$D$605,Payments!$E$6:$E$605,B11,Payments!$B$6:$B$605,"<="&$AK$3)-SUMIFS(Payments!$AC$6:$AC$605,Payments!$B$6:$B$605,"<="&$AK$3),2)) | F11: =IF(B11="","",IF(ABS(E11)<0.005,"Settled",IF(E11>0,"Gets back "&FIXED(E11,2),"Owes "&FIXED(-E11,2)))) | H11: =IF(N(AB71)<0.01,"",INDEX($B$10:$B$17,AB73)&" pays "&INDEX($B$10:$B$17,AB72)) | I11: =IF(N(AB71)<0.01,"",AB71)
B12: =IF(Housemates!B10="","",Housemates!B10) | C12: =IF(B12="","",SUMIFS(Payments!$D$6:$D$605,Payments!$E$6:$E$605,B12,Payments!$B$6:$B$605,">="&$AK$2,Payments!$B$6:$B$605,"<="&$AK$3,Payments!$C$6:$C$605,"<>Paying back")) | D12: =IF(B12="","",SUMIFS(Payments!$AD$6:$AD$605,Payments!$B$6:$B$605,">="&$AK$2,Payments!$B$6:$B$605,"<="&$AK$3,Payments!$C$6:$C$605,"<>Paying back")) | E12: =IF(B12="","",ROUND(SUMIFS(Payments!$D$6:$D$605,Payments!$E$6:$E$605,B12,Payments!$B$6:$B$605,"<="&$AK$3)-SUMIFS(Payments!$AD$6:$AD$605,Payments!$B$6:$B$605,"<="&$AK$3),2)) | F12: =IF(B12="","",IF(ABS(E12)<0.005,"Settled",IF(E12>0,"Gets back "&FIXED(E12,2),"Owes "&FIXED(-E12,2)))) | H12: =IF(N(AC71)<0.01,"",INDEX($B$10:$B$17,AC73)&" pays "&INDEX($B$10:$B$17,AC72)) | I12: =IF(N(AC71)<0.01,"",AC71)
B13: =IF(Housemates!B11="","",Housemates!B11) | C13: =IF(B13="","",SUMIFS(Payments!$D$6:$D$605,Payments!$E$6:$E$605,B13,Payments!$B$6:$B$605,">="&$AK$2,Payments!$B$6:$B$605,"<="&$AK$3,Payments!$C$6:$C$605,"<>Paying back")) | D13: =IF(B13="","",SUMIFS(Payments!$AE$6:$AE$605,Payments!$B$6:$B$605,">="&$AK$2,Payments!$B$6:$B$605,"<="&$AK$3,Payments!$C$6:$C$605,"<>Paying back")) | E13: =IF(B13="","",ROUND(SUMIFS(Payments!$D$6:$D$605,Payments!$E$6:$E$605,B13,Payments!$B$6:$B$605,"<="&$AK$3)-SUMIFS(Payments!$AE$6:$AE$605,Payments!$B$6:$B$605,"<="&$AK$3),2)) | F13: =IF(B13="","",IF(ABS(E13)<0.005,"Settled",IF(E13>0,"Gets back "&FIXED(E13,2),"Owes "&FIXED(-E13,2)))) | H13: =IF(N(AD71)<0.01,"",INDEX($B$10:$B$17,AD73)&" pays "&INDEX($B$10:$B$17,AD72)) | I13: =IF(N(AD71)<0.01,"",AD71)
B14: =IF(Housemates!B12="","",Housemates!B12) | C14: =IF(B14="","",SUMIFS(Payments!$D$6:$D$605,Payments!$E$6:$E$605,B14,Payments!$B$6:$B$605,">="&$AK$2,Payments!$B$6:$B$605,"<="&$AK$3,Payments!$C$6:$C$605,"<>Paying back")) | D14: =IF(B14="","",SUMIFS(Payments!$AF$6:$AF$605,Payments!$B$6:$B$605,">="&$AK$2,Payments!$B$6:$B$605,"<="&$AK$3,Payments!$C$6:$C$605,"<>Paying back")) | E14: =IF(B14="","",ROUND(SUMIFS(Payments!$D$6:$D$605,Payments!$E$6:$E$605,B14,Payments!$B$6:$B$605,"<="&$AK$3)-SUMIFS(Payments!$AF$6:$AF$605,Payments!$B$6:$B$605,"<="&$AK$3),2)) | F14: =IF(B14="","",IF(ABS(E14)<0.005,"Settled",IF(E14>0,"Gets back "&FIXED(E14,2),"Owes "&FIXED(-E14,2)))) | H14: =IF(N(AE71)<0.01,"",INDEX($B$10:$B$17,AE73)&" pays "&INDEX($B$10:$B$17,AE72)) | I14: =IF(N(AE71)<0.01,"",AE71)
B15: =IF(Housemates!B13="","",Housemates!B13) | C15: =IF(B15="","",SUMIFS(Payments!$D$6:$D$605,Payments!$E$6:$E$605,B15,Payments!$B$6:$B$605,">="&$AK$2,Payments!$B$6:$B$605,"<="&$AK$3,Payments!$C$6:$C$605,"<>Paying back")) | D15: =IF(B15="","",SUMIFS(Payments!$AG$6:$AG$605,Payments!$B$6:$B$605,">="&$AK$2,Payments!$B$6:$B$605,"<="&$AK$3,Payments!$C$6:$C$605,"<>Paying back")) | E15: =IF(B15="","",ROUND(SUMIFS(Payments!$D$6:$D$605,Payments!$E$6:$E$605,B15,Payments!$B$6:$B$605,"<="&$AK$3)-SUMIFS(Payments!$AG$6:$AG$605,Payments!$B$6:$B$605,"<="&$AK$3),2)) | F15: =IF(B15="","",IF(ABS(E15)<0.005,"Settled",IF(E15>0,"Gets back "&FIXED(E15,2),"Owes "&FIXED(-E15,2)))) | H15: =IF(N(AF71)<0.01,"",INDEX($B$10:$B$17,AF73)&" pays "&INDEX($B$10:$B$17,AF72)) | I15: =IF(N(AF71)<0.01,"",AF71)
B16: =IF(Housemates!B14="","",Housemates!B14) | C16: =IF(B16="","",SUMIFS(Payments!$D$6:$D$605,Payments!$E$6:$E$605,B16,Payments!$B$6:$B$605,">="&$AK$2,Payments!$B$6:$B$605,"<="&$AK$3,Payments!$C$6:$C$605,"<>Paying back")) | D16: =IF(B16="","",SUMIFS(Payments!$AH$6:$AH$605,Payments!$B$6:$B$605,">="&$AK$2,Payments!$B$6:$B$605,"<="&$AK$3,Payments!$C$6:$C$605,"<>Paying back")) | E16: =IF(B16="","",ROUND(SUMIFS(Payments!$D$6:$D$605,Payments!$E$6:$E$605,B16,Payments!$B$6:$B$605,"<="&$AK$3)-SUMIFS(Payments!$AH$6:$AH$605,Payments!$B$6:$B$605,"<="&$AK$3),2)) | F16: =IF(B16="","",IF(ABS(E16)<0.005,"Settled",IF(E16>0,"Gets back "&FIXED(E16,2),"Owes "&FIXED(-E16,2)))) | H16: =IF(N(AG71)<0.01,"",INDEX($B$10:$B$17,AG73)&" pays "&INDEX($B$10:$B$17,AG72)) | I16: =IF(N(AG71)<0.01,"",AG71)
B17: =IF(Housemates!B15="","",Housemates!B15) | C17: =IF(B17="","",SUMIFS(Payments!$D$6:$D$605,Payments!$E$6:$E$605,B17,Payments!$B$6:$B$605,">="&$AK$2,Payments!$B$6:$B$605,"<="&$AK$3,Payments!$C$6:$C$605,"<>Paying back")) | D17: =IF(B17="","",SUMIFS(Payments!$AI$6:$AI$605,Payments!$B$6:$B$605,">="&$AK$2,Payments!$B$6:$B$605,"<="&$AK$3,Payments!$C$6:$C$605,"<>Paying back")) | E17: =IF(B17="","",ROUND(SUMIFS(Payments!$D$6:$D$605,Payments!$E$6:$E$605,B17,Payments!$B$6:$B$605,"<="&$AK$3)-SUMIFS(Payments!$AI$6:$AI$605,Payments!$B$6:$B$605,"<="&$AK$3),2)) | F17: =IF(B17="","",IF(ABS(E17)<0.005,"Settled",IF(E17>0,"Gets back "&FIXED(E17,2),"Owes "&FIXED(-E17,2))))
B18: Balance counts everything up to the end of the month, money paid back included. | H18: The fewest payments that bring every balance to zero.
B20: Due | C20: Bill | D20: Amount | E20: Paid by | F20: Status | H20: Category | I20: This month
B21: =IF(AL21="","",INT(AL21)) | C21: =IF(AL21="","No bills due this month",INDEX(Bills!$B$6:$B$25,MATCH(AL21,Bills!$X$6:$X$25,0))) | D21: =IF(AL21="","",IF(INDEX(Bills!$W$6:$W$25,MATCH(AL21,Bills!$X$6:$X$25,0))>0,INDEX(Bills!$W$6:$W$25,MATCH(AL21,Bills!$X$6:$X$25,0)),INDEX(Bills!$D$6:$D$25,MATCH(AL21,Bills!$X$6:$X$25,0)))) | E21: =IF(AL21="","",IF(INDEX(Bills!$W$6:$W$25,MATCH(AL21,Bills!$X$6:$X$25,0))>0,IFERROR(INDEX(Payments!$E$6:$E$605,MATCH(C21&"|"&(YEAR($AK$2)*100+MONTH($AK$2)),Payments!$AJ$6:$AJ$605,0)),""),INDEX(Bills!$G$6:$G$25,MATCH(AL21,Bills!$X$6:$X$25,0)))) | F21: =IF(AL21="","",IF(INDEX(Bills!$W$6:$W$25,MATCH(AL21,Bills!$X$6:$X$25,0))>0,"Paid",IF(B21<TODAY(),"Late",IF(B21=TODAY(),"Due today",IF(B21-TODAY()<=3,"Due in "&(B21-TODAY())&IF(B21-TODAY()=1," day"," days"),"Coming"))))) | H21: Rent | I21: =SUMIFS(Payments!$D$6:$D$605,Payments!$O$6:$O$605,H21,Payments!$B$6:$B$605,">="&$AK$2,Payments!$B$6:$B$605,"<="&$AK$3) | AL21: =IFERROR(SMALL(Bills!$X$6:$X$25,1),"")
B22: =IF(AL22="","",INT(AL22)) | C22: =IF(AL22="","",INDEX(Bills!$B$6:$B$25,MATCH(AL22,Bills!$X$6:$X$25,0))) | D22: =IF(AL22="","",IF(INDEX(Bills!$W$6:$W$25,MATCH(AL22,Bills!$X$6:$X$25,0))>0,INDEX(Bills!$W$6:$W$25,MATCH(AL22,Bills!$X$6:$X$25,0)),INDEX(Bills!$D$6:$D$25,MATCH(AL22,Bills!$X$6:$X$25,0)))) | E22: =IF(AL22="","",IF(INDEX(Bills!$W$6:$W$25,MATCH(AL22,Bills!$X$6:$X$25,0))>0,IFERROR(INDEX(Payments!$E$6:$E$605,MATCH(C22&"|"&(YEAR($AK$2)*100+MONTH($AK$2)),Payments!$AJ$6:$AJ$605,0)),""),INDEX(Bills!$G$6:$G$25,MATCH(AL22,Bills!$X$6:$X$25,0)))) | F22: =IF(AL22="","",IF(INDEX(Bills!$W$6:$W$25,MATCH(AL22,Bills!$X$6:$X$25,0))>0,"Paid",IF(B22<TODAY(),"Late",IF(B22=TODAY(),"Due today",IF(B22-TODAY()<=3,"Due in "&(B22-TODAY())&IF(B22-TODAY()=1," day"," days"),"Coming"))))) | H22: Energy | I22: =SUMIFS(Payments!$D$6:$D$605,Payments!$O$6:$O$605,H22,Payments!$B$6:$B$605,">="&$AK$2,Payments!$B$6:$B$605,"<="&$AK$3) | AL22: =IFERROR(SMALL(Bills!$X$6:$X$25,2),"")
B23: =IF(AL23="","",INT(AL23)) | C23: =IF(AL23="","",INDEX(Bills!$B$6:$B$25,MATCH(AL23,Bills!$X$6:$X$25,0))) | D23: =IF(AL23="","",IF(INDEX(Bills!$W$6:$W$25,MATCH(AL23,Bills!$X$6:$X$25,0))>0,INDEX(Bills!$W$6:$W$25,MATCH(AL23,Bills!$X$6:$X$25,0)),INDEX(Bills!$D$6:$D$25,MATCH(AL23,Bills!$X$6:$X$25,0)))) | E23: =IF(AL23="","",IF(INDEX(Bills!$W$6:$W$25,MATCH(AL23,Bills!$X$6:$X$25,0))>0,IFERROR(INDEX(Payments!$E$6:$E$605,MATCH(C23&"|"&(YEAR($AK$2)*100+MONTH($AK$2)),Payments!$AJ$6:$AJ$605,0)),""),INDEX(Bills!$G$6:$G$25,MATCH(AL23,Bills!$X$6:$X$25,0)))) | F23: =IF(AL23="","",IF(INDEX(Bills!$W$6:$W$25,MATCH(AL23,Bills!$X$6:$X$25,0))>0,"Paid",IF(B23<TODAY(),"Late",IF(B23=TODAY(),"Due today",IF(B23-TODAY()<=3,"Due in "&(B23-TODAY())&IF(B23-TODAY()=1," day"," days"),"Coming"))))) | H23: Water | I23: =SUMIFS(Payments!$D$6:$D$605,Payments!$O$6:$O$605,H23,Payments!$B$6:$B$605,">="&$AK$2,Payments!$B$6:$B$605,"<="&$AK$3) | AL23: =IFERROR(SMALL(Bills!$X$6:$X$25,3),"")
B24: =IF(AL24="","",INT(AL24)) | C24: =IF(AL24="","",INDEX(Bills!$B$6:$B$25,MATCH(AL24,Bills!$X$6:$X$25,0))) | D24: =IF(AL24="","",IF(INDEX(Bills!$W$6:$W$25,MATCH(AL24,Bills!$X$6:$X$25,0))>0,INDEX(Bills!$W$6:$W$25,MATCH(AL24,Bills!$X$6:$X$25,0)),INDEX(Bills!$D$6:$D$25,MATCH(AL24,Bills!$X$6:$X$25,0)))) | E24: =IF(AL24="","",IF(INDEX(Bills!$W$6:$W$25,MATCH(AL24,Bills!$X$6:$X$25,0))>0,IFERROR(INDEX(Payments!$E$6:$E$605,MATCH(C24&"|"&(YEAR($AK$2)*100+MONTH($AK$2)),Payments!$AJ$6:$AJ$605,0)),""),INDEX(Bills!$G$6:$G$25,MATCH(AL24,Bills!$X$6:$X$25,0)))) | F24: =IF(AL24="","",IF(INDEX(Bills!$W$6:$W$25,MATCH(AL24,Bills!$X$6:$X$25,0))>0,"Paid",IF(B24<TODAY(),"Late",IF(B24=TODAY(),"Due today",IF(B24-TODAY()<=3,"Due in "&(B24-TODAY())&IF(B24-TODAY()=1," day"," days"),"Coming"))))) | H24: Internet | I24: =SUMIFS(Payments!$D$6:$D$605,Payments!$O$6:$O$605,H24,Payments!$B$6:$B$605,">="&$AK$2,Payments!$B$6:$B$605,"<="&$AK$3) | AL24: =IFERROR(SMALL(Bills!$X$6:$X$25,4),"")
B25: =IF(AL25="","",INT(AL25)) | C25: =IF(AL25="","",INDEX(Bills!$B$6:$B$25,MATCH(AL25,Bills!$X$6:$X$25,0))) | D25: =IF(AL25="","",IF(INDEX(Bills!$W$6:$W$25,MATCH(AL25,Bills!$X$6:$X$25,0))>0,INDEX(Bills!$W$6:$W$25,MATCH(AL25,Bills!$X$6:$X$25,0)),INDEX(Bills!$D$6:$D$25,MATCH(AL25,Bills!$X$6:$X$25,0)))) | E25: =IF(AL25="","",IF(INDEX(Bills!$W$6:$W$25,MATCH(AL25,Bills!$X$6:$X$25,0))>0,IFERROR(INDEX(Payments!$E$6:$E$605,MATCH(C25&"|"&(YEAR($AK$2)*100+MONTH($AK$2)),Payments!$AJ$6:$AJ$605,0)),""),INDEX(Bills!$G$6:$G$25,MATCH(AL25,Bills!$X$6:$X$25,0)))) | F25: =IF(AL25="","",IF(INDEX(Bills!$W$6:$W$25,MATCH(AL25,Bills!$X$6:$X$25,0))>0,"Paid",IF(B25<TODAY(),"Late",IF(B25=TODAY(),"Due today",IF(B25-TODAY()<=3,"Due in "&(B25-TODAY())&IF(B25-TODAY()=1," day"," days"),"Coming"))))) | H25: Subscriptions | I25: =SUMIFS(Payments!$D$6:$D$605,Payments!$O$6:$O$605,H25,Payments!$B$6:$B$605,">="&$AK$2,Payments!$B$6:$B$605,"<="&$AK$3) | AL25: =IFERROR(SMALL(Bills!$X$6:$X$25,5),"")
B26: =IF(AL26="","",INT(AL26)) | C26: =IF(AL26="","",INDEX(Bills!$B$6:$B$25,MATCH(AL26,Bills!$X$6:$X$25,0))) | D26: =IF(AL26="","",IF(INDEX(Bills!$W$6:$W$25,MATCH(AL26,Bills!$X$6:$X$25,0))>0,INDEX(Bills!$W$6:$W$25,MATCH(AL26,Bills!$X$6:$X$25,0)),INDEX(Bills!$D$6:$D$25,MATCH(AL26,Bills!$X$6:$X$25,0)))) | E26: =IF(AL26="","",IF(INDEX(Bills!$W$6:$W$25,MATCH(AL26,Bills!$X$6:$X$25,0))>0,IFERROR(INDEX(Payments!$E$6:$E$605,MATCH(C26&"|"&(YEAR($AK$2)*100+MONTH($AK$2)),Payments!$AJ$6:$AJ$605,0)),""),INDEX(Bills!$G$6:$G$25,MATCH(AL26,Bills!$X$6:$X$25,0)))) | F26: =IF(AL26="","",IF(INDEX(Bills!$W$6:$W$25,MATCH(AL26,Bills!$X$6:$X$25,0))>0,"Paid",IF(B26<TODAY(),"Late",IF(B26=TODAY(),"Due today",IF(B26-TODAY()<=3,"Due in "&(B26-TODAY())&IF(B26-TODAY()=1," day"," days"),"Coming"))))) | H26: Insurance | I26: =SUMIFS(Payments!$D$6:$D$605,Payments!$O$6:$O$605,H26,Payments!$B$6:$B$605,">="&$AK$2,Payments!$B$6:$B$605,"<="&$AK$3) | AL26: =IFERROR(SMALL(Bills!$X$6:$X$25,6),"")
B27: =IF(AL27="","",INT(AL27)) | C27: =IF(AL27="","",INDEX(Bills!$B$6:$B$25,MATCH(AL27,Bills!$X$6:$X$25,0))) | D27: =IF(AL27="","",IF(INDEX(Bills!$W$6:$W$25,MATCH(AL27,Bills!$X$6:$X$25,0))>0,INDEX(Bills!$W$6:$W$25,MATCH(AL27,Bills!$X$6:$X$25,0)),INDEX(Bills!$D$6:$D$25,MATCH(AL27,Bills!$X$6:$X$25,0)))) | E27: =IF(AL27="","",IF(INDEX(Bills!$W$6:$W$25,MATCH(AL27,Bills!$X$6:$X$25,0))>0,IFERROR(INDEX(Payments!$E$6:$E$605,MATCH(C27&"|"&(YEAR($AK$2)*100+MONTH($AK$2)),Payments!$AJ$6:$AJ$605,0)),""),INDEX(Bills!$G$6:$G$25,MATCH(AL27,Bills!$X$6:$X$25,0)))) | F27: =IF(AL27="","",IF(INDEX(Bills!$W$6:$W$25,MATCH(AL27,Bills!$X$6:$X$25,0))>0,"Paid",IF(B27<TODAY(),"Late",IF(B27=TODAY(),"Due today",IF(B27-TODAY()<=3,"Due in "&(B27-TODAY())&IF(B27-TODAY()=1," day"," days"),"Coming"))))) | H27: Groceries | I27: =SUMIFS(Payments!$D$6:$D$605,Payments!$O$6:$O$605,H27,Payments!$B$6:$B$605,">="&$AK$2,Payments!$B$6:$B$605,"<="&$AK$3) | AL27: =IFERROR(SMALL(Bills!$X$6:$X$25,7),"")
B28: =IF(AL28="","",INT(AL28)) | C28: =IF(AL28="","",INDEX(Bills!$B$6:$B$25,MATCH(AL28,Bills!$X$6:$X$25,0))) | D28: =IF(AL28="","",IF(INDEX(Bills!$W$6:$W$25,MATCH(AL28,Bills!$X$6:$X$25,0))>0,INDEX(Bills!$W$6:$W$25,MATCH(AL28,Bills!$X$6:$X$25,0)),INDEX(Bills!$D$6:$D$25,MATCH(AL28,Bills!$X$6:$X$25,0)))) | E28: =IF(AL28="","",IF(INDEX(Bills!$W$6:$W$25,MATCH(AL28,Bills!$X$6:$X$25,0))>0,IFERROR(INDEX(Payments!$E$6:$E$605,MATCH(C28&"|"&(YEAR($AK$2)*100+MONTH($AK$2)),Payments!$AJ$6:$AJ$605,0)),""),INDEX(Bills!$G$6:$G$25,MATCH(AL28,Bills!$X$6:$X$25,0)))) | F28: =IF(AL28="","",IF(INDEX(Bills!$W$6:$W$25,MATCH(AL28,Bills!$X$6:$X$25,0))>0,"Paid",IF(B28<TODAY(),"Late",IF(B28=TODAY(),"Due today",IF(B28-TODAY()<=3,"Due in "&(B28-TODAY())&IF(B28-TODAY()=1," day"," days"),"Coming"))))) | H28: Household | I28: =SUMIFS(Payments!$D$6:$D$605,Payments!$O$6:$O$605,H28,Payments!$B$6:$B$605,">="&$AK$2,Payments!$B$6:$B$605,"<="&$AK$3) | AL28: =IFERROR(SMALL(Bills!$X$6:$X$25,8),"")
B29: =IF(AL29="","",INT(AL29)) | C29: =IF(AL29="","",INDEX(Bills!$B$6:$B$25,MATCH(AL29,Bills!$X$6:$X$25,0))) | D29: =IF(AL29="","",IF(INDEX(Bills!$W$6:$W$25,MATCH(AL29,Bills!$X$6:$X$25,0))>0,INDEX(Bills!$W$6:$W$25,MATCH(AL29,Bills!$X$6:$X$25,0)),INDEX(Bills!$D$6:$D$25,MATCH(AL29,Bills!$X$6:$X$25,0)))) | E29: =IF(AL29="","",IF(INDEX(Bills!$W$6:$W$25,MATCH(AL29,Bills!$X$6:$X$25,0))>0,IFERROR(INDEX(Payments!$E$6:$E$605,MATCH(C29&"|"&(YEAR($AK$2)*100+MONTH($AK$2)),Payments!$AJ$6:$AJ$605,0)),""),INDEX(Bills!$G$6:$G$25,MATCH(AL29,Bills!$X$6:$X$25,0)))) | F29: =IF(AL29="","",IF(INDEX(Bills!$W$6:$W$25,MATCH(AL29,Bills!$X$6:$X$25,0))>0,"Paid",IF(B29<TODAY(),"Late",IF(B29=TODAY(),"Due today",IF(B29-TODAY()<=3,"Due in "&(B29-TODAY())&IF(B29-TODAY()=1," day"," days"),"Coming"))))) | H29: Other | I29: =SUMIFS(Payments!$D$6:$D$605,Payments!$O$6:$O$605,H29,Payments!$B$6:$B$605,">="&$AK$2,Payments!$B$6:$B$605,"<="&$AK$3) | AL29: =IFERROR(SMALL(Bills!$X$6:$X$25,9),"")
B30: =IF(AL30="","",INT(AL30)) | C30: =IF(AL30="","",INDEX(Bills!$B$6:$B$25,MATCH(AL30,Bills!$X$6:$X$25,0))) | D30: =IF(AL30="","",IF(INDEX(Bills!$W$6:$W$25,MATCH(AL30,Bills!$X$6:$X$25,0))>0,INDEX(Bills!$W$6:$W$25,MATCH(AL30,Bills!$X$6:$X$25,0)),INDEX(Bills!$D$6:$D$25,MATCH(AL30,Bills!$X$6:$X$25,0)))) | E30: =IF(AL30="","",IF(INDEX(Bills!$W$6:$W$25,MATCH(AL30,Bills!$X$6:$X$25,0))>0,IFERROR(INDEX(Payments!$E$6:$E$605,MATCH(C30&"|"&(YEAR($AK$2)*100+MONTH($AK$2)),Payments!$AJ$6:$AJ$605,0)),""),INDEX(Bills!$G$6:$G$25,MATCH(AL30,Bills!$X$6:$X$25,0)))) | F30: =IF(AL30="","",IF(INDEX(Bills!$W$6:$W$25,MATCH(AL30,Bills!$X$6:$X$25,0))>0,"Paid",IF(B30<TODAY(),"Late",IF(B30=TODAY(),"Due today",IF(B30-TODAY()<=3,"Due in "&(B30-TODAY())&IF(B30-TODAY()=1," day"," days"),"Coming"))))) | AL30: =IFERROR(SMALL(Bills!$X$6:$X$25,10),"")
B31: =IF(AL31="","",INT(AL31)) | C31: =IF(AL31="","",INDEX(Bills!$B$6:$B$25,MATCH(AL31,Bills!$X$6:$X$25,0))) | D31: =IF(AL31="","",IF(INDEX(Bills!$W$6:$W$25,MATCH(AL31,Bills!$X$6:$X$25,0))>0,INDEX(Bills!$W$6:$W$25,MATCH(AL31,Bills!$X$6:$X$25,0)),INDEX(Bills!$D$6:$D$25,MATCH(AL31,Bills!$X$6:$X$25,0)))) | E31: =IF(AL31="","",IF(INDEX(Bills!$W$6:$W$25,MATCH(AL31,Bills!$X$6:$X$25,0))>0,IFERROR(INDEX(Payments!$E$6:$E$605,MATCH(C31&"|"&(YEAR($AK$2)*100+MONTH($AK$2)),Payments!$AJ$6:$AJ$605,0)),""),INDEX(Bills!$G$6:$G$25,MATCH(AL31,Bills!$X$6:$X$25,0)))) | F31: =IF(AL31="","",IF(INDEX(Bills!$W$6:$W$25,MATCH(AL31,Bills!$X$6:$X$25,0))>0,"Paid",IF(B31<TODAY(),"Late",IF(B31=TODAY(),"Due today",IF(B31-TODAY()<=3,"Due in "&(B31-TODAY())&IF(B31-TODAY()=1," day"," days"),"Coming"))))) | H31: Paid by: who paid it, or in grey who usually pays it. | AL31: =IFERROR(SMALL(Bills!$X$6:$X$25,11),"")
B32: =IF(AL32="","",INT(AL32)) | C32: =IF(AL32="","",INDEX(Bills!$B$6:$B$25,MATCH(AL32,Bills!$X$6:$X$25,0))) | D32: =IF(AL32="","",IF(INDEX(Bills!$W$6:$W$25,MATCH(AL32,Bills!$X$6:$X$25,0))>0,INDEX(Bills!$W$6:$W$25,MATCH(AL32,Bills!$X$6:$X$25,0)),INDEX(Bills!$D$6:$D$25,MATCH(AL32,Bills!$X$6:$X$25,0)))) | E32: =IF(AL32="","",IF(INDEX(Bills!$W$6:$W$25,MATCH(AL32,Bills!$X$6:$X$25,0))>0,IFERROR(INDEX(Payments!$E$6:$E$605,MATCH(C32&"|"&(YEAR($AK$2)*100+MONTH($AK$2)),Payments!$AJ$6:$AJ$605,0)),""),INDEX(Bills!$G$6:$G$25,MATCH(AL32,Bills!$X$6:$X$25,0)))) | F32: =IF(AL32="","",IF(INDEX(Bills!$W$6:$W$25,MATCH(AL32,Bills!$X$6:$X$25,0))>0,"Paid",IF(B32<TODAY(),"Late",IF(B32=TODAY(),"Due today",IF(B32-TODAY()<=3,"Due in "&(B32-TODAY())&IF(B32-TODAY()=1," day"," days"),"Coming"))))) | AL32: =IFERROR(SMALL(Bills!$X$6:$X$25,12),"")
B33: =IF(COUNT(Bills!$X$6:$X$25)>12,"And "&(COUNT(Bills!$X$6:$X$25)-12)&" more due this month, on the Bills tab.","")
AA60: =IF(B10="",0,E10) | AB60: =ROUND(AA60-IF(1=AA$72,AA$71,0)+IF(1=AA$73,AA$71,0),2) | AC60: =ROUND(AB60-IF(1=AB$72,AB$71,0)+IF(1=AB$73,AB$71,0),2) | AD60: =ROUND(AC60-IF(1=AC$72,AC$71,0)+IF(1=AC$73,AC$71,0),2) | AE60: =ROUND(AD60-IF(1=AD$72,AD$71,0)+IF(1=AD$73,AD$71,0),2) | AF60: =ROUND(AE60-IF(1=AE$72,AE$71,0)+IF(1=AE$73,AE$71,0),2) | AG60: =ROUND(AF60-IF(1=AF$72,AF$71,0)+IF(1=AF$73,AF$71,0),2) | AH60: =ROUND(AG60-IF(1=AG$72,AG$71,0)+IF(1=AG$73,AG$71,0),2)
AA61: =IF(B11="",0,E11) | AB61: =ROUND(AA61-IF(2=AA$72,AA$71,0)+IF(2=AA$73,AA$71,0),2) | AC61: =ROUND(AB61-IF(2=AB$72,AB$71,0)+IF(2=AB$73,AB$71,0),2) | AD61: =ROUND(AC61-IF(2=AC$72,AC$71,0)+IF(2=AC$73,AC$71,0),2) | AE61: =ROUND(AD61-IF(2=AD$72,AD$71,0)+IF(2=AD$73,AD$71,0),2) | AF61: =ROUND(AE61-IF(2=AE$72,AE$71,0)+IF(2=AE$73,AE$71,0),2) | AG61: =ROUND(AF61-IF(2=AF$72,AF$71,0)+IF(2=AF$73,AF$71,0),2) | AH61: =ROUND(AG61-IF(2=AG$72,AG$71,0)+IF(2=AG$73,AG$71,0),2)
AA62: =IF(B12="",0,E12) | AB62: =ROUND(AA62-IF(3=AA$72,AA$71,0)+IF(3=AA$73,AA$71,0),2) | AC62: =ROUND(AB62-IF(3=AB$72,AB$71,0)+IF(3=AB$73,AB$71,0),2) | AD62: =ROUND(AC62-IF(3=AC$72,AC$71,0)+IF(3=AC$73,AC$71,0),2) | AE62: =ROUND(AD62-IF(3=AD$72,AD$71,0)+IF(3=AD$73,AD$71,0),2) | AF62: =ROUND(AE62-IF(3=AE$72,AE$71,0)+IF(3=AE$73,AE$71,0),2) | AG62: =ROUND(AF62-IF(3=AF$72,AF$71,0)+IF(3=AF$73,AF$71,0),2) | AH62: =ROUND(AG62-IF(3=AG$72,AG$71,0)+IF(3=AG$73,AG$71,0),2)
AA63: =IF(B13="",0,E13) | AB63: =ROUND(AA63-IF(4=AA$72,AA$71,0)+IF(4=AA$73,AA$71,0),2) | AC63: =ROUND(AB63-IF(4=AB$72,AB$71,0)+IF(4=AB$73,AB$71,0),2) | AD63: =ROUND(AC63-IF(4=AC$72,AC$71,0)+IF(4=AC$73,AC$71,0),2) | AE63: =ROUND(AD63-IF(4=AD$72,AD$71,0)+IF(4=AD$73,AD$71,0),2) | AF63: =ROUND(AE63-IF(4=AE$72,AE$71,0)+IF(4=AE$73,AE$71,0),2) | AG63: =ROUND(AF63-IF(4=AF$72,AF$71,0)+IF(4=AF$73,AF$71,0),2) | AH63: =ROUND(AG63-IF(4=AG$72,AG$71,0)+IF(4=AG$73,AG$71,0),2)
AA64: =IF(B14="",0,E14) | AB64: =ROUND(AA64-IF(5=AA$72,AA$71,0)+IF(5=AA$73,AA$71,0),2) | AC64: =ROUND(AB64-IF(5=AB$72,AB$71,0)+IF(5=AB$73,AB$71,0),2) | AD64: =ROUND(AC64-IF(5=AC$72,AC$71,0)+IF(5=AC$73,AC$71,0),2) | AE64: =ROUND(AD64-IF(5=AD$72,AD$71,0)+IF(5=AD$73,AD$71,0),2) | AF64: =ROUND(AE64-IF(5=AE$72,AE$71,0)+IF(5=AE$73,AE$71,0),2) | AG64: =ROUND(AF64-IF(5=AF$72,AF$71,0)+IF(5=AF$73,AF$71,0),2) | AH64: =ROUND(AG64-IF(5=AG$72,AG$71,0)+IF(5=AG$73,AG$71,0),2)
AA65: =IF(B15="",0,E15) | AB65: =ROUND(AA65-IF(6=AA$72,AA$71,0)+IF(6=AA$73,AA$71,0),2) | AC65: =ROUND(AB65-IF(6=AB$72,AB$71,0)+IF(6=AB$73,AB$71,0),2) | AD65: =ROUND(AC65-IF(6=AC$72,AC$71,0)+IF(6=AC$73,AC$71,0),2) | AE65: =ROUND(AD65-IF(6=AD$72,AD$71,0)+IF(6=AD$73,AD$71,0),2) | AF65: =ROUND(AE65-IF(6=AE$72,AE$71,0)+IF(6=AE$73,AE$71,0),2) | AG65: =ROUND(AF65-IF(6=AF$72,AF$71,0)+IF(6=AF$73,AF$71,0),2) | AH65: =ROUND(AG65-IF(6=AG$72,AG$71,0)+IF(6=AG$73,AG$71,0),2)
AA66: =IF(B16="",0,E16) | AB66: =ROUND(AA66-IF(7=AA$72,AA$71,0)+IF(7=AA$73,AA$71,0),2) | AC66: =ROUND(AB66-IF(7=AB$72,AB$71,0)+IF(7=AB$73,AB$71,0),2) | AD66: =ROUND(AC66-IF(7=AC$72,AC$71,0)+IF(7=AC$73,AC$71,0),2) | AE66: =ROUND(AD66-IF(7=AD$72,AD$71,0)+IF(7=AD$73,AD$71,0),2) | AF66: =ROUND(AE66-IF(7=AE$72,AE$71,0)+IF(7=AE$73,AE$71,0),2) | AG66: =ROUND(AF66-IF(7=AF$72,AF$71,0)+IF(7=AF$73,AF$71,0),2) | AH66: =ROUND(AG66-IF(7=AG$72,AG$71,0)+IF(7=AG$73,AG$71,0),2)
AA67: =IF(B17="",0,E17) | AB67: =ROUND(AA67-IF(8=AA$72,AA$71,0)+IF(8=AA$73,AA$71,0),2) | AC67: =ROUND(AB67-IF(8=AB$72,AB$71,0)+IF(8=AB$73,AB$71,0),2) | AD67: =ROUND(AC67-IF(8=AC$72,AC$71,0)+IF(8=AC$73,AC$71,0),2) | AE67: =ROUND(AD67-IF(8=AD$72,AD$71,0)+IF(8=AD$73,AD$71,0),2) | AF67: =ROUND(AE67-IF(8=AE$72,AE$71,0)+IF(8=AE$73,AE$71,0),2) | AG67: =ROUND(AF67-IF(8=AF$72,AF$71,0)+IF(8=AF$73,AF$71,0),2) | AH67: =ROUND(AG67-IF(8=AG$72,AG$71,0)+IF(8=AG$73,AG$71,0),2)
AA69: =MAX(AA$60:AA$67) | AB69: =MAX(AB$60:AB$67) | AC69: =MAX(AC$60:AC$67) | AD69: =MAX(AD$60:AD$67) | AE69: =MAX(AE$60:AE$67) | AF69: =MAX(AF$60:AF$67) | AG69: =MAX(AG$60:AG$67)
AA70: =MIN(AA$60:AA$67) | AB70: =MIN(AB$60:AB$67) | AC70: =MIN(AC$60:AC$67) | AD70: =MIN(AD$60:AD$67) | AE70: =MIN(AE$60:AE$67) | AF70: =MIN(AF$60:AF$67) | AG70: =MIN(AG$60:AG$67)
...

Sheet Payments
B2: Payments
B3: One line per bill paid or shared buy. Leave the shares empty to use the bill's split. Put an x under the people who share it, or a number for more or less than one share.
B5: Date | C5: Bill or what | D5: Amount | E5: Paid by | F5: =IF(Housemates!$B$8="","",Housemates!$B$8) | G5: =IF(Housemates!$B$9="","",Housemates!$B$9) | H5: =IF(Housemates!$B$10="","",Housemates!$B$10) | I5: =IF(Housemates!$B$11="","",Housemates!$B$11) | J5: =IF(Housemates!$B$12="","",Housemates!$B$12) | K5: =IF(Housemates!$B$13="","",Housemates!$B$13) | L5: =IF(Housemates!$B$14="","",Housemates!$B$14) | M5: =IF(Housemates!$B$15="","",Housemates!$B$15) | N5: Split | O5: Category
B6: 46023 | C6: Rent | D6: 2400 | E6: Maya | N6: =IF(D6="","",IF(B6="","No date",IF(AND(C6="Paying back",R6=0),"To whom?",IF(AA6=0,"Nobody",IF(C6="Paying back","To "&INDEX(Housemates!$B$8:$B$15,MATCH(MAX(S6:Z6),S6:Z6,0)),IF(R6>0,IF(COUNTIF(S6:Z6,">0")=1,"1 person",COUNTIF(S6:Z6,">0")&" people"),IF(Q6=0,"Everyone",INDEX(Bills!$Q$6:$Q$25,Q6)))))))) | O6: =IF(D6="","",IF(C6="Paying back","Paying back",IF(Q6=0,"Other",IF(INDEX(Bills!$C$6:$C$25,Q6)="","Other",INDEX(Bills!$C$6:$C$25,Q6))))) | Q6: =IF(C6="",0,IFERROR(MATCH(C6,Bills!$B$6:$B$25,0),0)) | R6: =COUNTA(F6:M6) | S6: =IF(OR($D6="",$B6="",Housemates!$B$8=""),0,IF($R6>0,IF(F6="",0,IF(ISNUMBER(F6),F6,1)),IF($C6="Paying back",0,IF(AND(OR(Housemates!$C$8="",Housemates!$C$8<=$B6),OR(Housemates!$D$8="",Housemates!$D$8>=$B6)),IF($Q6=0,1,INDEX(Bills!$AA$6:$AA$25,$Q6)),0)))) | T6: =IF(OR($D6="",$B6="",Housemates!$B$9=""),0,IF($R6>0,IF(G6="",0,IF(ISNUMBER(G6),G6,1)),IF($C6="Paying back",0,IF(AND(OR(Housemates!$C$9="",Housemates!$C$9<=$B6),OR(Housemates!$D$9="",Housemates!$D$9>=$B6)),IF($Q6=0,1,INDEX(Bills!$AB$6:$AB$25,$Q6)),0)))) | U6: =IF(OR($D6="",$B6="",Housemates!$B$10=""),0,IF($R6>0,IF(H6="",0,IF(ISNUMBER(H6),H6,1)),IF($C6="Paying back",0,IF(AND(OR(Housemates!$C$10="",Housemates!$C$10<=$B6),OR(Housemates!$D$10="",Housemates!$D$10>=$B6)),IF($Q6=0,1,INDEX(Bills!$AC$6:$AC$25,$Q6)),0)))) | V6: =IF(OR($D6="",$B6="",Housemates!$B$11=""),0,IF($R6>0,IF(I6="",0,IF(ISNUMBER(I6),I6,1)),IF($C6="Paying back",0,IF(AND(OR(Housemates!$C$11="",Housemates!$C$11<=$B6),OR(Housemates!$D$11="",Housemates!$D$11>=$B6)),IF($Q6=0,1,INDEX(Bills!$AD$6:$AD$25,$Q6)),0)))) | W6: =IF(OR($D6="",$B6="",Housemates!$B$12=""),0,IF($R6>0,IF(J6="",0,IF(ISNUMBER(J6),J6,1)),IF($C6="Paying back",0,IF(AND(OR(Housemates!$C$12="",Housemates!$C$12<=$B6),OR(Housemates!$D$12="",Housemates!$D$12>=$B6)),IF($Q6=0,1,INDEX(Bills!$AE$6:$AE$25,$Q6)),0)))) | X6: =IF(OR($D6="",$B6="",Housemates!$B$13=""),0,IF($R6>0,IF(K6="",0,IF(ISNUMBER(K6),K6,1)),IF($C6="Paying back",0,IF(AND(OR(Housemates!$C$13="",Housemates!$C$13<=$B6),OR(Housemates!$D$13="",Housemates!$D$13>=$B6)),IF($Q6=0,1,INDEX(Bills!$AF$6:$AF$25,$Q6)),0)))) | Y6: =IF(OR($D6="",$B6="",Housemates!$B$14=""),0,IF($R6>0,IF(L6="",0,IF(ISNUMBER(L6),L6,1)),IF($C6="Paying back",0,IF(AND(OR(Housemates!$C$14="",Housemates!$C$14<=$B6),OR(Housemates!$D$14="",Housemates!$D$14>=$B6)),IF($Q6=0,1,INDEX(Bills!$AG$6:$AG$25,$Q6)),0)))) | Z6: =IF(OR($D6="",$B6="",Housemates!$B$15=""),0,IF($R6>0,IF(M6="",0,IF(ISNUMBER(M6),M6,1)),IF($C6="Paying back",0,IF(AND(OR(Housemates!$C$15="",Housemates!$C$15<=$B6),OR(Housemates!$D$15="",Housemates!$D$15>=$B6)),IF($Q6=0,1,INDEX(Bills!$AH$6:$AH$25,$Q6)),0)))) | AA6: =SUM(S6:Z6) | AB6: =IF(AA6=0,0,D6*S6/AA6) | AC6: =IF(AA6=0,0,D6*T6/AA6) | AD6: =IF(AA6=0,0,D6*U6/AA6) | AE6: =IF(AA6=0,0,D6*V6/AA6) | AF6: =IF(AA6=0,0,D6*W6/AA6) | AG6: =IF(AA6=0,0,D6*X6/AA6) | AH6: =IF(AA6=0,0,D6*Y6/AA6) | AI6: =IF(AA6=0,0,D6*Z6/AA6) | AJ6: =IF(OR(C6="",B6=""),"",C6&"|"&(YEAR(B6)*100+MONTH(B6)))
B7: 46023 | C7: Groceries | D7: 50.88 | E7: Tom | N7: =IF(D7="","",IF(B7="","No date",IF(AND(C7="Paying back",R7=0),"To whom?",IF(AA7=0,"Nobody",IF(C7="Paying back","To "&INDEX(Housemates!$B$8:$B$15,MATCH(MAX(S7:Z7),S7:Z7,0)),IF(R7>0,IF(COUNTIF(S7:Z7,">0")=1,"1 person",COUNTIF(S7:Z7,">0")&" people"),IF(Q7=0,"Everyone",INDEX(Bills!$Q$6:$Q$25,Q7)))))))) | O7: =IF(D7="","",IF(C7="Paying back","Paying back",IF(Q7=0,"Other",IF(INDEX(Bills!$C$6:$C$25,Q7)="","Other",INDEX(Bills!$C$6:$C$25,Q7))))) | Q7: =IF(C7="",0,IFERROR(MATCH(C7,Bills!$B$6:$B$25,0),0)) | R7: =COUNTA(F7:M7) | S7: =IF(OR($D7="",$B7="",Housemates!$B$8=""),0,IF($R7>0,IF(F7="",0,IF(ISNUMBER(F7),F7,1)),IF($C7="Paying back",0,IF(AND(OR(Housemates!$C$8="",Housemates!$C$8<=$B7),OR(Housemates!$D$8="",Housemates!$D$8>=$B7)),IF($Q7=0,1,INDEX(Bills!$AA$6:$AA$25,$Q7)),0)))) | T7: =IF(OR($D7="",$B7="",Housemates!$B$9=""),0,IF($R7>0,IF(G7="",0,IF(ISNUMBER(G7),G7,1)),IF($C7="Paying back",0,IF(AND(OR(Housemates!$C$9="",Housemates!$C$9<=$B7),OR(Housemates!$D$9="",Housemates!$D$9>=$B7)),IF($Q7=0,1,INDEX(Bills!$AB$6:$AB$25,$Q7)),0)))) | U7: =IF(OR($D7="",$B7="",Housemates!$B$10=""),0,IF($R7>0,IF(H7="",0,IF(ISNUMBER(H7),H7,1)),IF($C7="Paying back",0,IF(AND(OR(Housemates!$C$10="",Housemates!$C$10<=$B7),OR(Housemates!$D$10="",Housemates!$D$10>=$B7)),IF($Q7=0,1,INDEX(Bills!$AC$6:$AC$25,$Q7)),0)))) | V7: =IF(OR($D7="",$B7="",Housemates!$B$11=""),0,IF($R7>0,IF(I7="",0,IF(ISNUMBER(I7),I7,1)),IF($C7="Paying back",0,IF(AND(OR(Housemates!$C$11="",Housemates!$C$11<=$B7),OR(Housemates!$D$11="",Housemates!$D$11>=$B7)),IF($Q7=0,1,INDEX(Bills!$AD$6:$AD$25,$Q7)),0)))) | W7: =IF(OR($D7="",$B7="",Housemates!$B$12=""),0,IF($R7>0,IF(J7="",0,IF(ISNUMBER(J7),J7,1)),IF($C7="Paying back",0,IF(AND(OR(Housemates!$C$12="",Housemates!$C$12<=$B7),OR(Housemates!$D$12="",Housemates!$D$12>=$B7)),IF($Q7=0,1,INDEX(Bills!$AE$6:$AE$25,$Q7)),0)))) | X7: =IF(OR($D7="",$B7="",Housemates!$B$13=""),0,IF($R7>0,IF(K7="",0,IF(ISNUMBER(K7),K7,1)),IF($C7="Paying back",0,IF(AND(OR(Housemates!$C$13="",Housemates!$C$13<=$B7),OR(Housemates!$D$13="",Housemates!$D$13>=$B7)),IF($Q7=0,1,INDEX(Bills!$AF$6:$AF$25,$Q7)),0)))) | Y7: =IF(OR($D7="",$B7="",Housemates!$B$14=""),0,IF($R7>0,IF(L7="",0,IF(ISNUMBER(L7),L7,1)),IF($C7="Paying back",0,IF(AND(OR(Housemates!$C$14="",Housemates!$C$14<=$B7),OR(Housemates!$D$14="",Housemates!$D$14>=$B7)),IF($Q7=0,1,INDEX(Bills!$AG$6:$AG$25,$Q7)),0)))) | Z7: =IF(OR($D7="",$B7="",Housemates!$B$15=""),0,IF($R7>0,IF(M7="",0,IF(ISNUMBER(M7),M7,1)),IF($C7="Paying back",0,IF(AND(OR(Housemates!$C$15="",Housemates!$C$15<=$B7),OR(Housemates!$D$15="",Housemates!$D$15>=$B7)),IF($Q7=0,1,INDEX(Bills!$AH$6:$AH$25,$Q7)),0)))) | AA7: =SUM(S7:Z7) | AB7: =IF(AA7=0,0,D7*S7/AA7) | AC7: =IF(AA7=0,0,D7*T7/AA7) | AD7: =IF(AA7=0,0,D7*U7/AA7) | AE7: =IF(AA7=0,0,D7*V7/AA7) | AF7: =IF(AA7=0,0,D7*W7/AA7) | AG7: =IF(AA7=0,0,D7*X7/AA7) | AH7: =IF(AA7=0,0,D7*Y7/AA7) | AI7: =IF(AA7=0,0,D7*Z7/AA7) | AJ7: =IF(OR(C7="",B7=""),"",C7&"|"&(YEAR(B7)*100+MONTH(B7)))
B8: 46025 | C8: Internet | D8: 45 | E8: Leo | N8: =IF(D8="","",IF(B8="","No date",IF(AND(C8="Paying back",R8=0),"To whom?",IF(AA8=0,"Nobody",IF(C8="Paying back","To "&INDEX(Housemates!$B$8:$B$15,MATCH(MAX(S8:Z8),S8:Z8,0)),IF(R8>0,IF(COUNTIF(S8:Z8,">0")=1,"1 person",COUNTIF(S8:Z8,">0")&" people"),IF(Q8=0,"Everyone",INDEX(Bills!$Q$6:$Q$25,Q8)))))))) | O8: =IF(D8="","",IF(C8="Paying back","Paying back",IF(Q8=0,"Other",IF(INDEX(Bills!$C$6:$C$25,Q8)="","Other",INDEX(Bills!$C$6:$C$25,Q8))))) | Q8: =IF(C8="",0,IFERROR(MATCH(C8,Bills!$B$6:$B$25,0),0)) | R8: =COUNTA(F8:M8) | S8: =IF(OR($D8="",$B8="",Housemates!$B$8=""),0,IF($R8>0,IF(F8="",0,IF(ISNUMBER(F8),F8,1)),IF($C8="Paying back",0,IF(AND(OR(Housemates!$C$8="",Housemates!$C$8<=$B8),OR(Housemates!$D$8="",Housemates!$D$8>=$B8)),IF($Q8=0,1,INDEX(Bills!$AA$6:$AA$25,$Q8)),0)))) | T8: =IF(OR($D8="",$B8="",Housemates!$B$9=""),0,IF($R8>0,IF(G8="",0,IF(ISNUMBER(G8),G8,1)),IF($C8="Paying back",0,IF(AND(OR(Housemates!$C$9="",Housemates!$C$9<=$B8),OR(Housemates!$D$9="",Housemates!$D$9>=$B8)),IF($Q8=0,1,INDEX(Bills!$AB$6:$AB$25,$Q8)),0)))) | U8: =IF(OR($D8="",$B8="",Housemates!$B$10=""),0,IF($R8>0,IF(H8="",0,IF(ISNUMBER(H8),H8,1)),IF($C8="Paying back",0,IF(AND(OR(Housemates!$C$10="",Housemates!$C$10<=$B8),OR(Housemates!$D$10="",Housemates!$D$10>=$B8)),IF($Q8=0,1,INDEX(Bills!$AC$6:$AC$25,$Q8)),0)))) | V8: =IF(OR($D8="",$B8="",Housemates!$B$11=""),0,IF($R8>0,IF(I8="",0,IF(ISNUMBER(I8),I8,1)),IF($C8="Paying back",0,IF(AND(OR(Housemates!$C$11="",Housemates!$C$11<=$B8),OR(Housemates!$D$11="",Housemates!$D$11>=$B8)),IF($Q8=0,1,INDEX(Bills!$AD$6:$AD$25,$Q8)),0)))) | W8: =IF(OR($D8="",$B8="",Housemates!$B$12=""),0,IF($R8>0,IF(J8="",0,IF(ISNUMBER(J8),J8,1)),IF($C8="Paying back",0,IF(AND(OR(Housemates!$C$12="",Housemates!$C$12<=$B8),OR(Housemates!$D$12="",Housemates!$D$12>=$B8)),IF($Q8=0,1,INDEX(Bills!$AE$6:$AE$25,$Q8)),0)))) | X8: =IF(OR($D8="",$B8="",Housemates!$B$13=""),0,IF($R8>0,IF(K8="",0,IF(ISNUMBER(K8),K8,1)),IF($C8="Paying back",0,IF(AND(OR(Housemates!$C$13="",Housemates!$C$13<=$B8),OR(Housemates!$D$13="",Housemates!$D$13>=$B8)),IF($Q8=0,1,INDEX(Bills!$AF$6:$AF$25,$Q8)),0)))) | Y8: =IF(OR($D8="",$B8="",Housemates!$B$14=""),0,IF($R8>0,IF(L8="",0,IF(ISNUMBER(L8),L8,1)),IF($C8="Paying back",0,IF(AND(OR(Housemates!$C$14="",Housemates!$C$14<=$B8),OR(Housemates!$D$14="",Housemates!$D$14>=$B8)),IF($Q8=0,1,INDEX(Bills!$AG$6:$AG$25,$Q8)),0)))) | Z8: =IF(OR($D8="",$B8="",Housemates!$B$15=""),0,IF($R8>0,IF(M8="",0,IF(ISNUMBER(M8),M8,1)),IF($C8="Paying back",0,IF(AND(OR(Housemates!$C$15="",Housemates!$C$15<=$B8),OR(Housemates!$D$15="",Housemates!$D$15>=$B8)),IF($Q8=0,1,INDEX(Bills!$AH$6:$AH$25,$Q8)),0)))) | AA8: =SUM(S8:Z8) | AB8: =IF(AA8=0,0,D8*S8/AA8) | AC8: =IF(AA8=0,0,D8*T8/AA8) | AD8: =IF(AA8=0,0,D8*U8/AA8) | AE8: =IF(AA8=0,0,D8*V8/AA8) | AF8: =IF(AA8=0,0,D8*W8/AA8) | AG8: =IF(AA8=0,0,D8*X8/AA8) | AH8: =IF(AA8=0,0,D8*Y8/AA8) | AI8: =IF(AA8=0,0,D8*Z8/AA8) | AJ8: =IF(OR(C8="",B8=""),"",C8&"|"&(YEAR(B8)*100+MONTH(B8)))
B9: 46030 | C9: Water | D9: 74.52 | E9: Maya | N9: =IF(D9="","",IF(B9="","No date",IF(AND(C9="Paying back",R9=0),"To whom?",IF(AA9=0,"Nobody",IF(C9="Paying back","To "&INDEX(Housemates!$B$8:$B$15,MATCH(MAX(S9:Z9),S9:Z9,0)),IF(R9>0,IF(COUNTIF(S9:Z9,">0")=1,"1 person",COUNTIF(S9:Z9,">0")&" people"),IF(Q9=0,"Everyone",INDEX(Bills!$Q$6:$Q$25,Q9)))))))) | O9: =IF(D9="","",IF(C9="Paying back","Paying back",IF(Q9=0,"Other",IF(INDEX(Bills!$C$6:$C$25,Q9)="","Other",INDEX(Bills!$C$6:$C$25,Q9))))) | Q9: =IF(C9="",0,IFERROR(MATCH(C9,Bills!$B$6:$B$25,0),0)) | R9: =COUNTA(F9:M9) | S9: =IF(OR($D9="",$B9="",Housemates!$B$8=""),0,IF($R9>0,IF(F9="",0,IF(ISNUMBER(F9),F9,1)),IF($C9="Paying back",0,IF(AND(OR(Housemates!$C$8="",Housemates!$C$8<=$B9),OR(Housemates!$D$8="",Housemates!$D$8>=$B9)),IF($Q9=0,1,INDEX(Bills!$AA$6:$AA$25,$Q9)),0)))) | T9: =IF(OR($D9="",$B9="",Housemates!$B$9=""),0,IF($R9>0,IF(G9="",0,IF(ISNUMBER(G9),G9,1)),IF($C9="Paying back",0,IF(AND(OR(Housemates!$C$9="",Housemates!$C$9<=$B9),OR(Housemates!$D$9="",Housemates!$D$9>=$B9)),IF($Q9=0,1,INDEX(Bills!$AB$6:$AB$25,$Q9)),0)))) | U9: =IF(OR($D9="",$B9="",Housemates!$B$10=""),0,IF($R9>0,IF(H9="",0,IF(ISNUMBER(H9),H9,1)),IF($C9="Paying back",0,IF(AND(OR(Housemates!$C$10="",Housemates!$C$10<=$B9),OR(Housemates!$D$10="",Housemates!$D$10>=$B9)),IF($Q9=0,1,INDEX(Bills!$AC$6:$AC$25,$Q9)),0)))) | V9: =IF(OR($D9="",$B9="",Housemates!$B$11=""),0,IF($R9>0,IF(I9="",0,IF(ISNUMBER(I9),I9,1)),IF($C9="Paying back",0,IF(AND(OR(Housemates!$C$11="",Housemates!$C$11<=$B9),OR(Housemates!$D$11="",Housemates!$D$11>=$B9)),IF($Q9=0,1,INDEX(Bills!$AD$6:$AD$25,$Q9)),0)))) | W9: =IF(OR($D9="",$B9="",Housemates!$B$12=""),0,IF($R9>0,IF(J9="",0,IF(ISNUMBER(J9),J9,1)),IF($C9="Paying back",0,IF(AND(OR(Housemates!$C$12="",Housemates!$C$12<=$B9),OR(Housemates!$D$12="",Housemates!$D$12>=$B9)),IF($Q9=0,1,INDEX(Bills!$AE$6:$AE$25,$Q9)),0)))) | X9: =IF(OR($D9="",$B9="",Housemates!$B$13=""),0,IF($R9>0,IF(K9="",0,IF(ISNUMBER(K9),K9,1)),IF($C9="Paying back",0,IF(AND(OR(Housemates!$C$13="",Housemates!$C$13<=$B9),OR(Housemates!$D$13="",Housemates!$D$13>=$B9)),IF($Q9=0,1,INDEX(Bills!$AF$6:$AF$25,$Q9)),0)))) | Y9: =IF(OR($D9="",$B9="",Housemates!$B$14=""),0,IF($R9>0,IF(L9="",0,IF(ISNUMBER(L9),L9,1)),IF($C9="Paying back",0,IF(AND(OR(Housemates!$C$14="",Housemates!$C$14<=$B9),OR(Housemates!$D$14="",Housemates!$D$14>=$B9)),IF($Q9=0,1,INDEX(Bills!$AG$6:$AG$25,$Q9)),0)))) | Z9: =IF(OR($D9="",$B9="",Housemates!$B$15=""),0,IF($R9>0,IF(M9="",0,IF(ISNUMBER(M9),M9,1)),IF($C9="Paying back",0,IF(AND(OR(Housemates!$C$15="",Housemates!$C$15<=$B9),OR(Housemates!$D$15="",Housemates!$D$15>=$B9)),IF($Q9=0,1,INDEX(Bills!$AH$6:$AH$25,$Q9)),0)))) | AA9: =SUM(S9:Z9) | AB9: =IF(AA9=0,0,D9*S9/AA9) | AC9: =IF(AA9=0,0,D9*T9/AA9) | AD9: =IF(AA9=0,0,D9*U9/AA9) | AE9: =IF(AA9=0,0,D9*V9/AA9) | AF9: =IF(AA9=0,0,D9*W9/AA9) | AG9: =IF(AA9=0,0,D9*X9/AA9) | AH9: =IF(AA9=0,0,D9*Y9/AA9) | AI9: =IF(AA9=0,0,D9*Z9/AA9) | AJ9: =IF(OR(C9="",B9=""),"",C9&"|"&(YEAR(B9)*100+MONTH(B9)))
B10: 46037 | C10: Electricity | D10: 137.04 | E10: Leo | N10: =IF(D10="","",IF(B10="","No date",IF(AND(C10="Paying back",R10=0),"To whom?",IF(AA10=0,"Nobody",IF(C10="Paying back","To "&INDEX(Housemates!$B$8:$B$15,MATCH(MAX(S10:Z10),S10:Z10,0)),IF(R10>0,IF(COUNTIF(S10:Z10,">0")=1,"1 person",COUNTIF(S10:Z10,">0")&" people"),IF(Q10=0,"Everyone",INDEX(Bills!$Q$6:$Q$25,Q10)))))))) | O10: =IF(D10="","",IF(C10="Paying back","Paying back",IF(Q10=0,"Other",IF(INDEX(Bills!$C$6:$C$25,Q10)="","Other",INDEX(Bills!$C$6:$C$25,Q10))))) | Q10: =IF(C10="",0,IFERROR(MATCH(C10,Bills!$B$6:$B$25,0),0)) | R10: =COUNTA(F10:M10) | S10: =IF(OR($D10="",$B10="",Housemates!$B$8=""),0,IF($R10>0,IF(F10="",0,IF(ISNUMBER(F10),F10,1)),IF($C10="Paying back",0,IF(AND(OR(Housemates!$C$8="",Housemates!$C$8<=$B10),OR(Housemates!$D$8="",Housemates!$D$8>=$B10)),IF($Q10=0,1,INDEX(Bills!$AA$6:$AA$25,$Q10)),0)))) | T10: =IF(OR($D10="",$B10="",Housemates!$B$9=""),0,IF($R10>0,IF(G10="",0,IF(ISNUMBER(G10),G10,1)),IF($C10="Paying back",0,IF(AND(OR(Housemates!$C$9="",Housemates!$C$9<=$B10),OR(Housemates!$D$9="",Housemates!$D$9>=$B10)),IF($Q10=0,1,INDEX(Bills!$AB$6:$AB$25,$Q10)),0)))) | U10: =IF(OR($D10="",$B10="",Housemates!$B$10=""),0,IF($R10>0,IF(H10="",0,IF(ISNUMBER(H10),H10,1)),IF($C10="Paying back",0,IF(AND(OR(Housemates!$C$10="",Housemates!$C$10<=$B10),OR(Housemates!$D$10="",Housemates!$D$10>=$B10)),IF($Q10=0,1,INDEX(Bills!$AC$6:$AC$25,$Q10)),0)))) | V10: =IF(OR($D10="",$B10="",Housemates!$B$11=""),0,IF($R10>0,IF(I10="",0,IF(ISNUMBER(I10),I10,1)),IF($C10="Paying back",0,IF(AND(OR(Housemates!$C$11="",Housemates!$C$11<=$B10),OR(Housemates!$D$11="",Housemates!$D$11>=$B10)),IF($Q10=0,1,INDEX(Bills!$AD$6:$AD$25,$Q10)),0)))) | W10: =IF(OR($D10="",$B10="",Housemates!$B$12=""),0,IF($R10>0,IF(J10="",0,IF(ISNUMBER(J10),J10,1)),IF($C10="Paying back",0,IF(AND(OR(Housemates!$C$12="",Housemates!$C$12<=$B10),OR(Housemates!$D$12="",Housemates!$D$12>=$B10)),IF($Q10=0,1,INDEX(Bills!$AE$6:$AE$25,$Q10)),0)))) | X10: =IF(OR($D10="",$B10="",Housemates!$B$13=""),0,IF($R10>0,IF(K10="",0,IF(ISNUMBER(K10),K10,1)),IF($C10="Paying back",0,IF(AND(OR(Housemates!$C$13="",Housemates!$C$13<=$B10),OR(Housemates!$D$13="",Housemates!$D$13>=$B10)),IF($Q10=0,1,INDEX(Bills!$AF$6:$AF$25,$Q10)),0)))) | Y10: =IF(OR($D10="",$B10="",Housemates!$B$14=""),0,IF($R10>0,IF(L10="",0,IF(ISNUMBER(L10),L10,1)),IF($C10="Paying back",0,IF(AND(OR(Housemates!$C$14="",Housemates!$C$14<=$B10),OR(Housemates!$D$14="",Housemates!$D$14>=$B10)),IF($Q10=0,1,INDEX(Bills!$AG$6:$AG$25,$Q10)),0)))) | Z10: =IF(OR($D10="",$B10="",Housemates!$B$15=""),0,IF($R10>0,IF(M10="",0,IF(ISNUMBER(M10),M10,1)),IF($C10="Paying back",0,IF(AND(OR(Housemates!$C$15="",Housemates!$C$15<=$B10),OR(Housemates!$D$15="",Housemates!$D$15>=$B10)),IF($Q10=0,1,INDEX(Bills!$AH$6:$AH$25,$Q10)),0)))) | AA10: =SUM(S10:Z10) | AB10: =IF(AA10=0,0,D10*S10/AA10) | AC10: =IF(AA10=0,0,D10*T10/AA10) | AD10: =IF(AA10=0,0,D10*U10/AA10) | AE10: =IF(AA10=0,0,D10*V10/AA10) | AF10: =IF(AA10=0,0,D10*W10/AA10) | AG10: =IF(AA10=0,0,D10*X10/AA10) | AH10: =IF(AA10=0,0,D10*Y10/AA10) | AI10: =IF(AA10=0,0,D10*Z10/AA10) | AJ10: =IF(OR(C10="",B10=""),"",C10&"|"&(YEAR(B10)*100+MONTH(B10)))
B11: 46043 | C11: Streaming | D11: 15.96 | E11: Priya | N11: =IF(D11="","",IF(B11="","No date",IF(AND(C11="Paying back",R11=0),"To whom?",IF(AA11=0,"Nobody",IF(C11="Paying back","To "&INDEX(Housemates!$B$8:$B$15,MATCH(MAX(S11:Z11),S11:Z11,0)),IF(R11>0,IF(COUNTIF(S11:Z11,">0")=1,"1 person",COUNTIF(S11:Z11,">0")&" people"),IF(Q11=0,"Everyone",INDEX(Bills!$Q$6:$Q$25,Q11)))))))) | O11: =IF(D11="","",IF(C11="Paying back","Paying back",IF(Q11=0,"Other",IF(INDEX(Bills!$C$6:$C$25,Q11)="","Other",INDEX(Bills!$C$6:$C$25,Q11))))) | Q11: =IF(C11="",0,IFERROR(MATCH(C11,Bills!$B$6:$B$25,0),0)) | R11: =COUNTA(F11:M11) | S11: =IF(OR($D11="",$B11="",Housemates!$B$8=""),0,IF($R11>0,IF(F11="",0,IF(ISNUMBER(F11),F11,1)),IF($C11="Paying back",0,IF(AND(OR(Housemates!$C$8="",Housemates!$C$8<=$B11),OR(Housemates!$D$8="",Housemates!$D$8>=$B11)),IF($Q11=0,1,INDEX(Bills!$AA$6:$AA$25,$Q11)),0)))) | T11: =IF(OR($D11="",$B11="",Housemates!$B$9=""),0,IF($R11>0,IF(G11="",0,IF(ISNUMBER(G11),G11,1)),IF($C11="Paying back",0,IF(AND(OR(Housemates!$C$9="",Housemates!$C$9<=$B11),OR(Housemates!$D$9="",Housemates!$D$9>=$B11)),IF($Q11=0,1,INDEX(Bills!$AB$6:$AB$25,$Q11)),0)))) | U11: =IF(OR($D11="",$B11="",Housemates!$B$10=""),0,IF($R11>0,IF(H11="",0,IF(ISNUMBER(H11),H11,1)),IF($C11="Paying back",0,IF(AND(OR(Housemates!$C$10="",Housemates!$C$10<=$B11),OR(Housemates!$D$10="",Housemates!$D$10>=$B11)),IF($Q11=0,1,INDEX(Bills!$AC$6:$AC$25,$Q11)),0)))) | V11: =IF(OR($D11="",$B11="",Housemates!$B$11=""),0,IF($R11>0,IF(I11="",0,IF(ISNUMBER(I11),I11,1)),IF($C11="Paying back",0,IF(AND(OR(Housemates!$C$11="",Housemates!$C$11<=$B11),OR(Housemates!$D$11="",Housemates!$D$11>=$B11)),IF($Q11=0,1,INDEX(Bills!$AD$6:$AD$25,$Q11)),0)))) | W11: =IF(OR($D11="",$B11="",Housemates!$B$12=""),0,IF($R11>0,IF(J11="",0,IF(ISNUMBER(J11),J11,1)),IF($C11="Paying back",0,IF(AND(OR(Housemates!$C$12="",Housemates!$C$12<=$B11),OR(Housemates!$D$12="",Housemates!$D$12>=$B11)),IF($Q11=0,1,INDEX(Bills!$AE$6:$AE$25,$Q11)),0)))) | X11: =IF(OR($D11="",$B11="",Housemates!$B$13=""),0,IF($R11>0,IF(K11="",0,IF(ISNUMBER(K11),K11,1)),IF($C11="Paying back",0,IF(AND(OR(Housemates!$C$13="",Housemates!$C$13<=$B11),OR(Housemates!$D$13="",Housemates!$D$13>=$B11)),IF($Q11=0,1,INDEX(Bills!$AF$6:$AF$25,$Q11)),0)))) | Y11: =IF(OR($D11="",$B11="",Housemates!$B$14=""),0,IF($R11>0,IF(L11="",0,IF(ISNUMBER(L11),L11,1)),IF($C11="Paying back",0,IF(AND(OR(Housemates!$C$14="",Housemates!$C$14<=$B11),OR(Housemates!$D$14="",Housemates!$D$14>=$B11)),IF($Q11=0,1,INDEX(Bills!$AG$6:$AG$25,$Q11)),0)))) | Z11: =IF(OR($D11="",$B11="",Housemates!$B$15=""),0,IF($R11>0,IF(M11="",0,IF(ISNUMBER(M11),M11,1)),IF($C11="Paying back",0,IF(AND(OR(Housemates!$C$15="",Housemates!$C$15<=$B11),OR(Housemates!$D$15="",Housemates!$D$15>=$B11)),IF($Q11=0,1,INDEX(Bills!$AH$6:$AH$25,$Q11)),0)))) | AA11: =SUM(S11:Z11) | AB11: =IF(AA11=0,0,D11*S11/AA11) | AC11: =IF(AA11=0,0,D11*T11/AA11) | AD11: =IF(AA11=0,0,D11*U11/AA11) | AE11: =IF(AA11=0,0,D11*V11/AA11) | AF11: =IF(AA11=0,0,D11*W11/AA11) | AG11: =IF(AA11=0,0,D11*X11/AA11) | AH11: =IF(AA11=0,0,D11*Y11/AA11) | AI11: =IF(AA11=0,0,D11*Z11/AA11) | AJ11: =IF(OR(C11="",B11=""),"",C11&"|"&(YEAR(B11)*100+MONTH(B11)))
B12: 46045 | C12: Cleaning and household | D12: 23.4 | E12: Maya | N12: =IF(D12="","",IF(B12="","No date",IF(AND(C12="Paying back",R12=0),"To whom?",IF(AA12=0,"Nobody",IF(C12="Paying back","To "&INDEX(Housemates!$B$8:$B$15,MATCH(MAX(S12:Z12),S12:Z12,0)),IF(R12>0,IF(COUNTIF(S12:Z12,">0")=1,"1 person",COUNTIF(S12:Z12,">0")&" people"),IF(Q12=0,"Everyone",INDEX(Bills!$Q$6:$Q$25,Q12)))))))) | O12: =IF(D12="","",IF(C12="Paying back","Paying back",IF(Q12=0,"Other",IF(INDEX(Bills!$C$6:$C$25,Q12)="","Other",INDEX(Bills!$C$6:$C$25,Q12))))) | Q12: =IF(C12="",0,IFERROR(MATCH(C12,Bills!$B$6:$B$25,0),0)) | R12: =COUNTA(F12:M12) | S12: =IF(OR($D12="",$B12="",Housemates!$B$8=""),0,IF($R12>0,IF(F12="",0,IF(ISNUMBER(F12),F12,1)),IF($C12="Paying back",0,IF(AND(OR(Housemates!$C$8="",Housemates!$C$8<=$B12),OR(Housemates!$D$8="",Housemates!$D$8>=$B12)),IF($Q12=0,1,INDEX(Bills!$AA$6:$AA$25,$Q12)),0)))) | T12: =IF(OR($D12="",$B12="",Housemates!$B$9=""),0,IF($R12>0,IF(G12="",0,IF(ISNUMBER(G12),G12,1)),IF($C12="Paying back",0,IF(AND(OR(Housemates!$C$9="",Housemates!$C$9<=$B12),OR(Housemates!$D$9="",Housemates!$D$9>=$B12)),IF($Q12=0,1,INDEX(Bills!$AB$6:$AB$25,$Q12)),0)))) | U12: =IF(OR($D12="",$B12="",Housemates!$B$10=""),0,IF($R12>0,IF(H12="",0,IF(ISNUMBER(H12),H12,1)),IF($C12="Paying back",0,IF(AND(OR(Housemates!$C$10="",Housemates!$C$10<=$B12),OR(Housemates!$D$10="",Housemates!$D$10>=$B12)),IF($Q12=0,1,INDEX(Bills!$AC$6:$AC$25,$Q12)),0)))) | V12: =IF(OR($D12="",$B12="",Housemates!$B$11=""),0,IF($R12>0,IF(I12="",0,IF(ISNUMBER(I12),I12,1)),IF($C12="Paying back",0,IF(AND(OR(Housemates!$C$11="",Housemates!$C$11<=$B12),OR(Housemates!$D$11="",Housemates!$D$11>=$B12)),IF($Q12=0,1,INDEX(Bills!$AD$6:$AD$25,$Q12)),0)))) | W12: =IF(OR($D12="",$B12="",Housemates!$B$12=""),0,IF($R12>0,IF(J12="",0,IF(ISNUMBER(J12),J12,1)),IF($C12="Paying back",0,IF(AND(OR(Housemates!$C$12="",Housemates!$C$12<=$B12),OR(Housemates!$D$12="",Housemates!$D$12>=$B12)),IF($Q12=0,1,INDEX(Bills!$AE$6:$AE$25,$Q12)),0)))) | X12: =IF(OR($D12="",$B12="",Housemates!$B$13=""),0,IF($R12>0,IF(K12="",0,IF(ISNUMBER(K12),K12,1)),IF($C12="Paying back",0,IF(AND(OR(Housemates!$C$13="",Housemates!$C$13<=$B12),OR(Housemates!$D$13="",Housemates!$D$13>=$B12)),IF($Q12=0,1,INDEX(Bills!$AF$6:$AF$25,$Q12)),0)))) | Y12: =IF(OR($D12="",$B12="",Housemates!$B$14=""),0,IF($R12>0,IF(L12="",0,IF(ISNUMBER(L12),L12,1)),IF($C12="Paying back",0,IF(AND(OR(Housemates!$C$14="",Housemates!$C$14<=$B12),OR(Housemates!$D$14="",Housemates!$D$14>=$B12)),IF($Q12=0,1,INDEX(Bills!$AG$6:$AG$25,$Q12)),0)))) | Z12: =IF(OR($D12="",$B12="",Housemates!$B$15=""),0,IF($R12>0,IF(M12="",0,IF(ISNUMBER(M12),M12,1)),IF($C12="Paying back",0,IF(AND(OR(Housemates!$C$15="",Housemates!$C$15<=$B12),OR(Housemates!$D$15="",Housemates!$D$15>=$B12)),IF($Q12=0,1,INDEX(Bills!$AH$6:$AH$25,$Q12)),0)))) | AA12: =SUM(S12:Z12) | AB12: =IF(AA12=0,0,D12*S12/AA12) | AC12: =IF(AA12=0,0,D12*T12/AA12) | AD12: =IF(AA12=0,0,D12*U12/AA12) | AE12: =IF(AA12=0,0,D12*V12/AA12) | AF12: =IF(AA12=0,0,D12*W12/AA12) | AG12: =IF(AA12=0,0,D12*X12/AA12) | AH12: =IF(AA12=0,0,D12*Y12/AA12) | AI12: =IF(AA12=0,0,D12*Z12/AA12) | AJ12: =IF(OR(C12="",B12=""),"",C12&"|"&(YEAR(B12)*100+MONTH(B12)))
B13: 46046 | C13: Groceries | D13: 49.08 | E13: Tom | N13: =IF(D13="","",IF(B13="","No date",IF(AND(C13="Paying back",R13=0),"To whom?",IF(AA13=0,"Nobody",IF(C13="Paying back","To "&INDEX(Housemates!$B$8:$B$15,MATCH(MAX(S13:Z13),S13:Z13,0)),IF(R13>0,IF(COUNTIF(S13:Z13,">0")=1,"1 person",COUNTIF(S13:Z13,">0")&" people"),IF(Q13=0,"Everyone",INDEX(Bills!$Q$6:$Q$25,Q13)))))))) | O13: =IF(D13="","",IF(C13="Paying back","Paying back",IF(Q13=0,"Other",IF(INDEX(Bills!$C$6:$C$25,Q13)="","Other",INDEX(Bills!$C$6:$C$25,Q13))))) | Q13: =IF(C13="",0,IFERROR(MATCH(C13,Bills!$B$6:$B$25,0),0)) | R13: =COUNTA(F13:M13) | S13: =IF(OR($D13="",$B13="",Housemates!$B$8=""),0,IF($R13>0,IF(F13="",0,IF(ISNUMBER(F13),F13,1)),IF($C13="Paying back",0,IF(AND(OR(Housemates!$C$8="",Housemates!$C$8<=$B13),OR(Housemates!$D$8="",Housemates!$D$8>=$B13)),IF($Q13=0,1,INDEX(Bills!$AA$6:$AA$25,$Q13)),0)))) | T13: =IF(OR($D13="",$B13="",Housemates!$B$9=""),0,IF($R13>0,IF(G13="",0,IF(ISNUMBER(G13),G13,1)),IF($C13="Paying back",0,IF(AND(OR(Housemates!$C$9="",Housemates!$C$9<=$B13),OR(Housemates!$D$9="",Housemates!$D$9>=$B13)),IF($Q13=0,1,INDEX(Bills!$AB$6:$AB$25,$Q13)),0)))) | U13: =IF(OR($D13="",$B13="",Housemates!$B$10=""),0,IF($R13>0,IF(H13="",0,IF(ISNUMBER(H13),H13,1)),IF($C13="Paying back",0,IF(AND(OR(Housemates!$C$10="",Housemates!$C$10<=$B13),OR(Housemates!$D$10="",Housemates!$D$10>=$B13)),IF($Q13=0,1,INDEX(Bills!$AC$6:$AC$25,$Q13)),0)))) | V13: =IF(OR($D13="",$B13="",Housemates!$B$11=""),0,IF($R13>0,IF(I13="",0,IF(ISNUMBER(I13),I13,1)),IF($C13="Paying back",0,IF(AND(OR(Housemates!$C$11="",Housemates!$C$11<=$B13),OR(Housemates!$D$11="",Housemates!$D$11>=$B13)),IF($Q13=0,1,INDEX(Bills!$AD$6:$AD$25,$Q13)),0)))) | W13: =IF(OR($D13="",$B13="",Housemates!$B$12=""),0,IF($R13>0,IF(J13="",0,IF(ISNUMBER(J13),J13,1)),IF($C13="Paying back",0,IF(AND(OR(Housemates!$C$12="",Housemates!$C$12<=$B13),OR(Housemates!$D$12="",Housemates!$D$12>=$B13)),IF($Q13=0,1,INDEX(Bills!$AE$6:$AE$25,$Q13)),0)))) | X13: =IF(OR($D13="",$B13="",Housemates!$B$13=""),0,IF($R13>0,IF(K13="",0,IF(ISNUMBER(K13),K13,1)),IF($C13="Paying back",0,IF(AND(OR(Housemates!$C$13="",Housemates!$C$13<=$B13),OR(Housemates!$D$13="",Housemates!$D$13>=$B13)),IF($Q13=0,1,INDEX(Bills!$AF$6:$AF$25,$Q13)),0)))) | Y13: =IF(OR($D13="",$B13="",Housemates!$B$14=""),0,IF($R13>0,IF(L13="",0,IF(ISNUMBER(L13),L13,1)),IF($C13="Paying back",0,IF(AND(OR(Housemates!$C$14="",Housemates!$C$14<=$B13),OR(Housemates!$D$14="",Housemates!$D$14>=$B13)),IF($Q13=0,1,INDEX(Bills!$AG$6:$AG$25,$Q13)),0)))) | Z13: =IF(OR($D13="",$B13="",Housemates!$B$15=""),0,IF($R13>0,IF(M13="",0,IF(ISNUMBER(M13),M13,1)),IF($C13="Paying back",0,IF(AND(OR(Housemates!$C$15="",Housemates!$C$15<=$B13),OR(Housemates!$D$15="",Housemates!$D$15>=$B13)),IF($Q13=0,1,INDEX(Bills!$AH$6:$AH$25,$Q13)),0)))) | AA13: =SUM(S13:Z13) | AB13: =IF(AA13=0,0,D13*S13/AA13) | AC13: =IF(AA13=0,0,D13*T13/AA13) | AD13: =IF(AA13=0,0,D13*U13/AA13) | AE13: =IF(AA13=0,0,D13*V13/AA13) | AF13: =IF(AA13=0,0,D13*W13/AA13) | AG13: =IF(AA13=0,0,D13*X13/AA13) | AH13: =IF(AA13=0,0,D13*Y13/AA13) | AI13: =IF(AA13=0,0,D13*Z13/AA13) | AJ13: =IF(OR(C13="",B13=""),"",C13&"|"&(YEAR(B13)*100+MONTH(B13)))
B14: 46051 | C14: Groceries | D14: 39.48 | E14: Maya | N14: =IF(D14="","",IF(B14="","No date",IF(AND(C14="Paying back",R14=0),"To whom?",IF(AA14=0,"Nobody",IF(C14="Paying back","To "&INDEX(Housemates!$B$8:$B$15,MATCH(MAX(S14:Z14),S14:Z14,0)),IF(R14>0,IF(COUNTIF(S14:Z14,">0")=1,"1 person",COUNTIF(S14:Z14,">0")&" people"),IF(Q14=0,"Everyone",INDEX(Bills!$Q$6:$Q$25,Q14)))))))) | O14: =IF(D14="","",IF(C14="Paying back","Paying back",IF(Q14=0,"Other",IF(INDEX(Bills!$C$6:$C$25,Q14)="","Other",INDEX(Bills!$C$6:$C$25,Q14))))) | Q14: =IF(C14="",0,IFERROR(MATCH(C14,Bills!$B$6:$B$25,0),0)) | R14: =COUNTA(F14:M14) | S14: =IF(OR($D14="",$B14="",Housemates!$B$8=""),0,IF($R14>0,IF(F14="",0,IF(ISNUMBER(F14),F14,1)),IF($C14="Paying back",0,IF(AND(OR(Housemates!$C$8="",Housemates!$C$8<=$B14),OR(Housemates!$D$8="",Housemates!$D$8>=$B14)),IF($Q14=0,1,INDEX(Bills!$AA$6:$AA$25,$Q14)),0)))) | T14: =IF(OR($D14="",$B14="",Housemates!$B$9=""),0,IF($R14>0,IF(G14="",0,IF(ISNUMBER(G14),G14,1)),IF($C14="Paying back",0,IF(AND(OR(Housemates!$C$9="",Housemates!$C$9<=$B14),OR(Housemates!$D$9="",Housemates!$D$9>=$B14)),IF($Q14=0,1,INDEX(Bills!$AB$6:$AB$25,$Q14)),0)))) | U14: =IF(OR($D14="",$B14="",Housemates!$B$10=""),0,IF($R14>0,IF(H14="",0,IF(ISNUMBER(H14),H14,1)),IF($C14="Paying back",0,IF(AND(OR(Housemates!$C$10="",Housemates!$C$10<=$B14),OR(Housemates!$D$10="",Housemates!$D$10>=$B14)),IF($Q14=0,1,INDEX(Bills!$AC$6:$AC$25,$Q14)),0)))) | V14: =IF(OR($D14="",$B14="",Housemates!$B$11=""),0,IF($R14>0,IF(I14="",0,IF(ISNUMBER(I14),I14,1)),IF($C14="Paying back",0,IF(AND(OR(Housemates!$C$11="",Housemates!$C$11<=$B14),OR(Housemates!$D$11="",Housemates!$D$11>=$B14)),IF($Q14=0,1,INDEX(Bills!$AD$6:$AD$25,$Q14)),0)))) | W14: =IF(OR($D14="",$B14="",Housemates!$B$12=""),0,IF($R14>0,IF(J14="",0,IF(ISNUMBER(J14),J14,1)),IF($C14="Paying back",0,IF(AND(OR(Housemates!$C$12="",Housemates!$C$12<=$B14),OR(Housemates!$D$12="",Housemates!$D$12>=$B14)),IF($Q14=0,1,INDEX(Bills!$AE$6:$AE$25,$Q14)),0)))) | X14: =IF(OR($D14="",$B14="",Housemates!$B$13=""),0,IF($R14>0,IF(K14="",0,IF(ISNUMBER(K14),K14,1)),IF($C14="Paying back",0,IF(AND(OR(Housemates!$C$13="",Housemates!$C$13<=$B14),OR(Housemates!$D$13="",Housemates!$D$13>=$B14)),IF($Q14=0,1,INDEX(Bills!$AF$6:$AF$25,$Q14)),0)))) | Y14: =IF(OR($D14="",$B14="",Housemates!$B$14=""),0,IF($R14>0,IF(L14="",0,IF(ISNUMBER(L14),L14,1)),IF($C14="Paying back",0,IF(AND(OR(Housemates!$C$14="",Housemates!$C$14<=$B14),OR(Housemates!$D$14="",Housemates!$D$14>=$B14)),IF($Q14=0,1,INDEX(Bills!$AG$6:$AG$25,$Q14)),0)))) | Z14: =IF(OR($D14="",$B14="",Housemates!$B$15=""),0,IF($R14>0,IF(M14="",0,IF(ISNUMBER(M14),M14,1)),IF($C14="Paying back",0,IF(AND(OR(Housemates!$C$15="",Housemates!$C$15<=$B14),OR(Housemates!$D$15="",Housemates!$D$15>=$B14)),IF($Q14=0,1,INDEX(Bills!$AH$6:$AH$25,$Q14)),0)))) | AA14: =SUM(S14:Z14) | AB14: =IF(AA14=0,0,D14*S14/AA14) | AC14: =IF(AA14=0,0,D14*T14/AA14) | AD14: =IF(AA14=0,0,D14*U14/AA14) | AE14: =IF(AA14=0,0,D14*V14/AA14) | AF14: =IF(AA14=0,0,D14*W14/AA14) | AG14: =IF(AA14=0,0,D14*X14/AA14) | AH14: =IF(AA14=0,0,D14*Y14/AA14) | AI14: =IF(AA14=0,0,D14*Z14/AA14) | AJ14: =IF(OR(C14="",B14=""),"",C14&"|"&(YEAR(B14)*100+MONTH(B14)))
B15: 46054 | C15: Rent | D15: 2400 | E15: Maya | N15: =IF(D15="","",IF(B15="","No date",IF(AND(C15="Paying back",R15=0),"To whom?",IF(AA15=0,"Nobody",IF(C15="Paying back","To "&INDEX(Housemates!$B$8:$B$15,MATCH(MAX(S15:Z15),S15:Z15,0)),IF(R15>0,IF(COUNTIF(S15:Z15,">0")=1,"1 person",COUNTIF(S15:Z15,">0")&" people"),IF(Q15=0,"Everyone",INDEX(Bills!$Q$6:$Q$25,Q15)))))))) | O15: =IF(D15="","",IF(C15="Paying back","Paying back",IF(Q15=0,"Other",IF(INDEX(Bills!$C$6:$C$25,Q15)="","Other",INDEX(Bills!$C$6:$C$25,Q15))))) | Q15: =IF(C15="",0,IFERROR(MATCH(C15,Bills!$B$6:$B$25,0),0)) | R15: =COUNTA(F15:M15) | S15: =IF(OR($D15="",$B15="",Housemates!$B$8=""),0,IF($R15>0,IF(F15="",0,IF(ISNUMBER(F15),F15,1)),IF($C15="Paying back",0,IF(AND(OR(Housemates!$C$8="",Housemates!$C$8<=$B15),OR(Housemates!$D$8="",Housemates!$D$8>=$B15)),IF($Q15=0,1,INDEX(Bills!$AA$6:$AA$25,$Q15)),0)))) | T15: =IF(OR($D15="",$B15="",Housemates!$B$9=""),0,IF($R15>0,IF(G15="",0,IF(ISNUMBER(G15),G15,1)),IF($C15="Paying back",0,IF(AND(OR(Housemates!$C$9="",Housemates!$C$9<=$B15),OR(Housemates!$D$9="",Housemates!$D$9>=$B15)),IF($Q15=0,1,INDEX(Bills!$AB$6:$AB$25,$Q15)),0)))) | U15: =IF(OR($D15="",$B15="",Housemates!$B$10=""),0,IF($R15>0,IF(H15="",0,IF(ISNUMBER(H15),H15,1)),IF($C15="Paying back",0,IF(AND(OR(Housemates!$C$10="",Housemates!$C$10<=$B15),OR(Housemates!$D$10="",Housemates!$D$10>=$B15)),IF($Q15=0,1,INDEX(Bills!$AC$6:$AC$25,$Q15)),0)))) | V15: =IF(OR($D15="",$B15="",Housemates!$B$11=""),0,IF($R15>0,IF(I15="",0,IF(ISNUMBER(I15),I15,1)),IF($C15="Paying back",0,IF(AND(OR(Housemates!$C$11="",Housemates!$C$11<=$B15),OR(Housemates!$D$11="",Housemates!$D$11>=$B15)),IF($Q15=0,1,INDEX(Bills!$AD$6:$AD$25,$Q15)),0)))) | W15: =IF(OR($D15="",$B15="",Housemates!$B$12=""),0,IF($R15>0,IF(J15="",0,IF(ISNUMBER(J15),J15,1)),IF($C15="Paying back",0,IF(AND(OR(Housemates!$C$12="",Housemates!$C$12<=$B15),OR(Housemates!$D$12="",Housemates!$D$12>=$B15)),IF($Q15=0,1,INDEX(Bills!$AE$6:$AE$25,$Q15)),0)))) | X15: =IF(OR($D15="",$B15="",Housemates!$B$13=""),0,IF($R15>0,IF(K15="",0,IF(ISNUMBER(K15),K15,1)),IF($C15="Paying back",0,IF(AND(OR(Housemates!$C$13="",Housemates!$C$13<=$B15),OR(Housemates!$D$13="",Housemates!$D$13>=$B15)),IF($Q15=0,1,INDEX(Bills!$AF$6:$AF$25,$Q15)),0)))) | Y15: =IF(OR($D15="",$B15="",Housemates!$B$14=""),0,IF($R15>0,IF(L15="",0,IF(ISNUMBER(L15),L15,1)),IF($C15="Paying back",0,IF(AND(OR(Housemates!$C$14="",Housemates!$C$14<=$B15),OR(Housemates!$D$14="",Housemates!$D$14>=$B15)),IF($Q15=0,1,INDEX(Bills!$AG$6:$AG$25,$Q15)),0)))) | Z15: =IF(OR($D15="",$B15="",Housemates!$B$15=""),0,IF($R15>0,IF(M15="",0,IF(ISNUMBER(M15),M15,1)),IF($C15="Paying back",0,IF(AND(OR(Housemates!$C$15="",Housemates!$C$15<=$B15),OR(Housemates!$D$15="",Housemates!$D$15>=$B15)),IF($Q15=0,1,INDEX(Bills!$AH$6:$AH$25,$Q15)),0)))) | AA15: =SUM(S15:Z15) | AB15: =IF(AA15=0,0,D15*S15/AA15) | AC15: =IF(AA15=0,0,D15*T15/AA15) | AD15: =IF(AA15=0,0,D15*U15/AA15) | AE15: =IF(AA15=0,0,D15*V15/AA15) | AF15: =IF(AA15=0,0,D15*W15/AA15) | AG15: =IF(AA15=0,0,D15*X15/AA15) | AH15: =IF(AA15=0,0,D15*Y15/AA15) | AI15: =IF(AA15=0,0,D15*Z15/AA15) | AJ15: =IF(OR(C15="",B15=""),"",C15&"|"&(YEAR(B15)*100+MONTH(B15)))
B16: 46056 | C16: Internet | D16: 45 | E16: Leo | N16: =IF(D16="","",IF(B16="","No date",IF(AND(C16="Paying back",R16=0),"To whom?",IF(AA16=0,"Nobody",IF(C16="Paying back","To "&INDEX(Housemates!$B$8:$B$15,MATCH(MAX(S16:Z16),S16:Z16,0)),IF(R16>0,IF(COUNTIF(S16:Z16,">0")=1,"1 person",COUNTIF(S16:Z16,">0")&" people"),IF(Q16=0,"Everyone",INDEX(Bills!$Q$6:$Q$25,Q16)))))))) | O16: =IF(D16="","",IF(C16="Paying back","Paying back",IF(Q16=0,"Other",IF(INDEX(Bills!$C$6:$C$25,Q16)="","Other",INDEX(Bills!$C$6:$C$25,Q16))))) | Q16: =IF(C16="",0,IFERROR(MATCH(C16,Bills!$B$6:$B$25,0),0)) | R16: =COUNTA(F16:M16) | S16: =IF(OR($D16="",$B16="",Housemates!$B$8=""),0,IF($R16>0,IF(F16="",0,IF(ISNUMBER(F16),F16,1)),IF($C16="Paying back",0,IF(AND(OR(Housemates!$C$8="",Housemates!$C$8<=$B16),OR(Housemates!$D$8="",Housemates!$D$8>=$B16)),IF($Q16=0,1,INDEX(Bills!$AA$6:$AA$25,$Q16)),0)))) | T16: =IF(OR($D16="",$B16="",Housemates!$B$9=""),0,IF($R16>0,IF(G16="",0,IF(ISNUMBER(G16),G16,1)),IF($C16="Paying back",0,IF(AND(OR(Housemates!$C$9="",Housemates!$C$9<=$B16),OR(Housemates!$D$9="",Housemates!$D$9>=$B16)),IF($Q16=0,1,INDEX(Bills!$AB$6:$AB$25,$Q16)),0)))) | U16: =IF(OR($D16="",$B16="",Housemates!$B$10=""),0,IF($R16>0,IF(H16="",0,IF(ISNUMBER(H16),H16,1)),IF($C16="Paying back",0,IF(AND(OR(Housemates!$C$10="",Housemates!$C$10<=$B16),OR(Housemates!$D$10="",Housemates!$D$10>=$B16)),IF($Q16=0,1,INDEX(Bills!$AC$6:$AC$25,$Q16)),0)))) | V16: =IF(OR($D16="",$B16="",Housemates!$B$11=""),0,IF($R16>0,IF(I16="",0,IF(ISNUMBER(I16),I16,1)),IF($C16="Paying back",0,IF(AND(OR(Housemates!$C$11="",Housemates!$C$11<=$B16),OR(Housemates!$D$11="",Housemates!$D$11>=$B16)),IF($Q16=0,1,INDEX(Bills!$AD$6:$AD$25,$Q16)),0)))) | W16: =IF(OR($D16="",$B16="",Housemates!$B$12=""),0,IF($R16>0,IF(J16="",0,IF(ISNUMBER(J16),J16,1)),IF($C16="Paying back",0,IF(AND(OR(Housemates!$C$12="",Housemates!$C$12<=$B16),OR(Housemates!$D$12="",Housemates!$D$12>=$B16)),IF($Q16=0,1,INDEX(Bills!$AE$6:$AE$25,$Q16)),0)))) | X16: =IF(OR($D16="",$B16="",Housemates!$B$13=""),0,IF($R16>0,IF(K16="",0,IF(ISNUMBER(K16),K16,1)),IF($C16="Paying back",0,IF(AND(OR(Housemates!$C$13="",Housemates!$C$13<=$B16),OR(Housemates!$D$13="",Housemates!$D$13>=$B16)),IF($Q16=0,1,INDEX(Bills!$AF$6:$AF$25,$Q16)),0)))) | Y16: =IF(OR($D16="",$B16="",Housemates!$B$14=""),0,IF($R16>0,IF(L16="",0,IF(ISNUMBER(L16),L16,1)),IF($C16="Paying back",0,IF(AND(OR(Housemates!$C$14="",Housemates!$C$14<=$B16),OR(Housemates!$D$14="",Housemates!$D$14>=$B16)),IF($Q16=0,1,INDEX(Bills!$AG$6:$AG$25,$Q16)),0)))) | Z16: =IF(OR($D16="",$B16="",Housemates!$B$15=""),0,IF($R16>0,IF(M16="",0,IF(ISNUMBER(M16),M16,1)),IF($C16="Paying back",0,IF(AND(OR(Housemates!$C$15="",Housemates!$C$15<=$B16),OR(Housemates!$D$15="",Housemates!$D$15>=$B16)),IF($Q16=0,1,INDEX(Bills!$AH$6:$AH$25,$Q16)),0)))) | AA16: =SUM(S16:Z16) | AB16: =IF(AA16=0,0,D16*S16/AA16) | AC16: =IF(AA16=0,0,D16*T16/AA16) | AD16: =IF(AA16=0,0,D16*U16/AA16) | AE16: =IF(AA16=0,0,D16*V16/AA16) | AF16: =IF(AA16=0,0,D16*W16/AA16) | AG16: =IF(AA16=0,0,D16*X16/AA16) | AH16: =IF(AA16=0,0,D16*Y16/AA16) | AI16: =IF(AA16=0,0,D16*Z16/AA16) | AJ16: =IF(OR(C16="",B16=""),"",C16&"|"&(YEAR(B16)*100+MONTH(B16)))
