Workbook

Sheet Dashboard
B2: Your way out of debt
B3: Change the method or the extra amount on the Debts tab: everything updates.
B6: Total debt now | C6: Paying per month | D6: Interest you will pay | E6: Months to go | F6: Debt-free in
B7: =Debts!$C$16 | C7: =Debts!$E$16+Debts!$J$7 | D7: =IF(Debts!$J$10="Snowball",SUM(Snowball!$F$8:$F$187),SUM(Avalanche!$F$8:$F$187)) | E7: =IF(Debts!$J$10="Snowball",IF(COUNTIF(Snowball!$G$8:$G$187,">0.005")>=180,"",COUNTIF(Snowball!$G$8:$G$187,">0.005")+1),IF(COUNTIF(Avalanche!$G$8:$G$187,">0.005")>=180,"",COUNTIF(Avalanche!$G$8:$G$187,">0.005")+1)) | F7: =IF(IF(Debts!$J$10="Snowball",IF(COUNTIF(Snowball!$G$8:$G$187,">0.005")>=180,"",COUNTIF(Snowball!$G$8:$G$187,">0.005")+1),IF(COUNTIF(Avalanche!$G$8:$G$187,">0.005")>=180,"",COUNTIF(Avalanche!$G$8:$G$187,">0.005")+1))="","15+ years",EDATE(Debts!$J$13,IF(Debts!$J$10="Snowball",IF(COUNTIF(Snowball!$G$8:$G$187,">0.005")>=180,"",COUNTIF(Snowball!$G$8:$G$187,">0.005")+1),IF(COUNTIF(Avalanche!$G$8:$G$187,">0.005")>=180,"",COUNTIF(Avalanche!$G$8:$G$187,">0.005")+1))-1))
B9: This month
B10: =IFERROR("Pay the minimum on every debt, and "&FIXED(INDEX(Debts!$H$6:$H$15,MATCH(1,IF(Debts!$J$10="Snowball",Debts!$F$6:$F$15,Debts!$G$6:$G$15),0)),2)&" on "&INDEX(Debts!$B$6:$B$15,MATCH(1,IF(Debts!$J$10="Snowball",Debts!$F$6:$F$15,Debts!$G$6:$G$15),0))&". That is your focus debt.","Add your debts on the Debts tab.")
B12: Compare | C12: Months | D12: Debt-free | E12: Interest | F12: Difference
B13: Avalanche | C13: =IF(COUNTIF(Avalanche!$G$8:$G$187,">0.005")>=180,"",COUNTIF(Avalanche!$G$8:$G$187,">0.005")+1) | D13: =IF(C13="","15+ years",EDATE(Debts!$J$13,C13-1)) | E13: =SUM(Avalanche!$F$8:$F$187) | F13: =IF(E14-E13>0.5,"saves "&FIXED(E14-E13,0)&" in interest","same interest")
B14: Snowball | C14: =IF(COUNTIF(Snowball!$G$8:$G$187,">0.005")>=180,"",COUNTIF(Snowball!$G$8:$G$187,">0.005")+1) | D14: =IF(C14="","15+ years",EDATE(Debts!$J$13,C14-1)) | E14: =SUM(Snowball!$F$8:$F$187) | F14: ="1st debt gone in "&MIN(Debts!$M$6:$M$15)&" mo (vs "&MIN(Debts!$N$6:$N$15)&")"
B16: Debt | C16: Balance now | D16: Interest % | E16: Paid off in | F16: Order
B17: =IF(Debts!B6="","",Debts!B6) | C17: =IF(Debts!B6="","",Debts!C6) | D17: =IF(Debts!B6="","",Debts!D6) | E17: =IF(OR(Debts!B6="",Debts!I6=""),"",EDATE(Debts!$J$13,Debts!I6-1)) | F17: =IF(Debts!B6="","",IF(Debts!$J$10="Snowball",Debts!F6,Debts!G6))
B18: =IF(Debts!B7="","",Debts!B7) | C18: =IF(Debts!B7="","",Debts!C7) | D18: =IF(Debts!B7="","",Debts!D7) | E18: =IF(OR(Debts!B7="",Debts!I7=""),"",EDATE(Debts!$J$13,Debts!I7-1)) | F18: =IF(Debts!B7="","",IF(Debts!$J$10="Snowball",Debts!F7,Debts!G7))
B19: =IF(Debts!B8="","",Debts!B8) | C19: =IF(Debts!B8="","",Debts!C8) | D19: =IF(Debts!B8="","",Debts!D8) | E19: =IF(OR(Debts!B8="",Debts!I8=""),"",EDATE(Debts!$J$13,Debts!I8-1)) | F19: =IF(Debts!B8="","",IF(Debts!$J$10="Snowball",Debts!F8,Debts!G8))
B20: =IF(Debts!B9="","",Debts!B9) | C20: =IF(Debts!B9="","",Debts!C9) | D20: =IF(Debts!B9="","",Debts!D9) | E20: =IF(OR(Debts!B9="",Debts!I9=""),"",EDATE(Debts!$J$13,Debts!I9-1)) | F20: =IF(Debts!B9="","",IF(Debts!$J$10="Snowball",Debts!F9,Debts!G9))
B21: =IF(Debts!B10="","",Debts!B10) | C21: =IF(Debts!B10="","",Debts!C10) | D21: =IF(Debts!B10="","",Debts!D10) | E21: =IF(OR(Debts!B10="",Debts!I10=""),"",EDATE(Debts!$J$13,Debts!I10-1)) | F21: =IF(Debts!B10="","",IF(Debts!$J$10="Snowball",Debts!F10,Debts!G10))
B22: =IF(Debts!B11="","",Debts!B11) | C22: =IF(Debts!B11="","",Debts!C11) | D22: =IF(Debts!B11="","",Debts!D11) | E22: =IF(OR(Debts!B11="",Debts!I11=""),"",EDATE(Debts!$J$13,Debts!I11-1)) | F22: =IF(Debts!B11="","",IF(Debts!$J$10="Snowball",Debts!F11,Debts!G11))
B23: =IF(Debts!B12="","",Debts!B12) | C23: =IF(Debts!B12="","",Debts!C12) | D23: =IF(Debts!B12="","",Debts!D12) | E23: =IF(OR(Debts!B12="",Debts!I12=""),"",EDATE(Debts!$J$13,Debts!I12-1)) | F23: =IF(Debts!B12="","",IF(Debts!$J$10="Snowball",Debts!F12,Debts!G12))
B24: =IF(Debts!B13="","",Debts!B13) | C24: =IF(Debts!B13="","",Debts!C13) | D24: =IF(Debts!B13="","",Debts!D13) | E24: =IF(OR(Debts!B13="",Debts!I13=""),"",EDATE(Debts!$J$13,Debts!I13-1)) | F24: =IF(Debts!B13="","",IF(Debts!$J$10="Snowball",Debts!F13,Debts!G13))
B25: =IF(Debts!B14="","",Debts!B14) | C25: =IF(Debts!B14="","",Debts!C14) | D25: =IF(Debts!B14="","",Debts!D14) | E25: =IF(OR(Debts!B14="",Debts!I14=""),"",EDATE(Debts!$J$13,Debts!I14-1)) | F25: =IF(Debts!B14="","",IF(Debts!$J$10="Snowball",Debts!F14,Debts!G14))
B26: =IF(Debts!B15="","",Debts!B15) | C26: =IF(Debts!B15="","",Debts!C15) | D26: =IF(Debts!B15="","",Debts!D15) | E26: =IF(OR(Debts!B15="",Debts!I15=""),"",EDATE(Debts!$J$13,Debts!I15-1)) | F26: =IF(Debts!B15="","",IF(Debts!$J$10="Snowball",Debts!F15,Debts!G15))

Sheet Debts
B2: Your debts
B3: One line per debt. Only the yellow cells.
B5: Debt | C5: Balance now | D5: Interest % per year | E5: Minimum payment | F5: Snowball order | G5: Avalanche order | H5: Pay this month | I5: Paid off (month #) | M5: Snowball month # | N5: Avalanche month #
B6: Credit card | C6: 3200 | D6: 24.9 | E6: 96 | F6: =IF(AND($B6<>"",N($C6)>0),COUNTIFS($C$6:$C$15,"<"&$C6,$B$6:$B$15,"<>",$C$6:$C$15,">0")+COUNTIFS($C$6:$C6,$C6,$B$6:$B6,"<>"),"") | G6: =IF(AND($B6<>"",N($C6)>0),COUNTIFS($D$6:$D$15,">"&N($D6),$B$6:$B$15,"<>",$C$6:$C$15,">0")+COUNTIFS($D$6:$D6,N($D6),$B$6:$B6,"<>",$C$6:$C6,">0"),"") | H6: =IF($B6="","",IF(Debts!$J$10="Snowball",Snowball!H8-Snowball!J8,Avalanche!H8-Avalanche!J8)) | I6: =IF($B6="","",IF(Debts!$J$10="Snowball",M6,N6)) | J6: Extra you can add every month | M6: =IF($B6="","",IF(COUNTIF(Snowball!$J$8:$J$187,">0.005")>=180,"",COUNTIF(Snowball!$J$8:$J$187,">0.005")+1)) | N6: =IF($B6="","",IF(COUNTIF(Avalanche!$J$8:$J$187,">0.005")>=180,"",COUNTIF(Avalanche!$J$8:$J$187,">0.005")+1))
B7: Store card | C7: 850 | D7: 29.9 | E7: 35 | F7: =IF(AND($B7<>"",N($C7)>0),COUNTIFS($C$6:$C$15,"<"&$C7,$B$6:$B$15,"<>",$C$6:$C$15,">0")+COUNTIFS($C$6:$C7,$C7,$B$6:$B7,"<>"),"") | G7: =IF(AND($B7<>"",N($C7)>0),COUNTIFS($D$6:$D$15,">"&N($D7),$B$6:$B$15,"<>",$C$6:$C$15,">0")+COUNTIFS($D$6:$D7,N($D7),$B$6:$B7,"<>",$C$6:$C7,">0"),"") | H7: =IF($B7="","",IF(Debts!$J$10="Snowball",Snowball!K8-Snowball!M8,Avalanche!K8-Avalanche!M8)) | I7: =IF($B7="","",IF(Debts!$J$10="Snowball",M7,N7)) | J7: 200 | M7: =IF($B7="","",IF(COUNTIF(Snowball!$M$8:$M$187,">0.005")>=180,"",COUNTIF(Snowball!$M$8:$M$187,">0.005")+1)) | N7: =IF($B7="","",IF(COUNTIF(Avalanche!$M$8:$M$187,">0.005")>=180,"",COUNTIF(Avalanche!$M$8:$M$187,">0.005")+1))
B8: Car loan | C8: 7400 | D8: 6.9 | E8: 210 | F8: =IF(AND($B8<>"",N($C8)>0),COUNTIFS($C$6:$C$15,"<"&$C8,$B$6:$B$15,"<>",$C$6:$C$15,">0")+COUNTIFS($C$6:$C8,$C8,$B$6:$B8,"<>"),"") | G8: =IF(AND($B8<>"",N($C8)>0),COUNTIFS($D$6:$D$15,">"&N($D8),$B$6:$B$15,"<>",$C$6:$C$15,">0")+COUNTIFS($D$6:$D8,N($D8),$B$6:$B8,"<>",$C$6:$C8,">0"),"") | H8: =IF($B8="","",IF(Debts!$J$10="Snowball",Snowball!N8-Snowball!P8,Avalanche!N8-Avalanche!P8)) | I8: =IF($B8="","",IF(Debts!$J$10="Snowball",M8,N8)) | M8: =IF($B8="","",IF(COUNTIF(Snowball!$P$8:$P$187,">0.005")>=180,"",COUNTIF(Snowball!$P$8:$P$187,">0.005")+1)) | N8: =IF($B8="","",IF(COUNTIF(Avalanche!$P$8:$P$187,">0.005")>=180,"",COUNTIF(Avalanche!$P$8:$P$187,">0.005")+1))
B9: Personal loan | C9: 2100 | D9: 11.5 | E9: 85 | F9: =IF(AND($B9<>"",N($C9)>0),COUNTIFS($C$6:$C$15,"<"&$C9,$B$6:$B$15,"<>",$C$6:$C$15,">0")+COUNTIFS($C$6:$C9,$C9,$B$6:$B9,"<>"),"") | G9: =IF(AND($B9<>"",N($C9)>0),COUNTIFS($D$6:$D$15,">"&N($D9),$B$6:$B$15,"<>",$C$6:$C$15,">0")+COUNTIFS($D$6:$D9,N($D9),$B$6:$B9,"<>",$C$6:$C9,">0"),"") | H9: =IF($B9="","",IF(Debts!$J$10="Snowball",Snowball!Q8-Snowball!S8,Avalanche!Q8-Avalanche!S8)) | I9: =IF($B9="","",IF(Debts!$J$10="Snowball",M9,N9)) | J9: Method (Avalanche or Snowball) | M9: =IF($B9="","",IF(COUNTIF(Snowball!$S$8:$S$187,">0.005")>=180,"",COUNTIF(Snowball!$S$8:$S$187,">0.005")+1)) | N9: =IF($B9="","",IF(COUNTIF(Avalanche!$S$8:$S$187,">0.005")>=180,"",COUNTIF(Avalanche!$S$8:$S$187,">0.005")+1))
B10: Medical bill | C10: 600 | D10: 0 | E10: 50 | F10: =IF(AND($B10<>"",N($C10)>0),COUNTIFS($C$6:$C$15,"<"&$C10,$B$6:$B$15,"<>",$C$6:$C$15,">0")+COUNTIFS($C$6:$C10,$C10,$B$6:$B10,"<>"),"") | G10: =IF(AND($B10<>"",N($C10)>0),COUNTIFS($D$6:$D$15,">"&N($D10),$B$6:$B$15,"<>",$C$6:$C$15,">0")+COUNTIFS($D$6:$D10,N($D10),$B$6:$B10,"<>",$C$6:$C10,">0"),"") | H10: =IF($B10="","",IF(Debts!$J$10="Snowball",Snowball!T8-Snowball!V8,Avalanche!T8-Avalanche!V8)) | I10: =IF($B10="","",IF(Debts!$J$10="Snowball",M10,N10)) | J10: Avalanche | M10: =IF($B10="","",IF(COUNTIF(Snowball!$V$8:$V$187,">0.005")>=180,"",COUNTIF(Snowball!$V$8:$V$187,">0.005")+1)) | N10: =IF($B10="","",IF(COUNTIF(Avalanche!$V$8:$V$187,">0.005")>=180,"",COUNTIF(Avalanche!$V$8:$V$187,">0.005")+1))
F11: =IF(AND($B11<>"",N($C11)>0),COUNTIFS($C$6:$C$15,"<"&$C11,$B$6:$B$15,"<>",$C$6:$C$15,">0")+COUNTIFS($C$6:$C11,$C11,$B$6:$B11,"<>"),"") | G11: =IF(AND($B11<>"",N($C11)>0),COUNTIFS($D$6:$D$15,">"&N($D11),$B$6:$B$15,"<>",$C$6:$C$15,">0")+COUNTIFS($D$6:$D11,N($D11),$B$6:$B11,"<>",$C$6:$C11,">0"),"") | H11: =IF($B11="","",IF(Debts!$J$10="Snowball",Snowball!W8-Snowball!Y8,Avalanche!W8-Avalanche!Y8)) | I11: =IF($B11="","",IF(Debts!$J$10="Snowball",M11,N11)) | M11: =IF($B11="","",IF(COUNTIF(Snowball!$Y$8:$Y$187,">0.005")>=180,"",COUNTIF(Snowball!$Y$8:$Y$187,">0.005")+1)) | N11: =IF($B11="","",IF(COUNTIF(Avalanche!$Y$8:$Y$187,">0.005")>=180,"",COUNTIF(Avalanche!$Y$8:$Y$187,">0.005")+1))
F12: =IF(AND($B12<>"",N($C12)>0),COUNTIFS($C$6:$C$15,"<"&$C12,$B$6:$B$15,"<>",$C$6:$C$15,">0")+COUNTIFS($C$6:$C12,$C12,$B$6:$B12,"<>"),"") | G12: =IF(AND($B12<>"",N($C12)>0),COUNTIFS($D$6:$D$15,">"&N($D12),$B$6:$B$15,"<>",$C$6:$C$15,">0")+COUNTIFS($D$6:$D12,N($D12),$B$6:$B12,"<>",$C$6:$C12,">0"),"") | H12: =IF($B12="","",IF(Debts!$J$10="Snowball",Snowball!Z8-Snowball!AB8,Avalanche!Z8-Avalanche!AB8)) | I12: =IF($B12="","",IF(Debts!$J$10="Snowball",M12,N12)) | J12: First payment month | M12: =IF($B12="","",IF(COUNTIF(Snowball!$AB$8:$AB$187,">0.005")>=180,"",COUNTIF(Snowball!$AB$8:$AB$187,">0.005")+1)) | N12: =IF($B12="","",IF(COUNTIF(Avalanche!$AB$8:$AB$187,">0.005")>=180,"",COUNTIF(Avalanche!$AB$8:$AB$187,">0.005")+1))
F13: =IF(AND($B13<>"",N($C13)>0),COUNTIFS($C$6:$C$15,"<"&$C13,$B$6:$B$15,"<>",$C$6:$C$15,">0")+COUNTIFS($C$6:$C13,$C13,$B$6:$B13,"<>"),"") | G13: =IF(AND($B13<>"",N($C13)>0),COUNTIFS($D$6:$D$15,">"&N($D13),$B$6:$B$15,"<>",$C$6:$C$15,">0")+COUNTIFS($D$6:$D13,N($D13),$B$6:$B13,"<>",$C$6:$C13,">0"),"") | H13: =IF($B13="","",IF(Debts!$J$10="Snowball",Snowball!AC8-Snowball!AE8,Avalanche!AC8-Avalanche!AE8)) | I13: =IF($B13="","",IF(Debts!$J$10="Snowball",M13,N13)) | J13: 46296 | M13: =IF($B13="","",IF(COUNTIF(Snowball!$AE$8:$AE$187,">0.005")>=180,"",COUNTIF(Snowball!$AE$8:$AE$187,">0.005")+1)) | N13: =IF($B13="","",IF(COUNTIF(Avalanche!$AE$8:$AE$187,">0.005")>=180,"",COUNTIF(Avalanche!$AE$8:$AE$187,">0.005")+1))
F14: =IF(AND($B14<>"",N($C14)>0),COUNTIFS($C$6:$C$15,"<"&$C14,$B$6:$B$15,"<>",$C$6:$C$15,">0")+COUNTIFS($C$6:$C14,$C14,$B$6:$B14,"<>"),"") | G14: =IF(AND($B14<>"",N($C14)>0),COUNTIFS($D$6:$D$15,">"&N($D14),$B$6:$B$15,"<>",$C$6:$C$15,">0")+COUNTIFS($D$6:$D14,N($D14),$B$6:$B14,"<>",$C$6:$C14,">0"),"") | H14: =IF($B14="","",IF(Debts!$J$10="Snowball",Snowball!AF8-Snowball!AH8,Avalanche!AF8-Avalanche!AH8)) | I14: =IF($B14="","",IF(Debts!$J$10="Snowball",M14,N14)) | M14: =IF($B14="","",IF(COUNTIF(Snowball!$AH$8:$AH$187,">0.005")>=180,"",COUNTIF(Snowball!$AH$8:$AH$187,">0.005")+1)) | N14: =IF($B14="","",IF(COUNTIF(Avalanche!$AH$8:$AH$187,">0.005")>=180,"",COUNTIF(Avalanche!$AH$8:$AH$187,">0.005")+1))
F15: =IF(AND($B15<>"",N($C15)>0),COUNTIFS($C$6:$C$15,"<"&$C15,$B$6:$B$15,"<>",$C$6:$C$15,">0")+COUNTIFS($C$6:$C15,$C15,$B$6:$B15,"<>"),"") | G15: =IF(AND($B15<>"",N($C15)>0),COUNTIFS($D$6:$D$15,">"&N($D15),$B$6:$B$15,"<>",$C$6:$C$15,">0")+COUNTIFS($D$6:$D15,N($D15),$B$6:$B15,"<>",$C$6:$C15,">0"),"") | H15: =IF($B15="","",IF(Debts!$J$10="Snowball",Snowball!AI8-Snowball!AK8,Avalanche!AI8-Avalanche!AK8)) | I15: =IF($B15="","",IF(Debts!$J$10="Snowball",M15,N15)) | J15: Avalanche: highest interest first (saves the most money). | M15: =IF($B15="","",IF(COUNTIF(Snowball!$AK$8:$AK$187,">0.005")>=180,"",COUNTIF(Snowball!$AK$8:$AK$187,">0.005")+1)) | N15: =IF($B15="","",IF(COUNTIF(Avalanche!$AK$8:$AK$187,">0.005")>=180,"",COUNTIF(Avalanche!$AK$8:$AK$187,">0.005")+1))
B16: Total | C16: =SUM(C6:C15) | E16: =SUMIFS(E6:E15,C6:C15,">0") | J16: Snowball: smallest balance first (quick wins, more motivation).

Sheet Snowball
B2: Snowball: month by month
B3: Calculated for you. Nothing to type here.
H4: =IF(Debts!$F$6="","",Debts!$F$6) | I4: =IF(Debts!$F$6="","",Debts!$F$6) | J4: =IF(Debts!$F$6="","",Debts!$F$6) | K4: =IF(Debts!$F$7="","",Debts!$F$7) | L4: =IF(Debts!$F$7="","",Debts!$F$7) | M4: =IF(Debts!$F$7="","",Debts!$F$7) | N4: =IF(Debts!$F$8="","",Debts!$F$8) | O4: =IF(Debts!$F$8="","",Debts!$F$8) | P4: =IF(Debts!$F$8="","",Debts!$F$8) | Q4: =IF(Debts!$F$9="","",Debts!$F$9) | R4: =IF(Debts!$F$9="","",Debts!$F$9) | S4: =IF(Debts!$F$9="","",Debts!$F$9) | T4: =IF(Debts!$F$10="","",Debts!$F$10) | U4: =IF(Debts!$F$10="","",Debts!$F$10) | V4: =IF(Debts!$F$10="","",Debts!$F$10) | W4: =IF(Debts!$F$11="","",Debts!$F$11) | X4: =IF(Debts!$F$11="","",Debts!$F$11) | Y4: =IF(Debts!$F$11="","",Debts!$F$11) | Z4: =IF(Debts!$F$12="","",Debts!$F$12) | AA4: =IF(Debts!$F$12="","",Debts!$F$12) | AB4: =IF(Debts!$F$12="","",Debts!$F$12) | AC4: =IF(Debts!$F$13="","",Debts!$F$13) | AD4: =IF(Debts!$F$13="","",Debts!$F$13) | AE4: =IF(Debts!$F$13="","",Debts!$F$13) | AF4: =IF(Debts!$F$14="","",Debts!$F$14) | AG4: =IF(Debts!$F$14="","",Debts!$F$14) | AH4: =IF(Debts!$F$14="","",Debts!$F$14) | AI4: =IF(Debts!$F$15="","",Debts!$F$15) | AJ4: =IF(Debts!$F$15="","",Debts!$F$15) | AK4: =IF(Debts!$F$15="","",Debts!$F$15)
H5: Due | I5: Rem | J5: Bal | K5: Due | L5: Rem | M5: Bal | N5: Due | O5: Rem | P5: Bal | Q5: Due | R5: Rem | S5: Bal | T5: Due | U5: Rem | V5: Bal | W5: Due | X5: Rem | Y5: Bal | Z5: Due | AA5: Rem | AB5: Bal | AC5: Due | AD5: Rem | AE5: Bal | AF5: Due | AG5: Rem | AH5: Bal | AI5: Due | AJ5: Rem | AK5: Bal
B6: Month | C6: Date | D6: Paying | E6: Extra left | F6: Interest | G6: Total owed | H6: =IF(Debts!$B$6="","",Debts!$B$6&" · due") | I6: =IF(Debts!$B$6="","",Debts!$B$6&" · rem") | J6: =IF(Debts!$B$6="","",Debts!$B$6) | K6: =IF(Debts!$B$7="","",Debts!$B$7&" · due") | L6: =IF(Debts!$B$7="","",Debts!$B$7&" · rem") | M6: =IF(Debts!$B$7="","",Debts!$B$7) | N6: =IF(Debts!$B$8="","",Debts!$B$8&" · due") | O6: =IF(Debts!$B$8="","",Debts!$B$8&" · rem") | P6: =IF(Debts!$B$8="","",Debts!$B$8) | Q6: =IF(Debts!$B$9="","",Debts!$B$9&" · due") | R6: =IF(Debts!$B$9="","",Debts!$B$9&" · rem") | S6: =IF(Debts!$B$9="","",Debts!$B$9) | T6: =IF(Debts!$B$10="","",Debts!$B$10&" · due") | U6: =IF(Debts!$B$10="","",Debts!$B$10&" · rem") | V6: =IF(Debts!$B$10="","",Debts!$B$10) | W6: =IF(Debts!$B$11="","",Debts!$B$11&" · due") | X6: =IF(Debts!$B$11="","",Debts!$B$11&" · rem") | Y6: =IF(Debts!$B$11="","",Debts!$B$11) | Z6: =IF(Debts!$B$12="","",Debts!$B$12&" · due") | AA6: =IF(Debts!$B$12="","",Debts!$B$12&" · rem") | AB6: =IF(Debts!$B$12="","",Debts!$B$12) | AC6: =IF(Debts!$B$13="","",Debts!$B$13&" · due") | AD6: =IF(Debts!$B$13="","",Debts!$B$13&" · rem") | AE6: =IF(Debts!$B$13="","",Debts!$B$13) | AF6: =IF(Debts!$B$14="","",Debts!$B$14&" · due") | AG6: =IF(Debts!$B$14="","",Debts!$B$14&" · rem") | AH6: =IF(Debts!$B$14="","",Debts!$B$14) | AI6: =IF(Debts!$B$15="","",Debts!$B$15&" · due") | AJ6: =IF(Debts!$B$15="","",Debts!$B$15&" · rem") | AK6: =IF(Debts!$B$15="","",Debts!$B$15)
B7: 0 | G7: =SUMIF($H$5:$AK$5,"Bal",H7:AK7) | J7: =N(Debts!$C$6) | M7: =N(Debts!$C$7) | P7: =N(Debts!$C$8) | S7: =N(Debts!$C$9) | V7: =N(Debts!$C$10) | Y7: =N(Debts!$C$11) | AB7: =N(Debts!$C$12) | AE7: =N(Debts!$C$13) | AH7: =N(Debts!$C$14) | AK7: =N(Debts!$C$15)
B8: 1 | C8: =EDATE(Debts!$J$13,B8-1) | D8: =IF(G7<=0.005,0,Debts!$E$16+Debts!$J$7) | E8: =MAX(0,D8-(SUMIF($H$5:$AK$5,"Due",H8:AK8)-SUMIF($H$5:$AK$5,"Rem",H8:AK8))) | F8: =SUMIF($H$5:$AK$5,"Due",H8:AK8)-SUMIF($H$5:$AK$5,"Bal",H7:AK7) | G8: =SUMIF($H$5:$AK$5,"Bal",H8:AK8) | H8: =J7*(1+N(Debts!$D$6)/1200) | I8: =H8-MIN(N(Debts!$E$6),H8) | J8: =IF(I8<=0.005,0,I8-MIN(I8,MAX(0,$E8-SUMIFS(H8:AK8,$H$5:$AK$5,"Rem",$H$4:$AK$4,"<"&J$4)))) | K8: =M7*(1+N(Debts!$D$7)/1200) | L8: =K8-MIN(N(Debts!$E$7),K8) | M8: =IF(L8<=0.005,0,L8-MIN(L8,MAX(0,$E8-SUMIFS(H8:AK8,$H$5:$AK$5,"Rem",$H$4:$AK$4,"<"&M$4)))) | N8: =P7*(1+N(Debts!$D$8)/1200) | O8: =N8-MIN(N(Debts!$E$8),N8) | P8: =IF(O8<=0.005,0,O8-MIN(O8,MAX(0,$E8-SUMIFS(H8:AK8,$H$5:$AK$5,"Rem",$H$4:$AK$4,"<"&P$4)))) | Q8: =S7*(1+N(Debts!$D$9)/1200) | R8: =Q8-MIN(N(Debts!$E$9),Q8) | S8: =IF(R8<=0.005,0,R8-MIN(R8,MAX(0,$E8-SUMIFS(H8:AK8,$H$5:$AK$5,"Rem",$H$4:$AK$4,"<"&S$4)))) | T8: =V7*(1+N(Debts!$D$10)/1200) | U8: =T8-MIN(N(Debts!$E$10),T8) | V8: =IF(U8<=0.005,0,U8-MIN(U8,MAX(0,$E8-SUMIFS(H8:AK8,$H$5:$AK$5,"Rem",$H$4:$AK$4,"<"&V$4)))) | W8: =Y7*(1+N(Debts!$D$11)/1200) | X8: =W8-MIN(N(Debts!$E$11),W8) | Y8: =IF(X8<=0.005,0,X8-MIN(X8,MAX(0,$E8-SUMIFS(H8:AK8,$H$5:$AK$5,"Rem",$H$4:$AK$4,"<"&Y$4)))) | Z8: =AB7*(1+N(Debts!$D$12)/1200) | AA8: =Z8-MIN(N(Debts!$E$12),Z8) | AB8: =IF(AA8<=0.005,0,AA8-MIN(AA8,MAX(0,$E8-SUMIFS(H8:AK8,$H$5:$AK$5,"Rem",$H$4:$AK$4,"<"&AB$4)))) | AC8: =AE7*(1+N(Debts!$D$13)/1200) | AD8: =AC8-MIN(N(Debts!$E$13),AC8) | AE8: =IF(AD8<=0.005,0,AD8-MIN(AD8,MAX(0,$E8-SUMIFS(H8:AK8,$H$5:$AK$5,"Rem",$H$4:$AK$4,"<"&AE$4)))) | AF8: =AH7*(1+N(Debts!$D$14)/1200) | AG8: =AF8-MIN(N(Debts!$E$14),AF8) | AH8: =IF(AG8<=0.005,0,AG8-MIN(AG8,MAX(0,$E8-SUMIFS(H8:AK8,$H$5:$AK$5,"Rem",$H$4:$AK$4,"<"&AH$4)))) | AI8: =AK7*(1+N(Debts!$D$15)/1200) | AJ8: =AI8-MIN(N(Debts!$E$15),AI8) | AK8: =IF(AJ8<=0.005,0,AJ8-MIN(AJ8,MAX(0,$E8-SUMIFS(H8:AK8,$H$5:$AK$5,"Rem",$H$4:$AK$4,"<"&AK$4))))
B9: 2 | C9: =EDATE(Debts!$J$13,B9-1) | D9: =IF(G8<=0.005,0,Debts!$E$16+Debts!$J$7) | E9: =MAX(0,D9-(SUMIF($H$5:$AK$5,"Due",H9:AK9)-SUMIF($H$5:$AK$5,"Rem",H9:AK9))) | F9: =SUMIF($H$5:$AK$5,"Due",H9:AK9)-SUMIF($H$5:$AK$5,"Bal",H8:AK8) | G9: =SUMIF($H$5:$AK$5,"Bal",H9:AK9) | H9: =J8*(1+N(Debts!$D$6)/1200) | I9: =H9-MIN(N(Debts!$E$6),H9) | J9: =IF(I9<=0.005,0,I9-MIN(I9,MAX(0,$E9-SUMIFS(H9:AK9,$H$5:$AK$5,"Rem",$H$4:$AK$4,"<"&J$4)))) | K9: =M8*(1+N(Debts!$D$7)/1200) | L9: =K9-MIN(N(Debts!$E$7),K9) | M9: =IF(L9<=0.005,0,L9-MIN(L9,MAX(0,$E9-SUMIFS(H9:AK9,$H$5:$AK$5,"Rem",$H$4:$AK$4,"<"&M$4)))) | N9: =P8*(1+N(Debts!$D$8)/1200) | O9: =N9-MIN(N(Debts!$E$8),N9) | P9: =IF(O9<=0.005,0,O9-MIN(O9,MAX(0,$E9-SUMIFS(H9:AK9,$H$5:$AK$5,"Rem",$H$4:$AK$4,"<"&P$4)))) | Q9: =S8*(1+N(Debts!$D$9)/1200) | R9: =Q9-MIN(N(Debts!$E$9),Q9) | S9: =IF(R9<=0.005,0,R9-MIN(R9,MAX(0,$E9-SUMIFS(H9:AK9,$H$5:$AK$5,"Rem",$H$4:$AK$4,"<"&S$4)))) | T9: =V8*(1+N(Debts!$D$10)/1200) | U9: =T9-MIN(N(Debts!$E$10),T9) | V9: =IF(U9<=0.005,0,U9-MIN(U9,MAX(0,$E9-SUMIFS(H9:AK9,$H$5:$AK$5,"Rem",$H$4:$AK$4,"<"&V$4)))) | W9: =Y8*(1+N(Debts!$D$11)/1200) | X9: =W9-MIN(N(Debts!$E$11),W9) | Y9: =IF(X9<=0.005,0,X9-MIN(X9,MAX(0,$E9-SUMIFS(H9:AK9,$H$5:$AK$5,"Rem",$H$4:$AK$4,"<"&Y$4)))) | Z9: =AB8*(1+N(Debts!$D$12)/1200) | AA9: =Z9-MIN(N(Debts!$E$12),Z9) | AB9: =IF(AA9<=0.005,0,AA9-MIN(AA9,MAX(0,$E9-SUMIFS(H9:AK9,$H$5:$AK$5,"Rem",$H$4:$AK$4,"<"&AB$4)))) | AC9: =AE8*(1+N(Debts!$D$13)/1200) | AD9: =AC9-MIN(N(Debts!$E$13),AC9) | AE9: =IF(AD9<=0.005,0,AD9-MIN(AD9,MAX(0,$E9-SUMIFS(H9:AK9,$H$5:$AK$5,"Rem",$H$4:$AK$4,"<"&AE$4)))) | AF9: =AH8*(1+N(Debts!$D$14)/1200) | AG9: =AF9-MIN(N(Debts!$E$14),AF9) | AH9: =IF(AG9<=0.005,0,AG9-MIN(AG9,MAX(0,$E9-SUMIFS(H9:AK9,$H$5:$AK$5,"Rem",$H$4:$AK$4,"<"&AH$4)))) | AI9: =AK8*(1+N(Debts!$D$15)/1200) | AJ9: =AI9-MIN(N(Debts!$E$15),AI9) | AK9: =IF(AJ9<=0.005,0,AJ9-MIN(AJ9,MAX(0,$E9-SUMIFS(H9:AK9,$H$5:$AK$5,"Rem",$H$4:$AK$4,"<"&AK$4))))
B10: 3 | C10: =EDATE(Debts!$J$13,B10-1) | D10: =IF(G9<=0.005,0,Debts!$E$16+Debts!$J$7) | E10: =MAX(0,D10-(SUMIF($H$5:$AK$5,"Due",H10:AK10)-SUMIF($H$5:$AK$5,"Rem",H10:AK10))) | F10: =SUMIF($H$5:$AK$5,"Due",H10:AK10)-SUMIF($H$5:$AK$5,"Bal",H9:AK9) | G10: =SUMIF($H$5:$AK$5,"Bal",H10:AK10) | H10: =J9*(1+N(Debts!$D$6)/1200) | I10: =H10-MIN(N(Debts!$E$6),H10) | J10: =IF(I10<=0.005,0,I10-MIN(I10,MAX(0,$E10-SUMIFS(H10:AK10,$H$5:$AK$5,"Rem",$H$4:$AK$4,"<"&J$4)))) | K10: =M9*(1+N(Debts!$D$7)/1200) | L10: =K10-MIN(N(Debts!$E$7),K10) | M10: =IF(L10<=0.005,0,L10-MIN(L10,MAX(0,$E10-SUMIFS(H10:AK10,$H$5:$AK$5,"Rem",$H$4:$AK$4,"<"&M$4)))) | N10: =P9*(1+N(Debts!$D$8)/1200) | O10: =N10-MIN(N(Debts!$E$8),N10) | P10: =IF(O10<=0.005,0,O10-MIN(O10,MAX(0,$E10-SUMIFS(H10:AK10,$H$5:$AK$5,"Rem",$H$4:$AK$4,"<"&P$4)))) | Q10: =S9*(1+N(Debts!$D$9)/1200) | R10: =Q10-MIN(N(Debts!$E$9),Q10) | S10: =IF(R10<=0.005,0,R10-MIN(R10,MAX(0,$E10-SUMIFS(H10:AK10,$H$5:$AK$5,"Rem",$H$4:$AK$4,"<"&S$4)))) | T10: =V9*(1+N(Debts!$D$10)/1200) | U10: =T10-MIN(N(Debts!$E$10),T10) | V10: =IF(U10<=0.005,0,U10-MIN(U10,MAX(0,$E10-SUMIFS(H10:AK10,$H$5:$AK$5,"Rem",$H$4:$AK$4,"<"&V$4)))) | W10: =Y9*(1+N(Debts!$D$11)/1200) | X10: =W10-MIN(N(Debts!$E$11),W10) | Y10: =IF(X10<=0.005,0,X10-MIN(X10,MAX(0,$E10-SUMIFS(H10:AK10,$H$5:$AK$5,"Rem",$H$4:$AK$4,"<"&Y$4)))) | Z10: =AB9*(1+N(Debts!$D$12)/1200) | AA10: =Z10-MIN(N(Debts!$E$12),Z10) | AB10: =IF(AA10<=0.005,0,AA10-MIN(AA10,MAX(0,$E10-SUMIFS(H10:AK10,$H$5:$AK$5,"Rem",$H$4:$AK$4,"<"&AB$4)))) | AC10: =AE9*(1+N(Debts!$D$13)/1200) | AD10: =AC10-MIN(N(Debts!$E$13),AC10) | AE10: =IF(AD10<=0.005,0,AD10-MIN(AD10,MAX(0,$E10-SUMIFS(H10:AK10,$H$5:$AK$5,"Rem",$H$4:$AK$4,"<"&AE$4)))) | AF10: =AH9*(1+N(Debts!$D$14)/1200) | AG10: =AF10-MIN(N(Debts!$E$14),AF10) | AH10: =IF(AG10<=0.005,0,AG10-MIN(AG10,MAX(0,$E10-SUMIFS(H10:AK10,$H$5:$AK$5,"Rem",$H$4:$AK$4,"<"&AH$4)))) | AI10: =AK9*(1+N(Debts!$D$15)/1200) | AJ10: =AI10-MIN(N(Debts!$E$15),AI10) | AK10: =IF(AJ10<=0.005,0,AJ10-MIN(AJ10,MAX(0,$E10-SUMIFS(H10:AK10,$H$5:$AK$5,"Rem",$H$4:$AK$4,"<"&AK$4))))
B11: 4 | C11: =EDATE(Debts!$J$13,B11-1) | D11: =IF(G10<=0.005,0,Debts!$E$16+Debts!$J$7) | E11: =MAX(0,D11-(SUMIF($H$5:$AK$5,"Due",H11:AK11)-SUMIF($H$5:$AK$5,"Rem",H11:AK11))) | F11: =SUMIF($H$5:$AK$5,"Due",H11:AK11)-SUMIF($H$5:$AK$5,"Bal",H10:AK10) | G11: =SUMIF($H$5:$AK$5,"Bal",H11:AK11) | H11: =J10*(1+N(Debts!$D$6)/1200) | I11: =H11-MIN(N(Debts!$E$6),H11) | J11: =IF(I11<=0.005,0,I11-MIN(I11,MAX(0,$E11-SUMIFS(H11:AK11,$H$5:$AK$5,"Rem",$H$4:$AK$4,"<"&J$4)))) | K11: =M10*(1+N(Debts!$D$7)/1200) | L11: =K11-MIN(N(Debts!$E$7),K11) | M11: =IF(L11<=0.005,0,L11-MIN(L11,MAX(0,$E11-SUMIFS(H11:AK11,$H$5:$AK$5,"Rem",$H$4:$AK$4,"<"&M$4)))) | N11: =P10*(1+N(Debts!$D$8)/1200) | O11: =N11-MIN(N(Debts!$E$8),N11) | P11: =IF(O11<=0.005,0,O11-MIN(O11,MAX(0,$E11-SUMIFS(H11:AK11,$H$5:$AK$5,"Rem",$H$4:$AK$4,"<"&P$4)))) | Q11: =S10*(1+N(Debts!$D$9)/1200) | R11: =Q11-MIN(N(Debts!$E$9),Q11) | S11: =IF(R11<=0.005,0,R11-MIN(R11,MAX(0,$E11-SUMIFS(H11:AK11,$H$5:$AK$5,"Rem",$H$4:$AK$4,"<"&S$4)))) | T11: =V10*(1+N(Debts!$D$10)/1200) | U11: =T11-MIN(N(Debts!$E$10),T11) | V11: =IF(U11<=0.005,0,U11-MIN(U11,MAX(0,$E11-SUMIFS(H11:AK11,$H$5:$AK$5,"Rem",$H$4:$AK$4,"<"&V$4)))) | W11: =Y10*(1+N(Debts!$D$11)/1200) | X11: =W11-MIN(N(Debts!$E$11),W11) | Y11: =IF(X11<=0.005,0,X11-MIN(X11,MAX(0,$E11-SUMIFS(H11:AK11,$H$5:$AK$5,"Rem",$H$4:$AK$4,"<"&Y$4)))) | Z11: =AB10*(1+N(Debts!$D$12)/1200) | AA11: =Z11-MIN(N(Debts!$E$12),Z11) | AB11: =IF(AA11<=0.005,0,AA11-MIN(AA11,MAX(0,$E11-SUMIFS(H11:AK11,$H$5:$AK$5,"Rem",$H$4:$AK$4,"<"&AB$4)))) | AC11: =AE10*(1+N(Debts!$D$13)/1200) | AD11: =AC11-MIN(N(Debts!$E$13),AC11) | AE11: =IF(AD11<=0.005,0,AD11-MIN(AD11,MAX(0,$E11-SUMIFS(H11:AK11,$H$5:$AK$5,"Rem",$H$4:$AK$4,"<"&AE$4)))) | AF11: =AH10*(1+N(Debts!$D$14)/1200) | AG11: =AF11-MIN(N(Debts!$E$14),AF11) | AH11: =IF(AG11<=0.005,0,AG11-MIN(AG11,MAX(0,$E11-SUMIFS(H11:AK11,$H$5:$AK$5,"Rem",$H$4:$AK$4,"<"&AH$4)))) | AI11: =AK10*(1+N(Debts!$D$15)/1200) | AJ11: =AI11-MIN(N(Debts!$E$15),AI11) | AK11: =IF(AJ11<=0.005,0,AJ11-MIN(AJ11,MAX(0,$E11-SUMIFS(H11:AK11,$H$5:$AK$5,"Rem",$H$4:$AK$4,"<"&AK$4))))
B12: 5 | C12: =EDATE(Debts!$J$13,B12-1) | D12: =IF(G11<=0.005,0,Debts!$E$16+Debts!$J$7) | E12: =MAX(0,D12-(SUMIF($H$5:$AK$5,"Due",H12:AK12)-SUMIF($H$5:$AK$5,"Rem",H12:AK12))) | F12: =SUMIF($H$5:$AK$5,"Due",H12:AK12)-SUMIF($H$5:$AK$5,"Bal",H11:AK11) | G12: =SUMIF($H$5:$AK$5,"Bal",H12:AK12) | H12: =J11*(1+N(Debts!$D$6)/1200) | I12: =H12-MIN(N(Debts!$E$6),H12) | J12: =IF(I12<=0.005,0,I12-MIN(I12,MAX(0,$E12-SUMIFS(H12:AK12,$H$5:$AK$5,"Rem",$H$4:$AK$4,"<"&J$4)))) | K12: =M11*(1+N(Debts!$D$7)/1200) | L12: =K12-MIN(N(Debts!$E$7),K12) | M12: =IF(L12<=0.005,0,L12-MIN(L12,MAX(0,$E12-SUMIFS(H12:AK12,$H$5:$AK$5,"Rem",$H$4:$AK$4,"<"&M$4)))) | N12: =P11*(1+N(Debts!$D$8)/1200) | O12: =N12-MIN(N(Debts!$E$8),N12) | P12: =IF(O12<=0.005,0,O12-MIN(O12,MAX(0,$E12-SUMIFS(H12:AK12,$H$5:$AK$5,"Rem",$H$4:$AK$4,"<"&P$4)))) | Q12: =S11*(1+N(Debts!$D$9)/1200) | R12: =Q12-MIN(N(Debts!$E$9),Q12) | S12: =IF(R12<=0.005,0,R12-MIN(R12,MAX(0,$E12-SUMIFS(H12:AK12,$H$5:$AK$5,"Rem",$H$4:$AK$4,"<"&S$4)))) | T12: =V11*(1+N(Debts!$D$10)/1200) | U12: =T12-MIN(N(Debts!$E$10),T12) | V12: =IF(U12<=0.005,0,U12-MIN(U12,MAX(0,$E12-SUMIFS(H12:AK12,$H$5:$AK$5,"Rem",$H$4:$AK$4,"<"&V$4)))) | W12: =Y11*(1+N(Debts!$D$11)/1200) | X12: =W12-MIN(N(Debts!$E$11),W12) | Y12: =IF(X12<=0.005,0,X12-MIN(X12,MAX(0,$E12-SUMIFS(H12:AK12,$H$5:$AK$5,"Rem",$H$4:$AK$4,"<"&Y$4)))) | Z12: =AB11*(1+N(Debts!$D$12)/1200) | AA12: =Z12-MIN(N(Debts!$E$12),Z12) | AB12: =IF(AA12<=0.005,0,AA12-MIN(AA12,MAX(0,$E12-SUMIFS(H12:AK12,$H$5:$AK$5,"Rem",$H$4:$AK$4,"<"&AB$4)))) | AC12: =AE11*(1+N(Debts!$D$13)/1200) | AD12: =AC12-MIN(N(Debts!$E$13),AC12) | AE12: =IF(AD12<=0.005,0,AD12-MIN(AD12,MAX(0,$E12-SUMIFS(H12:AK12,$H$5:$AK$5,"Rem",$H$4:$AK$4,"<"&AE$4)))) | AF12: =AH11*(1+N(Debts!$D$14)/1200) | AG12: =AF12-MIN(N(Debts!$E$14),AF12) | AH12: =IF(AG12<=0.005,0,AG12-MIN(AG12,MAX(0,$E12-SUMIFS(H12:AK12,$H$5:$AK$5,"Rem",$H$4:$AK$4,"<"&AH$4)))) | AI12: =AK11*(1+N(Debts!$D$15)/1200) | AJ12: =AI12-MIN(N(Debts!$E$15),AI12) | AK12: =IF(AJ12<=0.005,0,AJ12-MIN(AJ12,MAX(0,$E12-SUMIFS(H12:AK12,$H$5:$AK$5,"Rem",$H$4:$AK$4,"<"&AK$4))))
B13: 6 | C13: =EDATE(Debts!$J$13,B13-1) | D13: =IF(G12<=0.005,0,Debts!$E$16+Debts!$J$7) | E13: =MAX(0,D13-(SUMIF($H$5:$AK$5,"Due",H13:AK13)-SUMIF($H$5:$AK$5,"Rem",H13:AK13))) | F13: =SUMIF($H$5:$AK$5,"Due",H13:AK13)-SUMIF($H$5:$AK$5,"Bal",H12:AK12) | G13: =SUMIF($H$5:$AK$5,"Bal",H13:AK13) | H13: =J12*(1+N(Debts!$D$6)/1200) | I13: =H13-MIN(N(Debts!$E$6),H13) | J13: =IF(I13<=0.005,0,I13-MIN(I13,MAX(0,$E13-SUMIFS(H13:AK13,$H$5:$AK$5,"Rem",$H$4:$AK$4,"<"&J$4)))) | K13: =M12*(1+N(Debts!$D$7)/1200) | L13: =K13-MIN(N(Debts!$E$7),K13) | M13: =IF(L13<=0.005,0,L13-MIN(L13,MAX(0,$E13-SUMIFS(H13:AK13,$H$5:$AK$5,"Rem",$H$4:$AK$4,"<"&M$4)))) | N13: =P12*(1+N(Debts!$D$8)/1200) | O13: =N13-MIN(N(Debts!$E$8),N13) | P13: =IF(O13<=0.005,0,O13-MIN(O13,MAX(0,$E13-SUMIFS(H13:AK13,$H$5:$AK$5,"Rem",$H$4:$AK$4,"<"&P$4)))) | Q13: =S12*(1+N(Debts!$D$9)/1200) | R13: =Q13-MIN(N(Debts!$E$9),Q13) | S13: =IF(R13<=0.005,0,R13-MIN(R13,MAX(0,$E13-SUMIFS(H13:AK13,$H$5:$AK$5,"Rem",$H$4:$AK$4,"<"&S$4)))) | T13: =V12*(1+N(Debts!$D$10)/1200) | U13: =T13-MIN(N(Debts!$E$10),T13) | V13: =IF(U13<=0.005,0,U13-MIN(U13,MAX(0,$E13-SUMIFS(H13:AK13,$H$5:$AK$5,"Rem",$H$4:$AK$4,"<"&V$4)))) | W13: =Y12*(1+N(Debts!$D$11)/1200) | X13: =W13-MIN(N(Debts!$E$11),W13) | Y13: =IF(X13<=0.005,0,X13-MIN(X13,MAX(0,$E13-SUMIFS(H13:AK13,$H$5:$AK$5,"Rem",$H$4:$AK$4,"<"&Y$4)))) | Z13: =AB12*(1+N(Debts!$D$12)/1200) | AA13: =Z13-MIN(N(Debts!$E$12),Z13) | AB13: =IF(AA13<=0.005,0,AA13-MIN(AA13,MAX(0,$E13-SUMIFS(H13:AK13,$H$5:$AK$5,"Rem",$H$4:$AK$4,"<"&AB$4)))) | AC13: =AE12*(1+N(Debts!$D$13)/1200) | AD13: =AC13-MIN(N(Debts!$E$13),AC13) | AE13: =IF(AD13<=0.005,0,AD13-MIN(AD13,MAX(0,$E13-SUMIFS(H13:AK13,$H$5:$AK$5,"Rem",$H$4:$AK$4,"<"&AE$4)))) | AF13: =AH12*(1+N(Debts!$D$14)/1200) | AG13: =AF13-MIN(N(Debts!$E$14),AF13) | AH13: =IF(AG13<=0.005,0,AG13-MIN(AG13,MAX(0,$E13-SUMIFS(H13:AK13,$H$5:$AK$5,"Rem",$H$4:$AK$4,"<"&AH$4)))) | AI13: =AK12*(1+N(Debts!$D$15)/1200) | AJ13: =AI13-MIN(N(Debts!$E$15),AI13) | AK13: =IF(AJ13<=0.005,0,AJ13-MIN(AJ13,MAX(0,$E13-SUMIFS(H13:AK13,$H$5:$AK$5,"Rem",$H$4:$AK$4,"<"&AK$4))))
B14: 7 | C14: =EDATE(Debts!$J$13,B14-1) | D14: =IF(G13<=0.005,0,Debts!$E$16+Debts!$J$7) | E14: =MAX(0,D14-(SUMIF($H$5:$AK$5,"Due",H14:AK14)-SUMIF($H$5:$AK$5,"Rem",H14:AK14))) | F14: =SUMIF($H$5:$AK$5,"Due",H14:AK14)-SUMIF($H$5:$AK$5,"Bal",H13:AK13) | G14: =SUMIF($H$5:$AK$5,"Bal",H14:AK14) | H14: =J13*(1+N(Debts!$D$6)/1200) | I14: =H14-MIN(N(Debts!$E$6),H14) | J14: =IF(I14<=0.005,0,I14-MIN(I14,MAX(0,$E14-SUMIFS(H14:AK14,$H$5:$AK$5,"Rem",$H$4:$AK$4,"<"&J$4)))) | K14: =M13*(1+N(Debts!$D$7)/1200) | L14: =K14-MIN(N(Debts!$E$7),K14) | M14: =IF(L14<=0.005,0,L14-MIN(L14,MAX(0,$E14-SUMIFS(H14:AK14,$H$5:$AK$5,"Rem",$H$4:$AK$4,"<"&M$4)))) | N14: =P13*(1+N(Debts!$D$8)/1200) | O14: =N14-MIN(N(Debts!$E$8),N14) | P14: =IF(O14<=0.005,0,O14-MIN(O14,MAX(0,$E14-SUMIFS(H14:AK14,$H$5:$AK$5,"Rem",$H$4:$AK$4,"<"&P$4)))) | Q14: =S13*(1+N(Debts!$D$9)/1200) | R14: =Q14-MIN(N(Debts!$E$9),Q14) | S14: =IF(R14<=0.005,0,R14-MIN(R14,MAX(0,$E14-SUMIFS(H14:AK14,$H$5:$AK$5,"Rem",$H$4:$AK$4,"<"&S$4)))) | T14: =V13*(1+N(Debts!$D$10)/1200) | U14: =T14-MIN(N(Debts!$E$10),T14) | V14: =IF(U14<=0.005,0,U14-MIN(U14,MAX(0,$E14-SUMIFS(H14:AK14,$H$5:$AK$5,"Rem",$H$4:$AK$4,"<"&V$4)))) | W14: =Y13*(1+N(Debts!$D$11)/1200) | X14: =W14-MIN(N(Debts!$E$11),W14) | Y14: =IF(X14<=0.005,0,X14-MIN(X14,MAX(0,$E14-SUMIFS(H14:AK14,$H$5:$AK$5,"Rem",$H$4:$AK$4,"<"&Y$4)))) | Z14: =AB13*(1+N(Debts!$D$12)/1200) | AA14: =Z14-MIN(N(Debts!$E$12),Z14) | AB14: =IF(AA14<=0.005,0,AA14-MIN(AA14,MAX(0,$E14-SUMIFS(H14:AK14,$H$5:$AK$5,"Rem",$H$4:$AK$4,"<"&AB$4)))) | AC14: =AE13*(1+N(Debts!$D$13)/1200) | AD14: =AC14-MIN(N(Debts!$E$13),AC14) | AE14: =IF(AD14<=0.005,0,AD14-MIN(AD14,MAX(0,$E14-SUMIFS(H14:AK14,$H$5:$AK$5,"Rem",$H$4:$AK$4,"<"&AE$4)))) | AF14: =AH13*(1+N(Debts!$D$14)/1200) | AG14: =AF14-MIN(N(Debts!$E$14),AF14) | AH14: =IF(AG14<=0.005,0,AG14-MIN(AG14,MAX(0,$E14-SUMIFS(H14:AK14,$H$5:$AK$5,"Rem",$H$4:$AK$4,"<"&AH$4)))) | AI14: =AK13*(1+N(Debts!$D$15)/1200) | AJ14: =AI14-MIN(N(Debts!$E$15),AI14) | AK14: =IF(AJ14<=0.005,0,AJ14-MIN(AJ14,MAX(0,$E14-SUMIFS(H14:AK14,$H$5:$AK$5,"Rem",$H$4:$AK$4,"<"&AK$4))))
B15: 8 | C15: =EDATE(Debts!$J$13,B15-1) | D15: =IF(G14<=0.005,0,Debts!$E$16+Debts!$J$7) | E15: =MAX(0,D15-(SUMIF($H$5:$AK$5,"Due",H15:AK15)-SUMIF($H$5:$AK$5,"Rem",H15:AK15))) | F15: =SUMIF($H$5:$AK$5,"Due",H15:AK15)-SUMIF($H$5:$AK$5,"Bal",H14:AK14) | G15: =SUMIF($H$5:$AK$5,"Bal",H15:AK15) | H15: =J14*(1+N(Debts!$D$6)/1200) | I15: =H15-MIN(N(Debts!$E$6),H15) | J15: =IF(I15<=0.005,0,I15-MIN(I15,MAX(0,$E15-SUMIFS(H15:AK15,$H$5:$AK$5,"Rem",$H$4:$AK$4,"<"&J$4)))) | K15: =M14*(1+N(Debts!$D$7)/1200) | L15: =K15-MIN(N(Debts!$E$7),K15) | M15: =IF(L15<=0.005,0,L15-MIN(L15,MAX(0,$E15-SUMIFS(H15:AK15,$H$5:$AK$5,"Rem",$H$4:$AK$4,"<"&M$4)))) | N15: =P14*(1+N(Debts!$D$8)/1200) | O15: =N15-MIN(N(Debts!$E$8),N15) | P15: =IF(O15<=0.005,0,O15-MIN(O15,MAX(0,$E15-SUMIFS(H15:AK15,$H$5:$AK$5,"Rem",$H$4:$AK$4,"<"&P$4)))) | Q15: =S14*(1+N(Debts!$D$9)/1200) | R15: =Q15-MIN(N(Debts!$E$9),Q15) | S15: =IF(R15<=0.005,0,R15-MIN(R15,MAX(0,$E15-SUMIFS(H15:AK15,$H$5:$AK$5,"Rem",$H$4:$AK$4,"<"&S$4)))) | T15: =V14*(1+N(Debts!$D$10)/1200) | U15: =T15-MIN(N(Debts!$E$10),T15) | V15: =IF(U15<=0.005,0,U15-MIN(U15,MAX(0,$E15-SUMIFS(H15:AK15,$H$5:$AK$5,"Rem",$H$4:$AK$4,"<"&V$4)))) | W15: =Y14*(1+N(Debts!$D$11)/1200) | X15: =W15-MIN(N(Debts!$E$11),W15) | Y15: =IF(X15<=0.005,0,X15-MIN(X15,MAX(0,$E15-SUMIFS(H15:AK15,$H$5:$AK$5,"Rem",$H$4:$AK$4,"<"&Y$4)))) | Z15: =AB14*(1+N(Debts!$D$12)/1200) | AA15: =Z15-MIN(N(Debts!$E$12),Z15) | AB15: =IF(AA15<=0.005,0,AA15-MIN(AA15,MAX(0,$E15-SUMIFS(H15:AK15,$H$5:$AK$5,"Rem",$H$4:$AK$4,"<"&AB$4)))) | AC15: =AE14*(1+N(Debts!$D$13)/1200) | AD15: =AC15-MIN(N(Debts!$E$13),AC15) | AE15: =IF(AD15<=0.005,0,AD15-MIN(AD15,MAX(0,$E15-SUMIFS(H15:AK15,$H$5:$AK$5,"Rem",$H$4:$AK$4,"<"&AE$4)))) | AF15: =AH14*(1+N(Debts!$D$14)/1200) | AG15: =AF15-MIN(N(Debts!$E$14),AF15) | AH15: =IF(AG15<=0.005,0,AG15-MIN(AG15,MAX(0,$E15-SUMIFS(H15:AK15,$H$5:$AK$5,"Rem",$H$4:$AK$4,"<"&AH$4)))) | AI15: =AK14*(1+N(Debts!$D$15)/1200) | AJ15: =AI15-MIN(N(Debts!$E$15),AI15) | AK15: =IF(AJ15<=0.005,0,AJ15-MIN(AJ15,MAX(0,$E15-SUMIFS(H15:AK15,$H$5:$AK$5,"Rem",$H$4:$AK$4,"<"&AK$4))))
B16: 9 | C16: =EDATE(Debts!$J$13,B16-1) | D16: =IF(G15<=0.005,0,Debts!$E$16+Debts!$J$7) | E16: =MAX(0,D16-(SUMIF($H$5:$AK$5,"Due",H16:AK16)-SUMIF($H$5:$AK$5,"Rem",H16:AK16))) | F16: =SUMIF($H$5:$AK$5,"Due",H16:AK16)-SUMIF($H$5:$AK$5,"Bal",H15:AK15) | G16: =SUMIF($H$5:$AK$5,"Bal",H16:AK16) | H16: =J15*(1+N(Debts!$D$6)/1200) | I16: =H16-MIN(N(Debts!$E$6),H16) | J16: =IF(I16<=0.005,0,I16-MIN(I16,MAX(0,$E16-SUMIFS(H16:AK16,$H$5:$AK$5,"Rem",$H$4:$AK$4,"<"&J$4)))) | K16: =M15*(1+N(Debts!$D$7)/1200) | L16: =K16-MIN(N(Debts!$E$7),K16) | M16: =IF(L16<=0.005,0,L16-MIN(L16,MAX(0,$E16-SUMIFS(H16:AK16,$H$5:$AK$5,"Rem",$H$4:$AK$4,"<"&M$4)))) | N16: =P15*(1+N(Debts!$D$8)/1200) | O16: =N16-MIN(N(Debts!$E$8),N16) | P16: =IF(O16<=0.005,0,O16-MIN(O16,MAX(0,$E16-SUMIFS(H16:AK16,$H$5:$AK$5,"Rem",$H$4:$AK$4,"<"&P$4)))) | Q16: =S15*(1+N(Debts!$D$9)/1200) | R16: =Q16-MIN(N(Debts!$E$9),Q16) | S16: =IF(R16<=0.005,0,R16-MIN(R16,MAX(0,$E16-SUMIFS(H16:AK16,$H$5:$AK$5,"Rem",$H$4:$AK$4,"<"&S$4)))) | T16: =V15*(1+N(Debts!$D$10)/1200) | U16: =T16-MIN(N(Debts!$E$10),T16) | V16: =IF(U16<=0.005,0,U16-MIN(U16,MAX(0,$E16-SUMIFS(H16:AK16,$H$5:$AK$5,"Rem",$H$4:$AK$4,"<"&V$4)))) | W16: =Y15*(1+N(Debts!$D$11)/1200) | X16: =W16-MIN(N(Debts!$E$11),W16) | Y16: =IF(X16<=0.005,0,X16-MIN(X16,MAX(0,$E16-SUMIFS(H16:AK16,$H$5:$AK$5,"Rem",$H$4:$AK$4,"<"&Y$4)))) | Z16: =AB15*(1+N(Debts!$D$12)/1200) | AA16: =Z16-MIN(N(Debts!$E$12),Z16) | AB16: =IF(AA16<=0.005,0,AA16-MIN(AA16,MAX(0,$E16-SUMIFS(H16:AK16,$H$5:$AK$5,"Rem",$H$4:$AK$4,"<"&AB$4)))) | AC16: =AE15*(1+N(Debts!$D$13)/1200) | AD16: =AC16-MIN(N(Debts!$E$13),AC16) | AE16: =IF(AD16<=0.005,0,AD16-MIN(AD16,MAX(0,$E16-SUMIFS(H16:AK16,$H$5:$AK$5,"Rem",$H$4:$AK$4,"<"&AE$4)))) | AF16: =AH15*(1+N(Debts!$D$14)/1200) | AG16: =AF16-MIN(N(Debts!$E$14),AF16) | AH16: =IF(AG16<=0.005,0,AG16-MIN(AG16,MAX(0,$E16-SUMIFS(H16:AK16,$H$5:$AK$5,"Rem",$H$4:$AK$4,"<"&AH$4)))) | AI16: =AK15*(1+N(Debts!$D$15)/1200) | AJ16: =AI16-MIN(N(Debts!$E$15),AI16) | AK16: =IF(AJ16<=0.005,0,AJ16-MIN(AJ16,MAX(0,$E16-SUMIFS(H16:AK16,$H$5:$AK$5,"Rem",$H$4:$AK$4,"<"&AK$4))))
B17: 10 | C17: =EDATE(Debts!$J$13,B17-1) | D17: =IF(G16<=0.005,0,Debts!$E$16+Debts!$J$7) | E17: =MAX(0,D17-(SUMIF($H$5:$AK$5,"Due",H17:AK17)-SUMIF($H$5:$AK$5,"Rem",H17:AK17))) | F17: =SUMIF($H$5:$AK$5,"Due",H17:AK17)-SUMIF($H$5:$AK$5,"Bal",H16:AK16) | G17: =SUMIF($H$5:$AK$5,"Bal",H17:AK17) | H17: =J16*(1+N(Debts!$D$6)/1200) | I17: =H17-MIN(N(Debts!$E$6),H17) | J17: =IF(I17<=0.005,0,I17-MIN(I17,MAX(0,$E17-SUMIFS(H17:AK17,$H$5:$AK$5,"Rem",$H$4:$AK$4,"<"&J$4)))) | K17: =M16*(1+N(Debts!$D$7)/1200) | L17: =K17-MIN(N(Debts!$E$7),K17) | M17: =IF(L17<=0.005,0,L17-MIN(L17,MAX(0,$E17-SUMIFS(H17:AK17,$H$5:$AK$5,"Rem",$H$4:$AK$4,"<"&M$4)))) | N17: =P16*(1+N(Debts!$D$8)/1200) | O17: =N17-MIN(N(Debts!$E$8),N17) | P17: =IF(O17<=0.005,0,O17-MIN(O17,MAX(0,$E17-SUMIFS(H17:AK17,$H$5:$AK$5,"Rem",$H$4:$AK$4,"<"&P$4)))) | Q17: =S16*(1+N(Debts!$D$9)/1200) | R17: =Q17-MIN(N(Debts!$E$9),Q17) | S17: =IF(R17<=0.005,0,R17-MIN(R17,MAX(0,$E17-SUMIFS(H17:AK17,$H$5:$AK$5,"Rem",$H$4:$AK$4,"<"&S$4)))) | T17: =V16*(1+N(Debts!$D$10)/1200) | U17: =T17-MIN(N(Debts!$E$10),T17) | V17: =IF(U17<=0.005,0,U17-MIN(U17,MAX(0,$E17-SUMIFS(H17:AK17,$H$5:$AK$5,"Rem",$H$4:$AK$4,"<"&V$4)))) | W17: =Y16*(1+N(Debts!$D$11)/1200) | X17: =W17-MIN(N(Debts!$E$11),W17) | Y17: =IF(X17<=0.005,0,X17-MIN(X17,MAX(0,$E17-SUMIFS(H17:AK17,$H$5:$AK$5,"Rem",$H$4:$AK$4,"<"&Y$4)))) | Z17: =AB16*(1+N(Debts!$D$12)/1200) | AA17: =Z17-MIN(N(Debts!$E$12),Z17) | AB17: =IF(AA17<=0.005,0,AA17-MIN(AA17,MAX(0,$E17-SUMIFS(H17:AK17,$H$5:$AK$5,"Rem",$H$4:$AK$4,"<"&AB$4)))) | AC17: =AE16*(1+N(Debts!$D$13)/1200) | AD17: =AC17-MIN(N(Debts!$E$13),AC17) | AE17: =IF(AD17<=0.005,0,AD17-MIN(AD17,MAX(0,$E17-SUMIFS(H17:AK17,$H$5:$AK$5,"Rem",$H$4:$AK$4,"<"&AE$4)))) | AF17: =AH16*(1+N(Debts!$D$14)/1200) | AG17: =AF17-MIN(N(Debts!$E$14),AF17) | AH17: =IF(AG17<=0.005,0,AG17-MIN(AG17,MAX(0,$E17-SUMIFS(H17:AK17,$H$5:$AK$5,"Rem",$H$4:$AK$4,"<"&AH$4)))) | AI17: =AK16*(1+N(Debts!$D$15)/1200) | AJ17: =AI17-MIN(N(Debts!$E$15),AI17) | AK17: =IF(AJ17<=0.005,0,AJ17-MIN(AJ17,MAX(0,$E17-SUMIFS(H17:AK17,$H$5:$AK$5,"Rem",$H$4:$AK$4,"<"&AK$4))))
B18: 11 | C18: =EDATE(Debts!$J$13,B18-1) | D18: =IF(G17<=0.005,0,Debts!$E$16+Debts!$J$7) | E18: =MAX(0,D18-(SUMIF($H$5:$AK$5,"Due",H18:AK18)-SUMIF($H$5:$AK$5,"Rem",H18:AK18))) | F18: =SUMIF($H$5:$AK$5,"Due",H18:AK18)-SUMIF($H$5:$AK$5,"Bal",H17:AK17) | G18: =SUMIF($H$5:$AK$5,"Bal",H18:AK18) | H18: =J17*(1+N(Debts!$D$6)/1200) | I18: =H18-MIN(N(Debts!$E$6),H18) | J18: =IF(I18<=0.005,0,I18-MIN(I18,MAX(0,$E18-SUMIFS(H18:AK18,$H$5:$AK$5,"Rem",$H$4:$AK$4,"<"&J$4)))) | K18: =M17*(1+N(Debts!$D$7)/1200) | L18: =K18-MIN(N(Debts!$E$7),K18) | M18: =IF(L18<=0.005,0,L18-MIN(L18,MAX(0,$E18-SUMIFS(H18:AK18,$H$5:$AK$5,"Rem",$H$4:$AK$4,"<"&M$4)))) | N18: =P17*(1+N(Debts!$D$8)/1200) | O18: =N18-MIN(N(Debts!$E$8),N18) | P18: =IF(O18<=0.005,0,O18-MIN(O18,MAX(0,$E18-SUMIFS(H18:AK18,$H$5:$AK$5,"Rem",$H$4:$AK$4,"<"&P$4)))) | Q18: =S17*(1+N(Debts!$D$9)/1200) | R18: =Q18-MIN(N(Debts!$E$9),Q18) | S18: =IF(R18<=0.005,0,R18-MIN(R18,MAX(0,$E18-SUMIFS(H18:AK18,$H$5:$AK$5,"Rem",$H$4:$AK$4,"<"&S$4)))) | T18: =V17*(1+N(Debts!$D$10)/1200) | U18: =T18-MIN(N(Debts!$E$10),T18) | V18: =IF(U18<=0.005,0,U18-MIN(U18,MAX(0,$E18-SUMIFS(H18:AK18,$H$5:$AK$5,"Rem",$H$4:$AK$4,"<"&V$4)))) | W18: =Y17*(1+N(Debts!$D$11)/1200) | X18: =W18-MIN(N(Debts!$E$11),W18) | Y18: =IF(X18<=0.005,0,X18-MIN(X18,MAX(0,$E18-SUMIFS(H18:AK18,$H$5:$AK$5,"Rem",$H$4:$AK$4,"<"&Y$4)))) | Z18: =AB17*(1+N(Debts!$D$12)/1200) | AA18: =Z18-MIN(N(Debts!$E$12),Z18) | AB18: =IF(AA18<=0.005,0,AA18-MIN(AA18,MAX(0,$E18-SUMIFS(H18:AK18,$H$5:$AK$5,"Rem",$H$4:$AK$4,"<"&AB$4)))) | AC18: =AE17*(1+N(Debts!$D$13)/1200) | AD18: =AC18-MIN(N(Debts!$E$13),AC18) | AE18: =IF(AD18<=0.005,0,AD18-MIN(AD18,MAX(0,$E18-SUMIFS(H18:AK18,$H$5:$AK$5,"Rem",$H$4:$AK$4,"<"&AE$4)))) | AF18: =AH17*(1+N(Debts!$D$14)/1200) | AG18: =AF18-MIN(N(Debts!$E$14),AF18) | AH18: =IF(AG18<=0.005,0,AG18-MIN(AG18,MAX(0,$E18-SUMIFS(H18:AK18,$H$5:$AK$5,"Rem",$H$4:$AK$4,"<"&AH$4)))) | AI18: =AK17*(1+N(Debts!$D$15)/1200) | AJ18: =AI18-MIN(N(Debts!$E$15),AI18) | AK18: =IF(AJ18<=0.005,0,AJ18-MIN(AJ18,MAX(0,$E18-SUMIFS(H18:AK18,$H$5:$AK$5,"Rem",$H$4:$AK$4,"<"&AK$4))))
B19: 12 | C19: =EDATE(Debts!$J$13,B19-1) | D19: =IF(G18<=0.005,0,Debts!$E$16+Debts!$J$7) | E19: =MAX(0,D19-(SUMIF($H$5:$AK$5,"Due",H19:AK19)-SUMIF($H$5:$AK$5,"Rem",H19:AK19))) | F19: =SUMIF($H$5:$AK$5,"Due",H19:AK19)-SUMIF($H$5:$AK$5,"Bal",H18:AK18) | G19: =SUMIF($H$5:$AK$5,"Bal",H19:AK19) | H19: =J18*(1+N(Debts!$D$6)/1200) | I19: =H19-MIN(N(Debts!$E$6),H19) | J19: =IF(I19<=0.005,0,I19-MIN(I19,MAX(0,$E19-SUMIFS(H19:AK19,$H$5:$AK$5,"Rem",$H$4:$AK$4,"<"&J$4)))) | K19: =M18*(1+N(Debts!$D$7)/1200) | L19: =K19-MIN(N(Debts!$E$7),K19) | M19: =IF(L19<=0.005,0,L19-MIN(L19,MAX(0,$E19-SUMIFS(H19:AK19,$H$5:$AK$5,"Rem",$H$4:$AK$4,"<"&M$4)))) | N19: =P18*(1+N(Debts!$D$8)/1200) | O19: =N19-MIN(N(Debts!$E$8),N19) | P19: =IF(O19<=0.005,0,O19-MIN(O19,MAX(0,$E19-SUMIFS(H19:AK19,$H$5:$AK$5,"Rem",$H$4:$AK$4,"<"&P$4)))) | Q19: =S18*(1+N(Debts!$D$9)/1200) | R19: =Q19-MIN(N(Debts!$E$9),Q19) | S19: =IF(R19<=0.005,0,R19-MIN(R19,MAX(0,$E19-SUMIFS(H19:AK19,$H$5:$AK$5,"Rem",$H$4:$AK$4,"<"&S$4)))) | T19: =V18*(1+N(Debts!$D$10)/1200) | U19: =T19-MIN(N(Debts!$E$10),T19) | V19: =IF(U19<=0.005,0,U19-MIN(U19,MAX(0,$E19-SUMIFS(H19:AK19,$H$5:$AK$5,"Rem",$H$4:$AK$4,"<"&V$4)))) | W19: =Y18*(1+N(Debts!$D$11)/1200) | X19: =W19-MIN(N(Debts!$E$11),W19) | Y19: =IF(X19<=0.005,0,X19-MIN(X19,MAX(0,$E19-SUMIFS(H19:AK19,$H$5:$AK$5,"Rem",$H$4:$AK$4,"<"&Y$4)))) | Z19: =AB18*(1+N(Debts!$D$12)/1200) | AA19: =Z19-MIN(N(Debts!$E$12),Z19) | AB19: =IF(AA19<=0.005,0,AA19-MIN(AA19,MAX(0,$E19-SUMIFS(H19:AK19,$H$5:$AK$5,"Rem",$H$4:$AK$4,"<"&AB$4)))) | AC19: =AE18*(1+N(Debts!$D$13)/1200) | AD19: =AC19-MIN(N(Debts!$E$13),AC19) | AE19: =IF(AD19<=0.005,0,AD19-MIN(AD19,MAX(0,$E19-SUMIFS(H19:AK19,$H$5:$AK$5,"Rem",$H$4:$AK$4,"<"&AE$4)))) | AF19: =AH18*(1+N(Debts!$D$14)/1200) | AG19: =AF19-MIN(N(Debts!$E$14),AF19) | AH19: =IF(AG19<=0.005,0,AG19-MIN(AG19,MAX(0,$E19-SUMIFS(H19:AK19,$H$5:$AK$5,"Rem",$H$4:$AK$4,"<"&AH$4)))) | AI19: =AK18*(1+N(Debts!$D$15)/1200) | AJ19: =AI19-MIN(N(Debts!$E$15),AI19) | AK19: =IF(AJ19<=0.005,0,AJ19-MIN(AJ19,MAX(0,$E19-SUMIFS(H19:AK19,$H$5:$AK$5,"Rem",$H$4:$AK$4,"<"&AK$4))))
... B187: 180 | C187: =EDATE(Debts!$J$13,B187-1) | D187: =IF(G186<=0.005,0,Debts!$E$16+Debts!$J$7) | E187: =MAX(0,D187-(SUMIF($H$5:$AK$5,"Due",H187:AK187)-SUMIF($H$5:$AK$5,"Rem",H187:AK187))) | F187: =SUMIF($H$5:$AK$5,"Due",H187:AK187)-SUMIF($H$5:$AK$5,"Bal",H186:AK186) | G187: =SUMIF($H$5:$AK$5,"Bal",H187:AK187) | H187: =J186*(1+N(Debts!$D$6)/1200) | I187: =H187-MIN(N(Debts!$E$6),H187) | J187: =IF(I187<=0.005,0,I187-MIN(I187,MAX(0,$E187-SUMIFS(H187:AK187,$H$5:$AK$5,"Rem",$H$4:$AK$4,"<"&J$4)))) | K187: =M186*(1+N(Debts!$D$7)/1200) | L187: =K187-MIN(N(Debts!$E$7),K187) | M187: =IF(L187<=0.005,0,L187-MIN(L187,MAX(0,$E187-SUMIFS(H187:AK187,$H$5:$AK$5,"Rem",$H$4:$AK$4,"<"&M$4)))) | N187: =P186*(1+N(Debts!$D$8)/1200) | O187: =N187-MIN(N(Debts!$E$8),N187) | P187: =IF(O187<=0.005,0,O187-MIN(O187,MAX(0,$E187-SUMIFS(H187:AK187,$H$5:$AK$5,"Rem",$H$4:$AK$4,"<"&P$4)))) | Q187: =S186*(1+N(Debts!$D$9)/1200) | R187: =Q187-MIN(N(Debts!$E$9),Q187) | S187: =IF(R187<=0.005,0,R187-MIN(R187,MAX(0,$E187-SUMIFS(H187:AK187,$H$5:$AK$5,"Rem",$H$4:$AK$4,"<"&S$4)))) | T187: =V186*(1+N(Debts!$D$10)/1200) | U187: =T187-MIN(N(Debts!$E$10),T187) | V187: =IF(U187<=0.005,0,U187-MIN(U187,MAX(0,$E187-SUMIFS(H187:AK187,$H$5:$AK$5,"Rem",$H$4:$AK$4,"<"&V$4)))) | W187: =Y186*(1+N(Debts!$D$11)/1200) | X187: =W187-MIN(N(Debts!$E$11),W187) | Y187: =IF(X187<=0.005,0,X187-MIN(X187,MAX(0,$E187-SUMIFS(H187:AK187,$H$5:$AK$5,"Rem",$H$4:$AK$4,"<"&Y$4)))) | Z187: =AB186*(1+N(Debts!$D$12)/1200) | AA187: =Z187-MIN(N(Debts!$E$12),Z187) | AB187: =IF(AA187<=0.005,0,AA187-MIN(AA187,MAX(0,$E187-SUMIFS(H187:AK187,$H$5:$AK$5,"Rem",$H$4:$AK$4,"<"&AB$4)))) | AC187: =AE186*(1+N(Debts!$D$13)/1200) | AD187: =AC187-MIN(N(Debts!$E$13),AC187) | AE187: =IF(AD187<=0.005,0,AD187-MIN(AD187,MAX(0,$E187-SUMIFS(H187:AK187,$H$5:$AK$5,"Rem",$H$4:$AK$4,"<"&AE$4)))) | AF187: =AH186*(1+N(Debts!$D$14)/1200) | AG187: =AF187-MIN(N(Debts!$E$14),AF187) | AH187: =IF(AG187<=0.005,0,AG187-MIN(AG187,MAX(0,$E187-SUMIFS(H187:AK187,$H$5:$AK$5,"Rem",$H$4:$AK$4,"<"&AH$4)))) | AI187: =AK186*(1+N(Debts!$D$15)/1200) | AJ187: =AI187-MIN(N(Debts!$E$15),AI187) | AK187: =IF(AJ187<=0.005,0,AJ187-MIN(AJ187,MAX(0,$E187-SUMIFS(H187:AK187,$H$5:$AK$5,"Rem",$H$4:$AK$4,"<"&AK$4))))

Sheet Avalanche
B2: Avalanche: month by month
B3: Calculated for you. Nothing to type here.
H4: =IF(Debts!$G$6="","",Debts!$G$6) | I4: =IF(Debts!$G$6="","",Debts!$G$6) | J4: =IF(Debts!$G$6="","",Debts!$G$6) | K4: =IF(Debts!$G$7="","",Debts!$G$7) | L4: =IF(Debts!$G$7="","",Debts!$G$7) | M4: =IF(Debts!$G$7="","",Debts!$G$7) | N4: =IF(Debts!$G$8="","",Debts!$G$8) | O4: =IF(Debts!$G$8="","",Debts!$G$8) | P4: =IF(Debts!$G$8="","",Debts!$G$8) | Q4: =IF(Debts!$G$9="","",Debts!$G$9) | R4: =IF(Debts!$G$9="","",Debts!$G$9) | S4: =IF(Debts!$G$9="","",Debts!$G$9) | T4: =IF(Debts!$G$10="","",Debts!$G$10) | U4: =IF(Debts!$G$10="","",Debts!$G$10) | V4: =IF(Debts!$G$10="","",Debts!$G$10) | W4: =IF(Debts!$G$11="","",Debts!$G$11) | X4: =IF(Debts!$G$11="","",Debts!$G$11) | Y4: =IF(Debts!$G$11="","",Debts!$G$11) | Z4: =IF(Debts!$G$12="","",Debts!$G$12) | AA4: =IF(Debts!$G$12="","",Debts!$G$12) | AB4: =IF(Debts!$G$12="","",Debts!$G$12) | AC4: =IF(Debts!$G$13="","",Debts!$G$13) | AD4: =IF(Debts!$G$13="","",Debts!$G$13) | AE4: =IF(Debts!$G$13="","",Debts!$G$13) | AF4: =IF(Debts!$G$14="","",Debts!$G$14) | AG4: =IF(Debts!$G$14="","",Debts!$G$14) | AH4: =IF(Debts!$G$14="","",Debts!$G$14) | AI4: =IF(Debts!$G$15="","",Debts!$G$15) | AJ4: =IF(Debts!$G$15="","",Debts!$G$15) | AK4: =IF(Debts!$G$15="","",Debts!$G$15)
H5: Due | I5: Rem | J5: Bal | K5: Due | L5: Rem | M5: Bal | N5: Due | O5: Rem | P5: Bal | Q5: Due | R5: Rem | S5: Bal | T5: Due | U5: Rem | V5: Bal | W5: Due | X5: Rem | Y5: Bal | Z5: Due | AA5: Rem | AB5: Bal | AC5: Due | AD5: Rem | AE5: Bal | AF5: Due | AG5: Rem | AH5: Bal | AI5: Due | AJ5: Rem | AK5: Bal
B6: Month | C6: Date | D6: Paying | E6: Extra left | F6: Interest | G6: Total owed | H6: =IF(Debts!$B$6="","",Debts!$B$6&" · due") | I6: =IF(Debts!$B$6="","",Debts!$B$6&" · rem") | J6: =IF(Debts!$B$6="","",Debts!$B$6) | K6: =IF(Debts!$B$7="","",Debts!$B$7&" · due") | L6: =IF(Debts!$B$7="","",Debts!$B$7&" · rem") | M6: =IF(Debts!$B$7="","",Debts!$B$7) | N6: =IF(Debts!$B$8="","",Debts!$B$8&" · due") | O6: =IF(Debts!$B$8="","",Debts!$B$8&" · rem") | P6: =IF(Debts!$B$8="","",Debts!$B$8) | Q6: =IF(Debts!$B$9="","",Debts!$B$9&" · due") | R6: =IF(Debts!$B$9="","",Debts!$B$9&" · rem") | S6: =IF(Debts!$B$9="","",Debts!$B$9) | T6: =IF(Debts!$B$10="","",Debts!$B$10&" · due") | U6: =IF(Debts!$B$10="","",Debts!$B$10&" · rem") | V6: =IF(Debts!$B$10="","",Debts!$B$10) | W6: =IF(Debts!$B$11="","",Debts!$B$11&" · due") | X6: =IF(Debts!$B$11="","",Debts!$B$11&" · rem") | Y6: =IF(Debts!$B$11="","",Debts!$B$11) | Z6: =IF(Debts!$B$12="","",Debts!$B$12&" · due") | AA6: =IF(Debts!$B$12="","",Debts!$B$12&" · rem") | AB6: =IF(Debts!$B$12="","",Debts!$B$12) | AC6: =IF(Debts!$B$13="","",Debts!$B$13&" · due") | AD6: =IF(Debts!$B$13="","",Debts!$B$13&" · rem") | AE6: =IF(Debts!$B$13="","",Debts!$B$13) | AF6: =IF(Debts!$B$14="","",Debts!$B$14&" · due") | AG6: =IF(Debts!$B$14="","",Debts!$B$14&" · rem") | AH6: =IF(Debts!$B$14="","",Debts!$B$14) | AI6: =IF(Debts!$B$15="","",Debts!$B$15&" · due") | AJ6: =IF(Debts!$B$15="","",Debts!$B$15&" · rem") | AK6: =IF(Debts!$B$15="","",Debts!$B$15)
B7: 0 | G7: =SUMIF($H$5:$AK$5,"Bal",H7:AK7) | J7: =N(Debts!$C$6) | M7: =N(Debts!$C$7) | P7: =N(Debts!$C$8) | S7: =N(Debts!$C$9) | V7: =N(Debts!$C$10) | Y7: =N(Debts!$C$11) | AB7: =N(Debts!$C$12) | AE7: =N(Debts!$C$13) | AH7: =N(Debts!$C$14) | AK7: =N(Debts!$C$15)
B8: 1 | C8: =EDATE(Debts!$J$13,B8-1) | D8: =IF(G7<=0.005,0,Debts!$E$16+Debts!$J$7) | E8: =MAX(0,D8-(SUMIF($H$5:$AK$5,"Due",H8:AK8)-SUMIF($H$5:$AK$5,"Rem",H8:AK8))) | F8: =SUMIF($H$5:$AK$5,"Due",H8:AK8)-SUMIF($H$5:$AK$5,"Bal",H7:AK7) | G8: =SUMIF($H$5:$AK$5,"Bal",H8:AK8) | H8: =J7*(1+N(Debts!$D$6)/1200) | I8: =H8-MIN(N(Debts!$E$6),H8) | J8: =IF(I8<=0.005,0,I8-MIN(I8,MAX(0,$E8-SUMIFS(H8:AK8,$H$5:$AK$5,"Rem",$H$4:$AK$4,"<"&J$4)))) | K8: =M7*(1+N(Debts!$D$7)/1200) | L8: =K8-MIN(N(Debts!$E$7),K8) | M8: =IF(L8<=0.005,0,L8-MIN(L8,MAX(0,$E8-SUMIFS(H8:AK8,$H$5:$AK$5,"Rem",$H$4:$AK$4,"<"&M$4)))) | N8: =P7*(1+N(Debts!$D$8)/1200) | O8: =N8-MIN(N(Debts!$E$8),N8) | P8: =IF(O8<=0.005,0,O8-MIN(O8,MAX(0,$E8-SUMIFS(H8:AK8,$H$5:$AK$5,"Rem",$H$4:$AK$4,"<"&P$4)))) | Q8: =S7*(1+N(Debts!$D$9)/1200) | R8: =Q8-MIN(N(Debts!$E$9),Q8) | S8: =IF(R8<=0.005,0,R8-MIN(R8,MAX(0,$E8-SUMIFS(H8:AK8,$H$5:$AK$5,"Rem",$H$4:$AK$4,"<"&S$4)))) | T8: =V7*(1+N(Debts!$D$10)/1200) | U8: =T8-MIN(N(Debts!$E$10),T8) | V8: =IF(U8<=0.005,0,U8-MIN(U8,MAX(0,$E8-SUMIFS(H8:AK8,$H$5:$AK$5,"Rem",$H$4:$AK$4,"<"&V$4)))) | W8: =Y7*(1+N(Debts!$D$11)/1200) | X8: =W8-MIN(N(Debts!$E$11),W8) | Y8: =IF(X8<=0.005,0,X8-MIN(X8,MAX(0,$E8-SUMIFS(H8:AK8,$H$5:$AK$5,"Rem",$H$4:$AK$4,"<"&Y$4)))) | Z8: =AB7*(1+N(Debts!$D$12)/1200) | AA8: =Z8-MIN(N(Debts!$E$12),Z8) | AB8: =IF(AA8<=0.005,0,AA8-MIN(AA8,MAX(0,$E8-SUMIFS(H8:AK8,$H$5:$AK$5,"Rem",$H$4:$AK$4,"<"&AB$4)))) | AC8: =AE7*(1+N(Debts!$D$13)/1200) | AD8: =AC8-MIN(N(Debts!$E$13),AC8) | AE8: =IF(AD8<=0.005,0,AD8-MIN(AD8,MAX(0,$E8-SUMIFS(H8:AK8,$H$5:$AK$5,"Rem",$H$4:$AK$4,"<"&AE$4)))) | AF8: =AH7*(1+N(Debts!$D$14)/1200) | AG8: =AF8-MIN(N(Debts!$E$14),AF8) | AH8: =IF(AG8<=0.005,0,AG8-MIN(AG8,MAX(0,$E8-SUMIFS(H8:AK8,$H$5:$AK$5,"Rem",$H$4:$AK$4,"<"&AH$4)))) | AI8: =AK7*(1+N(Debts!$D$15)/1200) | AJ8: =AI8-MIN(N(Debts!$E$15),AI8) | AK8: =IF(AJ8<=0.005,0,AJ8-MIN(AJ8,MAX(0,$E8-SUMIFS(H8:AK8,$H$5:$AK$5,"Rem",$H$4:$AK$4,"<"&AK$4))))
B9: 2 | C9: =EDATE(Debts!$J$13,B9-1) | D9: =IF(G8<=0.005,0,Debts!$E$16+Debts!$J$7) | E9: =MAX(0,D9-(SUMIF($H$5:$AK$5,"Due",H9:AK9)-SUMIF($H$5:$AK$5,"Rem",H9:AK9))) | F9: =SUMIF($H$5:$AK$5,"Due",H9:AK9)-SUMIF($H$5:$AK$5,"Bal",H8:AK8) | G9: =SUMIF($H$5:$AK$5,"Bal",H9:AK9) | H9: =J8*(1+N(Debts!$D$6)/1200) | I9: =H9-MIN(N(Debts!$E$6),H9) | J9: =IF(I9<=0.005,0,I9-MIN(I9,MAX(0,$E9-SUMIFS(H9:AK9,$H$5:$AK$5,"Rem",$H$4:$AK$4,"<"&J$4)))) | K9: =M8*(1+N(Debts!$D$7)/1200) | L9: =K9-MIN(N(Debts!$E$7),K9) | M9: =IF(L9<=0.005,0,L9-MIN(L9,MAX(0,$E9-SUMIFS(H9:AK9,$H$5:$AK$5,"Rem",$H$4:$AK$4,"<"&M$4)))) | N9: =P8*(1+N(Debts!$D$8)/1200) | O9: =N9-MIN(N(Debts!$E$8),N9) | P9: =IF(O9<=0.005,0,O9-MIN(O9,MAX(0,$E9-SUMIFS(H9:AK9,$H$5:$AK$5,"Rem",$H$4:$AK$4,"<"&P$4)))) | Q9: =S8*(1+N(Debts!$D$9)/1200) | R9: =Q9-MIN(N(Debts!$E$9),Q9) | S9: =IF(R9<=0.005,0,R9-MIN(R9,MAX(0,$E9-SUMIFS(H9:AK9,$H$5:$AK$5,"Rem",$H$4:$AK$4,"<"&S$4)))) | T9: =V8*(1+N(Debts!$D$10)/1200) | U9: =T9-MIN(N(Debts!$E$10),T9) | V9: =IF(U9<=0.005,0,U9-MIN(U9,MAX(0,$E9-SUMIFS(H9:AK9,$H$5:$AK$5,"Rem",$H$4:$AK$4,"<"&V$4)))) | W9: =Y8*(1+N(Debts!$D$11)/1200) | X9: =W9-MIN(N(Debts!$E$11),W9) | Y9: =IF(X9<=0.005,0,X9-MIN(X9,MAX(0,$E9-SUMIFS(H9:AK9,$H$5:$AK$5,"Rem",$H$4:$AK$4,"<"&Y$4)))) | Z9: =AB8*(1+N(Debts!$D$12)/1200) | AA9: =Z9-MIN(N(Debts!$E$12),Z9) | AB9: =IF(AA9<=0.005,0,AA9-MIN(AA9,MAX(0,$E9-SUMIFS(H9:AK9,$H$5:$AK$5,"Rem",$H$4:$AK$4,"<"&AB$4)))) | AC9: =AE8*(1+N(Debts!$D$13)/1200) | AD9: =AC9-MIN(N(Debts!$E$13),AC9) | AE9: =IF(AD9<=0.005,0,AD9-MIN(AD9,MAX(0,$E9-SUMIFS(H9:AK9,$H$5:$AK$5,"Rem",$H$4:$AK$4,"<"&AE$4)))) | AF9: =AH8*(1+N(Debts!$D$14)/1200) | AG9: =AF9-MIN(N(Debts!$E$14),AF9) | AH9: =IF(AG9<=0.005,0,AG9-MIN(AG9,MAX(0,$E9-SUMIFS(H9:AK9,$H$5:$AK$5,"Rem",$H$4:$AK$4,"<"&AH$4)))) | AI9: =AK8*(1+N(Debts!$D$15)/1200) | AJ9: =AI9-MIN(N(Debts!$E$15),AI9) | AK9: =IF(AJ9<=0.005,0,AJ9-MIN(AJ9,MAX(0,$E9-SUMIFS(H9:AK9,$H$5:$AK$5,"Rem",$H$4:$AK$4,"<"&AK$4))))
B10: 3 | C10: =EDATE(Debts!$J$13,B10-1) | D10: =IF(G9<=0.005,0,Debts!$E$16+Debts!$J$7) | E10: =MAX(0,D10-(SUMIF($H$5:$AK$5,"Due",H10:AK10)-SUMIF($H$5:$AK$5,"Rem",H10:AK10))) | F10: =SUMIF($H$5:$AK$5,"Due",H10:AK10)-SUMIF($H$5:$AK$5,"Bal",H9:AK9) | G10: =SUMIF($H$5:$AK$5,"Bal",H10:AK10) | H10: =J9*(1+N(Debts!$D$6)/1200) | I10: =H10-MIN(N(Debts!$E$6),H10) | J10: =IF(I10<=0.005,0,I10-MIN(I10,MAX(0,$E10-SUMIFS(H10:AK10,$H$5:$AK$5,"Rem",$H$4:$AK$4,"<"&J$4)))) | K10: =M9*(1+N(Debts!$D$7)/1200) | L10: =K10-MIN(N(Debts!$E$7),K10) | M10: =IF(L10<=0.005,0,L10-MIN(L10,MAX(0,$E10-SUMIFS(H10:AK10,$H$5:$AK$5,"Rem",$H$4:$AK$4,"<"&M$4)))) | N10: =P9*(1+N(Debts!$D$8)/1200) | O10: =N10-MIN(N(Debts!$E$8),N10) | P10: =IF(O10<=0.005,0,O10-MIN(O10,MAX(0,$E10-SUMIFS(H10:AK10,$H$5:$AK$5,"Rem",$H$4:$AK$4,"<"&P$4)))) | Q10: =S9*(1+N(Debts!$D$9)/1200) | R10: =Q10-MIN(N(Debts!$E$9),Q10) | S10: =IF(R10<=0.005,0,R10-MIN(R10,MAX(0,$E10-SUMIFS(H10:AK10,$H$5:$AK$5,"Rem",$H$4:$AK$4,"<"&S$4)))) | T10: =V9*(1+N(Debts!$D$10)/1200) | U10: =T10-MIN(N(Debts!$E$10),T10) | V10: =IF(U10<=0.005,0,U10-MIN(U10,MAX(0,$E10-SUMIFS(H10:AK10,$H$5:$AK$5,"Rem",$H$4:$AK$4,"<"&V$4)))) | W10: =Y9*(1+N(Debts!$D$11)/1200) | X10: =W10-MIN(N(Debts!$E$11),W10) | Y10: =IF(X10<=0.005,0,X10-MIN(X10,MAX(0,$E10-SUMIFS(H10:AK10,$H$5:$AK$5,"Rem",$H$4:$AK$4,"<"&Y$4)))) | Z10: =AB9*(1+N(Debts!$D$12)/1200) | AA10: =Z10-MIN(N(Debts!$E$12),Z10) | AB10: =IF(AA10<=0.005,0,AA10-MIN(AA10,MAX(0,$E10-SUMIFS(H10:AK10,$H$5:$AK$5,"Rem",$H$4:$AK$4,"<"&AB$4)))) | AC10: =AE9*(1+N(Debts!$D$13)/1200) | AD10: =AC10-MIN(N(Debts!$E$13),AC10) | AE10: =IF(AD10<=0.005,0,AD10-MIN(AD10,MAX(0,$E10-SUMIFS(H10:AK10,$H$5:$AK$5,"Rem",$H$4:$AK$4,"<"&AE$4)))) | AF10: =AH9*(1+N(Debts!$D$14)/1200) | AG10: =AF10-MIN(N(Debts!$E$14),AF10) | AH10: =IF(AG10<=0.005,0,AG10-MIN(AG10,MAX(0,$E10-SUMIFS(H10:AK10,$H$5:$AK$5,"Rem",$H$4:$AK$4,"<"&AH$4)))) | AI10: =AK9*(1+N(Debts!$D$15)/1200) | AJ10: =AI10-MIN(N(Debts!$E$15),AI10) | AK10: =IF(AJ10<=0.005,0,AJ10-MIN(AJ10,MAX(0,$E10-SUMIFS(H10:AK10,$H$5:$AK$5,"Rem",$H$4:$AK$4,"<"&AK$4))))
B11: 4 | C11: =EDATE(Debts!$J$13,B11-1) | D11: =IF(G10<=0.005,0,Debts!$E$16+Debts!$J$7) | E11: =MAX(0,D11-(SUMIF($H$5:$AK$5,"Due",H11:AK11)-SUMIF($H$5:$AK$5,"Rem",H11:AK11))) | F11: =SUMIF($H$5:$AK$5,"Due",H11:AK11)-SUMIF($H$5:$AK$5,"Bal",H10:AK10) | G11: =SUMIF($H$5:$AK$5,"Bal",H11:AK11) | H11: =J10*(1+N(Debts!$D$6)/1200) | I11: =H11-MIN(N(Debts!$E$6),H11) | J11: =IF(I11<=0.005,0,I11-MIN(I11,MAX(0,$E11-SUMIFS(H11:AK11,$H$5:$AK$5,"Rem",$H$4:$AK$4,"<"&J$4)))) | K11: =M10*(1+N(Debts!$D$7)/1200) | L11: =K11-MIN(N(Debts!$E$7),K11) | M11: =IF(L11<=0.005,0,L11-MIN(L11,MAX(0,$E11-SUMIFS(H11:AK11,$H$5:$AK$5,"Rem",$H$4:$AK$4,"<"&M$4)))) | N11: =P10*(1+N(Debts!$D$8)/1200) | O11: =N11-MIN(N(Debts!$E$8),N11) | P11: =IF(O11<=0.005,0,O11-MIN(O11,MAX(0,$E11-SUMIFS(H11:AK11,$H$5:$AK$5,"Rem",$H$4:$AK$4,"<"&P$4)))) | Q11: =S10*(1+N(Debts!$D$9)/1200) | R11: =Q11-MIN(N(Debts!$E$9),Q11) | S11: =IF(R11<=0.005,0,R11-MIN(R11,MAX(0,$E11-SUMIFS(H11:AK11,$H$5:$AK$5,"Rem",$H$4:$AK$4,"<"&S$4)))) | T11: =V10*(1+N(Debts!$D$10)/1200) | U11: =T11-MIN(N(Debts!$E$10),T11) | V11: =IF(U11<=0.005,0,U11-MIN(U11,MAX(0,$E11-SUMIFS(H11:AK11,$H$5:$AK$5,"Rem",$H$4:$AK$4,"<"&V$4)))) | W11: =Y10*(1+N(Debts!$D$11)/1200) | X11: =W11-MIN(N(Debts!$E$11),W11) | Y11: =IF(X11<=0.005,0,X11-MIN(X11,MAX(0,$E11-SUMIFS(H11:AK11,$H$5:$AK$5,"Rem",$H$4:$AK$4,"<"&Y$4)))) | Z11: =AB10*(1+N(Debts!$D$12)/1200) | AA11: =Z11-MIN(N(Debts!$E$12),Z11) | AB11: =IF(AA11<=0.005,0,AA11-MIN(AA11,MAX(0,$E11-SUMIFS(H11:AK11,$H$5:$AK$5,"Rem",$H$4:$AK$4,"<"&AB$4)))) | AC11: =AE10*(1+N(Debts!$D$13)/1200) | AD11: =AC11-MIN(N(Debts!$E$13),AC11) | AE11: =IF(AD11<=0.005,0,AD11-MIN(AD11,MAX(0,$E11-SUMIFS(H11:AK11,$H$5:$AK$5,"Rem",$H$4:$AK$4,"<"&AE$4)))) | AF11: =AH10*(1+N(Debts!$D$14)/1200) | AG11: =AF11-MIN(N(Debts!$E$14),AF11) | AH11: =IF(AG11<=0.005,0,AG11-MIN(AG11,MAX(0,$E11-SUMIFS(H11:AK11,$H$5:$AK$5,"Rem",$H$4:$AK$4,"<"&AH$4)))) | AI11: =AK10*(1+N(Debts!$D$15)/1200) | AJ11: =AI11-MIN(N(Debts!$E$15),AI11) | AK11: =IF(AJ11<=0.005,0,AJ11-MIN(AJ11,MAX(0,$E11-SUMIFS(H11:AK11,$H$5:$AK$5,"Rem",$H$4:$AK$4,"<"&AK$4))))
B12: 5 | C12: =EDATE(Debts!$J$13,B12-1) | D12: =IF(G11<=0.005,0,Debts!$E$16+Debts!$J$7) | E12: =MAX(0,D12-(SUMIF($H$5:$AK$5,"Due",H12:AK12)-SUMIF($H$5:$AK$5,"Rem",H12:AK12))) | F12: =SUMIF($H$5:$AK$5,"Due",H12:AK12)-SUMIF($H$5:$AK$5,"Bal",H11:AK11) | G12: =SUMIF($H$5:$AK$5,"Bal",H12:AK12) | H12: =J11*(1+N(Debts!$D$6)/1200) | I12: =H12-MIN(N(Debts!$E$6),H12) | J12: =IF(I12<=0.005,0,I12-MIN(I12,MAX(0,$E12-SUMIFS(H12:AK12,$H$5:$AK$5,"Rem",$H$4:$AK$4,"<"&J$4)))) | K12: =M11*(1+N(Debts!$D$7)/1200) | L12: =K12-MIN(N(Debts!$E$7),K12) | M12: =IF(L12<=0.005,0,L12-MIN(L12,MAX(0,$E12-SUMIFS(H12:AK12,$H$5:$AK$5,"Rem",$H$4:$AK$4,"<"&M$4)))) | N12: =P11*(1+N(Debts!$D$8)/1200) | O12: =N12-MIN(N(Debts!$E$8),N12) | P12: =IF(O12<=0.005,0,O12-MIN(O12,MAX(0,$E12-SUMIFS(H12:AK12,$H$5:$AK$5,"Rem",$H$4:$AK$4,"<"&P$4)))) | Q12: =S11*(1+N(Debts!$D$9)/1200) | R12: =Q12-MIN(N(Debts!$E$9),Q12) | S12: =IF(R12<=0.005,0,R12-MIN(R12,MAX(0,$E12-SUMIFS(H12:AK12,$H$5:$AK$5,"Rem",$H$4:$AK$4,"<"&S$4)))) | T12: =V11*(1+N(Debts!$D$10)/1200) | U12: =T12-MIN(N(Debts!$E$10),T12) | V12: =IF(U12<=0.005,0,U12-MIN(U12,MAX(0,$E12-SUMIFS(H12:AK12,$H$5:$AK$5,"Rem",$H$4:$AK$4,"<"&V$4)))) | W12: =Y11*(1+N(Debts!$D$11)/1200) | X12: =W12-MIN(N(Debts!$E$11),W12) | Y12: =IF(X12<=0.005,0,X12-MIN(X12,MAX(0,$E12-SUMIFS(H12:AK12,$H$5:$AK$5,"Rem",$H$4:$AK$4,"<"&Y$4)))) | Z12: =AB11*(1+N(Debts!$D$12)/1200) | AA12: =Z12-MIN(N(Debts!$E$12),Z12) | AB12: =IF(AA12<=0.005,0,AA12-MIN(AA12,MAX(0,$E12-SUMIFS(H12:AK12,$H$5:$AK$5,"Rem",$H$4:$AK$4,"<"&AB$4)))) | AC12: =AE11*(1+N(Debts!$D$13)/1200) | AD12: =AC12-MIN(N(Debts!$E$13),AC12) | AE12: =IF(AD12<=0.005,0,AD12-MIN(AD12,MAX(0,$E12-SUMIFS(H12:AK12,$H$5:$AK$5,"Rem",$H$4:$AK$4,"<"&AE$4)))) | AF12: =AH11*(1+N(Debts!$D$14)/1200) | AG12: =AF12-MIN(N(Debts!$E$14),AF12) | AH12: =IF(AG12<=0.005,0,AG12-MIN(AG12,MAX(0,$E12-SUMIFS(H12:AK12,$H$5:$AK$5,"Rem",$H$4:$AK$4,"<"&AH$4)))) | AI12: =AK11*(1+N(Debts!$D$15)/1200) | AJ12: =AI12-MIN(N(Debts!$E$15),AI12) | AK12: =IF(AJ12<=0.005,0,AJ12-MIN(AJ12,MAX(0,$E12-SUMIFS(H12:AK12,$H$5:$AK$5,"Rem",$H$4:$AK$4,"<"&AK$4))))
B13: 6 | C13: =EDATE(Debts!$J$13,B13-1) | D13: =IF(G12<=0.005,0,Debts!$E$16+Debts!$J$7) | E13: =MAX(0,D13-(SUMIF($H$5:$AK$5,"Due",H13:AK13)-SUMIF($H$5:$AK$5,"Rem",H13:AK13))) | F13: =SUMIF($H$5:$AK$5,"Due",H13:AK13)-SUMIF($H$5:$AK$5,"Bal",H12:AK12) | G13: =SUMIF($H$5:$AK$5,"Bal",H13:AK13) | H13: =J12*(1+N(Debts!$D$6)/1200) | I13: =H13-MIN(N(Debts!$E$6),H13) | J13: =IF(I13<=0.005,0,I13-MIN(I13,MAX(0,$E13-SUMIFS(H13:AK13,$H$5:$AK$5,"Rem",$H$4:$AK$4,"<"&J$4)))) | K13: =M12*(1+N(Debts!$D$7)/1200) | L13: =K13-MIN(N(Debts!$E$7),K13) | M13: =IF(L13<=0.005,0,L13-MIN(L13,MAX(0,$E13-SUMIFS(H13:AK13,$H$5:$AK$5,"Rem",$H$4:$AK$4,"<"&M$4)))) | N13: =P12*(1+N(Debts!$D$8)/1200) | O13: =N13-MIN(N(Debts!$E$8),N13) | P13: =IF(O13<=0.005,0,O13-MIN(O13,MAX(0,$E13-SUMIFS(H13:AK13,$H$5:$AK$5,"Rem",$H$4:$AK$4,"<"&P$4)))) | Q13: =S12*(1+N(Debts!$D$9)/1200) | R13: =Q13-MIN(N(Debts!$E$9),Q13) | S13: =IF(R13<=0.005,0,R13-MIN(R13,MAX(0,$E13-SUMIFS(H13:AK13,$H$5:$AK$5,"Rem",$H$4:$AK$4,"<"&S$4)))) | T13: =V12*(1+N(Debts!$D$10)/1200) | U13: =T13-MIN(N(Debts!$E$10),T13) | V13: =IF(U13<=0.005,0,U13-MIN(U13,MAX(0,$E13-SUMIFS(H13:AK13,$H$5:$AK$5,"Rem",$H$4:$AK$4,"<"&V$4)))) | W13: =Y12*(1+N(Debts!$D$11)/1200) | X13: =W13-MIN(N(Debts!$E$11),W13) | Y13: =IF(X13<=0.005,0,X13-MIN(X13,MAX(0,$E13-SUMIFS(H13:AK13,$H$5:$AK$5,"Rem",$H$4:$AK$4,"<"&Y$4)))) | Z13: =AB12*(1+N(Debts!$D$12)/1200) | AA13: =Z13-MIN(N(Debts!$E$12),Z13) | AB13: =IF(AA13<=0.005,0,AA13-MIN(AA13,MAX(0,$E13-SUMIFS(H13:AK13,$H$5:$AK$5,"Rem",$H$4:$AK$4,"<"&AB$4)))) | AC13: =AE12*(1+N(Debts!$D$13)/1200) | AD13: =AC13-MIN(N(Debts!$E$13),AC13) | AE13: =IF(AD13<=0.005,0,AD13-MIN(AD13,MAX(0,$E13-SUMIFS(H13:AK13,$H$5:$AK$5,"Rem",$H$4:$AK$4,"<"&AE$4)))) | AF13: =AH12*(1+N(Debts!$D$14)/1200) | AG13: =AF13-MIN(N(Debts!$E$14),AF13) | AH13: =IF(AG13<=0.005,0,AG13-MIN(AG13,MAX(0,$E13-SUMIFS(H13:AK13,$H$5:$AK$5,"Rem",$H$4:$AK$4,"<"&AH$4)))) | AI13: =AK12*(1+N(Debts!$D$15)/1200) | AJ13: =AI13-MIN(N(Debts!$E$15),AI13) | AK13: =IF(AJ13<=0.005,0,AJ13-MIN(AJ13,MAX(0,$E13-SUMIFS(H13:AK13,$H$5:$AK$5,"Rem",$H$4:$AK$4,"<"&AK$4))))
