Workbook

Sheet Dashboard
B2: Money lent and borrowed
B3: Who owes what, the next payments, and what came in and went out.
B4: Owed to you | C4: Overdue to you | D4: In this month | E4: Open loans | G4: You owe | H4: You are late on | I4: Out this month | J4: Paid off
B5: =SUMIFS(Loans!$O$6:$O$305,Loans!$D$6:$D$305,"I lent",Loans!$O$6:$O$305,">0") | C5: =SUMIFS(Loans!$W$6:$W$305,Loans!$D$6:$D$305,"I lent") | D5: =SUMIFS(Payments!$D$6:$D$805,Payments!$I$6:$I$805,"In",Payments!$J$6:$J$805,(YEAR(TODAY())*100+MONTH(TODAY()))) | E5: =COUNTIF(Loans!$R$6:$R$305,"Open")+COUNTIF(Loans!$R$6:$R$305,"Overdue")+COUNTIF(Loans!$R$6:$R$305,"Due soon")+COUNTIF(Loans!$R$6:$R$305,"On track") | G5: =SUMIFS(Loans!$O$6:$O$305,Loans!$D$6:$D$305,"I borrowed",Loans!$O$6:$O$305,">0") | H5: =SUMIFS(Loans!$W$6:$W$305,Loans!$D$6:$D$305,"I borrowed") | I5: =SUMIFS(Payments!$D$6:$D$805,Payments!$I$6:$I$805,"Out",Payments!$J$6:$J$805,(YEAR(TODAY())*100+MONTH(TODAY()))) | J5: =COUNTIF(Loans!$R$6:$R$305,"Paid off")
B7: Next payments | C7: Which way | D7: Due on | E7: Amount | G7: Who owes what | H7: Owes you | I7: You owe | J7: Open loans
B8: =IF(M8="","",INDEX(Loans!$C$1:$C$305,MOD(M8,1000))) | C8: =IF(M8="","",INDEX(Loans!$Z$1:$Z$305,MOD(M8,1000))) | D8: =IF(M8="","",INDEX(Loans!$P$1:$P$305,MOD(M8,1000))) | E8: =IF(M8="","",INDEX(Loans!$Q$1:$Q$305,MOD(M8,1000))) | G8: =IF(O8="","",INDEX(Loans!$C$1:$C$305,O8)) | H8: =IF(G8="","",SUMIFS(Loans!$O$6:$O$305,Loans!$C$6:$C$305,G8,Loans!$D$6:$D$305,"I lent",Loans!$O$6:$O$305,">0")) | I8: =IF(G8="","",SUMIFS(Loans!$O$6:$O$305,Loans!$C$6:$C$305,G8,Loans!$D$6:$D$305,"I borrowed",Loans!$O$6:$O$305,">0")) | J8: =IF(G8="","",COUNTIFS(Loans!$C$6:$C$305,G8,Loans!$R$6:$R$305,"Open")+COUNTIFS(Loans!$C$6:$C$305,G8,Loans!$R$6:$R$305,"Overdue")+COUNTIFS(Loans!$C$6:$C$305,G8,Loans!$R$6:$R$305,"Due soon")+COUNTIFS(Loans!$C$6:$C$305,G8,Loans!$R$6:$R$305,"On track")) | M8: =IFERROR(SMALL(Loans!$X$6:$X$305,1),"") | N8: =IF(M8="","",INDEX(Loans!$R$1:$R$305,MOD(M8,1000))) | O8: =IFERROR(SMALL(Loans!$Y$6:$Y$305,1),"")
B9: =IF(M9="","",INDEX(Loans!$C$1:$C$305,MOD(M9,1000))) | C9: =IF(M9="","",INDEX(Loans!$Z$1:$Z$305,MOD(M9,1000))) | D9: =IF(M9="","",INDEX(Loans!$P$1:$P$305,MOD(M9,1000))) | E9: =IF(M9="","",INDEX(Loans!$Q$1:$Q$305,MOD(M9,1000))) | G9: =IF(O9="","",INDEX(Loans!$C$1:$C$305,O9)) | H9: =IF(G9="","",SUMIFS(Loans!$O$6:$O$305,Loans!$C$6:$C$305,G9,Loans!$D$6:$D$305,"I lent",Loans!$O$6:$O$305,">0")) | I9: =IF(G9="","",SUMIFS(Loans!$O$6:$O$305,Loans!$C$6:$C$305,G9,Loans!$D$6:$D$305,"I borrowed",Loans!$O$6:$O$305,">0")) | J9: =IF(G9="","",COUNTIFS(Loans!$C$6:$C$305,G9,Loans!$R$6:$R$305,"Open")+COUNTIFS(Loans!$C$6:$C$305,G9,Loans!$R$6:$R$305,"Overdue")+COUNTIFS(Loans!$C$6:$C$305,G9,Loans!$R$6:$R$305,"Due soon")+COUNTIFS(Loans!$C$6:$C$305,G9,Loans!$R$6:$R$305,"On track")) | M9: =IFERROR(SMALL(Loans!$X$6:$X$305,2),"") | N9: =IF(M9="","",INDEX(Loans!$R$1:$R$305,MOD(M9,1000))) | O9: =IFERROR(SMALL(Loans!$Y$6:$Y$305,2),"")
B10: =IF(M10="","",INDEX(Loans!$C$1:$C$305,MOD(M10,1000))) | C10: =IF(M10="","",INDEX(Loans!$Z$1:$Z$305,MOD(M10,1000))) | D10: =IF(M10="","",INDEX(Loans!$P$1:$P$305,MOD(M10,1000))) | E10: =IF(M10="","",INDEX(Loans!$Q$1:$Q$305,MOD(M10,1000))) | G10: =IF(O10="","",INDEX(Loans!$C$1:$C$305,O10)) | H10: =IF(G10="","",SUMIFS(Loans!$O$6:$O$305,Loans!$C$6:$C$305,G10,Loans!$D$6:$D$305,"I lent",Loans!$O$6:$O$305,">0")) | I10: =IF(G10="","",SUMIFS(Loans!$O$6:$O$305,Loans!$C$6:$C$305,G10,Loans!$D$6:$D$305,"I borrowed",Loans!$O$6:$O$305,">0")) | J10: =IF(G10="","",COUNTIFS(Loans!$C$6:$C$305,G10,Loans!$R$6:$R$305,"Open")+COUNTIFS(Loans!$C$6:$C$305,G10,Loans!$R$6:$R$305,"Overdue")+COUNTIFS(Loans!$C$6:$C$305,G10,Loans!$R$6:$R$305,"Due soon")+COUNTIFS(Loans!$C$6:$C$305,G10,Loans!$R$6:$R$305,"On track")) | M10: =IFERROR(SMALL(Loans!$X$6:$X$305,3),"") | N10: =IF(M10="","",INDEX(Loans!$R$1:$R$305,MOD(M10,1000))) | O10: =IFERROR(SMALL(Loans!$Y$6:$Y$305,3),"")
B11: =IF(M11="","",INDEX(Loans!$C$1:$C$305,MOD(M11,1000))) | C11: =IF(M11="","",INDEX(Loans!$Z$1:$Z$305,MOD(M11,1000))) | D11: =IF(M11="","",INDEX(Loans!$P$1:$P$305,MOD(M11,1000))) | E11: =IF(M11="","",INDEX(Loans!$Q$1:$Q$305,MOD(M11,1000))) | G11: =IF(O11="","",INDEX(Loans!$C$1:$C$305,O11)) | H11: =IF(G11="","",SUMIFS(Loans!$O$6:$O$305,Loans!$C$6:$C$305,G11,Loans!$D$6:$D$305,"I lent",Loans!$O$6:$O$305,">0")) | I11: =IF(G11="","",SUMIFS(Loans!$O$6:$O$305,Loans!$C$6:$C$305,G11,Loans!$D$6:$D$305,"I borrowed",Loans!$O$6:$O$305,">0")) | J11: =IF(G11="","",COUNTIFS(Loans!$C$6:$C$305,G11,Loans!$R$6:$R$305,"Open")+COUNTIFS(Loans!$C$6:$C$305,G11,Loans!$R$6:$R$305,"Overdue")+COUNTIFS(Loans!$C$6:$C$305,G11,Loans!$R$6:$R$305,"Due soon")+COUNTIFS(Loans!$C$6:$C$305,G11,Loans!$R$6:$R$305,"On track")) | M11: =IFERROR(SMALL(Loans!$X$6:$X$305,4),"") | N11: =IF(M11="","",INDEX(Loans!$R$1:$R$305,MOD(M11,1000))) | O11: =IFERROR(SMALL(Loans!$Y$6:$Y$305,4),"")
B12: =IF(M12="","",INDEX(Loans!$C$1:$C$305,MOD(M12,1000))) | C12: =IF(M12="","",INDEX(Loans!$Z$1:$Z$305,MOD(M12,1000))) | D12: =IF(M12="","",INDEX(Loans!$P$1:$P$305,MOD(M12,1000))) | E12: =IF(M12="","",INDEX(Loans!$Q$1:$Q$305,MOD(M12,1000))) | G12: =IF(O12="","",INDEX(Loans!$C$1:$C$305,O12)) | H12: =IF(G12="","",SUMIFS(Loans!$O$6:$O$305,Loans!$C$6:$C$305,G12,Loans!$D$6:$D$305,"I lent",Loans!$O$6:$O$305,">0")) | I12: =IF(G12="","",SUMIFS(Loans!$O$6:$O$305,Loans!$C$6:$C$305,G12,Loans!$D$6:$D$305,"I borrowed",Loans!$O$6:$O$305,">0")) | J12: =IF(G12="","",COUNTIFS(Loans!$C$6:$C$305,G12,Loans!$R$6:$R$305,"Open")+COUNTIFS(Loans!$C$6:$C$305,G12,Loans!$R$6:$R$305,"Overdue")+COUNTIFS(Loans!$C$6:$C$305,G12,Loans!$R$6:$R$305,"Due soon")+COUNTIFS(Loans!$C$6:$C$305,G12,Loans!$R$6:$R$305,"On track")) | M12: =IFERROR(SMALL(Loans!$X$6:$X$305,5),"") | N12: =IF(M12="","",INDEX(Loans!$R$1:$R$305,MOD(M12,1000))) | O12: =IFERROR(SMALL(Loans!$Y$6:$Y$305,5),"")
B13: =IF(M13="","",INDEX(Loans!$C$1:$C$305,MOD(M13,1000))) | C13: =IF(M13="","",INDEX(Loans!$Z$1:$Z$305,MOD(M13,1000))) | D13: =IF(M13="","",INDEX(Loans!$P$1:$P$305,MOD(M13,1000))) | E13: =IF(M13="","",INDEX(Loans!$Q$1:$Q$305,MOD(M13,1000))) | G13: =IF(O13="","",INDEX(Loans!$C$1:$C$305,O13)) | H13: =IF(G13="","",SUMIFS(Loans!$O$6:$O$305,Loans!$C$6:$C$305,G13,Loans!$D$6:$D$305,"I lent",Loans!$O$6:$O$305,">0")) | I13: =IF(G13="","",SUMIFS(Loans!$O$6:$O$305,Loans!$C$6:$C$305,G13,Loans!$D$6:$D$305,"I borrowed",Loans!$O$6:$O$305,">0")) | J13: =IF(G13="","",COUNTIFS(Loans!$C$6:$C$305,G13,Loans!$R$6:$R$305,"Open")+COUNTIFS(Loans!$C$6:$C$305,G13,Loans!$R$6:$R$305,"Overdue")+COUNTIFS(Loans!$C$6:$C$305,G13,Loans!$R$6:$R$305,"Due soon")+COUNTIFS(Loans!$C$6:$C$305,G13,Loans!$R$6:$R$305,"On track")) | M13: =IFERROR(SMALL(Loans!$X$6:$X$305,6),"") | N13: =IF(M13="","",INDEX(Loans!$R$1:$R$305,MOD(M13,1000))) | O13: =IFERROR(SMALL(Loans!$Y$6:$Y$305,6),"")
B14: =IF(M14="","",INDEX(Loans!$C$1:$C$305,MOD(M14,1000))) | C14: =IF(M14="","",INDEX(Loans!$Z$1:$Z$305,MOD(M14,1000))) | D14: =IF(M14="","",INDEX(Loans!$P$1:$P$305,MOD(M14,1000))) | E14: =IF(M14="","",INDEX(Loans!$Q$1:$Q$305,MOD(M14,1000))) | G14: =IF(O14="","",INDEX(Loans!$C$1:$C$305,O14)) | H14: =IF(G14="","",SUMIFS(Loans!$O$6:$O$305,Loans!$C$6:$C$305,G14,Loans!$D$6:$D$305,"I lent",Loans!$O$6:$O$305,">0")) | I14: =IF(G14="","",SUMIFS(Loans!$O$6:$O$305,Loans!$C$6:$C$305,G14,Loans!$D$6:$D$305,"I borrowed",Loans!$O$6:$O$305,">0")) | J14: =IF(G14="","",COUNTIFS(Loans!$C$6:$C$305,G14,Loans!$R$6:$R$305,"Open")+COUNTIFS(Loans!$C$6:$C$305,G14,Loans!$R$6:$R$305,"Overdue")+COUNTIFS(Loans!$C$6:$C$305,G14,Loans!$R$6:$R$305,"Due soon")+COUNTIFS(Loans!$C$6:$C$305,G14,Loans!$R$6:$R$305,"On track")) | M14: =IFERROR(SMALL(Loans!$X$6:$X$305,7),"") | N14: =IF(M14="","",INDEX(Loans!$R$1:$R$305,MOD(M14,1000))) | O14: =IFERROR(SMALL(Loans!$Y$6:$Y$305,7),"")
B15: =IF(M15="","",INDEX(Loans!$C$1:$C$305,MOD(M15,1000))) | C15: =IF(M15="","",INDEX(Loans!$Z$1:$Z$305,MOD(M15,1000))) | D15: =IF(M15="","",INDEX(Loans!$P$1:$P$305,MOD(M15,1000))) | E15: =IF(M15="","",INDEX(Loans!$Q$1:$Q$305,MOD(M15,1000))) | G15: =IF(O15="","",INDEX(Loans!$C$1:$C$305,O15)) | H15: =IF(G15="","",SUMIFS(Loans!$O$6:$O$305,Loans!$C$6:$C$305,G15,Loans!$D$6:$D$305,"I lent",Loans!$O$6:$O$305,">0")) | I15: =IF(G15="","",SUMIFS(Loans!$O$6:$O$305,Loans!$C$6:$C$305,G15,Loans!$D$6:$D$305,"I borrowed",Loans!$O$6:$O$305,">0")) | J15: =IF(G15="","",COUNTIFS(Loans!$C$6:$C$305,G15,Loans!$R$6:$R$305,"Open")+COUNTIFS(Loans!$C$6:$C$305,G15,Loans!$R$6:$R$305,"Overdue")+COUNTIFS(Loans!$C$6:$C$305,G15,Loans!$R$6:$R$305,"Due soon")+COUNTIFS(Loans!$C$6:$C$305,G15,Loans!$R$6:$R$305,"On track")) | M15: =IFERROR(SMALL(Loans!$X$6:$X$305,8),"") | N15: =IF(M15="","",INDEX(Loans!$R$1:$R$305,MOD(M15,1000))) | O15: =IFERROR(SMALL(Loans!$Y$6:$Y$305,8),"")
B18: Month | C18: In | D18: Out
B19: =CHOOSE(MONTH(DATE(YEAR(TODAY()),MONTH(TODAY())-11,1)),"Jan","Feb","Mar","Apr","May","Jun","Jul","Aug","Sep","Oct","Nov","Dec")&" "&YEAR(DATE(YEAR(TODAY()),MONTH(TODAY())-11,1)) | C19: =SUMIFS(Payments!$D$6:$D$805,Payments!$I$6:$I$805,"In",Payments!$J$6:$J$805,P19) | D19: =SUMIFS(Payments!$D$6:$D$805,Payments!$I$6:$I$805,"Out",Payments!$J$6:$J$805,P19) | P19: =YEAR(DATE(YEAR(TODAY()),MONTH(TODAY())-11,1))*100+MONTH(DATE(YEAR(TODAY()),MONTH(TODAY())-11,1))
B20: =CHOOSE(MONTH(DATE(YEAR(TODAY()),MONTH(TODAY())-10,1)),"Jan","Feb","Mar","Apr","May","Jun","Jul","Aug","Sep","Oct","Nov","Dec")&" "&YEAR(DATE(YEAR(TODAY()),MONTH(TODAY())-10,1)) | C20: =SUMIFS(Payments!$D$6:$D$805,Payments!$I$6:$I$805,"In",Payments!$J$6:$J$805,P20) | D20: =SUMIFS(Payments!$D$6:$D$805,Payments!$I$6:$I$805,"Out",Payments!$J$6:$J$805,P20) | P20: =YEAR(DATE(YEAR(TODAY()),MONTH(TODAY())-10,1))*100+MONTH(DATE(YEAR(TODAY()),MONTH(TODAY())-10,1))
B21: =CHOOSE(MONTH(DATE(YEAR(TODAY()),MONTH(TODAY())-9,1)),"Jan","Feb","Mar","Apr","May","Jun","Jul","Aug","Sep","Oct","Nov","Dec")&" "&YEAR(DATE(YEAR(TODAY()),MONTH(TODAY())-9,1)) | C21: =SUMIFS(Payments!$D$6:$D$805,Payments!$I$6:$I$805,"In",Payments!$J$6:$J$805,P21) | D21: =SUMIFS(Payments!$D$6:$D$805,Payments!$I$6:$I$805,"Out",Payments!$J$6:$J$805,P21) | P21: =YEAR(DATE(YEAR(TODAY()),MONTH(TODAY())-9,1))*100+MONTH(DATE(YEAR(TODAY()),MONTH(TODAY())-9,1))
B22: =CHOOSE(MONTH(DATE(YEAR(TODAY()),MONTH(TODAY())-8,1)),"Jan","Feb","Mar","Apr","May","Jun","Jul","Aug","Sep","Oct","Nov","Dec")&" "&YEAR(DATE(YEAR(TODAY()),MONTH(TODAY())-8,1)) | C22: =SUMIFS(Payments!$D$6:$D$805,Payments!$I$6:$I$805,"In",Payments!$J$6:$J$805,P22) | D22: =SUMIFS(Payments!$D$6:$D$805,Payments!$I$6:$I$805,"Out",Payments!$J$6:$J$805,P22) | P22: =YEAR(DATE(YEAR(TODAY()),MONTH(TODAY())-8,1))*100+MONTH(DATE(YEAR(TODAY()),MONTH(TODAY())-8,1))
B23: =CHOOSE(MONTH(DATE(YEAR(TODAY()),MONTH(TODAY())-7,1)),"Jan","Feb","Mar","Apr","May","Jun","Jul","Aug","Sep","Oct","Nov","Dec")&" "&YEAR(DATE(YEAR(TODAY()),MONTH(TODAY())-7,1)) | C23: =SUMIFS(Payments!$D$6:$D$805,Payments!$I$6:$I$805,"In",Payments!$J$6:$J$805,P23) | D23: =SUMIFS(Payments!$D$6:$D$805,Payments!$I$6:$I$805,"Out",Payments!$J$6:$J$805,P23) | P23: =YEAR(DATE(YEAR(TODAY()),MONTH(TODAY())-7,1))*100+MONTH(DATE(YEAR(TODAY()),MONTH(TODAY())-7,1))
B24: =CHOOSE(MONTH(DATE(YEAR(TODAY()),MONTH(TODAY())-6,1)),"Jan","Feb","Mar","Apr","May","Jun","Jul","Aug","Sep","Oct","Nov","Dec")&" "&YEAR(DATE(YEAR(TODAY()),MONTH(TODAY())-6,1)) | C24: =SUMIFS(Payments!$D$6:$D$805,Payments!$I$6:$I$805,"In",Payments!$J$6:$J$805,P24) | D24: =SUMIFS(Payments!$D$6:$D$805,Payments!$I$6:$I$805,"Out",Payments!$J$6:$J$805,P24) | P24: =YEAR(DATE(YEAR(TODAY()),MONTH(TODAY())-6,1))*100+MONTH(DATE(YEAR(TODAY()),MONTH(TODAY())-6,1))
B25: =CHOOSE(MONTH(DATE(YEAR(TODAY()),MONTH(TODAY())-5,1)),"Jan","Feb","Mar","Apr","May","Jun","Jul","Aug","Sep","Oct","Nov","Dec")&" "&YEAR(DATE(YEAR(TODAY()),MONTH(TODAY())-5,1)) | C25: =SUMIFS(Payments!$D$6:$D$805,Payments!$I$6:$I$805,"In",Payments!$J$6:$J$805,P25) | D25: =SUMIFS(Payments!$D$6:$D$805,Payments!$I$6:$I$805,"Out",Payments!$J$6:$J$805,P25) | P25: =YEAR(DATE(YEAR(TODAY()),MONTH(TODAY())-5,1))*100+MONTH(DATE(YEAR(TODAY()),MONTH(TODAY())-5,1))
B26: =CHOOSE(MONTH(DATE(YEAR(TODAY()),MONTH(TODAY())-4,1)),"Jan","Feb","Mar","Apr","May","Jun","Jul","Aug","Sep","Oct","Nov","Dec")&" "&YEAR(DATE(YEAR(TODAY()),MONTH(TODAY())-4,1)) | C26: =SUMIFS(Payments!$D$6:$D$805,Payments!$I$6:$I$805,"In",Payments!$J$6:$J$805,P26) | D26: =SUMIFS(Payments!$D$6:$D$805,Payments!$I$6:$I$805,"Out",Payments!$J$6:$J$805,P26) | P26: =YEAR(DATE(YEAR(TODAY()),MONTH(TODAY())-4,1))*100+MONTH(DATE(YEAR(TODAY()),MONTH(TODAY())-4,1))
B27: =CHOOSE(MONTH(DATE(YEAR(TODAY()),MONTH(TODAY())-3,1)),"Jan","Feb","Mar","Apr","May","Jun","Jul","Aug","Sep","Oct","Nov","Dec")&" "&YEAR(DATE(YEAR(TODAY()),MONTH(TODAY())-3,1)) | C27: =SUMIFS(Payments!$D$6:$D$805,Payments!$I$6:$I$805,"In",Payments!$J$6:$J$805,P27) | D27: =SUMIFS(Payments!$D$6:$D$805,Payments!$I$6:$I$805,"Out",Payments!$J$6:$J$805,P27) | P27: =YEAR(DATE(YEAR(TODAY()),MONTH(TODAY())-3,1))*100+MONTH(DATE(YEAR(TODAY()),MONTH(TODAY())-3,1))
B28: =CHOOSE(MONTH(DATE(YEAR(TODAY()),MONTH(TODAY())-2,1)),"Jan","Feb","Mar","Apr","May","Jun","Jul","Aug","Sep","Oct","Nov","Dec")&" "&YEAR(DATE(YEAR(TODAY()),MONTH(TODAY())-2,1)) | C28: =SUMIFS(Payments!$D$6:$D$805,Payments!$I$6:$I$805,"In",Payments!$J$6:$J$805,P28) | D28: =SUMIFS(Payments!$D$6:$D$805,Payments!$I$6:$I$805,"Out",Payments!$J$6:$J$805,P28) | P28: =YEAR(DATE(YEAR(TODAY()),MONTH(TODAY())-2,1))*100+MONTH(DATE(YEAR(TODAY()),MONTH(TODAY())-2,1))
B29: =CHOOSE(MONTH(DATE(YEAR(TODAY()),MONTH(TODAY())-1,1)),"Jan","Feb","Mar","Apr","May","Jun","Jul","Aug","Sep","Oct","Nov","Dec")&" "&YEAR(DATE(YEAR(TODAY()),MONTH(TODAY())-1,1)) | C29: =SUMIFS(Payments!$D$6:$D$805,Payments!$I$6:$I$805,"In",Payments!$J$6:$J$805,P29) | D29: =SUMIFS(Payments!$D$6:$D$805,Payments!$I$6:$I$805,"Out",Payments!$J$6:$J$805,P29) | P29: =YEAR(DATE(YEAR(TODAY()),MONTH(TODAY())-1,1))*100+MONTH(DATE(YEAR(TODAY()),MONTH(TODAY())-1,1))
B30: =CHOOSE(MONTH(DATE(YEAR(TODAY()),MONTH(TODAY())-0,1)),"Jan","Feb","Mar","Apr","May","Jun","Jul","Aug","Sep","Oct","Nov","Dec")&" "&YEAR(DATE(YEAR(TODAY()),MONTH(TODAY())-0,1)) | C30: =SUMIFS(Payments!$D$6:$D$805,Payments!$I$6:$I$805,"In",Payments!$J$6:$J$805,P30) | D30: =SUMIFS(Payments!$D$6:$D$805,Payments!$I$6:$I$805,"Out",Payments!$J$6:$J$805,P30) | P30: =YEAR(DATE(YEAR(TODAY()),MONTH(TODAY())-0,1))*100+MONTH(DATE(YEAR(TODAY()),MONTH(TODAY())-0,1))

Sheet Loans
B2: Loans
B3: Each loan once. A plan is optional: how many payments and how often. Interest is simple, on the amount of the loan.
B5: No. | C5: Person | D5: Who lent | E5: Date | F5: Amount | G5: Interest (% a year) | H5: Payments | I5: Every | J5: First payment | K5: Notes | L5: To repay | M5: Each payment | N5: Paid so far | O5: Still to pay | P5: Next due | Q5: Next amount | R5: Status
B6: 1 | C6: Sam | D6: I lent | E6: 46103 | F6: 500 | H6: 10 | I6: Month | J6: 46113 | K6: Car repair | L6: =IF(C6="","",ROUND(N(F6)*(1+N(G6)/100*IF(N(H6)>0,N(H6)*IF(I6="Week",7/365,IF(I6="2 weeks",14/365,1/12)),IF(ISNUMBER(E6),MAX(0,TODAY()-E6)/365,0))),2)) | M6: =IF(OR(C6="",N(H6)<=0),"",ROUND(L6/N(H6),2)) | N6: =IF(C6="","",SUMIFS(Payments!$D$6:$D$805,Payments!$G$6:$G$805,B6)) | O6: =IF(C6="","",ROUND(L6-N6,2)) | P6: =IF(OR(U6="",N(O6)<=0),"",IF(I6="Week",J6+7*U6,IF(I6="2 weeks",J6+14*U6,EDATE(J6,U6)))) | Q6: =IF(P6="","",IF(U6=N(H6)-1,O6,ROUND(M6*(U6+1)-N6,2))) | R6: =IF(C6="","",IF(O6<=0,"Paid off",IF(OR(M6="",NOT(ISNUMBER(J6))),"Open",IF(W6>0,"Overdue",IF(AND(ISNUMBER(P6),P6-TODAY()<=Settings!$C$6),"Due soon","On track"))))) | S6: =IF(C6="","",B6&" "&C6) | T6: =IF(OR(M6="",NOT(ISNUMBER(J6))),"",MIN(N(H6),IF(I6="Week",IF((TODAY()-1)<J6,0,INT(((TODAY()-1)-J6)/7)+1),IF(I6="2 weeks",IF((TODAY()-1)<J6,0,INT(((TODAY()-1)-J6)/14)+1),IF(((YEAR((TODAY()-1))-YEAR(J6))*12+MONTH((TODAY()-1))-MONTH(J6))<0,0,IF(EDATE(J6,((YEAR((TODAY()-1))-YEAR(J6))*12+MONTH((TODAY()-1))-MONTH(J6)))<=(TODAY()-1),((YEAR((TODAY()-1))-YEAR(J6))*12+MONTH((TODAY()-1))-MONTH(J6))+1,((YEAR((TODAY()-1))-YEAR(J6))*12+MONTH((TODAY()-1))-MONTH(J6)))))))) | U6: =IF(OR(M6="",NOT(ISNUMBER(J6))),"",IF(N(M6)<=0,"",MIN(N(H6)-1,INT(ROUND(N6/M6,6))))) | V6: =IF(T6="","",IF(T6>=N(H6),L6,M6*T6)) | W6: =IF(V6="",0,MAX(0,ROUND(V6-N6,2))) | X6: =IF(OR(R6="",R6="Paid off",NOT(ISNUMBER(P6))),"",P6*1000+ROW()) | Y6: =IF(C6="","",IF(AND(COUNTIF(C$6:C6,C6)=1,SUMIFS(Loans!$O$6:$O$305,Loans!$C$6:$C$305,C6,Loans!$O$6:$O$305,">0")>0),ROW(),"")) | Z6: =IF(OR(C6="",P6=""),"",IF(D6="I borrowed","From you","To you"))
B7: 2 | C7: Priya | D7: I lent | E7: 46056 | F7: 1200 | G7: 3 | H7: 12 | I7: Month | J7: 46096 | K7: Deposit for the flat | L7: =IF(C7="","",ROUND(N(F7)*(1+N(G7)/100*IF(N(H7)>0,N(H7)*IF(I7="Week",7/365,IF(I7="2 weeks",14/365,1/12)),IF(ISNUMBER(E7),MAX(0,TODAY()-E7)/365,0))),2)) | M7: =IF(OR(C7="",N(H7)<=0),"",ROUND(L7/N(H7),2)) | N7: =IF(C7="","",SUMIFS(Payments!$D$6:$D$805,Payments!$G$6:$G$805,B7)) | O7: =IF(C7="","",ROUND(L7-N7,2)) | P7: =IF(OR(U7="",N(O7)<=0),"",IF(I7="Week",J7+7*U7,IF(I7="2 weeks",J7+14*U7,EDATE(J7,U7)))) | Q7: =IF(P7="","",IF(U7=N(H7)-1,O7,ROUND(M7*(U7+1)-N7,2))) | R7: =IF(C7="","",IF(O7<=0,"Paid off",IF(OR(M7="",NOT(ISNUMBER(J7))),"Open",IF(W7>0,"Overdue",IF(AND(ISNUMBER(P7),P7-TODAY()<=Settings!$C$6),"Due soon","On track"))))) | S7: =IF(C7="","",B7&" "&C7) | T7: =IF(OR(M7="",NOT(ISNUMBER(J7))),"",MIN(N(H7),IF(I7="Week",IF((TODAY()-1)<J7,0,INT(((TODAY()-1)-J7)/7)+1),IF(I7="2 weeks",IF((TODAY()-1)<J7,0,INT(((TODAY()-1)-J7)/14)+1),IF(((YEAR((TODAY()-1))-YEAR(J7))*12+MONTH((TODAY()-1))-MONTH(J7))<0,0,IF(EDATE(J7,((YEAR((TODAY()-1))-YEAR(J7))*12+MONTH((TODAY()-1))-MONTH(J7)))<=(TODAY()-1),((YEAR((TODAY()-1))-YEAR(J7))*12+MONTH((TODAY()-1))-MONTH(J7))+1,((YEAR((TODAY()-1))-YEAR(J7))*12+MONTH((TODAY()-1))-MONTH(J7)))))))) | U7: =IF(OR(M7="",NOT(ISNUMBER(J7))),"",IF(N(M7)<=0,"",MIN(N(H7)-1,INT(ROUND(N7/M7,6))))) | V7: =IF(T7="","",IF(T7>=N(H7),L7,M7*T7)) | W7: =IF(V7="",0,MAX(0,ROUND(V7-N7,2))) | X7: =IF(OR(R7="",R7="Paid off",NOT(ISNUMBER(P7))),"",P7*1000+ROW()) | Y7: =IF(C7="","",IF(AND(COUNTIF(C$6:C7,C7)=1,SUMIFS(Loans!$O$6:$O$305,Loans!$C$6:$C$305,C7,Loans!$O$6:$O$305,">0")>0),ROW(),"")) | Z7: =IF(OR(C7="",P7=""),"",IF(D7="I borrowed","From you","To you"))
B8: 3 | C8: Jonah | D8: I lent | E8: 46253 | F8: 80 | K8: Festival ticket | L8: =IF(C8="","",ROUND(N(F8)*(1+N(G8)/100*IF(N(H8)>0,N(H8)*IF(I8="Week",7/365,IF(I8="2 weeks",14/365,1/12)),IF(ISNUMBER(E8),MAX(0,TODAY()-E8)/365,0))),2)) | M8: =IF(OR(C8="",N(H8)<=0),"",ROUND(L8/N(H8),2)) | N8: =IF(C8="","",SUMIFS(Payments!$D$6:$D$805,Payments!$G$6:$G$805,B8)) | O8: =IF(C8="","",ROUND(L8-N8,2)) | P8: =IF(OR(U8="",N(O8)<=0),"",IF(I8="Week",J8+7*U8,IF(I8="2 weeks",J8+14*U8,EDATE(J8,U8)))) | Q8: =IF(P8="","",IF(U8=N(H8)-1,O8,ROUND(M8*(U8+1)-N8,2))) | R8: =IF(C8="","",IF(O8<=0,"Paid off",IF(OR(M8="",NOT(ISNUMBER(J8))),"Open",IF(W8>0,"Overdue",IF(AND(ISNUMBER(P8),P8-TODAY()<=Settings!$C$6),"Due soon","On track"))))) | S8: =IF(C8="","",B8&" "&C8) | T8: =IF(OR(M8="",NOT(ISNUMBER(J8))),"",MIN(N(H8),IF(I8="Week",IF((TODAY()-1)<J8,0,INT(((TODAY()-1)-J8)/7)+1),IF(I8="2 weeks",IF((TODAY()-1)<J8,0,INT(((TODAY()-1)-J8)/14)+1),IF(((YEAR((TODAY()-1))-YEAR(J8))*12+MONTH((TODAY()-1))-MONTH(J8))<0,0,IF(EDATE(J8,((YEAR((TODAY()-1))-YEAR(J8))*12+MONTH((TODAY()-1))-MONTH(J8)))<=(TODAY()-1),((YEAR((TODAY()-1))-YEAR(J8))*12+MONTH((TODAY()-1))-MONTH(J8))+1,((YEAR((TODAY()-1))-YEAR(J8))*12+MONTH((TODAY()-1))-MONTH(J8)))))))) | U8: =IF(OR(M8="",NOT(ISNUMBER(J8))),"",IF(N(M8)<=0,"",MIN(N(H8)-1,INT(ROUND(N8/M8,6))))) | V8: =IF(T8="","",IF(T8>=N(H8),L8,M8*T8)) | W8: =IF(V8="",0,MAX(0,ROUND(V8-N8,2))) | X8: =IF(OR(R8="",R8="Paid off",NOT(ISNUMBER(P8))),"",P8*1000+ROW()) | Y8: =IF(C8="","",IF(AND(COUNTIF(C$6:C8,C8)=1,SUMIFS(Loans!$O$6:$O$305,Loans!$C$6:$C$305,C8,Loans!$O$6:$O$305,">0")>0),ROW(),"")) | Z8: =IF(OR(C8="",P8=""),"",IF(D8="I borrowed","From you","To you"))
B9: 4 | C9: Aunt Rosa | D9: I borrowed | E9: 45962 | F9: 2000 | H9: 20 | I9: Month | J9: 45992 | K9: Laptop for college | L9: =IF(C9="","",ROUND(N(F9)*(1+N(G9)/100*IF(N(H9)>0,N(H9)*IF(I9="Week",7/365,IF(I9="2 weeks",14/365,1/12)),IF(ISNUMBER(E9),MAX(0,TODAY()-E9)/365,0))),2)) | M9: =IF(OR(C9="",N(H9)<=0),"",ROUND(L9/N(H9),2)) | N9: =IF(C9="","",SUMIFS(Payments!$D$6:$D$805,Payments!$G$6:$G$805,B9)) | O9: =IF(C9="","",ROUND(L9-N9,2)) | P9: =IF(OR(U9="",N(O9)<=0),"",IF(I9="Week",J9+7*U9,IF(I9="2 weeks",J9+14*U9,EDATE(J9,U9)))) | Q9: =IF(P9="","",IF(U9=N(H9)-1,O9,ROUND(M9*(U9+1)-N9,2))) | R9: =IF(C9="","",IF(O9<=0,"Paid off",IF(OR(M9="",NOT(ISNUMBER(J9))),"Open",IF(W9>0,"Overdue",IF(AND(ISNUMBER(P9),P9-TODAY()<=Settings!$C$6),"Due soon","On track"))))) | S9: =IF(C9="","",B9&" "&C9) | T9: =IF(OR(M9="",NOT(ISNUMBER(J9))),"",MIN(N(H9),IF(I9="Week",IF((TODAY()-1)<J9,0,INT(((TODAY()-1)-J9)/7)+1),IF(I9="2 weeks",IF((TODAY()-1)<J9,0,INT(((TODAY()-1)-J9)/14)+1),IF(((YEAR((TODAY()-1))-YEAR(J9))*12+MONTH((TODAY()-1))-MONTH(J9))<0,0,IF(EDATE(J9,((YEAR((TODAY()-1))-YEAR(J9))*12+MONTH((TODAY()-1))-MONTH(J9)))<=(TODAY()-1),((YEAR((TODAY()-1))-YEAR(J9))*12+MONTH((TODAY()-1))-MONTH(J9))+1,((YEAR((TODAY()-1))-YEAR(J9))*12+MONTH((TODAY()-1))-MONTH(J9)))))))) | U9: =IF(OR(M9="",NOT(ISNUMBER(J9))),"",IF(N(M9)<=0,"",MIN(N(H9)-1,INT(ROUND(N9/M9,6))))) | V9: =IF(T9="","",IF(T9>=N(H9),L9,M9*T9)) | W9: =IF(V9="",0,MAX(0,ROUND(V9-N9,2))) | X9: =IF(OR(R9="",R9="Paid off",NOT(ISNUMBER(P9))),"",P9*1000+ROW()) | Y9: =IF(C9="","",IF(AND(COUNTIF(C$6:C9,C9)=1,SUMIFS(Loans!$O$6:$O$305,Loans!$C$6:$C$305,C9,Loans!$O$6:$O$305,">0")>0),ROW(),"")) | Z9: =IF(OR(C9="",P9=""),"",IF(D9="I borrowed","From you","To you"))
B10: 5 | C10: Leo | D10: I lent | E10: 46233 | F10: 150 | H10: 3 | I10: 2 weeks | J10: 46247 | L10: =IF(C10="","",ROUND(N(F10)*(1+N(G10)/100*IF(N(H10)>0,N(H10)*IF(I10="Week",7/365,IF(I10="2 weeks",14/365,1/12)),IF(ISNUMBER(E10),MAX(0,TODAY()-E10)/365,0))),2)) | M10: =IF(OR(C10="",N(H10)<=0),"",ROUND(L10/N(H10),2)) | N10: =IF(C10="","",SUMIFS(Payments!$D$6:$D$805,Payments!$G$6:$G$805,B10)) | O10: =IF(C10="","",ROUND(L10-N10,2)) | P10: =IF(OR(U10="",N(O10)<=0),"",IF(I10="Week",J10+7*U10,IF(I10="2 weeks",J10+14*U10,EDATE(J10,U10)))) | Q10: =IF(P10="","",IF(U10=N(H10)-1,O10,ROUND(M10*(U10+1)-N10,2))) | R10: =IF(C10="","",IF(O10<=0,"Paid off",IF(OR(M10="",NOT(ISNUMBER(J10))),"Open",IF(W10>0,"Overdue",IF(AND(ISNUMBER(P10),P10-TODAY()<=Settings!$C$6),"Due soon","On track"))))) | S10: =IF(C10="","",B10&" "&C10) | T10: =IF(OR(M10="",NOT(ISNUMBER(J10))),"",MIN(N(H10),IF(I10="Week",IF((TODAY()-1)<J10,0,INT(((TODAY()-1)-J10)/7)+1),IF(I10="2 weeks",IF((TODAY()-1)<J10,0,INT(((TODAY()-1)-J10)/14)+1),IF(((YEAR((TODAY()-1))-YEAR(J10))*12+MONTH((TODAY()-1))-MONTH(J10))<0,0,IF(EDATE(J10,((YEAR((TODAY()-1))-YEAR(J10))*12+MONTH((TODAY()-1))-MONTH(J10)))<=(TODAY()-1),((YEAR((TODAY()-1))-YEAR(J10))*12+MONTH((TODAY()-1))-MONTH(J10))+1,((YEAR((TODAY()-1))-YEAR(J10))*12+MONTH((TODAY()-1))-MONTH(J10)))))))) | U10: =IF(OR(M10="",NOT(ISNUMBER(J10))),"",IF(N(M10)<=0,"",MIN(N(H10)-1,INT(ROUND(N10/M10,6))))) | V10: =IF(T10="","",IF(T10>=N(H10),L10,M10*T10)) | W10: =IF(V10="",0,MAX(0,ROUND(V10-N10,2))) | X10: =IF(OR(R10="",R10="Paid off",NOT(ISNUMBER(P10))),"",P10*1000+ROW()) | Y10: =IF(C10="","",IF(AND(COUNTIF(C$6:C10,C10)=1,SUMIFS(Loans!$O$6:$O$305,Loans!$C$6:$C$305,C10,Loans!$O$6:$O$305,">0")>0),ROW(),"")) | Z10: =IF(OR(C10="",P10=""),"",IF(D10="I borrowed","From you","To you"))
B11: 6 | C11: Mira | D11: I borrowed | E11: 46284 | F11: 60 | K11: Train tickets | L11: =IF(C11="","",ROUND(N(F11)*(1+N(G11)/100*IF(N(H11)>0,N(H11)*IF(I11="Week",7/365,IF(I11="2 weeks",14/365,1/12)),IF(ISNUMBER(E11),MAX(0,TODAY()-E11)/365,0))),2)) | M11: =IF(OR(C11="",N(H11)<=0),"",ROUND(L11/N(H11),2)) | N11: =IF(C11="","",SUMIFS(Payments!$D$6:$D$805,Payments!$G$6:$G$805,B11)) | O11: =IF(C11="","",ROUND(L11-N11,2)) | P11: =IF(OR(U11="",N(O11)<=0),"",IF(I11="Week",J11+7*U11,IF(I11="2 weeks",J11+14*U11,EDATE(J11,U11)))) | Q11: =IF(P11="","",IF(U11=N(H11)-1,O11,ROUND(M11*(U11+1)-N11,2))) | R11: =IF(C11="","",IF(O11<=0,"Paid off",IF(OR(M11="",NOT(ISNUMBER(J11))),"Open",IF(W11>0,"Overdue",IF(AND(ISNUMBER(P11),P11-TODAY()<=Settings!$C$6),"Due soon","On track"))))) | S11: =IF(C11="","",B11&" "&C11) | T11: =IF(OR(M11="",NOT(ISNUMBER(J11))),"",MIN(N(H11),IF(I11="Week",IF((TODAY()-1)<J11,0,INT(((TODAY()-1)-J11)/7)+1),IF(I11="2 weeks",IF((TODAY()-1)<J11,0,INT(((TODAY()-1)-J11)/14)+1),IF(((YEAR((TODAY()-1))-YEAR(J11))*12+MONTH((TODAY()-1))-MONTH(J11))<0,0,IF(EDATE(J11,((YEAR((TODAY()-1))-YEAR(J11))*12+MONTH((TODAY()-1))-MONTH(J11)))<=(TODAY()-1),((YEAR((TODAY()-1))-YEAR(J11))*12+MONTH((TODAY()-1))-MONTH(J11))+1,((YEAR((TODAY()-1))-YEAR(J11))*12+MONTH((TODAY()-1))-MONTH(J11)))))))) | U11: =IF(OR(M11="",NOT(ISNUMBER(J11))),"",IF(N(M11)<=0,"",MIN(N(H11)-1,INT(ROUND(N11/M11,6))))) | V11: =IF(T11="","",IF(T11>=N(H11),L11,M11*T11)) | W11: =IF(V11="",0,MAX(0,ROUND(V11-N11,2))) | X11: =IF(OR(R11="",R11="Paid off",NOT(ISNUMBER(P11))),"",P11*1000+ROW()) | Y11: =IF(C11="","",IF(AND(COUNTIF(C$6:C11,C11)=1,SUMIFS(Loans!$O$6:$O$305,Loans!$C$6:$C$305,C11,Loans!$O$6:$O$305,">0")>0),ROW(),"")) | Z11: =IF(OR(C11="",P11=""),"",IF(D11="I borrowed","From you","To you"))
B12: 7 | C12: Sam | D12: I lent | E12: 46218 | F12: 40 | K12: Concert | L12: =IF(C12="","",ROUND(N(F12)*(1+N(G12)/100*IF(N(H12)>0,N(H12)*IF(I12="Week",7/365,IF(I12="2 weeks",14/365,1/12)),IF(ISNUMBER(E12),MAX(0,TODAY()-E12)/365,0))),2)) | M12: =IF(OR(C12="",N(H12)<=0),"",ROUND(L12/N(H12),2)) | N12: =IF(C12="","",SUMIFS(Payments!$D$6:$D$805,Payments!$G$6:$G$805,B12)) | O12: =IF(C12="","",ROUND(L12-N12,2)) | P12: =IF(OR(U12="",N(O12)<=0),"",IF(I12="Week",J12+7*U12,IF(I12="2 weeks",J12+14*U12,EDATE(J12,U12)))) | Q12: =IF(P12="","",IF(U12=N(H12)-1,O12,ROUND(M12*(U12+1)-N12,2))) | R12: =IF(C12="","",IF(O12<=0,"Paid off",IF(OR(M12="",NOT(ISNUMBER(J12))),"Open",IF(W12>0,"Overdue",IF(AND(ISNUMBER(P12),P12-TODAY()<=Settings!$C$6),"Due soon","On track"))))) | S12: =IF(C12="","",B12&" "&C12) | T12: =IF(OR(M12="",NOT(ISNUMBER(J12))),"",MIN(N(H12),IF(I12="Week",IF((TODAY()-1)<J12,0,INT(((TODAY()-1)-J12)/7)+1),IF(I12="2 weeks",IF((TODAY()-1)<J12,0,INT(((TODAY()-1)-J12)/14)+1),IF(((YEAR((TODAY()-1))-YEAR(J12))*12+MONTH((TODAY()-1))-MONTH(J12))<0,0,IF(EDATE(J12,((YEAR((TODAY()-1))-YEAR(J12))*12+MONTH((TODAY()-1))-MONTH(J12)))<=(TODAY()-1),((YEAR((TODAY()-1))-YEAR(J12))*12+MONTH((TODAY()-1))-MONTH(J12))+1,((YEAR((TODAY()-1))-YEAR(J12))*12+MONTH((TODAY()-1))-MONTH(J12)))))))) | U12: =IF(OR(M12="",NOT(ISNUMBER(J12))),"",IF(N(M12)<=0,"",MIN(N(H12)-1,INT(ROUND(N12/M12,6))))) | V12: =IF(T12="","",IF(T12>=N(H12),L12,M12*T12)) | W12: =IF(V12="",0,MAX(0,ROUND(V12-N12,2))) | X12: =IF(OR(R12="",R12="Paid off",NOT(ISNUMBER(P12))),"",P12*1000+ROW()) | Y12: =IF(C12="","",IF(AND(COUNTIF(C$6:C12,C12)=1,SUMIFS(Loans!$O$6:$O$305,Loans!$C$6:$C$305,C12,Loans!$O$6:$O$305,">0")>0),ROW(),"")) | Z12: =IF(OR(C12="",P12=""),"",IF(D12="I borrowed","From you","To you"))
B13: 8 | C13: Dev | D13: I lent | E13: 46273 | F13: 240 | H13: 8 | I13: Week | J13: 46280 | K13: Phone screen | L13: =IF(C13="","",ROUND(N(F13)*(1+N(G13)/100*IF(N(H13)>0,N(H13)*IF(I13="Week",7/365,IF(I13="2 weeks",14/365,1/12)),IF(ISNUMBER(E13),MAX(0,TODAY()-E13)/365,0))),2)) | M13: =IF(OR(C13="",N(H13)<=0),"",ROUND(L13/N(H13),2)) | N13: =IF(C13="","",SUMIFS(Payments!$D$6:$D$805,Payments!$G$6:$G$805,B13)) | O13: =IF(C13="","",ROUND(L13-N13,2)) | P13: =IF(OR(U13="",N(O13)<=0),"",IF(I13="Week",J13+7*U13,IF(I13="2 weeks",J13+14*U13,EDATE(J13,U13)))) | Q13: =IF(P13="","",IF(U13=N(H13)-1,O13,ROUND(M13*(U13+1)-N13,2))) | R13: =IF(C13="","",IF(O13<=0,"Paid off",IF(OR(M13="",NOT(ISNUMBER(J13))),"Open",IF(W13>0,"Overdue",IF(AND(ISNUMBER(P13),P13-TODAY()<=Settings!$C$6),"Due soon","On track"))))) | S13: =IF(C13="","",B13&" "&C13) | T13: =IF(OR(M13="",NOT(ISNUMBER(J13))),"",MIN(N(H13),IF(I13="Week",IF((TODAY()-1)<J13,0,INT(((TODAY()-1)-J13)/7)+1),IF(I13="2 weeks",IF((TODAY()-1)<J13,0,INT(((TODAY()-1)-J13)/14)+1),IF(((YEAR((TODAY()-1))-YEAR(J13))*12+MONTH((TODAY()-1))-MONTH(J13))<0,0,IF(EDATE(J13,((YEAR((TODAY()-1))-YEAR(J13))*12+MONTH((TODAY()-1))-MONTH(J13)))<=(TODAY()-1),((YEAR((TODAY()-1))-YEAR(J13))*12+MONTH((TODAY()-1))-MONTH(J13))+1,((YEAR((TODAY()-1))-YEAR(J13))*12+MONTH((TODAY()-1))-MONTH(J13)))))))) | U13: =IF(OR(M13="",NOT(ISNUMBER(J13))),"",IF(N(M13)<=0,"",MIN(N(H13)-1,INT(ROUND(N13/M13,6))))) | V13: =IF(T13="","",IF(T13>=N(H13),L13,M13*T13)) | W13: =IF(V13="",0,MAX(0,ROUND(V13-N13,2))) | X13: =IF(OR(R13="",R13="Paid off",NOT(ISNUMBER(P13))),"",P13*1000+ROW()) | Y13: =IF(C13="","",IF(AND(COUNTIF(C$6:C13,C13)=1,SUMIFS(Loans!$O$6:$O$305,Loans!$C$6:$C$305,C13,Loans!$O$6:$O$305,">0")>0),ROW(),"")) | Z13: =IF(OR(C13="",P13=""),"",IF(D13="I borrowed","From you","To you"))
B14: 9 | L14: =IF(C14="","",ROUND(N(F14)*(1+N(G14)/100*IF(N(H14)>0,N(H14)*IF(I14="Week",7/365,IF(I14="2 weeks",14/365,1/12)),IF(ISNUMBER(E14),MAX(0,TODAY()-E14)/365,0))),2)) | M14: =IF(OR(C14="",N(H14)<=0),"",ROUND(L14/N(H14),2)) | N14: =IF(C14="","",SUMIFS(Payments!$D$6:$D$805,Payments!$G$6:$G$805,B14)) | O14: =IF(C14="","",ROUND(L14-N14,2)) | P14: =IF(OR(U14="",N(O14)<=0),"",IF(I14="Week",J14+7*U14,IF(I14="2 weeks",J14+14*U14,EDATE(J14,U14)))) | Q14: =IF(P14="","",IF(U14=N(H14)-1,O14,ROUND(M14*(U14+1)-N14,2))) | R14: =IF(C14="","",IF(O14<=0,"Paid off",IF(OR(M14="",NOT(ISNUMBER(J14))),"Open",IF(W14>0,"Overdue",IF(AND(ISNUMBER(P14),P14-TODAY()<=Settings!$C$6),"Due soon","On track"))))) | S14: =IF(C14="","",B14&" "&C14) | T14: =IF(OR(M14="",NOT(ISNUMBER(J14))),"",MIN(N(H14),IF(I14="Week",IF((TODAY()-1)<J14,0,INT(((TODAY()-1)-J14)/7)+1),IF(I14="2 weeks",IF((TODAY()-1)<J14,0,INT(((TODAY()-1)-J14)/14)+1),IF(((YEAR((TODAY()-1))-YEAR(J14))*12+MONTH((TODAY()-1))-MONTH(J14))<0,0,IF(EDATE(J14,((YEAR((TODAY()-1))-YEAR(J14))*12+MONTH((TODAY()-1))-MONTH(J14)))<=(TODAY()-1),((YEAR((TODAY()-1))-YEAR(J14))*12+MONTH((TODAY()-1))-MONTH(J14))+1,((YEAR((TODAY()-1))-YEAR(J14))*12+MONTH((TODAY()-1))-MONTH(J14)))))))) | U14: =IF(OR(M14="",NOT(ISNUMBER(J14))),"",IF(N(M14)<=0,"",MIN(N(H14)-1,INT(ROUND(N14/M14,6))))) | V14: =IF(T14="","",IF(T14>=N(H14),L14,M14*T14)) | W14: =IF(V14="",0,MAX(0,ROUND(V14-N14,2))) | X14: =IF(OR(R14="",R14="Paid off",NOT(ISNUMBER(P14))),"",P14*1000+ROW()) | Y14: =IF(C14="","",IF(AND(COUNTIF(C$6:C14,C14)=1,SUMIFS(Loans!$O$6:$O$305,Loans!$C$6:$C$305,C14,Loans!$O$6:$O$305,">0")>0),ROW(),"")) | Z14: =IF(OR(C14="",P14=""),"",IF(D14="I borrowed","From you","To you"))
B15: 10 | L15: =IF(C15="","",ROUND(N(F15)*(1+N(G15)/100*IF(N(H15)>0,N(H15)*IF(I15="Week",7/365,IF(I15="2 weeks",14/365,1/12)),IF(ISNUMBER(E15),MAX(0,TODAY()-E15)/365,0))),2)) | M15: =IF(OR(C15="",N(H15)<=0),"",ROUND(L15/N(H15),2)) | N15: =IF(C15="","",SUMIFS(Payments!$D$6:$D$805,Payments!$G$6:$G$805,B15)) | O15: =IF(C15="","",ROUND(L15-N15,2)) | P15: =IF(OR(U15="",N(O15)<=0),"",IF(I15="Week",J15+7*U15,IF(I15="2 weeks",J15+14*U15,EDATE(J15,U15)))) | Q15: =IF(P15="","",IF(U15=N(H15)-1,O15,ROUND(M15*(U15+1)-N15,2))) | R15: =IF(C15="","",IF(O15<=0,"Paid off",IF(OR(M15="",NOT(ISNUMBER(J15))),"Open",IF(W15>0,"Overdue",IF(AND(ISNUMBER(P15),P15-TODAY()<=Settings!$C$6),"Due soon","On track"))))) | S15: =IF(C15="","",B15&" "&C15) | T15: =IF(OR(M15="",NOT(ISNUMBER(J15))),"",MIN(N(H15),IF(I15="Week",IF((TODAY()-1)<J15,0,INT(((TODAY()-1)-J15)/7)+1),IF(I15="2 weeks",IF((TODAY()-1)<J15,0,INT(((TODAY()-1)-J15)/14)+1),IF(((YEAR((TODAY()-1))-YEAR(J15))*12+MONTH((TODAY()-1))-MONTH(J15))<0,0,IF(EDATE(J15,((YEAR((TODAY()-1))-YEAR(J15))*12+MONTH((TODAY()-1))-MONTH(J15)))<=(TODAY()-1),((YEAR((TODAY()-1))-YEAR(J15))*12+MONTH((TODAY()-1))-MONTH(J15))+1,((YEAR((TODAY()-1))-YEAR(J15))*12+MONTH((TODAY()-1))-MONTH(J15)))))))) | U15: =IF(OR(M15="",NOT(ISNUMBER(J15))),"",IF(N(M15)<=0,"",MIN(N(H15)-1,INT(ROUND(N15/M15,6))))) | V15: =IF(T15="","",IF(T15>=N(H15),L15,M15*T15)) | W15: =IF(V15="",0,MAX(0,ROUND(V15-N15,2))) | X15: =IF(OR(R15="",R15="Paid off",NOT(ISNUMBER(P15))),"",P15*1000+ROW()) | Y15: =IF(C15="","",IF(AND(COUNTIF(C$6:C15,C15)=1,SUMIFS(Loans!$O$6:$O$305,Loans!$C$6:$C$305,C15,Loans!$O$6:$O$305,">0")>0),ROW(),"")) | Z15: =IF(OR(C15="",P15=""),"",IF(D15="I borrowed","From you","To you"))
B16: 11 | L16: =IF(C16="","",ROUND(N(F16)*(1+N(G16)/100*IF(N(H16)>0,N(H16)*IF(I16="Week",7/365,IF(I16="2 weeks",14/365,1/12)),IF(ISNUMBER(E16),MAX(0,TODAY()-E16)/365,0))),2)) | M16: =IF(OR(C16="",N(H16)<=0),"",ROUND(L16/N(H16),2)) | N16: =IF(C16="","",SUMIFS(Payments!$D$6:$D$805,Payments!$G$6:$G$805,B16)) | O16: =IF(C16="","",ROUND(L16-N16,2)) | P16: =IF(OR(U16="",N(O16)<=0),"",IF(I16="Week",J16+7*U16,IF(I16="2 weeks",J16+14*U16,EDATE(J16,U16)))) | Q16: =IF(P16="","",IF(U16=N(H16)-1,O16,ROUND(M16*(U16+1)-N16,2))) | R16: =IF(C16="","",IF(O16<=0,"Paid off",IF(OR(M16="",NOT(ISNUMBER(J16))),"Open",IF(W16>0,"Overdue",IF(AND(ISNUMBER(P16),P16-TODAY()<=Settings!$C$6),"Due soon","On track"))))) | S16: =IF(C16="","",B16&" "&C16) | T16: =IF(OR(M16="",NOT(ISNUMBER(J16))),"",MIN(N(H16),IF(I16="Week",IF((TODAY()-1)<J16,0,INT(((TODAY()-1)-J16)/7)+1),IF(I16="2 weeks",IF((TODAY()-1)<J16,0,INT(((TODAY()-1)-J16)/14)+1),IF(((YEAR((TODAY()-1))-YEAR(J16))*12+MONTH((TODAY()-1))-MONTH(J16))<0,0,IF(EDATE(J16,((YEAR((TODAY()-1))-YEAR(J16))*12+MONTH((TODAY()-1))-MONTH(J16)))<=(TODAY()-1),((YEAR((TODAY()-1))-YEAR(J16))*12+MONTH((TODAY()-1))-MONTH(J16))+1,((YEAR((TODAY()-1))-YEAR(J16))*12+MONTH((TODAY()-1))-MONTH(J16)))))))) | U16: =IF(OR(M16="",NOT(ISNUMBER(J16))),"",IF(N(M16)<=0,"",MIN(N(H16)-1,INT(ROUND(N16/M16,6))))) | V16: =IF(T16="","",IF(T16>=N(H16),L16,M16*T16)) | W16: =IF(V16="",0,MAX(0,ROUND(V16-N16,2))) | X16: =IF(OR(R16="",R16="Paid off",NOT(ISNUMBER(P16))),"",P16*1000+ROW()) | Y16: =IF(C16="","",IF(AND(COUNTIF(C$6:C16,C16)=1,SUMIFS(Loans!$O$6:$O$305,Loans!$C$6:$C$305,C16,Loans!$O$6:$O$305,">0")>0),ROW(),"")) | Z16: =IF(OR(C16="",P16=""),"",IF(D16="I borrowed","From you","To you"))
B17: 12 | L17: =IF(C17="","",ROUND(N(F17)*(1+N(G17)/100*IF(N(H17)>0,N(H17)*IF(I17="Week",7/365,IF(I17="2 weeks",14/365,1/12)),IF(ISNUMBER(E17),MAX(0,TODAY()-E17)/365,0))),2)) | M17: =IF(OR(C17="",N(H17)<=0),"",ROUND(L17/N(H17),2)) | N17: =IF(C17="","",SUMIFS(Payments!$D$6:$D$805,Payments!$G$6:$G$805,B17)) | O17: =IF(C17="","",ROUND(L17-N17,2)) | P17: =IF(OR(U17="",N(O17)<=0),"",IF(I17="Week",J17+7*U17,IF(I17="2 weeks",J17+14*U17,EDATE(J17,U17)))) | Q17: =IF(P17="","",IF(U17=N(H17)-1,O17,ROUND(M17*(U17+1)-N17,2))) | R17: =IF(C17="","",IF(O17<=0,"Paid off",IF(OR(M17="",NOT(ISNUMBER(J17))),"Open",IF(W17>0,"Overdue",IF(AND(ISNUMBER(P17),P17-TODAY()<=Settings!$C$6),"Due soon","On track"))))) | S17: =IF(C17="","",B17&" "&C17) | T17: =IF(OR(M17="",NOT(ISNUMBER(J17))),"",MIN(N(H17),IF(I17="Week",IF((TODAY()-1)<J17,0,INT(((TODAY()-1)-J17)/7)+1),IF(I17="2 weeks",IF((TODAY()-1)<J17,0,INT(((TODAY()-1)-J17)/14)+1),IF(((YEAR((TODAY()-1))-YEAR(J17))*12+MONTH((TODAY()-1))-MONTH(J17))<0,0,IF(EDATE(J17,((YEAR((TODAY()-1))-YEAR(J17))*12+MONTH((TODAY()-1))-MONTH(J17)))<=(TODAY()-1),((YEAR((TODAY()-1))-YEAR(J17))*12+MONTH((TODAY()-1))-MONTH(J17))+1,((YEAR((TODAY()-1))-YEAR(J17))*12+MONTH((TODAY()-1))-MONTH(J17)))))))) | U17: =IF(OR(M17="",NOT(ISNUMBER(J17))),"",IF(N(M17)<=0,"",MIN(N(H17)-1,INT(ROUND(N17/M17,6))))) | V17: =IF(T17="","",IF(T17>=N(H17),L17,M17*T17)) | W17: =IF(V17="",0,MAX(0,ROUND(V17-N17,2))) | X17: =IF(OR(R17="",R17="Paid off",NOT(ISNUMBER(P17))),"",P17*1000+ROW()) | Y17: =IF(C17="","",IF(AND(COUNTIF(C$6:C17,C17)=1,SUMIFS(Loans!$O$6:$O$305,Loans!$C$6:$C$305,C17,Loans!$O$6:$O$305,">0")>0),ROW(),"")) | Z17: =IF(OR(C17="",P17=""),"",IF(D17="I borrowed","From you","To you"))
B18: 13 | L18: =IF(C18="","",ROUND(N(F18)*(1+N(G18)/100*IF(N(H18)>0,N(H18)*IF(I18="Week",7/365,IF(I18="2 weeks",14/365,1/12)),IF(ISNUMBER(E18),MAX(0,TODAY()-E18)/365,0))),2)) | M18: =IF(OR(C18="",N(H18)<=0),"",ROUND(L18/N(H18),2)) | N18: =IF(C18="","",SUMIFS(Payments!$D$6:$D$805,Payments!$G$6:$G$805,B18)) | O18: =IF(C18="","",ROUND(L18-N18,2)) | P18: =IF(OR(U18="",N(O18)<=0),"",IF(I18="Week",J18+7*U18,IF(I18="2 weeks",J18+14*U18,EDATE(J18,U18)))) | Q18: =IF(P18="","",IF(U18=N(H18)-1,O18,ROUND(M18*(U18+1)-N18,2))) | R18: =IF(C18="","",IF(O18<=0,"Paid off",IF(OR(M18="",NOT(ISNUMBER(J18))),"Open",IF(W18>0,"Overdue",IF(AND(ISNUMBER(P18),P18-TODAY()<=Settings!$C$6),"Due soon","On track"))))) | S18: =IF(C18="","",B18&" "&C18) | T18: =IF(OR(M18="",NOT(ISNUMBER(J18))),"",MIN(N(H18),IF(I18="Week",IF((TODAY()-1)<J18,0,INT(((TODAY()-1)-J18)/7)+1),IF(I18="2 weeks",IF((TODAY()-1)<J18,0,INT(((TODAY()-1)-J18)/14)+1),IF(((YEAR((TODAY()-1))-YEAR(J18))*12+MONTH((TODAY()-1))-MONTH(J18))<0,0,IF(EDATE(J18,((YEAR((TODAY()-1))-YEAR(J18))*12+MONTH((TODAY()-1))-MONTH(J18)))<=(TODAY()-1),((YEAR((TODAY()-1))-YEAR(J18))*12+MONTH((TODAY()-1))-MONTH(J18))+1,((YEAR((TODAY()-1))-YEAR(J18))*12+MONTH((TODAY()-1))-MONTH(J18)))))))) | U18: =IF(OR(M18="",NOT(ISNUMBER(J18))),"",IF(N(M18)<=0,"",MIN(N(H18)-1,INT(ROUND(N18/M18,6))))) | V18: =IF(T18="","",IF(T18>=N(H18),L18,M18*T18)) | W18: =IF(V18="",0,MAX(0,ROUND(V18-N18,2))) | X18: =IF(OR(R18="",R18="Paid off",NOT(ISNUMBER(P18))),"",P18*1000+ROW()) | Y18: =IF(C18="","",IF(AND(COUNTIF(C$6:C18,C18)=1,SUMIFS(Loans!$O$6:$O$305,Loans!$C$6:$C$305,C18,Loans!$O$6:$O$305,">0")>0),ROW(),"")) | Z18: =IF(OR(C18="",P18=""),"",IF(D18="I borrowed","From you","To you"))
B19: 14 | L19: =IF(C19="","",ROUND(N(F19)*(1+N(G19)/100*IF(N(H19)>0,N(H19)*IF(I19="Week",7/365,IF(I19="2 weeks",14/365,1/12)),IF(ISNUMBER(E19),MAX(0,TODAY()-E19)/365,0))),2)) | M19: =IF(OR(C19="",N(H19)<=0),"",ROUND(L19/N(H19),2)) | N19: =IF(C19="","",SUMIFS(Payments!$D$6:$D$805,Payments!$G$6:$G$805,B19)) | O19: =IF(C19="","",ROUND(L19-N19,2)) | P19: =IF(OR(U19="",N(O19)<=0),"",IF(I19="Week",J19+7*U19,IF(I19="2 weeks",J19+14*U19,EDATE(J19,U19)))) | Q19: =IF(P19="","",IF(U19=N(H19)-1,O19,ROUND(M19*(U19+1)-N19,2))) | R19: =IF(C19="","",IF(O19<=0,"Paid off",IF(OR(M19="",NOT(ISNUMBER(J19))),"Open",IF(W19>0,"Overdue",IF(AND(ISNUMBER(P19),P19-TODAY()<=Settings!$C$6),"Due soon","On track"))))) | S19: =IF(C19="","",B19&" "&C19) | T19: =IF(OR(M19="",NOT(ISNUMBER(J19))),"",MIN(N(H19),IF(I19="Week",IF((TODAY()-1)<J19,0,INT(((TODAY()-1)-J19)/7)+1),IF(I19="2 weeks",IF((TODAY()-1)<J19,0,INT(((TODAY()-1)-J19)/14)+1),IF(((YEAR((TODAY()-1))-YEAR(J19))*12+MONTH((TODAY()-1))-MONTH(J19))<0,0,IF(EDATE(J19,((YEAR((TODAY()-1))-YEAR(J19))*12+MONTH((TODAY()-1))-MONTH(J19)))<=(TODAY()-1),((YEAR((TODAY()-1))-YEAR(J19))*12+MONTH((TODAY()-1))-MONTH(J19))+1,((YEAR((TODAY()-1))-YEAR(J19))*12+MONTH((TODAY()-1))-MONTH(J19)))))))) | U19: =IF(OR(M19="",NOT(ISNUMBER(J19))),"",IF(N(M19)<=0,"",MIN(N(H19)-1,INT(ROUND(N19/M19,6))))) | V19: =IF(T19="","",IF(T19>=N(H19),L19,M19*T19)) | W19: =IF(V19="",0,MAX(0,ROUND(V19-N19,2))) | X19: =IF(OR(R19="",R19="Paid off",NOT(ISNUMBER(P19))),"",P19*1000+ROW()) | Y19: =IF(C19="","",IF(AND(COUNTIF(C$6:C19,C19)=1,SUMIFS(Loans!$O$6:$O$305,Loans!$C$6:$C$305,C19,Loans!$O$6:$O$305,">0")>0),ROW(),"")) | Z19: =IF(OR(C19="",P19=""),"",IF(D19="I borrowed","From you","To you"))
B20: 15 | L20: =IF(C20="","",ROUND(N(F20)*(1+N(G20)/100*IF(N(H20)>0,N(H20)*IF(I20="Week",7/365,IF(I20="2 weeks",14/365,1/12)),IF(ISNUMBER(E20),MAX(0,TODAY()-E20)/365,0))),2)) | M20: =IF(OR(C20="",N(H20)<=0),"",ROUND(L20/N(H20),2)) | N20: =IF(C20="","",SUMIFS(Payments!$D$6:$D$805,Payments!$G$6:$G$805,B20)) | O20: =IF(C20="","",ROUND(L20-N20,2)) | P20: =IF(OR(U20="",N(O20)<=0),"",IF(I20="Week",J20+7*U20,IF(I20="2 weeks",J20+14*U20,EDATE(J20,U20)))) | Q20: =IF(P20="","",IF(U20=N(H20)-1,O20,ROUND(M20*(U20+1)-N20,2))) | R20: =IF(C20="","",IF(O20<=0,"Paid off",IF(OR(M20="",NOT(ISNUMBER(J20))),"Open",IF(W20>0,"Overdue",IF(AND(ISNUMBER(P20),P20-TODAY()<=Settings!$C$6),"Due soon","On track"))))) | S20: =IF(C20="","",B20&" "&C20) | T20: =IF(OR(M20="",NOT(ISNUMBER(J20))),"",MIN(N(H20),IF(I20="Week",IF((TODAY()-1)<J20,0,INT(((TODAY()-1)-J20)/7)+1),IF(I20="2 weeks",IF((TODAY()-1)<J20,0,INT(((TODAY()-1)-J20)/14)+1),IF(((YEAR((TODAY()-1))-YEAR(J20))*12+MONTH((TODAY()-1))-MONTH(J20))<0,0,IF(EDATE(J20,((YEAR((TODAY()-1))-YEAR(J20))*12+MONTH((TODAY()-1))-MONTH(J20)))<=(TODAY()-1),((YEAR((TODAY()-1))-YEAR(J20))*12+MONTH((TODAY()-1))-MONTH(J20))+1,((YEAR((TODAY()-1))-YEAR(J20))*12+MONTH((TODAY()-1))-MONTH(J20)))))))) | U20: =IF(OR(M20="",NOT(ISNUMBER(J20))),"",IF(N(M20)<=0,"",MIN(N(H20)-1,INT(ROUND(N20/M20,6))))) | V20: =IF(T20="","",IF(T20>=N(H20),L20,M20*T20)) | W20: =IF(V20="",0,MAX(0,ROUND(V20-N20,2))) | X20: =IF(OR(R20="",R20="Paid off",NOT(ISNUMBER(P20))),"",P20*1000+ROW()) | Y20: =IF(C20="","",IF(AND(COUNTIF(C$6:C20,C20)=1,SUMIFS(Loans!$O$6:$O$305,Loans!$C$6:$C$305,C20,Loans!$O$6:$O$305,">0")>0),ROW(),"")) | Z20: =IF(OR(C20="",P20=""),"",IF(D20="I borrowed","From you","To you"))
B21: 16 | L21: =IF(C21="","",ROUND(N(F21)*(1+N(G21)/100*IF(N(H21)>0,N(H21)*IF(I21="Week",7/365,IF(I21="2 weeks",14/365,1/12)),IF(ISNUMBER(E21),MAX(0,TODAY()-E21)/365,0))),2)) | M21: =IF(OR(C21="",N(H21)<=0),"",ROUND(L21/N(H21),2)) | N21: =IF(C21="","",SUMIFS(Payments!$D$6:$D$805,Payments!$G$6:$G$805,B21)) | O21: =IF(C21="","",ROUND(L21-N21,2)) | P21: =IF(OR(U21="",N(O21)<=0),"",IF(I21="Week",J21+7*U21,IF(I21="2 weeks",J21+14*U21,EDATE(J21,U21)))) | Q21: =IF(P21="","",IF(U21=N(H21)-1,O21,ROUND(M21*(U21+1)-N21,2))) | R21: =IF(C21="","",IF(O21<=0,"Paid off",IF(OR(M21="",NOT(ISNUMBER(J21))),"Open",IF(W21>0,"Overdue",IF(AND(ISNUMBER(P21),P21-TODAY()<=Settings!$C$6),"Due soon","On track"))))) | S21: =IF(C21="","",B21&" "&C21) | T21: =IF(OR(M21="",NOT(ISNUMBER(J21))),"",MIN(N(H21),IF(I21="Week",IF((TODAY()-1)<J21,0,INT(((TODAY()-1)-J21)/7)+1),IF(I21="2 weeks",IF((TODAY()-1)<J21,0,INT(((TODAY()-1)-J21)/14)+1),IF(((YEAR((TODAY()-1))-YEAR(J21))*12+MONTH((TODAY()-1))-MONTH(J21))<0,0,IF(EDATE(J21,((YEAR((TODAY()-1))-YEAR(J21))*12+MONTH((TODAY()-1))-MONTH(J21)))<=(TODAY()-1),((YEAR((TODAY()-1))-YEAR(J21))*12+MONTH((TODAY()-1))-MONTH(J21))+1,((YEAR((TODAY()-1))-YEAR(J21))*12+MONTH((TODAY()-1))-MONTH(J21)))))))) | U21: =IF(OR(M21="",NOT(ISNUMBER(J21))),"",IF(N(M21)<=0,"",MIN(N(H21)-1,INT(ROUND(N21/M21,6))))) | V21: =IF(T21="","",IF(T21>=N(H21),L21,M21*T21)) | W21: =IF(V21="",0,MAX(0,ROUND(V21-N21,2))) | X21: =IF(OR(R21="",R21="Paid off",NOT(ISNUMBER(P21))),"",P21*1000+ROW()) | Y21: =IF(C21="","",IF(AND(COUNTIF(C$6:C21,C21)=1,SUMIFS(Loans!$O$6:$O$305,Loans!$C$6:$C$305,C21,Loans!$O$6:$O$305,">0")>0),ROW(),"")) | Z21: =IF(OR(C21="",P21=""),"",IF(D21="I borrowed","From you","To you"))
B22: 17 | L22: =IF(C22="","",ROUND(N(F22)*(1+N(G22)/100*IF(N(H22)>0,N(H22)*IF(I22="Week",7/365,IF(I22="2 weeks",14/365,1/12)),IF(ISNUMBER(E22),MAX(0,TODAY()-E22)/365,0))),2)) | M22: =IF(OR(C22="",N(H22)<=0),"",ROUND(L22/N(H22),2)) | N22: =IF(C22="","",SUMIFS(Payments!$D$6:$D$805,Payments!$G$6:$G$805,B22)) | O22: =IF(C22="","",ROUND(L22-N22,2)) | P22: =IF(OR(U22="",N(O22)<=0),"",IF(I22="Week",J22+7*U22,IF(I22="2 weeks",J22+14*U22,EDATE(J22,U22)))) | Q22: =IF(P22="","",IF(U22=N(H22)-1,O22,ROUND(M22*(U22+1)-N22,2))) | R22: =IF(C22="","",IF(O22<=0,"Paid off",IF(OR(M22="",NOT(ISNUMBER(J22))),"Open",IF(W22>0,"Overdue",IF(AND(ISNUMBER(P22),P22-TODAY()<=Settings!$C$6),"Due soon","On track"))))) | S22: =IF(C22="","",B22&" "&C22) | T22: =IF(OR(M22="",NOT(ISNUMBER(J22))),"",MIN(N(H22),IF(I22="Week",IF((TODAY()-1)<J22,0,INT(((TODAY()-1)-J22)/7)+1),IF(I22="2 weeks",IF((TODAY()-1)<J22,0,INT(((TODAY()-1)-J22)/14)+1),IF(((YEAR((TODAY()-1))-YEAR(J22))*12+MONTH((TODAY()-1))-MONTH(J22))<0,0,IF(EDATE(J22,((YEAR((TODAY()-1))-YEAR(J22))*12+MONTH((TODAY()-1))-MONTH(J22)))<=(TODAY()-1),((YEAR((TODAY()-1))-YEAR(J22))*12+MONTH((TODAY()-1))-MONTH(J22))+1,((YEAR((TODAY()-1))-YEAR(J22))*12+MONTH((TODAY()-1))-MONTH(J22)))))))) | U22: =IF(OR(M22="",NOT(ISNUMBER(J22))),"",IF(N(M22)<=0,"",MIN(N(H22)-1,INT(ROUND(N22/M22,6))))) | V22: =IF(T22="","",IF(T22>=N(H22),L22,M22*T22)) | W22: =IF(V22="",0,MAX(0,ROUND(V22-N22,2))) | X22: =IF(OR(R22="",R22="Paid off",NOT(ISNUMBER(P22))),"",P22*1000+ROW()) | Y22: =IF(C22="","",IF(AND(COUNTIF(C$6:C22,C22)=1,SUMIFS(Loans!$O$6:$O$305,Loans!$C$6:$C$305,C22,Loans!$O$6:$O$305,">0")>0),ROW(),"")) | Z22: =IF(OR(C22="",P22=""),"",IF(D22="I borrowed","From you","To you"))
B23: 18 | L23: =IF(C23="","",ROUND(N(F23)*(1+N(G23)/100*IF(N(H23)>0,N(H23)*IF(I23="Week",7/365,IF(I23="2 weeks",14/365,1/12)),IF(ISNUMBER(E23),MAX(0,TODAY()-E23)/365,0))),2)) | M23: =IF(OR(C23="",N(H23)<=0),"",ROUND(L23/N(H23),2)) | N23: =IF(C23="","",SUMIFS(Payments!$D$6:$D$805,Payments!$G$6:$G$805,B23)) | O23: =IF(C23="","",ROUND(L23-N23,2)) | P23: =IF(OR(U23="",N(O23)<=0),"",IF(I23="Week",J23+7*U23,IF(I23="2 weeks",J23+14*U23,EDATE(J23,U23)))) | Q23: =IF(P23="","",IF(U23=N(H23)-1,O23,ROUND(M23*(U23+1)-N23,2))) | R23: =IF(C23="","",IF(O23<=0,"Paid off",IF(OR(M23="",NOT(ISNUMBER(J23))),"Open",IF(W23>0,"Overdue",IF(AND(ISNUMBER(P23),P23-TODAY()<=Settings!$C$6),"Due soon","On track"))))) | S23: =IF(C23="","",B23&" "&C23) | T23: =IF(OR(M23="",NOT(ISNUMBER(J23))),"",MIN(N(H23),IF(I23="Week",IF((TODAY()-1)<J23,0,INT(((TODAY()-1)-J23)/7)+1),IF(I23="2 weeks",IF((TODAY()-1)<J23,0,INT(((TODAY()-1)-J23)/14)+1),IF(((YEAR((TODAY()-1))-YEAR(J23))*12+MONTH((TODAY()-1))-MONTH(J23))<0,0,IF(EDATE(J23,((YEAR((TODAY()-1))-YEAR(J23))*12+MONTH((TODAY()-1))-MONTH(J23)))<=(TODAY()-1),((YEAR((TODAY()-1))-YEAR(J23))*12+MONTH((TODAY()-1))-MONTH(J23))+1,((YEAR((TODAY()-1))-YEAR(J23))*12+MONTH((TODAY()-1))-MONTH(J23)))))))) | U23: =IF(OR(M23="",NOT(ISNUMBER(J23))),"",IF(N(M23)<=0,"",MIN(N(H23)-1,INT(ROUND(N23/M23,6))))) | V23: =IF(T23="","",IF(T23>=N(H23),L23,M23*T23)) | W23: =IF(V23="",0,MAX(0,ROUND(V23-N23,2))) | X23: =IF(OR(R23="",R23="Paid off",NOT(ISNUMBER(P23))),"",P23*1000+ROW()) | Y23: =IF(C23="","",IF(AND(COUNTIF(C$6:C23,C23)=1,SUMIFS(Loans!$O$6:$O$305,Loans!$C$6:$C$305,C23,Loans!$O$6:$O$305,">0")>0),ROW(),"")) | Z23: =IF(OR(C23="",P23=""),"",IF(D23="I borrowed","From you","To you"))
B24: 19 | L24: =IF(C24="","",ROUND(N(F24)*(1+N(G24)/100*IF(N(H24)>0,N(H24)*IF(I24="Week",7/365,IF(I24="2 weeks",14/365,1/12)),IF(ISNUMBER(E24),MAX(0,TODAY()-E24)/365,0))),2)) | M24: =IF(OR(C24="",N(H24)<=0),"",ROUND(L24/N(H24),2)) | N24: =IF(C24="","",SUMIFS(Payments!$D$6:$D$805,Payments!$G$6:$G$805,B24)) | O24: =IF(C24="","",ROUND(L24-N24,2)) | P24: =IF(OR(U24="",N(O24)<=0),"",IF(I24="Week",J24+7*U24,IF(I24="2 weeks",J24+14*U24,EDATE(J24,U24)))) | Q24: =IF(P24="","",IF(U24=N(H24)-1,O24,ROUND(M24*(U24+1)-N24,2))) | R24: =IF(C24="","",IF(O24<=0,"Paid off",IF(OR(M24="",NOT(ISNUMBER(J24))),"Open",IF(W24>0,"Overdue",IF(AND(ISNUMBER(P24),P24-TODAY()<=Settings!$C$6),"Due soon","On track"))))) | S24: =IF(C24="","",B24&" "&C24) | T24: =IF(OR(M24="",NOT(ISNUMBER(J24))),"",MIN(N(H24),IF(I24="Week",IF((TODAY()-1)<J24,0,INT(((TODAY()-1)-J24)/7)+1),IF(I24="2 weeks",IF((TODAY()-1)<J24,0,INT(((TODAY()-1)-J24)/14)+1),IF(((YEAR((TODAY()-1))-YEAR(J24))*12+MONTH((TODAY()-1))-MONTH(J24))<0,0,IF(EDATE(J24,((YEAR((TODAY()-1))-YEAR(J24))*12+MONTH((TODAY()-1))-MONTH(J24)))<=(TODAY()-1),((YEAR((TODAY()-1))-YEAR(J24))*12+MONTH((TODAY()-1))-MONTH(J24))+1,((YEAR((TODAY()-1))-YEAR(J24))*12+MONTH((TODAY()-1))-MONTH(J24)))))))) | U24: =IF(OR(M24="",NOT(ISNUMBER(J24))),"",IF(N(M24)<=0,"",MIN(N(H24)-1,INT(ROUND(N24/M24,6))))) | V24: =IF(T24="","",IF(T24>=N(H24),L24,M24*T24)) | W24: =IF(V24="",0,MAX(0,ROUND(V24-N24,2))) | X24: =IF(OR(R24="",R24="Paid off",NOT(ISNUMBER(P24))),"",P24*1000+ROW()) | Y24: =IF(C24="","",IF(AND(COUNTIF(C$6:C24,C24)=1,SUMIFS(Loans!$O$6:$O$305,Loans!$C$6:$C$305,C24,Loans!$O$6:$O$305,">0")>0),ROW(),"")) | Z24: =IF(OR(C24="",P24=""),"",IF(D24="I borrowed","From you","To you"))
B25: 20 | L25: =IF(C25="","",ROUND(N(F25)*(1+N(G25)/100*IF(N(H25)>0,N(H25)*IF(I25="Week",7/365,IF(I25="2 weeks",14/365,1/12)),IF(ISNUMBER(E25),MAX(0,TODAY()-E25)/365,0))),2)) | M25: =IF(OR(C25="",N(H25)<=0),"",ROUND(L25/N(H25),2)) | N25: =IF(C25="","",SUMIFS(Payments!$D$6:$D$805,Payments!$G$6:$G$805,B25)) | O25: =IF(C25="","",ROUND(L25-N25,2)) | P25: =IF(OR(U25="",N(O25)<=0),"",IF(I25="Week",J25+7*U25,IF(I25="2 weeks",J25+14*U25,EDATE(J25,U25)))) | Q25: =IF(P25="","",IF(U25=N(H25)-1,O25,ROUND(M25*(U25+1)-N25,2))) | R25: =IF(C25="","",IF(O25<=0,"Paid off",IF(OR(M25="",NOT(ISNUMBER(J25))),"Open",IF(W25>0,"Overdue",IF(AND(ISNUMBER(P25),P25-TODAY()<=Settings!$C$6),"Due soon","On track"))))) | S25: =IF(C25="","",B25&" "&C25) | T25: =IF(OR(M25="",NOT(ISNUMBER(J25))),"",MIN(N(H25),IF(I25="Week",IF((TODAY()-1)<J25,0,INT(((TODAY()-1)-J25)/7)+1),IF(I25="2 weeks",IF((TODAY()-1)<J25,0,INT(((TODAY()-1)-J25)/14)+1),IF(((YEAR((TODAY()-1))-YEAR(J25))*12+MONTH((TODAY()-1))-MONTH(J25))<0,0,IF(EDATE(J25,((YEAR((TODAY()-1))-YEAR(J25))*12+MONTH((TODAY()-1))-MONTH(J25)))<=(TODAY()-1),((YEAR((TODAY()-1))-YEAR(J25))*12+MONTH((TODAY()-1))-MONTH(J25))+1,((YEAR((TODAY()-1))-YEAR(J25))*12+MONTH((TODAY()-1))-MONTH(J25)))))))) | U25: =IF(OR(M25="",NOT(ISNUMBER(J25))),"",IF(N(M25)<=0,"",MIN(N(H25)-1,INT(ROUND(N25/M25,6))))) | V25: =IF(T25="","",IF(T25>=N(H25),L25,M25*T25)) | W25: =IF(V25="",0,MAX(0,ROUND(V25-N25,2))) | X25: =IF(OR(R25="",R25="Paid off",NOT(ISNUMBER(P25))),"",P25*1000+ROW()) | Y25: =IF(C25="","",IF(AND(COUNTIF(C$6:C25,C25)=1,SUMIFS(Loans!$O$6:$O$305,Loans!$C$6:$C$305,C25,Loans!$O$6:$O$305,">0")>0),ROW(),"")) | Z25: =IF(OR(C25="",P25=""),"",IF(D25="I borrowed","From you","To you"))
... B305: 300 | L305: =IF(C305="","",ROUND(N(F305)*(1+N(G305)/100*IF(N(H305)>0,N(H305)*IF(I305="Week",7/365,IF(I305="2 weeks",14/365,1/12)),IF(ISNUMBER(E305),MAX(0,TODAY()-E305)/365,0))),2)) | M305: =IF(OR(C305="",N(H305)<=0),"",ROUND(L305/N(H305),2)) | N305: =IF(C305="","",SUMIFS(Payments!$D$6:$D$805,Payments!$G$6:$G$805,B305)) | O305: =IF(C305="","",ROUND(L305-N305,2)) | P305: =IF(OR(U305="",N(O305)<=0),"",IF(I305="Week",J305+7*U305,IF(I305="2 weeks",J305+14*U305,EDATE(J305,U305)))) | Q305: =IF(P305="","",IF(U305=N(H305)-1,O305,ROUND(M305*(U305+1)-N305,2))) | R305: =IF(C305="","",IF(O305<=0,"Paid off",IF(OR(M305="",NOT(ISNUMBER(J305))),"Open",IF(W305>0,"Overdue",IF(AND(ISNUMBER(P305),P305-TODAY()<=Settings!$C$6),"Due soon","On track"))))) | S305: =IF(C305="","",B305&" "&C305) | T305: =IF(OR(M305="",NOT(ISNUMBER(J305))),"",MIN(N(H305),IF(I305="Week",IF((TODAY()-1)<J305,0,INT(((TODAY()-1)-J305)/7)+1),IF(I305="2 weeks",IF((TODAY()-1)<J305,0,INT(((TODAY()-1)-J305)/14)+1),IF(((YEAR((TODAY()-1))-YEAR(J305))*12+MONTH((TODAY()-1))-MONTH(J305))<0,0,IF(EDATE(J305,((YEAR((TODAY()-1))-YEAR(J305))*12+MONTH((TODAY()-1))-MONTH(J305)))<=(TODAY()-1),((YEAR((TODAY()-1))-YEAR(J305))*12+MONTH((TODAY()-1))-MONTH(J305))+1,((YEAR((TODAY()-1))-YEAR(J305))*12+MONTH((TODAY()-1))-MONTH(J305)))))))) | U305: =IF(OR(M305="",NOT(ISNUMBER(J305))),"",IF(N(M305)<=0,"",MIN(N(H305)-1,INT(ROUND(N305/M305,6))))) | V305: =IF(T305="","",IF(T305>=N(H305),L305,M305*T305)) | W305: =IF(V305="",0,MAX(0,ROUND(V305-N305,2))) | X305: =IF(OR(R305="",R305="Paid off",NOT(ISNUMBER(P305))),"",P305*1000+ROW()) | Y305: =IF(C305="","",IF(AND(COUNTIF(C$6:C305,C305)=1,SUMIFS(Loans!$O$6:$O$305,Loans!$C$6:$C$305,C305,Loans!$O$6:$O$305,">0")>0),ROW(),"")) | Z305: =IF(OR(C305="",P305=""),"",IF(D305="I borrowed","From you","To you"))

Sheet Payments
B2: Payments
B3: Every payment, whichever way it goes. Pick the loan by its number and name.
B5: Date | C5: Loan | D5: Amount | E5: How | F5: Note | G5: No. | H5: Person | I5: Way
B6: 45992 | C6: 4 Aunt Rosa | D6: 100 | E6: Bank transfer | G6: =IF(C6="","",IFERROR(VALUE(LEFT(C6,FIND(" ",C6&" ")-1)),"")) | H6: =IF(C6="","",IF(G6="","Pick a loan",IFERROR(IF(INDEX(Loans!$C$6:$C$305,MATCH(G6,Loans!$B$6:$B$305,0))="","Not a loan",INDEX(Loans!$C$6:$C$305,MATCH(G6,Loans!$B$6:$B$305,0))),"Not a loan"))) | I6: =IF(OR(G6="",H6="Not a loan"),"",IF(INDEX(Loans!$D$6:$D$305,MATCH(G6,Loans!$B$6:$B$305,0))="I borrowed","Out","In")) | J6: =IF(NOT(ISNUMBER(B6)),"",YEAR(B6)*100+MONTH(B6)) | K6: =IF(OR(G6="",NOT(ISNUMBER(B6))),"",IF(G6=Statement!$H$2,B6*1000+ROW(),""))
B7: 46023 | C7: 4 Aunt Rosa | D7: 100 | E7: Bank transfer | G7: =IF(C7="","",IFERROR(VALUE(LEFT(C7,FIND(" ",C7&" ")-1)),"")) | H7: =IF(C7="","",IF(G7="","Pick a loan",IFERROR(IF(INDEX(Loans!$C$6:$C$305,MATCH(G7,Loans!$B$6:$B$305,0))="","Not a loan",INDEX(Loans!$C$6:$C$305,MATCH(G7,Loans!$B$6:$B$305,0))),"Not a loan"))) | I7: =IF(OR(G7="",H7="Not a loan"),"",IF(INDEX(Loans!$D$6:$D$305,MATCH(G7,Loans!$B$6:$B$305,0))="I borrowed","Out","In")) | J7: =IF(NOT(ISNUMBER(B7)),"",YEAR(B7)*100+MONTH(B7)) | K7: =IF(OR(G7="",NOT(ISNUMBER(B7))),"",IF(G7=Statement!$H$2,B7*1000+ROW(),""))
B8: 46054 | C8: 4 Aunt Rosa | D8: 100 | E8: Bank transfer | G8: =IF(C8="","",IFERROR(VALUE(LEFT(C8,FIND(" ",C8&" ")-1)),"")) | H8: =IF(C8="","",IF(G8="","Pick a loan",IFERROR(IF(INDEX(Loans!$C$6:$C$305,MATCH(G8,Loans!$B$6:$B$305,0))="","Not a loan",INDEX(Loans!$C$6:$C$305,MATCH(G8,Loans!$B$6:$B$305,0))),"Not a loan"))) | I8: =IF(OR(G8="",H8="Not a loan"),"",IF(INDEX(Loans!$D$6:$D$305,MATCH(G8,Loans!$B$6:$B$305,0))="I borrowed","Out","In")) | J8: =IF(NOT(ISNUMBER(B8)),"",YEAR(B8)*100+MONTH(B8)) | K8: =IF(OR(G8="",NOT(ISNUMBER(B8))),"",IF(G8=Statement!$H$2,B8*1000+ROW(),""))
B9: 46082 | C9: 4 Aunt Rosa | D9: 100 | E9: Bank transfer | G9: =IF(C9="","",IFERROR(VALUE(LEFT(C9,FIND(" ",C9&" ")-1)),"")) | H9: =IF(C9="","",IF(G9="","Pick a loan",IFERROR(IF(INDEX(Loans!$C$6:$C$305,MATCH(G9,Loans!$B$6:$B$305,0))="","Not a loan",INDEX(Loans!$C$6:$C$305,MATCH(G9,Loans!$B$6:$B$305,0))),"Not a loan"))) | I9: =IF(OR(G9="",H9="Not a loan"),"",IF(INDEX(Loans!$D$6:$D$305,MATCH(G9,Loans!$B$6:$B$305,0))="I borrowed","Out","In")) | J9: =IF(NOT(ISNUMBER(B9)),"",YEAR(B9)*100+MONTH(B9)) | K9: =IF(OR(G9="",NOT(ISNUMBER(B9))),"",IF(G9=Statement!$H$2,B9*1000+ROW(),""))
B10: 46096 | C10: 2 Priya | D10: 103 | E10: Bank transfer | G10: =IF(C10="","",IFERROR(VALUE(LEFT(C10,FIND(" ",C10&" ")-1)),"")) | H10: =IF(C10="","",IF(G10="","Pick a loan",IFERROR(IF(INDEX(Loans!$C$6:$C$305,MATCH(G10,Loans!$B$6:$B$305,0))="","Not a loan",INDEX(Loans!$C$6:$C$305,MATCH(G10,Loans!$B$6:$B$305,0))),"Not a loan"))) | I10: =IF(OR(G10="",H10="Not a loan"),"",IF(INDEX(Loans!$D$6:$D$305,MATCH(G10,Loans!$B$6:$B$305,0))="I borrowed","Out","In")) | J10: =IF(NOT(ISNUMBER(B10)),"",YEAR(B10)*100+MONTH(B10)) | K10: =IF(OR(G10="",NOT(ISNUMBER(B10))),"",IF(G10=Statement!$H$2,B10*1000+ROW(),""))
B11: 46113 | C11: 4 Aunt Rosa | D11: 100 | E11: Bank transfer | G11: =IF(C11="","",IFERROR(VALUE(LEFT(C11,FIND(" ",C11&" ")-1)),"")) | H11: =IF(C11="","",IF(G11="","Pick a loan",IFERROR(IF(INDEX(Loans!$C$6:$C$305,MATCH(G11,Loans!$B$6:$B$305,0))="","Not a loan",INDEX(Loans!$C$6:$C$305,MATCH(G11,Loans!$B$6:$B$305,0))),"Not a loan"))) | I11: =IF(OR(G11="",H11="Not a loan"),"",IF(INDEX(Loans!$D$6:$D$305,MATCH(G11,Loans!$B$6:$B$305,0))="I borrowed","Out","In")) | J11: =IF(NOT(ISNUMBER(B11)),"",YEAR(B11)*100+MONTH(B11)) | K11: =IF(OR(G11="",NOT(ISNUMBER(B11))),"",IF(G11=Statement!$H$2,B11*1000+ROW(),""))
B12: 46114 | C12: 1 Sam | D12: 50 | E12: Bank transfer | G12: =IF(C12="","",IFERROR(VALUE(LEFT(C12,FIND(" ",C12&" ")-1)),"")) | H12: =IF(C12="","",IF(G12="","Pick a loan",IFERROR(IF(INDEX(Loans!$C$6:$C$305,MATCH(G12,Loans!$B$6:$B$305,0))="","Not a loan",INDEX(Loans!$C$6:$C$305,MATCH(G12,Loans!$B$6:$B$305,0))),"Not a loan"))) | I12: =IF(OR(G12="",H12="Not a loan"),"",IF(INDEX(Loans!$D$6:$D$305,MATCH(G12,Loans!$B$6:$B$305,0))="I borrowed","Out","In")) | J12: =IF(NOT(ISNUMBER(B12)),"",YEAR(B12)*100+MONTH(B12)) | K12: =IF(OR(G12="",NOT(ISNUMBER(B12))),"",IF(G12=Statement!$H$2,B12*1000+ROW(),""))
B13: 46127 | C13: 2 Priya | D13: 103 | E13: Bank transfer | G13: =IF(C13="","",IFERROR(VALUE(LEFT(C13,FIND(" ",C13&" ")-1)),"")) | H13: =IF(C13="","",IF(G13="","Pick a loan",IFERROR(IF(INDEX(Loans!$C$6:$C$305,MATCH(G13,Loans!$B$6:$B$305,0))="","Not a loan",INDEX(Loans!$C$6:$C$305,MATCH(G13,Loans!$B$6:$B$305,0))),"Not a loan"))) | I13: =IF(OR(G13="",H13="Not a loan"),"",IF(INDEX(Loans!$D$6:$D$305,MATCH(G13,Loans!$B$6:$B$305,0))="I borrowed","Out","In")) | J13: =IF(NOT(ISNUMBER(B13)),"",YEAR(B13)*100+MONTH(B13)) | K13: =IF(OR(G13="",NOT(ISNUMBER(B13))),"",IF(G13=Statement!$H$2,B13*1000+ROW(),""))
B14: 46143 | C14: 4 Aunt Rosa | D14: 100 | E14: Bank transfer | G14: =IF(C14="","",IFERROR(VALUE(LEFT(C14,FIND(" ",C14&" ")-1)),"")) | H14: =IF(C14="","",IF(G14="","Pick a loan",IFERROR(IF(INDEX(Loans!$C$6:$C$305,MATCH(G14,Loans!$B$6:$B$305,0))="","Not a loan",INDEX(Loans!$C$6:$C$305,MATCH(G14,Loans!$B$6:$B$305,0))),"Not a loan"))) | I14: =IF(OR(G14="",H14="Not a loan"),"",IF(INDEX(Loans!$D$6:$D$305,MATCH(G14,Loans!$B$6:$B$305,0))="I borrowed","Out","In")) | J14: =IF(NOT(ISNUMBER(B14)),"",YEAR(B14)*100+MONTH(B14)) | K14: =IF(OR(G14="",NOT(ISNUMBER(B14))),"",IF(G14=Statement!$H$2,B14*1000+ROW(),""))
B15: 46144 | C15: 1 Sam | D15: 50 | E15: Bank transfer | G15: =IF(C15="","",IFERROR(VALUE(LEFT(C15,FIND(" ",C15&" ")-1)),"")) | H15: =IF(C15="","",IF(G15="","Pick a loan",IFERROR(IF(INDEX(Loans!$C$6:$C$305,MATCH(G15,Loans!$B$6:$B$305,0))="","Not a loan",INDEX(Loans!$C$6:$C$305,MATCH(G15,Loans!$B$6:$B$305,0))),"Not a loan"))) | I15: =IF(OR(G15="",H15="Not a loan"),"",IF(INDEX(Loans!$D$6:$D$305,MATCH(G15,Loans!$B$6:$B$305,0))="I borrowed","Out","In")) | J15: =IF(NOT(ISNUMBER(B15)),"",YEAR(B15)*100+MONTH(B15)) | K15: =IF(OR(G15="",NOT(ISNUMBER(B15))),"",IF(G15=Statement!$H$2,B15*1000+ROW(),""))
B16: 46157 | C16: 2 Priya | D16: 103 | E16: Bank transfer | G16: =IF(C16="","",IFERROR(VALUE(LEFT(C16,FIND(" ",C16&" ")-1)),"")) | H16: =IF(C16="","",IF(G16="","Pick a loan",IFERROR(IF(INDEX(Loans!$C$6:$C$305,MATCH(G16,Loans!$B$6:$B$305,0))="","Not a loan",INDEX(Loans!$C$6:$C$305,MATCH(G16,Loans!$B$6:$B$305,0))),"Not a loan"))) | I16: =IF(OR(G16="",H16="Not a loan"),"",IF(INDEX(Loans!$D$6:$D$305,MATCH(G16,Loans!$B$6:$B$305,0))="I borrowed","Out","In")) | J16: =IF(NOT(ISNUMBER(B16)),"",YEAR(B16)*100+MONTH(B16)) | K16: =IF(OR(G16="",NOT(ISNUMBER(B16))),"",IF(G16=Statement!$H$2,B16*1000+ROW(),""))
B17: 46174 | C17: 4 Aunt Rosa | D17: 100 | E17: Bank transfer | G17: =IF(C17="","",IFERROR(VALUE(LEFT(C17,FIND(" ",C17&" ")-1)),"")) | H17: =IF(C17="","",IF(G17="","Pick a loan",IFERROR(IF(INDEX(Loans!$C$6:$C$305,MATCH(G17,Loans!$B$6:$B$305,0))="","Not a loan",INDEX(Loans!$C$6:$C$305,MATCH(G17,Loans!$B$6:$B$305,0))),"Not a loan"))) | I17: =IF(OR(G17="",H17="Not a loan"),"",IF(INDEX(Loans!$D$6:$D$305,MATCH(G17,Loans!$B$6:$B$305,0))="I borrowed","Out","In")) | J17: =IF(NOT(ISNUMBER(B17)),"",YEAR(B17)*100+MONTH(B17)) | K17: =IF(OR(G17="",NOT(ISNUMBER(B17))),"",IF(G17=Statement!$H$2,B17*1000+ROW(),""))
... B27: 46261 | C27: 5 Leo | D27: 50 | E27: App | G27: =IF(C27="","",IFERROR(VALUE(LEFT(C27,FIND(" ",C27&" ")-1)),"")) | H27: =IF(C27="","",IF(G27="","Pick a loan",IFERROR(IF(INDEX(Loans!$C$6:$C$305,MATCH(G27,Loans!$B$6:$B$305,0))="","Not a loan",INDEX(Loans!$C$6:$C$305,MATCH(G27,Loans!$B$6:$B$305,0))),"Not a loan"))) | I27: =IF(OR(G27="",H27="Not a loan"),"",IF(INDEX(Loans!$D$6:$D$305,MATCH(G27,Loans!$B$6:$B$305,0))="I borrowed","Out","In")) | J27: =IF(NOT(ISNUMBER(B27)),"",YEAR(B27)*100+MONTH(B27)) | K27: =IF(OR(G27="",NOT(ISNUMBER(B27))),"",IF(G27=Statement!$H$2,B27*1000+ROW(),""))
B28: 46263 | C28: 3 Jonah | D28: 30 | E28: Cash | F28: Paid part at the pub | G28: =IF(C28="","",IFERROR(VALUE(LEFT(C28,FIND(" ",C28&" ")-1)),"")) | H28: =IF(C28="","",IF(G28="","Pick a loan",IFERROR(IF(INDEX(Loans!$C$6:$C$305,MATCH(G28,Loans!$B$6:$B$305,0))="","Not a loan",INDEX(Loans!$C$6:$C$305,MATCH(G28,Loans!$B$6:$B$305,0))),"Not a loan"))) | I28: =IF(OR(G28="",H28="Not a loan"),"",IF(INDEX(Loans!$D$6:$D$305,MATCH(G28,Loans!$B$6:$B$305,0))="I borrowed","Out","In")) | J28: =IF(NOT(ISNUMBER(B28)),"",YEAR(B28)*100+MONTH(B28)) | K28: =IF(OR(G28="",NOT(ISNUMBER(B28))),"",IF(G28=Statement!$H$2,B28*1000+ROW(),""))
B29: 46266 | C29: 4 Aunt Rosa | D29: 100 | E29: Bank transfer | G29: =IF(C29="","",IFERROR(VALUE(LEFT(C29,FIND(" ",C29&" ")-1)),"")) | H29: =IF(C29="","",IF(G29="","Pick a loan",IFERROR(IF(INDEX(Loans!$C$6:$C$305,MATCH(G29,Loans!$B$6:$B$305,0))="","Not a loan",INDEX(Loans!$C$6:$C$305,MATCH(G29,Loans!$B$6:$B$305,0))),"Not a loan"))) | I29: =IF(OR(G29="",H29="Not a loan"),"",IF(INDEX(Loans!$D$6:$D$305,MATCH(G29,Loans!$B$6:$B$305,0))="I borrowed","Out","In")) | J29: =IF(NOT(ISNUMBER(B29)),"",YEAR(B29)*100+MONTH(B29)) | K29: =IF(OR(G29="",NOT(ISNUMBER(B29))),"",IF(G29=Statement!$H$2,B29*1000+ROW(),""))
