Workbook

Sheet Dashboard
B2: =IF(Settings!$C$4="","Clients and sessions",Settings!$C$4)
B3: ="This month, "&CHOOSE(MONTH(TODAY()),"January","February","March","April","May","June","July","August","September","October","November","December")&": the sessions, what was sold, and who needs you."
B4: Active clients | C4: Sessions | D4: Missed | E4: Sold | G4: Owed to you | H4: Few sessions left | I4: Check-ins due
B5: =SUM(Clients!$V$6:$V$105) | C5: =SUMIFS(Sessions!$L$6:$L$3005,Sessions!$J$6:$J$3005,(YEAR(TODAY())*100+MONTH(TODAY()))) | D5: =SUMIFS(Sessions!$M$6:$M$3005,Sessions!$J$6:$J$3005,(YEAR(TODAY())*100+MONTH(TODAY()))) | E5: =SUMIFS(Packages!$E$6:$E$505,Packages!$L$6:$L$505,(YEAR(TODAY())*100+MONTH(TODAY())),Packages!$M$6:$M$505,1) | G5: =SUM(Clients!$O$6:$O$105) | H5: =SUM(Clients!$T$6:$T$105) | I5: =SUM(Clients!$U$6:$U$105)
B7: Needs attention | C7: Why | E7: Left | G7: Coming up | H7: Date | I7: Time
B8: =IF(L8="","",INDEX(Clients!$B$1:$B$105,L8)) | C8: =IF(L8="","",INDEX(Clients!$P$1:$P$105,L8)) | E8: =IF(L8="","",IF(INDEX(Clients!$J$1:$J$105,L8)=0,"",INDEX(Clients!$L$1:$L$105,L8))) | G8: =IF(M8="","",INDEX(Sessions!$D$1:$D$3005,MOD(M8,10000))) | H8: =IF(M8="","",INDEX(Sessions!$B$1:$B$3005,MOD(M8,10000))) | I8: =IF(M8="","",IF(INDEX(Sessions!$C$1:$C$3005,MOD(M8,10000))="","",INDEX(Sessions!$C$1:$C$3005,MOD(M8,10000)))) | L8: =IFERROR(SMALL(Clients!$R$6:$R$105,1),"") | M8: =IFERROR(SMALL(Sessions!$N$6:$N$3005,1),"")
B9: =IF(L9="","",INDEX(Clients!$B$1:$B$105,L9)) | C9: =IF(L9="","",INDEX(Clients!$P$1:$P$105,L9)) | E9: =IF(L9="","",IF(INDEX(Clients!$J$1:$J$105,L9)=0,"",INDEX(Clients!$L$1:$L$105,L9))) | G9: =IF(M9="","",INDEX(Sessions!$D$1:$D$3005,MOD(M9,10000))) | H9: =IF(M9="","",INDEX(Sessions!$B$1:$B$3005,MOD(M9,10000))) | I9: =IF(M9="","",IF(INDEX(Sessions!$C$1:$C$3005,MOD(M9,10000))="","",INDEX(Sessions!$C$1:$C$3005,MOD(M9,10000)))) | L9: =IFERROR(SMALL(Clients!$R$6:$R$105,2),"") | M9: =IFERROR(SMALL(Sessions!$N$6:$N$3005,2),"")
B10: =IF(L10="","",INDEX(Clients!$B$1:$B$105,L10)) | C10: =IF(L10="","",INDEX(Clients!$P$1:$P$105,L10)) | E10: =IF(L10="","",IF(INDEX(Clients!$J$1:$J$105,L10)=0,"",INDEX(Clients!$L$1:$L$105,L10))) | G10: =IF(M10="","",INDEX(Sessions!$D$1:$D$3005,MOD(M10,10000))) | H10: =IF(M10="","",INDEX(Sessions!$B$1:$B$3005,MOD(M10,10000))) | I10: =IF(M10="","",IF(INDEX(Sessions!$C$1:$C$3005,MOD(M10,10000))="","",INDEX(Sessions!$C$1:$C$3005,MOD(M10,10000)))) | L10: =IFERROR(SMALL(Clients!$R$6:$R$105,3),"") | M10: =IFERROR(SMALL(Sessions!$N$6:$N$3005,3),"")
B11: =IF(L11="","",INDEX(Clients!$B$1:$B$105,L11)) | C11: =IF(L11="","",INDEX(Clients!$P$1:$P$105,L11)) | E11: =IF(L11="","",IF(INDEX(Clients!$J$1:$J$105,L11)=0,"",INDEX(Clients!$L$1:$L$105,L11))) | G11: =IF(M11="","",INDEX(Sessions!$D$1:$D$3005,MOD(M11,10000))) | H11: =IF(M11="","",INDEX(Sessions!$B$1:$B$3005,MOD(M11,10000))) | I11: =IF(M11="","",IF(INDEX(Sessions!$C$1:$C$3005,MOD(M11,10000))="","",INDEX(Sessions!$C$1:$C$3005,MOD(M11,10000)))) | L11: =IFERROR(SMALL(Clients!$R$6:$R$105,4),"") | M11: =IFERROR(SMALL(Sessions!$N$6:$N$3005,4),"")
B12: =IF(L12="","",INDEX(Clients!$B$1:$B$105,L12)) | C12: =IF(L12="","",INDEX(Clients!$P$1:$P$105,L12)) | E12: =IF(L12="","",IF(INDEX(Clients!$J$1:$J$105,L12)=0,"",INDEX(Clients!$L$1:$L$105,L12))) | G12: =IF(M12="","",INDEX(Sessions!$D$1:$D$3005,MOD(M12,10000))) | H12: =IF(M12="","",INDEX(Sessions!$B$1:$B$3005,MOD(M12,10000))) | I12: =IF(M12="","",IF(INDEX(Sessions!$C$1:$C$3005,MOD(M12,10000))="","",INDEX(Sessions!$C$1:$C$3005,MOD(M12,10000)))) | L12: =IFERROR(SMALL(Clients!$R$6:$R$105,5),"") | M12: =IFERROR(SMALL(Sessions!$N$6:$N$3005,5),"")
B13: =IF(L13="","",INDEX(Clients!$B$1:$B$105,L13)) | C13: =IF(L13="","",INDEX(Clients!$P$1:$P$105,L13)) | E13: =IF(L13="","",IF(INDEX(Clients!$J$1:$J$105,L13)=0,"",INDEX(Clients!$L$1:$L$105,L13))) | G13: =IF(M13="","",INDEX(Sessions!$D$1:$D$3005,MOD(M13,10000))) | H13: =IF(M13="","",INDEX(Sessions!$B$1:$B$3005,MOD(M13,10000))) | I13: =IF(M13="","",IF(INDEX(Sessions!$C$1:$C$3005,MOD(M13,10000))="","",INDEX(Sessions!$C$1:$C$3005,MOD(M13,10000)))) | L13: =IFERROR(SMALL(Clients!$R$6:$R$105,6),"") | M13: =IFERROR(SMALL(Sessions!$N$6:$N$3005,6),"")
B14: =IF(L14="","",INDEX(Clients!$B$1:$B$105,L14)) | C14: =IF(L14="","",INDEX(Clients!$P$1:$P$105,L14)) | E14: =IF(L14="","",IF(INDEX(Clients!$J$1:$J$105,L14)=0,"",INDEX(Clients!$L$1:$L$105,L14))) | G14: =IF(M14="","",INDEX(Sessions!$D$1:$D$3005,MOD(M14,10000))) | H14: =IF(M14="","",INDEX(Sessions!$B$1:$B$3005,MOD(M14,10000))) | I14: =IF(M14="","",IF(INDEX(Sessions!$C$1:$C$3005,MOD(M14,10000))="","",INDEX(Sessions!$C$1:$C$3005,MOD(M14,10000)))) | L14: =IFERROR(SMALL(Clients!$R$6:$R$105,7),"") | M14: =IFERROR(SMALL(Sessions!$N$6:$N$3005,7),"")
B15: =IF(L15="","",INDEX(Clients!$B$1:$B$105,L15)) | C15: =IF(L15="","",INDEX(Clients!$P$1:$P$105,L15)) | E15: =IF(L15="","",IF(INDEX(Clients!$J$1:$J$105,L15)=0,"",INDEX(Clients!$L$1:$L$105,L15))) | G15: =IF(M15="","",INDEX(Sessions!$D$1:$D$3005,MOD(M15,10000))) | H15: =IF(M15="","",INDEX(Sessions!$B$1:$B$3005,MOD(M15,10000))) | I15: =IF(M15="","",IF(INDEX(Sessions!$C$1:$C$3005,MOD(M15,10000))="","",INDEX(Sessions!$C$1:$C$3005,MOD(M15,10000)))) | L15: =IFERROR(SMALL(Clients!$R$6:$R$105,8),"") | M15: =IFERROR(SMALL(Sessions!$N$6:$N$3005,8),"")
B16: =IF(L16="","",INDEX(Clients!$B$1:$B$105,L16)) | C16: =IF(L16="","",INDEX(Clients!$P$1:$P$105,L16)) | E16: =IF(L16="","",IF(INDEX(Clients!$J$1:$J$105,L16)=0,"",INDEX(Clients!$L$1:$L$105,L16))) | G16: =IF(M16="","",INDEX(Sessions!$D$1:$D$3005,MOD(M16,10000))) | H16: =IF(M16="","",INDEX(Sessions!$B$1:$B$3005,MOD(M16,10000))) | I16: =IF(M16="","",IF(INDEX(Sessions!$C$1:$C$3005,MOD(M16,10000))="","",INDEX(Sessions!$C$1:$C$3005,MOD(M16,10000)))) | L16: =IFERROR(SMALL(Clients!$R$6:$R$105,9),"") | M16: =IFERROR(SMALL(Sessions!$N$6:$N$3005,9),"")
B17: =IF(L17="","",INDEX(Clients!$B$1:$B$105,L17)) | C17: =IF(L17="","",INDEX(Clients!$P$1:$P$105,L17)) | E17: =IF(L17="","",IF(INDEX(Clients!$J$1:$J$105,L17)=0,"",INDEX(Clients!$L$1:$L$105,L17))) | G17: =IF(M17="","",INDEX(Sessions!$D$1:$D$3005,MOD(M17,10000))) | H17: =IF(M17="","",INDEX(Sessions!$B$1:$B$3005,MOD(M17,10000))) | I17: =IF(M17="","",IF(INDEX(Sessions!$C$1:$C$3005,MOD(M17,10000))="","",INDEX(Sessions!$C$1:$C$3005,MOD(M17,10000)))) | L17: =IFERROR(SMALL(Clients!$R$6:$R$105,10),"") | M17: =IFERROR(SMALL(Sessions!$N$6:$N$3005,10),"")
B19: Month | C19: Attended | D19: Missed | E19: Sold
B20: Jan | C20: =SUMIFS(Sessions!$L$6:$L$3005,Sessions!$J$6:$J$3005,(YEAR(TODAY())*100+1)) | D20: =SUMIFS(Sessions!$M$6:$M$3005,Sessions!$J$6:$J$3005,(YEAR(TODAY())*100+1)) | E20: =SUMIFS(Packages!$E$6:$E$505,Packages!$L$6:$L$505,(YEAR(TODAY())*100+1),Packages!$M$6:$M$505,1)
B21: Feb | C21: =SUMIFS(Sessions!$L$6:$L$3005,Sessions!$J$6:$J$3005,(YEAR(TODAY())*100+2)) | D21: =SUMIFS(Sessions!$M$6:$M$3005,Sessions!$J$6:$J$3005,(YEAR(TODAY())*100+2)) | E21: =SUMIFS(Packages!$E$6:$E$505,Packages!$L$6:$L$505,(YEAR(TODAY())*100+2),Packages!$M$6:$M$505,1)
B22: Mar | C22: =SUMIFS(Sessions!$L$6:$L$3005,Sessions!$J$6:$J$3005,(YEAR(TODAY())*100+3)) | D22: =SUMIFS(Sessions!$M$6:$M$3005,Sessions!$J$6:$J$3005,(YEAR(TODAY())*100+3)) | E22: =SUMIFS(Packages!$E$6:$E$505,Packages!$L$6:$L$505,(YEAR(TODAY())*100+3),Packages!$M$6:$M$505,1)
B23: Apr | C23: =SUMIFS(Sessions!$L$6:$L$3005,Sessions!$J$6:$J$3005,(YEAR(TODAY())*100+4)) | D23: =SUMIFS(Sessions!$M$6:$M$3005,Sessions!$J$6:$J$3005,(YEAR(TODAY())*100+4)) | E23: =SUMIFS(Packages!$E$6:$E$505,Packages!$L$6:$L$505,(YEAR(TODAY())*100+4),Packages!$M$6:$M$505,1)
B24: May | C24: =SUMIFS(Sessions!$L$6:$L$3005,Sessions!$J$6:$J$3005,(YEAR(TODAY())*100+5)) | D24: =SUMIFS(Sessions!$M$6:$M$3005,Sessions!$J$6:$J$3005,(YEAR(TODAY())*100+5)) | E24: =SUMIFS(Packages!$E$6:$E$505,Packages!$L$6:$L$505,(YEAR(TODAY())*100+5),Packages!$M$6:$M$505,1)
B25: Jun | C25: =SUMIFS(Sessions!$L$6:$L$3005,Sessions!$J$6:$J$3005,(YEAR(TODAY())*100+6)) | D25: =SUMIFS(Sessions!$M$6:$M$3005,Sessions!$J$6:$J$3005,(YEAR(TODAY())*100+6)) | E25: =SUMIFS(Packages!$E$6:$E$505,Packages!$L$6:$L$505,(YEAR(TODAY())*100+6),Packages!$M$6:$M$505,1)
B26: Jul | C26: =SUMIFS(Sessions!$L$6:$L$3005,Sessions!$J$6:$J$3005,(YEAR(TODAY())*100+7)) | D26: =SUMIFS(Sessions!$M$6:$M$3005,Sessions!$J$6:$J$3005,(YEAR(TODAY())*100+7)) | E26: =SUMIFS(Packages!$E$6:$E$505,Packages!$L$6:$L$505,(YEAR(TODAY())*100+7),Packages!$M$6:$M$505,1)
B27: Aug | C27: =SUMIFS(Sessions!$L$6:$L$3005,Sessions!$J$6:$J$3005,(YEAR(TODAY())*100+8)) | D27: =SUMIFS(Sessions!$M$6:$M$3005,Sessions!$J$6:$J$3005,(YEAR(TODAY())*100+8)) | E27: =SUMIFS(Packages!$E$6:$E$505,Packages!$L$6:$L$505,(YEAR(TODAY())*100+8),Packages!$M$6:$M$505,1)
B28: Sep | C28: =SUMIFS(Sessions!$L$6:$L$3005,Sessions!$J$6:$J$3005,(YEAR(TODAY())*100+9)) | D28: =SUMIFS(Sessions!$M$6:$M$3005,Sessions!$J$6:$J$3005,(YEAR(TODAY())*100+9)) | E28: =SUMIFS(Packages!$E$6:$E$505,Packages!$L$6:$L$505,(YEAR(TODAY())*100+9),Packages!$M$6:$M$505,1)
B29: Oct | C29: =SUMIFS(Sessions!$L$6:$L$3005,Sessions!$J$6:$J$3005,(YEAR(TODAY())*100+10)) | D29: =SUMIFS(Sessions!$M$6:$M$3005,Sessions!$J$6:$J$3005,(YEAR(TODAY())*100+10)) | E29: =SUMIFS(Packages!$E$6:$E$505,Packages!$L$6:$L$505,(YEAR(TODAY())*100+10),Packages!$M$6:$M$505,1)
B30: Nov | C30: =SUMIFS(Sessions!$L$6:$L$3005,Sessions!$J$6:$J$3005,(YEAR(TODAY())*100+11)) | D30: =SUMIFS(Sessions!$M$6:$M$3005,Sessions!$J$6:$J$3005,(YEAR(TODAY())*100+11)) | E30: =SUMIFS(Packages!$E$6:$E$505,Packages!$L$6:$L$505,(YEAR(TODAY())*100+11),Packages!$M$6:$M$505,1)
B31: Dec | C31: =SUMIFS(Sessions!$L$6:$L$3005,Sessions!$J$6:$J$3005,(YEAR(TODAY())*100+12)) | D31: =SUMIFS(Sessions!$M$6:$M$3005,Sessions!$J$6:$J$3005,(YEAR(TODAY())*100+12)) | E31: =SUMIFS(Packages!$E$6:$E$505,Packages!$L$6:$L$505,(YEAR(TODAY())*100+12),Packages!$M$6:$M$505,1)

Sheet Sessions
B2: Sessions
B3: Each session, booked ahead or done. Leave the status empty until it has happened.
B5: Date | C5: Time | D5: Client | E5: Type | F5: Status | G5: Note | H5: Check
B6: 45993 | C6: 0.72916667 | D6: Hannah Brooks | E6: Duo | F6: Attended | H6: =IF(AND(B6="",D6="",F6=""),"",IF(NOT(ISNUMBER(B6)),"Needs a date",IF(D6="","Needs a client",IF(COUNTIF(Clients!$B$6:$B$105,D6)=0,"Not on Clients",IF(AND(F6="",INT(B6)<TODAY()),"Needs a status",""))))) | I6: =IF(ISNUMBER(B6),INT(B6),0) | J6: =IF(ISNUMBER(B6),YEAR(B6)*100+MONTH(B6),"") | K6: =IF(AND(H6="",OR(F6="Attended",F6="No-show",AND(F6="Late cancel",Settings!$C$9="Yes"))),1,0) | L6: =IF(AND(H6="",F6="Attended"),1,0) | M6: =IF(AND(H6="",OR(F6="No-show",F6="Late cancel")),1,0) | N6: =IF(AND(H6="",F6="",D6<>"",I6>=TODAY()),ROUND((I6+IF(ISNUMBER(C6),MOD(C6,1),0))*1440,0)*10000+ROW(),"")
B7: 45996 | C7: 0.72916667 | D7: Hannah Brooks | E7: Duo | F7: Attended | H7: =IF(AND(B7="",D7="",F7=""),"",IF(NOT(ISNUMBER(B7)),"Needs a date",IF(D7="","Needs a client",IF(COUNTIF(Clients!$B$6:$B$105,D7)=0,"Not on Clients",IF(AND(F7="",INT(B7)<TODAY()),"Needs a status",""))))) | I7: =IF(ISNUMBER(B7),INT(B7),0) | J7: =IF(ISNUMBER(B7),YEAR(B7)*100+MONTH(B7),"") | K7: =IF(AND(H7="",OR(F7="Attended",F7="No-show",AND(F7="Late cancel",Settings!$C$9="Yes"))),1,0) | L7: =IF(AND(H7="",F7="Attended"),1,0) | M7: =IF(AND(H7="",OR(F7="No-show",F7="Late cancel")),1,0) | N7: =IF(AND(H7="",F7="",D7<>"",I7>=TODAY()),ROUND((I7+IF(ISNUMBER(C7),MOD(C7,1),0))*1440,0)*10000+ROW(),"")
B8: 46000 | C8: 0.72916667 | D8: Hannah Brooks | E8: Duo | F8: Attended | H8: =IF(AND(B8="",D8="",F8=""),"",IF(NOT(ISNUMBER(B8)),"Needs a date",IF(D8="","Needs a client",IF(COUNTIF(Clients!$B$6:$B$105,D8)=0,"Not on Clients",IF(AND(F8="",INT(B8)<TODAY()),"Needs a status",""))))) | I8: =IF(ISNUMBER(B8),INT(B8),0) | J8: =IF(ISNUMBER(B8),YEAR(B8)*100+MONTH(B8),"") | K8: =IF(AND(H8="",OR(F8="Attended",F8="No-show",AND(F8="Late cancel",Settings!$C$9="Yes"))),1,0) | L8: =IF(AND(H8="",F8="Attended"),1,0) | M8: =IF(AND(H8="",OR(F8="No-show",F8="Late cancel")),1,0) | N8: =IF(AND(H8="",F8="",D8<>"",I8>=TODAY()),ROUND((I8+IF(ISNUMBER(C8),MOD(C8,1),0))*1440,0)*10000+ROW(),"")
B9: 46003 | C9: 0.72916667 | D9: Hannah Brooks | E9: Duo | F9: Attended | H9: =IF(AND(B9="",D9="",F9=""),"",IF(NOT(ISNUMBER(B9)),"Needs a date",IF(D9="","Needs a client",IF(COUNTIF(Clients!$B$6:$B$105,D9)=0,"Not on Clients",IF(AND(F9="",INT(B9)<TODAY()),"Needs a status",""))))) | I9: =IF(ISNUMBER(B9),INT(B9),0) | J9: =IF(ISNUMBER(B9),YEAR(B9)*100+MONTH(B9),"") | K9: =IF(AND(H9="",OR(F9="Attended",F9="No-show",AND(F9="Late cancel",Settings!$C$9="Yes"))),1,0) | L9: =IF(AND(H9="",F9="Attended"),1,0) | M9: =IF(AND(H9="",OR(F9="No-show",F9="Late cancel")),1,0) | N9: =IF(AND(H9="",F9="",D9<>"",I9>=TODAY()),ROUND((I9+IF(ISNUMBER(C9),MOD(C9,1),0))*1440,0)*10000+ROW(),"")
B10: 46007 | C10: 0.72916667 | D10: Hannah Brooks | E10: Duo | F10: No-show | H10: =IF(AND(B10="",D10="",F10=""),"",IF(NOT(ISNUMBER(B10)),"Needs a date",IF(D10="","Needs a client",IF(COUNTIF(Clients!$B$6:$B$105,D10)=0,"Not on Clients",IF(AND(F10="",INT(B10)<TODAY()),"Needs a status",""))))) | I10: =IF(ISNUMBER(B10),INT(B10),0) | J10: =IF(ISNUMBER(B10),YEAR(B10)*100+MONTH(B10),"") | K10: =IF(AND(H10="",OR(F10="Attended",F10="No-show",AND(F10="Late cancel",Settings!$C$9="Yes"))),1,0) | L10: =IF(AND(H10="",F10="Attended"),1,0) | M10: =IF(AND(H10="",OR(F10="No-show",F10="Late cancel")),1,0) | N10: =IF(AND(H10="",F10="",D10<>"",I10>=TODAY()),ROUND((I10+IF(ISNUMBER(C10),MOD(C10,1),0))*1440,0)*10000+ROW(),"")
B11: 46010 | C11: 0.72916667 | D11: Hannah Brooks | E11: Duo | F11: Attended | H11: =IF(AND(B11="",D11="",F11=""),"",IF(NOT(ISNUMBER(B11)),"Needs a date",IF(D11="","Needs a client",IF(COUNTIF(Clients!$B$6:$B$105,D11)=0,"Not on Clients",IF(AND(F11="",INT(B11)<TODAY()),"Needs a status",""))))) | I11: =IF(ISNUMBER(B11),INT(B11),0) | J11: =IF(ISNUMBER(B11),YEAR(B11)*100+MONTH(B11),"") | K11: =IF(AND(H11="",OR(F11="Attended",F11="No-show",AND(F11="Late cancel",Settings!$C$9="Yes"))),1,0) | L11: =IF(AND(H11="",F11="Attended"),1,0) | M11: =IF(AND(H11="",OR(F11="No-show",F11="Late cancel")),1,0) | N11: =IF(AND(H11="",F11="",D11<>"",I11>=TODAY()),ROUND((I11+IF(ISNUMBER(C11),MOD(C11,1),0))*1440,0)*10000+ROW(),"")
B12: 46014 | C12: 0.72916667 | D12: Hannah Brooks | E12: Duo | F12: Attended | H12: =IF(AND(B12="",D12="",F12=""),"",IF(NOT(ISNUMBER(B12)),"Needs a date",IF(D12="","Needs a client",IF(COUNTIF(Clients!$B$6:$B$105,D12)=0,"Not on Clients",IF(AND(F12="",INT(B12)<TODAY()),"Needs a status",""))))) | I12: =IF(ISNUMBER(B12),INT(B12),0) | J12: =IF(ISNUMBER(B12),YEAR(B12)*100+MONTH(B12),"") | K12: =IF(AND(H12="",OR(F12="Attended",F12="No-show",AND(F12="Late cancel",Settings!$C$9="Yes"))),1,0) | L12: =IF(AND(H12="",F12="Attended"),1,0) | M12: =IF(AND(H12="",OR(F12="No-show",F12="Late cancel")),1,0) | N12: =IF(AND(H12="",F12="",D12<>"",I12>=TODAY()),ROUND((I12+IF(ISNUMBER(C12),MOD(C12,1),0))*1440,0)*10000+ROW(),"")
B13: 46017 | C13: 0.72916667 | D13: Hannah Brooks | E13: Duo | F13: Attended | H13: =IF(AND(B13="",D13="",F13=""),"",IF(NOT(ISNUMBER(B13)),"Needs a date",IF(D13="","Needs a client",IF(COUNTIF(Clients!$B$6:$B$105,D13)=0,"Not on Clients",IF(AND(F13="",INT(B13)<TODAY()),"Needs a status",""))))) | I13: =IF(ISNUMBER(B13),INT(B13),0) | J13: =IF(ISNUMBER(B13),YEAR(B13)*100+MONTH(B13),"") | K13: =IF(AND(H13="",OR(F13="Attended",F13="No-show",AND(F13="Late cancel",Settings!$C$9="Yes"))),1,0) | L13: =IF(AND(H13="",F13="Attended"),1,0) | M13: =IF(AND(H13="",OR(F13="No-show",F13="Late cancel")),1,0) | N13: =IF(AND(H13="",F13="",D13<>"",I13>=TODAY()),ROUND((I13+IF(ISNUMBER(C13),MOD(C13,1),0))*1440,0)*10000+ROW(),"")
B14: 46021 | C14: 0.72916667 | D14: Hannah Brooks | E14: Duo | F14: Attended | H14: =IF(AND(B14="",D14="",F14=""),"",IF(NOT(ISNUMBER(B14)),"Needs a date",IF(D14="","Needs a client",IF(COUNTIF(Clients!$B$6:$B$105,D14)=0,"Not on Clients",IF(AND(F14="",INT(B14)<TODAY()),"Needs a status",""))))) | I14: =IF(ISNUMBER(B14),INT(B14),0) | J14: =IF(ISNUMBER(B14),YEAR(B14)*100+MONTH(B14),"") | K14: =IF(AND(H14="",OR(F14="Attended",F14="No-show",AND(F14="Late cancel",Settings!$C$9="Yes"))),1,0) | L14: =IF(AND(H14="",F14="Attended"),1,0) | M14: =IF(AND(H14="",OR(F14="No-show",F14="Late cancel")),1,0) | N14: =IF(AND(H14="",F14="",D14<>"",I14>=TODAY()),ROUND((I14+IF(ISNUMBER(C14),MOD(C14,1),0))*1440,0)*10000+ROW(),"")
B15: 46024 | C15: 0.72916667 | D15: Hannah Brooks | E15: Duo | F15: No-show | H15: =IF(AND(B15="",D15="",F15=""),"",IF(NOT(ISNUMBER(B15)),"Needs a date",IF(D15="","Needs a client",IF(COUNTIF(Clients!$B$6:$B$105,D15)=0,"Not on Clients",IF(AND(F15="",INT(B15)<TODAY()),"Needs a status",""))))) | I15: =IF(ISNUMBER(B15),INT(B15),0) | J15: =IF(ISNUMBER(B15),YEAR(B15)*100+MONTH(B15),"") | K15: =IF(AND(H15="",OR(F15="Attended",F15="No-show",AND(F15="Late cancel",Settings!$C$9="Yes"))),1,0) | L15: =IF(AND(H15="",F15="Attended"),1,0) | M15: =IF(AND(H15="",OR(F15="No-show",F15="Late cancel")),1,0) | N15: =IF(AND(H15="",F15="",D15<>"",I15>=TODAY()),ROUND((I15+IF(ISNUMBER(C15),MOD(C15,1),0))*1440,0)*10000+ROW(),"")
B16: 46028 | C16: 0.72916667 | D16: Hannah Brooks | E16: Duo | F16: Attended | H16: =IF(AND(B16="",D16="",F16=""),"",IF(NOT(ISNUMBER(B16)),"Needs a date",IF(D16="","Needs a client",IF(COUNTIF(Clients!$B$6:$B$105,D16)=0,"Not on Clients",IF(AND(F16="",INT(B16)<TODAY()),"Needs a status",""))))) | I16: =IF(ISNUMBER(B16),INT(B16),0) | J16: =IF(ISNUMBER(B16),YEAR(B16)*100+MONTH(B16),"") | K16: =IF(AND(H16="",OR(F16="Attended",F16="No-show",AND(F16="Late cancel",Settings!$C$9="Yes"))),1,0) | L16: =IF(AND(H16="",F16="Attended"),1,0) | M16: =IF(AND(H16="",OR(F16="No-show",F16="Late cancel")),1,0) | N16: =IF(AND(H16="",F16="",D16<>"",I16>=TODAY()),ROUND((I16+IF(ISNUMBER(C16),MOD(C16,1),0))*1440,0)*10000+ROW(),"")
B17: 46031 | C17: 0.72916667 | D17: Hannah Brooks | E17: Duo | F17: Attended | H17: =IF(AND(B17="",D17="",F17=""),"",IF(NOT(ISNUMBER(B17)),"Needs a date",IF(D17="","Needs a client",IF(COUNTIF(Clients!$B$6:$B$105,D17)=0,"Not on Clients",IF(AND(F17="",INT(B17)<TODAY()),"Needs a status",""))))) | I17: =IF(ISNUMBER(B17),INT(B17),0) | J17: =IF(ISNUMBER(B17),YEAR(B17)*100+MONTH(B17),"") | K17: =IF(AND(H17="",OR(F17="Attended",F17="No-show",AND(F17="Late cancel",Settings!$C$9="Yes"))),1,0) | L17: =IF(AND(H17="",F17="Attended"),1,0) | M17: =IF(AND(H17="",OR(F17="No-show",F17="Late cancel")),1,0) | N17: =IF(AND(H17="",F17="",D17<>"",I17>=TODAY()),ROUND((I17+IF(ISNUMBER(C17),MOD(C17,1),0))*1440,0)*10000+ROW(),"")
... B330: 46292 | C330: 0.77083333 | D330: Leah Fischer | E330: Duo | F330: Attended | H330: =IF(AND(B330="",D330="",F330=""),"",IF(NOT(ISNUMBER(B330)),"Needs a date",IF(D330="","Needs a client",IF(COUNTIF(Clients!$B$6:$B$105,D330)=0,"Not on Clients",IF(AND(F330="",INT(B330)<TODAY()),"Needs a status",""))))) | I330: =IF(ISNUMBER(B330),INT(B330),0) | J330: =IF(ISNUMBER(B330),YEAR(B330)*100+MONTH(B330),"") | K330: =IF(AND(H330="",OR(F330="Attended",F330="No-show",AND(F330="Late cancel",Settings!$C$9="Yes"))),1,0) | L330: =IF(AND(H330="",F330="Attended"),1,0) | M330: =IF(AND(H330="",OR(F330="No-show",F330="Late cancel")),1,0) | N330: =IF(AND(H330="",F330="",D330<>"",I330>=TODAY()),ROUND((I330+IF(ISNUMBER(C330),MOD(C330,1),0))*1440,0)*10000+ROW(),"")
B331: 46294 | C331: 0.29166667 | D331: Maya Ortiz | E331: Duo | H331: =IF(AND(B331="",D331="",F331=""),"",IF(NOT(ISNUMBER(B331)),"Needs a date",IF(D331="","Needs a client",IF(COUNTIF(Clients!$B$6:$B$105,D331)=0,"Not on Clients",IF(AND(F331="",INT(B331)<TODAY()),"Needs a status",""))))) | I331: =IF(ISNUMBER(B331),INT(B331),0) | J331: =IF(ISNUMBER(B331),YEAR(B331)*100+MONTH(B331),"") | K331: =IF(AND(H331="",OR(F331="Attended",F331="No-show",AND(F331="Late cancel",Settings!$C$9="Yes"))),1,0) | L331: =IF(AND(H331="",F331="Attended"),1,0) | M331: =IF(AND(H331="",OR(F331="No-show",F331="Late cancel")),1,0) | N331: =IF(AND(H331="",F331="",D331<>"",I331>=TODAY()),ROUND((I331+IF(ISNUMBER(C331),MOD(C331,1),0))*1440,0)*10000+ROW(),"")
B332: 46294 | C332: 0.72916667 | D332: Tom Walsh | E332: 1 to 1 | H332: =IF(AND(B332="",D332="",F332=""),"",IF(NOT(ISNUMBER(B332)),"Needs a date",IF(D332="","Needs a client",IF(COUNTIF(Clients!$B$6:$B$105,D332)=0,"Not on Clients",IF(AND(F332="",INT(B332)<TODAY()),"Needs a status",""))))) | I332: =IF(ISNUMBER(B332),INT(B332),0) | J332: =IF(ISNUMBER(B332),YEAR(B332)*100+MONTH(B332),"") | K332: =IF(AND(H332="",OR(F332="Attended",F332="No-show",AND(F332="Late cancel",Settings!$C$9="Yes"))),1,0) | L332: =IF(AND(H332="",F332="Attended"),1,0) | M332: =IF(AND(H332="",OR(F332="No-show",F332="Late cancel")),1,0) | N332: =IF(AND(H332="",F332="",D332<>"",I332>=TODAY()),ROUND((I332+IF(ISNUMBER(C332),MOD(C332,1),0))*1440,0)*10000+ROW(),"")
B333: 46294 | C333: 0.77083333 | D333: Sam Taylor | E333: 1 to 1 | H333: =IF(AND(B333="",D333="",F333=""),"",IF(NOT(ISNUMBER(B333)),"Needs a date",IF(D333="","Needs a client",IF(COUNTIF(Clients!$B$6:$B$105,D333)=0,"Not on Clients",IF(AND(F333="",INT(B333)<TODAY()),"Needs a status",""))))) | I333: =IF(ISNUMBER(B333),INT(B333),0) | J333: =IF(ISNUMBER(B333),YEAR(B333)*100+MONTH(B333),"") | K333: =IF(AND(H333="",OR(F333="Attended",F333="No-show",AND(F333="Late cancel",Settings!$C$9="Yes"))),1,0) | L333: =IF(AND(H333="",F333="Attended"),1,0) | M333: =IF(AND(H333="",OR(F333="No-show",F333="Late cancel")),1,0) | N333: =IF(AND(H333="",F333="",D333<>"",I333>=TODAY()),ROUND((I333+IF(ISNUMBER(C333),MOD(C333,1),0))*1440,0)*10000+ROW(),"")
B334: 46295 | C334: 0.33333333 | D334: Ben Carter | E334: 1 to 1 | H334: =IF(AND(B334="",D334="",F334=""),"",IF(NOT(ISNUMBER(B334)),"Needs a date",IF(D334="","Needs a client",IF(COUNTIF(Clients!$B$6:$B$105,D334)=0,"Not on Clients",IF(AND(F334="",INT(B334)<TODAY()),"Needs a status",""))))) | I334: =IF(ISNUMBER(B334),INT(B334),0) | J334: =IF(ISNUMBER(B334),YEAR(B334)*100+MONTH(B334),"") | K334: =IF(AND(H334="",OR(F334="Attended",F334="No-show",AND(F334="Late cancel",Settings!$C$9="Yes"))),1,0) | L334: =IF(AND(H334="",F334="Attended"),1,0) | M334: =IF(AND(H334="",OR(F334="No-show",F334="Late cancel")),1,0) | N334: =IF(AND(H334="",F334="",D334<>"",I334>=TODAY()),ROUND((I334+IF(ISNUMBER(C334),MOD(C334,1),0))*1440,0)*10000+ROW(),"")
B335: 46295 | C335: 0.52083333 | D335: Luis Moreno | E335: 1 to 1 | H335: =IF(AND(B335="",D335="",F335=""),"",IF(NOT(ISNUMBER(B335)),"Needs a date",IF(D335="","Needs a client",IF(COUNTIF(Clients!$B$6:$B$105,D335)=0,"Not on Clients",IF(AND(F335="",INT(B335)<TODAY()),"Needs a status",""))))) | I335: =IF(ISNUMBER(B335),INT(B335),0) | J335: =IF(ISNUMBER(B335),YEAR(B335)*100+MONTH(B335),"") | K335: =IF(AND(H335="",OR(F335="Attended",F335="No-show",AND(F335="Late cancel",Settings!$C$9="Yes"))),1,0) | L335: =IF(AND(H335="",F335="Attended"),1,0) | M335: =IF(AND(H335="",OR(F335="No-show",F335="Late cancel")),1,0) | N335: =IF(AND(H335="",F335="",D335<>"",I335>=TODAY()),ROUND((I335+IF(ISNUMBER(C335),MOD(C335,1),0))*1440,0)*10000+ROW(),"")
B336: 46295 | C336: 0.77083333 | D336: Leah Fischer | E336: Duo | H336: =IF(AND(B336="",D336="",F336=""),"",IF(NOT(ISNUMBER(B336)),"Needs a date",IF(D336="","Needs a client",IF(COUNTIF(Clients!$B$6:$B$105,D336)=0,"Not on Clients",IF(AND(F336="",INT(B336)<TODAY()),"Needs a status",""))))) | I336: =IF(ISNUMBER(B336),INT(B336),0) | J336: =IF(ISNUMBER(B336),YEAR(B336)*100+MONTH(B336),"") | K336: =IF(AND(H336="",OR(F336="Attended",F336="No-show",AND(F336="Late cancel",Settings!$C$9="Yes"))),1,0) | L336: =IF(AND(H336="",F336="Attended"),1,0) | M336: =IF(AND(H336="",OR(F336="No-show",F336="Late cancel")),1,0) | N336: =IF(AND(H336="",F336="",D336<>"",I336>=TODAY()),ROUND((I336+IF(ISNUMBER(C336),MOD(C336,1),0))*1440,0)*10000+ROW(),"")
B337: 46296 | C337: 0.29166667 | D337: Maya Ortiz | E337: Duo | H337: =IF(AND(B337="",D337="",F337=""),"",IF(NOT(ISNUMBER(B337)),"Needs a date",IF(D337="","Needs a client",IF(COUNTIF(Clients!$B$6:$B$105,D337)=0,"Not on Clients",IF(AND(F337="",INT(B337)<TODAY()),"Needs a status",""))))) | I337: =IF(ISNUMBER(B337),INT(B337),0) | J337: =IF(ISNUMBER(B337),YEAR(B337)*100+MONTH(B337),"") | K337: =IF(AND(H337="",OR(F337="Attended",F337="No-show",AND(F337="Late cancel",Settings!$C$9="Yes"))),1,0) | L337: =IF(AND(H337="",F337="Attended"),1,0) | M337: =IF(AND(H337="",OR(F337="No-show",F337="Late cancel")),1,0) | N337: =IF(AND(H337="",F337="",D337<>"",I337>=TODAY()),ROUND((I337+IF(ISNUMBER(C337),MOD(C337,1),0))*1440,0)*10000+ROW(),"")
B338: 46296 | C338: 0.29166667 | D338: Omar Haddad | E338: 1 to 1 | H338: =IF(AND(B338="",D338="",F338=""),"",IF(NOT(ISNUMBER(B338)),"Needs a date",IF(D338="","Needs a client",IF(COUNTIF(Clients!$B$6:$B$105,D338)=0,"Not on Clients",IF(AND(F338="",INT(B338)<TODAY()),"Needs a status",""))))) | I338: =IF(ISNUMBER(B338),INT(B338),0) | J338: =IF(ISNUMBER(B338),YEAR(B338)*100+MONTH(B338),"") | K338: =IF(AND(H338="",OR(F338="Attended",F338="No-show",AND(F338="Late cancel",Settings!$C$9="Yes"))),1,0) | L338: =IF(AND(H338="",F338="Attended"),1,0) | M338: =IF(AND(H338="",OR(F338="No-show",F338="Late cancel")),1,0) | N338: =IF(AND(H338="",F338="",D338<>"",I338>=TODAY()),ROUND((I338+IF(ISNUMBER(C338),MOD(C338,1),0))*1440,0)*10000+ROW(),"")
B339: 46296 | C339: 0.52083333 | D339: Priya Nair | E339: 1 to 1 | H339: =IF(AND(B339="",D339="",F339=""),"",IF(NOT(ISNUMBER(B339)),"Needs a date",IF(D339="","Needs a client",IF(COUNTIF(Clients!$B$6:$B$105,D339)=0,"Not on Clients",IF(AND(F339="",INT(B339)<TODAY()),"Needs a status",""))))) | I339: =IF(ISNUMBER(B339),INT(B339),0) | J339: =IF(ISNUMBER(B339),YEAR(B339)*100+MONTH(B339),"") | K339: =IF(AND(H339="",OR(F339="Attended",F339="No-show",AND(F339="Late cancel",Settings!$C$9="Yes"))),1,0) | L339: =IF(AND(H339="",F339="Attended"),1,0) | M339: =IF(AND(H339="",OR(F339="No-show",F339="Late cancel")),1,0) | N339: =IF(AND(H339="",F339="",D339<>"",I339>=TODAY()),ROUND((I339+IF(ISNUMBER(C339),MOD(C339,1),0))*1440,0)*10000+ROW(),"")
B340: 46296 | C340: 0.72916667 | D340: Tom Walsh | E340: 1 to 1 | H340: =IF(AND(B340="",D340="",F340=""),"",IF(NOT(ISNUMBER(B340)),"Needs a date",IF(D340="","Needs a client",IF(COUNTIF(Clients!$B$6:$B$105,D340)=0,"Not on Clients",IF(AND(F340="",INT(B340)<TODAY()),"Needs a status",""))))) | I340: =IF(ISNUMBER(B340),INT(B340),0) | J340: =IF(ISNUMBER(B340),YEAR(B340)*100+MONTH(B340),"") | K340: =IF(AND(H340="",OR(F340="Attended",F340="No-show",AND(F340="Late cancel",Settings!$C$9="Yes"))),1,0) | L340: =IF(AND(H340="",F340="Attended"),1,0) | M340: =IF(AND(H340="",OR(F340="No-show",F340="Late cancel")),1,0) | N340: =IF(AND(H340="",F340="",D340<>"",I340>=TODAY()),ROUND((I340+IF(ISNUMBER(C340),MOD(C340,1),0))*1440,0)*10000+ROW(),"")
B341: 46296 | C341: 0.77083333 | D341: Sam Taylor | E341: 1 to 1 | H341: =IF(AND(B341="",D341="",F341=""),"",IF(NOT(ISNUMBER(B341)),"Needs a date",IF(D341="","Needs a client",IF(COUNTIF(Clients!$B$6:$B$105,D341)=0,"Not on Clients",IF(AND(F341="",INT(B341)<TODAY()),"Needs a status",""))))) | I341: =IF(ISNUMBER(B341),INT(B341),0) | J341: =IF(ISNUMBER(B341),YEAR(B341)*100+MONTH(B341),"") | K341: =IF(AND(H341="",OR(F341="Attended",F341="No-show",AND(F341="Late cancel",Settings!$C$9="Yes"))),1,0) | L341: =IF(AND(H341="",F341="Attended"),1,0) | M341: =IF(AND(H341="",OR(F341="No-show",F341="Late cancel")),1,0) | N341: =IF(AND(H341="",F341="",D341<>"",I341>=TODAY()),ROUND((I341+IF(ISNUMBER(C341),MOD(C341,1),0))*1440,0)*10000+ROW(),"")
B342: 46297 | C342: 0.33333333 | D342: Ben Carter | E342: 1 to 1 | H342: =IF(AND(B342="",D342="",F342=""),"",IF(NOT(ISNUMBER(B342)),"Needs a date",IF(D342="","Needs a client",IF(COUNTIF(Clients!$B$6:$B$105,D342)=0,"Not on Clients",IF(AND(F342="",INT(B342)<TODAY()),"Needs a status",""))))) | I342: =IF(ISNUMBER(B342),INT(B342),0) | J342: =IF(ISNUMBER(B342),YEAR(B342)*100+MONTH(B342),"") | K342: =IF(AND(H342="",OR(F342="Attended",F342="No-show",AND(F342="Late cancel",Settings!$C$9="Yes"))),1,0) | L342: =IF(AND(H342="",F342="Attended"),1,0) | M342: =IF(AND(H342="",OR(F342="No-show",F342="Late cancel")),1,0) | N342: =IF(AND(H342="",F342="",D342<>"",I342>=TODAY()),ROUND((I342+IF(ISNUMBER(C342),MOD(C342,1),0))*1440,0)*10000+ROW(),"")
... B354: 46303 | C354: 0.52083333 | D354: Priya Nair | E354: 1 to 1 | H354: =IF(AND(B354="",D354="",F354=""),"",IF(NOT(ISNUMBER(B354)),"Needs a date",IF(D354="","Needs a client",IF(COUNTIF(Clients!$B$6:$B$105,D354)=0,"Not on Clients",IF(AND(F354="",INT(B354)<TODAY()),"Needs a status",""))))) | I354: =IF(ISNUMBER(B354),INT(B354),0) | J354: =IF(ISNUMBER(B354),YEAR(B354)*100+MONTH(B354),"") | K354: =IF(AND(H354="",OR(F354="Attended",F354="No-show",AND(F354="Late cancel",Settings!$C$9="Yes"))),1,0) | L354: =IF(AND(H354="",F354="Attended"),1,0) | M354: =IF(AND(H354="",OR(F354="No-show",F354="Late cancel")),1,0) | N354: =IF(AND(H354="",F354="",D354<>"",I354>=TODAY()),ROUND((I354+IF(ISNUMBER(C354),MOD(C354,1),0))*1440,0)*10000+ROW(),"")
H355: =IF(AND(B355="",D355="",F355=""),"",IF(NOT(ISNUMBER(B355)),"Needs a date",IF(D355="","Needs a client",IF(COUNTIF(Clients!$B$6:$B$105,D355)=0,"Not on Clients",IF(AND(F355="",INT(B355)<TODAY()),"Needs a status",""))))) | I355: =IF(ISNUMBER(B355),INT(B355),0) | J355: =IF(ISNUMBER(B355),YEAR(B355)*100+MONTH(B355),"") | K355: =IF(AND(H355="",OR(F355="Attended",F355="No-show",AND(F355="Late cancel",Settings!$C$9="Yes"))),1,0) | L355: =IF(AND(H355="",F355="Attended"),1,0) | M355: =IF(AND(H355="",OR(F355="No-show",F355="Late cancel")),1,0) | N355: =IF(AND(H355="",F355="",D355<>"",I355>=TODAY()),ROUND((I355+IF(ISNUMBER(C355),MOD(C355,1),0))*1440,0)*10000+ROW(),"")
H356: =IF(AND(B356="",D356="",F356=""),"",IF(NOT(ISNUMBER(B356)),"Needs a date",IF(D356="","Needs a client",IF(COUNTIF(Clients!$B$6:$B$105,D356)=0,"Not on Clients",IF(AND(F356="",INT(B356)<TODAY()),"Needs a status",""))))) | I356: =IF(ISNUMBER(B356),INT(B356),0) | J356: =IF(ISNUMBER(B356),YEAR(B356)*100+MONTH(B356),"") | K356: =IF(AND(H356="",OR(F356="Attended",F356="No-show",AND(F356="Late cancel",Settings!$C$9="Yes"))),1,0) | L356: =IF(AND(H356="",F356="Attended"),1,0) | M356: =IF(AND(H356="",OR(F356="No-show",F356="Late cancel")),1,0) | N356: =IF(AND(H356="",F356="",D356<>"",I356>=TODAY()),ROUND((I356+IF(ISNUMBER(C356),MOD(C356,1),0))*1440,0)*10000+ROW(),"")
H357: =IF(AND(B357="",D357="",F357=""),"",IF(NOT(ISNUMBER(B357)),"Needs a date",IF(D357="","Needs a client",IF(COUNTIF(Clients!$B$6:$B$105,D357)=0,"Not on Clients",IF(AND(F357="",INT(B357)<TODAY()),"Needs a status",""))))) | I357: =IF(ISNUMBER(B357),INT(B357),0) | J357: =IF(ISNUMBER(B357),YEAR(B357)*100+MONTH(B357),"") | K357: =IF(AND(H357="",OR(F357="Attended",F357="No-show",AND(F357="Late cancel",Settings!$C$9="Yes"))),1,0) | L357: =IF(AND(H357="",F357="Attended"),1,0) | M357: =IF(AND(H357="",OR(F357="No-show",F357="Late cancel")),1,0) | N357: =IF(AND(H357="",F357="",D357<>"",I357>=TODAY()),ROUND((I357+IF(ISNUMBER(C357),MOD(C357,1),0))*1440,0)*10000+ROW(),"")
H358: =IF(AND(B358="",D358="",F358=""),"",IF(NOT(ISNUMBER(B358)),"Needs a date",IF(D358="","Needs a client",IF(COUNTIF(Clients!$B$6:$B$105,D358)=0,"Not on Clients",IF(AND(F358="",INT(B358)<TODAY()),"Needs a status",""))))) | I358: =IF(ISNUMBER(B358),INT(B358),0) | J358: =IF(ISNUMBER(B358),YEAR(B358)*100+MONTH(B358),"") | K358: =IF(AND(H358="",OR(F358="Attended",F358="No-show",AND(F358="Late cancel",Settings!$C$9="Yes"))),1,0) | L358: =IF(AND(H358="",F358="Attended"),1,0) | M358: =IF(AND(H358="",OR(F358="No-show",F358="Late cancel")),1,0) | N358: =IF(AND(H358="",F358="",D358<>"",I358>=TODAY()),ROUND((I358+IF(ISNUMBER(C358),MOD(C358,1),0))*1440,0)*10000+ROW(),"")
H359: =IF(AND(B359="",D359="",F359=""),"",IF(NOT(ISNUMBER(B359)),"Needs a date",IF(D359="","Needs a client",IF(COUNTIF(Clients!$B$6:$B$105,D359)=0,"Not on Clients",IF(AND(F359="",INT(B359)<TODAY()),"Needs a status",""))))) | I359: =IF(ISNUMBER(B359),INT(B359),0) | J359: =IF(ISNUMBER(B359),YEAR(B359)*100+MONTH(B359),"") | K359: =IF(AND(H359="",OR(F359="Attended",F359="No-show",AND(F359="Late cancel",Settings!$C$9="Yes"))),1,0) | L359: =IF(AND(H359="",F359="Attended"),1,0) | M359: =IF(AND(H359="",OR(F359="No-show",F359="Late cancel")),1,0) | N359: =IF(AND(H359="",F359="",D359<>"",I359>=TODAY()),ROUND((I359+IF(ISNUMBER(C359),MOD(C359,1),0))*1440,0)*10000+ROW(),"")
H360: =IF(AND(B360="",D360="",F360=""),"",IF(NOT(ISNUMBER(B360)),"Needs a date",IF(D360="","Needs a client",IF(COUNTIF(Clients!$B$6:$B$105,D360)=0,"Not on Clients",IF(AND(F360="",INT(B360)<TODAY()),"Needs a status",""))))) | I360: =IF(ISNUMBER(B360),INT(B360),0) | J360: =IF(ISNUMBER(B360),YEAR(B360)*100+MONTH(B360),"") | K360: =IF(AND(H360="",OR(F360="Attended",F360="No-show",AND(F360="Late cancel",Settings!$C$9="Yes"))),1,0) | L360: =IF(AND(H360="",F360="Attended"),1,0) | M360: =IF(AND(H360="",OR(F360="No-show",F360="Late cancel")),1,0) | N360: =IF(AND(H360="",F360="",D360<>"",I360>=TODAY()),ROUND((I360+IF(ISNUMBER(C360),MOD(C360,1),0))*1440,0)*10000+ROW(),"")
H361: =IF(AND(B361="",D361="",F361=""),"",IF(NOT(ISNUMBER(B361)),"Needs a date",IF(D361="","Needs a client",IF(COUNTIF(Clients!$B$6:$B$105,D361)=0,"Not on Clients",IF(AND(F361="",INT(B361)<TODAY()),"Needs a status",""))))) | I361: =IF(ISNUMBER(B361),INT(B361),0) | J361: =IF(ISNUMBER(B361),YEAR(B361)*100+MONTH(B361),"") | K361: =IF(AND(H361="",OR(F361="Attended",F361="No-show",AND(F361="Late cancel",Settings!$C$9="Yes"))),1,0) | L361: =IF(AND(H361="",F361="Attended"),1,0) | M361: =IF(AND(H361="",OR(F361="No-show",F361="Late cancel")),1,0) | N361: =IF(AND(H361="",F361="",D361<>"",I361>=TODAY()),ROUND((I361+IF(ISNUMBER(C361),MOD(C361,1),0))*1440,0)*10000+ROW(),"")
H362: =IF(AND(B362="",D362="",F362=""),"",IF(NOT(ISNUMBER(B362)),"Needs a date",IF(D362="","Needs a client",IF(COUNTIF(Clients!$B$6:$B$105,D362)=0,"Not on Clients",IF(AND(F362="",INT(B362)<TODAY()),"Needs a status",""))))) | I362: =IF(ISNUMBER(B362),INT(B362),0) | J362: =IF(ISNUMBER(B362),YEAR(B362)*100+MONTH(B362),"") | K362: =IF(AND(H362="",OR(F362="Attended",F362="No-show",AND(F362="Late cancel",Settings!$C$9="Yes"))),1,0) | L362: =IF(AND(H362="",F362="Attended"),1,0) | M362: =IF(AND(H362="",OR(F362="No-show",F362="Late cancel")),1,0) | N362: =IF(AND(H362="",F362="",D362<>"",I362>=TODAY()),ROUND((I362+IF(ISNUMBER(C362),MOD(C362,1),0))*1440,0)*10000+ROW(),"")
H363: =IF(AND(B363="",D363="",F363=""),"",IF(NOT(ISNUMBER(B363)),"Needs a date",IF(D363="","Needs a client",IF(COUNTIF(Clients!$B$6:$B$105,D363)=0,"Not on Clients",IF(AND(F363="",INT(B363)<TODAY()),"Needs a status",""))))) | I363: =IF(ISNUMBER(B363),INT(B363),0) | J363: =IF(ISNUMBER(B363),YEAR(B363)*100+MONTH(B363),"") | K363: =IF(AND(H363="",OR(F363="Attended",F363="No-show",AND(F363="Late cancel",Settings!$C$9="Yes"))),1,0) | L363: =IF(AND(H363="",F363="Attended"),1,0) | M363: =IF(AND(H363="",OR(F363="No-show",F363="Late cancel")),1,0) | N363: =IF(AND(H363="",F363="",D363<>"",I363>=TODAY()),ROUND((I363+IF(ISNUMBER(C363),MOD(C363,1),0))*1440,0)*10000+ROW(),"")
H364: =IF(AND(B364="",D364="",F364=""),"",IF(NOT(ISNUMBER(B364)),"Needs a date",IF(D364="","Needs a client",IF(COUNTIF(Clients!$B$6:$B$105,D364)=0,"Not on Clients",IF(AND(F364="",INT(B364)<TODAY()),"Needs a status",""))))) | I364: =IF(ISNUMBER(B364),INT(B364),0) | J364: =IF(ISNUMBER(B364),YEAR(B364)*100+MONTH(B364),"") | K364: =IF(AND(H364="",OR(F364="Attended",F364="No-show",AND(F364="Late cancel",Settings!$C$9="Yes"))),1,0) | L364: =IF(AND(H364="",F364="Attended"),1,0) | M364: =IF(AND(H364="",OR(F364="No-show",F364="Late cancel")),1,0) | N364: =IF(AND(H364="",F364="",D364<>"",I364>=TODAY()),ROUND((I364+IF(ISNUMBER(C364),MOD(C364,1),0))*1440,0)*10000+ROW(),"")
H365: =IF(AND(B365="",D365="",F365=""),"",IF(NOT(ISNUMBER(B365)),"Needs a date",IF(D365="","Needs a client",IF(COUNTIF(Clients!$B$6:$B$105,D365)=0,"Not on Clients",IF(AND(F365="",INT(B365)<TODAY()),"Needs a status",""))))) | I365: =IF(ISNUMBER(B365),INT(B365),0) | J365: =IF(ISNUMBER(B365),YEAR(B365)*100+MONTH(B365),"") | K365: =IF(AND(H365="",OR(F365="Attended",F365="No-show",AND(F365="Late cancel",Settings!$C$9="Yes"))),1,0) | L365: =IF(AND(H365="",F365="Attended"),1,0) | M365: =IF(AND(H365="",OR(F365="No-show",F365="Late cancel")),1,0) | N365: =IF(AND(H365="",F365="",D365<>"",I365>=TODAY()),ROUND((I365+IF(ISNUMBER(C365),MOD(C365,1),0))*1440,0)*10000+ROW(),"")
...

Sheet Clients
B2: Clients
B3: Each client once. Sessions, packages and check-ins add up from the other tabs.
B5: Client | C5: Phone or email | D5: Started | E5: Goal | F5: Status | G5: Attended | H5: This month | I5: Missed | J5: Bought | K5: Used | L5: Left | M5: Last session | N5: Next check-in | O5: Owed | P5: Needs
B6: Maya Ortiz | C6: maya.o@mail.example | D6: 46053 | E6: Stronger legs and back, run a 10 km in spring | F6: Active | G6: =IF(B6="","",SUMIFS(Sessions!$L$6:$L$3005,Sessions!$D$6:$D$3005,B6)) | H6: =IF(B6="","",SUMIFS(Sessions!$L$6:$L$3005,Sessions!$D$6:$D$3005,B6,Sessions!$J$6:$J$3005,(YEAR(TODAY())*100+MONTH(TODAY())))) | I6: =IF(B6="","",SUMIFS(Sessions!$M$6:$M$3005,Sessions!$D$6:$D$3005,B6)) | J6: =IF(B6="","",SUMIFS(Packages!$D$6:$D$505,Packages!$C$6:$C$505,B6,Packages!$M$6:$M$505,1)) | K6: =IF(B6="","",SUMIFS(Sessions!$K$6:$K$3005,Sessions!$D$6:$D$3005,B6)) | L6: =IF(OR(B6="",J6=0),"",J6-K6) | M6: =IF(B6="","",IF(SUMPRODUCT(MAX((Sessions!$D$6:$D$3005=B6)*Sessions!$L$6:$L$3005*Sessions!$I$6:$I$3005))=0,"",SUMPRODUCT(MAX((Sessions!$D$6:$D$3005=B6)*Sessions!$L$6:$L$3005*Sessions!$I$6:$I$3005)))) | N6: =IF(OR(B6="",F6="Finished"),"",IF(S6>0,S6+7*N(Settings!$C$8),IF(ISNUMBER(D6),INT(D6)+7*N(Settings!$C$8),""))) | O6: =IF(B6="","",SUMIFS(Packages!$J$6:$J$505,Packages!$C$6:$C$505,B6,Packages!$M$6:$M$505,1)) | P6: =IF(B6="","",IF(COUNTIF(Clients!$B$6:$B$105,B6)>1,"Listed twice",IF(O6>0,"Owes money",IF(F6="Finished","",IF(F6="Paused","",IF(AND(J6>0,L6<=0),"No sessions left",IF(AND(J6>0,L6<=N(Settings!$C$7)),"Few sessions left",IF(AND(Q6>0,L6>0,Q6<TODAY()),"Package expired",IF(AND(Q6>0,L6>0,Q6-TODAY()<=14),"Package ends soon",IF(AND(N6<>"",N6<=TODAY()),"Check-in due",""))))))))) | Q6: =IF(B6="",0,SUMPRODUCT(MAX((Packages!$C$6:$C$505=B6)*Packages!$N$6:$N$505))) | R6: =IF(P6<>"",ROW(),"") | S6: =IF(B6="",0,SUMPRODUCT(MAX(('Check-ins'!$C$6:$C$1505=B6)*'Check-ins'!$P$6:$P$1505))) | T6: =IF(AND(B6<>"",F6<>"Paused",F6<>"Finished",J6>0,L6<=N(Settings!$C$7)),1,0) | U6: =IF(AND(B6<>"",F6<>"Paused",F6<>"Finished",N6<>"",N6<=TODAY()),1,0) | V6: =IF(AND(B6<>"",F6<>"Paused",F6<>"Finished"),1,0)
B7: Ben Carter | C7: ben.c@mail.example | D7: 46093 | E7: Lose 8 kg before the summer | F7: Active | G7: =IF(B7="","",SUMIFS(Sessions!$L$6:$L$3005,Sessions!$D$6:$D$3005,B7)) | H7: =IF(B7="","",SUMIFS(Sessions!$L$6:$L$3005,Sessions!$D$6:$D$3005,B7,Sessions!$J$6:$J$3005,(YEAR(TODAY())*100+MONTH(TODAY())))) | I7: =IF(B7="","",SUMIFS(Sessions!$M$6:$M$3005,Sessions!$D$6:$D$3005,B7)) | J7: =IF(B7="","",SUMIFS(Packages!$D$6:$D$505,Packages!$C$6:$C$505,B7,Packages!$M$6:$M$505,1)) | K7: =IF(B7="","",SUMIFS(Sessions!$K$6:$K$3005,Sessions!$D$6:$D$3005,B7)) | L7: =IF(OR(B7="",J7=0),"",J7-K7) | M7: =IF(B7="","",IF(SUMPRODUCT(MAX((Sessions!$D$6:$D$3005=B7)*Sessions!$L$6:$L$3005*Sessions!$I$6:$I$3005))=0,"",SUMPRODUCT(MAX((Sessions!$D$6:$D$3005=B7)*Sessions!$L$6:$L$3005*Sessions!$I$6:$I$3005)))) | N7: =IF(OR(B7="",F7="Finished"),"",IF(S7>0,S7+7*N(Settings!$C$8),IF(ISNUMBER(D7),INT(D7)+7*N(Settings!$C$8),""))) | O7: =IF(B7="","",SUMIFS(Packages!$J$6:$J$505,Packages!$C$6:$C$505,B7,Packages!$M$6:$M$505,1)) | P7: =IF(B7="","",IF(COUNTIF(Clients!$B$6:$B$105,B7)>1,"Listed twice",IF(O7>0,"Owes money",IF(F7="Finished","",IF(F7="Paused","",IF(AND(J7>0,L7<=0),"No sessions left",IF(AND(J7>0,L7<=N(Settings!$C$7)),"Few sessions left",IF(AND(Q7>0,L7>0,Q7<TODAY()),"Package expired",IF(AND(Q7>0,L7>0,Q7-TODAY()<=14),"Package ends soon",IF(AND(N7<>"",N7<=TODAY()),"Check-in due",""))))))))) | Q7: =IF(B7="",0,SUMPRODUCT(MAX((Packages!$C$6:$C$505=B7)*Packages!$N$6:$N$505))) | R7: =IF(P7<>"",ROW(),"") | S7: =IF(B7="",0,SUMPRODUCT(MAX(('Check-ins'!$C$6:$C$1505=B7)*'Check-ins'!$P$6:$P$1505))) | T7: =IF(AND(B7<>"",F7<>"Paused",F7<>"Finished",J7>0,L7<=N(Settings!$C$7)),1,0) | U7: =IF(AND(B7<>"",F7<>"Paused",F7<>"Finished",N7<>"",N7<=TODAY()),1,0) | V7: =IF(AND(B7<>"",F7<>"Paused",F7<>"Finished"),1,0)
B8: Priya Nair | C8: priya.n@mail.example | D8: 46113 | E8: Back to training after a shoulder injury | F8: Active | G8: =IF(B8="","",SUMIFS(Sessions!$L$6:$L$3005,Sessions!$D$6:$D$3005,B8)) | H8: =IF(B8="","",SUMIFS(Sessions!$L$6:$L$3005,Sessions!$D$6:$D$3005,B8,Sessions!$J$6:$J$3005,(YEAR(TODAY())*100+MONTH(TODAY())))) | I8: =IF(B8="","",SUMIFS(Sessions!$M$6:$M$3005,Sessions!$D$6:$D$3005,B8)) | J8: =IF(B8="","",SUMIFS(Packages!$D$6:$D$505,Packages!$C$6:$C$505,B8,Packages!$M$6:$M$505,1)) | K8: =IF(B8="","",SUMIFS(Sessions!$K$6:$K$3005,Sessions!$D$6:$D$3005,B8)) | L8: =IF(OR(B8="",J8=0),"",J8-K8) | M8: =IF(B8="","",IF(SUMPRODUCT(MAX((Sessions!$D$6:$D$3005=B8)*Sessions!$L$6:$L$3005*Sessions!$I$6:$I$3005))=0,"",SUMPRODUCT(MAX((Sessions!$D$6:$D$3005=B8)*Sessions!$L$6:$L$3005*Sessions!$I$6:$I$3005)))) | N8: =IF(OR(B8="",F8="Finished"),"",IF(S8>0,S8+7*N(Settings!$C$8),IF(ISNUMBER(D8),INT(D8)+7*N(Settings!$C$8),""))) | O8: =IF(B8="","",SUMIFS(Packages!$J$6:$J$505,Packages!$C$6:$C$505,B8,Packages!$M$6:$M$505,1)) | P8: =IF(B8="","",IF(COUNTIF(Clients!$B$6:$B$105,B8)>1,"Listed twice",IF(O8>0,"Owes money",IF(F8="Finished","",IF(F8="Paused","",IF(AND(J8>0,L8<=0),"No sessions left",IF(AND(J8>0,L8<=N(Settings!$C$7)),"Few sessions left",IF(AND(Q8>0,L8>0,Q8<TODAY()),"Package expired",IF(AND(Q8>0,L8>0,Q8-TODAY()<=14),"Package ends soon",IF(AND(N8<>"",N8<=TODAY()),"Check-in due",""))))))))) | Q8: =IF(B8="",0,SUMPRODUCT(MAX((Packages!$C$6:$C$505=B8)*Packages!$N$6:$N$505))) | R8: =IF(P8<>"",ROW(),"") | S8: =IF(B8="",0,SUMPRODUCT(MAX(('Check-ins'!$C$6:$C$1505=B8)*'Check-ins'!$P$6:$P$1505))) | T8: =IF(AND(B8<>"",F8<>"Paused",F8<>"Finished",J8>0,L8<=N(Settings!$C$7)),1,0) | U8: =IF(AND(B8<>"",F8<>"Paused",F8<>"Finished",N8<>"",N8<=TODAY()),1,0) | V8: =IF(AND(B8<>"",F8<>"Paused",F8<>"Finished"),1,0)
B9: Tom Walsh | C9: tom.w@mail.example | D9: 46143 | E9: First pull-up | F9: Active | G9: =IF(B9="","",SUMIFS(Sessions!$L$6:$L$3005,Sessions!$D$6:$D$3005,B9)) | H9: =IF(B9="","",SUMIFS(Sessions!$L$6:$L$3005,Sessions!$D$6:$D$3005,B9,Sessions!$J$6:$J$3005,(YEAR(TODAY())*100+MONTH(TODAY())))) | I9: =IF(B9="","",SUMIFS(Sessions!$M$6:$M$3005,Sessions!$D$6:$D$3005,B9)) | J9: =IF(B9="","",SUMIFS(Packages!$D$6:$D$505,Packages!$C$6:$C$505,B9,Packages!$M$6:$M$505,1)) | K9: =IF(B9="","",SUMIFS(Sessions!$K$6:$K$3005,Sessions!$D$6:$D$3005,B9)) | L9: =IF(OR(B9="",J9=0),"",J9-K9) | M9: =IF(B9="","",IF(SUMPRODUCT(MAX((Sessions!$D$6:$D$3005=B9)*Sessions!$L$6:$L$3005*Sessions!$I$6:$I$3005))=0,"",SUMPRODUCT(MAX((Sessions!$D$6:$D$3005=B9)*Sessions!$L$6:$L$3005*Sessions!$I$6:$I$3005)))) | N9: =IF(OR(B9="",F9="Finished"),"",IF(S9>0,S9+7*N(Settings!$C$8),IF(ISNUMBER(D9),INT(D9)+7*N(Settings!$C$8),""))) | O9: =IF(B9="","",SUMIFS(Packages!$J$6:$J$505,Packages!$C$6:$C$505,B9,Packages!$M$6:$M$505,1)) | P9: =IF(B9="","",IF(COUNTIF(Clients!$B$6:$B$105,B9)>1,"Listed twice",IF(O9>0,"Owes money",IF(F9="Finished","",IF(F9="Paused","",IF(AND(J9>0,L9<=0),"No sessions left",IF(AND(J9>0,L9<=N(Settings!$C$7)),"Few sessions left",IF(AND(Q9>0,L9>0,Q9<TODAY()),"Package expired",IF(AND(Q9>0,L9>0,Q9-TODAY()<=14),"Package ends soon",IF(AND(N9<>"",N9<=TODAY()),"Check-in due",""))))))))) | Q9: =IF(B9="",0,SUMPRODUCT(MAX((Packages!$C$6:$C$505=B9)*Packages!$N$6:$N$505))) | R9: =IF(P9<>"",ROW(),"") | S9: =IF(B9="",0,SUMPRODUCT(MAX(('Check-ins'!$C$6:$C$1505=B9)*'Check-ins'!$P$6:$P$1505))) | T9: =IF(AND(B9<>"",F9<>"Paused",F9<>"Finished",J9>0,L9<=N(Settings!$C$7)),1,0) | U9: =IF(AND(B9<>"",F9<>"Paused",F9<>"Finished",N9<>"",N9<=TODAY()),1,0) | V9: =IF(AND(B9<>"",F9<>"Paused",F9<>"Finished"),1,0)
B10: Leah Fischer | C10: leah.f@mail.example | D10: 46173 | E10: Strength and energy for work | F10: Active | G10: =IF(B10="","",SUMIFS(Sessions!$L$6:$L$3005,Sessions!$D$6:$D$3005,B10)) | H10: =IF(B10="","",SUMIFS(Sessions!$L$6:$L$3005,Sessions!$D$6:$D$3005,B10,Sessions!$J$6:$J$3005,(YEAR(TODAY())*100+MONTH(TODAY())))) | I10: =IF(B10="","",SUMIFS(Sessions!$M$6:$M$3005,Sessions!$D$6:$D$3005,B10)) | J10: =IF(B10="","",SUMIFS(Packages!$D$6:$D$505,Packages!$C$6:$C$505,B10,Packages!$M$6:$M$505,1)) | K10: =IF(B10="","",SUMIFS(Sessions!$K$6:$K$3005,Sessions!$D$6:$D$3005,B10)) | L10: =IF(OR(B10="",J10=0),"",J10-K10) | M10: =IF(B10="","",IF(SUMPRODUCT(MAX((Sessions!$D$6:$D$3005=B10)*Sessions!$L$6:$L$3005*Sessions!$I$6:$I$3005))=0,"",SUMPRODUCT(MAX((Sessions!$D$6:$D$3005=B10)*Sessions!$L$6:$L$3005*Sessions!$I$6:$I$3005)))) | N10: =IF(OR(B10="",F10="Finished"),"",IF(S10>0,S10+7*N(Settings!$C$8),IF(ISNUMBER(D10),INT(D10)+7*N(Settings!$C$8),""))) | O10: =IF(B10="","",SUMIFS(Packages!$J$6:$J$505,Packages!$C$6:$C$505,B10,Packages!$M$6:$M$505,1)) | P10: =IF(B10="","",IF(COUNTIF(Clients!$B$6:$B$105,B10)>1,"Listed twice",IF(O10>0,"Owes money",IF(F10="Finished","",IF(F10="Paused","",IF(AND(J10>0,L10<=0),"No sessions left",IF(AND(J10>0,L10<=N(Settings!$C$7)),"Few sessions left",IF(AND(Q10>0,L10>0,Q10<TODAY()),"Package expired",IF(AND(Q10>0,L10>0,Q10-TODAY()<=14),"Package ends soon",IF(AND(N10<>"",N10<=TODAY()),"Check-in due",""))))))))) | Q10: =IF(B10="",0,SUMPRODUCT(MAX((Packages!$C$6:$C$505=B10)*Packages!$N$6:$N$505))) | R10: =IF(P10<>"",ROW(),"") | S10: =IF(B10="",0,SUMPRODUCT(MAX(('Check-ins'!$C$6:$C$1505=B10)*'Check-ins'!$P$6:$P$1505))) | T10: =IF(AND(B10<>"",F10<>"Paused",F10<>"Finished",J10>0,L10<=N(Settings!$C$7)),1,0) | U10: =IF(AND(B10<>"",F10<>"Paused",F10<>"Finished",N10<>"",N10<=TODAY()),1,0) | V10: =IF(AND(B10<>"",F10<>"Paused",F10<>"Finished"),1,0)
B11: Omar Haddad | C11: omar.h@mail.example | D11: 46193 | E11: Row 1 km under 4 minutes | F11: Active | G11: =IF(B11="","",SUMIFS(Sessions!$L$6:$L$3005,Sessions!$D$6:$D$3005,B11)) | H11: =IF(B11="","",SUMIFS(Sessions!$L$6:$L$3005,Sessions!$D$6:$D$3005,B11,Sessions!$J$6:$J$3005,(YEAR(TODAY())*100+MONTH(TODAY())))) | I11: =IF(B11="","",SUMIFS(Sessions!$M$6:$M$3005,Sessions!$D$6:$D$3005,B11)) | J11: =IF(B11="","",SUMIFS(Packages!$D$6:$D$505,Packages!$C$6:$C$505,B11,Packages!$M$6:$M$505,1)) | K11: =IF(B11="","",SUMIFS(Sessions!$K$6:$K$3005,Sessions!$D$6:$D$3005,B11)) | L11: =IF(OR(B11="",J11=0),"",J11-K11) | M11: =IF(B11="","",IF(SUMPRODUCT(MAX((Sessions!$D$6:$D$3005=B11)*Sessions!$L$6:$L$3005*Sessions!$I$6:$I$3005))=0,"",SUMPRODUCT(MAX((Sessions!$D$6:$D$3005=B11)*Sessions!$L$6:$L$3005*Sessions!$I$6:$I$3005)))) | N11: =IF(OR(B11="",F11="Finished"),"",IF(S11>0,S11+7*N(Settings!$C$8),IF(ISNUMBER(D11),INT(D11)+7*N(Settings!$C$8),""))) | O11: =IF(B11="","",SUMIFS(Packages!$J$6:$J$505,Packages!$C$6:$C$505,B11,Packages!$M$6:$M$505,1)) | P11: =IF(B11="","",IF(COUNTIF(Clients!$B$6:$B$105,B11)>1,"Listed twice",IF(O11>0,"Owes money",IF(F11="Finished","",IF(F11="Paused","",IF(AND(J11>0,L11<=0),"No sessions left",IF(AND(J11>0,L11<=N(Settings!$C$7)),"Few sessions left",IF(AND(Q11>0,L11>0,Q11<TODAY()),"Package expired",IF(AND(Q11>0,L11>0,Q11-TODAY()<=14),"Package ends soon",IF(AND(N11<>"",N11<=TODAY()),"Check-in due",""))))))))) | Q11: =IF(B11="",0,SUMPRODUCT(MAX((Packages!$C$6:$C$505=B11)*Packages!$N$6:$N$505))) | R11: =IF(P11<>"",ROW(),"") | S11: =IF(B11="",0,SUMPRODUCT(MAX(('Check-ins'!$C$6:$C$1505=B11)*'Check-ins'!$P$6:$P$1505))) | T11: =IF(AND(B11<>"",F11<>"Paused",F11<>"Finished",J11>0,L11<=N(Settings!$C$7)),1,0) | U11: =IF(AND(B11<>"",F11<>"Paused",F11<>"Finished",N11<>"",N11<=TODAY()),1,0) | V11: =IF(AND(B11<>"",F11<>"Paused",F11<>"Finished"),1,0)
B12: Grace Kim | C12: grace.k@mail.example | D12: 46143 | E12: Tone up for a wedding | F12: Paused | G12: =IF(B12="","",SUMIFS(Sessions!$L$6:$L$3005,Sessions!$D$6:$D$3005,B12)) | H12: =IF(B12="","",SUMIFS(Sessions!$L$6:$L$3005,Sessions!$D$6:$D$3005,B12,Sessions!$J$6:$J$3005,(YEAR(TODAY())*100+MONTH(TODAY())))) | I12: =IF(B12="","",SUMIFS(Sessions!$M$6:$M$3005,Sessions!$D$6:$D$3005,B12)) | J12: =IF(B12="","",SUMIFS(Packages!$D$6:$D$505,Packages!$C$6:$C$505,B12,Packages!$M$6:$M$505,1)) | K12: =IF(B12="","",SUMIFS(Sessions!$K$6:$K$3005,Sessions!$D$6:$D$3005,B12)) | L12: =IF(OR(B12="",J12=0),"",J12-K12) | M12: =IF(B12="","",IF(SUMPRODUCT(MAX((Sessions!$D$6:$D$3005=B12)*Sessions!$L$6:$L$3005*Sessions!$I$6:$I$3005))=0,"",SUMPRODUCT(MAX((Sessions!$D$6:$D$3005=B12)*Sessions!$L$6:$L$3005*Sessions!$I$6:$I$3005)))) | N12: =IF(OR(B12="",F12="Finished"),"",IF(S12>0,S12+7*N(Settings!$C$8),IF(ISNUMBER(D12),INT(D12)+7*N(Settings!$C$8),""))) | O12: =IF(B12="","",SUMIFS(Packages!$J$6:$J$505,Packages!$C$6:$C$505,B12,Packages!$M$6:$M$505,1)) | P12: =IF(B12="","",IF(COUNTIF(Clients!$B$6:$B$105,B12)>1,"Listed twice",IF(O12>0,"Owes money",IF(F12="Finished","",IF(F12="Paused","",IF(AND(J12>0,L12<=0),"No sessions left",IF(AND(J12>0,L12<=N(Settings!$C$7)),"Few sessions left",IF(AND(Q12>0,L12>0,Q12<TODAY()),"Package expired",IF(AND(Q12>0,L12>0,Q12-TODAY()<=14),"Package ends soon",IF(AND(N12<>"",N12<=TODAY()),"Check-in due",""))))))))) | Q12: =IF(B12="",0,SUMPRODUCT(MAX((Packages!$C$6:$C$505=B12)*Packages!$N$6:$N$505))) | R12: =IF(P12<>"",ROW(),"") | S12: =IF(B12="",0,SUMPRODUCT(MAX(('Check-ins'!$C$6:$C$1505=B12)*'Check-ins'!$P$6:$P$1505))) | T12: =IF(AND(B12<>"",F12<>"Paused",F12<>"Finished",J12>0,L12<=N(Settings!$C$7)),1,0) | U12: =IF(AND(B12<>"",F12<>"Paused",F12<>"Finished",N12<>"",N12<=TODAY()),1,0) | V12: =IF(AND(B12<>"",F12<>"Paused",F12<>"Finished"),1,0)
B13: Luis Moreno | C13: luis.m@mail.example | D13: 46233 | E13: Build muscle | F13: Active | G13: =IF(B13="","",SUMIFS(Sessions!$L$6:$L$3005,Sessions!$D$6:$D$3005,B13)) | H13: =IF(B13="","",SUMIFS(Sessions!$L$6:$L$3005,Sessions!$D$6:$D$3005,B13,Sessions!$J$6:$J$3005,(YEAR(TODAY())*100+MONTH(TODAY())))) | I13: =IF(B13="","",SUMIFS(Sessions!$M$6:$M$3005,Sessions!$D$6:$D$3005,B13)) | J13: =IF(B13="","",SUMIFS(Packages!$D$6:$D$505,Packages!$C$6:$C$505,B13,Packages!$M$6:$M$505,1)) | K13: =IF(B13="","",SUMIFS(Sessions!$K$6:$K$3005,Sessions!$D$6:$D$3005,B13)) | L13: =IF(OR(B13="",J13=0),"",J13-K13) | M13: =IF(B13="","",IF(SUMPRODUCT(MAX((Sessions!$D$6:$D$3005=B13)*Sessions!$L$6:$L$3005*Sessions!$I$6:$I$3005))=0,"",SUMPRODUCT(MAX((Sessions!$D$6:$D$3005=B13)*Sessions!$L$6:$L$3005*Sessions!$I$6:$I$3005)))) | N13: =IF(OR(B13="",F13="Finished"),"",IF(S13>0,S13+7*N(Settings!$C$8),IF(ISNUMBER(D13),INT(D13)+7*N(Settings!$C$8),""))) | O13: =IF(B13="","",SUMIFS(Packages!$J$6:$J$505,Packages!$C$6:$C$505,B13,Packages!$M$6:$M$505,1)) | P13: =IF(B13="","",IF(COUNTIF(Clients!$B$6:$B$105,B13)>1,"Listed twice",IF(O13>0,"Owes money",IF(F13="Finished","",IF(F13="Paused","",IF(AND(J13>0,L13<=0),"No sessions left",IF(AND(J13>0,L13<=N(Settings!$C$7)),"Few sessions left",IF(AND(Q13>0,L13>0,Q13<TODAY()),"Package expired",IF(AND(Q13>0,L13>0,Q13-TODAY()<=14),"Package ends soon",IF(AND(N13<>"",N13<=TODAY()),"Check-in due",""))))))))) | Q13: =IF(B13="",0,SUMPRODUCT(MAX((Packages!$C$6:$C$505=B13)*Packages!$N$6:$N$505))) | R13: =IF(P13<>"",ROW(),"") | S13: =IF(B13="",0,SUMPRODUCT(MAX(('Check-ins'!$C$6:$C$1505=B13)*'Check-ins'!$P$6:$P$1505))) | T13: =IF(AND(B13<>"",F13<>"Paused",F13<>"Finished",J13>0,L13<=N(Settings!$C$7)),1,0) | U13: =IF(AND(B13<>"",F13<>"Paused",F13<>"Finished",N13<>"",N13<=TODAY()),1,0) | V13: =IF(AND(B13<>"",F13<>"Paused",F13<>"Finished"),1,0)
B14: Hannah Brooks | C14: hannah.b@mail.example | D14: 45993 | E14: Stay fit and flexible | F14: Finished | G14: =IF(B14="","",SUMIFS(Sessions!$L$6:$L$3005,Sessions!$D$6:$D$3005,B14)) | H14: =IF(B14="","",SUMIFS(Sessions!$L$6:$L$3005,Sessions!$D$6:$D$3005,B14,Sessions!$J$6:$J$3005,(YEAR(TODAY())*100+MONTH(TODAY())))) | I14: =IF(B14="","",SUMIFS(Sessions!$M$6:$M$3005,Sessions!$D$6:$D$3005,B14)) | J14: =IF(B14="","",SUMIFS(Packages!$D$6:$D$505,Packages!$C$6:$C$505,B14,Packages!$M$6:$M$505,1)) | K14: =IF(B14="","",SUMIFS(Sessions!$K$6:$K$3005,Sessions!$D$6:$D$3005,B14)) | L14: =IF(OR(B14="",J14=0),"",J14-K14) | M14: =IF(B14="","",IF(SUMPRODUCT(MAX((Sessions!$D$6:$D$3005=B14)*Sessions!$L$6:$L$3005*Sessions!$I$6:$I$3005))=0,"",SUMPRODUCT(MAX((Sessions!$D$6:$D$3005=B14)*Sessions!$L$6:$L$3005*Sessions!$I$6:$I$3005)))) | N14: =IF(OR(B14="",F14="Finished"),"",IF(S14>0,S14+7*N(Settings!$C$8),IF(ISNUMBER(D14),INT(D14)+7*N(Settings!$C$8),""))) | O14: =IF(B14="","",SUMIFS(Packages!$J$6:$J$505,Packages!$C$6:$C$505,B14,Packages!$M$6:$M$505,1)) | P14: =IF(B14="","",IF(COUNTIF(Clients!$B$6:$B$105,B14)>1,"Listed twice",IF(O14>0,"Owes money",IF(F14="Finished","",IF(F14="Paused","",IF(AND(J14>0,L14<=0),"No sessions left",IF(AND(J14>0,L14<=N(Settings!$C$7)),"Few sessions left",IF(AND(Q14>0,L14>0,Q14<TODAY()),"Package expired",IF(AND(Q14>0,L14>0,Q14-TODAY()<=14),"Package ends soon",IF(AND(N14<>"",N14<=TODAY()),"Check-in due",""))))))))) | Q14: =IF(B14="",0,SUMPRODUCT(MAX((Packages!$C$6:$C$505=B14)*Packages!$N$6:$N$505))) | R14: =IF(P14<>"",ROW(),"") | S14: =IF(B14="",0,SUMPRODUCT(MAX(('Check-ins'!$C$6:$C$1505=B14)*'Check-ins'!$P$6:$P$1505))) | T14: =IF(AND(B14<>"",F14<>"Paused",F14<>"Finished",J14>0,L14<=N(Settings!$C$7)),1,0) | U14: =IF(AND(B14<>"",F14<>"Paused",F14<>"Finished",N14<>"",N14<=TODAY()),1,0) | V14: =IF(AND(B14<>"",F14<>"Paused",F14<>"Finished"),1,0)
B15: Sam Taylor | C15: sam.t@mail.example | D15: 46263 | E15: Get into a routine | F15: Active | G15: =IF(B15="","",SUMIFS(Sessions!$L$6:$L$3005,Sessions!$D$6:$D$3005,B15)) | H15: =IF(B15="","",SUMIFS(Sessions!$L$6:$L$3005,Sessions!$D$6:$D$3005,B15,Sessions!$J$6:$J$3005,(YEAR(TODAY())*100+MONTH(TODAY())))) | I15: =IF(B15="","",SUMIFS(Sessions!$M$6:$M$3005,Sessions!$D$6:$D$3005,B15)) | J15: =IF(B15="","",SUMIFS(Packages!$D$6:$D$505,Packages!$C$6:$C$505,B15,Packages!$M$6:$M$505,1)) | K15: =IF(B15="","",SUMIFS(Sessions!$K$6:$K$3005,Sessions!$D$6:$D$3005,B15)) | L15: =IF(OR(B15="",J15=0),"",J15-K15) | M15: =IF(B15="","",IF(SUMPRODUCT(MAX((Sessions!$D$6:$D$3005=B15)*Sessions!$L$6:$L$3005*Sessions!$I$6:$I$3005))=0,"",SUMPRODUCT(MAX((Sessions!$D$6:$D$3005=B15)*Sessions!$L$6:$L$3005*Sessions!$I$6:$I$3005)))) | N15: =IF(OR(B15="",F15="Finished"),"",IF(S15>0,S15+7*N(Settings!$C$8),IF(ISNUMBER(D15),INT(D15)+7*N(Settings!$C$8),""))) | O15: =IF(B15="","",SUMIFS(Packages!$J$6:$J$505,Packages!$C$6:$C$505,B15,Packages!$M$6:$M$505,1)) | P15: =IF(B15="","",IF(COUNTIF(Clients!$B$6:$B$105,B15)>1,"Listed twice",IF(O15>0,"Owes money",IF(F15="Finished","",IF(F15="Paused","",IF(AND(J15>0,L15<=0),"No sessions left",IF(AND(J15>0,L15<=N(Settings!$C$7)),"Few sessions left",IF(AND(Q15>0,L15>0,Q15<TODAY()),"Package expired",IF(AND(Q15>0,L15>0,Q15-TODAY()<=14),"Package ends soon",IF(AND(N15<>"",N15<=TODAY()),"Check-in due",""))))))))) | Q15: =IF(B15="",0,SUMPRODUCT(MAX((Packages!$C$6:$C$505=B15)*Packages!$N$6:$N$505))) | R15: =IF(P15<>"",ROW(),"") | S15: =IF(B15="",0,SUMPRODUCT(MAX(('Check-ins'!$C$6:$C$1505=B15)*'Check-ins'!$P$6:$P$1505))) | T15: =IF(AND(B15<>"",F15<>"Paused",F15<>"Finished",J15>0,L15<=N(Settings!$C$7)),1,0) | U15: =IF(AND(B15<>"",F15<>"Paused",F15<>"Finished",N15<>"",N15<=TODAY()),1,0) | V15: =IF(AND(B15<>"",F15<>"Paused",F15<>"Finished"),1,0)
G16: =IF(B16="","",SUMIFS(Sessions!$L$6:$L$3005,Sessions!$D$6:$D$3005,B16)) | H16: =IF(B16="","",SUMIFS(Sessions!$L$6:$L$3005,Sessions!$D$6:$D$3005,B16,Sessions!$J$6:$J$3005,(YEAR(TODAY())*100+MONTH(TODAY())))) | I16: =IF(B16="","",SUMIFS(Sessions!$M$6:$M$3005,Sessions!$D$6:$D$3005,B16)) | J16: =IF(B16="","",SUMIFS(Packages!$D$6:$D$505,Packages!$C$6:$C$505,B16,Packages!$M$6:$M$505,1)) | K16: =IF(B16="","",SUMIFS(Sessions!$K$6:$K$3005,Sessions!$D$6:$D$3005,B16)) | L16: =IF(OR(B16="",J16=0),"",J16-K16) | M16: =IF(B16="","",IF(SUMPRODUCT(MAX((Sessions!$D$6:$D$3005=B16)*Sessions!$L$6:$L$3005*Sessions!$I$6:$I$3005))=0,"",SUMPRODUCT(MAX((Sessions!$D$6:$D$3005=B16)*Sessions!$L$6:$L$3005*Sessions!$I$6:$I$3005)))) | N16: =IF(OR(B16="",F16="Finished"),"",IF(S16>0,S16+7*N(Settings!$C$8),IF(ISNUMBER(D16),INT(D16)+7*N(Settings!$C$8),""))) | O16: =IF(B16="","",SUMIFS(Packages!$J$6:$J$505,Packages!$C$6:$C$505,B16,Packages!$M$6:$M$505,1)) | P16: =IF(B16="","",IF(COUNTIF(Clients!$B$6:$B$105,B16)>1,"Listed twice",IF(O16>0,"Owes money",IF(F16="Finished","",IF(F16="Paused","",IF(AND(J16>0,L16<=0),"No sessions left",IF(AND(J16>0,L16<=N(Settings!$C$7)),"Few sessions left",IF(AND(Q16>0,L16>0,Q16<TODAY()),"Package expired",IF(AND(Q16>0,L16>0,Q16-TODAY()<=14),"Package ends soon",IF(AND(N16<>"",N16<=TODAY()),"Check-in due",""))))))))) | Q16: =IF(B16="",0,SUMPRODUCT(MAX((Packages!$C$6:$C$505=B16)*Packages!$N$6:$N$505))) | R16: =IF(P16<>"",ROW(),"") | S16: =IF(B16="",0,SUMPRODUCT(MAX(('Check-ins'!$C$6:$C$1505=B16)*'Check-ins'!$P$6:$P$1505))) | T16: =IF(AND(B16<>"",F16<>"Paused",F16<>"Finished",J16>0,L16<=N(Settings!$C$7)),1,0) | U16: =IF(AND(B16<>"",F16<>"Paused",F16<>"Finished",N16<>"",N16<=TODAY()),1,0) | V16: =IF(AND(B16<>"",F16<>"Paused",F16<>"Finished"),1,0)
G17: =IF(B17="","",SUMIFS(Sessions!$L$6:$L$3005,Sessions!$D$6:$D$3005,B17)) | H17: =IF(B17="","",SUMIFS(Sessions!$L$6:$L$3005,Sessions!$D$6:$D$3005,B17,Sessions!$J$6:$J$3005,(YEAR(TODAY())*100+MONTH(TODAY())))) | I17: =IF(B17="","",SUMIFS(Sessions!$M$6:$M$3005,Sessions!$D$6:$D$3005,B17)) | J17: =IF(B17="","",SUMIFS(Packages!$D$6:$D$505,Packages!$C$6:$C$505,B17,Packages!$M$6:$M$505,1)) | K17: =IF(B17="","",SUMIFS(Sessions!$K$6:$K$3005,Sessions!$D$6:$D$3005,B17)) | L17: =IF(OR(B17="",J17=0),"",J17-K17) | M17: =IF(B17="","",IF(SUMPRODUCT(MAX((Sessions!$D$6:$D$3005=B17)*Sessions!$L$6:$L$3005*Sessions!$I$6:$I$3005))=0,"",SUMPRODUCT(MAX((Sessions!$D$6:$D$3005=B17)*Sessions!$L$6:$L$3005*Sessions!$I$6:$I$3005)))) | N17: =IF(OR(B17="",F17="Finished"),"",IF(S17>0,S17+7*N(Settings!$C$8),IF(ISNUMBER(D17),INT(D17)+7*N(Settings!$C$8),""))) | O17: =IF(B17="","",SUMIFS(Packages!$J$6:$J$505,Packages!$C$6:$C$505,B17,Packages!$M$6:$M$505,1)) | P17: =IF(B17="","",IF(COUNTIF(Clients!$B$6:$B$105,B17)>1,"Listed twice",IF(O17>0,"Owes money",IF(F17="Finished","",IF(F17="Paused","",IF(AND(J17>0,L17<=0),"No sessions left",IF(AND(J17>0,L17<=N(Settings!$C$7)),"Few sessions left",IF(AND(Q17>0,L17>0,Q17<TODAY()),"Package expired",IF(AND(Q17>0,L17>0,Q17-TODAY()<=14),"Package ends soon",IF(AND(N17<>"",N17<=TODAY()),"Check-in due",""))))))))) | Q17: =IF(B17="",0,SUMPRODUCT(MAX((Packages!$C$6:$C$505=B17)*Packages!$N$6:$N$505))) | R17: =IF(P17<>"",ROW(),"") | S17: =IF(B17="",0,SUMPRODUCT(MAX(('Check-ins'!$C$6:$C$1505=B17)*'Check-ins'!$P$6:$P$1505))) | T17: =IF(AND(B17<>"",F17<>"Paused",F17<>"Finished",J17>0,L17<=N(Settings!$C$7)),1,0) | U17: =IF(AND(B17<>"",F17<>"Paused",F17<>"Finished",N17<>"",N17<=TODAY()),1,0) | V17: =IF(AND(B17<>"",F17<>"Paused",F17<>"Finished"),1,0)
