Workbook

Sheet Dashboard
B2: =Setup!$C$4&" trip planner"
B3: The countdown, the budget, what is booked and what is next.
B4: =IF(Setup!$C$6="","",DAY(Setup!$C$6)&" "&CHOOSE(MONTH(Setup!$C$6),"Jan","Feb","Mar","Apr","May","Jun","Jul","Aug","Sep","Oct","Nov","Dec")&" "&YEAR(Setup!$C$6)&" to "&DAY(Setup!$C$7)&" "&CHOOSE(MONTH(Setup!$C$7),"Jan","Feb","Mar","Apr","May","Jun","Jul","Aug","Sep","Oct","Nov","Dec")&" "&YEAR(Setup!$C$7)&", "&Setup!$C$5&IF(Setup!$C$5=1," traveler"," travelers"))
B6: Days to go | C6: Nights | D6: Budget | E6: Booked and spent | F6: Left | G6: Still to pay | I6: Packed
B7: =IF(Setup!$C$6="","",IF(TODAY()<Setup!$C$6,Setup!$C$6-TODAY(),IF(TODAY()<=Setup!$C$7,"Day "&(TODAY()-Setup!$C$6+1),"Home"))) | C7: =IF(Setup!$C$6="","",Setup!$C$7-Setup!$C$6) | D7: =SUM(C12:C18) | E7: =SUM(D12:D18) | F7: =SUM(C12:C18)-SUM(D12:D18) | G7: =SUM(Bookings!$L$6:$L$105) | I7: =IF(COUNTIF('Packing list'!$B$6:$B$255,"?*")=0,"",COUNTIFS('Packing list'!$B$6:$B$255,"?*",'Packing list'!$E$6:$E$255,"?*")/COUNTIF('Packing list'!$B$6:$B$255,"?*"))
B11: Budget | C11: Planned | D11: Booked and spent | E11: Paid so far | F11: Left | G11: Used | I11: Next bookings | K11: Confirmation | L11: Still to pay
B12: Flights | C12: 2400 | D12: =SUMIFS(Bookings!$K$6:$K$105,Bookings!$O$6:$O$105,B12)+SUMIFS(Expenses!$G$6:$G$505,Expenses!$D$6:$D$505,B12) | E12: =SUMIFS(Bookings!$P$6:$P$105,Bookings!$O$6:$O$105,B12)+SUMIFS(Expenses!$G$6:$G$505,Expenses!$D$6:$D$505,B12) | F12: =C12-D12 | G12: =IF(N(C12)=0,"",REPT("█",MIN(10,MAX(0,ROUND((D12/C12)*10,0))))&REPT("░",10-MIN(10,MAX(0,ROUND((D12/C12)*10,0))))) | I12: =IF(O12="","",INT(O12)) | J12: =IF(O12="","",INDEX(Bookings!$C$6:$C$105,MATCH(O12,Bookings!$Q$6:$Q$105,0))) | K12: =IF(O12="","",INDEX(Bookings!$G$6:$G$105,MATCH(O12,Bookings!$Q$6:$Q$105,0))&"") | L12: =IF(O12="","",INDEX(Bookings!$L$6:$L$105,MATCH(O12,Bookings!$Q$6:$Q$105,0))) | O12: =IFERROR(SMALL(Bookings!$Q$6:$Q$105,1),"")
B13: Lodging | C13: 2200 | D13: =SUMIFS(Bookings!$K$6:$K$105,Bookings!$O$6:$O$105,B13)+SUMIFS(Expenses!$G$6:$G$505,Expenses!$D$6:$D$505,B13) | E13: =SUMIFS(Bookings!$P$6:$P$105,Bookings!$O$6:$O$105,B13)+SUMIFS(Expenses!$G$6:$G$505,Expenses!$D$6:$D$505,B13) | F13: =C13-D13 | G13: =IF(N(C13)=0,"",REPT("█",MIN(10,MAX(0,ROUND((D13/C13)*10,0))))&REPT("░",10-MIN(10,MAX(0,ROUND((D13/C13)*10,0))))) | I13: =IF(O13="","",INT(O13)) | J13: =IF(O13="","",INDEX(Bookings!$C$6:$C$105,MATCH(O13,Bookings!$Q$6:$Q$105,0))) | K13: =IF(O13="","",INDEX(Bookings!$G$6:$G$105,MATCH(O13,Bookings!$Q$6:$Q$105,0))&"") | L13: =IF(O13="","",INDEX(Bookings!$L$6:$L$105,MATCH(O13,Bookings!$Q$6:$Q$105,0))) | O13: =IFERROR(SMALL(Bookings!$Q$6:$Q$105,2),"")
B14: Transport | C14: 900 | D14: =SUMIFS(Bookings!$K$6:$K$105,Bookings!$O$6:$O$105,B14)+SUMIFS(Expenses!$G$6:$G$505,Expenses!$D$6:$D$505,B14) | E14: =SUMIFS(Bookings!$P$6:$P$105,Bookings!$O$6:$O$105,B14)+SUMIFS(Expenses!$G$6:$G$505,Expenses!$D$6:$D$505,B14) | F14: =C14-D14 | G14: =IF(N(C14)=0,"",REPT("█",MIN(10,MAX(0,ROUND((D14/C14)*10,0))))&REPT("░",10-MIN(10,MAX(0,ROUND((D14/C14)*10,0))))) | I14: =IF(O14="","",INT(O14)) | J14: =IF(O14="","",INDEX(Bookings!$C$6:$C$105,MATCH(O14,Bookings!$Q$6:$Q$105,0))) | K14: =IF(O14="","",INDEX(Bookings!$G$6:$G$105,MATCH(O14,Bookings!$Q$6:$Q$105,0))&"") | L14: =IF(O14="","",INDEX(Bookings!$L$6:$L$105,MATCH(O14,Bookings!$Q$6:$Q$105,0))) | O14: =IFERROR(SMALL(Bookings!$Q$6:$Q$105,3),"")
B15: Food | C15: 1300 | D15: =SUMIFS(Bookings!$K$6:$K$105,Bookings!$O$6:$O$105,B15)+SUMIFS(Expenses!$G$6:$G$505,Expenses!$D$6:$D$505,B15) | E15: =SUMIFS(Bookings!$P$6:$P$105,Bookings!$O$6:$O$105,B15)+SUMIFS(Expenses!$G$6:$G$505,Expenses!$D$6:$D$505,B15) | F15: =C15-D15 | G15: =IF(N(C15)=0,"",REPT("█",MIN(10,MAX(0,ROUND((D15/C15)*10,0))))&REPT("░",10-MIN(10,MAX(0,ROUND((D15/C15)*10,0))))) | I15: =IF(O15="","",INT(O15)) | J15: =IF(O15="","",INDEX(Bookings!$C$6:$C$105,MATCH(O15,Bookings!$Q$6:$Q$105,0))) | K15: =IF(O15="","",INDEX(Bookings!$G$6:$G$105,MATCH(O15,Bookings!$Q$6:$Q$105,0))&"") | L15: =IF(O15="","",INDEX(Bookings!$L$6:$L$105,MATCH(O15,Bookings!$Q$6:$Q$105,0))) | O15: =IFERROR(SMALL(Bookings!$Q$6:$Q$105,4),"")
B16: Activities | C16: 800 | D16: =SUMIFS(Bookings!$K$6:$K$105,Bookings!$O$6:$O$105,B16)+SUMIFS(Expenses!$G$6:$G$505,Expenses!$D$6:$D$505,B16) | E16: =SUMIFS(Bookings!$P$6:$P$105,Bookings!$O$6:$O$105,B16)+SUMIFS(Expenses!$G$6:$G$505,Expenses!$D$6:$D$505,B16) | F16: =C16-D16 | G16: =IF(N(C16)=0,"",REPT("█",MIN(10,MAX(0,ROUND((D16/C16)*10,0))))&REPT("░",10-MIN(10,MAX(0,ROUND((D16/C16)*10,0))))) | I16: =IF(O16="","",INT(O16)) | J16: =IF(O16="","",INDEX(Bookings!$C$6:$C$105,MATCH(O16,Bookings!$Q$6:$Q$105,0))) | K16: =IF(O16="","",INDEX(Bookings!$G$6:$G$105,MATCH(O16,Bookings!$Q$6:$Q$105,0))&"") | L16: =IF(O16="","",INDEX(Bookings!$L$6:$L$105,MATCH(O16,Bookings!$Q$6:$Q$105,0))) | O16: =IFERROR(SMALL(Bookings!$Q$6:$Q$105,5),"")
B17: Shopping | C17: 500 | D17: =SUMIFS(Bookings!$K$6:$K$105,Bookings!$O$6:$O$105,B17)+SUMIFS(Expenses!$G$6:$G$505,Expenses!$D$6:$D$505,B17) | E17: =SUMIFS(Bookings!$P$6:$P$105,Bookings!$O$6:$O$105,B17)+SUMIFS(Expenses!$G$6:$G$505,Expenses!$D$6:$D$505,B17) | F17: =C17-D17 | G17: =IF(N(C17)=0,"",REPT("█",MIN(10,MAX(0,ROUND((D17/C17)*10,0))))&REPT("░",10-MIN(10,MAX(0,ROUND((D17/C17)*10,0))))) | I17: =IF(O17="","",INT(O17)) | J17: =IF(O17="","",INDEX(Bookings!$C$6:$C$105,MATCH(O17,Bookings!$Q$6:$Q$105,0))) | K17: =IF(O17="","",INDEX(Bookings!$G$6:$G$105,MATCH(O17,Bookings!$Q$6:$Q$105,0))&"") | L17: =IF(O17="","",INDEX(Bookings!$L$6:$L$105,MATCH(O17,Bookings!$Q$6:$Q$105,0))) | O17: =IFERROR(SMALL(Bookings!$Q$6:$Q$105,6),"")
B18: Other | C18: 400 | D18: =SUMIFS(Bookings!$K$6:$K$105,Bookings!$O$6:$O$105,B18)+SUMIFS(Expenses!$G$6:$G$505,Expenses!$D$6:$D$505,B18) | E18: =SUMIFS(Bookings!$P$6:$P$105,Bookings!$O$6:$O$105,B18)+SUMIFS(Expenses!$G$6:$G$505,Expenses!$D$6:$D$505,B18) | F18: =C18-D18 | G18: =IF(N(C18)=0,"",REPT("█",MIN(10,MAX(0,ROUND((D18/C18)*10,0))))&REPT("░",10-MIN(10,MAX(0,ROUND((D18/C18)*10,0))))) | I18: =IF(O18="","",INT(O18)) | J18: =IF(O18="","",INDEX(Bookings!$C$6:$C$105,MATCH(O18,Bookings!$Q$6:$Q$105,0))) | K18: =IF(O18="","",INDEX(Bookings!$G$6:$G$105,MATCH(O18,Bookings!$Q$6:$Q$105,0))&"") | L18: =IF(O18="","",INDEX(Bookings!$L$6:$L$105,MATCH(O18,Bookings!$Q$6:$Q$105,0))) | O18: =IFERROR(SMALL(Bookings!$Q$6:$Q$105,7),"")
B19: Total | C19: =SUM(C12:C18) | D19: =SUM(D12:D18) | E19: =SUM(E12:E18) | F19: =SUM(F12:F18) | I19: =IF(O19="","",INT(O19)) | J19: =IF(O19="","",INDEX(Bookings!$C$6:$C$105,MATCH(O19,Bookings!$Q$6:$Q$105,0))) | K19: =IF(O19="","",INDEX(Bookings!$G$6:$G$105,MATCH(O19,Bookings!$Q$6:$Q$105,0))&"") | L19: =IF(O19="","",INDEX(Bookings!$L$6:$L$105,MATCH(O19,Bookings!$Q$6:$Q$105,0))) | O19: =IFERROR(SMALL(Bookings!$Q$6:$Q$105,8),"")
B20: Booked and spent counts the full cost of every booking, paid or not, plus the expenses.
I22: Itinerary | L22: Where
I23: =IF(P23="","",INT(P23)) | J23: =IF(P23="","",HOUR(P23)&":"&RIGHT("0"&MINUTE(P23),2)&" "&INDEX(Itinerary!$D$6:$D$305,MATCH(P23,Itinerary!$H$6:$H$305,0))) | L23: =IF(P23="","",INDEX(Itinerary!$E$6:$E$305,MATCH(P23,Itinerary!$H$6:$H$305,0))) | P23: =IFERROR(SMALL(Itinerary!$H$6:$H$305,COUNTIF(Itinerary!$H$6:$H$305,"<"&IF(TODAY()<Setup!$C$6,Setup!$C$6,TODAY()))+1),"")
I24: =IF(P24="","",IF(INT(P24)=INT(N(P23)),"",INT(P24))) | J24: =IF(P24="","",HOUR(P24)&":"&RIGHT("0"&MINUTE(P24),2)&" "&INDEX(Itinerary!$D$6:$D$305,MATCH(P24,Itinerary!$H$6:$H$305,0))) | L24: =IF(P24="","",INDEX(Itinerary!$E$6:$E$305,MATCH(P24,Itinerary!$H$6:$H$305,0))) | P24: =IFERROR(SMALL(Itinerary!$H$6:$H$305,COUNTIF(Itinerary!$H$6:$H$305,"<"&IF(TODAY()<Setup!$C$6,Setup!$C$6,TODAY()))+2),"")
I25: =IF(P25="","",IF(INT(P25)=INT(N(P24)),"",INT(P25))) | J25: =IF(P25="","",HOUR(P25)&":"&RIGHT("0"&MINUTE(P25),2)&" "&INDEX(Itinerary!$D$6:$D$305,MATCH(P25,Itinerary!$H$6:$H$305,0))) | L25: =IF(P25="","",INDEX(Itinerary!$E$6:$E$305,MATCH(P25,Itinerary!$H$6:$H$305,0))) | P25: =IFERROR(SMALL(Itinerary!$H$6:$H$305,COUNTIF(Itinerary!$H$6:$H$305,"<"&IF(TODAY()<Setup!$C$6,Setup!$C$6,TODAY()))+3),"")
I26: =IF(P26="","",IF(INT(P26)=INT(N(P25)),"",INT(P26))) | J26: =IF(P26="","",HOUR(P26)&":"&RIGHT("0"&MINUTE(P26),2)&" "&INDEX(Itinerary!$D$6:$D$305,MATCH(P26,Itinerary!$H$6:$H$305,0))) | L26: =IF(P26="","",INDEX(Itinerary!$E$6:$E$305,MATCH(P26,Itinerary!$H$6:$H$305,0))) | P26: =IFERROR(SMALL(Itinerary!$H$6:$H$305,COUNTIF(Itinerary!$H$6:$H$305,"<"&IF(TODAY()<Setup!$C$6,Setup!$C$6,TODAY()))+4),"")
I27: =IF(P27="","",IF(INT(P27)=INT(N(P26)),"",INT(P27))) | J27: =IF(P27="","",HOUR(P27)&":"&RIGHT("0"&MINUTE(P27),2)&" "&INDEX(Itinerary!$D$6:$D$305,MATCH(P27,Itinerary!$H$6:$H$305,0))) | L27: =IF(P27="","",INDEX(Itinerary!$E$6:$E$305,MATCH(P27,Itinerary!$H$6:$H$305,0))) | P27: =IFERROR(SMALL(Itinerary!$H$6:$H$305,COUNTIF(Itinerary!$H$6:$H$305,"<"&IF(TODAY()<Setup!$C$6,Setup!$C$6,TODAY()))+5),"")
I28: =IF(P28="","",IF(INT(P28)=INT(N(P27)),"",INT(P28))) | J28: =IF(P28="","",HOUR(P28)&":"&RIGHT("0"&MINUTE(P28),2)&" "&INDEX(Itinerary!$D$6:$D$305,MATCH(P28,Itinerary!$H$6:$H$305,0))) | L28: =IF(P28="","",INDEX(Itinerary!$E$6:$E$305,MATCH(P28,Itinerary!$H$6:$H$305,0))) | P28: =IFERROR(SMALL(Itinerary!$H$6:$H$305,COUNTIF(Itinerary!$H$6:$H$305,"<"&IF(TODAY()<Setup!$C$6,Setup!$C$6,TODAY()))+6),"")
I29: =IF(P29="","",IF(INT(P29)=INT(N(P28)),"",INT(P29))) | J29: =IF(P29="","",HOUR(P29)&":"&RIGHT("0"&MINUTE(P29),2)&" "&INDEX(Itinerary!$D$6:$D$305,MATCH(P29,Itinerary!$H$6:$H$305,0))) | L29: =IF(P29="","",INDEX(Itinerary!$E$6:$E$305,MATCH(P29,Itinerary!$H$6:$H$305,0))) | P29: =IFERROR(SMALL(Itinerary!$H$6:$H$305,COUNTIF(Itinerary!$H$6:$H$305,"<"&IF(TODAY()<Setup!$C$6,Setup!$C$6,TODAY()))+7),"")
I30: =IF(P30="","",IF(INT(P30)=INT(N(P29)),"",INT(P30))) | J30: =IF(P30="","",HOUR(P30)&":"&RIGHT("0"&MINUTE(P30),2)&" "&INDEX(Itinerary!$D$6:$D$305,MATCH(P30,Itinerary!$H$6:$H$305,0))) | L30: =IF(P30="","",INDEX(Itinerary!$E$6:$E$305,MATCH(P30,Itinerary!$H$6:$H$305,0))) | P30: =IFERROR(SMALL(Itinerary!$H$6:$H$305,COUNTIF(Itinerary!$H$6:$H$305,"<"&IF(TODAY()<Setup!$C$6,Setup!$C$6,TODAY()))+8),"")
I31: =IF(P31="","",IF(INT(P31)=INT(N(P30)),"",INT(P31))) | J31: =IF(P31="","",HOUR(P31)&":"&RIGHT("0"&MINUTE(P31),2)&" "&INDEX(Itinerary!$D$6:$D$305,MATCH(P31,Itinerary!$H$6:$H$305,0))) | L31: =IF(P31="","",INDEX(Itinerary!$E$6:$E$305,MATCH(P31,Itinerary!$H$6:$H$305,0))) | P31: =IFERROR(SMALL(Itinerary!$H$6:$H$305,COUNTIF(Itinerary!$H$6:$H$305,"<"&IF(TODAY()<Setup!$C$6,Setup!$C$6,TODAY()))+9),"")
I32: =IF(P32="","",IF(INT(P32)=INT(N(P31)),"",INT(P32))) | J32: =IF(P32="","",HOUR(P32)&":"&RIGHT("0"&MINUTE(P32),2)&" "&INDEX(Itinerary!$D$6:$D$305,MATCH(P32,Itinerary!$H$6:$H$305,0))) | L32: =IF(P32="","",INDEX(Itinerary!$E$6:$E$305,MATCH(P32,Itinerary!$H$6:$H$305,0))) | P32: =IFERROR(SMALL(Itinerary!$H$6:$H$305,COUNTIF(Itinerary!$H$6:$H$305,"<"&IF(TODAY()<Setup!$C$6,Setup!$C$6,TODAY()))+10),"")
I33: =IF(P33="","",IF(INT(P33)=INT(N(P32)),"",INT(P33))) | J33: =IF(P33="","",HOUR(P33)&":"&RIGHT("0"&MINUTE(P33),2)&" "&INDEX(Itinerary!$D$6:$D$305,MATCH(P33,Itinerary!$H$6:$H$305,0))) | L33: =IF(P33="","",INDEX(Itinerary!$E$6:$E$305,MATCH(P33,Itinerary!$H$6:$H$305,0))) | P33: =IFERROR(SMALL(Itinerary!$H$6:$H$305,COUNTIF(Itinerary!$H$6:$H$305,"<"&IF(TODAY()<Setup!$C$6,Setup!$C$6,TODAY()))+11),"")
I34: =IF(P34="","",IF(INT(P34)=INT(N(P33)),"",INT(P34))) | J34: =IF(P34="","",HOUR(P34)&":"&RIGHT("0"&MINUTE(P34),2)&" "&INDEX(Itinerary!$D$6:$D$305,MATCH(P34,Itinerary!$H$6:$H$305,0))) | L34: =IF(P34="","",INDEX(Itinerary!$E$6:$E$305,MATCH(P34,Itinerary!$H$6:$H$305,0))) | P34: =IFERROR(SMALL(Itinerary!$H$6:$H$305,COUNTIF(Itinerary!$H$6:$H$305,"<"&IF(TODAY()<Setup!$C$6,Setup!$C$6,TODAY()))+12),"")
I35: =IF(P35="","",IF(INT(P35)=INT(N(P34)),"",INT(P35))) | J35: =IF(P35="","",HOUR(P35)&":"&RIGHT("0"&MINUTE(P35),2)&" "&INDEX(Itinerary!$D$6:$D$305,MATCH(P35,Itinerary!$H$6:$H$305,0))) | L35: =IF(P35="","",INDEX(Itinerary!$E$6:$E$305,MATCH(P35,Itinerary!$H$6:$H$305,0))) | P35: =IFERROR(SMALL(Itinerary!$H$6:$H$305,COUNTIF(Itinerary!$H$6:$H$305,"<"&IF(TODAY()<Setup!$C$6,Setup!$C$6,TODAY()))+13),"")
I36: =IF(P36="","",IF(INT(P36)=INT(N(P35)),"",INT(P36))) | J36: =IF(P36="","",HOUR(P36)&":"&RIGHT("0"&MINUTE(P36),2)&" "&INDEX(Itinerary!$D$6:$D$305,MATCH(P36,Itinerary!$H$6:$H$305,0))) | L36: =IF(P36="","",INDEX(Itinerary!$E$6:$E$305,MATCH(P36,Itinerary!$H$6:$H$305,0))) | P36: =IFERROR(SMALL(Itinerary!$H$6:$H$305,COUNTIF(Itinerary!$H$6:$H$305,"<"&IF(TODAY()<Setup!$C$6,Setup!$C$6,TODAY()))+14),"")

Sheet Itinerary
B2: Itinerary
B3: What you plan to do, day by day. Put the lines in any order: the dashboard sorts them.
B5: Date | C5: Time | D5: Plan | E5: Where | F5: Booking | G5: Note
B6: 46315 | C6: 0.46180556 | D6: Flight to Tokyo | E6: Los Angeles airport | F6: KX7Q2M | H6: =IF(OR(B6="",D6=""),"",B6+N(C6)+ROW()/100000000) | I6: =IF(B6="","","Day "&(B6-Setup!$C$6+1))
B7: 46316 | C7: 0.64583333 | D7: Land at Haneda, train to Shinjuku | E7: Haneda airport | H7: =IF(OR(B7="",D7=""),"",B7+N(C7)+ROW()/100000000) | I7: =IF(B7="","","Day "&(B7-Setup!$C$6+1))
B8: 46316 | C8: 0.70833333 | D8: Check in | E8: Shinjuku hotel | F8: 88213-04 | H8: =IF(OR(B8="",D8=""),"",B8+N(C8)+ROW()/100000000) | I8: =IF(B8="","","Day "&(B8-Setup!$C$6+1))
B9: 46316 | C9: 0.79166667 | D9: Ramen dinner | E9: Omoide Yokocho | H9: =IF(OR(B9="",D9=""),"",B9+N(C9)+ROW()/100000000) | I9: =IF(B9="","","Day "&(B9-Setup!$C$6+1))
B10: 46317 | C10: 0.375 | D10: Meiji Shrine | E10: Harajuku | H10: =IF(OR(B10="",D10=""),"",B10+N(C10)+ROW()/100000000) | I10: =IF(B10="","","Day "&(B10-Setup!$C$6+1))
B11: 46317 | C11: 0.45833333 | D11: Walk Omotesando | E11: Omotesando | H11: =IF(OR(B11="",D11=""),"",B11+N(C11)+ROW()/100000000) | I11: =IF(B11="","","Day "&(B11-Setup!$C$6+1))
B12: 46317 | C12: 0.625 | D12: teamLab Planets | E12: Toyosu | F12: TLP-5521 | H12: =IF(OR(B12="",D12=""),"",B12+N(C12)+ROW()/100000000) | I12: =IF(B12="","","Day "&(B12-Setup!$C$6+1))
B13: 46317 | C13: 0.79166667 | D13: Shibuya crossing at night | E13: Shibuya | H13: =IF(OR(B13="",D13=""),"",B13+N(C13)+ROW()/100000000) | I13: =IF(B13="","","Day "&(B13-Setup!$C$6+1))
B14: 46318 | C14: 0.33333333 | D14: Breakfast at the outer market | E14: Tsukiji | H14: =IF(OR(B14="",D14=""),"",B14+N(C14)+ROW()/100000000) | I14: =IF(B14="","","Day "&(B14-Setup!$C$6+1))
B15: 46318 | C15: 0.45833333 | D15: Senso-ji temple | E15: Asakusa | H15: =IF(OR(B15="",D15=""),"",B15+N(C15)+ROW()/100000000) | I15: =IF(B15="","","Day "&(B15-Setup!$C$6+1))
B16: 46318 | C16: 0.66666667 | D16: Tokyo Skytree | E16: Oshiage | H16: =IF(OR(B16="",D16=""),"",B16+N(C16)+ROW()/100000000) | I16: =IF(B16="","","Day "&(B16-Setup!$C$6+1))
B17: 46319 | C17: 0.41666667 | D17: Sushi cooking class | E17: Tsukiji | F17: SC-3310 | H17: =IF(OR(B17="",D17=""),"",B17+N(C17)+ROW()/100000000) | I17: =IF(B17="","","Day "&(B17-Setup!$C$6+1))
B18: 46319 | C18: 0.625 | D18: Akihabara | E18: Akihabara | H18: =IF(OR(B18="",D18=""),"",B18+N(C18)+ROW()/100000000) | I18: =IF(B18="","","Day "&(B18-Setup!$C$6+1))
B19: 46320 | C19: 0.33333333 | D19: Day trip to Nikko | E19: Nikko | H19: =IF(OR(B19="",D19=""),"",B19+N(C19)+ROW()/100000000) | I19: =IF(B19="","","Day "&(B19-Setup!$C$6+1))
B20: 46321 | C20: 0.33333333 | D20: Exchange rail pass, train to Kyoto | E20: Tokyo station | F20: JRP-77410 | H20: =IF(OR(B20="",D20=""),"",B20+N(C20)+ROW()/100000000) | I20: =IF(B20="","","Day "&(B20-Setup!$C$6+1))
B21: 46321 | C21: 0.625 | D21: Check in | E21: Kyoto ryokan | F21: RK-2291 | H21: =IF(OR(B21="",D21=""),"",B21+N(C21)+ROW()/100000000) | I21: =IF(B21="","","Day "&(B21-Setup!$C$6+1))
B22: 46321 | C22: 0.70833333 | D22: Fushimi Inari at sunset | E22: Fushimi | H22: =IF(OR(B22="",D22=""),"",B22+N(C22)+ROW()/100000000) | I22: =IF(B22="","","Day "&(B22-Setup!$C$6+1))
B23: 46322 | C23: 0.3125 | D23: Bamboo grove before the crowds | E23: Arashiyama | H23: =IF(OR(B23="",D23=""),"",B23+N(C23)+ROW()/100000000) | I23: =IF(B23="","","Day "&(B23-Setup!$C$6+1))
B24: 46322 | C24: 0.54166667 | D24: Golden Pavilion | E24: Kinkaku-ji | H24: =IF(OR(B24="",D24=""),"",B24+N(C24)+ROW()/100000000) | I24: =IF(B24="","","Day "&(B24-Setup!$C$6+1))
B25: 46323 | C25: 0.41666667 | D25: Nishiki market | E25: Central Kyoto | H25: =IF(OR(B25="",D25=""),"",B25+N(C25)+ROW()/100000000) | I25: =IF(B25="","","Day "&(B25-Setup!$C$6+1))
B26: 46323 | C26: 0.58333333 | D26: Tea ceremony | E26: Gion | H26: =IF(OR(B26="",D26=""),"",B26+N(C26)+ROW()/100000000) | I26: =IF(B26="","","Day "&(B26-Setup!$C$6+1))
B27: 46323 | C27: 0.75 | D27: Evening walk in Gion | E27: Gion | H27: =IF(OR(B27="",D27=""),"",B27+N(C27)+ROW()/100000000) | I27: =IF(B27="","","Day "&(B27-Setup!$C$6+1))
B28: 46324 | C28: 0.375 | D28: Day trip to Nara, deer park | E28: Nara | H28: =IF(OR(B28="",D28=""),"",B28+N(C28)+ROW()/100000000) | I28: =IF(B28="","","Day "&(B28-Setup!$C$6+1))
B29: 46324 | C29: 0.79166667 | D29: Kaiseki dinner | E29: Pontocho | F29: KD-14 | H29: =IF(OR(B29="",D29=""),"",B29+N(C29)+ROW()/100000000) | I29: =IF(B29="","","Day "&(B29-Setup!$C$6+1))
B30: 46325 | C30: 0.45833333 | D30: Train to Osaka, check in | E30: Osaka hotel | F30: OS-5570 | H30: =IF(OR(B30="",D30=""),"",B30+N(C30)+ROW()/100000000) | I30: =IF(B30="","","Day "&(B30-Setup!$C$6+1))
B31: 46325 | C31: 0.75 | D31: Street food in Dotonbori | E31: Dotonbori | H31: =IF(OR(B31="",D31=""),"",B31+N(C31)+ROW()/100000000) | I31: =IF(B31="","","Day "&(B31-Setup!$C$6+1))
B32: 46326 | C32: 0.41666667 | D32: Osaka castle | E32: Osaka | H32: =IF(OR(B32="",D32=""),"",B32+N(C32)+ROW()/100000000) | I32: =IF(B32="","","Day "&(B32-Setup!$C$6+1))
B33: 46326 | C33: 0.72222222 | D33: Flight home | E33: Kansai airport | F33: KX7Q2M | H33: =IF(OR(B33="",D33=""),"",B33+N(C33)+ROW()/100000000) | I33: =IF(B33="","","Day "&(B33-Setup!$C$6+1))
H34: =IF(OR(B34="",D34=""),"",B34+N(C34)+ROW()/100000000) | I34: =IF(B34="","","Day "&(B34-Setup!$C$6+1))
H35: =IF(OR(B35="",D35=""),"",B35+N(C35)+ROW()/100000000) | I35: =IF(B35="","","Day "&(B35-Setup!$C$6+1))
H36: =IF(OR(B36="",D36=""),"",B36+N(C36)+ROW()/100000000) | I36: =IF(B36="","","Day "&(B36-Setup!$C$6+1))
H37: =IF(OR(B37="",D37=""),"",B37+N(C37)+ROW()/100000000) | I37: =IF(B37="","","Day "&(B37-Setup!$C$6+1))
H38: =IF(OR(B38="",D38=""),"",B38+N(C38)+ROW()/100000000) | I38: =IF(B38="","","Day "&(B38-Setup!$C$6+1))
H39: =IF(OR(B39="",D39=""),"",B39+N(C39)+ROW()/100000000) | I39: =IF(B39="","","Day "&(B39-Setup!$C$6+1))
H40: =IF(OR(B40="",D40=""),"",B40+N(C40)+ROW()/100000000) | I40: =IF(B40="","","Day "&(B40-Setup!$C$6+1))
H41: =IF(OR(B41="",D41=""),"",B41+N(C41)+ROW()/100000000) | I41: =IF(B41="","","Day "&(B41-Setup!$C$6+1))
H42: =IF(OR(B42="",D42=""),"",B42+N(C42)+ROW()/100000000) | I42: =IF(B42="","","Day "&(B42-Setup!$C$6+1))
...

Sheet Bookings
B2: Bookings
B3: Every flight, hotel, train and ticket, with its confirmation code and what is still to pay.
B5: Type | C5: What | D5: Starts | E5: Time | F5: Ends | G5: Confirmation | H5: Cost | I5: Currency | J5: Paid | K5: In home currency | L5: Still to pay | M5: When | N5: Note
B6: Flight | C6: Los Angeles to Tokyo Haneda | D6: 46315 | E6: 0.46180556 | F6: 46316 | G6: KX7Q2M | H6: 1180 | I6: USD | J6: 1180 | K6: =IF(N(H6)=0,"",IF(N(H6)=0,0,H6*IF(I6="",1,IFERROR(INDEX(Setup!$F$9:$F$18,MATCH(I6,Setup!$E$9:$E$18,0)),0)))) | L6: =IF(N(H6)=0,"",IF(IF(N(H6)=0,0,H6*IF(I6="",1,IFERROR(INDEX(Setup!$F$9:$F$18,MATCH(I6,Setup!$E$9:$E$18,0)),0)))-IF(N(J6)=0,0,J6*IF(I6="",1,IFERROR(INDEX(Setup!$F$9:$F$18,MATCH(I6,Setup!$E$9:$E$18,0)),0)))>0.005,IF(N(H6)=0,0,H6*IF(I6="",1,IFERROR(INDEX(Setup!$F$9:$F$18,MATCH(I6,Setup!$E$9:$E$18,0)),0)))-IF(N(J6)=0,0,J6*IF(I6="",1,IFERROR(INDEX(Setup!$F$9:$F$18,MATCH(I6,Setup!$E$9:$E$18,0)),0))),"")) | M6: =IF(D6="","",IF(D6>TODAY(),"In "&(D6-TODAY())&IF((D6-TODAY())=1," day"," days"),IF(D6=TODAY(),"Today",IF(OR(F6="",F6<TODAY()),"Done","Now")))) | N6: Two seats, 23 kg bags | O6: =IF(B6="","",IFERROR(INDEX(Setup!$I$9:$I$15,MATCH(B6,Setup!$H$9:$H$15,0)),"Other")) | P6: =IF(N(H6)=0,0,IF(N(J6)=0,0,J6*IF(I6="",1,IFERROR(INDEX(Setup!$F$9:$F$18,MATCH(I6,Setup!$E$9:$E$18,0)),0)))) | Q6: =IF(OR(D6="",M6="Done"),"",D6+N(E6)+ROW()/100000000)
B7: Hotel | C7: Shinjuku hotel, 5 nights | D7: 46316 | E7: 0.625 | F7: 46321 | G7: 88213-04 | H7: 145000 | I7: JPY | J7: 0 | K7: =IF(N(H7)=0,"",IF(N(H7)=0,0,H7*IF(I7="",1,IFERROR(INDEX(Setup!$F$9:$F$18,MATCH(I7,Setup!$E$9:$E$18,0)),0)))) | L7: =IF(N(H7)=0,"",IF(IF(N(H7)=0,0,H7*IF(I7="",1,IFERROR(INDEX(Setup!$F$9:$F$18,MATCH(I7,Setup!$E$9:$E$18,0)),0)))-IF(N(J7)=0,0,J7*IF(I7="",1,IFERROR(INDEX(Setup!$F$9:$F$18,MATCH(I7,Setup!$E$9:$E$18,0)),0)))>0.005,IF(N(H7)=0,0,H7*IF(I7="",1,IFERROR(INDEX(Setup!$F$9:$F$18,MATCH(I7,Setup!$E$9:$E$18,0)),0)))-IF(N(J7)=0,0,J7*IF(I7="",1,IFERROR(INDEX(Setup!$F$9:$F$18,MATCH(I7,Setup!$E$9:$E$18,0)),0))),"")) | M7: =IF(D7="","",IF(D7>TODAY(),"In "&(D7-TODAY())&IF((D7-TODAY())=1," day"," days"),IF(D7=TODAY(),"Today",IF(OR(F7="",F7<TODAY()),"Done","Now")))) | N7: Pay at the hotel | O7: =IF(B7="","",IFERROR(INDEX(Setup!$I$9:$I$15,MATCH(B7,Setup!$H$9:$H$15,0)),"Other")) | P7: =IF(N(H7)=0,0,IF(N(J7)=0,0,J7*IF(I7="",1,IFERROR(INDEX(Setup!$F$9:$F$18,MATCH(I7,Setup!$E$9:$E$18,0)),0)))) | Q7: =IF(OR(D7="",M7="Done"),"",D7+N(E7)+ROW()/100000000)
B8: Tour | C8: teamLab Planets | D8: 46317 | E8: 0.625 | F8: 46317 | G8: TLP-5521 | H8: 7600 | I8: JPY | J8: 7600 | K8: =IF(N(H8)=0,"",IF(N(H8)=0,0,H8*IF(I8="",1,IFERROR(INDEX(Setup!$F$9:$F$18,MATCH(I8,Setup!$E$9:$E$18,0)),0)))) | L8: =IF(N(H8)=0,"",IF(IF(N(H8)=0,0,H8*IF(I8="",1,IFERROR(INDEX(Setup!$F$9:$F$18,MATCH(I8,Setup!$E$9:$E$18,0)),0)))-IF(N(J8)=0,0,J8*IF(I8="",1,IFERROR(INDEX(Setup!$F$9:$F$18,MATCH(I8,Setup!$E$9:$E$18,0)),0)))>0.005,IF(N(H8)=0,0,H8*IF(I8="",1,IFERROR(INDEX(Setup!$F$9:$F$18,MATCH(I8,Setup!$E$9:$E$18,0)),0)))-IF(N(J8)=0,0,J8*IF(I8="",1,IFERROR(INDEX(Setup!$F$9:$F$18,MATCH(I8,Setup!$E$9:$E$18,0)),0))),"")) | M8: =IF(D8="","",IF(D8>TODAY(),"In "&(D8-TODAY())&IF((D8-TODAY())=1," day"," days"),IF(D8=TODAY(),"Today",IF(OR(F8="",F8<TODAY()),"Done","Now")))) | O8: =IF(B8="","",IFERROR(INDEX(Setup!$I$9:$I$15,MATCH(B8,Setup!$H$9:$H$15,0)),"Other")) | P8: =IF(N(H8)=0,0,IF(N(J8)=0,0,J8*IF(I8="",1,IFERROR(INDEX(Setup!$F$9:$F$18,MATCH(I8,Setup!$E$9:$E$18,0)),0)))) | Q8: =IF(OR(D8="",M8="Done"),"",D8+N(E8)+ROW()/100000000)
B9: Tour | C9: Sushi cooking class | D9: 46319 | E9: 0.41666667 | F9: 46319 | G9: SC-3310 | H9: 24000 | I9: JPY | J9: 24000 | K9: =IF(N(H9)=0,"",IF(N(H9)=0,0,H9*IF(I9="",1,IFERROR(INDEX(Setup!$F$9:$F$18,MATCH(I9,Setup!$E$9:$E$18,0)),0)))) | L9: =IF(N(H9)=0,"",IF(IF(N(H9)=0,0,H9*IF(I9="",1,IFERROR(INDEX(Setup!$F$9:$F$18,MATCH(I9,Setup!$E$9:$E$18,0)),0)))-IF(N(J9)=0,0,J9*IF(I9="",1,IFERROR(INDEX(Setup!$F$9:$F$18,MATCH(I9,Setup!$E$9:$E$18,0)),0)))>0.005,IF(N(H9)=0,0,H9*IF(I9="",1,IFERROR(INDEX(Setup!$F$9:$F$18,MATCH(I9,Setup!$E$9:$E$18,0)),0)))-IF(N(J9)=0,0,J9*IF(I9="",1,IFERROR(INDEX(Setup!$F$9:$F$18,MATCH(I9,Setup!$E$9:$E$18,0)),0))),"")) | M9: =IF(D9="","",IF(D9>TODAY(),"In "&(D9-TODAY())&IF((D9-TODAY())=1," day"," days"),IF(D9=TODAY(),"Today",IF(OR(F9="",F9<TODAY()),"Done","Now")))) | N9: Meet at Tsukiji station | O9: =IF(B9="","",IFERROR(INDEX(Setup!$I$9:$I$15,MATCH(B9,Setup!$H$9:$H$15,0)),"Other")) | P9: =IF(N(H9)=0,0,IF(N(J9)=0,0,J9*IF(I9="",1,IFERROR(INDEX(Setup!$F$9:$F$18,MATCH(I9,Setup!$E$9:$E$18,0)),0)))) | Q9: =IF(OR(D9="",M9="Done"),"",D9+N(E9)+ROW()/100000000)
B10: Train | C10: Rail pass, 7 days, two people | D10: 46321 | E10: 0.33333333 | F10: 46327 | G10: JRP-77410 | H10: 100000 | I10: JPY | J10: 100000 | K10: =IF(N(H10)=0,"",IF(N(H10)=0,0,H10*IF(I10="",1,IFERROR(INDEX(Setup!$F$9:$F$18,MATCH(I10,Setup!$E$9:$E$18,0)),0)))) | L10: =IF(N(H10)=0,"",IF(IF(N(H10)=0,0,H10*IF(I10="",1,IFERROR(INDEX(Setup!$F$9:$F$18,MATCH(I10,Setup!$E$9:$E$18,0)),0)))-IF(N(J10)=0,0,J10*IF(I10="",1,IFERROR(INDEX(Setup!$F$9:$F$18,MATCH(I10,Setup!$E$9:$E$18,0)),0)))>0.005,IF(N(H10)=0,0,H10*IF(I10="",1,IFERROR(INDEX(Setup!$F$9:$F$18,MATCH(I10,Setup!$E$9:$E$18,0)),0)))-IF(N(J10)=0,0,J10*IF(I10="",1,IFERROR(INDEX(Setup!$F$9:$F$18,MATCH(I10,Setup!$E$9:$E$18,0)),0))),"")) | M10: =IF(D10="","",IF(D10>TODAY(),"In "&(D10-TODAY())&IF((D10-TODAY())=1," day"," days"),IF(D10=TODAY(),"Today",IF(OR(F10="",F10<TODAY()),"Done","Now")))) | N10: Exchange at Tokyo station | O10: =IF(B10="","",IFERROR(INDEX(Setup!$I$9:$I$15,MATCH(B10,Setup!$H$9:$H$15,0)),"Other")) | P10: =IF(N(H10)=0,0,IF(N(J10)=0,0,J10*IF(I10="",1,IFERROR(INDEX(Setup!$F$9:$F$18,MATCH(I10,Setup!$E$9:$E$18,0)),0)))) | Q10: =IF(OR(D10="",M10="Done"),"",D10+N(E10)+ROW()/100000000)
B11: Hotel | C11: Kyoto ryokan, 4 nights | D11: 46321 | E11: 0.625 | F11: 46325 | G11: RK-2291 | H11: 168000 | I11: JPY | J11: 50000 | K11: =IF(N(H11)=0,"",IF(N(H11)=0,0,H11*IF(I11="",1,IFERROR(INDEX(Setup!$F$9:$F$18,MATCH(I11,Setup!$E$9:$E$18,0)),0)))) | L11: =IF(N(H11)=0,"",IF(IF(N(H11)=0,0,H11*IF(I11="",1,IFERROR(INDEX(Setup!$F$9:$F$18,MATCH(I11,Setup!$E$9:$E$18,0)),0)))-IF(N(J11)=0,0,J11*IF(I11="",1,IFERROR(INDEX(Setup!$F$9:$F$18,MATCH(I11,Setup!$E$9:$E$18,0)),0)))>0.005,IF(N(H11)=0,0,H11*IF(I11="",1,IFERROR(INDEX(Setup!$F$9:$F$18,MATCH(I11,Setup!$E$9:$E$18,0)),0)))-IF(N(J11)=0,0,J11*IF(I11="",1,IFERROR(INDEX(Setup!$F$9:$F$18,MATCH(I11,Setup!$E$9:$E$18,0)),0))),"")) | M11: =IF(D11="","",IF(D11>TODAY(),"In "&(D11-TODAY())&IF((D11-TODAY())=1," day"," days"),IF(D11=TODAY(),"Today",IF(OR(F11="",F11<TODAY()),"Done","Now")))) | N11: Dinner included twice | O11: =IF(B11="","",IFERROR(INDEX(Setup!$I$9:$I$15,MATCH(B11,Setup!$H$9:$H$15,0)),"Other")) | P11: =IF(N(H11)=0,0,IF(N(J11)=0,0,J11*IF(I11="",1,IFERROR(INDEX(Setup!$F$9:$F$18,MATCH(I11,Setup!$E$9:$E$18,0)),0)))) | Q11: =IF(OR(D11="",M11="Done"),"",D11+N(E11)+ROW()/100000000)
B12: Tour | C12: Tea ceremony in Kyoto | D12: 46323 | E12: 0.58333333 | F12: 46323 | H12: 8000 | I12: JPY | J12: 0 | K12: =IF(N(H12)=0,"",IF(N(H12)=0,0,H12*IF(I12="",1,IFERROR(INDEX(Setup!$F$9:$F$18,MATCH(I12,Setup!$E$9:$E$18,0)),0)))) | L12: =IF(N(H12)=0,"",IF(IF(N(H12)=0,0,H12*IF(I12="",1,IFERROR(INDEX(Setup!$F$9:$F$18,MATCH(I12,Setup!$E$9:$E$18,0)),0)))-IF(N(J12)=0,0,J12*IF(I12="",1,IFERROR(INDEX(Setup!$F$9:$F$18,MATCH(I12,Setup!$E$9:$E$18,0)),0)))>0.005,IF(N(H12)=0,0,H12*IF(I12="",1,IFERROR(INDEX(Setup!$F$9:$F$18,MATCH(I12,Setup!$E$9:$E$18,0)),0)))-IF(N(J12)=0,0,J12*IF(I12="",1,IFERROR(INDEX(Setup!$F$9:$F$18,MATCH(I12,Setup!$E$9:$E$18,0)),0))),"")) | M12: =IF(D12="","",IF(D12>TODAY(),"In "&(D12-TODAY())&IF((D12-TODAY())=1," day"," days"),IF(D12=TODAY(),"Today",IF(OR(F12="",F12<TODAY()),"Done","Now")))) | N12: Pay on the day | O12: =IF(B12="","",IFERROR(INDEX(Setup!$I$9:$I$15,MATCH(B12,Setup!$H$9:$H$15,0)),"Other")) | P12: =IF(N(H12)=0,0,IF(N(J12)=0,0,J12*IF(I12="",1,IFERROR(INDEX(Setup!$F$9:$F$18,MATCH(I12,Setup!$E$9:$E$18,0)),0)))) | Q12: =IF(OR(D12="",M12="Done"),"",D12+N(E12)+ROW()/100000000)
B13: Restaurant | C13: Kaiseki dinner | D13: 46324 | E13: 0.79166667 | F13: 46324 | G13: KD-14 | H13: 36000 | I13: JPY | J13: 0 | K13: =IF(N(H13)=0,"",IF(N(H13)=0,0,H13*IF(I13="",1,IFERROR(INDEX(Setup!$F$9:$F$18,MATCH(I13,Setup!$E$9:$E$18,0)),0)))) | L13: =IF(N(H13)=0,"",IF(IF(N(H13)=0,0,H13*IF(I13="",1,IFERROR(INDEX(Setup!$F$9:$F$18,MATCH(I13,Setup!$E$9:$E$18,0)),0)))-IF(N(J13)=0,0,J13*IF(I13="",1,IFERROR(INDEX(Setup!$F$9:$F$18,MATCH(I13,Setup!$E$9:$E$18,0)),0)))>0.005,IF(N(H13)=0,0,H13*IF(I13="",1,IFERROR(INDEX(Setup!$F$9:$F$18,MATCH(I13,Setup!$E$9:$E$18,0)),0)))-IF(N(J13)=0,0,J13*IF(I13="",1,IFERROR(INDEX(Setup!$F$9:$F$18,MATCH(I13,Setup!$E$9:$E$18,0)),0))),"")) | M13: =IF(D13="","",IF(D13>TODAY(),"In "&(D13-TODAY())&IF((D13-TODAY())=1," day"," days"),IF(D13=TODAY(),"Today",IF(OR(F13="",F13<TODAY()),"Done","Now")))) | O13: =IF(B13="","",IFERROR(INDEX(Setup!$I$9:$I$15,MATCH(B13,Setup!$H$9:$H$15,0)),"Other")) | P13: =IF(N(H13)=0,0,IF(N(J13)=0,0,J13*IF(I13="",1,IFERROR(INDEX(Setup!$F$9:$F$18,MATCH(I13,Setup!$E$9:$E$18,0)),0)))) | Q13: =IF(OR(D13="",M13="Done"),"",D13+N(E13)+ROW()/100000000)
B14: Hotel | C14: Osaka hotel, 1 night | D14: 46325 | E14: 0.625 | F14: 46326 | G14: OS-5570 | H14: 22000 | I14: JPY | J14: 22000 | K14: =IF(N(H14)=0,"",IF(N(H14)=0,0,H14*IF(I14="",1,IFERROR(INDEX(Setup!$F$9:$F$18,MATCH(I14,Setup!$E$9:$E$18,0)),0)))) | L14: =IF(N(H14)=0,"",IF(IF(N(H14)=0,0,H14*IF(I14="",1,IFERROR(INDEX(Setup!$F$9:$F$18,MATCH(I14,Setup!$E$9:$E$18,0)),0)))-IF(N(J14)=0,0,J14*IF(I14="",1,IFERROR(INDEX(Setup!$F$9:$F$18,MATCH(I14,Setup!$E$9:$E$18,0)),0)))>0.005,IF(N(H14)=0,0,H14*IF(I14="",1,IFERROR(INDEX(Setup!$F$9:$F$18,MATCH(I14,Setup!$E$9:$E$18,0)),0)))-IF(N(J14)=0,0,J14*IF(I14="",1,IFERROR(INDEX(Setup!$F$9:$F$18,MATCH(I14,Setup!$E$9:$E$18,0)),0))),"")) | M14: =IF(D14="","",IF(D14>TODAY(),"In "&(D14-TODAY())&IF((D14-TODAY())=1," day"," days"),IF(D14=TODAY(),"Today",IF(OR(F14="",F14<TODAY()),"Done","Now")))) | O14: =IF(B14="","",IFERROR(INDEX(Setup!$I$9:$I$15,MATCH(B14,Setup!$H$9:$H$15,0)),"Other")) | P14: =IF(N(H14)=0,0,IF(N(J14)=0,0,J14*IF(I14="",1,IFERROR(INDEX(Setup!$F$9:$F$18,MATCH(I14,Setup!$E$9:$E$18,0)),0)))) | Q14: =IF(OR(D14="",M14="Done"),"",D14+N(E14)+ROW()/100000000)
B15: Flight | C15: Osaka Kansai to Los Angeles | D15: 46326 | E15: 0.72222222 | F15: 46326 | G15: KX7Q2M | H15: 1180 | I15: USD | J15: 1180 | K15: =IF(N(H15)=0,"",IF(N(H15)=0,0,H15*IF(I15="",1,IFERROR(INDEX(Setup!$F$9:$F$18,MATCH(I15,Setup!$E$9:$E$18,0)),0)))) | L15: =IF(N(H15)=0,"",IF(IF(N(H15)=0,0,H15*IF(I15="",1,IFERROR(INDEX(Setup!$F$9:$F$18,MATCH(I15,Setup!$E$9:$E$18,0)),0)))-IF(N(J15)=0,0,J15*IF(I15="",1,IFERROR(INDEX(Setup!$F$9:$F$18,MATCH(I15,Setup!$E$9:$E$18,0)),0)))>0.005,IF(N(H15)=0,0,H15*IF(I15="",1,IFERROR(INDEX(Setup!$F$9:$F$18,MATCH(I15,Setup!$E$9:$E$18,0)),0)))-IF(N(J15)=0,0,J15*IF(I15="",1,IFERROR(INDEX(Setup!$F$9:$F$18,MATCH(I15,Setup!$E$9:$E$18,0)),0))),"")) | M15: =IF(D15="","",IF(D15>TODAY(),"In "&(D15-TODAY())&IF((D15-TODAY())=1," day"," days"),IF(D15=TODAY(),"Today",IF(OR(F15="",F15<TODAY()),"Done","Now")))) | O15: =IF(B15="","",IFERROR(INDEX(Setup!$I$9:$I$15,MATCH(B15,Setup!$H$9:$H$15,0)),"Other")) | P15: =IF(N(H15)=0,0,IF(N(J15)=0,0,J15*IF(I15="",1,IFERROR(INDEX(Setup!$F$9:$F$18,MATCH(I15,Setup!$E$9:$E$18,0)),0)))) | Q15: =IF(OR(D15="",M15="Done"),"",D15+N(E15)+ROW()/100000000)
K16: =IF(N(H16)=0,"",IF(N(H16)=0,0,H16*IF(I16="",1,IFERROR(INDEX(Setup!$F$9:$F$18,MATCH(I16,Setup!$E$9:$E$18,0)),0)))) | L16: =IF(N(H16)=0,"",IF(IF(N(H16)=0,0,H16*IF(I16="",1,IFERROR(INDEX(Setup!$F$9:$F$18,MATCH(I16,Setup!$E$9:$E$18,0)),0)))-IF(N(J16)=0,0,J16*IF(I16="",1,IFERROR(INDEX(Setup!$F$9:$F$18,MATCH(I16,Setup!$E$9:$E$18,0)),0)))>0.005,IF(N(H16)=0,0,H16*IF(I16="",1,IFERROR(INDEX(Setup!$F$9:$F$18,MATCH(I16,Setup!$E$9:$E$18,0)),0)))-IF(N(J16)=0,0,J16*IF(I16="",1,IFERROR(INDEX(Setup!$F$9:$F$18,MATCH(I16,Setup!$E$9:$E$18,0)),0))),"")) | M16: =IF(D16="","",IF(D16>TODAY(),"In "&(D16-TODAY())&IF((D16-TODAY())=1," day"," days"),IF(D16=TODAY(),"Today",IF(OR(F16="",F16<TODAY()),"Done","Now")))) | O16: =IF(B16="","",IFERROR(INDEX(Setup!$I$9:$I$15,MATCH(B16,Setup!$H$9:$H$15,0)),"Other")) | P16: =IF(N(H16)=0,0,IF(N(J16)=0,0,J16*IF(I16="",1,IFERROR(INDEX(Setup!$F$9:$F$18,MATCH(I16,Setup!$E$9:$E$18,0)),0)))) | Q16: =IF(OR(D16="",M16="Done"),"",D16+N(E16)+ROW()/100000000)
K17: =IF(N(H17)=0,"",IF(N(H17)=0,0,H17*IF(I17="",1,IFERROR(INDEX(Setup!$F$9:$F$18,MATCH(I17,Setup!$E$9:$E$18,0)),0)))) | L17: =IF(N(H17)=0,"",IF(IF(N(H17)=0,0,H17*IF(I17="",1,IFERROR(INDEX(Setup!$F$9:$F$18,MATCH(I17,Setup!$E$9:$E$18,0)),0)))-IF(N(J17)=0,0,J17*IF(I17="",1,IFERROR(INDEX(Setup!$F$9:$F$18,MATCH(I17,Setup!$E$9:$E$18,0)),0)))>0.005,IF(N(H17)=0,0,H17*IF(I17="",1,IFERROR(INDEX(Setup!$F$9:$F$18,MATCH(I17,Setup!$E$9:$E$18,0)),0)))-IF(N(J17)=0,0,J17*IF(I17="",1,IFERROR(INDEX(Setup!$F$9:$F$18,MATCH(I17,Setup!$E$9:$E$18,0)),0))),"")) | M17: =IF(D17="","",IF(D17>TODAY(),"In "&(D17-TODAY())&IF((D17-TODAY())=1," day"," days"),IF(D17=TODAY(),"Today",IF(OR(F17="",F17<TODAY()),"Done","Now")))) | O17: =IF(B17="","",IFERROR(INDEX(Setup!$I$9:$I$15,MATCH(B17,Setup!$H$9:$H$15,0)),"Other")) | P17: =IF(N(H17)=0,0,IF(N(J17)=0,0,J17*IF(I17="",1,IFERROR(INDEX(Setup!$F$9:$F$18,MATCH(I17,Setup!$E$9:$E$18,0)),0)))) | Q17: =IF(OR(D17="",M17="Done"),"",D17+N(E17)+ROW()/100000000)
K18: =IF(N(H18)=0,"",IF(N(H18)=0,0,H18*IF(I18="",1,IFERROR(INDEX(Setup!$F$9:$F$18,MATCH(I18,Setup!$E$9:$E$18,0)),0)))) | L18: =IF(N(H18)=0,"",IF(IF(N(H18)=0,0,H18*IF(I18="",1,IFERROR(INDEX(Setup!$F$9:$F$18,MATCH(I18,Setup!$E$9:$E$18,0)),0)))-IF(N(J18)=0,0,J18*IF(I18="",1,IFERROR(INDEX(Setup!$F$9:$F$18,MATCH(I18,Setup!$E$9:$E$18,0)),0)))>0.005,IF(N(H18)=0,0,H18*IF(I18="",1,IFERROR(INDEX(Setup!$F$9:$F$18,MATCH(I18,Setup!$E$9:$E$18,0)),0)))-IF(N(J18)=0,0,J18*IF(I18="",1,IFERROR(INDEX(Setup!$F$9:$F$18,MATCH(I18,Setup!$E$9:$E$18,0)),0))),"")) | M18: =IF(D18="","",IF(D18>TODAY(),"In "&(D18-TODAY())&IF((D18-TODAY())=1," day"," days"),IF(D18=TODAY(),"Today",IF(OR(F18="",F18<TODAY()),"Done","Now")))) | O18: =IF(B18="","",IFERROR(INDEX(Setup!$I$9:$I$15,MATCH(B18,Setup!$H$9:$H$15,0)),"Other")) | P18: =IF(N(H18)=0,0,IF(N(J18)=0,0,J18*IF(I18="",1,IFERROR(INDEX(Setup!$F$9:$F$18,MATCH(I18,Setup!$E$9:$E$18,0)),0)))) | Q18: =IF(OR(D18="",M18="Done"),"",D18+N(E18)+ROW()/100000000)
K19: =IF(N(H19)=0,"",IF(N(H19)=0,0,H19*IF(I19="",1,IFERROR(INDEX(Setup!$F$9:$F$18,MATCH(I19,Setup!$E$9:$E$18,0)),0)))) | L19: =IF(N(H19)=0,"",IF(IF(N(H19)=0,0,H19*IF(I19="",1,IFERROR(INDEX(Setup!$F$9:$F$18,MATCH(I19,Setup!$E$9:$E$18,0)),0)))-IF(N(J19)=0,0,J19*IF(I19="",1,IFERROR(INDEX(Setup!$F$9:$F$18,MATCH(I19,Setup!$E$9:$E$18,0)),0)))>0.005,IF(N(H19)=0,0,H19*IF(I19="",1,IFERROR(INDEX(Setup!$F$9:$F$18,MATCH(I19,Setup!$E$9:$E$18,0)),0)))-IF(N(J19)=0,0,J19*IF(I19="",1,IFERROR(INDEX(Setup!$F$9:$F$18,MATCH(I19,Setup!$E$9:$E$18,0)),0))),"")) | M19: =IF(D19="","",IF(D19>TODAY(),"In "&(D19-TODAY())&IF((D19-TODAY())=1," day"," days"),IF(D19=TODAY(),"Today",IF(OR(F19="",F19<TODAY()),"Done","Now")))) | O19: =IF(B19="","",IFERROR(INDEX(Setup!$I$9:$I$15,MATCH(B19,Setup!$H$9:$H$15,0)),"Other")) | P19: =IF(N(H19)=0,0,IF(N(J19)=0,0,J19*IF(I19="",1,IFERROR(INDEX(Setup!$F$9:$F$18,MATCH(I19,Setup!$E$9:$E$18,0)),0)))) | Q19: =IF(OR(D19="",M19="Done"),"",D19+N(E19)+ROW()/100000000)
K20: =IF(N(H20)=0,"",IF(N(H20)=0,0,H20*IF(I20="",1,IFERROR(INDEX(Setup!$F$9:$F$18,MATCH(I20,Setup!$E$9:$E$18,0)),0)))) | L20: =IF(N(H20)=0,"",IF(IF(N(H20)=0,0,H20*IF(I20="",1,IFERROR(INDEX(Setup!$F$9:$F$18,MATCH(I20,Setup!$E$9:$E$18,0)),0)))-IF(N(J20)=0,0,J20*IF(I20="",1,IFERROR(INDEX(Setup!$F$9:$F$18,MATCH(I20,Setup!$E$9:$E$18,0)),0)))>0.005,IF(N(H20)=0,0,H20*IF(I20="",1,IFERROR(INDEX(Setup!$F$9:$F$18,MATCH(I20,Setup!$E$9:$E$18,0)),0)))-IF(N(J20)=0,0,J20*IF(I20="",1,IFERROR(INDEX(Setup!$F$9:$F$18,MATCH(I20,Setup!$E$9:$E$18,0)),0))),"")) | M20: =IF(D20="","",IF(D20>TODAY(),"In "&(D20-TODAY())&IF((D20-TODAY())=1," day"," days"),IF(D20=TODAY(),"Today",IF(OR(F20="",F20<TODAY()),"Done","Now")))) | O20: =IF(B20="","",IFERROR(INDEX(Setup!$I$9:$I$15,MATCH(B20,Setup!$H$9:$H$15,0)),"Other")) | P20: =IF(N(H20)=0,0,IF(N(J20)=0,0,J20*IF(I20="",1,IFERROR(INDEX(Setup!$F$9:$F$18,MATCH(I20,Setup!$E$9:$E$18,0)),0)))) | Q20: =IF(OR(D20="",M20="Done"),"",D20+N(E20)+ROW()/100000000)
K21: =IF(N(H21)=0,"",IF(N(H21)=0,0,H21*IF(I21="",1,IFERROR(INDEX(Setup!$F$9:$F$18,MATCH(I21,Setup!$E$9:$E$18,0)),0)))) | L21: =IF(N(H21)=0,"",IF(IF(N(H21)=0,0,H21*IF(I21="",1,IFERROR(INDEX(Setup!$F$9:$F$18,MATCH(I21,Setup!$E$9:$E$18,0)),0)))-IF(N(J21)=0,0,J21*IF(I21="",1,IFERROR(INDEX(Setup!$F$9:$F$18,MATCH(I21,Setup!$E$9:$E$18,0)),0)))>0.005,IF(N(H21)=0,0,H21*IF(I21="",1,IFERROR(INDEX(Setup!$F$9:$F$18,MATCH(I21,Setup!$E$9:$E$18,0)),0)))-IF(N(J21)=0,0,J21*IF(I21="",1,IFERROR(INDEX(Setup!$F$9:$F$18,MATCH(I21,Setup!$E$9:$E$18,0)),0))),"")) | M21: =IF(D21="","",IF(D21>TODAY(),"In "&(D21-TODAY())&IF((D21-TODAY())=1," day"," days"),IF(D21=TODAY(),"Today",IF(OR(F21="",F21<TODAY()),"Done","Now")))) | O21: =IF(B21="","",IFERROR(INDEX(Setup!$I$9:$I$15,MATCH(B21,Setup!$H$9:$H$15,0)),"Other")) | P21: =IF(N(H21)=0,0,IF(N(J21)=0,0,J21*IF(I21="",1,IFERROR(INDEX(Setup!$F$9:$F$18,MATCH(I21,Setup!$E$9:$E$18,0)),0)))) | Q21: =IF(OR(D21="",M21="Done"),"",D21+N(E21)+ROW()/100000000)
K22: =IF(N(H22)=0,"",IF(N(H22)=0,0,H22*IF(I22="",1,IFERROR(INDEX(Setup!$F$9:$F$18,MATCH(I22,Setup!$E$9:$E$18,0)),0)))) | L22: =IF(N(H22)=0,"",IF(IF(N(H22)=0,0,H22*IF(I22="",1,IFERROR(INDEX(Setup!$F$9:$F$18,MATCH(I22,Setup!$E$9:$E$18,0)),0)))-IF(N(J22)=0,0,J22*IF(I22="",1,IFERROR(INDEX(Setup!$F$9:$F$18,MATCH(I22,Setup!$E$9:$E$18,0)),0)))>0.005,IF(N(H22)=0,0,H22*IF(I22="",1,IFERROR(INDEX(Setup!$F$9:$F$18,MATCH(I22,Setup!$E$9:$E$18,0)),0)))-IF(N(J22)=0,0,J22*IF(I22="",1,IFERROR(INDEX(Setup!$F$9:$F$18,MATCH(I22,Setup!$E$9:$E$18,0)),0))),"")) | M22: =IF(D22="","",IF(D22>TODAY(),"In "&(D22-TODAY())&IF((D22-TODAY())=1," day"," days"),IF(D22=TODAY(),"Today",IF(OR(F22="",F22<TODAY()),"Done","Now")))) | O22: =IF(B22="","",IFERROR(INDEX(Setup!$I$9:$I$15,MATCH(B22,Setup!$H$9:$H$15,0)),"Other")) | P22: =IF(N(H22)=0,0,IF(N(J22)=0,0,J22*IF(I22="",1,IFERROR(INDEX(Setup!$F$9:$F$18,MATCH(I22,Setup!$E$9:$E$18,0)),0)))) | Q22: =IF(OR(D22="",M22="Done"),"",D22+N(E22)+ROW()/100000000)
K23: =IF(N(H23)=0,"",IF(N(H23)=0,0,H23*IF(I23="",1,IFERROR(INDEX(Setup!$F$9:$F$18,MATCH(I23,Setup!$E$9:$E$18,0)),0)))) | L23: =IF(N(H23)=0,"",IF(IF(N(H23)=0,0,H23*IF(I23="",1,IFERROR(INDEX(Setup!$F$9:$F$18,MATCH(I23,Setup!$E$9:$E$18,0)),0)))-IF(N(J23)=0,0,J23*IF(I23="",1,IFERROR(INDEX(Setup!$F$9:$F$18,MATCH(I23,Setup!$E$9:$E$18,0)),0)))>0.005,IF(N(H23)=0,0,H23*IF(I23="",1,IFERROR(INDEX(Setup!$F$9:$F$18,MATCH(I23,Setup!$E$9:$E$18,0)),0)))-IF(N(J23)=0,0,J23*IF(I23="",1,IFERROR(INDEX(Setup!$F$9:$F$18,MATCH(I23,Setup!$E$9:$E$18,0)),0))),"")) | M23: =IF(D23="","",IF(D23>TODAY(),"In "&(D23-TODAY())&IF((D23-TODAY())=1," day"," days"),IF(D23=TODAY(),"Today",IF(OR(F23="",F23<TODAY()),"Done","Now")))) | O23: =IF(B23="","",IFERROR(INDEX(Setup!$I$9:$I$15,MATCH(B23,Setup!$H$9:$H$15,0)),"Other")) | P23: =IF(N(H23)=0,0,IF(N(J23)=0,0,J23*IF(I23="",1,IFERROR(INDEX(Setup!$F$9:$F$18,MATCH(I23,Setup!$E$9:$E$18,0)),0)))) | Q23: =IF(OR(D23="",M23="Done"),"",D23+N(E23)+ROW()/100000000)
K24: =IF(N(H24)=0,"",IF(N(H24)=0,0,H24*IF(I24="",1,IFERROR(INDEX(Setup!$F$9:$F$18,MATCH(I24,Setup!$E$9:$E$18,0)),0)))) | L24: =IF(N(H24)=0,"",IF(IF(N(H24)=0,0,H24*IF(I24="",1,IFERROR(INDEX(Setup!$F$9:$F$18,MATCH(I24,Setup!$E$9:$E$18,0)),0)))-IF(N(J24)=0,0,J24*IF(I24="",1,IFERROR(INDEX(Setup!$F$9:$F$18,MATCH(I24,Setup!$E$9:$E$18,0)),0)))>0.005,IF(N(H24)=0,0,H24*IF(I24="",1,IFERROR(INDEX(Setup!$F$9:$F$18,MATCH(I24,Setup!$E$9:$E$18,0)),0)))-IF(N(J24)=0,0,J24*IF(I24="",1,IFERROR(INDEX(Setup!$F$9:$F$18,MATCH(I24,Setup!$E$9:$E$18,0)),0))),"")) | M24: =IF(D24="","",IF(D24>TODAY(),"In "&(D24-TODAY())&IF((D24-TODAY())=1," day"," days"),IF(D24=TODAY(),"Today",IF(OR(F24="",F24<TODAY()),"Done","Now")))) | O24: =IF(B24="","",IFERROR(INDEX(Setup!$I$9:$I$15,MATCH(B24,Setup!$H$9:$H$15,0)),"Other")) | P24: =IF(N(H24)=0,0,IF(N(J24)=0,0,J24*IF(I24="",1,IFERROR(INDEX(Setup!$F$9:$F$18,MATCH(I24,Setup!$E$9:$E$18,0)),0)))) | Q24: =IF(OR(D24="",M24="Done"),"",D24+N(E24)+ROW()/100000000)
K25: =IF(N(H25)=0,"",IF(N(H25)=0,0,H25*IF(I25="",1,IFERROR(INDEX(Setup!$F$9:$F$18,MATCH(I25,Setup!$E$9:$E$18,0)),0)))) | L25: =IF(N(H25)=0,"",IF(IF(N(H25)=0,0,H25*IF(I25="",1,IFERROR(INDEX(Setup!$F$9:$F$18,MATCH(I25,Setup!$E$9:$E$18,0)),0)))-IF(N(J25)=0,0,J25*IF(I25="",1,IFERROR(INDEX(Setup!$F$9:$F$18,MATCH(I25,Setup!$E$9:$E$18,0)),0)))>0.005,IF(N(H25)=0,0,H25*IF(I25="",1,IFERROR(INDEX(Setup!$F$9:$F$18,MATCH(I25,Setup!$E$9:$E$18,0)),0)))-IF(N(J25)=0,0,J25*IF(I25="",1,IFERROR(INDEX(Setup!$F$9:$F$18,MATCH(I25,Setup!$E$9:$E$18,0)),0))),"")) | M25: =IF(D25="","",IF(D25>TODAY(),"In "&(D25-TODAY())&IF((D25-TODAY())=1," day"," days"),IF(D25=TODAY(),"Today",IF(OR(F25="",F25<TODAY()),"Done","Now")))) | O25: =IF(B25="","",IFERROR(INDEX(Setup!$I$9:$I$15,MATCH(B25,Setup!$H$9:$H$15,0)),"Other")) | P25: =IF(N(H25)=0,0,IF(N(J25)=0,0,J25*IF(I25="",1,IFERROR(INDEX(Setup!$F$9:$F$18,MATCH(I25,Setup!$E$9:$E$18,0)),0)))) | Q25: =IF(OR(D25="",M25="Done"),"",D25+N(E25)+ROW()/100000000)
K26: =IF(N(H26)=0,"",IF(N(H26)=0,0,H26*IF(I26="",1,IFERROR(INDEX(Setup!$F$9:$F$18,MATCH(I26,Setup!$E$9:$E$18,0)),0)))) | L26: =IF(N(H26)=0,"",IF(IF(N(H26)=0,0,H26*IF(I26="",1,IFERROR(INDEX(Setup!$F$9:$F$18,MATCH(I26,Setup!$E$9:$E$18,0)),0)))-IF(N(J26)=0,0,J26*IF(I26="",1,IFERROR(INDEX(Setup!$F$9:$F$18,MATCH(I26,Setup!$E$9:$E$18,0)),0)))>0.005,IF(N(H26)=0,0,H26*IF(I26="",1,IFERROR(INDEX(Setup!$F$9:$F$18,MATCH(I26,Setup!$E$9:$E$18,0)),0)))-IF(N(J26)=0,0,J26*IF(I26="",1,IFERROR(INDEX(Setup!$F$9:$F$18,MATCH(I26,Setup!$E$9:$E$18,0)),0))),"")) | M26: =IF(D26="","",IF(D26>TODAY(),"In "&(D26-TODAY())&IF((D26-TODAY())=1," day"," days"),IF(D26=TODAY(),"Today",IF(OR(F26="",F26<TODAY()),"Done","Now")))) | O26: =IF(B26="","",IFERROR(INDEX(Setup!$I$9:$I$15,MATCH(B26,Setup!$H$9:$H$15,0)),"Other")) | P26: =IF(N(H26)=0,0,IF(N(J26)=0,0,J26*IF(I26="",1,IFERROR(INDEX(Setup!$F$9:$F$18,MATCH(I26,Setup!$E$9:$E$18,0)),0)))) | Q26: =IF(OR(D26="",M26="Done"),"",D26+N(E26)+ROW()/100000000)
K27: =IF(N(H27)=0,"",IF(N(H27)=0,0,H27*IF(I27="",1,IFERROR(INDEX(Setup!$F$9:$F$18,MATCH(I27,Setup!$E$9:$E$18,0)),0)))) | L27: =IF(N(H27)=0,"",IF(IF(N(H27)=0,0,H27*IF(I27="",1,IFERROR(INDEX(Setup!$F$9:$F$18,MATCH(I27,Setup!$E$9:$E$18,0)),0)))-IF(N(J27)=0,0,J27*IF(I27="",1,IFERROR(INDEX(Setup!$F$9:$F$18,MATCH(I27,Setup!$E$9:$E$18,0)),0)))>0.005,IF(N(H27)=0,0,H27*IF(I27="",1,IFERROR(INDEX(Setup!$F$9:$F$18,MATCH(I27,Setup!$E$9:$E$18,0)),0)))-IF(N(J27)=0,0,J27*IF(I27="",1,IFERROR(INDEX(Setup!$F$9:$F$18,MATCH(I27,Setup!$E$9:$E$18,0)),0))),"")) | M27: =IF(D27="","",IF(D27>TODAY(),"In "&(D27-TODAY())&IF((D27-TODAY())=1," day"," days"),IF(D27=TODAY(),"Today",IF(OR(F27="",F27<TODAY()),"Done","Now")))) | O27: =IF(B27="","",IFERROR(INDEX(Setup!$I$9:$I$15,MATCH(B27,Setup!$H$9:$H$15,0)),"Other")) | P27: =IF(N(H27)=0,0,IF(N(J27)=0,0,J27*IF(I27="",1,IFERROR(INDEX(Setup!$F$9:$F$18,MATCH(I27,Setup!$E$9:$E$18,0)),0)))) | Q27: =IF(OR(D27="",M27="Done"),"",D27+N(E27)+ROW()/100000000)
... K105: =IF(N(H105)=0,"",IF(N(H105)=0,0,H105*IF(I105="",1,IFERROR(INDEX(Setup!$F$9:$F$18,MATCH(I105,Setup!$E$9:$E$18,0)),0)))) | L105: =IF(N(H105)=0,"",IF(IF(N(H105)=0,0,H105*IF(I105="",1,IFERROR(INDEX(Setup!$F$9:$F$18,MATCH(I105,Setup!$E$9:$E$18,0)),0)))-IF(N(J105)=0,0,J105*IF(I105="",1,IFERROR(INDEX(Setup!$F$9:$F$18,MATCH(I105,Setup!$E$9:$E$18,0)),0)))>0.005,IF(N(H105)=0,0,H105*IF(I105="",1,IFERROR(INDEX(Setup!$F$9:$F$18,MATCH(I105,Setup!$E$9:$E$18,0)),0)))-IF(N(J105)=0,0,J105*IF(I105="",1,IFERROR(INDEX(Setup!$F$9:$F$18,MATCH(I105,Setup!$E$9:$E$18,0)),0))),"")) | M105: =IF(D105="","",IF(D105>TODAY(),"In "&(D105-TODAY())&IF((D105-TODAY())=1," day"," days"),IF(D105=TODAY(),"Today",IF(OR(F105="",F105<TODAY()),"Done","Now")))) | O105: =IF(B105="","",IFERROR(INDEX(Setup!$I$9:$I$15,MATCH(B105,Setup!$H$9:$H$15,0)),"Other")) | P105: =IF(N(H105)=0,0,IF(N(J105)=0,0,J105*IF(I105="",1,IFERROR(INDEX(Setup!$F$9:$F$18,MATCH(I105,Setup!$E$9:$E$18,0)),0)))) | Q105: =IF(OR(D105="",M105="Done"),"",D105+N(E105)+ROW()/100000000)

Sheet Expenses
B2: Expenses
B3: Everything you pay that is not a booking: food, tickets, souvenirs, taxis.
B5: Date | C5: What | D5: Category | E5: Amount | F5: Currency | G5: In home currency
B6: 46263 | C6: Travel insurance, two people | D6: Other | E6: 180 | F6: USD | G6: =IF(N(E6)=0,"",IF(N(E6)=0,0,E6*IF(F6="",1,IFERROR(INDEX(Setup!$F$9:$F$18,MATCH(F6,Setup!$E$9:$E$18,0)),0))))
B7: 46272 | C7: Guidebook | D7: Other | E7: 25 | F7: USD | G7: =IF(N(E7)=0,"",IF(N(E7)=0,0,E7*IF(F7="",1,IFERROR(INDEX(Setup!$F$9:$F$18,MATCH(F7,Setup!$E$9:$E$18,0)),0))))
B8: 46281 | C8: Pocket wifi rental | D8: Other | E8: 6000 | F8: JPY | G8: =IF(N(E8)=0,"",IF(N(E8)=0,0,E8*IF(F8="",1,IFERROR(INDEX(Setup!$F$9:$F$18,MATCH(F8,Setup!$E$9:$E$18,0)),0))))
B9: 46288 | C9: Cabin suitcase | D9: Shopping | E9: 95 | F9: USD | G9: =IF(N(E9)=0,"",IF(N(E9)=0,0,E9*IF(F9="",1,IFERROR(INDEX(Setup!$F$9:$F$18,MATCH(F9,Setup!$E$9:$E$18,0)),0))))
G10: =IF(N(E10)=0,"",IF(N(E10)=0,0,E10*IF(F10="",1,IFERROR(INDEX(Setup!$F$9:$F$18,MATCH(F10,Setup!$E$9:$E$18,0)),0))))
G11: =IF(N(E11)=0,"",IF(N(E11)=0,0,E11*IF(F11="",1,IFERROR(INDEX(Setup!$F$9:$F$18,MATCH(F11,Setup!$E$9:$E$18,0)),0))))
G12: =IF(N(E12)=0,"",IF(N(E12)=0,0,E12*IF(F12="",1,IFERROR(INDEX(Setup!$F$9:$F$18,MATCH(F12,Setup!$E$9:$E$18,0)),0))))
G13: =IF(N(E13)=0,"",IF(N(E13)=0,0,E13*IF(F13="",1,IFERROR(INDEX(Setup!$F$9:$F$18,MATCH(F13,Setup!$E$9:$E$18,0)),0))))
G14: =IF(N(E14)=0,"",IF(N(E14)=0,0,E14*IF(F14="",1,IFERROR(INDEX(Setup!$F$9:$F$18,MATCH(F14,Setup!$E$9:$E$18,0)),0))))
G15: =IF(N(E15)=0,"",IF(N(E15)=0,0,E15*IF(F15="",1,IFERROR(INDEX(Setup!$F$9:$F$18,MATCH(F15,Setup!$E$9:$E$18,0)),0))))
G16: =IF(N(E16)=0,"",IF(N(E16)=0,0,E16*IF(F16="",1,IFERROR(INDEX(Setup!$F$9:$F$18,MATCH(F16,Setup!$E$9:$E$18,0)),0))))
G17: =IF(N(E17)=0,"",IF(N(E17)=0,0,E17*IF(F17="",1,IFERROR(INDEX(Setup!$F$9:$F$18,MATCH(F17,Setup!$E$9:$E$18,0)),0))))
G18: =IF(N(E18)=0,"",IF(N(E18)=0,0,E18*IF(F18="",1,IFERROR(INDEX(Setup!$F$9:$F$18,MATCH(F18,Setup!$E$9:$E$18,0)),0))))
G19: =IF(N(E19)=0,"",IF(N(E19)=0,0,E19*IF(F19="",1,IFERROR(INDEX(Setup!$F$9:$F$18,MATCH(F19,Setup!$E$9:$E$18,0)),0))))
G20: =IF(N(E20)=0,"",IF(N(E20)=0,0,E20*IF(F20="",1,IFERROR(INDEX(Setup!$F$9:$F$18,MATCH(F20,Setup!$E$9:$E$18,0)),0))))
G21: =IF(N(E21)=0,"",IF(N(E21)=0,0,E21*IF(F21="",1,IFERROR(INDEX(Setup!$F$9:$F$18,MATCH(F21,Setup!$E$9:$E$18,0)),0))))
... G505: =IF(N(E505)=0,"",IF(N(E505)=0,0,E505*IF(F505="",1,IFERROR(INDEX(Setup!$F$9:$F$18,MATCH(F505,Setup!$E$9:$E$18,0)),0))))

Sheet Packing list
B2: Packing list
B3: Type x under Packed as things go in the bag. Add your own at the end.
B5: Item | C5: Category | D5: How many | E5: Packed
B6: Passports | C6: Documents | D6: 2 | E6: x
B7: Printed bookings | C7: Documents | D7: 1 | E7: x
B8: Travel insurance card | C8: Documents | D8: 1 | E8: x
B9: Credit cards | C9: Documents | D9: 2 | E9: x
B10: Some cash in yen | C10: Documents | D10: 1
B11: Rail pass voucher | C11: Documents | D11: 1 | E11: x
B12: T-shirts | C12: Clothes | D12: 6
B13: Long sleeve tops | C13: Clothes | D13: 3
B14: Jeans | C14: Clothes | D14: 2
B15: Light jacket | C15: Clothes | D15: 1 | E15: x
B16: Sweater | C16: Clothes | D16: 1
B17: Pajamas | C17: Clothes | D17: 1
B18: Underwear | C18: Clothes | D18: 12
B19: Socks | C19: Clothes | D19: 12
B20: Walking shoes | C20: Clothes | D20: 1 | E20: x
B21: Slip-on shoes for temples | C21: Clothes | D21: 1
B22: Scarf | C22: Clothes | D22: 1
B23: Toothbrush and toothpaste | C23: Toiletries | D23: 1
B24: Deodorant | C24: Toiletries | D24: 1
B25: Sunscreen | C25: Toiletries | D25: 1
B26: Shampoo, travel size | C26: Toiletries | D26: 1
B27: Hairbrush | C27: Toiletries | D27: 1
B28: Razor | C28: Toiletries | D28: 1
B29: Lip balm | C29: Toiletries | D29: 1
B30: Phone and charger | C30: Electronics | D30: 1
B31: Power bank | C31: Electronics | D31: 1 | E31: x
B32: Plug adapter | C32: Electronics | D32: 1 | E32: x
B33: Headphones | C33: Electronics | D33: 1 | E33: x
B34: Camera | C34: Electronics | D34: 1 | E34: x
B35: Painkillers | C35: Health | D35: 1
B36: Plasters | C36: Health | D36: 1 | E36: x
B37: Motion sickness tablets | C37: Health | D37: 1
B38: Prescription medicine | C38: Health | D38: 1
B39: Hand sanitiser | C39: Health | D39: 1
B40: Day backpack | C40: Other | D40: 1
B41: Reusable water bottle | C41: Other | D41: 1
B42: Small towel | C42: Other | D42: 1
...

Sheet Setup
B2: Setup
B3: The trip, its dates, and the currencies you will pay in.
B4: Trip | C4: Japan
B5: Travelers | C5: 2
B6: First day | C6: 46315
B7: Last day | C7: 46326
B8: Home currency | C8: USD | E8: Currency | F8: 1 unit is worth | H8: Booking type | I8: Budget category
E9: =$C$8 | F9: 1 | H9: Flight | I9: Flights
E10: JPY | F10: 0.0068 | H10: Hotel | I10: Lodging
B11: Each currency's worth in your home currency, for example 1 JPY is worth 0.0068 USD. | E11: EUR | F11: 1.08 | H11: Train | I11: Transport
B12: Each kind of booking counts in one budget category. | E12: GBP | F12: 1.27 | H12: Car | I12: Transport
H13: Tour | I13: Activities
H14: Restaurant | I14: Food
H15: Other | I15: Other

Sheet Start Here
B2: Start here
B3: Type only in the yellow cells. Everything else is calculated.
B5: 1 | C5: Setup: the trip, how many travel, the first and last day, your home currency and the other currencies.
B7: 2 | C7: Dashboard: your budget for each category.
B9: 3 | C9: Bookings: every flight, hotel, train, tour and table, with its code, its cost and what you have paid.
B11: 4 | C11: Itinerary: what you plan each day. Expenses: what you spend that is not a booking.
B13: 5 | C13: Packing list: type x as things go in the bag. The list has room for your own items.
C16: The budget counts the full cost of each booking as soon as you add it, so you see what is left.
C18: The example trip shows how it works. Delete it and plan your own.
C20: Works in Google Sheets and Microsoft Excel, with any currencies.
