Workbook

Sheet Dashboard
B2: Habit dashboard
B3: This month at the top, the whole year below.
B4: ="Showing "&CHOOSE(IF(Habits!$C$4=YEAR(TODAY()),MONTH(TODAY()),12),"January","February","March","April","May","June","July","August","September","October","November","December")&" "&Habits!$C$4
B6: Habits done this month | C6: Longest streak now | E6: Mood this month | G6: Sleep this month
B7: =IFERROR(SUM(C10:C24)/SUMIFS(D10:D24,B10:B24,"?*"),0) | C7: =MAX(G10:G24) | E7: =IFERROR(CHOOSE(IF(Habits!$C$4=YEAR(TODAY()),MONTH(TODAY()),12),Jan!AH23,Feb!AH23,Mar!AH23,Apr!AH23,May!AH23,Jun!AH23,Jul!AH23,Aug!AH23,Sep!AH23,Oct!AH23,Nov!AH23,Dec!AH23)*1,"") | G7: =IFERROR(CHOOSE(IF(Habits!$C$4=YEAR(TODAY()),MONTH(TODAY()),12),Jan!AH24,Feb!AH24,Mar!AH24,Apr!AH24,May!AH24,Jun!AH24,Jul!AH24,Aug!AH24,Sep!AH24,Oct!AH24,Nov!AH24,Dec!AH24)*1,"")
B9: Habit | C9: Done | D9: Days | E9: Share | G9: Streak now | H9: Best this year | J9: Month | K9: Mood | L9: Sleep | M9: Habits
B10: =IF(Habits!B8="","",Habits!B8) | C10: =IF(B10="","",CHOOSE(IF(Habits!$C$4=YEAR(TODAY()),MONTH(TODAY()),12),Jan!AH7,Feb!AH7,Mar!AH7,Apr!AH7,May!AH7,Jun!AH7,Jul!AH7,Aug!AH7,Sep!AH7,Oct!AH7,Nov!AH7,Dec!AH7)) | D10: =IF(B10="","",IF(Habits!$C$4=YEAR(TODAY()),DAY(TODAY()),31)) | E10: =IF(B10="","",CHOOSE(IF(Habits!$C$4=YEAR(TODAY()),MONTH(TODAY()),12),Jan!AI7,Feb!AI7,Mar!AI7,Apr!AI7,May!AI7,Jun!AI7,Jul!AI7,Aug!AI7,Sep!AI7,Oct!AI7,Nov!AI7,Dec!AI7)) | F10: =IF(OR(B10="",E10=""),"",REPT("█",MIN(8,MAX(0,ROUND((E10)*8,0))))&REPT("░",8-MIN(8,MAX(0,ROUND((E10)*8,0))))) | G10: =IF(B10="","",CHOOSE(IF(Habits!$C$4=YEAR(TODAY()),MONTH(TODAY()),12),Jan!AJ7,Feb!AJ7,Mar!AJ7,Apr!AJ7,May!AJ7,Jun!AJ7,Jul!AJ7,Aug!AJ7,Sep!AJ7,Oct!AJ7,Nov!AJ7,Dec!AJ7)) | H10: =IF(B10="","",MAX(Jan!AK7,Feb!AK7,Mar!AK7,Apr!AK7,May!AK7,Jun!AK7,Jul!AK7,Aug!AK7,Sep!AK7,Oct!AK7,Nov!AK7,Dec!AK7)) | J10: Jan | K10: =IFERROR(Jan!AH23*1,"") | L10: =IFERROR(Jan!AH24*1,"") | M10: =IF(OR(IF(Habits!$C$4<YEAR(TODAY()),DAY(EOMONTH(DATE(Habits!$C$4,1,1),0)),IF(Habits!$C$4>YEAR(TODAY()),0,IF(1<MONTH(TODAY()),DAY(EOMONTH(DATE(Habits!$C$4,1,1),0)),IF(1=MONTH(TODAY()),DAY(TODAY()),0))))=0,COUNTIF(B$10:B$24,"?*")=0),"",SUM(Jan!AH7:AH21)/(IF(Habits!$C$4<YEAR(TODAY()),DAY(EOMONTH(DATE(Habits!$C$4,1,1),0)),IF(Habits!$C$4>YEAR(TODAY()),0,IF(1<MONTH(TODAY()),DAY(EOMONTH(DATE(Habits!$C$4,1,1),0)),IF(1=MONTH(TODAY()),DAY(TODAY()),0))))*COUNTIF(B$10:B$24,"?*")))
B11: =IF(Habits!B9="","",Habits!B9) | C11: =IF(B11="","",CHOOSE(IF(Habits!$C$4=YEAR(TODAY()),MONTH(TODAY()),12),Jan!AH8,Feb!AH8,Mar!AH8,Apr!AH8,May!AH8,Jun!AH8,Jul!AH8,Aug!AH8,Sep!AH8,Oct!AH8,Nov!AH8,Dec!AH8)) | D11: =IF(B11="","",IF(Habits!$C$4=YEAR(TODAY()),DAY(TODAY()),31)) | E11: =IF(B11="","",CHOOSE(IF(Habits!$C$4=YEAR(TODAY()),MONTH(TODAY()),12),Jan!AI8,Feb!AI8,Mar!AI8,Apr!AI8,May!AI8,Jun!AI8,Jul!AI8,Aug!AI8,Sep!AI8,Oct!AI8,Nov!AI8,Dec!AI8)) | F11: =IF(OR(B11="",E11=""),"",REPT("█",MIN(8,MAX(0,ROUND((E11)*8,0))))&REPT("░",8-MIN(8,MAX(0,ROUND((E11)*8,0))))) | G11: =IF(B11="","",CHOOSE(IF(Habits!$C$4=YEAR(TODAY()),MONTH(TODAY()),12),Jan!AJ8,Feb!AJ8,Mar!AJ8,Apr!AJ8,May!AJ8,Jun!AJ8,Jul!AJ8,Aug!AJ8,Sep!AJ8,Oct!AJ8,Nov!AJ8,Dec!AJ8)) | H11: =IF(B11="","",MAX(Jan!AK8,Feb!AK8,Mar!AK8,Apr!AK8,May!AK8,Jun!AK8,Jul!AK8,Aug!AK8,Sep!AK8,Oct!AK8,Nov!AK8,Dec!AK8)) | J11: Feb | K11: =IFERROR(Feb!AH23*1,"") | L11: =IFERROR(Feb!AH24*1,"") | M11: =IF(OR(IF(Habits!$C$4<YEAR(TODAY()),DAY(EOMONTH(DATE(Habits!$C$4,2,1),0)),IF(Habits!$C$4>YEAR(TODAY()),0,IF(2<MONTH(TODAY()),DAY(EOMONTH(DATE(Habits!$C$4,2,1),0)),IF(2=MONTH(TODAY()),DAY(TODAY()),0))))=0,COUNTIF(B$10:B$24,"?*")=0),"",SUM(Feb!AH7:AH21)/(IF(Habits!$C$4<YEAR(TODAY()),DAY(EOMONTH(DATE(Habits!$C$4,2,1),0)),IF(Habits!$C$4>YEAR(TODAY()),0,IF(2<MONTH(TODAY()),DAY(EOMONTH(DATE(Habits!$C$4,2,1),0)),IF(2=MONTH(TODAY()),DAY(TODAY()),0))))*COUNTIF(B$10:B$24,"?*")))
B12: =IF(Habits!B10="","",Habits!B10) | C12: =IF(B12="","",CHOOSE(IF(Habits!$C$4=YEAR(TODAY()),MONTH(TODAY()),12),Jan!AH9,Feb!AH9,Mar!AH9,Apr!AH9,May!AH9,Jun!AH9,Jul!AH9,Aug!AH9,Sep!AH9,Oct!AH9,Nov!AH9,Dec!AH9)) | D12: =IF(B12="","",IF(Habits!$C$4=YEAR(TODAY()),DAY(TODAY()),31)) | E12: =IF(B12="","",CHOOSE(IF(Habits!$C$4=YEAR(TODAY()),MONTH(TODAY()),12),Jan!AI9,Feb!AI9,Mar!AI9,Apr!AI9,May!AI9,Jun!AI9,Jul!AI9,Aug!AI9,Sep!AI9,Oct!AI9,Nov!AI9,Dec!AI9)) | F12: =IF(OR(B12="",E12=""),"",REPT("█",MIN(8,MAX(0,ROUND((E12)*8,0))))&REPT("░",8-MIN(8,MAX(0,ROUND((E12)*8,0))))) | G12: =IF(B12="","",CHOOSE(IF(Habits!$C$4=YEAR(TODAY()),MONTH(TODAY()),12),Jan!AJ9,Feb!AJ9,Mar!AJ9,Apr!AJ9,May!AJ9,Jun!AJ9,Jul!AJ9,Aug!AJ9,Sep!AJ9,Oct!AJ9,Nov!AJ9,Dec!AJ9)) | H12: =IF(B12="","",MAX(Jan!AK9,Feb!AK9,Mar!AK9,Apr!AK9,May!AK9,Jun!AK9,Jul!AK9,Aug!AK9,Sep!AK9,Oct!AK9,Nov!AK9,Dec!AK9)) | J12: Mar | K12: =IFERROR(Mar!AH23*1,"") | L12: =IFERROR(Mar!AH24*1,"") | M12: =IF(OR(IF(Habits!$C$4<YEAR(TODAY()),DAY(EOMONTH(DATE(Habits!$C$4,3,1),0)),IF(Habits!$C$4>YEAR(TODAY()),0,IF(3<MONTH(TODAY()),DAY(EOMONTH(DATE(Habits!$C$4,3,1),0)),IF(3=MONTH(TODAY()),DAY(TODAY()),0))))=0,COUNTIF(B$10:B$24,"?*")=0),"",SUM(Mar!AH7:AH21)/(IF(Habits!$C$4<YEAR(TODAY()),DAY(EOMONTH(DATE(Habits!$C$4,3,1),0)),IF(Habits!$C$4>YEAR(TODAY()),0,IF(3<MONTH(TODAY()),DAY(EOMONTH(DATE(Habits!$C$4,3,1),0)),IF(3=MONTH(TODAY()),DAY(TODAY()),0))))*COUNTIF(B$10:B$24,"?*")))
B13: =IF(Habits!B11="","",Habits!B11) | C13: =IF(B13="","",CHOOSE(IF(Habits!$C$4=YEAR(TODAY()),MONTH(TODAY()),12),Jan!AH10,Feb!AH10,Mar!AH10,Apr!AH10,May!AH10,Jun!AH10,Jul!AH10,Aug!AH10,Sep!AH10,Oct!AH10,Nov!AH10,Dec!AH10)) | D13: =IF(B13="","",IF(Habits!$C$4=YEAR(TODAY()),DAY(TODAY()),31)) | E13: =IF(B13="","",CHOOSE(IF(Habits!$C$4=YEAR(TODAY()),MONTH(TODAY()),12),Jan!AI10,Feb!AI10,Mar!AI10,Apr!AI10,May!AI10,Jun!AI10,Jul!AI10,Aug!AI10,Sep!AI10,Oct!AI10,Nov!AI10,Dec!AI10)) | F13: =IF(OR(B13="",E13=""),"",REPT("█",MIN(8,MAX(0,ROUND((E13)*8,0))))&REPT("░",8-MIN(8,MAX(0,ROUND((E13)*8,0))))) | G13: =IF(B13="","",CHOOSE(IF(Habits!$C$4=YEAR(TODAY()),MONTH(TODAY()),12),Jan!AJ10,Feb!AJ10,Mar!AJ10,Apr!AJ10,May!AJ10,Jun!AJ10,Jul!AJ10,Aug!AJ10,Sep!AJ10,Oct!AJ10,Nov!AJ10,Dec!AJ10)) | H13: =IF(B13="","",MAX(Jan!AK10,Feb!AK10,Mar!AK10,Apr!AK10,May!AK10,Jun!AK10,Jul!AK10,Aug!AK10,Sep!AK10,Oct!AK10,Nov!AK10,Dec!AK10)) | J13: Apr | K13: =IFERROR(Apr!AH23*1,"") | L13: =IFERROR(Apr!AH24*1,"") | M13: =IF(OR(IF(Habits!$C$4<YEAR(TODAY()),DAY(EOMONTH(DATE(Habits!$C$4,4,1),0)),IF(Habits!$C$4>YEAR(TODAY()),0,IF(4<MONTH(TODAY()),DAY(EOMONTH(DATE(Habits!$C$4,4,1),0)),IF(4=MONTH(TODAY()),DAY(TODAY()),0))))=0,COUNTIF(B$10:B$24,"?*")=0),"",SUM(Apr!AH7:AH21)/(IF(Habits!$C$4<YEAR(TODAY()),DAY(EOMONTH(DATE(Habits!$C$4,4,1),0)),IF(Habits!$C$4>YEAR(TODAY()),0,IF(4<MONTH(TODAY()),DAY(EOMONTH(DATE(Habits!$C$4,4,1),0)),IF(4=MONTH(TODAY()),DAY(TODAY()),0))))*COUNTIF(B$10:B$24,"?*")))
B14: =IF(Habits!B12="","",Habits!B12) | C14: =IF(B14="","",CHOOSE(IF(Habits!$C$4=YEAR(TODAY()),MONTH(TODAY()),12),Jan!AH11,Feb!AH11,Mar!AH11,Apr!AH11,May!AH11,Jun!AH11,Jul!AH11,Aug!AH11,Sep!AH11,Oct!AH11,Nov!AH11,Dec!AH11)) | D14: =IF(B14="","",IF(Habits!$C$4=YEAR(TODAY()),DAY(TODAY()),31)) | E14: =IF(B14="","",CHOOSE(IF(Habits!$C$4=YEAR(TODAY()),MONTH(TODAY()),12),Jan!AI11,Feb!AI11,Mar!AI11,Apr!AI11,May!AI11,Jun!AI11,Jul!AI11,Aug!AI11,Sep!AI11,Oct!AI11,Nov!AI11,Dec!AI11)) | F14: =IF(OR(B14="",E14=""),"",REPT("█",MIN(8,MAX(0,ROUND((E14)*8,0))))&REPT("░",8-MIN(8,MAX(0,ROUND((E14)*8,0))))) | G14: =IF(B14="","",CHOOSE(IF(Habits!$C$4=YEAR(TODAY()),MONTH(TODAY()),12),Jan!AJ11,Feb!AJ11,Mar!AJ11,Apr!AJ11,May!AJ11,Jun!AJ11,Jul!AJ11,Aug!AJ11,Sep!AJ11,Oct!AJ11,Nov!AJ11,Dec!AJ11)) | H14: =IF(B14="","",MAX(Jan!AK11,Feb!AK11,Mar!AK11,Apr!AK11,May!AK11,Jun!AK11,Jul!AK11,Aug!AK11,Sep!AK11,Oct!AK11,Nov!AK11,Dec!AK11)) | J14: May | K14: =IFERROR(May!AH23*1,"") | L14: =IFERROR(May!AH24*1,"") | M14: =IF(OR(IF(Habits!$C$4<YEAR(TODAY()),DAY(EOMONTH(DATE(Habits!$C$4,5,1),0)),IF(Habits!$C$4>YEAR(TODAY()),0,IF(5<MONTH(TODAY()),DAY(EOMONTH(DATE(Habits!$C$4,5,1),0)),IF(5=MONTH(TODAY()),DAY(TODAY()),0))))=0,COUNTIF(B$10:B$24,"?*")=0),"",SUM(May!AH7:AH21)/(IF(Habits!$C$4<YEAR(TODAY()),DAY(EOMONTH(DATE(Habits!$C$4,5,1),0)),IF(Habits!$C$4>YEAR(TODAY()),0,IF(5<MONTH(TODAY()),DAY(EOMONTH(DATE(Habits!$C$4,5,1),0)),IF(5=MONTH(TODAY()),DAY(TODAY()),0))))*COUNTIF(B$10:B$24,"?*")))
B15: =IF(Habits!B13="","",Habits!B13) | C15: =IF(B15="","",CHOOSE(IF(Habits!$C$4=YEAR(TODAY()),MONTH(TODAY()),12),Jan!AH12,Feb!AH12,Mar!AH12,Apr!AH12,May!AH12,Jun!AH12,Jul!AH12,Aug!AH12,Sep!AH12,Oct!AH12,Nov!AH12,Dec!AH12)) | D15: =IF(B15="","",IF(Habits!$C$4=YEAR(TODAY()),DAY(TODAY()),31)) | E15: =IF(B15="","",CHOOSE(IF(Habits!$C$4=YEAR(TODAY()),MONTH(TODAY()),12),Jan!AI12,Feb!AI12,Mar!AI12,Apr!AI12,May!AI12,Jun!AI12,Jul!AI12,Aug!AI12,Sep!AI12,Oct!AI12,Nov!AI12,Dec!AI12)) | F15: =IF(OR(B15="",E15=""),"",REPT("█",MIN(8,MAX(0,ROUND((E15)*8,0))))&REPT("░",8-MIN(8,MAX(0,ROUND((E15)*8,0))))) | G15: =IF(B15="","",CHOOSE(IF(Habits!$C$4=YEAR(TODAY()),MONTH(TODAY()),12),Jan!AJ12,Feb!AJ12,Mar!AJ12,Apr!AJ12,May!AJ12,Jun!AJ12,Jul!AJ12,Aug!AJ12,Sep!AJ12,Oct!AJ12,Nov!AJ12,Dec!AJ12)) | H15: =IF(B15="","",MAX(Jan!AK12,Feb!AK12,Mar!AK12,Apr!AK12,May!AK12,Jun!AK12,Jul!AK12,Aug!AK12,Sep!AK12,Oct!AK12,Nov!AK12,Dec!AK12)) | J15: Jun | K15: =IFERROR(Jun!AH23*1,"") | L15: =IFERROR(Jun!AH24*1,"") | M15: =IF(OR(IF(Habits!$C$4<YEAR(TODAY()),DAY(EOMONTH(DATE(Habits!$C$4,6,1),0)),IF(Habits!$C$4>YEAR(TODAY()),0,IF(6<MONTH(TODAY()),DAY(EOMONTH(DATE(Habits!$C$4,6,1),0)),IF(6=MONTH(TODAY()),DAY(TODAY()),0))))=0,COUNTIF(B$10:B$24,"?*")=0),"",SUM(Jun!AH7:AH21)/(IF(Habits!$C$4<YEAR(TODAY()),DAY(EOMONTH(DATE(Habits!$C$4,6,1),0)),IF(Habits!$C$4>YEAR(TODAY()),0,IF(6<MONTH(TODAY()),DAY(EOMONTH(DATE(Habits!$C$4,6,1),0)),IF(6=MONTH(TODAY()),DAY(TODAY()),0))))*COUNTIF(B$10:B$24,"?*")))
B16: =IF(Habits!B14="","",Habits!B14) | C16: =IF(B16="","",CHOOSE(IF(Habits!$C$4=YEAR(TODAY()),MONTH(TODAY()),12),Jan!AH13,Feb!AH13,Mar!AH13,Apr!AH13,May!AH13,Jun!AH13,Jul!AH13,Aug!AH13,Sep!AH13,Oct!AH13,Nov!AH13,Dec!AH13)) | D16: =IF(B16="","",IF(Habits!$C$4=YEAR(TODAY()),DAY(TODAY()),31)) | E16: =IF(B16="","",CHOOSE(IF(Habits!$C$4=YEAR(TODAY()),MONTH(TODAY()),12),Jan!AI13,Feb!AI13,Mar!AI13,Apr!AI13,May!AI13,Jun!AI13,Jul!AI13,Aug!AI13,Sep!AI13,Oct!AI13,Nov!AI13,Dec!AI13)) | F16: =IF(OR(B16="",E16=""),"",REPT("█",MIN(8,MAX(0,ROUND((E16)*8,0))))&REPT("░",8-MIN(8,MAX(0,ROUND((E16)*8,0))))) | G16: =IF(B16="","",CHOOSE(IF(Habits!$C$4=YEAR(TODAY()),MONTH(TODAY()),12),Jan!AJ13,Feb!AJ13,Mar!AJ13,Apr!AJ13,May!AJ13,Jun!AJ13,Jul!AJ13,Aug!AJ13,Sep!AJ13,Oct!AJ13,Nov!AJ13,Dec!AJ13)) | H16: =IF(B16="","",MAX(Jan!AK13,Feb!AK13,Mar!AK13,Apr!AK13,May!AK13,Jun!AK13,Jul!AK13,Aug!AK13,Sep!AK13,Oct!AK13,Nov!AK13,Dec!AK13)) | J16: Jul | K16: =IFERROR(Jul!AH23*1,"") | L16: =IFERROR(Jul!AH24*1,"") | M16: =IF(OR(IF(Habits!$C$4<YEAR(TODAY()),DAY(EOMONTH(DATE(Habits!$C$4,7,1),0)),IF(Habits!$C$4>YEAR(TODAY()),0,IF(7<MONTH(TODAY()),DAY(EOMONTH(DATE(Habits!$C$4,7,1),0)),IF(7=MONTH(TODAY()),DAY(TODAY()),0))))=0,COUNTIF(B$10:B$24,"?*")=0),"",SUM(Jul!AH7:AH21)/(IF(Habits!$C$4<YEAR(TODAY()),DAY(EOMONTH(DATE(Habits!$C$4,7,1),0)),IF(Habits!$C$4>YEAR(TODAY()),0,IF(7<MONTH(TODAY()),DAY(EOMONTH(DATE(Habits!$C$4,7,1),0)),IF(7=MONTH(TODAY()),DAY(TODAY()),0))))*COUNTIF(B$10:B$24,"?*")))
B17: =IF(Habits!B15="","",Habits!B15) | C17: =IF(B17="","",CHOOSE(IF(Habits!$C$4=YEAR(TODAY()),MONTH(TODAY()),12),Jan!AH14,Feb!AH14,Mar!AH14,Apr!AH14,May!AH14,Jun!AH14,Jul!AH14,Aug!AH14,Sep!AH14,Oct!AH14,Nov!AH14,Dec!AH14)) | D17: =IF(B17="","",IF(Habits!$C$4=YEAR(TODAY()),DAY(TODAY()),31)) | E17: =IF(B17="","",CHOOSE(IF(Habits!$C$4=YEAR(TODAY()),MONTH(TODAY()),12),Jan!AI14,Feb!AI14,Mar!AI14,Apr!AI14,May!AI14,Jun!AI14,Jul!AI14,Aug!AI14,Sep!AI14,Oct!AI14,Nov!AI14,Dec!AI14)) | F17: =IF(OR(B17="",E17=""),"",REPT("█",MIN(8,MAX(0,ROUND((E17)*8,0))))&REPT("░",8-MIN(8,MAX(0,ROUND((E17)*8,0))))) | G17: =IF(B17="","",CHOOSE(IF(Habits!$C$4=YEAR(TODAY()),MONTH(TODAY()),12),Jan!AJ14,Feb!AJ14,Mar!AJ14,Apr!AJ14,May!AJ14,Jun!AJ14,Jul!AJ14,Aug!AJ14,Sep!AJ14,Oct!AJ14,Nov!AJ14,Dec!AJ14)) | H17: =IF(B17="","",MAX(Jan!AK14,Feb!AK14,Mar!AK14,Apr!AK14,May!AK14,Jun!AK14,Jul!AK14,Aug!AK14,Sep!AK14,Oct!AK14,Nov!AK14,Dec!AK14)) | J17: Aug | K17: =IFERROR(Aug!AH23*1,"") | L17: =IFERROR(Aug!AH24*1,"") | M17: =IF(OR(IF(Habits!$C$4<YEAR(TODAY()),DAY(EOMONTH(DATE(Habits!$C$4,8,1),0)),IF(Habits!$C$4>YEAR(TODAY()),0,IF(8<MONTH(TODAY()),DAY(EOMONTH(DATE(Habits!$C$4,8,1),0)),IF(8=MONTH(TODAY()),DAY(TODAY()),0))))=0,COUNTIF(B$10:B$24,"?*")=0),"",SUM(Aug!AH7:AH21)/(IF(Habits!$C$4<YEAR(TODAY()),DAY(EOMONTH(DATE(Habits!$C$4,8,1),0)),IF(Habits!$C$4>YEAR(TODAY()),0,IF(8<MONTH(TODAY()),DAY(EOMONTH(DATE(Habits!$C$4,8,1),0)),IF(8=MONTH(TODAY()),DAY(TODAY()),0))))*COUNTIF(B$10:B$24,"?*")))
B18: =IF(Habits!B16="","",Habits!B16) | C18: =IF(B18="","",CHOOSE(IF(Habits!$C$4=YEAR(TODAY()),MONTH(TODAY()),12),Jan!AH15,Feb!AH15,Mar!AH15,Apr!AH15,May!AH15,Jun!AH15,Jul!AH15,Aug!AH15,Sep!AH15,Oct!AH15,Nov!AH15,Dec!AH15)) | D18: =IF(B18="","",IF(Habits!$C$4=YEAR(TODAY()),DAY(TODAY()),31)) | E18: =IF(B18="","",CHOOSE(IF(Habits!$C$4=YEAR(TODAY()),MONTH(TODAY()),12),Jan!AI15,Feb!AI15,Mar!AI15,Apr!AI15,May!AI15,Jun!AI15,Jul!AI15,Aug!AI15,Sep!AI15,Oct!AI15,Nov!AI15,Dec!AI15)) | F18: =IF(OR(B18="",E18=""),"",REPT("█",MIN(8,MAX(0,ROUND((E18)*8,0))))&REPT("░",8-MIN(8,MAX(0,ROUND((E18)*8,0))))) | G18: =IF(B18="","",CHOOSE(IF(Habits!$C$4=YEAR(TODAY()),MONTH(TODAY()),12),Jan!AJ15,Feb!AJ15,Mar!AJ15,Apr!AJ15,May!AJ15,Jun!AJ15,Jul!AJ15,Aug!AJ15,Sep!AJ15,Oct!AJ15,Nov!AJ15,Dec!AJ15)) | H18: =IF(B18="","",MAX(Jan!AK15,Feb!AK15,Mar!AK15,Apr!AK15,May!AK15,Jun!AK15,Jul!AK15,Aug!AK15,Sep!AK15,Oct!AK15,Nov!AK15,Dec!AK15)) | J18: Sep | K18: =IFERROR(Sep!AH23*1,"") | L18: =IFERROR(Sep!AH24*1,"") | M18: =IF(OR(IF(Habits!$C$4<YEAR(TODAY()),DAY(EOMONTH(DATE(Habits!$C$4,9,1),0)),IF(Habits!$C$4>YEAR(TODAY()),0,IF(9<MONTH(TODAY()),DAY(EOMONTH(DATE(Habits!$C$4,9,1),0)),IF(9=MONTH(TODAY()),DAY(TODAY()),0))))=0,COUNTIF(B$10:B$24,"?*")=0),"",SUM(Sep!AH7:AH21)/(IF(Habits!$C$4<YEAR(TODAY()),DAY(EOMONTH(DATE(Habits!$C$4,9,1),0)),IF(Habits!$C$4>YEAR(TODAY()),0,IF(9<MONTH(TODAY()),DAY(EOMONTH(DATE(Habits!$C$4,9,1),0)),IF(9=MONTH(TODAY()),DAY(TODAY()),0))))*COUNTIF(B$10:B$24,"?*")))
B19: =IF(Habits!B17="","",Habits!B17) | C19: =IF(B19="","",CHOOSE(IF(Habits!$C$4=YEAR(TODAY()),MONTH(TODAY()),12),Jan!AH16,Feb!AH16,Mar!AH16,Apr!AH16,May!AH16,Jun!AH16,Jul!AH16,Aug!AH16,Sep!AH16,Oct!AH16,Nov!AH16,Dec!AH16)) | D19: =IF(B19="","",IF(Habits!$C$4=YEAR(TODAY()),DAY(TODAY()),31)) | E19: =IF(B19="","",CHOOSE(IF(Habits!$C$4=YEAR(TODAY()),MONTH(TODAY()),12),Jan!AI16,Feb!AI16,Mar!AI16,Apr!AI16,May!AI16,Jun!AI16,Jul!AI16,Aug!AI16,Sep!AI16,Oct!AI16,Nov!AI16,Dec!AI16)) | F19: =IF(OR(B19="",E19=""),"",REPT("█",MIN(8,MAX(0,ROUND((E19)*8,0))))&REPT("░",8-MIN(8,MAX(0,ROUND((E19)*8,0))))) | G19: =IF(B19="","",CHOOSE(IF(Habits!$C$4=YEAR(TODAY()),MONTH(TODAY()),12),Jan!AJ16,Feb!AJ16,Mar!AJ16,Apr!AJ16,May!AJ16,Jun!AJ16,Jul!AJ16,Aug!AJ16,Sep!AJ16,Oct!AJ16,Nov!AJ16,Dec!AJ16)) | H19: =IF(B19="","",MAX(Jan!AK16,Feb!AK16,Mar!AK16,Apr!AK16,May!AK16,Jun!AK16,Jul!AK16,Aug!AK16,Sep!AK16,Oct!AK16,Nov!AK16,Dec!AK16)) | J19: Oct | K19: =IFERROR(Oct!AH23*1,"") | L19: =IFERROR(Oct!AH24*1,"") | M19: =IF(OR(IF(Habits!$C$4<YEAR(TODAY()),DAY(EOMONTH(DATE(Habits!$C$4,10,1),0)),IF(Habits!$C$4>YEAR(TODAY()),0,IF(10<MONTH(TODAY()),DAY(EOMONTH(DATE(Habits!$C$4,10,1),0)),IF(10=MONTH(TODAY()),DAY(TODAY()),0))))=0,COUNTIF(B$10:B$24,"?*")=0),"",SUM(Oct!AH7:AH21)/(IF(Habits!$C$4<YEAR(TODAY()),DAY(EOMONTH(DATE(Habits!$C$4,10,1),0)),IF(Habits!$C$4>YEAR(TODAY()),0,IF(10<MONTH(TODAY()),DAY(EOMONTH(DATE(Habits!$C$4,10,1),0)),IF(10=MONTH(TODAY()),DAY(TODAY()),0))))*COUNTIF(B$10:B$24,"?*")))
B20: =IF(Habits!B18="","",Habits!B18) | C20: =IF(B20="","",CHOOSE(IF(Habits!$C$4=YEAR(TODAY()),MONTH(TODAY()),12),Jan!AH17,Feb!AH17,Mar!AH17,Apr!AH17,May!AH17,Jun!AH17,Jul!AH17,Aug!AH17,Sep!AH17,Oct!AH17,Nov!AH17,Dec!AH17)) | D20: =IF(B20="","",IF(Habits!$C$4=YEAR(TODAY()),DAY(TODAY()),31)) | E20: =IF(B20="","",CHOOSE(IF(Habits!$C$4=YEAR(TODAY()),MONTH(TODAY()),12),Jan!AI17,Feb!AI17,Mar!AI17,Apr!AI17,May!AI17,Jun!AI17,Jul!AI17,Aug!AI17,Sep!AI17,Oct!AI17,Nov!AI17,Dec!AI17)) | F20: =IF(OR(B20="",E20=""),"",REPT("█",MIN(8,MAX(0,ROUND((E20)*8,0))))&REPT("░",8-MIN(8,MAX(0,ROUND((E20)*8,0))))) | G20: =IF(B20="","",CHOOSE(IF(Habits!$C$4=YEAR(TODAY()),MONTH(TODAY()),12),Jan!AJ17,Feb!AJ17,Mar!AJ17,Apr!AJ17,May!AJ17,Jun!AJ17,Jul!AJ17,Aug!AJ17,Sep!AJ17,Oct!AJ17,Nov!AJ17,Dec!AJ17)) | H20: =IF(B20="","",MAX(Jan!AK17,Feb!AK17,Mar!AK17,Apr!AK17,May!AK17,Jun!AK17,Jul!AK17,Aug!AK17,Sep!AK17,Oct!AK17,Nov!AK17,Dec!AK17)) | J20: Nov | K20: =IFERROR(Nov!AH23*1,"") | L20: =IFERROR(Nov!AH24*1,"") | M20: =IF(OR(IF(Habits!$C$4<YEAR(TODAY()),DAY(EOMONTH(DATE(Habits!$C$4,11,1),0)),IF(Habits!$C$4>YEAR(TODAY()),0,IF(11<MONTH(TODAY()),DAY(EOMONTH(DATE(Habits!$C$4,11,1),0)),IF(11=MONTH(TODAY()),DAY(TODAY()),0))))=0,COUNTIF(B$10:B$24,"?*")=0),"",SUM(Nov!AH7:AH21)/(IF(Habits!$C$4<YEAR(TODAY()),DAY(EOMONTH(DATE(Habits!$C$4,11,1),0)),IF(Habits!$C$4>YEAR(TODAY()),0,IF(11<MONTH(TODAY()),DAY(EOMONTH(DATE(Habits!$C$4,11,1),0)),IF(11=MONTH(TODAY()),DAY(TODAY()),0))))*COUNTIF(B$10:B$24,"?*")))
B21: =IF(Habits!B19="","",Habits!B19) | C21: =IF(B21="","",CHOOSE(IF(Habits!$C$4=YEAR(TODAY()),MONTH(TODAY()),12),Jan!AH18,Feb!AH18,Mar!AH18,Apr!AH18,May!AH18,Jun!AH18,Jul!AH18,Aug!AH18,Sep!AH18,Oct!AH18,Nov!AH18,Dec!AH18)) | D21: =IF(B21="","",IF(Habits!$C$4=YEAR(TODAY()),DAY(TODAY()),31)) | E21: =IF(B21="","",CHOOSE(IF(Habits!$C$4=YEAR(TODAY()),MONTH(TODAY()),12),Jan!AI18,Feb!AI18,Mar!AI18,Apr!AI18,May!AI18,Jun!AI18,Jul!AI18,Aug!AI18,Sep!AI18,Oct!AI18,Nov!AI18,Dec!AI18)) | F21: =IF(OR(B21="",E21=""),"",REPT("█",MIN(8,MAX(0,ROUND((E21)*8,0))))&REPT("░",8-MIN(8,MAX(0,ROUND((E21)*8,0))))) | G21: =IF(B21="","",CHOOSE(IF(Habits!$C$4=YEAR(TODAY()),MONTH(TODAY()),12),Jan!AJ18,Feb!AJ18,Mar!AJ18,Apr!AJ18,May!AJ18,Jun!AJ18,Jul!AJ18,Aug!AJ18,Sep!AJ18,Oct!AJ18,Nov!AJ18,Dec!AJ18)) | H21: =IF(B21="","",MAX(Jan!AK18,Feb!AK18,Mar!AK18,Apr!AK18,May!AK18,Jun!AK18,Jul!AK18,Aug!AK18,Sep!AK18,Oct!AK18,Nov!AK18,Dec!AK18)) | J21: Dec | K21: =IFERROR(Dec!AH23*1,"") | L21: =IFERROR(Dec!AH24*1,"") | M21: =IF(OR(IF(Habits!$C$4<YEAR(TODAY()),DAY(EOMONTH(DATE(Habits!$C$4,12,1),0)),IF(Habits!$C$4>YEAR(TODAY()),0,IF(12<MONTH(TODAY()),DAY(EOMONTH(DATE(Habits!$C$4,12,1),0)),IF(12=MONTH(TODAY()),DAY(TODAY()),0))))=0,COUNTIF(B$10:B$24,"?*")=0),"",SUM(Dec!AH7:AH21)/(IF(Habits!$C$4<YEAR(TODAY()),DAY(EOMONTH(DATE(Habits!$C$4,12,1),0)),IF(Habits!$C$4>YEAR(TODAY()),0,IF(12<MONTH(TODAY()),DAY(EOMONTH(DATE(Habits!$C$4,12,1),0)),IF(12=MONTH(TODAY()),DAY(TODAY()),0))))*COUNTIF(B$10:B$24,"?*")))
B22: =IF(Habits!B20="","",Habits!B20) | C22: =IF(B22="","",CHOOSE(IF(Habits!$C$4=YEAR(TODAY()),MONTH(TODAY()),12),Jan!AH19,Feb!AH19,Mar!AH19,Apr!AH19,May!AH19,Jun!AH19,Jul!AH19,Aug!AH19,Sep!AH19,Oct!AH19,Nov!AH19,Dec!AH19)) | D22: =IF(B22="","",IF(Habits!$C$4=YEAR(TODAY()),DAY(TODAY()),31)) | E22: =IF(B22="","",CHOOSE(IF(Habits!$C$4=YEAR(TODAY()),MONTH(TODAY()),12),Jan!AI19,Feb!AI19,Mar!AI19,Apr!AI19,May!AI19,Jun!AI19,Jul!AI19,Aug!AI19,Sep!AI19,Oct!AI19,Nov!AI19,Dec!AI19)) | F22: =IF(OR(B22="",E22=""),"",REPT("█",MIN(8,MAX(0,ROUND((E22)*8,0))))&REPT("░",8-MIN(8,MAX(0,ROUND((E22)*8,0))))) | G22: =IF(B22="","",CHOOSE(IF(Habits!$C$4=YEAR(TODAY()),MONTH(TODAY()),12),Jan!AJ19,Feb!AJ19,Mar!AJ19,Apr!AJ19,May!AJ19,Jun!AJ19,Jul!AJ19,Aug!AJ19,Sep!AJ19,Oct!AJ19,Nov!AJ19,Dec!AJ19)) | H22: =IF(B22="","",MAX(Jan!AK19,Feb!AK19,Mar!AK19,Apr!AK19,May!AK19,Jun!AK19,Jul!AK19,Aug!AK19,Sep!AK19,Oct!AK19,Nov!AK19,Dec!AK19))
B23: =IF(Habits!B21="","",Habits!B21) | C23: =IF(B23="","",CHOOSE(IF(Habits!$C$4=YEAR(TODAY()),MONTH(TODAY()),12),Jan!AH20,Feb!AH20,Mar!AH20,Apr!AH20,May!AH20,Jun!AH20,Jul!AH20,Aug!AH20,Sep!AH20,Oct!AH20,Nov!AH20,Dec!AH20)) | D23: =IF(B23="","",IF(Habits!$C$4=YEAR(TODAY()),DAY(TODAY()),31)) | E23: =IF(B23="","",CHOOSE(IF(Habits!$C$4=YEAR(TODAY()),MONTH(TODAY()),12),Jan!AI20,Feb!AI20,Mar!AI20,Apr!AI20,May!AI20,Jun!AI20,Jul!AI20,Aug!AI20,Sep!AI20,Oct!AI20,Nov!AI20,Dec!AI20)) | F23: =IF(OR(B23="",E23=""),"",REPT("█",MIN(8,MAX(0,ROUND((E23)*8,0))))&REPT("░",8-MIN(8,MAX(0,ROUND((E23)*8,0))))) | G23: =IF(B23="","",CHOOSE(IF(Habits!$C$4=YEAR(TODAY()),MONTH(TODAY()),12),Jan!AJ20,Feb!AJ20,Mar!AJ20,Apr!AJ20,May!AJ20,Jun!AJ20,Jul!AJ20,Aug!AJ20,Sep!AJ20,Oct!AJ20,Nov!AJ20,Dec!AJ20)) | H23: =IF(B23="","",MAX(Jan!AK20,Feb!AK20,Mar!AK20,Apr!AK20,May!AK20,Jun!AK20,Jul!AK20,Aug!AK20,Sep!AK20,Oct!AK20,Nov!AK20,Dec!AK20))
B24: =IF(Habits!B22="","",Habits!B22) | C24: =IF(B24="","",CHOOSE(IF(Habits!$C$4=YEAR(TODAY()),MONTH(TODAY()),12),Jan!AH21,Feb!AH21,Mar!AH21,Apr!AH21,May!AH21,Jun!AH21,Jul!AH21,Aug!AH21,Sep!AH21,Oct!AH21,Nov!AH21,Dec!AH21)) | D24: =IF(B24="","",IF(Habits!$C$4=YEAR(TODAY()),DAY(TODAY()),31)) | E24: =IF(B24="","",CHOOSE(IF(Habits!$C$4=YEAR(TODAY()),MONTH(TODAY()),12),Jan!AI21,Feb!AI21,Mar!AI21,Apr!AI21,May!AI21,Jun!AI21,Jul!AI21,Aug!AI21,Sep!AI21,Oct!AI21,Nov!AI21,Dec!AI21)) | F24: =IF(OR(B24="",E24=""),"",REPT("█",MIN(8,MAX(0,ROUND((E24)*8,0))))&REPT("░",8-MIN(8,MAX(0,ROUND((E24)*8,0))))) | G24: =IF(B24="","",CHOOSE(IF(Habits!$C$4=YEAR(TODAY()),MONTH(TODAY()),12),Jan!AJ21,Feb!AJ21,Mar!AJ21,Apr!AJ21,May!AJ21,Jun!AJ21,Jul!AJ21,Aug!AJ21,Sep!AJ21,Oct!AJ21,Nov!AJ21,Dec!AJ21)) | H24: =IF(B24="","",MAX(Jan!AK21,Feb!AK21,Mar!AK21,Apr!AK21,May!AK21,Jun!AK21,Jul!AK21,Aug!AK21,Sep!AK21,Oct!AK21,Nov!AK21,Dec!AK21))
B27: Share of days | C27: Jan | D27: Feb | E27: Mar | F27: Apr | G27: May | H27: Jun | I27: Jul | J27: Aug | K27: Sep | L27: Oct | M27: Nov | N27: Dec
B28: =B10 | C28: =IF($B28="","",Jan!AI7) | D28: =IF($B28="","",Feb!AI7) | E28: =IF($B28="","",Mar!AI7) | F28: =IF($B28="","",Apr!AI7) | G28: =IF($B28="","",May!AI7) | H28: =IF($B28="","",Jun!AI7) | I28: =IF($B28="","",Jul!AI7) | J28: =IF($B28="","",Aug!AI7) | K28: =IF($B28="","",Sep!AI7) | L28: =IF($B28="","",Oct!AI7) | M28: =IF($B28="","",Nov!AI7) | N28: =IF($B28="","",Dec!AI7)
B29: =B11 | C29: =IF($B29="","",Jan!AI8) | D29: =IF($B29="","",Feb!AI8) | E29: =IF($B29="","",Mar!AI8) | F29: =IF($B29="","",Apr!AI8) | G29: =IF($B29="","",May!AI8) | H29: =IF($B29="","",Jun!AI8) | I29: =IF($B29="","",Jul!AI8) | J29: =IF($B29="","",Aug!AI8) | K29: =IF($B29="","",Sep!AI8) | L29: =IF($B29="","",Oct!AI8) | M29: =IF($B29="","",Nov!AI8) | N29: =IF($B29="","",Dec!AI8)
B30: =B12 | C30: =IF($B30="","",Jan!AI9) | D30: =IF($B30="","",Feb!AI9) | E30: =IF($B30="","",Mar!AI9) | F30: =IF($B30="","",Apr!AI9) | G30: =IF($B30="","",May!AI9) | H30: =IF($B30="","",Jun!AI9) | I30: =IF($B30="","",Jul!AI9) | J30: =IF($B30="","",Aug!AI9) | K30: =IF($B30="","",Sep!AI9) | L30: =IF($B30="","",Oct!AI9) | M30: =IF($B30="","",Nov!AI9) | N30: =IF($B30="","",Dec!AI9)
B31: =B13 | C31: =IF($B31="","",Jan!AI10) | D31: =IF($B31="","",Feb!AI10) | E31: =IF($B31="","",Mar!AI10) | F31: =IF($B31="","",Apr!AI10) | G31: =IF($B31="","",May!AI10) | H31: =IF($B31="","",Jun!AI10) | I31: =IF($B31="","",Jul!AI10) | J31: =IF($B31="","",Aug!AI10) | K31: =IF($B31="","",Sep!AI10) | L31: =IF($B31="","",Oct!AI10) | M31: =IF($B31="","",Nov!AI10) | N31: =IF($B31="","",Dec!AI10)
B32: =B14 | C32: =IF($B32="","",Jan!AI11) | D32: =IF($B32="","",Feb!AI11) | E32: =IF($B32="","",Mar!AI11) | F32: =IF($B32="","",Apr!AI11) | G32: =IF($B32="","",May!AI11) | H32: =IF($B32="","",Jun!AI11) | I32: =IF($B32="","",Jul!AI11) | J32: =IF($B32="","",Aug!AI11) | K32: =IF($B32="","",Sep!AI11) | L32: =IF($B32="","",Oct!AI11) | M32: =IF($B32="","",Nov!AI11) | N32: =IF($B32="","",Dec!AI11)
B33: =B15 | C33: =IF($B33="","",Jan!AI12) | D33: =IF($B33="","",Feb!AI12) | E33: =IF($B33="","",Mar!AI12) | F33: =IF($B33="","",Apr!AI12) | G33: =IF($B33="","",May!AI12) | H33: =IF($B33="","",Jun!AI12) | I33: =IF($B33="","",Jul!AI12) | J33: =IF($B33="","",Aug!AI12) | K33: =IF($B33="","",Sep!AI12) | L33: =IF($B33="","",Oct!AI12) | M33: =IF($B33="","",Nov!AI12) | N33: =IF($B33="","",Dec!AI12)
B34: =B16 | C34: =IF($B34="","",Jan!AI13) | D34: =IF($B34="","",Feb!AI13) | E34: =IF($B34="","",Mar!AI13) | F34: =IF($B34="","",Apr!AI13) | G34: =IF($B34="","",May!AI13) | H34: =IF($B34="","",Jun!AI13) | I34: =IF($B34="","",Jul!AI13) | J34: =IF($B34="","",Aug!AI13) | K34: =IF($B34="","",Sep!AI13) | L34: =IF($B34="","",Oct!AI13) | M34: =IF($B34="","",Nov!AI13) | N34: =IF($B34="","",Dec!AI13)
B35: =B17 | C35: =IF($B35="","",Jan!AI14) | D35: =IF($B35="","",Feb!AI14) | E35: =IF($B35="","",Mar!AI14) | F35: =IF($B35="","",Apr!AI14) | G35: =IF($B35="","",May!AI14) | H35: =IF($B35="","",Jun!AI14) | I35: =IF($B35="","",Jul!AI14) | J35: =IF($B35="","",Aug!AI14) | K35: =IF($B35="","",Sep!AI14) | L35: =IF($B35="","",Oct!AI14) | M35: =IF($B35="","",Nov!AI14) | N35: =IF($B35="","",Dec!AI14)
B36: =B18 | C36: =IF($B36="","",Jan!AI15) | D36: =IF($B36="","",Feb!AI15) | E36: =IF($B36="","",Mar!AI15) | F36: =IF($B36="","",Apr!AI15) | G36: =IF($B36="","",May!AI15) | H36: =IF($B36="","",Jun!AI15) | I36: =IF($B36="","",Jul!AI15) | J36: =IF($B36="","",Aug!AI15) | K36: =IF($B36="","",Sep!AI15) | L36: =IF($B36="","",Oct!AI15) | M36: =IF($B36="","",Nov!AI15) | N36: =IF($B36="","",Dec!AI15)
B37: =B19 | C37: =IF($B37="","",Jan!AI16) | D37: =IF($B37="","",Feb!AI16) | E37: =IF($B37="","",Mar!AI16) | F37: =IF($B37="","",Apr!AI16) | G37: =IF($B37="","",May!AI16) | H37: =IF($B37="","",Jun!AI16) | I37: =IF($B37="","",Jul!AI16) | J37: =IF($B37="","",Aug!AI16) | K37: =IF($B37="","",Sep!AI16) | L37: =IF($B37="","",Oct!AI16) | M37: =IF($B37="","",Nov!AI16) | N37: =IF($B37="","",Dec!AI16)
B38: =B20 | C38: =IF($B38="","",Jan!AI17) | D38: =IF($B38="","",Feb!AI17) | E38: =IF($B38="","",Mar!AI17) | F38: =IF($B38="","",Apr!AI17) | G38: =IF($B38="","",May!AI17) | H38: =IF($B38="","",Jun!AI17) | I38: =IF($B38="","",Jul!AI17) | J38: =IF($B38="","",Aug!AI17) | K38: =IF($B38="","",Sep!AI17) | L38: =IF($B38="","",Oct!AI17) | M38: =IF($B38="","",Nov!AI17) | N38: =IF($B38="","",Dec!AI17)
B39: =B21 | C39: =IF($B39="","",Jan!AI18) | D39: =IF($B39="","",Feb!AI18) | E39: =IF($B39="","",Mar!AI18) | F39: =IF($B39="","",Apr!AI18) | G39: =IF($B39="","",May!AI18) | H39: =IF($B39="","",Jun!AI18) | I39: =IF($B39="","",Jul!AI18) | J39: =IF($B39="","",Aug!AI18) | K39: =IF($B39="","",Sep!AI18) | L39: =IF($B39="","",Oct!AI18) | M39: =IF($B39="","",Nov!AI18) | N39: =IF($B39="","",Dec!AI18)
... B42: =B24 | C42: =IF($B42="","",Jan!AI21) | D42: =IF($B42="","",Feb!AI21) | E42: =IF($B42="","",Mar!AI21) | F42: =IF($B42="","",Apr!AI21) | G42: =IF($B42="","",May!AI21) | H42: =IF($B42="","",Jun!AI21) | I42: =IF($B42="","",Jul!AI21) | J42: =IF($B42="","",Aug!AI21) | K42: =IF($B42="","",Sep!AI21) | L42: =IF($B42="","",Oct!AI21) | M42: =IF($B42="","",Nov!AI21) | N42: =IF($B42="","",Dec!AI21)

Sheet Year in pixels
B2: ="Year in pixels "&Habits!$C$4
B3: Your mood on every day of the year, one square per day, from the month tabs.
C5: Jan | D5: Feb | E5: Mar | F5: Apr | G5: May | H5: Jun | I5: Jul | J5: Aug | K5: Sep | L5: Oct | M5: Nov | N5: Dec | P5: Mood
B6: 1 | C6: =IF(Jan!C$5="","x",IF(Jan!C23="","",Jan!C23)) | D6: =IF(Feb!C$5="","x",IF(Feb!C23="","",Feb!C23)) | E6: =IF(Mar!C$5="","x",IF(Mar!C23="","",Mar!C23)) | F6: =IF(Apr!C$5="","x",IF(Apr!C23="","",Apr!C23)) | G6: =IF(May!C$5="","x",IF(May!C23="","",May!C23)) | H6: =IF(Jun!C$5="","x",IF(Jun!C23="","",Jun!C23)) | I6: =IF(Jul!C$5="","x",IF(Jul!C23="","",Jul!C23)) | J6: =IF(Aug!C$5="","x",IF(Aug!C23="","",Aug!C23)) | K6: =IF(Sep!C$5="","x",IF(Sep!C23="","",Sep!C23)) | L6: =IF(Oct!C$5="","x",IF(Oct!C23="","",Oct!C23)) | M6: =IF(Nov!C$5="","x",IF(Nov!C23="","",Nov!C23)) | N6: =IF(Dec!C$5="","x",IF(Dec!C23="","",Dec!C23)) | P6: 5 Great
B7: 2 | C7: =IF(Jan!D$5="","x",IF(Jan!D23="","",Jan!D23)) | D7: =IF(Feb!D$5="","x",IF(Feb!D23="","",Feb!D23)) | E7: =IF(Mar!D$5="","x",IF(Mar!D23="","",Mar!D23)) | F7: =IF(Apr!D$5="","x",IF(Apr!D23="","",Apr!D23)) | G7: =IF(May!D$5="","x",IF(May!D23="","",May!D23)) | H7: =IF(Jun!D$5="","x",IF(Jun!D23="","",Jun!D23)) | I7: =IF(Jul!D$5="","x",IF(Jul!D23="","",Jul!D23)) | J7: =IF(Aug!D$5="","x",IF(Aug!D23="","",Aug!D23)) | K7: =IF(Sep!D$5="","x",IF(Sep!D23="","",Sep!D23)) | L7: =IF(Oct!D$5="","x",IF(Oct!D23="","",Oct!D23)) | M7: =IF(Nov!D$5="","x",IF(Nov!D23="","",Nov!D23)) | N7: =IF(Dec!D$5="","x",IF(Dec!D23="","",Dec!D23)) | P7: 4 Good
B8: 3 | C8: =IF(Jan!E$5="","x",IF(Jan!E23="","",Jan!E23)) | D8: =IF(Feb!E$5="","x",IF(Feb!E23="","",Feb!E23)) | E8: =IF(Mar!E$5="","x",IF(Mar!E23="","",Mar!E23)) | F8: =IF(Apr!E$5="","x",IF(Apr!E23="","",Apr!E23)) | G8: =IF(May!E$5="","x",IF(May!E23="","",May!E23)) | H8: =IF(Jun!E$5="","x",IF(Jun!E23="","",Jun!E23)) | I8: =IF(Jul!E$5="","x",IF(Jul!E23="","",Jul!E23)) | J8: =IF(Aug!E$5="","x",IF(Aug!E23="","",Aug!E23)) | K8: =IF(Sep!E$5="","x",IF(Sep!E23="","",Sep!E23)) | L8: =IF(Oct!E$5="","x",IF(Oct!E23="","",Oct!E23)) | M8: =IF(Nov!E$5="","x",IF(Nov!E23="","",Nov!E23)) | N8: =IF(Dec!E$5="","x",IF(Dec!E23="","",Dec!E23)) | P8: 3 Okay
B9: 4 | C9: =IF(Jan!F$5="","x",IF(Jan!F23="","",Jan!F23)) | D9: =IF(Feb!F$5="","x",IF(Feb!F23="","",Feb!F23)) | E9: =IF(Mar!F$5="","x",IF(Mar!F23="","",Mar!F23)) | F9: =IF(Apr!F$5="","x",IF(Apr!F23="","",Apr!F23)) | G9: =IF(May!F$5="","x",IF(May!F23="","",May!F23)) | H9: =IF(Jun!F$5="","x",IF(Jun!F23="","",Jun!F23)) | I9: =IF(Jul!F$5="","x",IF(Jul!F23="","",Jul!F23)) | J9: =IF(Aug!F$5="","x",IF(Aug!F23="","",Aug!F23)) | K9: =IF(Sep!F$5="","x",IF(Sep!F23="","",Sep!F23)) | L9: =IF(Oct!F$5="","x",IF(Oct!F23="","",Oct!F23)) | M9: =IF(Nov!F$5="","x",IF(Nov!F23="","",Nov!F23)) | N9: =IF(Dec!F$5="","x",IF(Dec!F23="","",Dec!F23)) | P9: 2 Low
B10: 5 | C10: =IF(Jan!G$5="","x",IF(Jan!G23="","",Jan!G23)) | D10: =IF(Feb!G$5="","x",IF(Feb!G23="","",Feb!G23)) | E10: =IF(Mar!G$5="","x",IF(Mar!G23="","",Mar!G23)) | F10: =IF(Apr!G$5="","x",IF(Apr!G23="","",Apr!G23)) | G10: =IF(May!G$5="","x",IF(May!G23="","",May!G23)) | H10: =IF(Jun!G$5="","x",IF(Jun!G23="","",Jun!G23)) | I10: =IF(Jul!G$5="","x",IF(Jul!G23="","",Jul!G23)) | J10: =IF(Aug!G$5="","x",IF(Aug!G23="","",Aug!G23)) | K10: =IF(Sep!G$5="","x",IF(Sep!G23="","",Sep!G23)) | L10: =IF(Oct!G$5="","x",IF(Oct!G23="","",Oct!G23)) | M10: =IF(Nov!G$5="","x",IF(Nov!G23="","",Nov!G23)) | N10: =IF(Dec!G$5="","x",IF(Dec!G23="","",Dec!G23)) | P10: 1 Bad
B11: 6 | C11: =IF(Jan!H$5="","x",IF(Jan!H23="","",Jan!H23)) | D11: =IF(Feb!H$5="","x",IF(Feb!H23="","",Feb!H23)) | E11: =IF(Mar!H$5="","x",IF(Mar!H23="","",Mar!H23)) | F11: =IF(Apr!H$5="","x",IF(Apr!H23="","",Apr!H23)) | G11: =IF(May!H$5="","x",IF(May!H23="","",May!H23)) | H11: =IF(Jun!H$5="","x",IF(Jun!H23="","",Jun!H23)) | I11: =IF(Jul!H$5="","x",IF(Jul!H23="","",Jul!H23)) | J11: =IF(Aug!H$5="","x",IF(Aug!H23="","",Aug!H23)) | K11: =IF(Sep!H$5="","x",IF(Sep!H23="","",Sep!H23)) | L11: =IF(Oct!H$5="","x",IF(Oct!H23="","",Oct!H23)) | M11: =IF(Nov!H$5="","x",IF(Nov!H23="","",Nov!H23)) | N11: =IF(Dec!H$5="","x",IF(Dec!H23="","",Dec!H23))
B12: 7 | C12: =IF(Jan!I$5="","x",IF(Jan!I23="","",Jan!I23)) | D12: =IF(Feb!I$5="","x",IF(Feb!I23="","",Feb!I23)) | E12: =IF(Mar!I$5="","x",IF(Mar!I23="","",Mar!I23)) | F12: =IF(Apr!I$5="","x",IF(Apr!I23="","",Apr!I23)) | G12: =IF(May!I$5="","x",IF(May!I23="","",May!I23)) | H12: =IF(Jun!I$5="","x",IF(Jun!I23="","",Jun!I23)) | I12: =IF(Jul!I$5="","x",IF(Jul!I23="","",Jul!I23)) | J12: =IF(Aug!I$5="","x",IF(Aug!I23="","",Aug!I23)) | K12: =IF(Sep!I$5="","x",IF(Sep!I23="","",Sep!I23)) | L12: =IF(Oct!I$5="","x",IF(Oct!I23="","",Oct!I23)) | M12: =IF(Nov!I$5="","x",IF(Nov!I23="","",Nov!I23)) | N12: =IF(Dec!I$5="","x",IF(Dec!I23="","",Dec!I23)) | P12: An empty square is a day with no mood yet.
B13: 8 | C13: =IF(Jan!J$5="","x",IF(Jan!J23="","",Jan!J23)) | D13: =IF(Feb!J$5="","x",IF(Feb!J23="","",Feb!J23)) | E13: =IF(Mar!J$5="","x",IF(Mar!J23="","",Mar!J23)) | F13: =IF(Apr!J$5="","x",IF(Apr!J23="","",Apr!J23)) | G13: =IF(May!J$5="","x",IF(May!J23="","",May!J23)) | H13: =IF(Jun!J$5="","x",IF(Jun!J23="","",Jun!J23)) | I13: =IF(Jul!J$5="","x",IF(Jul!J23="","",Jul!J23)) | J13: =IF(Aug!J$5="","x",IF(Aug!J23="","",Aug!J23)) | K13: =IF(Sep!J$5="","x",IF(Sep!J23="","",Sep!J23)) | L13: =IF(Oct!J$5="","x",IF(Oct!J23="","",Oct!J23)) | M13: =IF(Nov!J$5="","x",IF(Nov!J23="","",Nov!J23)) | N13: =IF(Dec!J$5="","x",IF(Dec!J23="","",Dec!J23))
B14: 9 | C14: =IF(Jan!K$5="","x",IF(Jan!K23="","",Jan!K23)) | D14: =IF(Feb!K$5="","x",IF(Feb!K23="","",Feb!K23)) | E14: =IF(Mar!K$5="","x",IF(Mar!K23="","",Mar!K23)) | F14: =IF(Apr!K$5="","x",IF(Apr!K23="","",Apr!K23)) | G14: =IF(May!K$5="","x",IF(May!K23="","",May!K23)) | H14: =IF(Jun!K$5="","x",IF(Jun!K23="","",Jun!K23)) | I14: =IF(Jul!K$5="","x",IF(Jul!K23="","",Jul!K23)) | J14: =IF(Aug!K$5="","x",IF(Aug!K23="","",Aug!K23)) | K14: =IF(Sep!K$5="","x",IF(Sep!K23="","",Sep!K23)) | L14: =IF(Oct!K$5="","x",IF(Oct!K23="","",Oct!K23)) | M14: =IF(Nov!K$5="","x",IF(Nov!K23="","",Nov!K23)) | N14: =IF(Dec!K$5="","x",IF(Dec!K23="","",Dec!K23))
B15: 10 | C15: =IF(Jan!L$5="","x",IF(Jan!L23="","",Jan!L23)) | D15: =IF(Feb!L$5="","x",IF(Feb!L23="","",Feb!L23)) | E15: =IF(Mar!L$5="","x",IF(Mar!L23="","",Mar!L23)) | F15: =IF(Apr!L$5="","x",IF(Apr!L23="","",Apr!L23)) | G15: =IF(May!L$5="","x",IF(May!L23="","",May!L23)) | H15: =IF(Jun!L$5="","x",IF(Jun!L23="","",Jun!L23)) | I15: =IF(Jul!L$5="","x",IF(Jul!L23="","",Jul!L23)) | J15: =IF(Aug!L$5="","x",IF(Aug!L23="","",Aug!L23)) | K15: =IF(Sep!L$5="","x",IF(Sep!L23="","",Sep!L23)) | L15: =IF(Oct!L$5="","x",IF(Oct!L23="","",Oct!L23)) | M15: =IF(Nov!L$5="","x",IF(Nov!L23="","",Nov!L23)) | N15: =IF(Dec!L$5="","x",IF(Dec!L23="","",Dec!L23))
B16: 11 | C16: =IF(Jan!M$5="","x",IF(Jan!M23="","",Jan!M23)) | D16: =IF(Feb!M$5="","x",IF(Feb!M23="","",Feb!M23)) | E16: =IF(Mar!M$5="","x",IF(Mar!M23="","",Mar!M23)) | F16: =IF(Apr!M$5="","x",IF(Apr!M23="","",Apr!M23)) | G16: =IF(May!M$5="","x",IF(May!M23="","",May!M23)) | H16: =IF(Jun!M$5="","x",IF(Jun!M23="","",Jun!M23)) | I16: =IF(Jul!M$5="","x",IF(Jul!M23="","",Jul!M23)) | J16: =IF(Aug!M$5="","x",IF(Aug!M23="","",Aug!M23)) | K16: =IF(Sep!M$5="","x",IF(Sep!M23="","",Sep!M23)) | L16: =IF(Oct!M$5="","x",IF(Oct!M23="","",Oct!M23)) | M16: =IF(Nov!M$5="","x",IF(Nov!M23="","",Nov!M23)) | N16: =IF(Dec!M$5="","x",IF(Dec!M23="","",Dec!M23))
B17: 12 | C17: =IF(Jan!N$5="","x",IF(Jan!N23="","",Jan!N23)) | D17: =IF(Feb!N$5="","x",IF(Feb!N23="","",Feb!N23)) | E17: =IF(Mar!N$5="","x",IF(Mar!N23="","",Mar!N23)) | F17: =IF(Apr!N$5="","x",IF(Apr!N23="","",Apr!N23)) | G17: =IF(May!N$5="","x",IF(May!N23="","",May!N23)) | H17: =IF(Jun!N$5="","x",IF(Jun!N23="","",Jun!N23)) | I17: =IF(Jul!N$5="","x",IF(Jul!N23="","",Jul!N23)) | J17: =IF(Aug!N$5="","x",IF(Aug!N23="","",Aug!N23)) | K17: =IF(Sep!N$5="","x",IF(Sep!N23="","",Sep!N23)) | L17: =IF(Oct!N$5="","x",IF(Oct!N23="","",Oct!N23)) | M17: =IF(Nov!N$5="","x",IF(Nov!N23="","",Nov!N23)) | N17: =IF(Dec!N$5="","x",IF(Dec!N23="","",Dec!N23))
B18: 13 | C18: =IF(Jan!O$5="","x",IF(Jan!O23="","",Jan!O23)) | D18: =IF(Feb!O$5="","x",IF(Feb!O23="","",Feb!O23)) | E18: =IF(Mar!O$5="","x",IF(Mar!O23="","",Mar!O23)) | F18: =IF(Apr!O$5="","x",IF(Apr!O23="","",Apr!O23)) | G18: =IF(May!O$5="","x",IF(May!O23="","",May!O23)) | H18: =IF(Jun!O$5="","x",IF(Jun!O23="","",Jun!O23)) | I18: =IF(Jul!O$5="","x",IF(Jul!O23="","",Jul!O23)) | J18: =IF(Aug!O$5="","x",IF(Aug!O23="","",Aug!O23)) | K18: =IF(Sep!O$5="","x",IF(Sep!O23="","",Sep!O23)) | L18: =IF(Oct!O$5="","x",IF(Oct!O23="","",Oct!O23)) | M18: =IF(Nov!O$5="","x",IF(Nov!O23="","",Nov!O23)) | N18: =IF(Dec!O$5="","x",IF(Dec!O23="","",Dec!O23))
B19: 14 | C19: =IF(Jan!P$5="","x",IF(Jan!P23="","",Jan!P23)) | D19: =IF(Feb!P$5="","x",IF(Feb!P23="","",Feb!P23)) | E19: =IF(Mar!P$5="","x",IF(Mar!P23="","",Mar!P23)) | F19: =IF(Apr!P$5="","x",IF(Apr!P23="","",Apr!P23)) | G19: =IF(May!P$5="","x",IF(May!P23="","",May!P23)) | H19: =IF(Jun!P$5="","x",IF(Jun!P23="","",Jun!P23)) | I19: =IF(Jul!P$5="","x",IF(Jul!P23="","",Jul!P23)) | J19: =IF(Aug!P$5="","x",IF(Aug!P23="","",Aug!P23)) | K19: =IF(Sep!P$5="","x",IF(Sep!P23="","",Sep!P23)) | L19: =IF(Oct!P$5="","x",IF(Oct!P23="","",Oct!P23)) | M19: =IF(Nov!P$5="","x",IF(Nov!P23="","",Nov!P23)) | N19: =IF(Dec!P$5="","x",IF(Dec!P23="","",Dec!P23))
B20: 15 | C20: =IF(Jan!Q$5="","x",IF(Jan!Q23="","",Jan!Q23)) | D20: =IF(Feb!Q$5="","x",IF(Feb!Q23="","",Feb!Q23)) | E20: =IF(Mar!Q$5="","x",IF(Mar!Q23="","",Mar!Q23)) | F20: =IF(Apr!Q$5="","x",IF(Apr!Q23="","",Apr!Q23)) | G20: =IF(May!Q$5="","x",IF(May!Q23="","",May!Q23)) | H20: =IF(Jun!Q$5="","x",IF(Jun!Q23="","",Jun!Q23)) | I20: =IF(Jul!Q$5="","x",IF(Jul!Q23="","",Jul!Q23)) | J20: =IF(Aug!Q$5="","x",IF(Aug!Q23="","",Aug!Q23)) | K20: =IF(Sep!Q$5="","x",IF(Sep!Q23="","",Sep!Q23)) | L20: =IF(Oct!Q$5="","x",IF(Oct!Q23="","",Oct!Q23)) | M20: =IF(Nov!Q$5="","x",IF(Nov!Q23="","",Nov!Q23)) | N20: =IF(Dec!Q$5="","x",IF(Dec!Q23="","",Dec!Q23))
B21: 16 | C21: =IF(Jan!R$5="","x",IF(Jan!R23="","",Jan!R23)) | D21: =IF(Feb!R$5="","x",IF(Feb!R23="","",Feb!R23)) | E21: =IF(Mar!R$5="","x",IF(Mar!R23="","",Mar!R23)) | F21: =IF(Apr!R$5="","x",IF(Apr!R23="","",Apr!R23)) | G21: =IF(May!R$5="","x",IF(May!R23="","",May!R23)) | H21: =IF(Jun!R$5="","x",IF(Jun!R23="","",Jun!R23)) | I21: =IF(Jul!R$5="","x",IF(Jul!R23="","",Jul!R23)) | J21: =IF(Aug!R$5="","x",IF(Aug!R23="","",Aug!R23)) | K21: =IF(Sep!R$5="","x",IF(Sep!R23="","",Sep!R23)) | L21: =IF(Oct!R$5="","x",IF(Oct!R23="","",Oct!R23)) | M21: =IF(Nov!R$5="","x",IF(Nov!R23="","",Nov!R23)) | N21: =IF(Dec!R$5="","x",IF(Dec!R23="","",Dec!R23))
B22: 17 | C22: =IF(Jan!S$5="","x",IF(Jan!S23="","",Jan!S23)) | D22: =IF(Feb!S$5="","x",IF(Feb!S23="","",Feb!S23)) | E22: =IF(Mar!S$5="","x",IF(Mar!S23="","",Mar!S23)) | F22: =IF(Apr!S$5="","x",IF(Apr!S23="","",Apr!S23)) | G22: =IF(May!S$5="","x",IF(May!S23="","",May!S23)) | H22: =IF(Jun!S$5="","x",IF(Jun!S23="","",Jun!S23)) | I22: =IF(Jul!S$5="","x",IF(Jul!S23="","",Jul!S23)) | J22: =IF(Aug!S$5="","x",IF(Aug!S23="","",Aug!S23)) | K22: =IF(Sep!S$5="","x",IF(Sep!S23="","",Sep!S23)) | L22: =IF(Oct!S$5="","x",IF(Oct!S23="","",Oct!S23)) | M22: =IF(Nov!S$5="","x",IF(Nov!S23="","",Nov!S23)) | N22: =IF(Dec!S$5="","x",IF(Dec!S23="","",Dec!S23))
B23: 18 | C23: =IF(Jan!T$5="","x",IF(Jan!T23="","",Jan!T23)) | D23: =IF(Feb!T$5="","x",IF(Feb!T23="","",Feb!T23)) | E23: =IF(Mar!T$5="","x",IF(Mar!T23="","",Mar!T23)) | F23: =IF(Apr!T$5="","x",IF(Apr!T23="","",Apr!T23)) | G23: =IF(May!T$5="","x",IF(May!T23="","",May!T23)) | H23: =IF(Jun!T$5="","x",IF(Jun!T23="","",Jun!T23)) | I23: =IF(Jul!T$5="","x",IF(Jul!T23="","",Jul!T23)) | J23: =IF(Aug!T$5="","x",IF(Aug!T23="","",Aug!T23)) | K23: =IF(Sep!T$5="","x",IF(Sep!T23="","",Sep!T23)) | L23: =IF(Oct!T$5="","x",IF(Oct!T23="","",Oct!T23)) | M23: =IF(Nov!T$5="","x",IF(Nov!T23="","",Nov!T23)) | N23: =IF(Dec!T$5="","x",IF(Dec!T23="","",Dec!T23))
B24: 19 | C24: =IF(Jan!U$5="","x",IF(Jan!U23="","",Jan!U23)) | D24: =IF(Feb!U$5="","x",IF(Feb!U23="","",Feb!U23)) | E24: =IF(Mar!U$5="","x",IF(Mar!U23="","",Mar!U23)) | F24: =IF(Apr!U$5="","x",IF(Apr!U23="","",Apr!U23)) | G24: =IF(May!U$5="","x",IF(May!U23="","",May!U23)) | H24: =IF(Jun!U$5="","x",IF(Jun!U23="","",Jun!U23)) | I24: =IF(Jul!U$5="","x",IF(Jul!U23="","",Jul!U23)) | J24: =IF(Aug!U$5="","x",IF(Aug!U23="","",Aug!U23)) | K24: =IF(Sep!U$5="","x",IF(Sep!U23="","",Sep!U23)) | L24: =IF(Oct!U$5="","x",IF(Oct!U23="","",Oct!U23)) | M24: =IF(Nov!U$5="","x",IF(Nov!U23="","",Nov!U23)) | N24: =IF(Dec!U$5="","x",IF(Dec!U23="","",Dec!U23))
B25: 20 | C25: =IF(Jan!V$5="","x",IF(Jan!V23="","",Jan!V23)) | D25: =IF(Feb!V$5="","x",IF(Feb!V23="","",Feb!V23)) | E25: =IF(Mar!V$5="","x",IF(Mar!V23="","",Mar!V23)) | F25: =IF(Apr!V$5="","x",IF(Apr!V23="","",Apr!V23)) | G25: =IF(May!V$5="","x",IF(May!V23="","",May!V23)) | H25: =IF(Jun!V$5="","x",IF(Jun!V23="","",Jun!V23)) | I25: =IF(Jul!V$5="","x",IF(Jul!V23="","",Jul!V23)) | J25: =IF(Aug!V$5="","x",IF(Aug!V23="","",Aug!V23)) | K25: =IF(Sep!V$5="","x",IF(Sep!V23="","",Sep!V23)) | L25: =IF(Oct!V$5="","x",IF(Oct!V23="","",Oct!V23)) | M25: =IF(Nov!V$5="","x",IF(Nov!V23="","",Nov!V23)) | N25: =IF(Dec!V$5="","x",IF(Dec!V23="","",Dec!V23))
B26: 21 | C26: =IF(Jan!W$5="","x",IF(Jan!W23="","",Jan!W23)) | D26: =IF(Feb!W$5="","x",IF(Feb!W23="","",Feb!W23)) | E26: =IF(Mar!W$5="","x",IF(Mar!W23="","",Mar!W23)) | F26: =IF(Apr!W$5="","x",IF(Apr!W23="","",Apr!W23)) | G26: =IF(May!W$5="","x",IF(May!W23="","",May!W23)) | H26: =IF(Jun!W$5="","x",IF(Jun!W23="","",Jun!W23)) | I26: =IF(Jul!W$5="","x",IF(Jul!W23="","",Jul!W23)) | J26: =IF(Aug!W$5="","x",IF(Aug!W23="","",Aug!W23)) | K26: =IF(Sep!W$5="","x",IF(Sep!W23="","",Sep!W23)) | L26: =IF(Oct!W$5="","x",IF(Oct!W23="","",Oct!W23)) | M26: =IF(Nov!W$5="","x",IF(Nov!W23="","",Nov!W23)) | N26: =IF(Dec!W$5="","x",IF(Dec!W23="","",Dec!W23))
B27: 22 | C27: =IF(Jan!X$5="","x",IF(Jan!X23="","",Jan!X23)) | D27: =IF(Feb!X$5="","x",IF(Feb!X23="","",Feb!X23)) | E27: =IF(Mar!X$5="","x",IF(Mar!X23="","",Mar!X23)) | F27: =IF(Apr!X$5="","x",IF(Apr!X23="","",Apr!X23)) | G27: =IF(May!X$5="","x",IF(May!X23="","",May!X23)) | H27: =IF(Jun!X$5="","x",IF(Jun!X23="","",Jun!X23)) | I27: =IF(Jul!X$5="","x",IF(Jul!X23="","",Jul!X23)) | J27: =IF(Aug!X$5="","x",IF(Aug!X23="","",Aug!X23)) | K27: =IF(Sep!X$5="","x",IF(Sep!X23="","",Sep!X23)) | L27: =IF(Oct!X$5="","x",IF(Oct!X23="","",Oct!X23)) | M27: =IF(Nov!X$5="","x",IF(Nov!X23="","",Nov!X23)) | N27: =IF(Dec!X$5="","x",IF(Dec!X23="","",Dec!X23))
B28: 23 | C28: =IF(Jan!Y$5="","x",IF(Jan!Y23="","",Jan!Y23)) | D28: =IF(Feb!Y$5="","x",IF(Feb!Y23="","",Feb!Y23)) | E28: =IF(Mar!Y$5="","x",IF(Mar!Y23="","",Mar!Y23)) | F28: =IF(Apr!Y$5="","x",IF(Apr!Y23="","",Apr!Y23)) | G28: =IF(May!Y$5="","x",IF(May!Y23="","",May!Y23)) | H28: =IF(Jun!Y$5="","x",IF(Jun!Y23="","",Jun!Y23)) | I28: =IF(Jul!Y$5="","x",IF(Jul!Y23="","",Jul!Y23)) | J28: =IF(Aug!Y$5="","x",IF(Aug!Y23="","",Aug!Y23)) | K28: =IF(Sep!Y$5="","x",IF(Sep!Y23="","",Sep!Y23)) | L28: =IF(Oct!Y$5="","x",IF(Oct!Y23="","",Oct!Y23)) | M28: =IF(Nov!Y$5="","x",IF(Nov!Y23="","",Nov!Y23)) | N28: =IF(Dec!Y$5="","x",IF(Dec!Y23="","",Dec!Y23))
B29: 24 | C29: =IF(Jan!Z$5="","x",IF(Jan!Z23="","",Jan!Z23)) | D29: =IF(Feb!Z$5="","x",IF(Feb!Z23="","",Feb!Z23)) | E29: =IF(Mar!Z$5="","x",IF(Mar!Z23="","",Mar!Z23)) | F29: =IF(Apr!Z$5="","x",IF(Apr!Z23="","",Apr!Z23)) | G29: =IF(May!Z$5="","x",IF(May!Z23="","",May!Z23)) | H29: =IF(Jun!Z$5="","x",IF(Jun!Z23="","",Jun!Z23)) | I29: =IF(Jul!Z$5="","x",IF(Jul!Z23="","",Jul!Z23)) | J29: =IF(Aug!Z$5="","x",IF(Aug!Z23="","",Aug!Z23)) | K29: =IF(Sep!Z$5="","x",IF(Sep!Z23="","",Sep!Z23)) | L29: =IF(Oct!Z$5="","x",IF(Oct!Z23="","",Oct!Z23)) | M29: =IF(Nov!Z$5="","x",IF(Nov!Z23="","",Nov!Z23)) | N29: =IF(Dec!Z$5="","x",IF(Dec!Z23="","",Dec!Z23))
B30: 25 | C30: =IF(Jan!AA$5="","x",IF(Jan!AA23="","",Jan!AA23)) | D30: =IF(Feb!AA$5="","x",IF(Feb!AA23="","",Feb!AA23)) | E30: =IF(Mar!AA$5="","x",IF(Mar!AA23="","",Mar!AA23)) | F30: =IF(Apr!AA$5="","x",IF(Apr!AA23="","",Apr!AA23)) | G30: =IF(May!AA$5="","x",IF(May!AA23="","",May!AA23)) | H30: =IF(Jun!AA$5="","x",IF(Jun!AA23="","",Jun!AA23)) | I30: =IF(Jul!AA$5="","x",IF(Jul!AA23="","",Jul!AA23)) | J30: =IF(Aug!AA$5="","x",IF(Aug!AA23="","",Aug!AA23)) | K30: =IF(Sep!AA$5="","x",IF(Sep!AA23="","",Sep!AA23)) | L30: =IF(Oct!AA$5="","x",IF(Oct!AA23="","",Oct!AA23)) | M30: =IF(Nov!AA$5="","x",IF(Nov!AA23="","",Nov!AA23)) | N30: =IF(Dec!AA$5="","x",IF(Dec!AA23="","",Dec!AA23))
B31: 26 | C31: =IF(Jan!AB$5="","x",IF(Jan!AB23="","",Jan!AB23)) | D31: =IF(Feb!AB$5="","x",IF(Feb!AB23="","",Feb!AB23)) | E31: =IF(Mar!AB$5="","x",IF(Mar!AB23="","",Mar!AB23)) | F31: =IF(Apr!AB$5="","x",IF(Apr!AB23="","",Apr!AB23)) | G31: =IF(May!AB$5="","x",IF(May!AB23="","",May!AB23)) | H31: =IF(Jun!AB$5="","x",IF(Jun!AB23="","",Jun!AB23)) | I31: =IF(Jul!AB$5="","x",IF(Jul!AB23="","",Jul!AB23)) | J31: =IF(Aug!AB$5="","x",IF(Aug!AB23="","",Aug!AB23)) | K31: =IF(Sep!AB$5="","x",IF(Sep!AB23="","",Sep!AB23)) | L31: =IF(Oct!AB$5="","x",IF(Oct!AB23="","",Oct!AB23)) | M31: =IF(Nov!AB$5="","x",IF(Nov!AB23="","",Nov!AB23)) | N31: =IF(Dec!AB$5="","x",IF(Dec!AB23="","",Dec!AB23))
B32: 27 | C32: =IF(Jan!AC$5="","x",IF(Jan!AC23="","",Jan!AC23)) | D32: =IF(Feb!AC$5="","x",IF(Feb!AC23="","",Feb!AC23)) | E32: =IF(Mar!AC$5="","x",IF(Mar!AC23="","",Mar!AC23)) | F32: =IF(Apr!AC$5="","x",IF(Apr!AC23="","",Apr!AC23)) | G32: =IF(May!AC$5="","x",IF(May!AC23="","",May!AC23)) | H32: =IF(Jun!AC$5="","x",IF(Jun!AC23="","",Jun!AC23)) | I32: =IF(Jul!AC$5="","x",IF(Jul!AC23="","",Jul!AC23)) | J32: =IF(Aug!AC$5="","x",IF(Aug!AC23="","",Aug!AC23)) | K32: =IF(Sep!AC$5="","x",IF(Sep!AC23="","",Sep!AC23)) | L32: =IF(Oct!AC$5="","x",IF(Oct!AC23="","",Oct!AC23)) | M32: =IF(Nov!AC$5="","x",IF(Nov!AC23="","",Nov!AC23)) | N32: =IF(Dec!AC$5="","x",IF(Dec!AC23="","",Dec!AC23))
B33: 28 | C33: =IF(Jan!AD$5="","x",IF(Jan!AD23="","",Jan!AD23)) | D33: =IF(Feb!AD$5="","x",IF(Feb!AD23="","",Feb!AD23)) | E33: =IF(Mar!AD$5="","x",IF(Mar!AD23="","",Mar!AD23)) | F33: =IF(Apr!AD$5="","x",IF(Apr!AD23="","",Apr!AD23)) | G33: =IF(May!AD$5="","x",IF(May!AD23="","",May!AD23)) | H33: =IF(Jun!AD$5="","x",IF(Jun!AD23="","",Jun!AD23)) | I33: =IF(Jul!AD$5="","x",IF(Jul!AD23="","",Jul!AD23)) | J33: =IF(Aug!AD$5="","x",IF(Aug!AD23="","",Aug!AD23)) | K33: =IF(Sep!AD$5="","x",IF(Sep!AD23="","",Sep!AD23)) | L33: =IF(Oct!AD$5="","x",IF(Oct!AD23="","",Oct!AD23)) | M33: =IF(Nov!AD$5="","x",IF(Nov!AD23="","",Nov!AD23)) | N33: =IF(Dec!AD$5="","x",IF(Dec!AD23="","",Dec!AD23))
B34: 29 | C34: =IF(Jan!AE$5="","x",IF(Jan!AE23="","",Jan!AE23)) | D34: =IF(Feb!AE$5="","x",IF(Feb!AE23="","",Feb!AE23)) | E34: =IF(Mar!AE$5="","x",IF(Mar!AE23="","",Mar!AE23)) | F34: =IF(Apr!AE$5="","x",IF(Apr!AE23="","",Apr!AE23)) | G34: =IF(May!AE$5="","x",IF(May!AE23="","",May!AE23)) | H34: =IF(Jun!AE$5="","x",IF(Jun!AE23="","",Jun!AE23)) | I34: =IF(Jul!AE$5="","x",IF(Jul!AE23="","",Jul!AE23)) | J34: =IF(Aug!AE$5="","x",IF(Aug!AE23="","",Aug!AE23)) | K34: =IF(Sep!AE$5="","x",IF(Sep!AE23="","",Sep!AE23)) | L34: =IF(Oct!AE$5="","x",IF(Oct!AE23="","",Oct!AE23)) | M34: =IF(Nov!AE$5="","x",IF(Nov!AE23="","",Nov!AE23)) | N34: =IF(Dec!AE$5="","x",IF(Dec!AE23="","",Dec!AE23))
B35: 30 | C35: =IF(Jan!AF$5="","x",IF(Jan!AF23="","",Jan!AF23)) | D35: =IF(Feb!AF$5="","x",IF(Feb!AF23="","",Feb!AF23)) | E35: =IF(Mar!AF$5="","x",IF(Mar!AF23="","",Mar!AF23)) | F35: =IF(Apr!AF$5="","x",IF(Apr!AF23="","",Apr!AF23)) | G35: =IF(May!AF$5="","x",IF(May!AF23="","",May!AF23)) | H35: =IF(Jun!AF$5="","x",IF(Jun!AF23="","",Jun!AF23)) | I35: =IF(Jul!AF$5="","x",IF(Jul!AF23="","",Jul!AF23)) | J35: =IF(Aug!AF$5="","x",IF(Aug!AF23="","",Aug!AF23)) | K35: =IF(Sep!AF$5="","x",IF(Sep!AF23="","",Sep!AF23)) | L35: =IF(Oct!AF$5="","x",IF(Oct!AF23="","",Oct!AF23)) | M35: =IF(Nov!AF$5="","x",IF(Nov!AF23="","",Nov!AF23)) | N35: =IF(Dec!AF$5="","x",IF(Dec!AF23="","",Dec!AF23))
B36: 31 | C36: =IF(Jan!AG$5="","x",IF(Jan!AG23="","",Jan!AG23)) | D36: =IF(Feb!AG$5="","x",IF(Feb!AG23="","",Feb!AG23)) | E36: =IF(Mar!AG$5="","x",IF(Mar!AG23="","",Mar!AG23)) | F36: =IF(Apr!AG$5="","x",IF(Apr!AG23="","",Apr!AG23)) | G36: =IF(May!AG$5="","x",IF(May!AG23="","",May!AG23)) | H36: =IF(Jun!AG$5="","x",IF(Jun!AG23="","",Jun!AG23)) | I36: =IF(Jul!AG$5="","x",IF(Jul!AG23="","",Jul!AG23)) | J36: =IF(Aug!AG$5="","x",IF(Aug!AG23="","",Aug!AG23)) | K36: =IF(Sep!AG$5="","x",IF(Sep!AG23="","",Sep!AG23)) | L36: =IF(Oct!AG$5="","x",IF(Oct!AG23="","",Oct!AG23)) | M36: =IF(Nov!AG$5="","x",IF(Nov!AG23="","",Nov!AG23)) | N36: =IF(Dec!AG$5="","x",IF(Dec!AG23="","",Dec!AG23))

Sheet Jan
B2: ="January "&Habits!$C$4
B3: Type x on each day you did a habit. Mood from 1 to 5, sleep in hours.
B5: Habit | C5: =IF(1<=DAY(EOMONTH(DATE(Habits!$C$4,1,1),0)),1,"") | D5: =IF(2<=DAY(EOMONTH(DATE(Habits!$C$4,1,1),0)),2,"") | E5: =IF(3<=DAY(EOMONTH(DATE(Habits!$C$4,1,1),0)),3,"") | F5: =IF(4<=DAY(EOMONTH(DATE(Habits!$C$4,1,1),0)),4,"") | G5: =IF(5<=DAY(EOMONTH(DATE(Habits!$C$4,1,1),0)),5,"") | H5: =IF(6<=DAY(EOMONTH(DATE(Habits!$C$4,1,1),0)),6,"") | I5: =IF(7<=DAY(EOMONTH(DATE(Habits!$C$4,1,1),0)),7,"") | J5: =IF(8<=DAY(EOMONTH(DATE(Habits!$C$4,1,1),0)),8,"") | K5: =IF(9<=DAY(EOMONTH(DATE(Habits!$C$4,1,1),0)),9,"") | L5: =IF(10<=DAY(EOMONTH(DATE(Habits!$C$4,1,1),0)),10,"") | M5: =IF(11<=DAY(EOMONTH(DATE(Habits!$C$4,1,1),0)),11,"") | N5: =IF(12<=DAY(EOMONTH(DATE(Habits!$C$4,1,1),0)),12,"") | O5: =IF(13<=DAY(EOMONTH(DATE(Habits!$C$4,1,1),0)),13,"") | P5: =IF(14<=DAY(EOMONTH(DATE(Habits!$C$4,1,1),0)),14,"") | Q5: =IF(15<=DAY(EOMONTH(DATE(Habits!$C$4,1,1),0)),15,"") | R5: =IF(16<=DAY(EOMONTH(DATE(Habits!$C$4,1,1),0)),16,"") | S5: =IF(17<=DAY(EOMONTH(DATE(Habits!$C$4,1,1),0)),17,"") | T5: =IF(18<=DAY(EOMONTH(DATE(Habits!$C$4,1,1),0)),18,"") | U5: =IF(19<=DAY(EOMONTH(DATE(Habits!$C$4,1,1),0)),19,"") | V5: =IF(20<=DAY(EOMONTH(DATE(Habits!$C$4,1,1),0)),20,"") | W5: =IF(21<=DAY(EOMONTH(DATE(Habits!$C$4,1,1),0)),21,"") | X5: =IF(22<=DAY(EOMONTH(DATE(Habits!$C$4,1,1),0)),22,"") | Y5: =IF(23<=DAY(EOMONTH(DATE(Habits!$C$4,1,1),0)),23,"") | Z5: =IF(24<=DAY(EOMONTH(DATE(Habits!$C$4,1,1),0)),24,"") | AA5: =IF(25<=DAY(EOMONTH(DATE(Habits!$C$4,1,1),0)),25,"") | AB5: =IF(26<=DAY(EOMONTH(DATE(Habits!$C$4,1,1),0)),26,"") | AC5: =IF(27<=DAY(EOMONTH(DATE(Habits!$C$4,1,1),0)),27,"") | AD5: =IF(28<=DAY(EOMONTH(DATE(Habits!$C$4,1,1),0)),28,"") | AE5: =IF(29<=DAY(EOMONTH(DATE(Habits!$C$4,1,1),0)),29,"") | AF5: =IF(30<=DAY(EOMONTH(DATE(Habits!$C$4,1,1),0)),30,"") | AG5: =IF(31<=DAY(EOMONTH(DATE(Habits!$C$4,1,1),0)),31,"") | AH5: Done | AI5: Share | AJ5: Streak now | AK5: Best streak
C6: =IF(C$5="","",CHOOSE(WEEKDAY(DATE(Habits!$C$4,1,1),2),"M","T","W","T","F","S","S")) | D6: =IF(D$5="","",CHOOSE(WEEKDAY(DATE(Habits!$C$4,1,2),2),"M","T","W","T","F","S","S")) | E6: =IF(E$5="","",CHOOSE(WEEKDAY(DATE(Habits!$C$4,1,3),2),"M","T","W","T","F","S","S")) | F6: =IF(F$5="","",CHOOSE(WEEKDAY(DATE(Habits!$C$4,1,4),2),"M","T","W","T","F","S","S")) | G6: =IF(G$5="","",CHOOSE(WEEKDAY(DATE(Habits!$C$4,1,5),2),"M","T","W","T","F","S","S")) | H6: =IF(H$5="","",CHOOSE(WEEKDAY(DATE(Habits!$C$4,1,6),2),"M","T","W","T","F","S","S")) | I6: =IF(I$5="","",CHOOSE(WEEKDAY(DATE(Habits!$C$4,1,7),2),"M","T","W","T","F","S","S")) | J6: =IF(J$5="","",CHOOSE(WEEKDAY(DATE(Habits!$C$4,1,8),2),"M","T","W","T","F","S","S")) | K6: =IF(K$5="","",CHOOSE(WEEKDAY(DATE(Habits!$C$4,1,9),2),"M","T","W","T","F","S","S")) | L6: =IF(L$5="","",CHOOSE(WEEKDAY(DATE(Habits!$C$4,1,10),2),"M","T","W","T","F","S","S")) | M6: =IF(M$5="","",CHOOSE(WEEKDAY(DATE(Habits!$C$4,1,11),2),"M","T","W","T","F","S","S")) | N6: =IF(N$5="","",CHOOSE(WEEKDAY(DATE(Habits!$C$4,1,12),2),"M","T","W","T","F","S","S")) | O6: =IF(O$5="","",CHOOSE(WEEKDAY(DATE(Habits!$C$4,1,13),2),"M","T","W","T","F","S","S")) | P6: =IF(P$5="","",CHOOSE(WEEKDAY(DATE(Habits!$C$4,1,14),2),"M","T","W","T","F","S","S")) | Q6: =IF(Q$5="","",CHOOSE(WEEKDAY(DATE(Habits!$C$4,1,15),2),"M","T","W","T","F","S","S")) | R6: =IF(R$5="","",CHOOSE(WEEKDAY(DATE(Habits!$C$4,1,16),2),"M","T","W","T","F","S","S")) | S6: =IF(S$5="","",CHOOSE(WEEKDAY(DATE(Habits!$C$4,1,17),2),"M","T","W","T","F","S","S")) | T6: =IF(T$5="","",CHOOSE(WEEKDAY(DATE(Habits!$C$4,1,18),2),"M","T","W","T","F","S","S")) | U6: =IF(U$5="","",CHOOSE(WEEKDAY(DATE(Habits!$C$4,1,19),2),"M","T","W","T","F","S","S")) | V6: =IF(V$5="","",CHOOSE(WEEKDAY(DATE(Habits!$C$4,1,20),2),"M","T","W","T","F","S","S")) | W6: =IF(W$5="","",CHOOSE(WEEKDAY(DATE(Habits!$C$4,1,21),2),"M","T","W","T","F","S","S")) | X6: =IF(X$5="","",CHOOSE(WEEKDAY(DATE(Habits!$C$4,1,22),2),"M","T","W","T","F","S","S")) | Y6: =IF(Y$5="","",CHOOSE(WEEKDAY(DATE(Habits!$C$4,1,23),2),"M","T","W","T","F","S","S")) | Z6: =IF(Z$5="","",CHOOSE(WEEKDAY(DATE(Habits!$C$4,1,24),2),"M","T","W","T","F","S","S")) | AA6: =IF(AA$5="","",CHOOSE(WEEKDAY(DATE(Habits!$C$4,1,25),2),"M","T","W","T","F","S","S")) | AB6: =IF(AB$5="","",CHOOSE(WEEKDAY(DATE(Habits!$C$4,1,26),2),"M","T","W","T","F","S","S")) | AC6: =IF(AC$5="","",CHOOSE(WEEKDAY(DATE(Habits!$C$4,1,27),2),"M","T","W","T","F","S","S")) | AD6: =IF(AD$5="","",CHOOSE(WEEKDAY(DATE(Habits!$C$4,1,28),2),"M","T","W","T","F","S","S")) | AE6: =IF(AE$5="","",CHOOSE(WEEKDAY(DATE(Habits!$C$4,1,29),2),"M","T","W","T","F","S","S")) | AF6: =IF(AF$5="","",CHOOSE(WEEKDAY(DATE(Habits!$C$4,1,30),2),"M","T","W","T","F","S","S")) | AG6: =IF(AG$5="","",CHOOSE(WEEKDAY(DATE(Habits!$C$4,1,31),2),"M","T","W","T","F","S","S"))
B7: =IF(Habits!B8="","",Habits!B8) | C7: x | D7: x | E7: x | F7: x | G7: x | I7: x | J7: x | K7: x | L7: x | M7: x | N7: x | O7: x | Q7: x | R7: x | S7: x | U7: x | V7: x | X7: x | Y7: x | Z7: x | AA7: x | AB7: x | AC7: x | AD7: x | AE7: x | AG7: x | AH7: =IF(B7="","",COUNTIF($C40:$AG40,">0")) | AI7: =IF(OR(B7="",IF(AND(Habits!$C$4=YEAR(TODAY()),1=MONTH(TODAY())),DAY(TODAY()),IF(DATE(Habits!$C$4,1,1)>TODAY(),0,DAY(EOMONTH(DATE(Habits!$C$4,1,1),0))))=0),"",MIN(1,(COUNTIF($C40:$AG40,">0"))/IF(AND(Habits!$C$4=YEAR(TODAY()),1=MONTH(TODAY())),DAY(TODAY()),IF(DATE(Habits!$C$4,1,1)>TODAY(),0,DAY(EOMONTH(DATE(Habits!$C$4,1,1),0)))))) | AJ7: =IF(B7="","",IF(AND(Habits!$C$4=YEAR(TODAY()),1=MONTH(TODAY())),IF(INDEX($C40:$AG40,DAY(TODAY()))>0,INDEX($C40:$AG40,DAY(TODAY())),IF(DAY(TODAY())=1,0,INDEX($C40:$AG40,DAY(TODAY())-1))),IF(DATE(Habits!$C$4,1,1)>TODAY(),"",INDEX($C40:$AG40,DAY(EOMONTH(DATE(Habits!$C$4,1,1),0)))))) | AK7: =IF(B7="","",MAX($C40:$AG40))
B8: =IF(Habits!B9="","",Habits!B9) | C8: x | I8: x | J8: x | L8: x | M8: x | N8: x | P8: x | Q8: x | R8: x | T8: x | U8: x | X8: x | Y8: x | Z8: x | AA8: x | AB8: x | AC8: x | AF8: x | AH8: =IF(B8="","",COUNTIF($C41:$AG41,">0")) | AI8: =IF(OR(B8="",IF(AND(Habits!$C$4=YEAR(TODAY()),1=MONTH(TODAY())),DAY(TODAY()),IF(DATE(Habits!$C$4,1,1)>TODAY(),0,DAY(EOMONTH(DATE(Habits!$C$4,1,1),0))))=0),"",MIN(1,(COUNTIF($C41:$AG41,">0"))/IF(AND(Habits!$C$4=YEAR(TODAY()),1=MONTH(TODAY())),DAY(TODAY()),IF(DATE(Habits!$C$4,1,1)>TODAY(),0,DAY(EOMONTH(DATE(Habits!$C$4,1,1),0)))))) | AJ8: =IF(B8="","",IF(AND(Habits!$C$4=YEAR(TODAY()),1=MONTH(TODAY())),IF(INDEX($C41:$AG41,DAY(TODAY()))>0,INDEX($C41:$AG41,DAY(TODAY())),IF(DAY(TODAY())=1,0,INDEX($C41:$AG41,DAY(TODAY())-1))),IF(DATE(Habits!$C$4,1,1)>TODAY(),"",INDEX($C41:$AG41,DAY(EOMONTH(DATE(Habits!$C$4,1,1),0)))))) | AK8: =IF(B8="","",MAX($C41:$AG41))
B9: =IF(Habits!B10="","",Habits!B10) | C9: x | D9: x | E9: x | F9: x | J9: x | K9: x | N9: x | O9: x | P9: x | S9: x | U9: x | AA9: x | AC9: x | AD9: x | AE9: x | AH9: =IF(B9="","",COUNTIF($C42:$AG42,">0")) | AI9: =IF(OR(B9="",IF(AND(Habits!$C$4=YEAR(TODAY()),1=MONTH(TODAY())),DAY(TODAY()),IF(DATE(Habits!$C$4,1,1)>TODAY(),0,DAY(EOMONTH(DATE(Habits!$C$4,1,1),0))))=0),"",MIN(1,(COUNTIF($C42:$AG42,">0"))/IF(AND(Habits!$C$4=YEAR(TODAY()),1=MONTH(TODAY())),DAY(TODAY()),IF(DATE(Habits!$C$4,1,1)>TODAY(),0,DAY(EOMONTH(DATE(Habits!$C$4,1,1),0)))))) | AJ9: =IF(B9="","",IF(AND(Habits!$C$4=YEAR(TODAY()),1=MONTH(TODAY())),IF(INDEX($C42:$AG42,DAY(TODAY()))>0,INDEX($C42:$AG42,DAY(TODAY())),IF(DAY(TODAY())=1,0,INDEX($C42:$AG42,DAY(TODAY())-1))),IF(DATE(Habits!$C$4,1,1)>TODAY(),"",INDEX($C42:$AG42,DAY(EOMONTH(DATE(Habits!$C$4,1,1),0)))))) | AK9: =IF(B9="","",MAX($C42:$AG42))
B10: =IF(Habits!B11="","",Habits!B11) | K10: x | N10: x | R10: x | T10: x | U10: x | V10: x | W10: x | X10: x | Z10: x | AC10: x | AE10: x | AG10: x | AH10: =IF(B10="","",COUNTIF($C43:$AG43,">0")) | AI10: =IF(OR(B10="",IF(AND(Habits!$C$4=YEAR(TODAY()),1=MONTH(TODAY())),DAY(TODAY()),IF(DATE(Habits!$C$4,1,1)>TODAY(),0,DAY(EOMONTH(DATE(Habits!$C$4,1,1),0))))=0),"",MIN(1,(COUNTIF($C43:$AG43,">0"))/IF(AND(Habits!$C$4=YEAR(TODAY()),1=MONTH(TODAY())),DAY(TODAY()),IF(DATE(Habits!$C$4,1,1)>TODAY(),0,DAY(EOMONTH(DATE(Habits!$C$4,1,1),0)))))) | AJ10: =IF(B10="","",IF(AND(Habits!$C$4=YEAR(TODAY()),1=MONTH(TODAY())),IF(INDEX($C43:$AG43,DAY(TODAY()))>0,INDEX($C43:$AG43,DAY(TODAY())),IF(DAY(TODAY())=1,0,INDEX($C43:$AG43,DAY(TODAY())-1))),IF(DATE(Habits!$C$4,1,1)>TODAY(),"",INDEX($C43:$AG43,DAY(EOMONTH(DATE(Habits!$C$4,1,1),0)))))) | AK10: =IF(B10="","",MAX($C43:$AG43))
B11: =IF(Habits!B12="","",Habits!B12) | D11: x | F11: x | G11: x | I11: x | K11: x | L11: x | O11: x | P11: x | R11: x | S11: x | V11: x | W11: x | X11: x | AB11: x | AD11: x | AF11: x | AH11: =IF(B11="","",COUNTIF($C44:$AG44,">0")) | AI11: =IF(OR(B11="",IF(AND(Habits!$C$4=YEAR(TODAY()),1=MONTH(TODAY())),DAY(TODAY()),IF(DATE(Habits!$C$4,1,1)>TODAY(),0,DAY(EOMONTH(DATE(Habits!$C$4,1,1),0))))=0),"",MIN(1,(COUNTIF($C44:$AG44,">0"))/IF(AND(Habits!$C$4=YEAR(TODAY()),1=MONTH(TODAY())),DAY(TODAY()),IF(DATE(Habits!$C$4,1,1)>TODAY(),0,DAY(EOMONTH(DATE(Habits!$C$4,1,1),0)))))) | AJ11: =IF(B11="","",IF(AND(Habits!$C$4=YEAR(TODAY()),1=MONTH(TODAY())),IF(INDEX($C44:$AG44,DAY(TODAY()))>0,INDEX($C44:$AG44,DAY(TODAY())),IF(DAY(TODAY())=1,0,INDEX($C44:$AG44,DAY(TODAY())-1))),IF(DATE(Habits!$C$4,1,1)>TODAY(),"",INDEX($C44:$AG44,DAY(EOMONTH(DATE(Habits!$C$4,1,1),0)))))) | AK11: =IF(B11="","",MAX($C44:$AG44))
B12: =IF(Habits!B13="","",Habits!B13) | C12: x | E12: x | I12: x | J12: x | K12: x | L12: x | P12: x | Q12: x | R12: x | U12: x | W12: x | Y12: x | AA12: x | AB12: x | AG12: x | AH12: =IF(B12="","",COUNTIF($C45:$AG45,">0")) | AI12: =IF(OR(B12="",IF(AND(Habits!$C$4=YEAR(TODAY()),1=MONTH(TODAY())),DAY(TODAY()),IF(DATE(Habits!$C$4,1,1)>TODAY(),0,DAY(EOMONTH(DATE(Habits!$C$4,1,1),0))))=0),"",MIN(1,(COUNTIF($C45:$AG45,">0"))/IF(AND(Habits!$C$4=YEAR(TODAY()),1=MONTH(TODAY())),DAY(TODAY()),IF(DATE(Habits!$C$4,1,1)>TODAY(),0,DAY(EOMONTH(DATE(Habits!$C$4,1,1),0)))))) | AJ12: =IF(B12="","",IF(AND(Habits!$C$4=YEAR(TODAY()),1=MONTH(TODAY())),IF(INDEX($C45:$AG45,DAY(TODAY()))>0,INDEX($C45:$AG45,DAY(TODAY())),IF(DAY(TODAY())=1,0,INDEX($C45:$AG45,DAY(TODAY())-1))),IF(DATE(Habits!$C$4,1,1)>TODAY(),"",INDEX($C45:$AG45,DAY(EOMONTH(DATE(Habits!$C$4,1,1),0)))))) | AK12: =IF(B12="","",MAX($C45:$AG45))
B13: =IF(Habits!B14="","",Habits!B14) | C13: x | D13: x | E13: x | F13: x | G13: x | H13: x | I13: x | J13: x | K13: x | L13: x | M13: x | N13: x | O13: x | P13: x | Q13: x | R13: x | S13: x | T13: x | U13: x | V13: x | W13: x | X13: x | Y13: x | Z13: x | AA13: x | AB13: x | AC13: x | AD13: x | AE13: x | AF13: x | AG13: x | AH13: =IF(B13="","",COUNTIF($C46:$AG46,">0")) | AI13: =IF(OR(B13="",IF(AND(Habits!$C$4=YEAR(TODAY()),1=MONTH(TODAY())),DAY(TODAY()),IF(DATE(Habits!$C$4,1,1)>TODAY(),0,DAY(EOMONTH(DATE(Habits!$C$4,1,1),0))))=0),"",MIN(1,(COUNTIF($C46:$AG46,">0"))/IF(AND(Habits!$C$4=YEAR(TODAY()),1=MONTH(TODAY())),DAY(TODAY()),IF(DATE(Habits!$C$4,1,1)>TODAY(),0,DAY(EOMONTH(DATE(Habits!$C$4,1,1),0)))))) | AJ13: =IF(B13="","",IF(AND(Habits!$C$4=YEAR(TODAY()),1=MONTH(TODAY())),IF(INDEX($C46:$AG46,DAY(TODAY()))>0,INDEX($C46:$AG46,DAY(TODAY())),IF(DAY(TODAY())=1,0,INDEX($C46:$AG46,DAY(TODAY())-1))),IF(DATE(Habits!$C$4,1,1)>TODAY(),"",INDEX($C46:$AG46,DAY(EOMONTH(DATE(Habits!$C$4,1,1),0)))))) | AK13: =IF(B13="","",MAX($C46:$AG46))
B14: =IF(Habits!B15="","",Habits!B15) | D14: x | F14: x | J14: x | N14: x | O14: x | P14: x | R14: x | X14: x | Z14: x | AA14: x | AB14: x | AC14: x | AE14: x | AH14: =IF(B14="","",COUNTIF($C47:$AG47,">0")) | AI14: =IF(OR(B14="",IF(AND(Habits!$C$4=YEAR(TODAY()),1=MONTH(TODAY())),DAY(TODAY()),IF(DATE(Habits!$C$4,1,1)>TODAY(),0,DAY(EOMONTH(DATE(Habits!$C$4,1,1),0))))=0),"",MIN(1,(COUNTIF($C47:$AG47,">0"))/IF(AND(Habits!$C$4=YEAR(TODAY()),1=MONTH(TODAY())),DAY(TODAY()),IF(DATE(Habits!$C$4,1,1)>TODAY(),0,DAY(EOMONTH(DATE(Habits!$C$4,1,1),0)))))) | AJ14: =IF(B14="","",IF(AND(Habits!$C$4=YEAR(TODAY()),1=MONTH(TODAY())),IF(INDEX($C47:$AG47,DAY(TODAY()))>0,INDEX($C47:$AG47,DAY(TODAY())),IF(DAY(TODAY())=1,0,INDEX($C47:$AG47,DAY(TODAY())-1))),IF(DATE(Habits!$C$4,1,1)>TODAY(),"",INDEX($C47:$AG47,DAY(EOMONTH(DATE(Habits!$C$4,1,1),0)))))) | AK14: =IF(B14="","",MAX($C47:$AG47))
B15: =IF(Habits!B16="","",Habits!B16) | AH15: =IF(B15="","",COUNTIF($C48:$AG48,">0")) | AI15: =IF(OR(B15="",IF(AND(Habits!$C$4=YEAR(TODAY()),1=MONTH(TODAY())),DAY(TODAY()),IF(DATE(Habits!$C$4,1,1)>TODAY(),0,DAY(EOMONTH(DATE(Habits!$C$4,1,1),0))))=0),"",MIN(1,(COUNTIF($C48:$AG48,">0"))/IF(AND(Habits!$C$4=YEAR(TODAY()),1=MONTH(TODAY())),DAY(TODAY()),IF(DATE(Habits!$C$4,1,1)>TODAY(),0,DAY(EOMONTH(DATE(Habits!$C$4,1,1),0)))))) | AJ15: =IF(B15="","",IF(AND(Habits!$C$4=YEAR(TODAY()),1=MONTH(TODAY())),IF(INDEX($C48:$AG48,DAY(TODAY()))>0,INDEX($C48:$AG48,DAY(TODAY())),IF(DAY(TODAY())=1,0,INDEX($C48:$AG48,DAY(TODAY())-1))),IF(DATE(Habits!$C$4,1,1)>TODAY(),"",INDEX($C48:$AG48,DAY(EOMONTH(DATE(Habits!$C$4,1,1),0)))))) | AK15: =IF(B15="","",MAX($C48:$AG48))
