Workbook

Sheet Today
B2: Plant care
B3: What your plants need today and in the days ahead.
B4: ="Today, "&DAY(TODAY())&" "&CHOOSE(MONTH(TODAY()),"Jan","Feb","Mar","Apr","May","Jun","Jul","Aug","Sep","Oct","Nov","Dec")&": "&IF(Settings!$C$7=1,"growing season","resting season")
B6: Plants | C6: Water today | D6: Late | F6: Feed this week | I6: Repot soon
B7: =COUNTIF(Plants!$B$6:$B$65,"?*") | C7: =COUNTIFS(Plants!$L$6:$L$65,"<="&TODAY()) | D7: =COUNTIFS(Plants!$L$6:$L$65,"<"&TODAY()) | F7: =COUNTIFS(Plants!$W$6:$W$65,"<"&TODAY()+7) | I7: =COUNTIFS(Plants!$X$6:$X$65,"<"&EDATE(TODAY(),2))
B9: Water | C9: Spot | D9: When | F9: Feed | G9: When | I9: Repot | J9: When
B10: =IF(T10="","Nothing to water this week",INDEX(Plants!$B$6:$B$65,MATCH(T10,Plants!$V$6:$V$65,0))) | C10: =IF(T10="","",INDEX(Plants!$D$6:$D$65,MATCH(T10,Plants!$V$6:$V$65,0))) | D10: =IF(T10="","",IF(INT(T10)<TODAY(),"Late "&(TODAY()-INT(T10))&IF((TODAY()-INT(T10))=1," day"," days"),IF(INT(T10)=TODAY(),"Today",CHOOSE(WEEKDAY(INT(T10),2),"Mon","Tue","Wed","Thu","Fri","Sat","Sun")&" "&DAY(INT(T10))&" "&CHOOSE(MONTH(INT(T10)),"Jan","Feb","Mar","Apr","May","Jun","Jul","Aug","Sep","Oct","Nov","Dec")))) | F10: =IF(U10="","No feeds this week",INDEX(Plants!$B$6:$B$65,MATCH(U10,Plants!$W$6:$W$65,0))) | G10: =IF(U10="","",IF(INT(U10)<=TODAY(),"Today",CHOOSE(WEEKDAY(INT(U10),2),"Mon","Tue","Wed","Thu","Fri","Sat","Sun")&" "&DAY(INT(U10))&" "&CHOOSE(MONTH(INT(U10)),"Jan","Feb","Mar","Apr","May","Jun","Jul","Aug","Sep","Oct","Nov","Dec"))) | I10: =IF(V10="","No repots in the next two months",INDEX(Plants!$B$6:$B$65,MATCH(V10,Plants!$X$6:$X$65,0))) | J10: =IF(V10="","",IF(INT(V10)<=TODAY(),"Now",CHOOSE(MONTH(INT(V10)),"Jan","Feb","Mar","Apr","May","Jun","Jul","Aug","Sep","Oct","Nov","Dec")&" "&YEAR(INT(V10)))) | T10: =IFERROR(IF(SMALL(Plants!$V$6:$V$65,1)<TODAY()+7,SMALL(Plants!$V$6:$V$65,1),""),"") | U10: =IFERROR(IF(SMALL(Plants!$W$6:$W$65,1)<TODAY()+7,SMALL(Plants!$W$6:$W$65,1),""),"") | V10: =IFERROR(IF(SMALL(Plants!$X$6:$X$65,1)<EDATE(TODAY(),2),SMALL(Plants!$X$6:$X$65,1),""),"")
B11: =IF(T11="","",INDEX(Plants!$B$6:$B$65,MATCH(T11,Plants!$V$6:$V$65,0))) | C11: =IF(T11="","",INDEX(Plants!$D$6:$D$65,MATCH(T11,Plants!$V$6:$V$65,0))) | D11: =IF(T11="","",IF(INT(T11)<TODAY(),"Late "&(TODAY()-INT(T11))&IF((TODAY()-INT(T11))=1," day"," days"),IF(INT(T11)=TODAY(),"Today",CHOOSE(WEEKDAY(INT(T11),2),"Mon","Tue","Wed","Thu","Fri","Sat","Sun")&" "&DAY(INT(T11))&" "&CHOOSE(MONTH(INT(T11)),"Jan","Feb","Mar","Apr","May","Jun","Jul","Aug","Sep","Oct","Nov","Dec")))) | F11: =IF(U11="","",INDEX(Plants!$B$6:$B$65,MATCH(U11,Plants!$W$6:$W$65,0))) | G11: =IF(U11="","",IF(INT(U11)<=TODAY(),"Today",CHOOSE(WEEKDAY(INT(U11),2),"Mon","Tue","Wed","Thu","Fri","Sat","Sun")&" "&DAY(INT(U11))&" "&CHOOSE(MONTH(INT(U11)),"Jan","Feb","Mar","Apr","May","Jun","Jul","Aug","Sep","Oct","Nov","Dec"))) | I11: =IF(V11="","",INDEX(Plants!$B$6:$B$65,MATCH(V11,Plants!$X$6:$X$65,0))) | J11: =IF(V11="","",IF(INT(V11)<=TODAY(),"Now",CHOOSE(MONTH(INT(V11)),"Jan","Feb","Mar","Apr","May","Jun","Jul","Aug","Sep","Oct","Nov","Dec")&" "&YEAR(INT(V11)))) | T11: =IFERROR(IF(SMALL(Plants!$V$6:$V$65,2)<TODAY()+7,SMALL(Plants!$V$6:$V$65,2),""),"") | U11: =IFERROR(IF(SMALL(Plants!$W$6:$W$65,2)<TODAY()+7,SMALL(Plants!$W$6:$W$65,2),""),"") | V11: =IFERROR(IF(SMALL(Plants!$X$6:$X$65,2)<EDATE(TODAY(),2),SMALL(Plants!$X$6:$X$65,2),""),"")
B12: =IF(T12="","",INDEX(Plants!$B$6:$B$65,MATCH(T12,Plants!$V$6:$V$65,0))) | C12: =IF(T12="","",INDEX(Plants!$D$6:$D$65,MATCH(T12,Plants!$V$6:$V$65,0))) | D12: =IF(T12="","",IF(INT(T12)<TODAY(),"Late "&(TODAY()-INT(T12))&IF((TODAY()-INT(T12))=1," day"," days"),IF(INT(T12)=TODAY(),"Today",CHOOSE(WEEKDAY(INT(T12),2),"Mon","Tue","Wed","Thu","Fri","Sat","Sun")&" "&DAY(INT(T12))&" "&CHOOSE(MONTH(INT(T12)),"Jan","Feb","Mar","Apr","May","Jun","Jul","Aug","Sep","Oct","Nov","Dec")))) | F12: =IF(U12="","",INDEX(Plants!$B$6:$B$65,MATCH(U12,Plants!$W$6:$W$65,0))) | G12: =IF(U12="","",IF(INT(U12)<=TODAY(),"Today",CHOOSE(WEEKDAY(INT(U12),2),"Mon","Tue","Wed","Thu","Fri","Sat","Sun")&" "&DAY(INT(U12))&" "&CHOOSE(MONTH(INT(U12)),"Jan","Feb","Mar","Apr","May","Jun","Jul","Aug","Sep","Oct","Nov","Dec"))) | I12: =IF(V12="","",INDEX(Plants!$B$6:$B$65,MATCH(V12,Plants!$X$6:$X$65,0))) | J12: =IF(V12="","",IF(INT(V12)<=TODAY(),"Now",CHOOSE(MONTH(INT(V12)),"Jan","Feb","Mar","Apr","May","Jun","Jul","Aug","Sep","Oct","Nov","Dec")&" "&YEAR(INT(V12)))) | T12: =IFERROR(IF(SMALL(Plants!$V$6:$V$65,3)<TODAY()+7,SMALL(Plants!$V$6:$V$65,3),""),"") | U12: =IFERROR(IF(SMALL(Plants!$W$6:$W$65,3)<TODAY()+7,SMALL(Plants!$W$6:$W$65,3),""),"") | V12: =IFERROR(IF(SMALL(Plants!$X$6:$X$65,3)<EDATE(TODAY(),2),SMALL(Plants!$X$6:$X$65,3),""),"")
B13: =IF(T13="","",INDEX(Plants!$B$6:$B$65,MATCH(T13,Plants!$V$6:$V$65,0))) | C13: =IF(T13="","",INDEX(Plants!$D$6:$D$65,MATCH(T13,Plants!$V$6:$V$65,0))) | D13: =IF(T13="","",IF(INT(T13)<TODAY(),"Late "&(TODAY()-INT(T13))&IF((TODAY()-INT(T13))=1," day"," days"),IF(INT(T13)=TODAY(),"Today",CHOOSE(WEEKDAY(INT(T13),2),"Mon","Tue","Wed","Thu","Fri","Sat","Sun")&" "&DAY(INT(T13))&" "&CHOOSE(MONTH(INT(T13)),"Jan","Feb","Mar","Apr","May","Jun","Jul","Aug","Sep","Oct","Nov","Dec")))) | F13: =IF(U13="","",INDEX(Plants!$B$6:$B$65,MATCH(U13,Plants!$W$6:$W$65,0))) | G13: =IF(U13="","",IF(INT(U13)<=TODAY(),"Today",CHOOSE(WEEKDAY(INT(U13),2),"Mon","Tue","Wed","Thu","Fri","Sat","Sun")&" "&DAY(INT(U13))&" "&CHOOSE(MONTH(INT(U13)),"Jan","Feb","Mar","Apr","May","Jun","Jul","Aug","Sep","Oct","Nov","Dec"))) | I13: =IF(V13="","",INDEX(Plants!$B$6:$B$65,MATCH(V13,Plants!$X$6:$X$65,0))) | J13: =IF(V13="","",IF(INT(V13)<=TODAY(),"Now",CHOOSE(MONTH(INT(V13)),"Jan","Feb","Mar","Apr","May","Jun","Jul","Aug","Sep","Oct","Nov","Dec")&" "&YEAR(INT(V13)))) | T13: =IFERROR(IF(SMALL(Plants!$V$6:$V$65,4)<TODAY()+7,SMALL(Plants!$V$6:$V$65,4),""),"") | U13: =IFERROR(IF(SMALL(Plants!$W$6:$W$65,4)<TODAY()+7,SMALL(Plants!$W$6:$W$65,4),""),"") | V13: =IFERROR(IF(SMALL(Plants!$X$6:$X$65,4)<EDATE(TODAY(),2),SMALL(Plants!$X$6:$X$65,4),""),"")
B14: =IF(T14="","",INDEX(Plants!$B$6:$B$65,MATCH(T14,Plants!$V$6:$V$65,0))) | C14: =IF(T14="","",INDEX(Plants!$D$6:$D$65,MATCH(T14,Plants!$V$6:$V$65,0))) | D14: =IF(T14="","",IF(INT(T14)<TODAY(),"Late "&(TODAY()-INT(T14))&IF((TODAY()-INT(T14))=1," day"," days"),IF(INT(T14)=TODAY(),"Today",CHOOSE(WEEKDAY(INT(T14),2),"Mon","Tue","Wed","Thu","Fri","Sat","Sun")&" "&DAY(INT(T14))&" "&CHOOSE(MONTH(INT(T14)),"Jan","Feb","Mar","Apr","May","Jun","Jul","Aug","Sep","Oct","Nov","Dec")))) | F14: =IF(U14="","",INDEX(Plants!$B$6:$B$65,MATCH(U14,Plants!$W$6:$W$65,0))) | G14: =IF(U14="","",IF(INT(U14)<=TODAY(),"Today",CHOOSE(WEEKDAY(INT(U14),2),"Mon","Tue","Wed","Thu","Fri","Sat","Sun")&" "&DAY(INT(U14))&" "&CHOOSE(MONTH(INT(U14)),"Jan","Feb","Mar","Apr","May","Jun","Jul","Aug","Sep","Oct","Nov","Dec"))) | I14: =IF(V14="","",INDEX(Plants!$B$6:$B$65,MATCH(V14,Plants!$X$6:$X$65,0))) | J14: =IF(V14="","",IF(INT(V14)<=TODAY(),"Now",CHOOSE(MONTH(INT(V14)),"Jan","Feb","Mar","Apr","May","Jun","Jul","Aug","Sep","Oct","Nov","Dec")&" "&YEAR(INT(V14)))) | T14: =IFERROR(IF(SMALL(Plants!$V$6:$V$65,5)<TODAY()+7,SMALL(Plants!$V$6:$V$65,5),""),"") | U14: =IFERROR(IF(SMALL(Plants!$W$6:$W$65,5)<TODAY()+7,SMALL(Plants!$W$6:$W$65,5),""),"") | V14: =IFERROR(IF(SMALL(Plants!$X$6:$X$65,5)<EDATE(TODAY(),2),SMALL(Plants!$X$6:$X$65,5),""),"")
B15: =IF(T15="","",INDEX(Plants!$B$6:$B$65,MATCH(T15,Plants!$V$6:$V$65,0))) | C15: =IF(T15="","",INDEX(Plants!$D$6:$D$65,MATCH(T15,Plants!$V$6:$V$65,0))) | D15: =IF(T15="","",IF(INT(T15)<TODAY(),"Late "&(TODAY()-INT(T15))&IF((TODAY()-INT(T15))=1," day"," days"),IF(INT(T15)=TODAY(),"Today",CHOOSE(WEEKDAY(INT(T15),2),"Mon","Tue","Wed","Thu","Fri","Sat","Sun")&" "&DAY(INT(T15))&" "&CHOOSE(MONTH(INT(T15)),"Jan","Feb","Mar","Apr","May","Jun","Jul","Aug","Sep","Oct","Nov","Dec")))) | F15: =IF(U15="","",INDEX(Plants!$B$6:$B$65,MATCH(U15,Plants!$W$6:$W$65,0))) | G15: =IF(U15="","",IF(INT(U15)<=TODAY(),"Today",CHOOSE(WEEKDAY(INT(U15),2),"Mon","Tue","Wed","Thu","Fri","Sat","Sun")&" "&DAY(INT(U15))&" "&CHOOSE(MONTH(INT(U15)),"Jan","Feb","Mar","Apr","May","Jun","Jul","Aug","Sep","Oct","Nov","Dec"))) | I15: =IF(V15="","",INDEX(Plants!$B$6:$B$65,MATCH(V15,Plants!$X$6:$X$65,0))) | J15: =IF(V15="","",IF(INT(V15)<=TODAY(),"Now",CHOOSE(MONTH(INT(V15)),"Jan","Feb","Mar","Apr","May","Jun","Jul","Aug","Sep","Oct","Nov","Dec")&" "&YEAR(INT(V15)))) | T15: =IFERROR(IF(SMALL(Plants!$V$6:$V$65,6)<TODAY()+7,SMALL(Plants!$V$6:$V$65,6),""),"") | U15: =IFERROR(IF(SMALL(Plants!$W$6:$W$65,6)<TODAY()+7,SMALL(Plants!$W$6:$W$65,6),""),"") | V15: =IFERROR(IF(SMALL(Plants!$X$6:$X$65,6)<EDATE(TODAY(),2),SMALL(Plants!$X$6:$X$65,6),""),"")
B16: =IF(T16="","",INDEX(Plants!$B$6:$B$65,MATCH(T16,Plants!$V$6:$V$65,0))) | C16: =IF(T16="","",INDEX(Plants!$D$6:$D$65,MATCH(T16,Plants!$V$6:$V$65,0))) | D16: =IF(T16="","",IF(INT(T16)<TODAY(),"Late "&(TODAY()-INT(T16))&IF((TODAY()-INT(T16))=1," day"," days"),IF(INT(T16)=TODAY(),"Today",CHOOSE(WEEKDAY(INT(T16),2),"Mon","Tue","Wed","Thu","Fri","Sat","Sun")&" "&DAY(INT(T16))&" "&CHOOSE(MONTH(INT(T16)),"Jan","Feb","Mar","Apr","May","Jun","Jul","Aug","Sep","Oct","Nov","Dec")))) | F16: =IF(U16="","",INDEX(Plants!$B$6:$B$65,MATCH(U16,Plants!$W$6:$W$65,0))) | G16: =IF(U16="","",IF(INT(U16)<=TODAY(),"Today",CHOOSE(WEEKDAY(INT(U16),2),"Mon","Tue","Wed","Thu","Fri","Sat","Sun")&" "&DAY(INT(U16))&" "&CHOOSE(MONTH(INT(U16)),"Jan","Feb","Mar","Apr","May","Jun","Jul","Aug","Sep","Oct","Nov","Dec"))) | I16: =IF(V16="","",INDEX(Plants!$B$6:$B$65,MATCH(V16,Plants!$X$6:$X$65,0))) | J16: =IF(V16="","",IF(INT(V16)<=TODAY(),"Now",CHOOSE(MONTH(INT(V16)),"Jan","Feb","Mar","Apr","May","Jun","Jul","Aug","Sep","Oct","Nov","Dec")&" "&YEAR(INT(V16)))) | T16: =IFERROR(IF(SMALL(Plants!$V$6:$V$65,7)<TODAY()+7,SMALL(Plants!$V$6:$V$65,7),""),"") | U16: =IFERROR(IF(SMALL(Plants!$W$6:$W$65,7)<TODAY()+7,SMALL(Plants!$W$6:$W$65,7),""),"") | V16: =IFERROR(IF(SMALL(Plants!$X$6:$X$65,7)<EDATE(TODAY(),2),SMALL(Plants!$X$6:$X$65,7),""),"")
B17: =IF(T17="","",INDEX(Plants!$B$6:$B$65,MATCH(T17,Plants!$V$6:$V$65,0))) | C17: =IF(T17="","",INDEX(Plants!$D$6:$D$65,MATCH(T17,Plants!$V$6:$V$65,0))) | D17: =IF(T17="","",IF(INT(T17)<TODAY(),"Late "&(TODAY()-INT(T17))&IF((TODAY()-INT(T17))=1," day"," days"),IF(INT(T17)=TODAY(),"Today",CHOOSE(WEEKDAY(INT(T17),2),"Mon","Tue","Wed","Thu","Fri","Sat","Sun")&" "&DAY(INT(T17))&" "&CHOOSE(MONTH(INT(T17)),"Jan","Feb","Mar","Apr","May","Jun","Jul","Aug","Sep","Oct","Nov","Dec")))) | F17: =IF(U17="","",INDEX(Plants!$B$6:$B$65,MATCH(U17,Plants!$W$6:$W$65,0))) | G17: =IF(U17="","",IF(INT(U17)<=TODAY(),"Today",CHOOSE(WEEKDAY(INT(U17),2),"Mon","Tue","Wed","Thu","Fri","Sat","Sun")&" "&DAY(INT(U17))&" "&CHOOSE(MONTH(INT(U17)),"Jan","Feb","Mar","Apr","May","Jun","Jul","Aug","Sep","Oct","Nov","Dec"))) | I17: =IF(V17="","",INDEX(Plants!$B$6:$B$65,MATCH(V17,Plants!$X$6:$X$65,0))) | J17: =IF(V17="","",IF(INT(V17)<=TODAY(),"Now",CHOOSE(MONTH(INT(V17)),"Jan","Feb","Mar","Apr","May","Jun","Jul","Aug","Sep","Oct","Nov","Dec")&" "&YEAR(INT(V17)))) | T17: =IFERROR(IF(SMALL(Plants!$V$6:$V$65,8)<TODAY()+7,SMALL(Plants!$V$6:$V$65,8),""),"") | U17: =IFERROR(IF(SMALL(Plants!$W$6:$W$65,8)<TODAY()+7,SMALL(Plants!$W$6:$W$65,8),""),"") | V17: =IFERROR(IF(SMALL(Plants!$X$6:$X$65,8)<EDATE(TODAY(),2),SMALL(Plants!$X$6:$X$65,8),""),"")
B18: =IF(T18="","",INDEX(Plants!$B$6:$B$65,MATCH(T18,Plants!$V$6:$V$65,0))) | C18: =IF(T18="","",INDEX(Plants!$D$6:$D$65,MATCH(T18,Plants!$V$6:$V$65,0))) | D18: =IF(T18="","",IF(INT(T18)<TODAY(),"Late "&(TODAY()-INT(T18))&IF((TODAY()-INT(T18))=1," day"," days"),IF(INT(T18)=TODAY(),"Today",CHOOSE(WEEKDAY(INT(T18),2),"Mon","Tue","Wed","Thu","Fri","Sat","Sun")&" "&DAY(INT(T18))&" "&CHOOSE(MONTH(INT(T18)),"Jan","Feb","Mar","Apr","May","Jun","Jul","Aug","Sep","Oct","Nov","Dec")))) | F18: =IF(U18="","",INDEX(Plants!$B$6:$B$65,MATCH(U18,Plants!$W$6:$W$65,0))) | G18: =IF(U18="","",IF(INT(U18)<=TODAY(),"Today",CHOOSE(WEEKDAY(INT(U18),2),"Mon","Tue","Wed","Thu","Fri","Sat","Sun")&" "&DAY(INT(U18))&" "&CHOOSE(MONTH(INT(U18)),"Jan","Feb","Mar","Apr","May","Jun","Jul","Aug","Sep","Oct","Nov","Dec"))) | I18: =IF(V18="","",INDEX(Plants!$B$6:$B$65,MATCH(V18,Plants!$X$6:$X$65,0))) | J18: =IF(V18="","",IF(INT(V18)<=TODAY(),"Now",CHOOSE(MONTH(INT(V18)),"Jan","Feb","Mar","Apr","May","Jun","Jul","Aug","Sep","Oct","Nov","Dec")&" "&YEAR(INT(V18)))) | T18: =IFERROR(IF(SMALL(Plants!$V$6:$V$65,9)<TODAY()+7,SMALL(Plants!$V$6:$V$65,9),""),"") | U18: =IFERROR(IF(SMALL(Plants!$W$6:$W$65,9)<TODAY()+7,SMALL(Plants!$W$6:$W$65,9),""),"") | V18: =IFERROR(IF(SMALL(Plants!$X$6:$X$65,9)<EDATE(TODAY(),2),SMALL(Plants!$X$6:$X$65,9),""),"")
B19: =IF(T19="","",INDEX(Plants!$B$6:$B$65,MATCH(T19,Plants!$V$6:$V$65,0))) | C19: =IF(T19="","",INDEX(Plants!$D$6:$D$65,MATCH(T19,Plants!$V$6:$V$65,0))) | D19: =IF(T19="","",IF(INT(T19)<TODAY(),"Late "&(TODAY()-INT(T19))&IF((TODAY()-INT(T19))=1," day"," days"),IF(INT(T19)=TODAY(),"Today",CHOOSE(WEEKDAY(INT(T19),2),"Mon","Tue","Wed","Thu","Fri","Sat","Sun")&" "&DAY(INT(T19))&" "&CHOOSE(MONTH(INT(T19)),"Jan","Feb","Mar","Apr","May","Jun","Jul","Aug","Sep","Oct","Nov","Dec")))) | F19: =IF(U19="","",INDEX(Plants!$B$6:$B$65,MATCH(U19,Plants!$W$6:$W$65,0))) | G19: =IF(U19="","",IF(INT(U19)<=TODAY(),"Today",CHOOSE(WEEKDAY(INT(U19),2),"Mon","Tue","Wed","Thu","Fri","Sat","Sun")&" "&DAY(INT(U19))&" "&CHOOSE(MONTH(INT(U19)),"Jan","Feb","Mar","Apr","May","Jun","Jul","Aug","Sep","Oct","Nov","Dec"))) | I19: =IF(V19="","",INDEX(Plants!$B$6:$B$65,MATCH(V19,Plants!$X$6:$X$65,0))) | J19: =IF(V19="","",IF(INT(V19)<=TODAY(),"Now",CHOOSE(MONTH(INT(V19)),"Jan","Feb","Mar","Apr","May","Jun","Jul","Aug","Sep","Oct","Nov","Dec")&" "&YEAR(INT(V19)))) | T19: =IFERROR(IF(SMALL(Plants!$V$6:$V$65,10)<TODAY()+7,SMALL(Plants!$V$6:$V$65,10),""),"") | U19: =IFERROR(IF(SMALL(Plants!$W$6:$W$65,10)<TODAY()+7,SMALL(Plants!$W$6:$W$65,10),""),"") | V19: =IFERROR(IF(SMALL(Plants!$X$6:$X$65,10)<EDATE(TODAY(),2),SMALL(Plants!$X$6:$X$65,10),""),"")
B20: =IF(T20="","",INDEX(Plants!$B$6:$B$65,MATCH(T20,Plants!$V$6:$V$65,0))) | C20: =IF(T20="","",INDEX(Plants!$D$6:$D$65,MATCH(T20,Plants!$V$6:$V$65,0))) | D20: =IF(T20="","",IF(INT(T20)<TODAY(),"Late "&(TODAY()-INT(T20))&IF((TODAY()-INT(T20))=1," day"," days"),IF(INT(T20)=TODAY(),"Today",CHOOSE(WEEKDAY(INT(T20),2),"Mon","Tue","Wed","Thu","Fri","Sat","Sun")&" "&DAY(INT(T20))&" "&CHOOSE(MONTH(INT(T20)),"Jan","Feb","Mar","Apr","May","Jun","Jul","Aug","Sep","Oct","Nov","Dec")))) | F20: =IF(U20="","",INDEX(Plants!$B$6:$B$65,MATCH(U20,Plants!$W$6:$W$65,0))) | G20: =IF(U20="","",IF(INT(U20)<=TODAY(),"Today",CHOOSE(WEEKDAY(INT(U20),2),"Mon","Tue","Wed","Thu","Fri","Sat","Sun")&" "&DAY(INT(U20))&" "&CHOOSE(MONTH(INT(U20)),"Jan","Feb","Mar","Apr","May","Jun","Jul","Aug","Sep","Oct","Nov","Dec"))) | I20: =IF(V20="","",INDEX(Plants!$B$6:$B$65,MATCH(V20,Plants!$X$6:$X$65,0))) | J20: =IF(V20="","",IF(INT(V20)<=TODAY(),"Now",CHOOSE(MONTH(INT(V20)),"Jan","Feb","Mar","Apr","May","Jun","Jul","Aug","Sep","Oct","Nov","Dec")&" "&YEAR(INT(V20)))) | T20: =IFERROR(IF(SMALL(Plants!$V$6:$V$65,11)<TODAY()+7,SMALL(Plants!$V$6:$V$65,11),""),"") | U20: =IFERROR(IF(SMALL(Plants!$W$6:$W$65,11)<TODAY()+7,SMALL(Plants!$W$6:$W$65,11),""),"") | V20: =IFERROR(IF(SMALL(Plants!$X$6:$X$65,11)<EDATE(TODAY(),2),SMALL(Plants!$X$6:$X$65,11),""),"")
B21: =IF(T21="","",INDEX(Plants!$B$6:$B$65,MATCH(T21,Plants!$V$6:$V$65,0))) | C21: =IF(T21="","",INDEX(Plants!$D$6:$D$65,MATCH(T21,Plants!$V$6:$V$65,0))) | D21: =IF(T21="","",IF(INT(T21)<TODAY(),"Late "&(TODAY()-INT(T21))&IF((TODAY()-INT(T21))=1," day"," days"),IF(INT(T21)=TODAY(),"Today",CHOOSE(WEEKDAY(INT(T21),2),"Mon","Tue","Wed","Thu","Fri","Sat","Sun")&" "&DAY(INT(T21))&" "&CHOOSE(MONTH(INT(T21)),"Jan","Feb","Mar","Apr","May","Jun","Jul","Aug","Sep","Oct","Nov","Dec")))) | F21: =IF(U21="","",INDEX(Plants!$B$6:$B$65,MATCH(U21,Plants!$W$6:$W$65,0))) | G21: =IF(U21="","",IF(INT(U21)<=TODAY(),"Today",CHOOSE(WEEKDAY(INT(U21),2),"Mon","Tue","Wed","Thu","Fri","Sat","Sun")&" "&DAY(INT(U21))&" "&CHOOSE(MONTH(INT(U21)),"Jan","Feb","Mar","Apr","May","Jun","Jul","Aug","Sep","Oct","Nov","Dec"))) | I21: =IF(V21="","",INDEX(Plants!$B$6:$B$65,MATCH(V21,Plants!$X$6:$X$65,0))) | J21: =IF(V21="","",IF(INT(V21)<=TODAY(),"Now",CHOOSE(MONTH(INT(V21)),"Jan","Feb","Mar","Apr","May","Jun","Jul","Aug","Sep","Oct","Nov","Dec")&" "&YEAR(INT(V21)))) | T21: =IFERROR(IF(SMALL(Plants!$V$6:$V$65,12)<TODAY()+7,SMALL(Plants!$V$6:$V$65,12),""),"") | U21: =IFERROR(IF(SMALL(Plants!$W$6:$W$65,12)<TODAY()+7,SMALL(Plants!$W$6:$W$65,12),""),"") | V21: =IFERROR(IF(SMALL(Plants!$X$6:$X$65,12)<EDATE(TODAY(),2),SMALL(Plants!$X$6:$X$65,12),""),"")
B23: Water: the plants due in the next seven days, the late ones first. Feeds stop while plants rest. Repot: the next two months.

Sheet This week
B2: This week
B3: What each plant needs over the next seven days, from what the care log says.
B5: Plant | C5: Spot | D5: =CHOOSE(WEEKDAY(TODAY()+0,2),"Mon","Tue","Wed","Thu","Fri","Sat","Sun")&" "&DAY((TODAY()+0))&" "&CHOOSE(MONTH((TODAY()+0)),"Jan","Feb","Mar","Apr","May","Jun","Jul","Aug","Sep","Oct","Nov","Dec") | E5: =CHOOSE(WEEKDAY(TODAY()+1,2),"Mon","Tue","Wed","Thu","Fri","Sat","Sun")&" "&DAY((TODAY()+1))&" "&CHOOSE(MONTH((TODAY()+1)),"Jan","Feb","Mar","Apr","May","Jun","Jul","Aug","Sep","Oct","Nov","Dec") | F5: =CHOOSE(WEEKDAY(TODAY()+2,2),"Mon","Tue","Wed","Thu","Fri","Sat","Sun")&" "&DAY((TODAY()+2))&" "&CHOOSE(MONTH((TODAY()+2)),"Jan","Feb","Mar","Apr","May","Jun","Jul","Aug","Sep","Oct","Nov","Dec") | G5: =CHOOSE(WEEKDAY(TODAY()+3,2),"Mon","Tue","Wed","Thu","Fri","Sat","Sun")&" "&DAY((TODAY()+3))&" "&CHOOSE(MONTH((TODAY()+3)),"Jan","Feb","Mar","Apr","May","Jun","Jul","Aug","Sep","Oct","Nov","Dec") | H5: =CHOOSE(WEEKDAY(TODAY()+4,2),"Mon","Tue","Wed","Thu","Fri","Sat","Sun")&" "&DAY((TODAY()+4))&" "&CHOOSE(MONTH((TODAY()+4)),"Jan","Feb","Mar","Apr","May","Jun","Jul","Aug","Sep","Oct","Nov","Dec") | I5: =CHOOSE(WEEKDAY(TODAY()+5,2),"Mon","Tue","Wed","Thu","Fri","Sat","Sun")&" "&DAY((TODAY()+5))&" "&CHOOSE(MONTH((TODAY()+5)),"Jan","Feb","Mar","Apr","May","Jun","Jul","Aug","Sep","Oct","Nov","Dec") | J5: =CHOOSE(WEEKDAY(TODAY()+6,2),"Mon","Tue","Wed","Thu","Fri","Sat","Sun")&" "&DAY((TODAY()+6))&" "&CHOOSE(MONTH((TODAY()+6)),"Jan","Feb","Mar","Apr","May","Jun","Jul","Aug","Sep","Oct","Nov","Dec")
B6: =IF(Plants!B6="","",Plants!B6) | C6: =IF(Plants!B6="","",Plants!D6) | D6: =IF(AND(ISNUMBER(Plants!L6),N(Plants!S6)>0,(TODAY()+0)>=MAX(Plants!L6,TODAY()),MOD((TODAY()+0)-MAX(Plants!L6,TODAY()),MAX(1,N(Plants!S6)))=0),IF(AND(ISNUMBER(Plants!N6),N(Plants!H6)>0,(TODAY()+0)>=MAX(Plants!N6,TODAY()),MOD((TODAY()+0)-MAX(Plants!N6,TODAY()),MAX(1,N(Plants!H6)))=0),"Water, feed","Water"),IF(AND(ISNUMBER(Plants!N6),N(Plants!H6)>0,(TODAY()+0)>=MAX(Plants!N6,TODAY()),MOD((TODAY()+0)-MAX(Plants!N6,TODAY()),MAX(1,N(Plants!H6)))=0),"Feed","")) | E6: =IF(AND(ISNUMBER(Plants!L6),N(Plants!S6)>0,(TODAY()+1)>=MAX(Plants!L6,TODAY()),MOD((TODAY()+1)-MAX(Plants!L6,TODAY()),MAX(1,N(Plants!S6)))=0),IF(AND(ISNUMBER(Plants!N6),N(Plants!H6)>0,(TODAY()+1)>=MAX(Plants!N6,TODAY()),MOD((TODAY()+1)-MAX(Plants!N6,TODAY()),MAX(1,N(Plants!H6)))=0),"Water, feed","Water"),IF(AND(ISNUMBER(Plants!N6),N(Plants!H6)>0,(TODAY()+1)>=MAX(Plants!N6,TODAY()),MOD((TODAY()+1)-MAX(Plants!N6,TODAY()),MAX(1,N(Plants!H6)))=0),"Feed","")) | F6: =IF(AND(ISNUMBER(Plants!L6),N(Plants!S6)>0,(TODAY()+2)>=MAX(Plants!L6,TODAY()),MOD((TODAY()+2)-MAX(Plants!L6,TODAY()),MAX(1,N(Plants!S6)))=0),IF(AND(ISNUMBER(Plants!N6),N(Plants!H6)>0,(TODAY()+2)>=MAX(Plants!N6,TODAY()),MOD((TODAY()+2)-MAX(Plants!N6,TODAY()),MAX(1,N(Plants!H6)))=0),"Water, feed","Water"),IF(AND(ISNUMBER(Plants!N6),N(Plants!H6)>0,(TODAY()+2)>=MAX(Plants!N6,TODAY()),MOD((TODAY()+2)-MAX(Plants!N6,TODAY()),MAX(1,N(Plants!H6)))=0),"Feed","")) | G6: =IF(AND(ISNUMBER(Plants!L6),N(Plants!S6)>0,(TODAY()+3)>=MAX(Plants!L6,TODAY()),MOD((TODAY()+3)-MAX(Plants!L6,TODAY()),MAX(1,N(Plants!S6)))=0),IF(AND(ISNUMBER(Plants!N6),N(Plants!H6)>0,(TODAY()+3)>=MAX(Plants!N6,TODAY()),MOD((TODAY()+3)-MAX(Plants!N6,TODAY()),MAX(1,N(Plants!H6)))=0),"Water, feed","Water"),IF(AND(ISNUMBER(Plants!N6),N(Plants!H6)>0,(TODAY()+3)>=MAX(Plants!N6,TODAY()),MOD((TODAY()+3)-MAX(Plants!N6,TODAY()),MAX(1,N(Plants!H6)))=0),"Feed","")) | H6: =IF(AND(ISNUMBER(Plants!L6),N(Plants!S6)>0,(TODAY()+4)>=MAX(Plants!L6,TODAY()),MOD((TODAY()+4)-MAX(Plants!L6,TODAY()),MAX(1,N(Plants!S6)))=0),IF(AND(ISNUMBER(Plants!N6),N(Plants!H6)>0,(TODAY()+4)>=MAX(Plants!N6,TODAY()),MOD((TODAY()+4)-MAX(Plants!N6,TODAY()),MAX(1,N(Plants!H6)))=0),"Water, feed","Water"),IF(AND(ISNUMBER(Plants!N6),N(Plants!H6)>0,(TODAY()+4)>=MAX(Plants!N6,TODAY()),MOD((TODAY()+4)-MAX(Plants!N6,TODAY()),MAX(1,N(Plants!H6)))=0),"Feed","")) | I6: =IF(AND(ISNUMBER(Plants!L6),N(Plants!S6)>0,(TODAY()+5)>=MAX(Plants!L6,TODAY()),MOD((TODAY()+5)-MAX(Plants!L6,TODAY()),MAX(1,N(Plants!S6)))=0),IF(AND(ISNUMBER(Plants!N6),N(Plants!H6)>0,(TODAY()+5)>=MAX(Plants!N6,TODAY()),MOD((TODAY()+5)-MAX(Plants!N6,TODAY()),MAX(1,N(Plants!H6)))=0),"Water, feed","Water"),IF(AND(ISNUMBER(Plants!N6),N(Plants!H6)>0,(TODAY()+5)>=MAX(Plants!N6,TODAY()),MOD((TODAY()+5)-MAX(Plants!N6,TODAY()),MAX(1,N(Plants!H6)))=0),"Feed","")) | J6: =IF(AND(ISNUMBER(Plants!L6),N(Plants!S6)>0,(TODAY()+6)>=MAX(Plants!L6,TODAY()),MOD((TODAY()+6)-MAX(Plants!L6,TODAY()),MAX(1,N(Plants!S6)))=0),IF(AND(ISNUMBER(Plants!N6),N(Plants!H6)>0,(TODAY()+6)>=MAX(Plants!N6,TODAY()),MOD((TODAY()+6)-MAX(Plants!N6,TODAY()),MAX(1,N(Plants!H6)))=0),"Water, feed","Water"),IF(AND(ISNUMBER(Plants!N6),N(Plants!H6)>0,(TODAY()+6)>=MAX(Plants!N6,TODAY()),MOD((TODAY()+6)-MAX(Plants!N6,TODAY()),MAX(1,N(Plants!H6)))=0),"Feed",""))
B7: =IF(Plants!B7="","",Plants!B7) | C7: =IF(Plants!B7="","",Plants!D7) | D7: =IF(AND(ISNUMBER(Plants!L7),N(Plants!S7)>0,(TODAY()+0)>=MAX(Plants!L7,TODAY()),MOD((TODAY()+0)-MAX(Plants!L7,TODAY()),MAX(1,N(Plants!S7)))=0),IF(AND(ISNUMBER(Plants!N7),N(Plants!H7)>0,(TODAY()+0)>=MAX(Plants!N7,TODAY()),MOD((TODAY()+0)-MAX(Plants!N7,TODAY()),MAX(1,N(Plants!H7)))=0),"Water, feed","Water"),IF(AND(ISNUMBER(Plants!N7),N(Plants!H7)>0,(TODAY()+0)>=MAX(Plants!N7,TODAY()),MOD((TODAY()+0)-MAX(Plants!N7,TODAY()),MAX(1,N(Plants!H7)))=0),"Feed","")) | E7: =IF(AND(ISNUMBER(Plants!L7),N(Plants!S7)>0,(TODAY()+1)>=MAX(Plants!L7,TODAY()),MOD((TODAY()+1)-MAX(Plants!L7,TODAY()),MAX(1,N(Plants!S7)))=0),IF(AND(ISNUMBER(Plants!N7),N(Plants!H7)>0,(TODAY()+1)>=MAX(Plants!N7,TODAY()),MOD((TODAY()+1)-MAX(Plants!N7,TODAY()),MAX(1,N(Plants!H7)))=0),"Water, feed","Water"),IF(AND(ISNUMBER(Plants!N7),N(Plants!H7)>0,(TODAY()+1)>=MAX(Plants!N7,TODAY()),MOD((TODAY()+1)-MAX(Plants!N7,TODAY()),MAX(1,N(Plants!H7)))=0),"Feed","")) | F7: =IF(AND(ISNUMBER(Plants!L7),N(Plants!S7)>0,(TODAY()+2)>=MAX(Plants!L7,TODAY()),MOD((TODAY()+2)-MAX(Plants!L7,TODAY()),MAX(1,N(Plants!S7)))=0),IF(AND(ISNUMBER(Plants!N7),N(Plants!H7)>0,(TODAY()+2)>=MAX(Plants!N7,TODAY()),MOD((TODAY()+2)-MAX(Plants!N7,TODAY()),MAX(1,N(Plants!H7)))=0),"Water, feed","Water"),IF(AND(ISNUMBER(Plants!N7),N(Plants!H7)>0,(TODAY()+2)>=MAX(Plants!N7,TODAY()),MOD((TODAY()+2)-MAX(Plants!N7,TODAY()),MAX(1,N(Plants!H7)))=0),"Feed","")) | G7: =IF(AND(ISNUMBER(Plants!L7),N(Plants!S7)>0,(TODAY()+3)>=MAX(Plants!L7,TODAY()),MOD((TODAY()+3)-MAX(Plants!L7,TODAY()),MAX(1,N(Plants!S7)))=0),IF(AND(ISNUMBER(Plants!N7),N(Plants!H7)>0,(TODAY()+3)>=MAX(Plants!N7,TODAY()),MOD((TODAY()+3)-MAX(Plants!N7,TODAY()),MAX(1,N(Plants!H7)))=0),"Water, feed","Water"),IF(AND(ISNUMBER(Plants!N7),N(Plants!H7)>0,(TODAY()+3)>=MAX(Plants!N7,TODAY()),MOD((TODAY()+3)-MAX(Plants!N7,TODAY()),MAX(1,N(Plants!H7)))=0),"Feed","")) | H7: =IF(AND(ISNUMBER(Plants!L7),N(Plants!S7)>0,(TODAY()+4)>=MAX(Plants!L7,TODAY()),MOD((TODAY()+4)-MAX(Plants!L7,TODAY()),MAX(1,N(Plants!S7)))=0),IF(AND(ISNUMBER(Plants!N7),N(Plants!H7)>0,(TODAY()+4)>=MAX(Plants!N7,TODAY()),MOD((TODAY()+4)-MAX(Plants!N7,TODAY()),MAX(1,N(Plants!H7)))=0),"Water, feed","Water"),IF(AND(ISNUMBER(Plants!N7),N(Plants!H7)>0,(TODAY()+4)>=MAX(Plants!N7,TODAY()),MOD((TODAY()+4)-MAX(Plants!N7,TODAY()),MAX(1,N(Plants!H7)))=0),"Feed","")) | I7: =IF(AND(ISNUMBER(Plants!L7),N(Plants!S7)>0,(TODAY()+5)>=MAX(Plants!L7,TODAY()),MOD((TODAY()+5)-MAX(Plants!L7,TODAY()),MAX(1,N(Plants!S7)))=0),IF(AND(ISNUMBER(Plants!N7),N(Plants!H7)>0,(TODAY()+5)>=MAX(Plants!N7,TODAY()),MOD((TODAY()+5)-MAX(Plants!N7,TODAY()),MAX(1,N(Plants!H7)))=0),"Water, feed","Water"),IF(AND(ISNUMBER(Plants!N7),N(Plants!H7)>0,(TODAY()+5)>=MAX(Plants!N7,TODAY()),MOD((TODAY()+5)-MAX(Plants!N7,TODAY()),MAX(1,N(Plants!H7)))=0),"Feed","")) | J7: =IF(AND(ISNUMBER(Plants!L7),N(Plants!S7)>0,(TODAY()+6)>=MAX(Plants!L7,TODAY()),MOD((TODAY()+6)-MAX(Plants!L7,TODAY()),MAX(1,N(Plants!S7)))=0),IF(AND(ISNUMBER(Plants!N7),N(Plants!H7)>0,(TODAY()+6)>=MAX(Plants!N7,TODAY()),MOD((TODAY()+6)-MAX(Plants!N7,TODAY()),MAX(1,N(Plants!H7)))=0),"Water, feed","Water"),IF(AND(ISNUMBER(Plants!N7),N(Plants!H7)>0,(TODAY()+6)>=MAX(Plants!N7,TODAY()),MOD((TODAY()+6)-MAX(Plants!N7,TODAY()),MAX(1,N(Plants!H7)))=0),"Feed",""))
B8: =IF(Plants!B8="","",Plants!B8) | C8: =IF(Plants!B8="","",Plants!D8) | D8: =IF(AND(ISNUMBER(Plants!L8),N(Plants!S8)>0,(TODAY()+0)>=MAX(Plants!L8,TODAY()),MOD((TODAY()+0)-MAX(Plants!L8,TODAY()),MAX(1,N(Plants!S8)))=0),IF(AND(ISNUMBER(Plants!N8),N(Plants!H8)>0,(TODAY()+0)>=MAX(Plants!N8,TODAY()),MOD((TODAY()+0)-MAX(Plants!N8,TODAY()),MAX(1,N(Plants!H8)))=0),"Water, feed","Water"),IF(AND(ISNUMBER(Plants!N8),N(Plants!H8)>0,(TODAY()+0)>=MAX(Plants!N8,TODAY()),MOD((TODAY()+0)-MAX(Plants!N8,TODAY()),MAX(1,N(Plants!H8)))=0),"Feed","")) | E8: =IF(AND(ISNUMBER(Plants!L8),N(Plants!S8)>0,(TODAY()+1)>=MAX(Plants!L8,TODAY()),MOD((TODAY()+1)-MAX(Plants!L8,TODAY()),MAX(1,N(Plants!S8)))=0),IF(AND(ISNUMBER(Plants!N8),N(Plants!H8)>0,(TODAY()+1)>=MAX(Plants!N8,TODAY()),MOD((TODAY()+1)-MAX(Plants!N8,TODAY()),MAX(1,N(Plants!H8)))=0),"Water, feed","Water"),IF(AND(ISNUMBER(Plants!N8),N(Plants!H8)>0,(TODAY()+1)>=MAX(Plants!N8,TODAY()),MOD((TODAY()+1)-MAX(Plants!N8,TODAY()),MAX(1,N(Plants!H8)))=0),"Feed","")) | F8: =IF(AND(ISNUMBER(Plants!L8),N(Plants!S8)>0,(TODAY()+2)>=MAX(Plants!L8,TODAY()),MOD((TODAY()+2)-MAX(Plants!L8,TODAY()),MAX(1,N(Plants!S8)))=0),IF(AND(ISNUMBER(Plants!N8),N(Plants!H8)>0,(TODAY()+2)>=MAX(Plants!N8,TODAY()),MOD((TODAY()+2)-MAX(Plants!N8,TODAY()),MAX(1,N(Plants!H8)))=0),"Water, feed","Water"),IF(AND(ISNUMBER(Plants!N8),N(Plants!H8)>0,(TODAY()+2)>=MAX(Plants!N8,TODAY()),MOD((TODAY()+2)-MAX(Plants!N8,TODAY()),MAX(1,N(Plants!H8)))=0),"Feed","")) | G8: =IF(AND(ISNUMBER(Plants!L8),N(Plants!S8)>0,(TODAY()+3)>=MAX(Plants!L8,TODAY()),MOD((TODAY()+3)-MAX(Plants!L8,TODAY()),MAX(1,N(Plants!S8)))=0),IF(AND(ISNUMBER(Plants!N8),N(Plants!H8)>0,(TODAY()+3)>=MAX(Plants!N8,TODAY()),MOD((TODAY()+3)-MAX(Plants!N8,TODAY()),MAX(1,N(Plants!H8)))=0),"Water, feed","Water"),IF(AND(ISNUMBER(Plants!N8),N(Plants!H8)>0,(TODAY()+3)>=MAX(Plants!N8,TODAY()),MOD((TODAY()+3)-MAX(Plants!N8,TODAY()),MAX(1,N(Plants!H8)))=0),"Feed","")) | H8: =IF(AND(ISNUMBER(Plants!L8),N(Plants!S8)>0,(TODAY()+4)>=MAX(Plants!L8,TODAY()),MOD((TODAY()+4)-MAX(Plants!L8,TODAY()),MAX(1,N(Plants!S8)))=0),IF(AND(ISNUMBER(Plants!N8),N(Plants!H8)>0,(TODAY()+4)>=MAX(Plants!N8,TODAY()),MOD((TODAY()+4)-MAX(Plants!N8,TODAY()),MAX(1,N(Plants!H8)))=0),"Water, feed","Water"),IF(AND(ISNUMBER(Plants!N8),N(Plants!H8)>0,(TODAY()+4)>=MAX(Plants!N8,TODAY()),MOD((TODAY()+4)-MAX(Plants!N8,TODAY()),MAX(1,N(Plants!H8)))=0),"Feed","")) | I8: =IF(AND(ISNUMBER(Plants!L8),N(Plants!S8)>0,(TODAY()+5)>=MAX(Plants!L8,TODAY()),MOD((TODAY()+5)-MAX(Plants!L8,TODAY()),MAX(1,N(Plants!S8)))=0),IF(AND(ISNUMBER(Plants!N8),N(Plants!H8)>0,(TODAY()+5)>=MAX(Plants!N8,TODAY()),MOD((TODAY()+5)-MAX(Plants!N8,TODAY()),MAX(1,N(Plants!H8)))=0),"Water, feed","Water"),IF(AND(ISNUMBER(Plants!N8),N(Plants!H8)>0,(TODAY()+5)>=MAX(Plants!N8,TODAY()),MOD((TODAY()+5)-MAX(Plants!N8,TODAY()),MAX(1,N(Plants!H8)))=0),"Feed","")) | J8: =IF(AND(ISNUMBER(Plants!L8),N(Plants!S8)>0,(TODAY()+6)>=MAX(Plants!L8,TODAY()),MOD((TODAY()+6)-MAX(Plants!L8,TODAY()),MAX(1,N(Plants!S8)))=0),IF(AND(ISNUMBER(Plants!N8),N(Plants!H8)>0,(TODAY()+6)>=MAX(Plants!N8,TODAY()),MOD((TODAY()+6)-MAX(Plants!N8,TODAY()),MAX(1,N(Plants!H8)))=0),"Water, feed","Water"),IF(AND(ISNUMBER(Plants!N8),N(Plants!H8)>0,(TODAY()+6)>=MAX(Plants!N8,TODAY()),MOD((TODAY()+6)-MAX(Plants!N8,TODAY()),MAX(1,N(Plants!H8)))=0),"Feed",""))
B9: =IF(Plants!B9="","",Plants!B9) | C9: =IF(Plants!B9="","",Plants!D9) | D9: =IF(AND(ISNUMBER(Plants!L9),N(Plants!S9)>0,(TODAY()+0)>=MAX(Plants!L9,TODAY()),MOD((TODAY()+0)-MAX(Plants!L9,TODAY()),MAX(1,N(Plants!S9)))=0),IF(AND(ISNUMBER(Plants!N9),N(Plants!H9)>0,(TODAY()+0)>=MAX(Plants!N9,TODAY()),MOD((TODAY()+0)-MAX(Plants!N9,TODAY()),MAX(1,N(Plants!H9)))=0),"Water, feed","Water"),IF(AND(ISNUMBER(Plants!N9),N(Plants!H9)>0,(TODAY()+0)>=MAX(Plants!N9,TODAY()),MOD((TODAY()+0)-MAX(Plants!N9,TODAY()),MAX(1,N(Plants!H9)))=0),"Feed","")) | E9: =IF(AND(ISNUMBER(Plants!L9),N(Plants!S9)>0,(TODAY()+1)>=MAX(Plants!L9,TODAY()),MOD((TODAY()+1)-MAX(Plants!L9,TODAY()),MAX(1,N(Plants!S9)))=0),IF(AND(ISNUMBER(Plants!N9),N(Plants!H9)>0,(TODAY()+1)>=MAX(Plants!N9,TODAY()),MOD((TODAY()+1)-MAX(Plants!N9,TODAY()),MAX(1,N(Plants!H9)))=0),"Water, feed","Water"),IF(AND(ISNUMBER(Plants!N9),N(Plants!H9)>0,(TODAY()+1)>=MAX(Plants!N9,TODAY()),MOD((TODAY()+1)-MAX(Plants!N9,TODAY()),MAX(1,N(Plants!H9)))=0),"Feed","")) | F9: =IF(AND(ISNUMBER(Plants!L9),N(Plants!S9)>0,(TODAY()+2)>=MAX(Plants!L9,TODAY()),MOD((TODAY()+2)-MAX(Plants!L9,TODAY()),MAX(1,N(Plants!S9)))=0),IF(AND(ISNUMBER(Plants!N9),N(Plants!H9)>0,(TODAY()+2)>=MAX(Plants!N9,TODAY()),MOD((TODAY()+2)-MAX(Plants!N9,TODAY()),MAX(1,N(Plants!H9)))=0),"Water, feed","Water"),IF(AND(ISNUMBER(Plants!N9),N(Plants!H9)>0,(TODAY()+2)>=MAX(Plants!N9,TODAY()),MOD((TODAY()+2)-MAX(Plants!N9,TODAY()),MAX(1,N(Plants!H9)))=0),"Feed","")) | G9: =IF(AND(ISNUMBER(Plants!L9),N(Plants!S9)>0,(TODAY()+3)>=MAX(Plants!L9,TODAY()),MOD((TODAY()+3)-MAX(Plants!L9,TODAY()),MAX(1,N(Plants!S9)))=0),IF(AND(ISNUMBER(Plants!N9),N(Plants!H9)>0,(TODAY()+3)>=MAX(Plants!N9,TODAY()),MOD((TODAY()+3)-MAX(Plants!N9,TODAY()),MAX(1,N(Plants!H9)))=0),"Water, feed","Water"),IF(AND(ISNUMBER(Plants!N9),N(Plants!H9)>0,(TODAY()+3)>=MAX(Plants!N9,TODAY()),MOD((TODAY()+3)-MAX(Plants!N9,TODAY()),MAX(1,N(Plants!H9)))=0),"Feed","")) | H9: =IF(AND(ISNUMBER(Plants!L9),N(Plants!S9)>0,(TODAY()+4)>=MAX(Plants!L9,TODAY()),MOD((TODAY()+4)-MAX(Plants!L9,TODAY()),MAX(1,N(Plants!S9)))=0),IF(AND(ISNUMBER(Plants!N9),N(Plants!H9)>0,(TODAY()+4)>=MAX(Plants!N9,TODAY()),MOD((TODAY()+4)-MAX(Plants!N9,TODAY()),MAX(1,N(Plants!H9)))=0),"Water, feed","Water"),IF(AND(ISNUMBER(Plants!N9),N(Plants!H9)>0,(TODAY()+4)>=MAX(Plants!N9,TODAY()),MOD((TODAY()+4)-MAX(Plants!N9,TODAY()),MAX(1,N(Plants!H9)))=0),"Feed","")) | I9: =IF(AND(ISNUMBER(Plants!L9),N(Plants!S9)>0,(TODAY()+5)>=MAX(Plants!L9,TODAY()),MOD((TODAY()+5)-MAX(Plants!L9,TODAY()),MAX(1,N(Plants!S9)))=0),IF(AND(ISNUMBER(Plants!N9),N(Plants!H9)>0,(TODAY()+5)>=MAX(Plants!N9,TODAY()),MOD((TODAY()+5)-MAX(Plants!N9,TODAY()),MAX(1,N(Plants!H9)))=0),"Water, feed","Water"),IF(AND(ISNUMBER(Plants!N9),N(Plants!H9)>0,(TODAY()+5)>=MAX(Plants!N9,TODAY()),MOD((TODAY()+5)-MAX(Plants!N9,TODAY()),MAX(1,N(Plants!H9)))=0),"Feed","")) | J9: =IF(AND(ISNUMBER(Plants!L9),N(Plants!S9)>0,(TODAY()+6)>=MAX(Plants!L9,TODAY()),MOD((TODAY()+6)-MAX(Plants!L9,TODAY()),MAX(1,N(Plants!S9)))=0),IF(AND(ISNUMBER(Plants!N9),N(Plants!H9)>0,(TODAY()+6)>=MAX(Plants!N9,TODAY()),MOD((TODAY()+6)-MAX(Plants!N9,TODAY()),MAX(1,N(Plants!H9)))=0),"Water, feed","Water"),IF(AND(ISNUMBER(Plants!N9),N(Plants!H9)>0,(TODAY()+6)>=MAX(Plants!N9,TODAY()),MOD((TODAY()+6)-MAX(Plants!N9,TODAY()),MAX(1,N(Plants!H9)))=0),"Feed",""))
B10: =IF(Plants!B10="","",Plants!B10) | C10: =IF(Plants!B10="","",Plants!D10) | D10: =IF(AND(ISNUMBER(Plants!L10),N(Plants!S10)>0,(TODAY()+0)>=MAX(Plants!L10,TODAY()),MOD((TODAY()+0)-MAX(Plants!L10,TODAY()),MAX(1,N(Plants!S10)))=0),IF(AND(ISNUMBER(Plants!N10),N(Plants!H10)>0,(TODAY()+0)>=MAX(Plants!N10,TODAY()),MOD((TODAY()+0)-MAX(Plants!N10,TODAY()),MAX(1,N(Plants!H10)))=0),"Water, feed","Water"),IF(AND(ISNUMBER(Plants!N10),N(Plants!H10)>0,(TODAY()+0)>=MAX(Plants!N10,TODAY()),MOD((TODAY()+0)-MAX(Plants!N10,TODAY()),MAX(1,N(Plants!H10)))=0),"Feed","")) | E10: =IF(AND(ISNUMBER(Plants!L10),N(Plants!S10)>0,(TODAY()+1)>=MAX(Plants!L10,TODAY()),MOD((TODAY()+1)-MAX(Plants!L10,TODAY()),MAX(1,N(Plants!S10)))=0),IF(AND(ISNUMBER(Plants!N10),N(Plants!H10)>0,(TODAY()+1)>=MAX(Plants!N10,TODAY()),MOD((TODAY()+1)-MAX(Plants!N10,TODAY()),MAX(1,N(Plants!H10)))=0),"Water, feed","Water"),IF(AND(ISNUMBER(Plants!N10),N(Plants!H10)>0,(TODAY()+1)>=MAX(Plants!N10,TODAY()),MOD((TODAY()+1)-MAX(Plants!N10,TODAY()),MAX(1,N(Plants!H10)))=0),"Feed","")) | F10: =IF(AND(ISNUMBER(Plants!L10),N(Plants!S10)>0,(TODAY()+2)>=MAX(Plants!L10,TODAY()),MOD((TODAY()+2)-MAX(Plants!L10,TODAY()),MAX(1,N(Plants!S10)))=0),IF(AND(ISNUMBER(Plants!N10),N(Plants!H10)>0,(TODAY()+2)>=MAX(Plants!N10,TODAY()),MOD((TODAY()+2)-MAX(Plants!N10,TODAY()),MAX(1,N(Plants!H10)))=0),"Water, feed","Water"),IF(AND(ISNUMBER(Plants!N10),N(Plants!H10)>0,(TODAY()+2)>=MAX(Plants!N10,TODAY()),MOD((TODAY()+2)-MAX(Plants!N10,TODAY()),MAX(1,N(Plants!H10)))=0),"Feed","")) | G10: =IF(AND(ISNUMBER(Plants!L10),N(Plants!S10)>0,(TODAY()+3)>=MAX(Plants!L10,TODAY()),MOD((TODAY()+3)-MAX(Plants!L10,TODAY()),MAX(1,N(Plants!S10)))=0),IF(AND(ISNUMBER(Plants!N10),N(Plants!H10)>0,(TODAY()+3)>=MAX(Plants!N10,TODAY()),MOD((TODAY()+3)-MAX(Plants!N10,TODAY()),MAX(1,N(Plants!H10)))=0),"Water, feed","Water"),IF(AND(ISNUMBER(Plants!N10),N(Plants!H10)>0,(TODAY()+3)>=MAX(Plants!N10,TODAY()),MOD((TODAY()+3)-MAX(Plants!N10,TODAY()),MAX(1,N(Plants!H10)))=0),"Feed","")) | H10: =IF(AND(ISNUMBER(Plants!L10),N(Plants!S10)>0,(TODAY()+4)>=MAX(Plants!L10,TODAY()),MOD((TODAY()+4)-MAX(Plants!L10,TODAY()),MAX(1,N(Plants!S10)))=0),IF(AND(ISNUMBER(Plants!N10),N(Plants!H10)>0,(TODAY()+4)>=MAX(Plants!N10,TODAY()),MOD((TODAY()+4)-MAX(Plants!N10,TODAY()),MAX(1,N(Plants!H10)))=0),"Water, feed","Water"),IF(AND(ISNUMBER(Plants!N10),N(Plants!H10)>0,(TODAY()+4)>=MAX(Plants!N10,TODAY()),MOD((TODAY()+4)-MAX(Plants!N10,TODAY()),MAX(1,N(Plants!H10)))=0),"Feed","")) | I10: =IF(AND(ISNUMBER(Plants!L10),N(Plants!S10)>0,(TODAY()+5)>=MAX(Plants!L10,TODAY()),MOD((TODAY()+5)-MAX(Plants!L10,TODAY()),MAX(1,N(Plants!S10)))=0),IF(AND(ISNUMBER(Plants!N10),N(Plants!H10)>0,(TODAY()+5)>=MAX(Plants!N10,TODAY()),MOD((TODAY()+5)-MAX(Plants!N10,TODAY()),MAX(1,N(Plants!H10)))=0),"Water, feed","Water"),IF(AND(ISNUMBER(Plants!N10),N(Plants!H10)>0,(TODAY()+5)>=MAX(Plants!N10,TODAY()),MOD((TODAY()+5)-MAX(Plants!N10,TODAY()),MAX(1,N(Plants!H10)))=0),"Feed","")) | J10: =IF(AND(ISNUMBER(Plants!L10),N(Plants!S10)>0,(TODAY()+6)>=MAX(Plants!L10,TODAY()),MOD((TODAY()+6)-MAX(Plants!L10,TODAY()),MAX(1,N(Plants!S10)))=0),IF(AND(ISNUMBER(Plants!N10),N(Plants!H10)>0,(TODAY()+6)>=MAX(Plants!N10,TODAY()),MOD((TODAY()+6)-MAX(Plants!N10,TODAY()),MAX(1,N(Plants!H10)))=0),"Water, feed","Water"),IF(AND(ISNUMBER(Plants!N10),N(Plants!H10)>0,(TODAY()+6)>=MAX(Plants!N10,TODAY()),MOD((TODAY()+6)-MAX(Plants!N10,TODAY()),MAX(1,N(Plants!H10)))=0),"Feed",""))
B11: =IF(Plants!B11="","",Plants!B11) | C11: =IF(Plants!B11="","",Plants!D11) | D11: =IF(AND(ISNUMBER(Plants!L11),N(Plants!S11)>0,(TODAY()+0)>=MAX(Plants!L11,TODAY()),MOD((TODAY()+0)-MAX(Plants!L11,TODAY()),MAX(1,N(Plants!S11)))=0),IF(AND(ISNUMBER(Plants!N11),N(Plants!H11)>0,(TODAY()+0)>=MAX(Plants!N11,TODAY()),MOD((TODAY()+0)-MAX(Plants!N11,TODAY()),MAX(1,N(Plants!H11)))=0),"Water, feed","Water"),IF(AND(ISNUMBER(Plants!N11),N(Plants!H11)>0,(TODAY()+0)>=MAX(Plants!N11,TODAY()),MOD((TODAY()+0)-MAX(Plants!N11,TODAY()),MAX(1,N(Plants!H11)))=0),"Feed","")) | E11: =IF(AND(ISNUMBER(Plants!L11),N(Plants!S11)>0,(TODAY()+1)>=MAX(Plants!L11,TODAY()),MOD((TODAY()+1)-MAX(Plants!L11,TODAY()),MAX(1,N(Plants!S11)))=0),IF(AND(ISNUMBER(Plants!N11),N(Plants!H11)>0,(TODAY()+1)>=MAX(Plants!N11,TODAY()),MOD((TODAY()+1)-MAX(Plants!N11,TODAY()),MAX(1,N(Plants!H11)))=0),"Water, feed","Water"),IF(AND(ISNUMBER(Plants!N11),N(Plants!H11)>0,(TODAY()+1)>=MAX(Plants!N11,TODAY()),MOD((TODAY()+1)-MAX(Plants!N11,TODAY()),MAX(1,N(Plants!H11)))=0),"Feed","")) | F11: =IF(AND(ISNUMBER(Plants!L11),N(Plants!S11)>0,(TODAY()+2)>=MAX(Plants!L11,TODAY()),MOD((TODAY()+2)-MAX(Plants!L11,TODAY()),MAX(1,N(Plants!S11)))=0),IF(AND(ISNUMBER(Plants!N11),N(Plants!H11)>0,(TODAY()+2)>=MAX(Plants!N11,TODAY()),MOD((TODAY()+2)-MAX(Plants!N11,TODAY()),MAX(1,N(Plants!H11)))=0),"Water, feed","Water"),IF(AND(ISNUMBER(Plants!N11),N(Plants!H11)>0,(TODAY()+2)>=MAX(Plants!N11,TODAY()),MOD((TODAY()+2)-MAX(Plants!N11,TODAY()),MAX(1,N(Plants!H11)))=0),"Feed","")) | G11: =IF(AND(ISNUMBER(Plants!L11),N(Plants!S11)>0,(TODAY()+3)>=MAX(Plants!L11,TODAY()),MOD((TODAY()+3)-MAX(Plants!L11,TODAY()),MAX(1,N(Plants!S11)))=0),IF(AND(ISNUMBER(Plants!N11),N(Plants!H11)>0,(TODAY()+3)>=MAX(Plants!N11,TODAY()),MOD((TODAY()+3)-MAX(Plants!N11,TODAY()),MAX(1,N(Plants!H11)))=0),"Water, feed","Water"),IF(AND(ISNUMBER(Plants!N11),N(Plants!H11)>0,(TODAY()+3)>=MAX(Plants!N11,TODAY()),MOD((TODAY()+3)-MAX(Plants!N11,TODAY()),MAX(1,N(Plants!H11)))=0),"Feed","")) | H11: =IF(AND(ISNUMBER(Plants!L11),N(Plants!S11)>0,(TODAY()+4)>=MAX(Plants!L11,TODAY()),MOD((TODAY()+4)-MAX(Plants!L11,TODAY()),MAX(1,N(Plants!S11)))=0),IF(AND(ISNUMBER(Plants!N11),N(Plants!H11)>0,(TODAY()+4)>=MAX(Plants!N11,TODAY()),MOD((TODAY()+4)-MAX(Plants!N11,TODAY()),MAX(1,N(Plants!H11)))=0),"Water, feed","Water"),IF(AND(ISNUMBER(Plants!N11),N(Plants!H11)>0,(TODAY()+4)>=MAX(Plants!N11,TODAY()),MOD((TODAY()+4)-MAX(Plants!N11,TODAY()),MAX(1,N(Plants!H11)))=0),"Feed","")) | I11: =IF(AND(ISNUMBER(Plants!L11),N(Plants!S11)>0,(TODAY()+5)>=MAX(Plants!L11,TODAY()),MOD((TODAY()+5)-MAX(Plants!L11,TODAY()),MAX(1,N(Plants!S11)))=0),IF(AND(ISNUMBER(Plants!N11),N(Plants!H11)>0,(TODAY()+5)>=MAX(Plants!N11,TODAY()),MOD((TODAY()+5)-MAX(Plants!N11,TODAY()),MAX(1,N(Plants!H11)))=0),"Water, feed","Water"),IF(AND(ISNUMBER(Plants!N11),N(Plants!H11)>0,(TODAY()+5)>=MAX(Plants!N11,TODAY()),MOD((TODAY()+5)-MAX(Plants!N11,TODAY()),MAX(1,N(Plants!H11)))=0),"Feed","")) | J11: =IF(AND(ISNUMBER(Plants!L11),N(Plants!S11)>0,(TODAY()+6)>=MAX(Plants!L11,TODAY()),MOD((TODAY()+6)-MAX(Plants!L11,TODAY()),MAX(1,N(Plants!S11)))=0),IF(AND(ISNUMBER(Plants!N11),N(Plants!H11)>0,(TODAY()+6)>=MAX(Plants!N11,TODAY()),MOD((TODAY()+6)-MAX(Plants!N11,TODAY()),MAX(1,N(Plants!H11)))=0),"Water, feed","Water"),IF(AND(ISNUMBER(Plants!N11),N(Plants!H11)>0,(TODAY()+6)>=MAX(Plants!N11,TODAY()),MOD((TODAY()+6)-MAX(Plants!N11,TODAY()),MAX(1,N(Plants!H11)))=0),"Feed",""))
B12: =IF(Plants!B12="","",Plants!B12) | C12: =IF(Plants!B12="","",Plants!D12) | D12: =IF(AND(ISNUMBER(Plants!L12),N(Plants!S12)>0,(TODAY()+0)>=MAX(Plants!L12,TODAY()),MOD((TODAY()+0)-MAX(Plants!L12,TODAY()),MAX(1,N(Plants!S12)))=0),IF(AND(ISNUMBER(Plants!N12),N(Plants!H12)>0,(TODAY()+0)>=MAX(Plants!N12,TODAY()),MOD((TODAY()+0)-MAX(Plants!N12,TODAY()),MAX(1,N(Plants!H12)))=0),"Water, feed","Water"),IF(AND(ISNUMBER(Plants!N12),N(Plants!H12)>0,(TODAY()+0)>=MAX(Plants!N12,TODAY()),MOD((TODAY()+0)-MAX(Plants!N12,TODAY()),MAX(1,N(Plants!H12)))=0),"Feed","")) | E12: =IF(AND(ISNUMBER(Plants!L12),N(Plants!S12)>0,(TODAY()+1)>=MAX(Plants!L12,TODAY()),MOD((TODAY()+1)-MAX(Plants!L12,TODAY()),MAX(1,N(Plants!S12)))=0),IF(AND(ISNUMBER(Plants!N12),N(Plants!H12)>0,(TODAY()+1)>=MAX(Plants!N12,TODAY()),MOD((TODAY()+1)-MAX(Plants!N12,TODAY()),MAX(1,N(Plants!H12)))=0),"Water, feed","Water"),IF(AND(ISNUMBER(Plants!N12),N(Plants!H12)>0,(TODAY()+1)>=MAX(Plants!N12,TODAY()),MOD((TODAY()+1)-MAX(Plants!N12,TODAY()),MAX(1,N(Plants!H12)))=0),"Feed","")) | F12: =IF(AND(ISNUMBER(Plants!L12),N(Plants!S12)>0,(TODAY()+2)>=MAX(Plants!L12,TODAY()),MOD((TODAY()+2)-MAX(Plants!L12,TODAY()),MAX(1,N(Plants!S12)))=0),IF(AND(ISNUMBER(Plants!N12),N(Plants!H12)>0,(TODAY()+2)>=MAX(Plants!N12,TODAY()),MOD((TODAY()+2)-MAX(Plants!N12,TODAY()),MAX(1,N(Plants!H12)))=0),"Water, feed","Water"),IF(AND(ISNUMBER(Plants!N12),N(Plants!H12)>0,(TODAY()+2)>=MAX(Plants!N12,TODAY()),MOD((TODAY()+2)-MAX(Plants!N12,TODAY()),MAX(1,N(Plants!H12)))=0),"Feed","")) | G12: =IF(AND(ISNUMBER(Plants!L12),N(Plants!S12)>0,(TODAY()+3)>=MAX(Plants!L12,TODAY()),MOD((TODAY()+3)-MAX(Plants!L12,TODAY()),MAX(1,N(Plants!S12)))=0),IF(AND(ISNUMBER(Plants!N12),N(Plants!H12)>0,(TODAY()+3)>=MAX(Plants!N12,TODAY()),MOD((TODAY()+3)-MAX(Plants!N12,TODAY()),MAX(1,N(Plants!H12)))=0),"Water, feed","Water"),IF(AND(ISNUMBER(Plants!N12),N(Plants!H12)>0,(TODAY()+3)>=MAX(Plants!N12,TODAY()),MOD((TODAY()+3)-MAX(Plants!N12,TODAY()),MAX(1,N(Plants!H12)))=0),"Feed","")) | H12: =IF(AND(ISNUMBER(Plants!L12),N(Plants!S12)>0,(TODAY()+4)>=MAX(Plants!L12,TODAY()),MOD((TODAY()+4)-MAX(Plants!L12,TODAY()),MAX(1,N(Plants!S12)))=0),IF(AND(ISNUMBER(Plants!N12),N(Plants!H12)>0,(TODAY()+4)>=MAX(Plants!N12,TODAY()),MOD((TODAY()+4)-MAX(Plants!N12,TODAY()),MAX(1,N(Plants!H12)))=0),"Water, feed","Water"),IF(AND(ISNUMBER(Plants!N12),N(Plants!H12)>0,(TODAY()+4)>=MAX(Plants!N12,TODAY()),MOD((TODAY()+4)-MAX(Plants!N12,TODAY()),MAX(1,N(Plants!H12)))=0),"Feed","")) | I12: =IF(AND(ISNUMBER(Plants!L12),N(Plants!S12)>0,(TODAY()+5)>=MAX(Plants!L12,TODAY()),MOD((TODAY()+5)-MAX(Plants!L12,TODAY()),MAX(1,N(Plants!S12)))=0),IF(AND(ISNUMBER(Plants!N12),N(Plants!H12)>0,(TODAY()+5)>=MAX(Plants!N12,TODAY()),MOD((TODAY()+5)-MAX(Plants!N12,TODAY()),MAX(1,N(Plants!H12)))=0),"Water, feed","Water"),IF(AND(ISNUMBER(Plants!N12),N(Plants!H12)>0,(TODAY()+5)>=MAX(Plants!N12,TODAY()),MOD((TODAY()+5)-MAX(Plants!N12,TODAY()),MAX(1,N(Plants!H12)))=0),"Feed","")) | J12: =IF(AND(ISNUMBER(Plants!L12),N(Plants!S12)>0,(TODAY()+6)>=MAX(Plants!L12,TODAY()),MOD((TODAY()+6)-MAX(Plants!L12,TODAY()),MAX(1,N(Plants!S12)))=0),IF(AND(ISNUMBER(Plants!N12),N(Plants!H12)>0,(TODAY()+6)>=MAX(Plants!N12,TODAY()),MOD((TODAY()+6)-MAX(Plants!N12,TODAY()),MAX(1,N(Plants!H12)))=0),"Water, feed","Water"),IF(AND(ISNUMBER(Plants!N12),N(Plants!H12)>0,(TODAY()+6)>=MAX(Plants!N12,TODAY()),MOD((TODAY()+6)-MAX(Plants!N12,TODAY()),MAX(1,N(Plants!H12)))=0),"Feed",""))
B13: =IF(Plants!B13="","",Plants!B13) | C13: =IF(Plants!B13="","",Plants!D13) | D13: =IF(AND(ISNUMBER(Plants!L13),N(Plants!S13)>0,(TODAY()+0)>=MAX(Plants!L13,TODAY()),MOD((TODAY()+0)-MAX(Plants!L13,TODAY()),MAX(1,N(Plants!S13)))=0),IF(AND(ISNUMBER(Plants!N13),N(Plants!H13)>0,(TODAY()+0)>=MAX(Plants!N13,TODAY()),MOD((TODAY()+0)-MAX(Plants!N13,TODAY()),MAX(1,N(Plants!H13)))=0),"Water, feed","Water"),IF(AND(ISNUMBER(Plants!N13),N(Plants!H13)>0,(TODAY()+0)>=MAX(Plants!N13,TODAY()),MOD((TODAY()+0)-MAX(Plants!N13,TODAY()),MAX(1,N(Plants!H13)))=0),"Feed","")) | E13: =IF(AND(ISNUMBER(Plants!L13),N(Plants!S13)>0,(TODAY()+1)>=MAX(Plants!L13,TODAY()),MOD((TODAY()+1)-MAX(Plants!L13,TODAY()),MAX(1,N(Plants!S13)))=0),IF(AND(ISNUMBER(Plants!N13),N(Plants!H13)>0,(TODAY()+1)>=MAX(Plants!N13,TODAY()),MOD((TODAY()+1)-MAX(Plants!N13,TODAY()),MAX(1,N(Plants!H13)))=0),"Water, feed","Water"),IF(AND(ISNUMBER(Plants!N13),N(Plants!H13)>0,(TODAY()+1)>=MAX(Plants!N13,TODAY()),MOD((TODAY()+1)-MAX(Plants!N13,TODAY()),MAX(1,N(Plants!H13)))=0),"Feed","")) | F13: =IF(AND(ISNUMBER(Plants!L13),N(Plants!S13)>0,(TODAY()+2)>=MAX(Plants!L13,TODAY()),MOD((TODAY()+2)-MAX(Plants!L13,TODAY()),MAX(1,N(Plants!S13)))=0),IF(AND(ISNUMBER(Plants!N13),N(Plants!H13)>0,(TODAY()+2)>=MAX(Plants!N13,TODAY()),MOD((TODAY()+2)-MAX(Plants!N13,TODAY()),MAX(1,N(Plants!H13)))=0),"Water, feed","Water"),IF(AND(ISNUMBER(Plants!N13),N(Plants!H13)>0,(TODAY()+2)>=MAX(Plants!N13,TODAY()),MOD((TODAY()+2)-MAX(Plants!N13,TODAY()),MAX(1,N(Plants!H13)))=0),"Feed","")) | G13: =IF(AND(ISNUMBER(Plants!L13),N(Plants!S13)>0,(TODAY()+3)>=MAX(Plants!L13,TODAY()),MOD((TODAY()+3)-MAX(Plants!L13,TODAY()),MAX(1,N(Plants!S13)))=0),IF(AND(ISNUMBER(Plants!N13),N(Plants!H13)>0,(TODAY()+3)>=MAX(Plants!N13,TODAY()),MOD((TODAY()+3)-MAX(Plants!N13,TODAY()),MAX(1,N(Plants!H13)))=0),"Water, feed","Water"),IF(AND(ISNUMBER(Plants!N13),N(Plants!H13)>0,(TODAY()+3)>=MAX(Plants!N13,TODAY()),MOD((TODAY()+3)-MAX(Plants!N13,TODAY()),MAX(1,N(Plants!H13)))=0),"Feed","")) | H13: =IF(AND(ISNUMBER(Plants!L13),N(Plants!S13)>0,(TODAY()+4)>=MAX(Plants!L13,TODAY()),MOD((TODAY()+4)-MAX(Plants!L13,TODAY()),MAX(1,N(Plants!S13)))=0),IF(AND(ISNUMBER(Plants!N13),N(Plants!H13)>0,(TODAY()+4)>=MAX(Plants!N13,TODAY()),MOD((TODAY()+4)-MAX(Plants!N13,TODAY()),MAX(1,N(Plants!H13)))=0),"Water, feed","Water"),IF(AND(ISNUMBER(Plants!N13),N(Plants!H13)>0,(TODAY()+4)>=MAX(Plants!N13,TODAY()),MOD((TODAY()+4)-MAX(Plants!N13,TODAY()),MAX(1,N(Plants!H13)))=0),"Feed","")) | I13: =IF(AND(ISNUMBER(Plants!L13),N(Plants!S13)>0,(TODAY()+5)>=MAX(Plants!L13,TODAY()),MOD((TODAY()+5)-MAX(Plants!L13,TODAY()),MAX(1,N(Plants!S13)))=0),IF(AND(ISNUMBER(Plants!N13),N(Plants!H13)>0,(TODAY()+5)>=MAX(Plants!N13,TODAY()),MOD((TODAY()+5)-MAX(Plants!N13,TODAY()),MAX(1,N(Plants!H13)))=0),"Water, feed","Water"),IF(AND(ISNUMBER(Plants!N13),N(Plants!H13)>0,(TODAY()+5)>=MAX(Plants!N13,TODAY()),MOD((TODAY()+5)-MAX(Plants!N13,TODAY()),MAX(1,N(Plants!H13)))=0),"Feed","")) | J13: =IF(AND(ISNUMBER(Plants!L13),N(Plants!S13)>0,(TODAY()+6)>=MAX(Plants!L13,TODAY()),MOD((TODAY()+6)-MAX(Plants!L13,TODAY()),MAX(1,N(Plants!S13)))=0),IF(AND(ISNUMBER(Plants!N13),N(Plants!H13)>0,(TODAY()+6)>=MAX(Plants!N13,TODAY()),MOD((TODAY()+6)-MAX(Plants!N13,TODAY()),MAX(1,N(Plants!H13)))=0),"Water, feed","Water"),IF(AND(ISNUMBER(Plants!N13),N(Plants!H13)>0,(TODAY()+6)>=MAX(Plants!N13,TODAY()),MOD((TODAY()+6)-MAX(Plants!N13,TODAY()),MAX(1,N(Plants!H13)))=0),"Feed",""))
B14: =IF(Plants!B14="","",Plants!B14) | C14: =IF(Plants!B14="","",Plants!D14) | D14: =IF(AND(ISNUMBER(Plants!L14),N(Plants!S14)>0,(TODAY()+0)>=MAX(Plants!L14,TODAY()),MOD((TODAY()+0)-MAX(Plants!L14,TODAY()),MAX(1,N(Plants!S14)))=0),IF(AND(ISNUMBER(Plants!N14),N(Plants!H14)>0,(TODAY()+0)>=MAX(Plants!N14,TODAY()),MOD((TODAY()+0)-MAX(Plants!N14,TODAY()),MAX(1,N(Plants!H14)))=0),"Water, feed","Water"),IF(AND(ISNUMBER(Plants!N14),N(Plants!H14)>0,(TODAY()+0)>=MAX(Plants!N14,TODAY()),MOD((TODAY()+0)-MAX(Plants!N14,TODAY()),MAX(1,N(Plants!H14)))=0),"Feed","")) | E14: =IF(AND(ISNUMBER(Plants!L14),N(Plants!S14)>0,(TODAY()+1)>=MAX(Plants!L14,TODAY()),MOD((TODAY()+1)-MAX(Plants!L14,TODAY()),MAX(1,N(Plants!S14)))=0),IF(AND(ISNUMBER(Plants!N14),N(Plants!H14)>0,(TODAY()+1)>=MAX(Plants!N14,TODAY()),MOD((TODAY()+1)-MAX(Plants!N14,TODAY()),MAX(1,N(Plants!H14)))=0),"Water, feed","Water"),IF(AND(ISNUMBER(Plants!N14),N(Plants!H14)>0,(TODAY()+1)>=MAX(Plants!N14,TODAY()),MOD((TODAY()+1)-MAX(Plants!N14,TODAY()),MAX(1,N(Plants!H14)))=0),"Feed","")) | F14: =IF(AND(ISNUMBER(Plants!L14),N(Plants!S14)>0,(TODAY()+2)>=MAX(Plants!L14,TODAY()),MOD((TODAY()+2)-MAX(Plants!L14,TODAY()),MAX(1,N(Plants!S14)))=0),IF(AND(ISNUMBER(Plants!N14),N(Plants!H14)>0,(TODAY()+2)>=MAX(Plants!N14,TODAY()),MOD((TODAY()+2)-MAX(Plants!N14,TODAY()),MAX(1,N(Plants!H14)))=0),"Water, feed","Water"),IF(AND(ISNUMBER(Plants!N14),N(Plants!H14)>0,(TODAY()+2)>=MAX(Plants!N14,TODAY()),MOD((TODAY()+2)-MAX(Plants!N14,TODAY()),MAX(1,N(Plants!H14)))=0),"Feed","")) | G14: =IF(AND(ISNUMBER(Plants!L14),N(Plants!S14)>0,(TODAY()+3)>=MAX(Plants!L14,TODAY()),MOD((TODAY()+3)-MAX(Plants!L14,TODAY()),MAX(1,N(Plants!S14)))=0),IF(AND(ISNUMBER(Plants!N14),N(Plants!H14)>0,(TODAY()+3)>=MAX(Plants!N14,TODAY()),MOD((TODAY()+3)-MAX(Plants!N14,TODAY()),MAX(1,N(Plants!H14)))=0),"Water, feed","Water"),IF(AND(ISNUMBER(Plants!N14),N(Plants!H14)>0,(TODAY()+3)>=MAX(Plants!N14,TODAY()),MOD((TODAY()+3)-MAX(Plants!N14,TODAY()),MAX(1,N(Plants!H14)))=0),"Feed","")) | H14: =IF(AND(ISNUMBER(Plants!L14),N(Plants!S14)>0,(TODAY()+4)>=MAX(Plants!L14,TODAY()),MOD((TODAY()+4)-MAX(Plants!L14,TODAY()),MAX(1,N(Plants!S14)))=0),IF(AND(ISNUMBER(Plants!N14),N(Plants!H14)>0,(TODAY()+4)>=MAX(Plants!N14,TODAY()),MOD((TODAY()+4)-MAX(Plants!N14,TODAY()),MAX(1,N(Plants!H14)))=0),"Water, feed","Water"),IF(AND(ISNUMBER(Plants!N14),N(Plants!H14)>0,(TODAY()+4)>=MAX(Plants!N14,TODAY()),MOD((TODAY()+4)-MAX(Plants!N14,TODAY()),MAX(1,N(Plants!H14)))=0),"Feed","")) | I14: =IF(AND(ISNUMBER(Plants!L14),N(Plants!S14)>0,(TODAY()+5)>=MAX(Plants!L14,TODAY()),MOD((TODAY()+5)-MAX(Plants!L14,TODAY()),MAX(1,N(Plants!S14)))=0),IF(AND(ISNUMBER(Plants!N14),N(Plants!H14)>0,(TODAY()+5)>=MAX(Plants!N14,TODAY()),MOD((TODAY()+5)-MAX(Plants!N14,TODAY()),MAX(1,N(Plants!H14)))=0),"Water, feed","Water"),IF(AND(ISNUMBER(Plants!N14),N(Plants!H14)>0,(TODAY()+5)>=MAX(Plants!N14,TODAY()),MOD((TODAY()+5)-MAX(Plants!N14,TODAY()),MAX(1,N(Plants!H14)))=0),"Feed","")) | J14: =IF(AND(ISNUMBER(Plants!L14),N(Plants!S14)>0,(TODAY()+6)>=MAX(Plants!L14,TODAY()),MOD((TODAY()+6)-MAX(Plants!L14,TODAY()),MAX(1,N(Plants!S14)))=0),IF(AND(ISNUMBER(Plants!N14),N(Plants!H14)>0,(TODAY()+6)>=MAX(Plants!N14,TODAY()),MOD((TODAY()+6)-MAX(Plants!N14,TODAY()),MAX(1,N(Plants!H14)))=0),"Water, feed","Water"),IF(AND(ISNUMBER(Plants!N14),N(Plants!H14)>0,(TODAY()+6)>=MAX(Plants!N14,TODAY()),MOD((TODAY()+6)-MAX(Plants!N14,TODAY()),MAX(1,N(Plants!H14)))=0),"Feed",""))
B15: =IF(Plants!B15="","",Plants!B15) | C15: =IF(Plants!B15="","",Plants!D15) | D15: =IF(AND(ISNUMBER(Plants!L15),N(Plants!S15)>0,(TODAY()+0)>=MAX(Plants!L15,TODAY()),MOD((TODAY()+0)-MAX(Plants!L15,TODAY()),MAX(1,N(Plants!S15)))=0),IF(AND(ISNUMBER(Plants!N15),N(Plants!H15)>0,(TODAY()+0)>=MAX(Plants!N15,TODAY()),MOD((TODAY()+0)-MAX(Plants!N15,TODAY()),MAX(1,N(Plants!H15)))=0),"Water, feed","Water"),IF(AND(ISNUMBER(Plants!N15),N(Plants!H15)>0,(TODAY()+0)>=MAX(Plants!N15,TODAY()),MOD((TODAY()+0)-MAX(Plants!N15,TODAY()),MAX(1,N(Plants!H15)))=0),"Feed","")) | E15: =IF(AND(ISNUMBER(Plants!L15),N(Plants!S15)>0,(TODAY()+1)>=MAX(Plants!L15,TODAY()),MOD((TODAY()+1)-MAX(Plants!L15,TODAY()),MAX(1,N(Plants!S15)))=0),IF(AND(ISNUMBER(Plants!N15),N(Plants!H15)>0,(TODAY()+1)>=MAX(Plants!N15,TODAY()),MOD((TODAY()+1)-MAX(Plants!N15,TODAY()),MAX(1,N(Plants!H15)))=0),"Water, feed","Water"),IF(AND(ISNUMBER(Plants!N15),N(Plants!H15)>0,(TODAY()+1)>=MAX(Plants!N15,TODAY()),MOD((TODAY()+1)-MAX(Plants!N15,TODAY()),MAX(1,N(Plants!H15)))=0),"Feed","")) | F15: =IF(AND(ISNUMBER(Plants!L15),N(Plants!S15)>0,(TODAY()+2)>=MAX(Plants!L15,TODAY()),MOD((TODAY()+2)-MAX(Plants!L15,TODAY()),MAX(1,N(Plants!S15)))=0),IF(AND(ISNUMBER(Plants!N15),N(Plants!H15)>0,(TODAY()+2)>=MAX(Plants!N15,TODAY()),MOD((TODAY()+2)-MAX(Plants!N15,TODAY()),MAX(1,N(Plants!H15)))=0),"Water, feed","Water"),IF(AND(ISNUMBER(Plants!N15),N(Plants!H15)>0,(TODAY()+2)>=MAX(Plants!N15,TODAY()),MOD((TODAY()+2)-MAX(Plants!N15,TODAY()),MAX(1,N(Plants!H15)))=0),"Feed","")) | G15: =IF(AND(ISNUMBER(Plants!L15),N(Plants!S15)>0,(TODAY()+3)>=MAX(Plants!L15,TODAY()),MOD((TODAY()+3)-MAX(Plants!L15,TODAY()),MAX(1,N(Plants!S15)))=0),IF(AND(ISNUMBER(Plants!N15),N(Plants!H15)>0,(TODAY()+3)>=MAX(Plants!N15,TODAY()),MOD((TODAY()+3)-MAX(Plants!N15,TODAY()),MAX(1,N(Plants!H15)))=0),"Water, feed","Water"),IF(AND(ISNUMBER(Plants!N15),N(Plants!H15)>0,(TODAY()+3)>=MAX(Plants!N15,TODAY()),MOD((TODAY()+3)-MAX(Plants!N15,TODAY()),MAX(1,N(Plants!H15)))=0),"Feed","")) | H15: =IF(AND(ISNUMBER(Plants!L15),N(Plants!S15)>0,(TODAY()+4)>=MAX(Plants!L15,TODAY()),MOD((TODAY()+4)-MAX(Plants!L15,TODAY()),MAX(1,N(Plants!S15)))=0),IF(AND(ISNUMBER(Plants!N15),N(Plants!H15)>0,(TODAY()+4)>=MAX(Plants!N15,TODAY()),MOD((TODAY()+4)-MAX(Plants!N15,TODAY()),MAX(1,N(Plants!H15)))=0),"Water, feed","Water"),IF(AND(ISNUMBER(Plants!N15),N(Plants!H15)>0,(TODAY()+4)>=MAX(Plants!N15,TODAY()),MOD((TODAY()+4)-MAX(Plants!N15,TODAY()),MAX(1,N(Plants!H15)))=0),"Feed","")) | I15: =IF(AND(ISNUMBER(Plants!L15),N(Plants!S15)>0,(TODAY()+5)>=MAX(Plants!L15,TODAY()),MOD((TODAY()+5)-MAX(Plants!L15,TODAY()),MAX(1,N(Plants!S15)))=0),IF(AND(ISNUMBER(Plants!N15),N(Plants!H15)>0,(TODAY()+5)>=MAX(Plants!N15,TODAY()),MOD((TODAY()+5)-MAX(Plants!N15,TODAY()),MAX(1,N(Plants!H15)))=0),"Water, feed","Water"),IF(AND(ISNUMBER(Plants!N15),N(Plants!H15)>0,(TODAY()+5)>=MAX(Plants!N15,TODAY()),MOD((TODAY()+5)-MAX(Plants!N15,TODAY()),MAX(1,N(Plants!H15)))=0),"Feed","")) | J15: =IF(AND(ISNUMBER(Plants!L15),N(Plants!S15)>0,(TODAY()+6)>=MAX(Plants!L15,TODAY()),MOD((TODAY()+6)-MAX(Plants!L15,TODAY()),MAX(1,N(Plants!S15)))=0),IF(AND(ISNUMBER(Plants!N15),N(Plants!H15)>0,(TODAY()+6)>=MAX(Plants!N15,TODAY()),MOD((TODAY()+6)-MAX(Plants!N15,TODAY()),MAX(1,N(Plants!H15)))=0),"Water, feed","Water"),IF(AND(ISNUMBER(Plants!N15),N(Plants!H15)>0,(TODAY()+6)>=MAX(Plants!N15,TODAY()),MOD((TODAY()+6)-MAX(Plants!N15,TODAY()),MAX(1,N(Plants!H15)))=0),"Feed",""))
B16: =IF(Plants!B16="","",Plants!B16) | C16: =IF(Plants!B16="","",Plants!D16) | D16: =IF(AND(ISNUMBER(Plants!L16),N(Plants!S16)>0,(TODAY()+0)>=MAX(Plants!L16,TODAY()),MOD((TODAY()+0)-MAX(Plants!L16,TODAY()),MAX(1,N(Plants!S16)))=0),IF(AND(ISNUMBER(Plants!N16),N(Plants!H16)>0,(TODAY()+0)>=MAX(Plants!N16,TODAY()),MOD((TODAY()+0)-MAX(Plants!N16,TODAY()),MAX(1,N(Plants!H16)))=0),"Water, feed","Water"),IF(AND(ISNUMBER(Plants!N16),N(Plants!H16)>0,(TODAY()+0)>=MAX(Plants!N16,TODAY()),MOD((TODAY()+0)-MAX(Plants!N16,TODAY()),MAX(1,N(Plants!H16)))=0),"Feed","")) | E16: =IF(AND(ISNUMBER(Plants!L16),N(Plants!S16)>0,(TODAY()+1)>=MAX(Plants!L16,TODAY()),MOD((TODAY()+1)-MAX(Plants!L16,TODAY()),MAX(1,N(Plants!S16)))=0),IF(AND(ISNUMBER(Plants!N16),N(Plants!H16)>0,(TODAY()+1)>=MAX(Plants!N16,TODAY()),MOD((TODAY()+1)-MAX(Plants!N16,TODAY()),MAX(1,N(Plants!H16)))=0),"Water, feed","Water"),IF(AND(ISNUMBER(Plants!N16),N(Plants!H16)>0,(TODAY()+1)>=MAX(Plants!N16,TODAY()),MOD((TODAY()+1)-MAX(Plants!N16,TODAY()),MAX(1,N(Plants!H16)))=0),"Feed","")) | F16: =IF(AND(ISNUMBER(Plants!L16),N(Plants!S16)>0,(TODAY()+2)>=MAX(Plants!L16,TODAY()),MOD((TODAY()+2)-MAX(Plants!L16,TODAY()),MAX(1,N(Plants!S16)))=0),IF(AND(ISNUMBER(Plants!N16),N(Plants!H16)>0,(TODAY()+2)>=MAX(Plants!N16,TODAY()),MOD((TODAY()+2)-MAX(Plants!N16,TODAY()),MAX(1,N(Plants!H16)))=0),"Water, feed","Water"),IF(AND(ISNUMBER(Plants!N16),N(Plants!H16)>0,(TODAY()+2)>=MAX(Plants!N16,TODAY()),MOD((TODAY()+2)-MAX(Plants!N16,TODAY()),MAX(1,N(Plants!H16)))=0),"Feed","")) | G16: =IF(AND(ISNUMBER(Plants!L16),N(Plants!S16)>0,(TODAY()+3)>=MAX(Plants!L16,TODAY()),MOD((TODAY()+3)-MAX(Plants!L16,TODAY()),MAX(1,N(Plants!S16)))=0),IF(AND(ISNUMBER(Plants!N16),N(Plants!H16)>0,(TODAY()+3)>=MAX(Plants!N16,TODAY()),MOD((TODAY()+3)-MAX(Plants!N16,TODAY()),MAX(1,N(Plants!H16)))=0),"Water, feed","Water"),IF(AND(ISNUMBER(Plants!N16),N(Plants!H16)>0,(TODAY()+3)>=MAX(Plants!N16,TODAY()),MOD((TODAY()+3)-MAX(Plants!N16,TODAY()),MAX(1,N(Plants!H16)))=0),"Feed","")) | H16: =IF(AND(ISNUMBER(Plants!L16),N(Plants!S16)>0,(TODAY()+4)>=MAX(Plants!L16,TODAY()),MOD((TODAY()+4)-MAX(Plants!L16,TODAY()),MAX(1,N(Plants!S16)))=0),IF(AND(ISNUMBER(Plants!N16),N(Plants!H16)>0,(TODAY()+4)>=MAX(Plants!N16,TODAY()),MOD((TODAY()+4)-MAX(Plants!N16,TODAY()),MAX(1,N(Plants!H16)))=0),"Water, feed","Water"),IF(AND(ISNUMBER(Plants!N16),N(Plants!H16)>0,(TODAY()+4)>=MAX(Plants!N16,TODAY()),MOD((TODAY()+4)-MAX(Plants!N16,TODAY()),MAX(1,N(Plants!H16)))=0),"Feed","")) | I16: =IF(AND(ISNUMBER(Plants!L16),N(Plants!S16)>0,(TODAY()+5)>=MAX(Plants!L16,TODAY()),MOD((TODAY()+5)-MAX(Plants!L16,TODAY()),MAX(1,N(Plants!S16)))=0),IF(AND(ISNUMBER(Plants!N16),N(Plants!H16)>0,(TODAY()+5)>=MAX(Plants!N16,TODAY()),MOD((TODAY()+5)-MAX(Plants!N16,TODAY()),MAX(1,N(Plants!H16)))=0),"Water, feed","Water"),IF(AND(ISNUMBER(Plants!N16),N(Plants!H16)>0,(TODAY()+5)>=MAX(Plants!N16,TODAY()),MOD((TODAY()+5)-MAX(Plants!N16,TODAY()),MAX(1,N(Plants!H16)))=0),"Feed","")) | J16: =IF(AND(ISNUMBER(Plants!L16),N(Plants!S16)>0,(TODAY()+6)>=MAX(Plants!L16,TODAY()),MOD((TODAY()+6)-MAX(Plants!L16,TODAY()),MAX(1,N(Plants!S16)))=0),IF(AND(ISNUMBER(Plants!N16),N(Plants!H16)>0,(TODAY()+6)>=MAX(Plants!N16,TODAY()),MOD((TODAY()+6)-MAX(Plants!N16,TODAY()),MAX(1,N(Plants!H16)))=0),"Water, feed","Water"),IF(AND(ISNUMBER(Plants!N16),N(Plants!H16)>0,(TODAY()+6)>=MAX(Plants!N16,TODAY()),MOD((TODAY()+6)-MAX(Plants!N16,TODAY()),MAX(1,N(Plants!H16)))=0),"Feed",""))
B17: =IF(Plants!B17="","",Plants!B17) | C17: =IF(Plants!B17="","",Plants!D17) | D17: =IF(AND(ISNUMBER(Plants!L17),N(Plants!S17)>0,(TODAY()+0)>=MAX(Plants!L17,TODAY()),MOD((TODAY()+0)-MAX(Plants!L17,TODAY()),MAX(1,N(Plants!S17)))=0),IF(AND(ISNUMBER(Plants!N17),N(Plants!H17)>0,(TODAY()+0)>=MAX(Plants!N17,TODAY()),MOD((TODAY()+0)-MAX(Plants!N17,TODAY()),MAX(1,N(Plants!H17)))=0),"Water, feed","Water"),IF(AND(ISNUMBER(Plants!N17),N(Plants!H17)>0,(TODAY()+0)>=MAX(Plants!N17,TODAY()),MOD((TODAY()+0)-MAX(Plants!N17,TODAY()),MAX(1,N(Plants!H17)))=0),"Feed","")) | E17: =IF(AND(ISNUMBER(Plants!L17),N(Plants!S17)>0,(TODAY()+1)>=MAX(Plants!L17,TODAY()),MOD((TODAY()+1)-MAX(Plants!L17,TODAY()),MAX(1,N(Plants!S17)))=0),IF(AND(ISNUMBER(Plants!N17),N(Plants!H17)>0,(TODAY()+1)>=MAX(Plants!N17,TODAY()),MOD((TODAY()+1)-MAX(Plants!N17,TODAY()),MAX(1,N(Plants!H17)))=0),"Water, feed","Water"),IF(AND(ISNUMBER(Plants!N17),N(Plants!H17)>0,(TODAY()+1)>=MAX(Plants!N17,TODAY()),MOD((TODAY()+1)-MAX(Plants!N17,TODAY()),MAX(1,N(Plants!H17)))=0),"Feed","")) | F17: =IF(AND(ISNUMBER(Plants!L17),N(Plants!S17)>0,(TODAY()+2)>=MAX(Plants!L17,TODAY()),MOD((TODAY()+2)-MAX(Plants!L17,TODAY()),MAX(1,N(Plants!S17)))=0),IF(AND(ISNUMBER(Plants!N17),N(Plants!H17)>0,(TODAY()+2)>=MAX(Plants!N17,TODAY()),MOD((TODAY()+2)-MAX(Plants!N17,TODAY()),MAX(1,N(Plants!H17)))=0),"Water, feed","Water"),IF(AND(ISNUMBER(Plants!N17),N(Plants!H17)>0,(TODAY()+2)>=MAX(Plants!N17,TODAY()),MOD((TODAY()+2)-MAX(Plants!N17,TODAY()),MAX(1,N(Plants!H17)))=0),"Feed","")) | G17: =IF(AND(ISNUMBER(Plants!L17),N(Plants!S17)>0,(TODAY()+3)>=MAX(Plants!L17,TODAY()),MOD((TODAY()+3)-MAX(Plants!L17,TODAY()),MAX(1,N(Plants!S17)))=0),IF(AND(ISNUMBER(Plants!N17),N(Plants!H17)>0,(TODAY()+3)>=MAX(Plants!N17,TODAY()),MOD((TODAY()+3)-MAX(Plants!N17,TODAY()),MAX(1,N(Plants!H17)))=0),"Water, feed","Water"),IF(AND(ISNUMBER(Plants!N17),N(Plants!H17)>0,(TODAY()+3)>=MAX(Plants!N17,TODAY()),MOD((TODAY()+3)-MAX(Plants!N17,TODAY()),MAX(1,N(Plants!H17)))=0),"Feed","")) | H17: =IF(AND(ISNUMBER(Plants!L17),N(Plants!S17)>0,(TODAY()+4)>=MAX(Plants!L17,TODAY()),MOD((TODAY()+4)-MAX(Plants!L17,TODAY()),MAX(1,N(Plants!S17)))=0),IF(AND(ISNUMBER(Plants!N17),N(Plants!H17)>0,(TODAY()+4)>=MAX(Plants!N17,TODAY()),MOD((TODAY()+4)-MAX(Plants!N17,TODAY()),MAX(1,N(Plants!H17)))=0),"Water, feed","Water"),IF(AND(ISNUMBER(Plants!N17),N(Plants!H17)>0,(TODAY()+4)>=MAX(Plants!N17,TODAY()),MOD((TODAY()+4)-MAX(Plants!N17,TODAY()),MAX(1,N(Plants!H17)))=0),"Feed","")) | I17: =IF(AND(ISNUMBER(Plants!L17),N(Plants!S17)>0,(TODAY()+5)>=MAX(Plants!L17,TODAY()),MOD((TODAY()+5)-MAX(Plants!L17,TODAY()),MAX(1,N(Plants!S17)))=0),IF(AND(ISNUMBER(Plants!N17),N(Plants!H17)>0,(TODAY()+5)>=MAX(Plants!N17,TODAY()),MOD((TODAY()+5)-MAX(Plants!N17,TODAY()),MAX(1,N(Plants!H17)))=0),"Water, feed","Water"),IF(AND(ISNUMBER(Plants!N17),N(Plants!H17)>0,(TODAY()+5)>=MAX(Plants!N17,TODAY()),MOD((TODAY()+5)-MAX(Plants!N17,TODAY()),MAX(1,N(Plants!H17)))=0),"Feed","")) | J17: =IF(AND(ISNUMBER(Plants!L17),N(Plants!S17)>0,(TODAY()+6)>=MAX(Plants!L17,TODAY()),MOD((TODAY()+6)-MAX(Plants!L17,TODAY()),MAX(1,N(Plants!S17)))=0),IF(AND(ISNUMBER(Plants!N17),N(Plants!H17)>0,(TODAY()+6)>=MAX(Plants!N17,TODAY()),MOD((TODAY()+6)-MAX(Plants!N17,TODAY()),MAX(1,N(Plants!H17)))=0),"Water, feed","Water"),IF(AND(ISNUMBER(Plants!N17),N(Plants!H17)>0,(TODAY()+6)>=MAX(Plants!N17,TODAY()),MOD((TODAY()+6)-MAX(Plants!N17,TODAY()),MAX(1,N(Plants!H17)))=0),"Feed",""))
