Workbook

Sheet Dashboard
B2: Car care
B3: Each car, what is due, and what the cars cost this year.
B5: Cars | C5: Services due soon | D5: Overdue | E5: Papers to renew | F5: Fuel this year | G5: All costs this year
B6: =COUNTIF(Cars!$B$6:$B$10,"?*") | C6: =COUNTIF(Services!$L$6:$L$65,"Due soon") | D6: =COUNTIF(Services!$L$6:$L$65,"Overdue") | E6: =COUNTIF(Documents!$G$6:$G$45,"End*") | F6: =SUMIFS(Fuel!$F$6:$F$605,Fuel!$B$6:$B$605,">="&DATE(YEAR(TODAY()),1,1)) | G6: =SUMIFS(Fuel!$F$6:$F$605,Fuel!$B$6:$B$605,">="&DATE(YEAR(TODAY()),1,1))+SUMIFS(Costs!$G$6:$G$505,Costs!$B$6:$B$505,">="&DATE(YEAR(TODAY()),1,1))
B9: Car | C9: Odometer | D9: =Settings!$C$5&" per 100 "&Settings!$C$4 | E9: =Settings!$C$4&" per "&Settings!$C$5 | F9: This year | G9: ="Cost per "&Settings!$C$4
B10: =IF(Cars!B6="","",Cars!B6) | C10: =IF(B10="","",Cars!I6) | D10: =IF(B10="","",Cars!K6) | E10: =IF(OR(B10="",N(D10)=0),"",100/D10) | F10: =IF(B10="","",SUMIFS(Fuel!$F$6:$F$605,Fuel!$C$6:$C$605,B10,Fuel!$B$6:$B$605,">="&DATE(YEAR(TODAY()),1,1))+SUMIFS(Costs!$G$6:$G$505,Costs!$C$6:$C$505,B10,Costs!$B$6:$B$505,">="&DATE(YEAR(TODAY()),1,1))) | G10: =IF(OR(B10="",(N(Cars!I6)-N(Cars!G6))<=0),"",(SUMIFS(Fuel!$F$6:$F$605,Fuel!$C$6:$C$605,B10)+SUMIFS(Costs!$G$6:$G$505,Costs!$C$6:$C$505,B10))/(N(Cars!I6)-N(Cars!G6)))
B11: =IF(Cars!B7="","",Cars!B7) | C11: =IF(B11="","",Cars!I7) | D11: =IF(B11="","",Cars!K7) | E11: =IF(OR(B11="",N(D11)=0),"",100/D11) | F11: =IF(B11="","",SUMIFS(Fuel!$F$6:$F$605,Fuel!$C$6:$C$605,B11,Fuel!$B$6:$B$605,">="&DATE(YEAR(TODAY()),1,1))+SUMIFS(Costs!$G$6:$G$505,Costs!$C$6:$C$505,B11,Costs!$B$6:$B$505,">="&DATE(YEAR(TODAY()),1,1))) | G11: =IF(OR(B11="",(N(Cars!I7)-N(Cars!G7))<=0),"",(SUMIFS(Fuel!$F$6:$F$605,Fuel!$C$6:$C$605,B11)+SUMIFS(Costs!$G$6:$G$505,Costs!$C$6:$C$505,B11))/(N(Cars!I7)-N(Cars!G7)))
B12: =IF(Cars!B8="","",Cars!B8) | C12: =IF(B12="","",Cars!I8) | D12: =IF(B12="","",Cars!K8) | E12: =IF(OR(B12="",N(D12)=0),"",100/D12) | F12: =IF(B12="","",SUMIFS(Fuel!$F$6:$F$605,Fuel!$C$6:$C$605,B12,Fuel!$B$6:$B$605,">="&DATE(YEAR(TODAY()),1,1))+SUMIFS(Costs!$G$6:$G$505,Costs!$C$6:$C$505,B12,Costs!$B$6:$B$505,">="&DATE(YEAR(TODAY()),1,1))) | G12: =IF(OR(B12="",(N(Cars!I8)-N(Cars!G8))<=0),"",(SUMIFS(Fuel!$F$6:$F$605,Fuel!$C$6:$C$605,B12)+SUMIFS(Costs!$G$6:$G$505,Costs!$C$6:$C$505,B12))/(N(Cars!I8)-N(Cars!G8)))
B13: =IF(Cars!B9="","",Cars!B9) | C13: =IF(B13="","",Cars!I9) | D13: =IF(B13="","",Cars!K9) | E13: =IF(OR(B13="",N(D13)=0),"",100/D13) | F13: =IF(B13="","",SUMIFS(Fuel!$F$6:$F$605,Fuel!$C$6:$C$605,B13,Fuel!$B$6:$B$605,">="&DATE(YEAR(TODAY()),1,1))+SUMIFS(Costs!$G$6:$G$505,Costs!$C$6:$C$505,B13,Costs!$B$6:$B$505,">="&DATE(YEAR(TODAY()),1,1))) | G13: =IF(OR(B13="",(N(Cars!I9)-N(Cars!G9))<=0),"",(SUMIFS(Fuel!$F$6:$F$605,Fuel!$C$6:$C$605,B13)+SUMIFS(Costs!$G$6:$G$505,Costs!$C$6:$C$505,B13))/(N(Cars!I9)-N(Cars!G9)))
B14: =IF(Cars!B10="","",Cars!B10) | C14: =IF(B14="","",Cars!I10) | D14: =IF(B14="","",Cars!K10) | E14: =IF(OR(B14="",N(D14)=0),"",100/D14) | F14: =IF(B14="","",SUMIFS(Fuel!$F$6:$F$605,Fuel!$C$6:$C$605,B14,Fuel!$B$6:$B$605,">="&DATE(YEAR(TODAY()),1,1))+SUMIFS(Costs!$G$6:$G$505,Costs!$C$6:$C$505,B14,Costs!$B$6:$B$505,">="&DATE(YEAR(TODAY()),1,1))) | G14: =IF(OR(B14="",(N(Cars!I10)-N(Cars!G10))<=0),"",(SUMIFS(Fuel!$F$6:$F$605,Fuel!$C$6:$C$605,B14)+SUMIFS(Costs!$G$6:$G$505,Costs!$C$6:$C$505,B14))/(N(Cars!I10)-N(Cars!G10)))
B15: Cost per distance: fuel and every cost, divided by the distance since the start of the file.
B17: Services | D17: About | E17: ="Left ("&Settings!$C$4&")" | F17: Status | I17: Papers | K17: Ends | L17: Status
B18: =IF(N18="","Nothing due soon",INDEX(Services!$B$6:$B$65,MATCH(N18,Services!$O$6:$O$65,0))) | C18: =IF(N18="","",INDEX(Services!$C$6:$C$65,MATCH(N18,Services!$O$6:$O$65,0))) | D18: =IF(N18="","",INT(N18)) | E18: =IF(N18="","",INDEX(Services!$J$6:$J$65,MATCH(N18,Services!$O$6:$O$65,0))) | F18: =IF(N18="","",INDEX(Services!$L$6:$L$65,MATCH(N18,Services!$O$6:$O$65,0))) | I18: =IF(O18="","Nothing to renew soon",INDEX(Documents!$B$6:$B$45,MATCH(O18,Documents!$J$6:$J$45,0))) | J18: =IF(O18="","",INDEX(Documents!$C$6:$C$45,MATCH(O18,Documents!$J$6:$J$45,0))) | K18: =IF(O18="","",INT(O18)) | L18: =IF(O18="","",INDEX(Documents!$G$6:$G$45,MATCH(O18,Documents!$J$6:$J$45,0))) | N18: =IFERROR(SMALL(Services!$O$6:$O$65,1),"") | O18: =IFERROR(SMALL(Documents!$J$6:$J$45,1),"")
B19: =IF(N19="","",INDEX(Services!$B$6:$B$65,MATCH(N19,Services!$O$6:$O$65,0))) | C19: =IF(N19="","",INDEX(Services!$C$6:$C$65,MATCH(N19,Services!$O$6:$O$65,0))) | D19: =IF(N19="","",INT(N19)) | E19: =IF(N19="","",INDEX(Services!$J$6:$J$65,MATCH(N19,Services!$O$6:$O$65,0))) | F19: =IF(N19="","",INDEX(Services!$L$6:$L$65,MATCH(N19,Services!$O$6:$O$65,0))) | I19: =IF(O19="","",INDEX(Documents!$B$6:$B$45,MATCH(O19,Documents!$J$6:$J$45,0))) | J19: =IF(O19="","",INDEX(Documents!$C$6:$C$45,MATCH(O19,Documents!$J$6:$J$45,0))) | K19: =IF(O19="","",INT(O19)) | L19: =IF(O19="","",INDEX(Documents!$G$6:$G$45,MATCH(O19,Documents!$J$6:$J$45,0))) | N19: =IFERROR(SMALL(Services!$O$6:$O$65,2),"") | O19: =IFERROR(SMALL(Documents!$J$6:$J$45,2),"")
B20: =IF(N20="","",INDEX(Services!$B$6:$B$65,MATCH(N20,Services!$O$6:$O$65,0))) | C20: =IF(N20="","",INDEX(Services!$C$6:$C$65,MATCH(N20,Services!$O$6:$O$65,0))) | D20: =IF(N20="","",INT(N20)) | E20: =IF(N20="","",INDEX(Services!$J$6:$J$65,MATCH(N20,Services!$O$6:$O$65,0))) | F20: =IF(N20="","",INDEX(Services!$L$6:$L$65,MATCH(N20,Services!$O$6:$O$65,0))) | I20: =IF(O20="","",INDEX(Documents!$B$6:$B$45,MATCH(O20,Documents!$J$6:$J$45,0))) | J20: =IF(O20="","",INDEX(Documents!$C$6:$C$45,MATCH(O20,Documents!$J$6:$J$45,0))) | K20: =IF(O20="","",INT(O20)) | L20: =IF(O20="","",INDEX(Documents!$G$6:$G$45,MATCH(O20,Documents!$J$6:$J$45,0))) | N20: =IFERROR(SMALL(Services!$O$6:$O$65,3),"") | O20: =IFERROR(SMALL(Documents!$J$6:$J$45,3),"")
B21: =IF(N21="","",INDEX(Services!$B$6:$B$65,MATCH(N21,Services!$O$6:$O$65,0))) | C21: =IF(N21="","",INDEX(Services!$C$6:$C$65,MATCH(N21,Services!$O$6:$O$65,0))) | D21: =IF(N21="","",INT(N21)) | E21: =IF(N21="","",INDEX(Services!$J$6:$J$65,MATCH(N21,Services!$O$6:$O$65,0))) | F21: =IF(N21="","",INDEX(Services!$L$6:$L$65,MATCH(N21,Services!$O$6:$O$65,0))) | I21: =IF(O21="","",INDEX(Documents!$B$6:$B$45,MATCH(O21,Documents!$J$6:$J$45,0))) | J21: =IF(O21="","",INDEX(Documents!$C$6:$C$45,MATCH(O21,Documents!$J$6:$J$45,0))) | K21: =IF(O21="","",INT(O21)) | L21: =IF(O21="","",INDEX(Documents!$G$6:$G$45,MATCH(O21,Documents!$J$6:$J$45,0))) | N21: =IFERROR(SMALL(Services!$O$6:$O$65,4),"") | O21: =IFERROR(SMALL(Documents!$J$6:$J$45,4),"")
B22: =IF(N22="","",INDEX(Services!$B$6:$B$65,MATCH(N22,Services!$O$6:$O$65,0))) | C22: =IF(N22="","",INDEX(Services!$C$6:$C$65,MATCH(N22,Services!$O$6:$O$65,0))) | D22: =IF(N22="","",INT(N22)) | E22: =IF(N22="","",INDEX(Services!$J$6:$J$65,MATCH(N22,Services!$O$6:$O$65,0))) | F22: =IF(N22="","",INDEX(Services!$L$6:$L$65,MATCH(N22,Services!$O$6:$O$65,0))) | I22: =IF(O22="","",INDEX(Documents!$B$6:$B$45,MATCH(O22,Documents!$J$6:$J$45,0))) | J22: =IF(O22="","",INDEX(Documents!$C$6:$C$45,MATCH(O22,Documents!$J$6:$J$45,0))) | K22: =IF(O22="","",INT(O22)) | L22: =IF(O22="","",INDEX(Documents!$G$6:$G$45,MATCH(O22,Documents!$J$6:$J$45,0))) | N22: =IFERROR(SMALL(Services!$O$6:$O$65,5),"") | O22: =IFERROR(SMALL(Documents!$J$6:$J$45,5),"")
B23: =IF(N23="","",INDEX(Services!$B$6:$B$65,MATCH(N23,Services!$O$6:$O$65,0))) | C23: =IF(N23="","",INDEX(Services!$C$6:$C$65,MATCH(N23,Services!$O$6:$O$65,0))) | D23: =IF(N23="","",INT(N23)) | E23: =IF(N23="","",INDEX(Services!$J$6:$J$65,MATCH(N23,Services!$O$6:$O$65,0))) | F23: =IF(N23="","",INDEX(Services!$L$6:$L$65,MATCH(N23,Services!$O$6:$O$65,0))) | I23: =IF(O23="","",INDEX(Documents!$B$6:$B$45,MATCH(O23,Documents!$J$6:$J$45,0))) | J23: =IF(O23="","",INDEX(Documents!$C$6:$C$45,MATCH(O23,Documents!$J$6:$J$45,0))) | K23: =IF(O23="","",INT(O23)) | L23: =IF(O23="","",INDEX(Documents!$G$6:$G$45,MATCH(O23,Documents!$J$6:$J$45,0))) | N23: =IFERROR(SMALL(Services!$O$6:$O$65,6),"") | O23: =IFERROR(SMALL(Documents!$J$6:$J$45,6),"")
B24: =IF(N24="","",INDEX(Services!$B$6:$B$65,MATCH(N24,Services!$O$6:$O$65,0))) | C24: =IF(N24="","",INDEX(Services!$C$6:$C$65,MATCH(N24,Services!$O$6:$O$65,0))) | D24: =IF(N24="","",INT(N24)) | E24: =IF(N24="","",INDEX(Services!$J$6:$J$65,MATCH(N24,Services!$O$6:$O$65,0))) | F24: =IF(N24="","",INDEX(Services!$L$6:$L$65,MATCH(N24,Services!$O$6:$O$65,0))) | I24: =IF(O24="","",INDEX(Documents!$B$6:$B$45,MATCH(O24,Documents!$J$6:$J$45,0))) | J24: =IF(O24="","",INDEX(Documents!$C$6:$C$45,MATCH(O24,Documents!$J$6:$J$45,0))) | K24: =IF(O24="","",INT(O24)) | L24: =IF(O24="","",INDEX(Documents!$G$6:$G$45,MATCH(O24,Documents!$J$6:$J$45,0))) | N24: =IFERROR(SMALL(Services!$O$6:$O$65,7),"") | O24: =IFERROR(SMALL(Documents!$J$6:$J$45,7),"")
B25: =IF(N25="","",INDEX(Services!$B$6:$B$65,MATCH(N25,Services!$O$6:$O$65,0))) | C25: =IF(N25="","",INDEX(Services!$C$6:$C$65,MATCH(N25,Services!$O$6:$O$65,0))) | D25: =IF(N25="","",INT(N25)) | E25: =IF(N25="","",INDEX(Services!$J$6:$J$65,MATCH(N25,Services!$O$6:$O$65,0))) | F25: =IF(N25="","",INDEX(Services!$L$6:$L$65,MATCH(N25,Services!$O$6:$O$65,0))) | I25: =IF(O25="","",INDEX(Documents!$B$6:$B$45,MATCH(O25,Documents!$J$6:$J$45,0))) | J25: =IF(O25="","",INDEX(Documents!$C$6:$C$45,MATCH(O25,Documents!$J$6:$J$45,0))) | K25: =IF(O25="","",INT(O25)) | L25: =IF(O25="","",INDEX(Documents!$G$6:$G$45,MATCH(O25,Documents!$J$6:$J$45,0))) | N25: =IFERROR(SMALL(Services!$O$6:$O$65,8),"") | O25: =IFERROR(SMALL(Documents!$J$6:$J$45,8),"")
B28: Month | C28: Fuel | D28: Other costs | E28: Total
B29: Jan | C29: =SUMIFS(Fuel!$F$6:$F$605,Fuel!$B$6:$B$605,">="&DATE(YEAR(TODAY()),1,1),Fuel!$B$6:$B$605,"<="&EOMONTH(DATE(YEAR(TODAY()),1,1),0)) | D29: =SUMIFS(Costs!$G$6:$G$505,Costs!$B$6:$B$505,">="&DATE(YEAR(TODAY()),1,1),Costs!$B$6:$B$505,"<="&EOMONTH(DATE(YEAR(TODAY()),1,1),0)) | E29: =C29+D29
B30: Feb | C30: =SUMIFS(Fuel!$F$6:$F$605,Fuel!$B$6:$B$605,">="&DATE(YEAR(TODAY()),2,1),Fuel!$B$6:$B$605,"<="&EOMONTH(DATE(YEAR(TODAY()),2,1),0)) | D30: =SUMIFS(Costs!$G$6:$G$505,Costs!$B$6:$B$505,">="&DATE(YEAR(TODAY()),2,1),Costs!$B$6:$B$505,"<="&EOMONTH(DATE(YEAR(TODAY()),2,1),0)) | E30: =C30+D30
B31: Mar | C31: =SUMIFS(Fuel!$F$6:$F$605,Fuel!$B$6:$B$605,">="&DATE(YEAR(TODAY()),3,1),Fuel!$B$6:$B$605,"<="&EOMONTH(DATE(YEAR(TODAY()),3,1),0)) | D31: =SUMIFS(Costs!$G$6:$G$505,Costs!$B$6:$B$505,">="&DATE(YEAR(TODAY()),3,1),Costs!$B$6:$B$505,"<="&EOMONTH(DATE(YEAR(TODAY()),3,1),0)) | E31: =C31+D31
B32: Apr | C32: =SUMIFS(Fuel!$F$6:$F$605,Fuel!$B$6:$B$605,">="&DATE(YEAR(TODAY()),4,1),Fuel!$B$6:$B$605,"<="&EOMONTH(DATE(YEAR(TODAY()),4,1),0)) | D32: =SUMIFS(Costs!$G$6:$G$505,Costs!$B$6:$B$505,">="&DATE(YEAR(TODAY()),4,1),Costs!$B$6:$B$505,"<="&EOMONTH(DATE(YEAR(TODAY()),4,1),0)) | E32: =C32+D32
B33: May | C33: =SUMIFS(Fuel!$F$6:$F$605,Fuel!$B$6:$B$605,">="&DATE(YEAR(TODAY()),5,1),Fuel!$B$6:$B$605,"<="&EOMONTH(DATE(YEAR(TODAY()),5,1),0)) | D33: =SUMIFS(Costs!$G$6:$G$505,Costs!$B$6:$B$505,">="&DATE(YEAR(TODAY()),5,1),Costs!$B$6:$B$505,"<="&EOMONTH(DATE(YEAR(TODAY()),5,1),0)) | E33: =C33+D33
B34: Jun | C34: =SUMIFS(Fuel!$F$6:$F$605,Fuel!$B$6:$B$605,">="&DATE(YEAR(TODAY()),6,1),Fuel!$B$6:$B$605,"<="&EOMONTH(DATE(YEAR(TODAY()),6,1),0)) | D34: =SUMIFS(Costs!$G$6:$G$505,Costs!$B$6:$B$505,">="&DATE(YEAR(TODAY()),6,1),Costs!$B$6:$B$505,"<="&EOMONTH(DATE(YEAR(TODAY()),6,1),0)) | E34: =C34+D34
B35: Jul | C35: =SUMIFS(Fuel!$F$6:$F$605,Fuel!$B$6:$B$605,">="&DATE(YEAR(TODAY()),7,1),Fuel!$B$6:$B$605,"<="&EOMONTH(DATE(YEAR(TODAY()),7,1),0)) | D35: =SUMIFS(Costs!$G$6:$G$505,Costs!$B$6:$B$505,">="&DATE(YEAR(TODAY()),7,1),Costs!$B$6:$B$505,"<="&EOMONTH(DATE(YEAR(TODAY()),7,1),0)) | E35: =C35+D35
B36: Aug | C36: =SUMIFS(Fuel!$F$6:$F$605,Fuel!$B$6:$B$605,">="&DATE(YEAR(TODAY()),8,1),Fuel!$B$6:$B$605,"<="&EOMONTH(DATE(YEAR(TODAY()),8,1),0)) | D36: =SUMIFS(Costs!$G$6:$G$505,Costs!$B$6:$B$505,">="&DATE(YEAR(TODAY()),8,1),Costs!$B$6:$B$505,"<="&EOMONTH(DATE(YEAR(TODAY()),8,1),0)) | E36: =C36+D36
B37: Sep | C37: =SUMIFS(Fuel!$F$6:$F$605,Fuel!$B$6:$B$605,">="&DATE(YEAR(TODAY()),9,1),Fuel!$B$6:$B$605,"<="&EOMONTH(DATE(YEAR(TODAY()),9,1),0)) | D37: =SUMIFS(Costs!$G$6:$G$505,Costs!$B$6:$B$505,">="&DATE(YEAR(TODAY()),9,1),Costs!$B$6:$B$505,"<="&EOMONTH(DATE(YEAR(TODAY()),9,1),0)) | E37: =C37+D37
B38: Oct | C38: =SUMIFS(Fuel!$F$6:$F$605,Fuel!$B$6:$B$605,">="&DATE(YEAR(TODAY()),10,1),Fuel!$B$6:$B$605,"<="&EOMONTH(DATE(YEAR(TODAY()),10,1),0)) | D38: =SUMIFS(Costs!$G$6:$G$505,Costs!$B$6:$B$505,">="&DATE(YEAR(TODAY()),10,1),Costs!$B$6:$B$505,"<="&EOMONTH(DATE(YEAR(TODAY()),10,1),0)) | E38: =C38+D38
B39: Nov | C39: =SUMIFS(Fuel!$F$6:$F$605,Fuel!$B$6:$B$605,">="&DATE(YEAR(TODAY()),11,1),Fuel!$B$6:$B$605,"<="&EOMONTH(DATE(YEAR(TODAY()),11,1),0)) | D39: =SUMIFS(Costs!$G$6:$G$505,Costs!$B$6:$B$505,">="&DATE(YEAR(TODAY()),11,1),Costs!$B$6:$B$505,"<="&EOMONTH(DATE(YEAR(TODAY()),11,1),0)) | E39: =C39+D39
B40: Dec | C40: =SUMIFS(Fuel!$F$6:$F$605,Fuel!$B$6:$B$605,">="&DATE(YEAR(TODAY()),12,1),Fuel!$B$6:$B$605,"<="&EOMONTH(DATE(YEAR(TODAY()),12,1),0)) | D40: =SUMIFS(Costs!$G$6:$G$505,Costs!$B$6:$B$505,">="&DATE(YEAR(TODAY()),12,1),Costs!$B$6:$B$505,"<="&EOMONTH(DATE(YEAR(TODAY()),12,1),0)) | E40: =C40+D40

Sheet Cars
B2: Cars
B3: Each car once, with the odometer on the day you start the file. The rest comes from the other tabs.
B5: Car | C5: Make and model | D5: Year | E5: Plate | F5: Fuel | G5: Odometer at start | H5: Start date | I5: Odometer now | J5: =Settings!$C$4&" a day" | K5: =Settings!$C$5&" per 100 "&Settings!$C$4
B6: Blue hatchback | C6: Hatchback, 1.2 petrol | D6: 2019 | E6: AB19 CDE | F6: Petrol | G6: 41200 | H6: 45993 | I6: =IF(B6="","",MAX(N(G6),SUMIFS(Fuel!$D$6:$D$605,Fuel!$C$6:$C$605,$B6,Fuel!$O$6:$O$605,0),SUMIFS(Costs!$F$6:$F$505,Costs!$C$6:$C$505,$B6,Costs!$J$6:$J$505,0))) | J6: =IF(OR(B6="",N(G6)=0,H6="",SUMIFS(Fuel!$B$6:$B$605,Fuel!$C$6:$C$605,$B6,Fuel!$O$6:$O$605,0)<=H6),"",(SUMIFS(Fuel!$D$6:$D$605,Fuel!$C$6:$C$605,$B6,Fuel!$O$6:$O$605,0)-G6)/(SUMIFS(Fuel!$B$6:$B$605,Fuel!$C$6:$C$605,$B6,Fuel!$O$6:$O$605,0)-H6)) | K6: =IF(B6="","",IFERROR(SUMIFS(Fuel!$J$6:$J$605,Fuel!$C$6:$C$605,$B6)/SUMIFS(Fuel!$I$6:$I$605,Fuel!$C$6:$C$605,$B6)*100,""))
B7: Grey van | C7: Small van, 1.6 diesel | D7: 2016 | E7: FG16 HJK | F7: Diesel | G7: 118500 | H7: 45993 | I7: =IF(B7="","",MAX(N(G7),SUMIFS(Fuel!$D$6:$D$605,Fuel!$C$6:$C$605,$B7,Fuel!$O$6:$O$605,0),SUMIFS(Costs!$F$6:$F$505,Costs!$C$6:$C$505,$B7,Costs!$J$6:$J$505,0))) | J7: =IF(OR(B7="",N(G7)=0,H7="",SUMIFS(Fuel!$B$6:$B$605,Fuel!$C$6:$C$605,$B7,Fuel!$O$6:$O$605,0)<=H7),"",(SUMIFS(Fuel!$D$6:$D$605,Fuel!$C$6:$C$605,$B7,Fuel!$O$6:$O$605,0)-G7)/(SUMIFS(Fuel!$B$6:$B$605,Fuel!$C$6:$C$605,$B7,Fuel!$O$6:$O$605,0)-H7)) | K7: =IF(B7="","",IFERROR(SUMIFS(Fuel!$J$6:$J$605,Fuel!$C$6:$C$605,$B7)/SUMIFS(Fuel!$I$6:$I$605,Fuel!$C$6:$C$605,$B7)*100,""))
I8: =IF(B8="","",MAX(N(G8),SUMIFS(Fuel!$D$6:$D$605,Fuel!$C$6:$C$605,$B8,Fuel!$O$6:$O$605,0),SUMIFS(Costs!$F$6:$F$505,Costs!$C$6:$C$505,$B8,Costs!$J$6:$J$505,0))) | J8: =IF(OR(B8="",N(G8)=0,H8="",SUMIFS(Fuel!$B$6:$B$605,Fuel!$C$6:$C$605,$B8,Fuel!$O$6:$O$605,0)<=H8),"",(SUMIFS(Fuel!$D$6:$D$605,Fuel!$C$6:$C$605,$B8,Fuel!$O$6:$O$605,0)-G8)/(SUMIFS(Fuel!$B$6:$B$605,Fuel!$C$6:$C$605,$B8,Fuel!$O$6:$O$605,0)-H8)) | K8: =IF(B8="","",IFERROR(SUMIFS(Fuel!$J$6:$J$605,Fuel!$C$6:$C$605,$B8)/SUMIFS(Fuel!$I$6:$I$605,Fuel!$C$6:$C$605,$B8)*100,""))
I9: =IF(B9="","",MAX(N(G9),SUMIFS(Fuel!$D$6:$D$605,Fuel!$C$6:$C$605,$B9,Fuel!$O$6:$O$605,0),SUMIFS(Costs!$F$6:$F$505,Costs!$C$6:$C$505,$B9,Costs!$J$6:$J$505,0))) | J9: =IF(OR(B9="",N(G9)=0,H9="",SUMIFS(Fuel!$B$6:$B$605,Fuel!$C$6:$C$605,$B9,Fuel!$O$6:$O$605,0)<=H9),"",(SUMIFS(Fuel!$D$6:$D$605,Fuel!$C$6:$C$605,$B9,Fuel!$O$6:$O$605,0)-G9)/(SUMIFS(Fuel!$B$6:$B$605,Fuel!$C$6:$C$605,$B9,Fuel!$O$6:$O$605,0)-H9)) | K9: =IF(B9="","",IFERROR(SUMIFS(Fuel!$J$6:$J$605,Fuel!$C$6:$C$605,$B9)/SUMIFS(Fuel!$I$6:$I$605,Fuel!$C$6:$C$605,$B9)*100,""))
I10: =IF(B10="","",MAX(N(G10),SUMIFS(Fuel!$D$6:$D$605,Fuel!$C$6:$C$605,$B10,Fuel!$O$6:$O$605,0),SUMIFS(Costs!$F$6:$F$505,Costs!$C$6:$C$505,$B10,Costs!$J$6:$J$505,0))) | J10: =IF(OR(B10="",N(G10)=0,H10="",SUMIFS(Fuel!$B$6:$B$605,Fuel!$C$6:$C$605,$B10,Fuel!$O$6:$O$605,0)<=H10),"",(SUMIFS(Fuel!$D$6:$D$605,Fuel!$C$6:$C$605,$B10,Fuel!$O$6:$O$605,0)-G10)/(SUMIFS(Fuel!$B$6:$B$605,Fuel!$C$6:$C$605,$B10,Fuel!$O$6:$O$605,0)-H10)) | K10: =IF(B10="","",IFERROR(SUMIFS(Fuel!$J$6:$J$605,Fuel!$C$6:$C$605,$B10)/SUMIFS(Fuel!$I$6:$I$605,Fuel!$C$6:$C$605,$B10)*100,""))
B12: Odometer now is the highest reading in Fuel and Costs. Distance a day is the average since the start date.

Sheet Services
B2: Services
B3: What each car needs, every so far or every so many months, whichever comes first. When it is done, change the last odometer and date.
B5: Car | C5: Service | D5: ="Every ("&Settings!$C$4&")" | E5: Every (months) | F5: Last odometer | G5: Last date | H5: Next odometer | I5: Next date | J5: ="Left ("&Settings!$C$4&")" | K5: About | L5: Status | M5: Notes
B6: Blue hatchback | C6: Oil and filter | D6: 15000 | E6: 12 | F6: 38242 | G6: 46043 | H6: =IF(OR(N(D6)=0,F6=""),"",F6+D6) | I6: =IF(OR(N(E6)=0,G6=""),"",EDATE(G6,E6)) | J6: =IF(OR(H6="",ISNA(MATCH($B6,Cars!$B$6:$B$10,0))),"",H6-INDEX(Cars!$I$6:$I$10,MATCH($B6,Cars!$B$6:$B$10,0))) | K6: =IF(AND(I6="",J6=""),"",IF(IF(OR(J6="",IFERROR(N(INDEX(Cars!$J$6:$J$10,MATCH($B6,Cars!$B$6:$B$10,0))),0)<=0),"",TODAY()+INT(J6/IFERROR(N(INDEX(Cars!$J$6:$J$10,MATCH($B6,Cars!$B$6:$B$10,0))),0)))="",I6,IF(I6="",IF(OR(J6="",IFERROR(N(INDEX(Cars!$J$6:$J$10,MATCH($B6,Cars!$B$6:$B$10,0))),0)<=0),"",TODAY()+INT(J6/IFERROR(N(INDEX(Cars!$J$6:$J$10,MATCH($B6,Cars!$B$6:$B$10,0))),0))),MIN(I6,IF(OR(J6="",IFERROR(N(INDEX(Cars!$J$6:$J$10,MATCH($B6,Cars!$B$6:$B$10,0))),0)<=0),"",TODAY()+INT(J6/IFERROR(N(INDEX(Cars!$J$6:$J$10,MATCH($B6,Cars!$B$6:$B$10,0))),0))))))) | L6: =IF(K6="","",IF(OR(K6<TODAY(),AND(ISNUMBER(J6),J6<0)),"Overdue",IF(OR(K6-TODAY()<=N(Settings!$C$7),AND(ISNUMBER(J6),J6<=N(Settings!$C$6))),"Due soon","OK"))) | O6: =IF(OR(L6="",L6="OK"),"",K6+ROW()/10000000)
B7: Blue hatchback | C7: Tyre rotation | D7: 10000 | E7: 12 | F7: 45942 | G7: 46123 | H7: =IF(OR(N(D7)=0,F7=""),"",F7+D7) | I7: =IF(OR(N(E7)=0,G7=""),"",EDATE(G7,E7)) | J7: =IF(OR(H7="",ISNA(MATCH($B7,Cars!$B$6:$B$10,0))),"",H7-INDEX(Cars!$I$6:$I$10,MATCH($B7,Cars!$B$6:$B$10,0))) | K7: =IF(AND(I7="",J7=""),"",IF(IF(OR(J7="",IFERROR(N(INDEX(Cars!$J$6:$J$10,MATCH($B7,Cars!$B$6:$B$10,0))),0)<=0),"",TODAY()+INT(J7/IFERROR(N(INDEX(Cars!$J$6:$J$10,MATCH($B7,Cars!$B$6:$B$10,0))),0)))="",I7,IF(I7="",IF(OR(J7="",IFERROR(N(INDEX(Cars!$J$6:$J$10,MATCH($B7,Cars!$B$6:$B$10,0))),0)<=0),"",TODAY()+INT(J7/IFERROR(N(INDEX(Cars!$J$6:$J$10,MATCH($B7,Cars!$B$6:$B$10,0))),0))),MIN(I7,IF(OR(J7="",IFERROR(N(INDEX(Cars!$J$6:$J$10,MATCH($B7,Cars!$B$6:$B$10,0))),0)<=0),"",TODAY()+INT(J7/IFERROR(N(INDEX(Cars!$J$6:$J$10,MATCH($B7,Cars!$B$6:$B$10,0))),0))))))) | L7: =IF(K7="","",IF(OR(K7<TODAY(),AND(ISNUMBER(J7),J7<0)),"Overdue",IF(OR(K7-TODAY()<=N(Settings!$C$7),AND(ISNUMBER(J7),J7<=N(Settings!$C$6))),"Due soon","OK"))) | O7: =IF(OR(L7="",L7="OK"),"",K7+ROW()/10000000)
B8: Blue hatchback | C8: Brakes check | D8: 20000 | E8: 24 | F8: 44142 | G8: 45893 | H8: =IF(OR(N(D8)=0,F8=""),"",F8+D8) | I8: =IF(OR(N(E8)=0,G8=""),"",EDATE(G8,E8)) | J8: =IF(OR(H8="",ISNA(MATCH($B8,Cars!$B$6:$B$10,0))),"",H8-INDEX(Cars!$I$6:$I$10,MATCH($B8,Cars!$B$6:$B$10,0))) | K8: =IF(AND(I8="",J8=""),"",IF(IF(OR(J8="",IFERROR(N(INDEX(Cars!$J$6:$J$10,MATCH($B8,Cars!$B$6:$B$10,0))),0)<=0),"",TODAY()+INT(J8/IFERROR(N(INDEX(Cars!$J$6:$J$10,MATCH($B8,Cars!$B$6:$B$10,0))),0)))="",I8,IF(I8="",IF(OR(J8="",IFERROR(N(INDEX(Cars!$J$6:$J$10,MATCH($B8,Cars!$B$6:$B$10,0))),0)<=0),"",TODAY()+INT(J8/IFERROR(N(INDEX(Cars!$J$6:$J$10,MATCH($B8,Cars!$B$6:$B$10,0))),0))),MIN(I8,IF(OR(J8="",IFERROR(N(INDEX(Cars!$J$6:$J$10,MATCH($B8,Cars!$B$6:$B$10,0))),0)<=0),"",TODAY()+INT(J8/IFERROR(N(INDEX(Cars!$J$6:$J$10,MATCH($B8,Cars!$B$6:$B$10,0))),0))))))) | L8: =IF(K8="","",IF(OR(K8<TODAY(),AND(ISNUMBER(J8),J8<0)),"Overdue",IF(OR(K8-TODAY()<=N(Settings!$C$7),AND(ISNUMBER(J8),J8<=N(Settings!$C$6))),"Due soon","OK"))) | O8: =IF(OR(L8="",L8="OK"),"",K8+ROW()/10000000)
B9: Blue hatchback | C9: Air filter | D9: 30000 | E9: 24 | F9: 31142 | G9: 45593 | H9: =IF(OR(N(D9)=0,F9=""),"",F9+D9) | I9: =IF(OR(N(E9)=0,G9=""),"",EDATE(G9,E9)) | J9: =IF(OR(H9="",ISNA(MATCH($B9,Cars!$B$6:$B$10,0))),"",H9-INDEX(Cars!$I$6:$I$10,MATCH($B9,Cars!$B$6:$B$10,0))) | K9: =IF(AND(I9="",J9=""),"",IF(IF(OR(J9="",IFERROR(N(INDEX(Cars!$J$6:$J$10,MATCH($B9,Cars!$B$6:$B$10,0))),0)<=0),"",TODAY()+INT(J9/IFERROR(N(INDEX(Cars!$J$6:$J$10,MATCH($B9,Cars!$B$6:$B$10,0))),0)))="",I9,IF(I9="",IF(OR(J9="",IFERROR(N(INDEX(Cars!$J$6:$J$10,MATCH($B9,Cars!$B$6:$B$10,0))),0)<=0),"",TODAY()+INT(J9/IFERROR(N(INDEX(Cars!$J$6:$J$10,MATCH($B9,Cars!$B$6:$B$10,0))),0))),MIN(I9,IF(OR(J9="",IFERROR(N(INDEX(Cars!$J$6:$J$10,MATCH($B9,Cars!$B$6:$B$10,0))),0)<=0),"",TODAY()+INT(J9/IFERROR(N(INDEX(Cars!$J$6:$J$10,MATCH($B9,Cars!$B$6:$B$10,0))),0))))))) | L9: =IF(K9="","",IF(OR(K9<TODAY(),AND(ISNUMBER(J9),J9<0)),"Overdue",IF(OR(K9-TODAY()<=N(Settings!$C$7),AND(ISNUMBER(J9),J9<=N(Settings!$C$6))),"Due soon","OK"))) | O9: =IF(OR(L9="",L9="OK"),"",K9+ROW()/10000000)
B10: Blue hatchback | C10: Brake fluid | E10: 24 | G10: 45588 | H10: =IF(OR(N(D10)=0,F10=""),"",F10+D10) | I10: =IF(OR(N(E10)=0,G10=""),"",EDATE(G10,E10)) | J10: =IF(OR(H10="",ISNA(MATCH($B10,Cars!$B$6:$B$10,0))),"",H10-INDEX(Cars!$I$6:$I$10,MATCH($B10,Cars!$B$6:$B$10,0))) | K10: =IF(AND(I10="",J10=""),"",IF(IF(OR(J10="",IFERROR(N(INDEX(Cars!$J$6:$J$10,MATCH($B10,Cars!$B$6:$B$10,0))),0)<=0),"",TODAY()+INT(J10/IFERROR(N(INDEX(Cars!$J$6:$J$10,MATCH($B10,Cars!$B$6:$B$10,0))),0)))="",I10,IF(I10="",IF(OR(J10="",IFERROR(N(INDEX(Cars!$J$6:$J$10,MATCH($B10,Cars!$B$6:$B$10,0))),0)<=0),"",TODAY()+INT(J10/IFERROR(N(INDEX(Cars!$J$6:$J$10,MATCH($B10,Cars!$B$6:$B$10,0))),0))),MIN(I10,IF(OR(J10="",IFERROR(N(INDEX(Cars!$J$6:$J$10,MATCH($B10,Cars!$B$6:$B$10,0))),0)<=0),"",TODAY()+INT(J10/IFERROR(N(INDEX(Cars!$J$6:$J$10,MATCH($B10,Cars!$B$6:$B$10,0))),0))))))) | L10: =IF(K10="","",IF(OR(K10<TODAY(),AND(ISNUMBER(J10),J10<0)),"Overdue",IF(OR(K10-TODAY()<=N(Settings!$C$7),AND(ISNUMBER(J10),J10<=N(Settings!$C$6))),"Due soon","OK"))) | O10: =IF(OR(L10="",L10="OK"),"",K10+ROW()/10000000)
B11: Grey van | C11: Oil and filter | D11: 15000 | E11: 12 | F11: 119566 | G11: 45953 | H11: =IF(OR(N(D11)=0,F11=""),"",F11+D11) | I11: =IF(OR(N(E11)=0,G11=""),"",EDATE(G11,E11)) | J11: =IF(OR(H11="",ISNA(MATCH($B11,Cars!$B$6:$B$10,0))),"",H11-INDEX(Cars!$I$6:$I$10,MATCH($B11,Cars!$B$6:$B$10,0))) | K11: =IF(AND(I11="",J11=""),"",IF(IF(OR(J11="",IFERROR(N(INDEX(Cars!$J$6:$J$10,MATCH($B11,Cars!$B$6:$B$10,0))),0)<=0),"",TODAY()+INT(J11/IFERROR(N(INDEX(Cars!$J$6:$J$10,MATCH($B11,Cars!$B$6:$B$10,0))),0)))="",I11,IF(I11="",IF(OR(J11="",IFERROR(N(INDEX(Cars!$J$6:$J$10,MATCH($B11,Cars!$B$6:$B$10,0))),0)<=0),"",TODAY()+INT(J11/IFERROR(N(INDEX(Cars!$J$6:$J$10,MATCH($B11,Cars!$B$6:$B$10,0))),0))),MIN(I11,IF(OR(J11="",IFERROR(N(INDEX(Cars!$J$6:$J$10,MATCH($B11,Cars!$B$6:$B$10,0))),0)<=0),"",TODAY()+INT(J11/IFERROR(N(INDEX(Cars!$J$6:$J$10,MATCH($B11,Cars!$B$6:$B$10,0))),0))))))) | L11: =IF(K11="","",IF(OR(K11<TODAY(),AND(ISNUMBER(J11),J11<0)),"Overdue",IF(OR(K11-TODAY()<=N(Settings!$C$7),AND(ISNUMBER(J11),J11<=N(Settings!$C$6))),"Due soon","OK"))) | O11: =IF(OR(L11="",L11="OK"),"",K11+ROW()/10000000)
B12: Grey van | C12: Timing belt | D12: 100000 | E12: 60 | F12: 100200 | G12: 45393 | H12: =IF(OR(N(D12)=0,F12=""),"",F12+D12) | I12: =IF(OR(N(E12)=0,G12=""),"",EDATE(G12,E12)) | J12: =IF(OR(H12="",ISNA(MATCH($B12,Cars!$B$6:$B$10,0))),"",H12-INDEX(Cars!$I$6:$I$10,MATCH($B12,Cars!$B$6:$B$10,0))) | K12: =IF(AND(I12="",J12=""),"",IF(IF(OR(J12="",IFERROR(N(INDEX(Cars!$J$6:$J$10,MATCH($B12,Cars!$B$6:$B$10,0))),0)<=0),"",TODAY()+INT(J12/IFERROR(N(INDEX(Cars!$J$6:$J$10,MATCH($B12,Cars!$B$6:$B$10,0))),0)))="",I12,IF(I12="",IF(OR(J12="",IFERROR(N(INDEX(Cars!$J$6:$J$10,MATCH($B12,Cars!$B$6:$B$10,0))),0)<=0),"",TODAY()+INT(J12/IFERROR(N(INDEX(Cars!$J$6:$J$10,MATCH($B12,Cars!$B$6:$B$10,0))),0))),MIN(I12,IF(OR(J12="",IFERROR(N(INDEX(Cars!$J$6:$J$10,MATCH($B12,Cars!$B$6:$B$10,0))),0)<=0),"",TODAY()+INT(J12/IFERROR(N(INDEX(Cars!$J$6:$J$10,MATCH($B12,Cars!$B$6:$B$10,0))),0))))))) | L12: =IF(K12="","",IF(OR(K12<TODAY(),AND(ISNUMBER(J12),J12<0)),"Overdue",IF(OR(K12-TODAY()<=N(Settings!$C$7),AND(ISNUMBER(J12),J12<=N(Settings!$C$6))),"Due soon","OK"))) | O12: =IF(OR(L12="",L12="OK"),"",K12+ROW()/10000000)
B13: Grey van | C13: Tyres checked | D13: 10000 | E13: 6 | F13: 130966 | G13: 46173 | H13: =IF(OR(N(D13)=0,F13=""),"",F13+D13) | I13: =IF(OR(N(E13)=0,G13=""),"",EDATE(G13,E13)) | J13: =IF(OR(H13="",ISNA(MATCH($B13,Cars!$B$6:$B$10,0))),"",H13-INDEX(Cars!$I$6:$I$10,MATCH($B13,Cars!$B$6:$B$10,0))) | K13: =IF(AND(I13="",J13=""),"",IF(IF(OR(J13="",IFERROR(N(INDEX(Cars!$J$6:$J$10,MATCH($B13,Cars!$B$6:$B$10,0))),0)<=0),"",TODAY()+INT(J13/IFERROR(N(INDEX(Cars!$J$6:$J$10,MATCH($B13,Cars!$B$6:$B$10,0))),0)))="",I13,IF(I13="",IF(OR(J13="",IFERROR(N(INDEX(Cars!$J$6:$J$10,MATCH($B13,Cars!$B$6:$B$10,0))),0)<=0),"",TODAY()+INT(J13/IFERROR(N(INDEX(Cars!$J$6:$J$10,MATCH($B13,Cars!$B$6:$B$10,0))),0))),MIN(I13,IF(OR(J13="",IFERROR(N(INDEX(Cars!$J$6:$J$10,MATCH($B13,Cars!$B$6:$B$10,0))),0)<=0),"",TODAY()+INT(J13/IFERROR(N(INDEX(Cars!$J$6:$J$10,MATCH($B13,Cars!$B$6:$B$10,0))),0))))))) | L13: =IF(K13="","",IF(OR(K13<TODAY(),AND(ISNUMBER(J13),J13<0)),"Overdue",IF(OR(K13-TODAY()<=N(Settings!$C$7),AND(ISNUMBER(J13),J13<=N(Settings!$C$6))),"Due soon","OK"))) | O13: =IF(OR(L13="",L13="OK"),"",K13+ROW()/10000000)
B14: Grey van | C14: Coolant | E14: 48 | G14: 44993 | H14: =IF(OR(N(D14)=0,F14=""),"",F14+D14) | I14: =IF(OR(N(E14)=0,G14=""),"",EDATE(G14,E14)) | J14: =IF(OR(H14="",ISNA(MATCH($B14,Cars!$B$6:$B$10,0))),"",H14-INDEX(Cars!$I$6:$I$10,MATCH($B14,Cars!$B$6:$B$10,0))) | K14: =IF(AND(I14="",J14=""),"",IF(IF(OR(J14="",IFERROR(N(INDEX(Cars!$J$6:$J$10,MATCH($B14,Cars!$B$6:$B$10,0))),0)<=0),"",TODAY()+INT(J14/IFERROR(N(INDEX(Cars!$J$6:$J$10,MATCH($B14,Cars!$B$6:$B$10,0))),0)))="",I14,IF(I14="",IF(OR(J14="",IFERROR(N(INDEX(Cars!$J$6:$J$10,MATCH($B14,Cars!$B$6:$B$10,0))),0)<=0),"",TODAY()+INT(J14/IFERROR(N(INDEX(Cars!$J$6:$J$10,MATCH($B14,Cars!$B$6:$B$10,0))),0))),MIN(I14,IF(OR(J14="",IFERROR(N(INDEX(Cars!$J$6:$J$10,MATCH($B14,Cars!$B$6:$B$10,0))),0)<=0),"",TODAY()+INT(J14/IFERROR(N(INDEX(Cars!$J$6:$J$10,MATCH($B14,Cars!$B$6:$B$10,0))),0))))))) | L14: =IF(K14="","",IF(OR(K14<TODAY(),AND(ISNUMBER(J14),J14<0)),"Overdue",IF(OR(K14-TODAY()<=N(Settings!$C$7),AND(ISNUMBER(J14),J14<=N(Settings!$C$6))),"Due soon","OK"))) | O14: =IF(OR(L14="",L14="OK"),"",K14+ROW()/10000000)
H15: =IF(OR(N(D15)=0,F15=""),"",F15+D15) | I15: =IF(OR(N(E15)=0,G15=""),"",EDATE(G15,E15)) | J15: =IF(OR(H15="",ISNA(MATCH($B15,Cars!$B$6:$B$10,0))),"",H15-INDEX(Cars!$I$6:$I$10,MATCH($B15,Cars!$B$6:$B$10,0))) | K15: =IF(AND(I15="",J15=""),"",IF(IF(OR(J15="",IFERROR(N(INDEX(Cars!$J$6:$J$10,MATCH($B15,Cars!$B$6:$B$10,0))),0)<=0),"",TODAY()+INT(J15/IFERROR(N(INDEX(Cars!$J$6:$J$10,MATCH($B15,Cars!$B$6:$B$10,0))),0)))="",I15,IF(I15="",IF(OR(J15="",IFERROR(N(INDEX(Cars!$J$6:$J$10,MATCH($B15,Cars!$B$6:$B$10,0))),0)<=0),"",TODAY()+INT(J15/IFERROR(N(INDEX(Cars!$J$6:$J$10,MATCH($B15,Cars!$B$6:$B$10,0))),0))),MIN(I15,IF(OR(J15="",IFERROR(N(INDEX(Cars!$J$6:$J$10,MATCH($B15,Cars!$B$6:$B$10,0))),0)<=0),"",TODAY()+INT(J15/IFERROR(N(INDEX(Cars!$J$6:$J$10,MATCH($B15,Cars!$B$6:$B$10,0))),0))))))) | L15: =IF(K15="","",IF(OR(K15<TODAY(),AND(ISNUMBER(J15),J15<0)),"Overdue",IF(OR(K15-TODAY()<=N(Settings!$C$7),AND(ISNUMBER(J15),J15<=N(Settings!$C$6))),"Due soon","OK"))) | O15: =IF(OR(L15="",L15="OK"),"",K15+ROW()/10000000)
H16: =IF(OR(N(D16)=0,F16=""),"",F16+D16) | I16: =IF(OR(N(E16)=0,G16=""),"",EDATE(G16,E16)) | J16: =IF(OR(H16="",ISNA(MATCH($B16,Cars!$B$6:$B$10,0))),"",H16-INDEX(Cars!$I$6:$I$10,MATCH($B16,Cars!$B$6:$B$10,0))) | K16: =IF(AND(I16="",J16=""),"",IF(IF(OR(J16="",IFERROR(N(INDEX(Cars!$J$6:$J$10,MATCH($B16,Cars!$B$6:$B$10,0))),0)<=0),"",TODAY()+INT(J16/IFERROR(N(INDEX(Cars!$J$6:$J$10,MATCH($B16,Cars!$B$6:$B$10,0))),0)))="",I16,IF(I16="",IF(OR(J16="",IFERROR(N(INDEX(Cars!$J$6:$J$10,MATCH($B16,Cars!$B$6:$B$10,0))),0)<=0),"",TODAY()+INT(J16/IFERROR(N(INDEX(Cars!$J$6:$J$10,MATCH($B16,Cars!$B$6:$B$10,0))),0))),MIN(I16,IF(OR(J16="",IFERROR(N(INDEX(Cars!$J$6:$J$10,MATCH($B16,Cars!$B$6:$B$10,0))),0)<=0),"",TODAY()+INT(J16/IFERROR(N(INDEX(Cars!$J$6:$J$10,MATCH($B16,Cars!$B$6:$B$10,0))),0))))))) | L16: =IF(K16="","",IF(OR(K16<TODAY(),AND(ISNUMBER(J16),J16<0)),"Overdue",IF(OR(K16-TODAY()<=N(Settings!$C$7),AND(ISNUMBER(J16),J16<=N(Settings!$C$6))),"Due soon","OK"))) | O16: =IF(OR(L16="",L16="OK"),"",K16+ROW()/10000000)
H17: =IF(OR(N(D17)=0,F17=""),"",F17+D17) | I17: =IF(OR(N(E17)=0,G17=""),"",EDATE(G17,E17)) | J17: =IF(OR(H17="",ISNA(MATCH($B17,Cars!$B$6:$B$10,0))),"",H17-INDEX(Cars!$I$6:$I$10,MATCH($B17,Cars!$B$6:$B$10,0))) | K17: =IF(AND(I17="",J17=""),"",IF(IF(OR(J17="",IFERROR(N(INDEX(Cars!$J$6:$J$10,MATCH($B17,Cars!$B$6:$B$10,0))),0)<=0),"",TODAY()+INT(J17/IFERROR(N(INDEX(Cars!$J$6:$J$10,MATCH($B17,Cars!$B$6:$B$10,0))),0)))="",I17,IF(I17="",IF(OR(J17="",IFERROR(N(INDEX(Cars!$J$6:$J$10,MATCH($B17,Cars!$B$6:$B$10,0))),0)<=0),"",TODAY()+INT(J17/IFERROR(N(INDEX(Cars!$J$6:$J$10,MATCH($B17,Cars!$B$6:$B$10,0))),0))),MIN(I17,IF(OR(J17="",IFERROR(N(INDEX(Cars!$J$6:$J$10,MATCH($B17,Cars!$B$6:$B$10,0))),0)<=0),"",TODAY()+INT(J17/IFERROR(N(INDEX(Cars!$J$6:$J$10,MATCH($B17,Cars!$B$6:$B$10,0))),0))))))) | L17: =IF(K17="","",IF(OR(K17<TODAY(),AND(ISNUMBER(J17),J17<0)),"Overdue",IF(OR(K17-TODAY()<=N(Settings!$C$7),AND(ISNUMBER(J17),J17<=N(Settings!$C$6))),"Due soon","OK"))) | O17: =IF(OR(L17="",L17="OK"),"",K17+ROW()/10000000)
H18: =IF(OR(N(D18)=0,F18=""),"",F18+D18) | I18: =IF(OR(N(E18)=0,G18=""),"",EDATE(G18,E18)) | J18: =IF(OR(H18="",ISNA(MATCH($B18,Cars!$B$6:$B$10,0))),"",H18-INDEX(Cars!$I$6:$I$10,MATCH($B18,Cars!$B$6:$B$10,0))) | K18: =IF(AND(I18="",J18=""),"",IF(IF(OR(J18="",IFERROR(N(INDEX(Cars!$J$6:$J$10,MATCH($B18,Cars!$B$6:$B$10,0))),0)<=0),"",TODAY()+INT(J18/IFERROR(N(INDEX(Cars!$J$6:$J$10,MATCH($B18,Cars!$B$6:$B$10,0))),0)))="",I18,IF(I18="",IF(OR(J18="",IFERROR(N(INDEX(Cars!$J$6:$J$10,MATCH($B18,Cars!$B$6:$B$10,0))),0)<=0),"",TODAY()+INT(J18/IFERROR(N(INDEX(Cars!$J$6:$J$10,MATCH($B18,Cars!$B$6:$B$10,0))),0))),MIN(I18,IF(OR(J18="",IFERROR(N(INDEX(Cars!$J$6:$J$10,MATCH($B18,Cars!$B$6:$B$10,0))),0)<=0),"",TODAY()+INT(J18/IFERROR(N(INDEX(Cars!$J$6:$J$10,MATCH($B18,Cars!$B$6:$B$10,0))),0))))))) | L18: =IF(K18="","",IF(OR(K18<TODAY(),AND(ISNUMBER(J18),J18<0)),"Overdue",IF(OR(K18-TODAY()<=N(Settings!$C$7),AND(ISNUMBER(J18),J18<=N(Settings!$C$6))),"Due soon","OK"))) | O18: =IF(OR(L18="",L18="OK"),"",K18+ROW()/10000000)
H19: =IF(OR(N(D19)=0,F19=""),"",F19+D19) | I19: =IF(OR(N(E19)=0,G19=""),"",EDATE(G19,E19)) | J19: =IF(OR(H19="",ISNA(MATCH($B19,Cars!$B$6:$B$10,0))),"",H19-INDEX(Cars!$I$6:$I$10,MATCH($B19,Cars!$B$6:$B$10,0))) | K19: =IF(AND(I19="",J19=""),"",IF(IF(OR(J19="",IFERROR(N(INDEX(Cars!$J$6:$J$10,MATCH($B19,Cars!$B$6:$B$10,0))),0)<=0),"",TODAY()+INT(J19/IFERROR(N(INDEX(Cars!$J$6:$J$10,MATCH($B19,Cars!$B$6:$B$10,0))),0)))="",I19,IF(I19="",IF(OR(J19="",IFERROR(N(INDEX(Cars!$J$6:$J$10,MATCH($B19,Cars!$B$6:$B$10,0))),0)<=0),"",TODAY()+INT(J19/IFERROR(N(INDEX(Cars!$J$6:$J$10,MATCH($B19,Cars!$B$6:$B$10,0))),0))),MIN(I19,IF(OR(J19="",IFERROR(N(INDEX(Cars!$J$6:$J$10,MATCH($B19,Cars!$B$6:$B$10,0))),0)<=0),"",TODAY()+INT(J19/IFERROR(N(INDEX(Cars!$J$6:$J$10,MATCH($B19,Cars!$B$6:$B$10,0))),0))))))) | L19: =IF(K19="","",IF(OR(K19<TODAY(),AND(ISNUMBER(J19),J19<0)),"Overdue",IF(OR(K19-TODAY()<=N(Settings!$C$7),AND(ISNUMBER(J19),J19<=N(Settings!$C$6))),"Due soon","OK"))) | O19: =IF(OR(L19="",L19="OK"),"",K19+ROW()/10000000)
H20: =IF(OR(N(D20)=0,F20=""),"",F20+D20) | I20: =IF(OR(N(E20)=0,G20=""),"",EDATE(G20,E20)) | J20: =IF(OR(H20="",ISNA(MATCH($B20,Cars!$B$6:$B$10,0))),"",H20-INDEX(Cars!$I$6:$I$10,MATCH($B20,Cars!$B$6:$B$10,0))) | K20: =IF(AND(I20="",J20=""),"",IF(IF(OR(J20="",IFERROR(N(INDEX(Cars!$J$6:$J$10,MATCH($B20,Cars!$B$6:$B$10,0))),0)<=0),"",TODAY()+INT(J20/IFERROR(N(INDEX(Cars!$J$6:$J$10,MATCH($B20,Cars!$B$6:$B$10,0))),0)))="",I20,IF(I20="",IF(OR(J20="",IFERROR(N(INDEX(Cars!$J$6:$J$10,MATCH($B20,Cars!$B$6:$B$10,0))),0)<=0),"",TODAY()+INT(J20/IFERROR(N(INDEX(Cars!$J$6:$J$10,MATCH($B20,Cars!$B$6:$B$10,0))),0))),MIN(I20,IF(OR(J20="",IFERROR(N(INDEX(Cars!$J$6:$J$10,MATCH($B20,Cars!$B$6:$B$10,0))),0)<=0),"",TODAY()+INT(J20/IFERROR(N(INDEX(Cars!$J$6:$J$10,MATCH($B20,Cars!$B$6:$B$10,0))),0))))))) | L20: =IF(K20="","",IF(OR(K20<TODAY(),AND(ISNUMBER(J20),J20<0)),"Overdue",IF(OR(K20-TODAY()<=N(Settings!$C$7),AND(ISNUMBER(J20),J20<=N(Settings!$C$6))),"Due soon","OK"))) | O20: =IF(OR(L20="",L20="OK"),"",K20+ROW()/10000000)
H21: =IF(OR(N(D21)=0,F21=""),"",F21+D21) | I21: =IF(OR(N(E21)=0,G21=""),"",EDATE(G21,E21)) | J21: =IF(OR(H21="",ISNA(MATCH($B21,Cars!$B$6:$B$10,0))),"",H21-INDEX(Cars!$I$6:$I$10,MATCH($B21,Cars!$B$6:$B$10,0))) | K21: =IF(AND(I21="",J21=""),"",IF(IF(OR(J21="",IFERROR(N(INDEX(Cars!$J$6:$J$10,MATCH($B21,Cars!$B$6:$B$10,0))),0)<=0),"",TODAY()+INT(J21/IFERROR(N(INDEX(Cars!$J$6:$J$10,MATCH($B21,Cars!$B$6:$B$10,0))),0)))="",I21,IF(I21="",IF(OR(J21="",IFERROR(N(INDEX(Cars!$J$6:$J$10,MATCH($B21,Cars!$B$6:$B$10,0))),0)<=0),"",TODAY()+INT(J21/IFERROR(N(INDEX(Cars!$J$6:$J$10,MATCH($B21,Cars!$B$6:$B$10,0))),0))),MIN(I21,IF(OR(J21="",IFERROR(N(INDEX(Cars!$J$6:$J$10,MATCH($B21,Cars!$B$6:$B$10,0))),0)<=0),"",TODAY()+INT(J21/IFERROR(N(INDEX(Cars!$J$6:$J$10,MATCH($B21,Cars!$B$6:$B$10,0))),0))))))) | L21: =IF(K21="","",IF(OR(K21<TODAY(),AND(ISNUMBER(J21),J21<0)),"Overdue",IF(OR(K21-TODAY()<=N(Settings!$C$7),AND(ISNUMBER(J21),J21<=N(Settings!$C$6))),"Due soon","OK"))) | O21: =IF(OR(L21="",L21="OK"),"",K21+ROW()/10000000)
H22: =IF(OR(N(D22)=0,F22=""),"",F22+D22) | I22: =IF(OR(N(E22)=0,G22=""),"",EDATE(G22,E22)) | J22: =IF(OR(H22="",ISNA(MATCH($B22,Cars!$B$6:$B$10,0))),"",H22-INDEX(Cars!$I$6:$I$10,MATCH($B22,Cars!$B$6:$B$10,0))) | K22: =IF(AND(I22="",J22=""),"",IF(IF(OR(J22="",IFERROR(N(INDEX(Cars!$J$6:$J$10,MATCH($B22,Cars!$B$6:$B$10,0))),0)<=0),"",TODAY()+INT(J22/IFERROR(N(INDEX(Cars!$J$6:$J$10,MATCH($B22,Cars!$B$6:$B$10,0))),0)))="",I22,IF(I22="",IF(OR(J22="",IFERROR(N(INDEX(Cars!$J$6:$J$10,MATCH($B22,Cars!$B$6:$B$10,0))),0)<=0),"",TODAY()+INT(J22/IFERROR(N(INDEX(Cars!$J$6:$J$10,MATCH($B22,Cars!$B$6:$B$10,0))),0))),MIN(I22,IF(OR(J22="",IFERROR(N(INDEX(Cars!$J$6:$J$10,MATCH($B22,Cars!$B$6:$B$10,0))),0)<=0),"",TODAY()+INT(J22/IFERROR(N(INDEX(Cars!$J$6:$J$10,MATCH($B22,Cars!$B$6:$B$10,0))),0))))))) | L22: =IF(K22="","",IF(OR(K22<TODAY(),AND(ISNUMBER(J22),J22<0)),"Overdue",IF(OR(K22-TODAY()<=N(Settings!$C$7),AND(ISNUMBER(J22),J22<=N(Settings!$C$6))),"Due soon","OK"))) | O22: =IF(OR(L22="",L22="OK"),"",K22+ROW()/10000000)
H23: =IF(OR(N(D23)=0,F23=""),"",F23+D23) | I23: =IF(OR(N(E23)=0,G23=""),"",EDATE(G23,E23)) | J23: =IF(OR(H23="",ISNA(MATCH($B23,Cars!$B$6:$B$10,0))),"",H23-INDEX(Cars!$I$6:$I$10,MATCH($B23,Cars!$B$6:$B$10,0))) | K23: =IF(AND(I23="",J23=""),"",IF(IF(OR(J23="",IFERROR(N(INDEX(Cars!$J$6:$J$10,MATCH($B23,Cars!$B$6:$B$10,0))),0)<=0),"",TODAY()+INT(J23/IFERROR(N(INDEX(Cars!$J$6:$J$10,MATCH($B23,Cars!$B$6:$B$10,0))),0)))="",I23,IF(I23="",IF(OR(J23="",IFERROR(N(INDEX(Cars!$J$6:$J$10,MATCH($B23,Cars!$B$6:$B$10,0))),0)<=0),"",TODAY()+INT(J23/IFERROR(N(INDEX(Cars!$J$6:$J$10,MATCH($B23,Cars!$B$6:$B$10,0))),0))),MIN(I23,IF(OR(J23="",IFERROR(N(INDEX(Cars!$J$6:$J$10,MATCH($B23,Cars!$B$6:$B$10,0))),0)<=0),"",TODAY()+INT(J23/IFERROR(N(INDEX(Cars!$J$6:$J$10,MATCH($B23,Cars!$B$6:$B$10,0))),0))))))) | L23: =IF(K23="","",IF(OR(K23<TODAY(),AND(ISNUMBER(J23),J23<0)),"Overdue",IF(OR(K23-TODAY()<=N(Settings!$C$7),AND(ISNUMBER(J23),J23<=N(Settings!$C$6))),"Due soon","OK"))) | O23: =IF(OR(L23="",L23="OK"),"",K23+ROW()/10000000)
H24: =IF(OR(N(D24)=0,F24=""),"",F24+D24) | I24: =IF(OR(N(E24)=0,G24=""),"",EDATE(G24,E24)) | J24: =IF(OR(H24="",ISNA(MATCH($B24,Cars!$B$6:$B$10,0))),"",H24-INDEX(Cars!$I$6:$I$10,MATCH($B24,Cars!$B$6:$B$10,0))) | K24: =IF(AND(I24="",J24=""),"",IF(IF(OR(J24="",IFERROR(N(INDEX(Cars!$J$6:$J$10,MATCH($B24,Cars!$B$6:$B$10,0))),0)<=0),"",TODAY()+INT(J24/IFERROR(N(INDEX(Cars!$J$6:$J$10,MATCH($B24,Cars!$B$6:$B$10,0))),0)))="",I24,IF(I24="",IF(OR(J24="",IFERROR(N(INDEX(Cars!$J$6:$J$10,MATCH($B24,Cars!$B$6:$B$10,0))),0)<=0),"",TODAY()+INT(J24/IFERROR(N(INDEX(Cars!$J$6:$J$10,MATCH($B24,Cars!$B$6:$B$10,0))),0))),MIN(I24,IF(OR(J24="",IFERROR(N(INDEX(Cars!$J$6:$J$10,MATCH($B24,Cars!$B$6:$B$10,0))),0)<=0),"",TODAY()+INT(J24/IFERROR(N(INDEX(Cars!$J$6:$J$10,MATCH($B24,Cars!$B$6:$B$10,0))),0))))))) | L24: =IF(K24="","",IF(OR(K24<TODAY(),AND(ISNUMBER(J24),J24<0)),"Overdue",IF(OR(K24-TODAY()<=N(Settings!$C$7),AND(ISNUMBER(J24),J24<=N(Settings!$C$6))),"Due soon","OK"))) | O24: =IF(OR(L24="",L24="OK"),"",K24+ROW()/10000000)
H25: =IF(OR(N(D25)=0,F25=""),"",F25+D25) | I25: =IF(OR(N(E25)=0,G25=""),"",EDATE(G25,E25)) | J25: =IF(OR(H25="",ISNA(MATCH($B25,Cars!$B$6:$B$10,0))),"",H25-INDEX(Cars!$I$6:$I$10,MATCH($B25,Cars!$B$6:$B$10,0))) | K25: =IF(AND(I25="",J25=""),"",IF(IF(OR(J25="",IFERROR(N(INDEX(Cars!$J$6:$J$10,MATCH($B25,Cars!$B$6:$B$10,0))),0)<=0),"",TODAY()+INT(J25/IFERROR(N(INDEX(Cars!$J$6:$J$10,MATCH($B25,Cars!$B$6:$B$10,0))),0)))="",I25,IF(I25="",IF(OR(J25="",IFERROR(N(INDEX(Cars!$J$6:$J$10,MATCH($B25,Cars!$B$6:$B$10,0))),0)<=0),"",TODAY()+INT(J25/IFERROR(N(INDEX(Cars!$J$6:$J$10,MATCH($B25,Cars!$B$6:$B$10,0))),0))),MIN(I25,IF(OR(J25="",IFERROR(N(INDEX(Cars!$J$6:$J$10,MATCH($B25,Cars!$B$6:$B$10,0))),0)<=0),"",TODAY()+INT(J25/IFERROR(N(INDEX(Cars!$J$6:$J$10,MATCH($B25,Cars!$B$6:$B$10,0))),0))))))) | L25: =IF(K25="","",IF(OR(K25<TODAY(),AND(ISNUMBER(J25),J25<0)),"Overdue",IF(OR(K25-TODAY()<=N(Settings!$C$7),AND(ISNUMBER(J25),J25<=N(Settings!$C$6))),"Due soon","OK"))) | O25: =IF(OR(L25="",L25="OK"),"",K25+ROW()/10000000)
H26: =IF(OR(N(D26)=0,F26=""),"",F26+D26) | I26: =IF(OR(N(E26)=0,G26=""),"",EDATE(G26,E26)) | J26: =IF(OR(H26="",ISNA(MATCH($B26,Cars!$B$6:$B$10,0))),"",H26-INDEX(Cars!$I$6:$I$10,MATCH($B26,Cars!$B$6:$B$10,0))) | K26: =IF(AND(I26="",J26=""),"",IF(IF(OR(J26="",IFERROR(N(INDEX(Cars!$J$6:$J$10,MATCH($B26,Cars!$B$6:$B$10,0))),0)<=0),"",TODAY()+INT(J26/IFERROR(N(INDEX(Cars!$J$6:$J$10,MATCH($B26,Cars!$B$6:$B$10,0))),0)))="",I26,IF(I26="",IF(OR(J26="",IFERROR(N(INDEX(Cars!$J$6:$J$10,MATCH($B26,Cars!$B$6:$B$10,0))),0)<=0),"",TODAY()+INT(J26/IFERROR(N(INDEX(Cars!$J$6:$J$10,MATCH($B26,Cars!$B$6:$B$10,0))),0))),MIN(I26,IF(OR(J26="",IFERROR(N(INDEX(Cars!$J$6:$J$10,MATCH($B26,Cars!$B$6:$B$10,0))),0)<=0),"",TODAY()+INT(J26/IFERROR(N(INDEX(Cars!$J$6:$J$10,MATCH($B26,Cars!$B$6:$B$10,0))),0))))))) | L26: =IF(K26="","",IF(OR(K26<TODAY(),AND(ISNUMBER(J26),J26<0)),"Overdue",IF(OR(K26-TODAY()<=N(Settings!$C$7),AND(ISNUMBER(J26),J26<=N(Settings!$C$6))),"Due soon","OK"))) | O26: =IF(OR(L26="",L26="OK"),"",K26+ROW()/10000000)
... H65: =IF(OR(N(D65)=0,F65=""),"",F65+D65) | I65: =IF(OR(N(E65)=0,G65=""),"",EDATE(G65,E65)) | J65: =IF(OR(H65="",ISNA(MATCH($B65,Cars!$B$6:$B$10,0))),"",H65-INDEX(Cars!$I$6:$I$10,MATCH($B65,Cars!$B$6:$B$10,0))) | K65: =IF(AND(I65="",J65=""),"",IF(IF(OR(J65="",IFERROR(N(INDEX(Cars!$J$6:$J$10,MATCH($B65,Cars!$B$6:$B$10,0))),0)<=0),"",TODAY()+INT(J65/IFERROR(N(INDEX(Cars!$J$6:$J$10,MATCH($B65,Cars!$B$6:$B$10,0))),0)))="",I65,IF(I65="",IF(OR(J65="",IFERROR(N(INDEX(Cars!$J$6:$J$10,MATCH($B65,Cars!$B$6:$B$10,0))),0)<=0),"",TODAY()+INT(J65/IFERROR(N(INDEX(Cars!$J$6:$J$10,MATCH($B65,Cars!$B$6:$B$10,0))),0))),MIN(I65,IF(OR(J65="",IFERROR(N(INDEX(Cars!$J$6:$J$10,MATCH($B65,Cars!$B$6:$B$10,0))),0)<=0),"",TODAY()+INT(J65/IFERROR(N(INDEX(Cars!$J$6:$J$10,MATCH($B65,Cars!$B$6:$B$10,0))),0))))))) | L65: =IF(K65="","",IF(OR(K65<TODAY(),AND(ISNUMBER(J65),J65<0)),"Overdue",IF(OR(K65-TODAY()<=N(Settings!$C$7),AND(ISNUMBER(J65),J65<=N(Settings!$C$6))),"Due soon","OK"))) | O65: =IF(OR(L65="",L65="OK"),"",K65+ROW()/10000000)
B66: About: the earlier of the next date and the day the car should reach the next odometer at its usual pace.

Sheet Fuel
B2: Fuel
B3: One line per fill-up. Put an x under Full when you fill the tank: the consumption is worked out from one full tank to the next.
B5: Date | C5: Car | D5: Odometer | E5: ="Fuel ("&Settings!$C$5&")" | F5: Paid | G5: Full | H5: Price | I5: ="Distance ("&Settings!$C$4&")" | J5: ="Used ("&Settings!$C$5&")" | K5: =Settings!$C$5&" per 100 "&Settings!$C$4 | L5: =Settings!$C$4&" per "&Settings!$C$5
B6: 46002 | C6: Blue hatchback | D6: 41575 | E6: 23.48 | F6: 40.9 | G6: x | H6: =IF(OR(N(E6)=0,F6=""),"",F6/E6) | I6: =IF(R6="","",D6-R6) | J6: =IF(R6="","",SUMIFS(Fuel!$E$6:$E$605,Fuel!$C$6:$C$605,C6,Fuel!$D$6:$D$605,">"&R6,Fuel!$D$6:$D$605,"<="&D6)) | K6: =IF(OR(I6="",N(I6)=0),"",J6/I6*100) | L6: =IF(OR(J6="",N(J6)=0),"",I6/J6) | N6: =IF(OR(C6="",N(D6)=0),"",D6+ROW()/10000000) | O6: =IF(N6="","",COUNTIFS(Fuel!$C$6:$C$605,C6,Fuel!$N$6:$N$605,">"&N6)) | P6: =IF(OR(N6="",G6=""),"",COUNTIFS(Fuel!$C$6:$C$605,C6,Fuel!$G$6:$G$605,"<>",Fuel!$N$6:$N$605,"<"&N6)) | R6: =IF(OR(P6="",N(P6)=0),"",SUMIFS(Fuel!$D$6:$D$605,Fuel!$C$6:$C$605,C6,Fuel!$P$6:$P$605,P6-1))
B7: 46002 | C7: Grey van | D7: 119019 | E7: 39.48 | F7: 66.9 | G7: x | H7: =IF(OR(N(E7)=0,F7=""),"",F7/E7) | I7: =IF(R7="","",D7-R7) | J7: =IF(R7="","",SUMIFS(Fuel!$E$6:$E$605,Fuel!$C$6:$C$605,C7,Fuel!$D$6:$D$605,">"&R7,Fuel!$D$6:$D$605,"<="&D7)) | K7: =IF(OR(I7="",N(I7)=0),"",J7/I7*100) | L7: =IF(OR(J7="",N(J7)=0),"",I7/J7) | N7: =IF(OR(C7="",N(D7)=0),"",D7+ROW()/10000000) | O7: =IF(N7="","",COUNTIFS(Fuel!$C$6:$C$605,C7,Fuel!$N$6:$N$605,">"&N7)) | P7: =IF(OR(N7="",G7=""),"",COUNTIFS(Fuel!$C$6:$C$605,C7,Fuel!$G$6:$G$605,"<>",Fuel!$N$6:$N$605,"<"&N7)) | R7: =IF(OR(P7="",N(P7)=0),"",SUMIFS(Fuel!$D$6:$D$605,Fuel!$C$6:$C$605,C7,Fuel!$P$6:$P$605,P7-1))
B8: 46012 | C8: Blue hatchback | D8: 41899 | E8: 20.11 | F8: 34.42 | G8: x | H8: =IF(OR(N(E8)=0,F8=""),"",F8/E8) | I8: =IF(R8="","",D8-R8) | J8: =IF(R8="","",SUMIFS(Fuel!$E$6:$E$605,Fuel!$C$6:$C$605,C8,Fuel!$D$6:$D$605,">"&R8,Fuel!$D$6:$D$605,"<="&D8)) | K8: =IF(OR(I8="",N(I8)=0),"",J8/I8*100) | L8: =IF(OR(J8="",N(J8)=0),"",I8/J8) | N8: =IF(OR(C8="",N(D8)=0),"",D8+ROW()/10000000) | O8: =IF(N8="","",COUNTIFS(Fuel!$C$6:$C$605,C8,Fuel!$N$6:$N$605,">"&N8)) | P8: =IF(OR(N8="",G8=""),"",COUNTIFS(Fuel!$C$6:$C$605,C8,Fuel!$G$6:$G$605,"<>",Fuel!$N$6:$N$605,"<"&N8)) | R8: =IF(OR(P8="",N(P8)=0),"",SUMIFS(Fuel!$D$6:$D$605,Fuel!$C$6:$C$605,C8,Fuel!$P$6:$P$605,P8-1))
B9: 46017 | C9: Grey van | D9: 119848 | E9: 66.92 | F9: 109.54 | G9: x | H9: =IF(OR(N(E9)=0,F9=""),"",F9/E9) | I9: =IF(R9="","",D9-R9) | J9: =IF(R9="","",SUMIFS(Fuel!$E$6:$E$605,Fuel!$C$6:$C$605,C9,Fuel!$D$6:$D$605,">"&R9,Fuel!$D$6:$D$605,"<="&D9)) | K9: =IF(OR(I9="",N(I9)=0),"",J9/I9*100) | L9: =IF(OR(J9="",N(J9)=0),"",I9/J9) | N9: =IF(OR(C9="",N(D9)=0),"",D9+ROW()/10000000) | O9: =IF(N9="","",COUNTIFS(Fuel!$C$6:$C$605,C9,Fuel!$N$6:$N$605,">"&N9)) | P9: =IF(OR(N9="",G9=""),"",COUNTIFS(Fuel!$C$6:$C$605,C9,Fuel!$G$6:$G$605,"<>",Fuel!$N$6:$N$605,"<"&N9)) | R9: =IF(OR(P9="",N(P9)=0),"",SUMIFS(Fuel!$D$6:$D$605,Fuel!$C$6:$C$605,C9,Fuel!$P$6:$P$605,P9-1))
B10: 46022 | C10: Blue hatchback | D10: 42225 | E10: 19.56 | F10: 34.56 | G10: x | H10: =IF(OR(N(E10)=0,F10=""),"",F10/E10) | I10: =IF(R10="","",D10-R10) | J10: =IF(R10="","",SUMIFS(Fuel!$E$6:$E$605,Fuel!$C$6:$C$605,C10,Fuel!$D$6:$D$605,">"&R10,Fuel!$D$6:$D$605,"<="&D10)) | K10: =IF(OR(I10="",N(I10)=0),"",J10/I10*100) | L10: =IF(OR(J10="",N(J10)=0),"",I10/J10) | N10: =IF(OR(C10="",N(D10)=0),"",D10+ROW()/10000000) | O10: =IF(N10="","",COUNTIFS(Fuel!$C$6:$C$605,C10,Fuel!$N$6:$N$605,">"&N10)) | P10: =IF(OR(N10="",G10=""),"",COUNTIFS(Fuel!$C$6:$C$605,C10,Fuel!$G$6:$G$605,"<>",Fuel!$N$6:$N$605,"<"&N10)) | R10: =IF(OR(P10="",N(P10)=0),"",SUMIFS(Fuel!$D$6:$D$605,Fuel!$C$6:$C$605,C10,Fuel!$P$6:$P$605,P10-1))
B11: 46032 | C11: Grey van | D11: 120760 | E11: 69.8 | F11: 117.41 | G11: x | H11: =IF(OR(N(E11)=0,F11=""),"",F11/E11) | I11: =IF(R11="","",D11-R11) | J11: =IF(R11="","",SUMIFS(Fuel!$E$6:$E$605,Fuel!$C$6:$C$605,C11,Fuel!$D$6:$D$605,">"&R11,Fuel!$D$6:$D$605,"<="&D11)) | K11: =IF(OR(I11="",N(I11)=0),"",J11/I11*100) | L11: =IF(OR(J11="",N(J11)=0),"",I11/J11) | N11: =IF(OR(C11="",N(D11)=0),"",D11+ROW()/10000000) | O11: =IF(N11="","",COUNTIFS(Fuel!$C$6:$C$605,C11,Fuel!$N$6:$N$605,">"&N11)) | P11: =IF(OR(N11="",G11=""),"",COUNTIFS(Fuel!$C$6:$C$605,C11,Fuel!$G$6:$G$605,"<>",Fuel!$N$6:$N$605,"<"&N11)) | R11: =IF(OR(P11="",N(P11)=0),"",SUMIFS(Fuel!$D$6:$D$605,Fuel!$C$6:$C$605,C11,Fuel!$P$6:$P$605,P11-1))
B12: 46035 | C12: Blue hatchback | D12: 42657 | E12: 25.53 | F12: 43.23 | G12: x | H12: =IF(OR(N(E12)=0,F12=""),"",F12/E12) | I12: =IF(R12="","",D12-R12) | J12: =IF(R12="","",SUMIFS(Fuel!$E$6:$E$605,Fuel!$C$6:$C$605,C12,Fuel!$D$6:$D$605,">"&R12,Fuel!$D$6:$D$605,"<="&D12)) | K12: =IF(OR(I12="",N(I12)=0),"",J12/I12*100) | L12: =IF(OR(J12="",N(J12)=0),"",I12/J12) | N12: =IF(OR(C12="",N(D12)=0),"",D12+ROW()/10000000) | O12: =IF(N12="","",COUNTIFS(Fuel!$C$6:$C$605,C12,Fuel!$N$6:$N$605,">"&N12)) | P12: =IF(OR(N12="",G12=""),"",COUNTIFS(Fuel!$C$6:$C$605,C12,Fuel!$G$6:$G$605,"<>",Fuel!$N$6:$N$605,"<"&N12)) | R12: =IF(OR(P12="",N(P12)=0),"",SUMIFS(Fuel!$D$6:$D$605,Fuel!$C$6:$C$605,C12,Fuel!$P$6:$P$605,P12-1))
B13: 46041 | C13: Grey van | D13: 121245 | E13: 22.65 | F13: 38.07 | H13: =IF(OR(N(E13)=0,F13=""),"",F13/E13) | I13: =IF(R13="","",D13-R13) | J13: =IF(R13="","",SUMIFS(Fuel!$E$6:$E$605,Fuel!$C$6:$C$605,C13,Fuel!$D$6:$D$605,">"&R13,Fuel!$D$6:$D$605,"<="&D13)) | K13: =IF(OR(I13="",N(I13)=0),"",J13/I13*100) | L13: =IF(OR(J13="",N(J13)=0),"",I13/J13) | N13: =IF(OR(C13="",N(D13)=0),"",D13+ROW()/10000000) | O13: =IF(N13="","",COUNTIFS(Fuel!$C$6:$C$605,C13,Fuel!$N$6:$N$605,">"&N13)) | P13: =IF(OR(N13="",G13=""),"",COUNTIFS(Fuel!$C$6:$C$605,C13,Fuel!$G$6:$G$605,"<>",Fuel!$N$6:$N$605,"<"&N13)) | R13: =IF(OR(P13="",N(P13)=0),"",SUMIFS(Fuel!$D$6:$D$605,Fuel!$C$6:$C$605,C13,Fuel!$P$6:$P$605,P13-1))
B14: 46044 | C14: Blue hatchback | D14: 42988 | E14: 21.52 | F14: 37.45 | G14: x | H14: =IF(OR(N(E14)=0,F14=""),"",F14/E14) | I14: =IF(R14="","",D14-R14) | J14: =IF(R14="","",SUMIFS(Fuel!$E$6:$E$605,Fuel!$C$6:$C$605,C14,Fuel!$D$6:$D$605,">"&R14,Fuel!$D$6:$D$605,"<="&D14)) | K14: =IF(OR(I14="",N(I14)=0),"",J14/I14*100) | L14: =IF(OR(J14="",N(J14)=0),"",I14/J14) | N14: =IF(OR(C14="",N(D14)=0),"",D14+ROW()/10000000) | O14: =IF(N14="","",COUNTIFS(Fuel!$C$6:$C$605,C14,Fuel!$N$6:$N$605,">"&N14)) | P14: =IF(OR(N14="",G14=""),"",COUNTIFS(Fuel!$C$6:$C$605,C14,Fuel!$G$6:$G$605,"<>",Fuel!$N$6:$N$605,"<"&N14)) | R14: =IF(OR(P14="",N(P14)=0),"",SUMIFS(Fuel!$D$6:$D$605,Fuel!$C$6:$C$605,C14,Fuel!$P$6:$P$605,P14-1))
B15: 46055 | C15: Grey van | D15: 122162 | E15: 89.71 | F15: 149.82 | G15: x | H15: =IF(OR(N(E15)=0,F15=""),"",F15/E15) | I15: =IF(R15="","",D15-R15) | J15: =IF(R15="","",SUMIFS(Fuel!$E$6:$E$605,Fuel!$C$6:$C$605,C15,Fuel!$D$6:$D$605,">"&R15,Fuel!$D$6:$D$605,"<="&D15)) | K15: =IF(OR(I15="",N(I15)=0),"",J15/I15*100) | L15: =IF(OR(J15="",N(J15)=0),"",I15/J15) | N15: =IF(OR(C15="",N(D15)=0),"",D15+ROW()/10000000) | O15: =IF(N15="","",COUNTIFS(Fuel!$C$6:$C$605,C15,Fuel!$N$6:$N$605,">"&N15)) | P15: =IF(OR(N15="",G15=""),"",COUNTIFS(Fuel!$C$6:$C$605,C15,Fuel!$G$6:$G$605,"<>",Fuel!$N$6:$N$605,"<"&N15)) | R15: =IF(OR(P15="",N(P15)=0),"",SUMIFS(Fuel!$D$6:$D$605,Fuel!$C$6:$C$605,C15,Fuel!$P$6:$P$605,P15-1))
B16: 46059 | C16: Blue hatchback | D16: 43474 | E16: 18.97 | F16: 32.64 | H16: =IF(OR(N(E16)=0,F16=""),"",F16/E16) | I16: =IF(R16="","",D16-R16) | J16: =IF(R16="","",SUMIFS(Fuel!$E$6:$E$605,Fuel!$C$6:$C$605,C16,Fuel!$D$6:$D$605,">"&R16,Fuel!$D$6:$D$605,"<="&D16)) | K16: =IF(OR(I16="",N(I16)=0),"",J16/I16*100) | L16: =IF(OR(J16="",N(J16)=0),"",I16/J16) | N16: =IF(OR(C16="",N(D16)=0),"",D16+ROW()/10000000) | O16: =IF(N16="","",COUNTIFS(Fuel!$C$6:$C$605,C16,Fuel!$N$6:$N$605,">"&N16)) | P16: =IF(OR(N16="",G16=""),"",COUNTIFS(Fuel!$C$6:$C$605,C16,Fuel!$G$6:$G$605,"<>",Fuel!$N$6:$N$605,"<"&N16)) | R16: =IF(OR(P16="",N(P16)=0),"",SUMIFS(Fuel!$D$6:$D$605,Fuel!$C$6:$C$605,C16,Fuel!$P$6:$P$605,P16-1))
B17: 46067 | C17: Grey van | D17: 122914 | E17: 56.89 | F17: 94.09 | G17: x | H17: =IF(OR(N(E17)=0,F17=""),"",F17/E17) | I17: =IF(R17="","",D17-R17) | J17: =IF(R17="","",SUMIFS(Fuel!$E$6:$E$605,Fuel!$C$6:$C$605,C17,Fuel!$D$6:$D$605,">"&R17,Fuel!$D$6:$D$605,"<="&D17)) | K17: =IF(OR(I17="",N(I17)=0),"",J17/I17*100) | L17: =IF(OR(J17="",N(J17)=0),"",I17/J17) | N17: =IF(OR(C17="",N(D17)=0),"",D17+ROW()/10000000) | O17: =IF(N17="","",COUNTIFS(Fuel!$C$6:$C$605,C17,Fuel!$N$6:$N$605,">"&N17)) | P17: =IF(OR(N17="",G17=""),"",COUNTIFS(Fuel!$C$6:$C$605,C17,Fuel!$G$6:$G$605,"<>",Fuel!$N$6:$N$605,"<"&N17)) | R17: =IF(OR(P17="",N(P17)=0),"",SUMIFS(Fuel!$D$6:$D$605,Fuel!$C$6:$C$605,C17,Fuel!$P$6:$P$605,P17-1))
B18: 46073 | C18: Blue hatchback | D18: 44053 | E18: 49.96 | F18: 86.51 | G18: x | H18: =IF(OR(N(E18)=0,F18=""),"",F18/E18) | I18: =IF(R18="","",D18-R18) | J18: =IF(R18="","",SUMIFS(Fuel!$E$6:$E$605,Fuel!$C$6:$C$605,C18,Fuel!$D$6:$D$605,">"&R18,Fuel!$D$6:$D$605,"<="&D18)) | K18: =IF(OR(I18="",N(I18)=0),"",J18/I18*100) | L18: =IF(OR(J18="",N(J18)=0),"",I18/J18) | N18: =IF(OR(C18="",N(D18)=0),"",D18+ROW()/10000000) | O18: =IF(N18="","",COUNTIFS(Fuel!$C$6:$C$605,C18,Fuel!$N$6:$N$605,">"&N18)) | P18: =IF(OR(N18="",G18=""),"",COUNTIFS(Fuel!$C$6:$C$605,C18,Fuel!$G$6:$G$605,"<>",Fuel!$N$6:$N$605,"<"&N18)) | R18: =IF(OR(P18="",N(P18)=0),"",SUMIFS(Fuel!$D$6:$D$605,Fuel!$C$6:$C$605,C18,Fuel!$P$6:$P$605,P18-1))
B19: 46080 | C19: Grey van | D19: 123584 | E19: 53.64 | F19: 90.22 | G19: x | H19: =IF(OR(N(E19)=0,F19=""),"",F19/E19) | I19: =IF(R19="","",D19-R19) | J19: =IF(R19="","",SUMIFS(Fuel!$E$6:$E$605,Fuel!$C$6:$C$605,C19,Fuel!$D$6:$D$605,">"&R19,Fuel!$D$6:$D$605,"<="&D19)) | K19: =IF(OR(I19="",N(I19)=0),"",J19/I19*100) | L19: =IF(OR(J19="",N(J19)=0),"",I19/J19) | N19: =IF(OR(C19="",N(D19)=0),"",D19+ROW()/10000000) | O19: =IF(N19="","",COUNTIFS(Fuel!$C$6:$C$605,C19,Fuel!$N$6:$N$605,">"&N19)) | P19: =IF(OR(N19="",G19=""),"",COUNTIFS(Fuel!$C$6:$C$605,C19,Fuel!$G$6:$G$605,"<>",Fuel!$N$6:$N$605,"<"&N19)) | R19: =IF(OR(P19="",N(P19)=0),"",SUMIFS(Fuel!$D$6:$D$605,Fuel!$C$6:$C$605,C19,Fuel!$P$6:$P$605,P19-1))
B20: 46087 | C20: Blue hatchback | D20: 44574 | E20: 31.4 | F20: 55.42 | G20: x | H20: =IF(OR(N(E20)=0,F20=""),"",F20/E20) | I20: =IF(R20="","",D20-R20) | J20: =IF(R20="","",SUMIFS(Fuel!$E$6:$E$605,Fuel!$C$6:$C$605,C20,Fuel!$D$6:$D$605,">"&R20,Fuel!$D$6:$D$605,"<="&D20)) | K20: =IF(OR(I20="",N(I20)=0),"",J20/I20*100) | L20: =IF(OR(J20="",N(J20)=0),"",I20/J20) | N20: =IF(OR(C20="",N(D20)=0),"",D20+ROW()/10000000) | O20: =IF(N20="","",COUNTIFS(Fuel!$C$6:$C$605,C20,Fuel!$N$6:$N$605,">"&N20)) | P20: =IF(OR(N20="",G20=""),"",COUNTIFS(Fuel!$C$6:$C$605,C20,Fuel!$G$6:$G$605,"<>",Fuel!$N$6:$N$605,"<"&N20)) | R20: =IF(OR(P20="",N(P20)=0),"",SUMIFS(Fuel!$D$6:$D$605,Fuel!$C$6:$C$605,C20,Fuel!$P$6:$P$605,P20-1))
B21: 46093 | C21: Grey van | D21: 124181 | E21: 46.53 | F21: 80.43 | G21: x | H21: =IF(OR(N(E21)=0,F21=""),"",F21/E21) | I21: =IF(R21="","",D21-R21) | J21: =IF(R21="","",SUMIFS(Fuel!$E$6:$E$605,Fuel!$C$6:$C$605,C21,Fuel!$D$6:$D$605,">"&R21,Fuel!$D$6:$D$605,"<="&D21)) | K21: =IF(OR(I21="",N(I21)=0),"",J21/I21*100) | L21: =IF(OR(J21="",N(J21)=0),"",I21/J21) | N21: =IF(OR(C21="",N(D21)=0),"",D21+ROW()/10000000) | O21: =IF(N21="","",COUNTIFS(Fuel!$C$6:$C$605,C21,Fuel!$N$6:$N$605,">"&N21)) | P21: =IF(OR(N21="",G21=""),"",COUNTIFS(Fuel!$C$6:$C$605,C21,Fuel!$G$6:$G$605,"<>",Fuel!$N$6:$N$605,"<"&N21)) | R21: =IF(OR(P21="",N(P21)=0),"",SUMIFS(Fuel!$D$6:$D$605,Fuel!$C$6:$C$605,C21,Fuel!$P$6:$P$605,P21-1))
B22: 46098 | C22: Blue hatchback | D22: 45014 | E22: 26.7 | F22: 45.98 | G22: x | H22: =IF(OR(N(E22)=0,F22=""),"",F22/E22) | I22: =IF(R22="","",D22-R22) | J22: =IF(R22="","",SUMIFS(Fuel!$E$6:$E$605,Fuel!$C$6:$C$605,C22,Fuel!$D$6:$D$605,">"&R22,Fuel!$D$6:$D$605,"<="&D22)) | K22: =IF(OR(I22="",N(I22)=0),"",J22/I22*100) | L22: =IF(OR(J22="",N(J22)=0),"",I22/J22) | N22: =IF(OR(C22="",N(D22)=0),"",D22+ROW()/10000000) | O22: =IF(N22="","",COUNTIFS(Fuel!$C$6:$C$605,C22,Fuel!$N$6:$N$605,">"&N22)) | P22: =IF(OR(N22="",G22=""),"",COUNTIFS(Fuel!$C$6:$C$605,C22,Fuel!$G$6:$G$605,"<>",Fuel!$N$6:$N$605,"<"&N22)) | R22: =IF(OR(P22="",N(P22)=0),"",SUMIFS(Fuel!$D$6:$D$605,Fuel!$C$6:$C$605,C22,Fuel!$P$6:$P$605,P22-1))
B23: 46102 | C23: Grey van | D23: 124705 | E23: 41.13 | F23: 68.65 | G23: x | H23: =IF(OR(N(E23)=0,F23=""),"",F23/E23) | I23: =IF(R23="","",D23-R23) | J23: =IF(R23="","",SUMIFS(Fuel!$E$6:$E$605,Fuel!$C$6:$C$605,C23,Fuel!$D$6:$D$605,">"&R23,Fuel!$D$6:$D$605,"<="&D23)) | K23: =IF(OR(I23="",N(I23)=0),"",J23/I23*100) | L23: =IF(OR(J23="",N(J23)=0),"",I23/J23) | N23: =IF(OR(C23="",N(D23)=0),"",D23+ROW()/10000000) | O23: =IF(N23="","",COUNTIFS(Fuel!$C$6:$C$605,C23,Fuel!$N$6:$N$605,">"&N23)) | P23: =IF(OR(N23="",G23=""),"",COUNTIFS(Fuel!$C$6:$C$605,C23,Fuel!$G$6:$G$605,"<>",Fuel!$N$6:$N$605,"<"&N23)) | R23: =IF(OR(P23="",N(P23)=0),"",SUMIFS(Fuel!$D$6:$D$605,Fuel!$C$6:$C$605,C23,Fuel!$P$6:$P$605,P23-1))
B24: 46109 | C24: Blue hatchback | D24: 45470 | E24: 28.65 | F24: 50.42 | G24: x | H24: =IF(OR(N(E24)=0,F24=""),"",F24/E24) | I24: =IF(R24="","",D24-R24) | J24: =IF(R24="","",SUMIFS(Fuel!$E$6:$E$605,Fuel!$C$6:$C$605,C24,Fuel!$D$6:$D$605,">"&R24,Fuel!$D$6:$D$605,"<="&D24)) | K24: =IF(OR(I24="",N(I24)=0),"",J24/I24*100) | L24: =IF(OR(J24="",N(J24)=0),"",I24/J24) | N24: =IF(OR(C24="",N(D24)=0),"",D24+ROW()/10000000) | O24: =IF(N24="","",COUNTIFS(Fuel!$C$6:$C$605,C24,Fuel!$N$6:$N$605,">"&N24)) | P24: =IF(OR(N24="",G24=""),"",COUNTIFS(Fuel!$C$6:$C$605,C24,Fuel!$G$6:$G$605,"<>",Fuel!$N$6:$N$605,"<"&N24)) | R24: =IF(OR(P24="",N(P24)=0),"",SUMIFS(Fuel!$D$6:$D$605,Fuel!$C$6:$C$605,C24,Fuel!$P$6:$P$605,P24-1))
B25: 46114 | C25: Grey van | D25: 125486 | E25: 59.54 | F25: 101.47 | G25: x | H25: =IF(OR(N(E25)=0,F25=""),"",F25/E25) | I25: =IF(R25="","",D25-R25) | J25: =IF(R25="","",SUMIFS(Fuel!$E$6:$E$605,Fuel!$C$6:$C$605,C25,Fuel!$D$6:$D$605,">"&R25,Fuel!$D$6:$D$605,"<="&D25)) | K25: =IF(OR(I25="",N(I25)=0),"",J25/I25*100) | L25: =IF(OR(J25="",N(J25)=0),"",I25/J25) | N25: =IF(OR(C25="",N(D25)=0),"",D25+ROW()/10000000) | O25: =IF(N25="","",COUNTIFS(Fuel!$C$6:$C$605,C25,Fuel!$N$6:$N$605,">"&N25)) | P25: =IF(OR(N25="",G25=""),"",COUNTIFS(Fuel!$C$6:$C$605,C25,Fuel!$G$6:$G$605,"<>",Fuel!$N$6:$N$605,"<"&N25)) | R25: =IF(OR(P25="",N(P25)=0),"",SUMIFS(Fuel!$D$6:$D$605,Fuel!$C$6:$C$605,C25,Fuel!$P$6:$P$605,P25-1))
B26: 46119 | C26: Blue hatchback | D26: 45830 | E26: 21.28 | F26: 37.18 | G26: x | H26: =IF(OR(N(E26)=0,F26=""),"",F26/E26) | I26: =IF(R26="","",D26-R26) | J26: =IF(R26="","",SUMIFS(Fuel!$E$6:$E$605,Fuel!$C$6:$C$605,C26,Fuel!$D$6:$D$605,">"&R26,Fuel!$D$6:$D$605,"<="&D26)) | K26: =IF(OR(I26="",N(I26)=0),"",J26/I26*100) | L26: =IF(OR(J26="",N(J26)=0),"",I26/J26) | N26: =IF(OR(C26="",N(D26)=0),"",D26+ROW()/10000000) | O26: =IF(N26="","",COUNTIFS(Fuel!$C$6:$C$605,C26,Fuel!$N$6:$N$605,">"&N26)) | P26: =IF(OR(N26="",G26=""),"",COUNTIFS(Fuel!$C$6:$C$605,C26,Fuel!$G$6:$G$605,"<>",Fuel!$N$6:$N$605,"<"&N26)) | R26: =IF(OR(P26="",N(P26)=0),"",SUMIFS(Fuel!$D$6:$D$605,Fuel!$C$6:$C$605,C26,Fuel!$P$6:$P$605,P26-1))
B27: 46126 | C27: Grey van | D27: 126078 | E27: 44.75 | F27: 74.3 | G27: x | H27: =IF(OR(N(E27)=0,F27=""),"",F27/E27) | I27: =IF(R27="","",D27-R27) | J27: =IF(R27="","",SUMIFS(Fuel!$E$6:$E$605,Fuel!$C$6:$C$605,C27,Fuel!$D$6:$D$605,">"&R27,Fuel!$D$6:$D$605,"<="&D27)) | K27: =IF(OR(I27="",N(I27)=0),"",J27/I27*100) | L27: =IF(OR(J27="",N(J27)=0),"",I27/J27) | N27: =IF(OR(C27="",N(D27)=0),"",D27+ROW()/10000000) | O27: =IF(N27="","",COUNTIFS(Fuel!$C$6:$C$605,C27,Fuel!$N$6:$N$605,">"&N27)) | P27: =IF(OR(N27="",G27=""),"",COUNTIFS(Fuel!$C$6:$C$605,C27,Fuel!$G$6:$G$605,"<>",Fuel!$N$6:$N$605,"<"&N27)) | R27: =IF(OR(P27="",N(P27)=0),"",SUMIFS(Fuel!$D$6:$D$605,Fuel!$C$6:$C$605,C27,Fuel!$P$6:$P$605,P27-1))
B28: 46134 | C28: Blue hatchback | D28: 46397 | E28: 34.01 | F28: 59.54 | G28: x | H28: =IF(OR(N(E28)=0,F28=""),"",F28/E28) | I28: =IF(R28="","",D28-R28) | J28: =IF(R28="","",SUMIFS(Fuel!$E$6:$E$605,Fuel!$C$6:$C$605,C28,Fuel!$D$6:$D$605,">"&R28,Fuel!$D$6:$D$605,"<="&D28)) | K28: =IF(OR(I28="",N(I28)=0),"",J28/I28*100) | L28: =IF(OR(J28="",N(J28)=0),"",I28/J28) | N28: =IF(OR(C28="",N(D28)=0),"",D28+ROW()/10000000) | O28: =IF(N28="","",COUNTIFS(Fuel!$C$6:$C$605,C28,Fuel!$N$6:$N$605,">"&N28)) | P28: =IF(OR(N28="",G28=""),"",COUNTIFS(Fuel!$C$6:$C$605,C28,Fuel!$G$6:$G$605,"<>",Fuel!$N$6:$N$605,"<"&N28)) | R28: =IF(OR(P28="",N(P28)=0),"",SUMIFS(Fuel!$D$6:$D$605,Fuel!$C$6:$C$605,C28,Fuel!$P$6:$P$605,P28-1))
... B54: 46287 | C54: Grey van | D54: 134966 | E54: 50.6 | F54: 87.45 | G54: x | H54: =IF(OR(N(E54)=0,F54=""),"",F54/E54) | I54: =IF(R54="","",D54-R54) | J54: =IF(R54="","",SUMIFS(Fuel!$E$6:$E$605,Fuel!$C$6:$C$605,C54,Fuel!$D$6:$D$605,">"&R54,Fuel!$D$6:$D$605,"<="&D54)) | K54: =IF(OR(I54="",N(I54)=0),"",J54/I54*100) | L54: =IF(OR(J54="",N(J54)=0),"",I54/J54) | N54: =IF(OR(C54="",N(D54)=0),"",D54+ROW()/10000000) | O54: =IF(N54="","",COUNTIFS(Fuel!$C$6:$C$605,C54,Fuel!$N$6:$N$605,">"&N54)) | P54: =IF(OR(N54="",G54=""),"",COUNTIFS(Fuel!$C$6:$C$605,C54,Fuel!$G$6:$G$605,"<>",Fuel!$N$6:$N$605,"<"&N54)) | R54: =IF(OR(P54="",N(P54)=0),"",SUMIFS(Fuel!$D$6:$D$605,Fuel!$C$6:$C$605,C54,Fuel!$P$6:$P$605,P54-1))
H55: =IF(OR(N(E55)=0,F55=""),"",F55/E55) | I55: =IF(R55="","",D55-R55) | J55: =IF(R55="","",SUMIFS(Fuel!$E$6:$E$605,Fuel!$C$6:$C$605,C55,Fuel!$D$6:$D$605,">"&R55,Fuel!$D$6:$D$605,"<="&D55)) | K55: =IF(OR(I55="",N(I55)=0),"",J55/I55*100) | L55: =IF(OR(J55="",N(J55)=0),"",I55/J55) | N55: =IF(OR(C55="",N(D55)=0),"",D55+ROW()/10000000) | O55: =IF(N55="","",COUNTIFS(Fuel!$C$6:$C$605,C55,Fuel!$N$6:$N$605,">"&N55)) | P55: =IF(OR(N55="",G55=""),"",COUNTIFS(Fuel!$C$6:$C$605,C55,Fuel!$G$6:$G$605,"<>",Fuel!$N$6:$N$605,"<"&N55)) | R55: =IF(OR(P55="",N(P55)=0),"",SUMIFS(Fuel!$D$6:$D$605,Fuel!$C$6:$C$605,C55,Fuel!$P$6:$P$605,P55-1))
H56: =IF(OR(N(E56)=0,F56=""),"",F56/E56) | I56: =IF(R56="","",D56-R56) | J56: =IF(R56="","",SUMIFS(Fuel!$E$6:$E$605,Fuel!$C$6:$C$605,C56,Fuel!$D$6:$D$605,">"&R56,Fuel!$D$6:$D$605,"<="&D56)) | K56: =IF(OR(I56="",N(I56)=0),"",J56/I56*100) | L56: =IF(OR(J56="",N(J56)=0),"",I56/J56) | N56: =IF(OR(C56="",N(D56)=0),"",D56+ROW()/10000000) | O56: =IF(N56="","",COUNTIFS(Fuel!$C$6:$C$605,C56,Fuel!$N$6:$N$605,">"&N56)) | P56: =IF(OR(N56="",G56=""),"",COUNTIFS(Fuel!$C$6:$C$605,C56,Fuel!$G$6:$G$605,"<>",Fuel!$N$6:$N$605,"<"&N56)) | R56: =IF(OR(P56="",N(P56)=0),"",SUMIFS(Fuel!$D$6:$D$605,Fuel!$C$6:$C$605,C56,Fuel!$P$6:$P$605,P56-1))
H57: =IF(OR(N(E57)=0,F57=""),"",F57/E57) | I57: =IF(R57="","",D57-R57) | J57: =IF(R57="","",SUMIFS(Fuel!$E$6:$E$605,Fuel!$C$6:$C$605,C57,Fuel!$D$6:$D$605,">"&R57,Fuel!$D$6:$D$605,"<="&D57)) | K57: =IF(OR(I57="",N(I57)=0),"",J57/I57*100) | L57: =IF(OR(J57="",N(J57)=0),"",I57/J57) | N57: =IF(OR(C57="",N(D57)=0),"",D57+ROW()/10000000) | O57: =IF(N57="","",COUNTIFS(Fuel!$C$6:$C$605,C57,Fuel!$N$6:$N$605,">"&N57)) | P57: =IF(OR(N57="",G57=""),"",COUNTIFS(Fuel!$C$6:$C$605,C57,Fuel!$G$6:$G$605,"<>",Fuel!$N$6:$N$605,"<"&N57)) | R57: =IF(OR(P57="",N(P57)=0),"",SUMIFS(Fuel!$D$6:$D$605,Fuel!$C$6:$C$605,C57,Fuel!$P$6:$P$605,P57-1))
H58: =IF(OR(N(E58)=0,F58=""),"",F58/E58) | I58: =IF(R58="","",D58-R58) | J58: =IF(R58="","",SUMIFS(Fuel!$E$6:$E$605,Fuel!$C$6:$C$605,C58,Fuel!$D$6:$D$605,">"&R58,Fuel!$D$6:$D$605,"<="&D58)) | K58: =IF(OR(I58="",N(I58)=0),"",J58/I58*100) | L58: =IF(OR(J58="",N(J58)=0),"",I58/J58) | N58: =IF(OR(C58="",N(D58)=0),"",D58+ROW()/10000000) | O58: =IF(N58="","",COUNTIFS(Fuel!$C$6:$C$605,C58,Fuel!$N$6:$N$605,">"&N58)) | P58: =IF(OR(N58="",G58=""),"",COUNTIFS(Fuel!$C$6:$C$605,C58,Fuel!$G$6:$G$605,"<>",Fuel!$N$6:$N$605,"<"&N58)) | R58: =IF(OR(P58="",N(P58)=0),"",SUMIFS(Fuel!$D$6:$D$605,Fuel!$C$6:$C$605,C58,Fuel!$P$6:$P$605,P58-1))
