Workbook

Sheet Dashboard
B2: =IF(C5="","Moving day","Moving to "&C5)
B3: The countdown, the checklist, the boxes, the money and who still needs your new address.
B4: Moving day | C4: 46319
B5: New home | C5: Maple Road
B6: Budget | C6: 1800
B8: Countdown | C8: Tasks done | D8: Late tasks | E8: Boxes packed | F8: Told new address | G8: Budget left
B9: =IF($C$4="","",IF($C$4-TODAY()>1,($C$4-TODAY())&" days",IF($C$4-TODAY()=1,"Tomorrow",IF($C$4=TODAY(),"Today","Moved")))) | C9: =COUNTIFS(Tasks!$B$6:$B$75,"<>",Tasks!$F$6:$F$75,"<>")&" of "&COUNTIF(Tasks!$B$6:$B$75,"?*") | D9: =COUNTIF(Tasks!$G$6:$G$75,"Late") | E9: =(COUNTIF(Boxes!$K$6:$K$305,"Packed")+COUNTIF(Boxes!$K$6:$K$305,"Arrived"))&" of "&COUNTIF(Boxes!$K$6:$K$305,"?*") | F9: =COUNTIFS('New address'!$B$6:$B$65,"<>",'New address'!$F$6:$F$65,"<>")&" of "&COUNTIF('New address'!$B$6:$B$65,"?*") | G9: =IF(N($C$6)=0,"",$C$6-SUM(Costs!$M$6:$M$55))
B11: Next up | E11: Date | F11: Who | G11: Status | I11: Boxes by room | J11: Boxes | K11: Packed | L11: Fragile | M11: Arrived
B12: =IF(P12="",IF($C$4="","Type moving day first","Nothing left to do"),INDEX(Tasks!$B$6:$B$75,MATCH(P12,Tasks!$J$6:$J$75,0))) | E12: =IF(P12="","",INT(P12)) | F12: =IF(P12="","",INDEX(Tasks!$E$6:$E$75,MATCH(P12,Tasks!$J$6:$J$75,0))) | G12: =IF(P12="","",INDEX(Tasks!$G$6:$G$75,MATCH(P12,Tasks!$J$6:$J$75,0))) | I12: =IF(Settings!B6="","",Settings!B6) | J12: =IF(I12="","",COUNTIF(Boxes!$C$6:$C$305,I12)) | K12: =IF(I12="","",COUNTIFS(Boxes!$C$6:$C$305,I12,Boxes!$K$6:$K$305,"Packed")+COUNTIFS(Boxes!$C$6:$C$305,I12,Boxes!$K$6:$K$305,"Arrived")) | L12: =IF(I12="","",COUNTIFS(Boxes!$C$6:$C$305,I12,Boxes!$G$6:$G$305,"<>")) | M12: =IF(I12="","",COUNTIFS(Boxes!$C$6:$C$305,I12,Boxes!$K$6:$K$305,"Arrived")) | P12: =IFERROR(SMALL(Tasks!$J$6:$J$75,1),"")
B13: =IF(P13="","",INDEX(Tasks!$B$6:$B$75,MATCH(P13,Tasks!$J$6:$J$75,0))) | E13: =IF(P13="","",INT(P13)) | F13: =IF(P13="","",INDEX(Tasks!$E$6:$E$75,MATCH(P13,Tasks!$J$6:$J$75,0))) | G13: =IF(P13="","",INDEX(Tasks!$G$6:$G$75,MATCH(P13,Tasks!$J$6:$J$75,0))) | I13: =IF(Settings!B7="","",Settings!B7) | J13: =IF(I13="","",COUNTIF(Boxes!$C$6:$C$305,I13)) | K13: =IF(I13="","",COUNTIFS(Boxes!$C$6:$C$305,I13,Boxes!$K$6:$K$305,"Packed")+COUNTIFS(Boxes!$C$6:$C$305,I13,Boxes!$K$6:$K$305,"Arrived")) | L13: =IF(I13="","",COUNTIFS(Boxes!$C$6:$C$305,I13,Boxes!$G$6:$G$305,"<>")) | M13: =IF(I13="","",COUNTIFS(Boxes!$C$6:$C$305,I13,Boxes!$K$6:$K$305,"Arrived")) | P13: =IFERROR(SMALL(Tasks!$J$6:$J$75,2),"")
B14: =IF(P14="","",INDEX(Tasks!$B$6:$B$75,MATCH(P14,Tasks!$J$6:$J$75,0))) | E14: =IF(P14="","",INT(P14)) | F14: =IF(P14="","",INDEX(Tasks!$E$6:$E$75,MATCH(P14,Tasks!$J$6:$J$75,0))) | G14: =IF(P14="","",INDEX(Tasks!$G$6:$G$75,MATCH(P14,Tasks!$J$6:$J$75,0))) | I14: =IF(Settings!B8="","",Settings!B8) | J14: =IF(I14="","",COUNTIF(Boxes!$C$6:$C$305,I14)) | K14: =IF(I14="","",COUNTIFS(Boxes!$C$6:$C$305,I14,Boxes!$K$6:$K$305,"Packed")+COUNTIFS(Boxes!$C$6:$C$305,I14,Boxes!$K$6:$K$305,"Arrived")) | L14: =IF(I14="","",COUNTIFS(Boxes!$C$6:$C$305,I14,Boxes!$G$6:$G$305,"<>")) | M14: =IF(I14="","",COUNTIFS(Boxes!$C$6:$C$305,I14,Boxes!$K$6:$K$305,"Arrived")) | P14: =IFERROR(SMALL(Tasks!$J$6:$J$75,3),"")
B15: =IF(P15="","",INDEX(Tasks!$B$6:$B$75,MATCH(P15,Tasks!$J$6:$J$75,0))) | E15: =IF(P15="","",INT(P15)) | F15: =IF(P15="","",INDEX(Tasks!$E$6:$E$75,MATCH(P15,Tasks!$J$6:$J$75,0))) | G15: =IF(P15="","",INDEX(Tasks!$G$6:$G$75,MATCH(P15,Tasks!$J$6:$J$75,0))) | I15: =IF(Settings!B9="","",Settings!B9) | J15: =IF(I15="","",COUNTIF(Boxes!$C$6:$C$305,I15)) | K15: =IF(I15="","",COUNTIFS(Boxes!$C$6:$C$305,I15,Boxes!$K$6:$K$305,"Packed")+COUNTIFS(Boxes!$C$6:$C$305,I15,Boxes!$K$6:$K$305,"Arrived")) | L15: =IF(I15="","",COUNTIFS(Boxes!$C$6:$C$305,I15,Boxes!$G$6:$G$305,"<>")) | M15: =IF(I15="","",COUNTIFS(Boxes!$C$6:$C$305,I15,Boxes!$K$6:$K$305,"Arrived")) | P15: =IFERROR(SMALL(Tasks!$J$6:$J$75,4),"")
B16: =IF(P16="","",INDEX(Tasks!$B$6:$B$75,MATCH(P16,Tasks!$J$6:$J$75,0))) | E16: =IF(P16="","",INT(P16)) | F16: =IF(P16="","",INDEX(Tasks!$E$6:$E$75,MATCH(P16,Tasks!$J$6:$J$75,0))) | G16: =IF(P16="","",INDEX(Tasks!$G$6:$G$75,MATCH(P16,Tasks!$J$6:$J$75,0))) | I16: =IF(Settings!B10="","",Settings!B10) | J16: =IF(I16="","",COUNTIF(Boxes!$C$6:$C$305,I16)) | K16: =IF(I16="","",COUNTIFS(Boxes!$C$6:$C$305,I16,Boxes!$K$6:$K$305,"Packed")+COUNTIFS(Boxes!$C$6:$C$305,I16,Boxes!$K$6:$K$305,"Arrived")) | L16: =IF(I16="","",COUNTIFS(Boxes!$C$6:$C$305,I16,Boxes!$G$6:$G$305,"<>")) | M16: =IF(I16="","",COUNTIFS(Boxes!$C$6:$C$305,I16,Boxes!$K$6:$K$305,"Arrived")) | P16: =IFERROR(SMALL(Tasks!$J$6:$J$75,5),"")
B17: =IF(P17="","",INDEX(Tasks!$B$6:$B$75,MATCH(P17,Tasks!$J$6:$J$75,0))) | E17: =IF(P17="","",INT(P17)) | F17: =IF(P17="","",INDEX(Tasks!$E$6:$E$75,MATCH(P17,Tasks!$J$6:$J$75,0))) | G17: =IF(P17="","",INDEX(Tasks!$G$6:$G$75,MATCH(P17,Tasks!$J$6:$J$75,0))) | I17: =IF(Settings!B11="","",Settings!B11) | J17: =IF(I17="","",COUNTIF(Boxes!$C$6:$C$305,I17)) | K17: =IF(I17="","",COUNTIFS(Boxes!$C$6:$C$305,I17,Boxes!$K$6:$K$305,"Packed")+COUNTIFS(Boxes!$C$6:$C$305,I17,Boxes!$K$6:$K$305,"Arrived")) | L17: =IF(I17="","",COUNTIFS(Boxes!$C$6:$C$305,I17,Boxes!$G$6:$G$305,"<>")) | M17: =IF(I17="","",COUNTIFS(Boxes!$C$6:$C$305,I17,Boxes!$K$6:$K$305,"Arrived")) | P17: =IFERROR(SMALL(Tasks!$J$6:$J$75,6),"")
B18: =IF(P18="","",INDEX(Tasks!$B$6:$B$75,MATCH(P18,Tasks!$J$6:$J$75,0))) | E18: =IF(P18="","",INT(P18)) | F18: =IF(P18="","",INDEX(Tasks!$E$6:$E$75,MATCH(P18,Tasks!$J$6:$J$75,0))) | G18: =IF(P18="","",INDEX(Tasks!$G$6:$G$75,MATCH(P18,Tasks!$J$6:$J$75,0))) | I18: =IF(Settings!B12="","",Settings!B12) | J18: =IF(I18="","",COUNTIF(Boxes!$C$6:$C$305,I18)) | K18: =IF(I18="","",COUNTIFS(Boxes!$C$6:$C$305,I18,Boxes!$K$6:$K$305,"Packed")+COUNTIFS(Boxes!$C$6:$C$305,I18,Boxes!$K$6:$K$305,"Arrived")) | L18: =IF(I18="","",COUNTIFS(Boxes!$C$6:$C$305,I18,Boxes!$G$6:$G$305,"<>")) | M18: =IF(I18="","",COUNTIFS(Boxes!$C$6:$C$305,I18,Boxes!$K$6:$K$305,"Arrived")) | P18: =IFERROR(SMALL(Tasks!$J$6:$J$75,7),"")
B19: =IF(P19="","",INDEX(Tasks!$B$6:$B$75,MATCH(P19,Tasks!$J$6:$J$75,0))) | E19: =IF(P19="","",INT(P19)) | F19: =IF(P19="","",INDEX(Tasks!$E$6:$E$75,MATCH(P19,Tasks!$J$6:$J$75,0))) | G19: =IF(P19="","",INDEX(Tasks!$G$6:$G$75,MATCH(P19,Tasks!$J$6:$J$75,0))) | I19: =IF(Settings!B13="","",Settings!B13) | J19: =IF(I19="","",COUNTIF(Boxes!$C$6:$C$305,I19)) | K19: =IF(I19="","",COUNTIFS(Boxes!$C$6:$C$305,I19,Boxes!$K$6:$K$305,"Packed")+COUNTIFS(Boxes!$C$6:$C$305,I19,Boxes!$K$6:$K$305,"Arrived")) | L19: =IF(I19="","",COUNTIFS(Boxes!$C$6:$C$305,I19,Boxes!$G$6:$G$305,"<>")) | M19: =IF(I19="","",COUNTIFS(Boxes!$C$6:$C$305,I19,Boxes!$K$6:$K$305,"Arrived")) | P19: =IFERROR(SMALL(Tasks!$J$6:$J$75,8),"")
I20: =IF(Settings!B14="","",Settings!B14) | J20: =IF(I20="","",COUNTIF(Boxes!$C$6:$C$305,I20)) | K20: =IF(I20="","",COUNTIFS(Boxes!$C$6:$C$305,I20,Boxes!$K$6:$K$305,"Packed")+COUNTIFS(Boxes!$C$6:$C$305,I20,Boxes!$K$6:$K$305,"Arrived")) | L20: =IF(I20="","",COUNTIFS(Boxes!$C$6:$C$305,I20,Boxes!$G$6:$G$305,"<>")) | M20: =IF(I20="","",COUNTIFS(Boxes!$C$6:$C$305,I20,Boxes!$K$6:$K$305,"Arrived"))
I21: =IF(Settings!B15="","",Settings!B15) | J21: =IF(I21="","",COUNTIF(Boxes!$C$6:$C$305,I21)) | K21: =IF(I21="","",COUNTIFS(Boxes!$C$6:$C$305,I21,Boxes!$K$6:$K$305,"Packed")+COUNTIFS(Boxes!$C$6:$C$305,I21,Boxes!$K$6:$K$305,"Arrived")) | L21: =IF(I21="","",COUNTIFS(Boxes!$C$6:$C$305,I21,Boxes!$G$6:$G$305,"<>")) | M21: =IF(I21="","",COUNTIFS(Boxes!$C$6:$C$305,I21,Boxes!$K$6:$K$305,"Arrived"))
B22: Money | C22: Planned | D22: Paid | E22: Still to pay | I22: Open first | J22: Box | K22: To
B23: Movers | C23: =SUMIFS(Costs!$M$6:$M$55,Costs!$C$6:$C$55,B23) | D23: =SUMIFS(Costs!$G$6:$G$55,Costs!$C$6:$C$55,B23) | E23: =SUMIFS(Costs!$H$6:$H$55,Costs!$C$6:$C$55,B23) | I23: =IF(Q23="","No box marked open first",INDEX(Boxes!$E$6:$E$305,MATCH(Q23,Boxes!$N$6:$N$305,0))) | J23: =IF(Q23="","",INT(Q23)) | K23: =IF(Q23="","",INDEX(Boxes!$D$6:$D$305,MATCH(Q23,Boxes!$N$6:$N$305,0))) | Q23: =IFERROR(SMALL(Boxes!$N$6:$N$305,1),"")
B24: Van and fuel | C24: =SUMIFS(Costs!$M$6:$M$55,Costs!$C$6:$C$55,B24) | D24: =SUMIFS(Costs!$G$6:$G$55,Costs!$C$6:$C$55,B24) | E24: =SUMIFS(Costs!$H$6:$H$55,Costs!$C$6:$C$55,B24) | I24: =IF(Q24="","",INDEX(Boxes!$E$6:$E$305,MATCH(Q24,Boxes!$N$6:$N$305,0))) | J24: =IF(Q24="","",INT(Q24)) | K24: =IF(Q24="","",INDEX(Boxes!$D$6:$D$305,MATCH(Q24,Boxes!$N$6:$N$305,0))) | Q24: =IFERROR(SMALL(Boxes!$N$6:$N$305,2),"")
B25: Packing | C25: =SUMIFS(Costs!$M$6:$M$55,Costs!$C$6:$C$55,B25) | D25: =SUMIFS(Costs!$G$6:$G$55,Costs!$C$6:$C$55,B25) | E25: =SUMIFS(Costs!$H$6:$H$55,Costs!$C$6:$C$55,B25) | I25: =IF(Q25="","",INDEX(Boxes!$E$6:$E$305,MATCH(Q25,Boxes!$N$6:$N$305,0))) | J25: =IF(Q25="","",INT(Q25)) | K25: =IF(Q25="","",INDEX(Boxes!$D$6:$D$305,MATCH(Q25,Boxes!$N$6:$N$305,0))) | Q25: =IFERROR(SMALL(Boxes!$N$6:$N$305,3),"")
B26: Cleaning | C26: =SUMIFS(Costs!$M$6:$M$55,Costs!$C$6:$C$55,B26) | D26: =SUMIFS(Costs!$G$6:$G$55,Costs!$C$6:$C$55,B26) | E26: =SUMIFS(Costs!$H$6:$H$55,Costs!$C$6:$C$55,B26) | I26: =IF(Q26="","",INDEX(Boxes!$E$6:$E$305,MATCH(Q26,Boxes!$N$6:$N$305,0))) | J26: =IF(Q26="","",INT(Q26)) | K26: =IF(Q26="","",INDEX(Boxes!$D$6:$D$305,MATCH(Q26,Boxes!$N$6:$N$305,0))) | Q26: =IFERROR(SMALL(Boxes!$N$6:$N$305,4),"")
B27: Storage | C27: =SUMIFS(Costs!$M$6:$M$55,Costs!$C$6:$C$55,B27) | D27: =SUMIFS(Costs!$G$6:$G$55,Costs!$C$6:$C$55,B27) | E27: =SUMIFS(Costs!$H$6:$H$55,Costs!$C$6:$C$55,B27) | I27: =IF(Q27="","",INDEX(Boxes!$E$6:$E$305,MATCH(Q27,Boxes!$N$6:$N$305,0))) | J27: =IF(Q27="","",INT(Q27)) | K27: =IF(Q27="","",INDEX(Boxes!$D$6:$D$305,MATCH(Q27,Boxes!$N$6:$N$305,0))) | Q27: =IFERROR(SMALL(Boxes!$N$6:$N$305,5),"")
B28: Deposits | C28: =SUMIFS(Costs!$M$6:$M$55,Costs!$C$6:$C$55,B28) | D28: =SUMIFS(Costs!$G$6:$G$55,Costs!$C$6:$C$55,B28) | E28: =SUMIFS(Costs!$H$6:$H$55,Costs!$C$6:$C$55,B28) | I28: =IF(Q28="","",INDEX(Boxes!$E$6:$E$305,MATCH(Q28,Boxes!$N$6:$N$305,0))) | J28: =IF(Q28="","",INT(Q28)) | K28: =IF(Q28="","",INDEX(Boxes!$D$6:$D$305,MATCH(Q28,Boxes!$N$6:$N$305,0))) | Q28: =IFERROR(SMALL(Boxes!$N$6:$N$305,6),"")
B29: Utilities | C29: =SUMIFS(Costs!$M$6:$M$55,Costs!$C$6:$C$55,B29) | D29: =SUMIFS(Costs!$G$6:$G$55,Costs!$C$6:$C$55,B29) | E29: =SUMIFS(Costs!$H$6:$H$55,Costs!$C$6:$C$55,B29) | I29: =IF(Q29="","",INDEX(Boxes!$E$6:$E$305,MATCH(Q29,Boxes!$N$6:$N$305,0))) | J29: =IF(Q29="","",INT(Q29)) | K29: =IF(Q29="","",INDEX(Boxes!$D$6:$D$305,MATCH(Q29,Boxes!$N$6:$N$305,0))) | Q29: =IFERROR(SMALL(Boxes!$N$6:$N$305,7),"")
B30: Furniture | C30: =SUMIFS(Costs!$M$6:$M$55,Costs!$C$6:$C$55,B30) | D30: =SUMIFS(Costs!$G$6:$G$55,Costs!$C$6:$C$55,B30) | E30: =SUMIFS(Costs!$H$6:$H$55,Costs!$C$6:$C$55,B30) | I30: =IF(Q30="","",INDEX(Boxes!$E$6:$E$305,MATCH(Q30,Boxes!$N$6:$N$305,0))) | J30: =IF(Q30="","",INT(Q30)) | K30: =IF(Q30="","",INDEX(Boxes!$D$6:$D$305,MATCH(Q30,Boxes!$N$6:$N$305,0))) | Q30: =IFERROR(SMALL(Boxes!$N$6:$N$305,8),"")
B31: Travel | C31: =SUMIFS(Costs!$M$6:$M$55,Costs!$C$6:$C$55,B31) | D31: =SUMIFS(Costs!$G$6:$G$55,Costs!$C$6:$C$55,B31) | E31: =SUMIFS(Costs!$H$6:$H$55,Costs!$C$6:$C$55,B31) | I31: ="Next box number: "&(MAX(Boxes!$B$6:$B$305)+1)
B32: Other | C32: =SUMIFS(Costs!$M$6:$M$55,Costs!$C$6:$C$55,B32) | D32: =SUMIFS(Costs!$G$6:$G$55,Costs!$C$6:$C$55,B32) | E32: =SUMIFS(Costs!$H$6:$H$55,Costs!$C$6:$C$55,B32)
B33: Total | C33: =SUM(Costs!$M$6:$M$55) | D33: =SUM(Costs!$G$6:$G$55) | E33: =SUM(Costs!$H$6:$H$55)
B34: =IF(N($C$6)=0,"",REPT("█",MIN(24,MAX(0,ROUND((MIN(1,C33/$C$6))*24,0))))&REPT("░",24-MIN(24,MAX(0,ROUND((MIN(1,C33/$C$6))*24,0))))) | E34: =IF(N($C$6)=0,"",IF(C33>$C$6,"Over by "&FIXED(C33-$C$6,2),FIXED(C33/$C$6*100,0)&"% of the budget"))

Sheet Tasks
B2: Tasks
B3: The checklist, counted back from moving day. Change the days before and the dates follow. 0 is moving day, and a minus number is after it.
B5: Task | C5: Days before | D5: Date | E5: Who | F5: Done | G5: Status | H5: Notes
B6: Set a budget and the moving date | C6: 56 | D6: =IF(OR(B6="",C6="",Dashboard!$C$4=""),"",Dashboard!$C$4-C6) | E6: Both | F6: x | G6: =IF(B6="","",IF(F6<>"","Done",IF(D6="","",IF(D6<TODAY(),"Late",IF(D6-TODAY()<=7,"This week","Coming"))))) | J6: =IF(AND(B6<>"",F6="",D6<>""),D6+ROW()/10000000,"")
B7: Get three quotes from movers | C7: 56 | D7: =IF(OR(B7="",C7="",Dashboard!$C$4=""),"",Dashboard!$C$4-C7) | E7: Sam | F7: x | G7: =IF(B7="","",IF(F7<>"","Done",IF(D7="","",IF(D7<TODAY(),"Late",IF(D7-TODAY()<=7,"This week","Coming"))))) | J7: =IF(AND(B7<>"",F7="",D7<>""),D7+ROW()/10000000,"")
B8: Book the movers | C8: 49 | D8: =IF(OR(B8="",C8="",Dashboard!$C$4=""),"",Dashboard!$C$4-C8) | E8: Sam | F8: x | G8: =IF(B8="","",IF(F8<>"","Done",IF(D8="","",IF(D8<TODAY(),"Late",IF(D8-TODAY()<=7,"This week","Coming"))))) | J8: =IF(AND(B8<>"",F8="",D8<>""),D8+ROW()/10000000,"")
B9: Start clearing out, room by room | C9: 49 | D9: =IF(OR(B9="",C9="",Dashboard!$C$4=""),"",Dashboard!$C$4-C9) | E9: Both | F9: x | G9: =IF(B9="","",IF(F9<>"","Done",IF(D9="","",IF(D9<TODAY(),"Late",IF(D9-TODAY()<=7,"This week","Coming"))))) | J9: =IF(AND(B9<>"",F9="",D9<>""),D9+ROW()/10000000,"")
B10: Order boxes, tape and bubble wrap | C10: 42 | D10: =IF(OR(B10="",C10="",Dashboard!$C$4=""),"",Dashboard!$C$4-C10) | E10: Alex | F10: x | G10: =IF(B10="","",IF(F10<>"","Done",IF(D10="","",IF(D10<TODAY(),"Late",IF(D10-TODAY()<=7,"This week","Coming"))))) | J10: =IF(AND(B10<>"",F10="",D10<>""),D10+ROW()/10000000,"")
B11: Book the day off work | C11: 42 | D11: =IF(OR(B11="",C11="",Dashboard!$C$4=""),"",Dashboard!$C$4-C11) | E11: Both | F11: x | G11: =IF(B11="","",IF(F11<>"","Done",IF(D11="","",IF(D11<TODAY(),"Late",IF(D11-TODAY()<=7,"This week","Coming"))))) | J11: =IF(AND(B11<>"",F11="",D11<>""),D11+ROW()/10000000,"")
B12: Sell or give away what does not come | C12: 35 | D12: =IF(OR(B12="",C12="",Dashboard!$C$4=""),"",Dashboard!$C$4-C12) | E12: Alex | G12: =IF(B12="","",IF(F12<>"","Done",IF(D12="","",IF(D12<TODAY(),"Late",IF(D12-TODAY()<=7,"This week","Coming"))))) | J12: =IF(AND(B12<>"",F12="",D12<>""),D12+ROW()/10000000,"")
B13: Measure the new home for the furniture | C13: 35 | D13: =IF(OR(B13="",C13="",Dashboard!$C$4=""),"",Dashboard!$C$4-C13) | E13: Sam | F13: x | G13: =IF(B13="","",IF(F13<>"","Done",IF(D13="","",IF(D13<TODAY(),"Late",IF(D13-TODAY()<=7,"This week","Coming"))))) | J13: =IF(AND(B13<>"",F13="",D13<>""),D13+ROW()/10000000,"")
B14: Give notice on the old flat | C14: 30 | D14: =IF(OR(B14="",C14="",Dashboard!$C$4=""),"",Dashboard!$C$4-C14) | E14: Sam | F14: x | G14: =IF(B14="","",IF(F14<>"","Done",IF(D14="","",IF(D14<TODAY(),"Late",IF(D14-TODAY()<=7,"This week","Coming"))))) | J14: =IF(AND(B14<>"",F14="",D14<>""),D14+ROW()/10000000,"")
B15: Pack the rooms you rarely use | C15: 28 | D15: =IF(OR(B15="",C15="",Dashboard!$C$4=""),"",Dashboard!$C$4-C15) | E15: Both | F15: x | G15: =IF(B15="","",IF(F15<>"","Done",IF(D15="","",IF(D15<TODAY(),"Late",IF(D15-TODAY()<=7,"This week","Coming"))))) | J15: =IF(AND(B15<>"",F15="",D15<>""),D15+ROW()/10000000,"")
B16: Set up mail forwarding | C16: 21 | D16: =IF(OR(B16="",C16="",Dashboard!$C$4=""),"",Dashboard!$C$4-C16) | E16: Alex | F16: x | G16: =IF(B16="","",IF(F16<>"","Done",IF(D16="","",IF(D16<TODAY(),"Late",IF(D16-TODAY()<=7,"This week","Coming"))))) | J16: =IF(AND(B16<>"",F16="",D16<>""),D16+ROW()/10000000,"")
B17: Book internet at the new home | C17: 21 | D17: =IF(OR(B17="",C17="",Dashboard!$C$4=""),"",Dashboard!$C$4-C17) | E17: Sam | G17: =IF(B17="","",IF(F17<>"","Done",IF(D17="","",IF(D17<TODAY(),"Late",IF(D17-TODAY()<=7,"This week","Coming"))))) | J17: =IF(AND(B17<>"",F17="",D17<>""),D17+ROW()/10000000,"")
B18: Tell the bank, work and the doctor | C18: 14 | D18: =IF(OR(B18="",C18="",Dashboard!$C$4=""),"",Dashboard!$C$4-C18) | E18: Both | G18: =IF(B18="","",IF(F18<>"","Done",IF(D18="","",IF(D18<TODAY(),"Late",IF(D18-TODAY()<=7,"This week","Coming"))))) | J18: =IF(AND(B18<>"",F18="",D18<>""),D18+ROW()/10000000,"")
B19: Book cleaning for the old flat | C19: 14 | D19: =IF(OR(B19="",C19="",Dashboard!$C$4=""),"",Dashboard!$C$4-C19) | E19: Alex | G19: =IF(B19="","",IF(F19<>"","Done",IF(D19="","",IF(D19<TODAY(),"Late",IF(D19-TODAY()<=7,"This week","Coming"))))) | J19: =IF(AND(B19<>"",F19="",D19<>""),D19+ROW()/10000000,"")
B20: Confirm the movers and the time | C20: 10 | D20: =IF(OR(B20="",C20="",Dashboard!$C$4=""),"",Dashboard!$C$4-C20) | E20: Sam | G20: =IF(B20="","",IF(F20<>"","Done",IF(D20="","",IF(D20<TODAY(),"Late",IF(D20-TODAY()<=7,"This week","Coming"))))) | J20: =IF(AND(B20<>"",F20="",D20<>""),D20+ROW()/10000000,"")
B21: Arrange parking for the van | C21: 10 | D21: =IF(OR(B21="",C21="",Dashboard!$C$4=""),"",Dashboard!$C$4-C21) | E21: Sam | G21: =IF(B21="","",IF(F21<>"","Done",IF(D21="","",IF(D21<TODAY(),"Late",IF(D21-TODAY()<=7,"This week","Coming"))))) | J21: =IF(AND(B21<>"",F21="",D21<>""),D21+ROW()/10000000,"")
B22: Use up the frozen food | C22: 7 | D22: =IF(OR(B22="",C22="",Dashboard!$C$4=""),"",Dashboard!$C$4-C22) | E22: Both | G22: =IF(B22="","",IF(F22<>"","Done",IF(D22="","",IF(D22<TODAY(),"Late",IF(D22-TODAY()<=7,"This week","Coming"))))) | J22: =IF(AND(B22<>"",F22="",D22<>""),D22+ROW()/10000000,"")
B23: Pack all but the essentials | C23: 7 | D23: =IF(OR(B23="",C23="",Dashboard!$C$4=""),"",Dashboard!$C$4-C23) | E23: Both | G23: =IF(B23="","",IF(F23<>"","Done",IF(D23="","",IF(D23<TODAY(),"Late",IF(D23-TODAY()<=7,"This week","Coming"))))) | J23: =IF(AND(B23<>"",F23="",D23<>""),D23+ROW()/10000000,"")
B24: Pack the open-first boxes | C24: 3 | D24: =IF(OR(B24="",C24="",Dashboard!$C$4=""),"",Dashboard!$C$4-C24) | E24: Alex | G24: =IF(B24="","",IF(F24<>"","Done",IF(D24="","",IF(D24<TODAY(),"Late",IF(D24-TODAY()<=7,"This week","Coming"))))) | J24: =IF(AND(B24<>"",F24="",D24<>""),D24+ROW()/10000000,"")
B25: Defrost the fridge | C25: 2 | D25: =IF(OR(B25="",C25="",Dashboard!$C$4=""),"",Dashboard!$C$4-C25) | E25: Alex | G25: =IF(B25="","",IF(F25<>"","Done",IF(D25="","",IF(D25<TODAY(),"Late",IF(D25-TODAY()<=7,"This week","Coming"))))) | J25: =IF(AND(B25<>"",F25="",D25<>""),D25+ROW()/10000000,"")
B26: Take photos of the old flat | C26: 1 | D26: =IF(OR(B26="",C26="",Dashboard!$C$4=""),"",Dashboard!$C$4-C26) | E26: Sam | G26: =IF(B26="","",IF(F26<>"","Done",IF(D26="","",IF(D26<TODAY(),"Late",IF(D26-TODAY()<=7,"This week","Coming"))))) | J26: =IF(AND(B26<>"",F26="",D26<>""),D26+ROW()/10000000,"")
B27: Take the meter readings | C27: 0 | D27: =IF(OR(B27="",C27="",Dashboard!$C$4=""),"",Dashboard!$C$4-C27) | E27: Sam | G27: =IF(B27="","",IF(F27<>"","Done",IF(D27="","",IF(D27<TODAY(),"Late",IF(D27-TODAY()<=7,"This week","Coming"))))) | J27: =IF(AND(B27<>"",F27="",D27<>""),D27+ROW()/10000000,"")
B28: Check every room and cupboard | C28: 0 | D28: =IF(OR(B28="",C28="",Dashboard!$C$4=""),"",Dashboard!$C$4-C28) | E28: Both | G28: =IF(B28="","",IF(F28<>"","Done",IF(D28="","",IF(D28<TODAY(),"Late",IF(D28-TODAY()<=7,"This week","Coming"))))) | J28: =IF(AND(B28<>"",F28="",D28<>""),D28+ROW()/10000000,"")
... B33: Unpack the last boxes | C33: -21 | D33: =IF(OR(B33="",C33="",Dashboard!$C$4=""),"",Dashboard!$C$4-C33) | E33: Both | G33: =IF(B33="","",IF(F33<>"","Done",IF(D33="","",IF(D33<TODAY(),"Late",IF(D33-TODAY()<=7,"This week","Coming"))))) | J33: =IF(AND(B33<>"",F33="",D33<>""),D33+ROW()/10000000,"")
D34: =IF(OR(B34="",C34="",Dashboard!$C$4=""),"",Dashboard!$C$4-C34) | G34: =IF(B34="","",IF(F34<>"","Done",IF(D34="","",IF(D34<TODAY(),"Late",IF(D34-TODAY()<=7,"This week","Coming"))))) | J34: =IF(AND(B34<>"",F34="",D34<>""),D34+ROW()/10000000,"")
D35: =IF(OR(B35="",C35="",Dashboard!$C$4=""),"",Dashboard!$C$4-C35) | G35: =IF(B35="","",IF(F35<>"","Done",IF(D35="","",IF(D35<TODAY(),"Late",IF(D35-TODAY()<=7,"This week","Coming"))))) | J35: =IF(AND(B35<>"",F35="",D35<>""),D35+ROW()/10000000,"")
D36: =IF(OR(B36="",C36="",Dashboard!$C$4=""),"",Dashboard!$C$4-C36) | G36: =IF(B36="","",IF(F36<>"","Done",IF(D36="","",IF(D36<TODAY(),"Late",IF(D36-TODAY()<=7,"This week","Coming"))))) | J36: =IF(AND(B36<>"",F36="",D36<>""),D36+ROW()/10000000,"")
D37: =IF(OR(B37="",C37="",Dashboard!$C$4=""),"",Dashboard!$C$4-C37) | G37: =IF(B37="","",IF(F37<>"","Done",IF(D37="","",IF(D37<TODAY(),"Late",IF(D37-TODAY()<=7,"This week","Coming"))))) | J37: =IF(AND(B37<>"",F37="",D37<>""),D37+ROW()/10000000,"")
D38: =IF(OR(B38="",C38="",Dashboard!$C$4=""),"",Dashboard!$C$4-C38) | G38: =IF(B38="","",IF(F38<>"","Done",IF(D38="","",IF(D38<TODAY(),"Late",IF(D38-TODAY()<=7,"This week","Coming"))))) | J38: =IF(AND(B38<>"",F38="",D38<>""),D38+ROW()/10000000,"")
D39: =IF(OR(B39="",C39="",Dashboard!$C$4=""),"",Dashboard!$C$4-C39) | G39: =IF(B39="","",IF(F39<>"","Done",IF(D39="","",IF(D39<TODAY(),"Late",IF(D39-TODAY()<=7,"This week","Coming"))))) | J39: =IF(AND(B39<>"",F39="",D39<>""),D39+ROW()/10000000,"")
D40: =IF(OR(B40="",C40="",Dashboard!$C$4=""),"",Dashboard!$C$4-C40) | G40: =IF(B40="","",IF(F40<>"","Done",IF(D40="","",IF(D40<TODAY(),"Late",IF(D40-TODAY()<=7,"This week","Coming"))))) | J40: =IF(AND(B40<>"",F40="",D40<>""),D40+ROW()/10000000,"")
D41: =IF(OR(B41="",C41="",Dashboard!$C$4=""),"",Dashboard!$C$4-C41) | G41: =IF(B41="","",IF(F41<>"","Done",IF(D41="","",IF(D41<TODAY(),"Late",IF(D41-TODAY()<=7,"This week","Coming"))))) | J41: =IF(AND(B41<>"",F41="",D41<>""),D41+ROW()/10000000,"")
D42: =IF(OR(B42="",C42="",Dashboard!$C$4=""),"",Dashboard!$C$4-C42) | G42: =IF(B42="","",IF(F42<>"","Done",IF(D42="","",IF(D42<TODAY(),"Late",IF(D42-TODAY()<=7,"This week","Coming"))))) | J42: =IF(AND(B42<>"",F42="",D42<>""),D42+ROW()/10000000,"")
D43: =IF(OR(B43="",C43="",Dashboard!$C$4=""),"",Dashboard!$C$4-C43) | G43: =IF(B43="","",IF(F43<>"","Done",IF(D43="","",IF(D43<TODAY(),"Late",IF(D43-TODAY()<=7,"This week","Coming"))))) | J43: =IF(AND(B43<>"",F43="",D43<>""),D43+ROW()/10000000,"")
D44: =IF(OR(B44="",C44="",Dashboard!$C$4=""),"",Dashboard!$C$4-C44) | G44: =IF(B44="","",IF(F44<>"","Done",IF(D44="","",IF(D44<TODAY(),"Late",IF(D44-TODAY()<=7,"This week","Coming"))))) | J44: =IF(AND(B44<>"",F44="",D44<>""),D44+ROW()/10000000,"")
D45: =IF(OR(B45="",C45="",Dashboard!$C$4=""),"",Dashboard!$C$4-C45) | G45: =IF(B45="","",IF(F45<>"","Done",IF(D45="","",IF(D45<TODAY(),"Late",IF(D45-TODAY()<=7,"This week","Coming"))))) | J45: =IF(AND(B45<>"",F45="",D45<>""),D45+ROW()/10000000,"")
... D75: =IF(OR(B75="",C75="",Dashboard!$C$4=""),"",Dashboard!$C$4-C75) | G75: =IF(B75="","",IF(F75<>"","Done",IF(D75="","",IF(D75<TODAY(),"Late",IF(D75-TODAY()<=7,"This week","Coming"))))) | J75: =IF(AND(B75<>"",F75="",D75<>""),D75+ROW()/10000000,"")

Sheet Boxes
B2: Boxes
B3: Write the number on the box and one line here: the room it leaves, the room it goes to and what is inside. Put an x as it is packed and when it arrives.
B5: Box | C5: From | D5: To | E5: What is inside | F5: Size | G5: Fragile | H5: Open first | I5: Packed | J5: Arrived | K5: Status | L5: Notes
B6: 1 | C6: Kitchen | D6: Kitchen | E6: Plates and bowls | F6: Medium | G6: x | K6: =IF(AND(B6="",E6=""),"",IF(J6<>"","Arrived",IF(I6<>"","Packed","To pack"))) | N6: =IF(AND(H6<>"",B6<>""),B6+ROW()/10000000,"")
B7: 2 | C7: Kitchen | D7: Kitchen | E7: Glasses | F7: Small | G7: x | K7: =IF(AND(B7="",E7=""),"",IF(J7<>"","Arrived",IF(I7<>"","Packed","To pack"))) | N7: =IF(AND(H7<>"",B7<>""),B7+ROW()/10000000,"")
B8: 3 | C8: Kitchen | D8: Kitchen | E8: Pots and pans | F8: Large | K8: =IF(AND(B8="",E8=""),"",IF(J8<>"","Arrived",IF(I8<>"","Packed","To pack"))) | N8: =IF(AND(H8<>"",B8<>""),B8+ROW()/10000000,"")
B9: 4 | C9: Kitchen | D9: Kitchen | E9: Baking things | F9: Medium | I9: x | K9: =IF(AND(B9="",E9=""),"",IF(J9<>"","Arrived",IF(I9<>"","Packed","To pack"))) | N9: =IF(AND(H9<>"",B9<>""),B9+ROW()/10000000,"")
B10: 5 | C10: Kitchen | D10: Kitchen | E10: Mugs and the kettle | F10: Small | G10: x | H10: x | K10: =IF(AND(B10="",E10=""),"",IF(J10<>"","Arrived",IF(I10<>"","Packed","To pack"))) | N10: =IF(AND(H10<>"",B10<>""),B10+ROW()/10000000,"")
B11: 6 | C11: Kitchen | D11: Kitchen | E11: Cutlery and knives | F11: Small | K11: =IF(AND(B11="",E11=""),"",IF(J11<>"","Arrived",IF(I11<>"","Packed","To pack"))) | N11: =IF(AND(H11<>"",B11<>""),B11+ROW()/10000000,"")
B12: 7 | C12: Kitchen | D12: Kitchen | E12: Food cupboard | F12: Medium | K12: =IF(AND(B12="",E12=""),"",IF(J12<>"","Arrived",IF(I12<>"","Packed","To pack"))) | N12: =IF(AND(H12<>"",B12<>""),B12+ROW()/10000000,"")
B13: 8 | C13: Kitchen | D13: Kitchen | E13: Small appliances | F13: Large | K13: =IF(AND(B13="",E13=""),"",IF(J13<>"","Arrived",IF(I13<>"","Packed","To pack"))) | N13: =IF(AND(H13<>"",B13<>""),B13+ROW()/10000000,"")
B14: 9 | C14: Kitchen | D14: Kitchen | E14: Tea towels and aprons | F14: Small | K14: =IF(AND(B14="",E14=""),"",IF(J14<>"","Arrived",IF(I14<>"","Packed","To pack"))) | N14: =IF(AND(H14<>"",B14<>""),B14+ROW()/10000000,"")
B15: 10 | C15: Living room | D15: Living room | E15: Books A to M | F15: Small | I15: x | K15: =IF(AND(B15="",E15=""),"",IF(J15<>"","Arrived",IF(I15<>"","Packed","To pack"))) | N15: =IF(AND(H15<>"",B15<>""),B15+ROW()/10000000,"")
B16: 11 | C16: Living room | D16: Living room | E16: Books N to Z | F16: Small | I16: x | K16: =IF(AND(B16="",E16=""),"",IF(J16<>"","Arrived",IF(I16<>"","Packed","To pack"))) | N16: =IF(AND(H16<>"",B16<>""),B16+ROW()/10000000,"")
B17: 12 | C17: Living room | D17: Living room | E17: Lamps | F17: Medium | G17: x | I17: x | K17: =IF(AND(B17="",E17=""),"",IF(J17<>"","Arrived",IF(I17<>"","Packed","To pack"))) | N17: =IF(AND(H17<>"",B17<>""),B17+ROW()/10000000,"")
B18: 13 | C18: Living room | D18: Living room | E18: Cushions and throws | F18: Large | I18: x | K18: =IF(AND(B18="",E18=""),"",IF(J18<>"","Arrived",IF(I18<>"","Packed","To pack"))) | N18: =IF(AND(H18<>"",B18<>""),B18+ROW()/10000000,"")
B19: 14 | C19: Living room | D19: Living room | E19: Board games | F19: Medium | I19: x | K19: =IF(AND(B19="",E19=""),"",IF(J19<>"","Arrived",IF(I19<>"","Packed","To pack"))) | N19: =IF(AND(H19<>"",B19<>""),B19+ROW()/10000000,"")
B20: 15 | C20: Living room | D20: Living room | E20: Photo frames | F20: Small | G20: x | I20: x | K20: =IF(AND(B20="",E20=""),"",IF(J20<>"","Arrived",IF(I20<>"","Packed","To pack"))) | N20: =IF(AND(H20<>"",B20<>""),B20+ROW()/10000000,"")
B21: 16 | C21: Living room | D21: Living room | E21: Speakers and cables | F21: Medium | G21: x | K21: =IF(AND(B21="",E21=""),"",IF(J21<>"","Arrived",IF(I21<>"","Packed","To pack"))) | N21: =IF(AND(H21<>"",B21<>""),B21+ROW()/10000000,"")
B22: 17 | C22: Bedroom | D22: Bedroom | E22: Bedding | F22: Large | H22: x | K22: =IF(AND(B22="",E22=""),"",IF(J22<>"","Arrived",IF(I22<>"","Packed","To pack"))) | N22: =IF(AND(H22<>"",B22<>""),B22+ROW()/10000000,"")
B23: 18 | C23: Bedroom | D23: Bedroom | E23: Winter clothes | F23: Large | I23: x | K23: =IF(AND(B23="",E23=""),"",IF(J23<>"","Arrived",IF(I23<>"","Packed","To pack"))) | N23: =IF(AND(H23<>"",B23<>""),B23+ROW()/10000000,"")
B24: 19 | C24: Bedroom | D24: Bedroom | E24: Shoes | F24: Medium | K24: =IF(AND(B24="",E24=""),"",IF(J24<>"","Arrived",IF(I24<>"","Packed","To pack"))) | N24: =IF(AND(H24<>"",B24<>""),B24+ROW()/10000000,"")
B25: 20 | C25: Bedroom | D25: Bedroom | E25: Summer clothes | F25: Large | I25: x | K25: =IF(AND(B25="",E25=""),"",IF(J25<>"","Arrived",IF(I25<>"","Packed","To pack"))) | N25: =IF(AND(H25<>"",B25<>""),B25+ROW()/10000000,"")
B26: 21 | C26: Bedroom | D26: Bedroom | E26: Jewellery box and watch | F26: Small | G26: x | K26: =IF(AND(B26="",E26=""),"",IF(J26<>"","Arrived",IF(I26<>"","Packed","To pack"))) | N26: =IF(AND(H26<>"",B26<>""),B26+ROW()/10000000,"")
B27: 22 | C27: Bedroom | D27: Bedroom | E27: Towels | F27: Medium | K27: =IF(AND(B27="",E27=""),"",IF(J27<>"","Arrived",IF(I27<>"","Packed","To pack"))) | N27: =IF(AND(H27<>"",B27<>""),B27+ROW()/10000000,"")
B28: 23 | C28: Kids room | D28: Kids room | E28: Toys | F28: Large | K28: =IF(AND(B28="",E28=""),"",IF(J28<>"","Arrived",IF(I28<>"","Packed","To pack"))) | N28: =IF(AND(H28<>"",B28<>""),B28+ROW()/10000000,"")
B29: 24 | C29: Kids room | D29: Kids room | E29: Kids books | F29: Small | K29: =IF(AND(B29="",E29=""),"",IF(J29<>"","Arrived",IF(I29<>"","Packed","To pack"))) | N29: =IF(AND(H29<>"",B29<>""),B29+ROW()/10000000,"")
B30: 25 | C30: Kids room | D30: Kids room | E30: Kids clothes | F30: Large | K30: =IF(AND(B30="",E30=""),"",IF(J30<>"","Arrived",IF(I30<>"","Packed","To pack"))) | N30: =IF(AND(H30<>"",B30<>""),B30+ROW()/10000000,"")
B31: 26 | C31: Kids room | D31: Kids room | E31: Night light and bedding | F31: Medium | H31: x | K31: =IF(AND(B31="",E31=""),"",IF(J31<>"","Arrived",IF(I31<>"","Packed","To pack"))) | N31: =IF(AND(H31<>"",B31<>""),B31+ROW()/10000000,"")
B32: 27 | C32: Bathroom | D32: Bathroom | E32: Bathroom things | F32: Small | H32: x | K32: =IF(AND(B32="",E32=""),"",IF(J32<>"","Arrived",IF(I32<>"","Packed","To pack"))) | N32: =IF(AND(H32<>"",B32<>""),B32+ROW()/10000000,"")
B33: 28 | C33: Bathroom | D33: Bathroom | E33: Medicine box | F33: Small | K33: =IF(AND(B33="",E33=""),"",IF(J33<>"","Arrived",IF(I33<>"","Packed","To pack"))) | N33: =IF(AND(H33<>"",B33<>""),B33+ROW()/10000000,"")
B34: 29 | C34: Office | D34: Study | E34: Files and papers | F34: Small | I34: x | K34: =IF(AND(B34="",E34=""),"",IF(J34<>"","Arrived",IF(I34<>"","Packed","To pack"))) | N34: =IF(AND(H34<>"",B34<>""),B34+ROW()/10000000,"")
B35: 30 | C35: Office | D35: Study | E35: Monitor | F35: Large | G35: x | I35: x | K35: =IF(AND(B35="",E35=""),"",IF(J35<>"","Arrived",IF(I35<>"","Packed","To pack"))) | N35: =IF(AND(H35<>"",B35<>""),B35+ROW()/10000000,"")
B36: 31 | C36: Office | D36: Study | E36: Printer | F36: Medium | G36: x | I36: x | K36: =IF(AND(B36="",E36=""),"",IF(J36<>"","Arrived",IF(I36<>"","Packed","To pack"))) | N36: =IF(AND(H36<>"",B36<>""),B36+ROW()/10000000,"")
B37: 32 | C37: Office | D37: Study | E37: Stationery | F37: Small | I37: x | K37: =IF(AND(B37="",E37=""),"",IF(J37<>"","Arrived",IF(I37<>"","Packed","To pack"))) | N37: =IF(AND(H37<>"",B37<>""),B37+ROW()/10000000,"")
B38: 33 | C38: Office | D38: Study | E38: Cables and chargers | F38: Small | H38: x | K38: =IF(AND(B38="",E38=""),"",IF(J38<>"","Arrived",IF(I38<>"","Packed","To pack"))) | N38: =IF(AND(H38<>"",B38<>""),B38+ROW()/10000000,"")
B39: 34 | C39: Hallway | D39: Hall | E39: Coats | F39: Large | K39: =IF(AND(B39="",E39=""),"",IF(J39<>"","Arrived",IF(I39<>"","Packed","To pack"))) | N39: =IF(AND(H39<>"",B39<>""),B39+ROW()/10000000,"")
B40: 35 | C40: Hallway | D40: Hall | E40: Umbrellas and bags | F40: Medium | K40: =IF(AND(B40="",E40=""),"",IF(J40<>"","Arrived",IF(I40<>"","Packed","To pack"))) | N40: =IF(AND(H40<>"",B40<>""),B40+ROW()/10000000,"")
B41: 36 | C41: Garage | D41: Garage | E41: Tools | F41: Medium | I41: x | K41: =IF(AND(B41="",E41=""),"",IF(J41<>"","Arrived",IF(I41<>"","Packed","To pack"))) | N41: =IF(AND(H41<>"",B41<>""),B41+ROW()/10000000,"")
B42: 37 | C42: Garage | D42: Garage | E42: Garden things | F42: Large | I42: x | K42: =IF(AND(B42="",E42=""),"",IF(J42<>"","Arrived",IF(I42<>"","Packed","To pack"))) | N42: =IF(AND(H42<>"",B42<>""),B42+ROW()/10000000,"")
...

Sheet Movers
B2: Movers
B3: Quotes side by side. Put an x under Chosen for the one you book, and add it to Costs.
B5: Company | C5: Price | D5: Free on | E5: Packing | F5: Insurance | G5: Notes | H5: Chosen
B6: Oak Lane Removals | C6: 1150 | D6: 46319 | E6: x | F6: x | G6: Pack the kitchen for us
B7: City Van Movers | C7: 890 | D7: 46326 | G7: Only free the week after
B8: Blue Box Removals | C8: 950 | D8: 46319 | F8: x | G8: Good reviews, can store for a week | H8: x
B17: The cheapest price is in green. A date in orange is not moving day.

Sheet Costs
B2: Costs
B3: Everything the move costs: what you booked, what you paid and when the rest is due.
B5: Item | C5: Category | D5: Company or shop | E5: Estimate | F5: Final price | G5: Paid | H5: Still to pay | I5: Pay by | J5: Status | K5: Notes
B6: Removal, 2 movers and a truck | C6: Movers | D6: Blue Box Removals | E6: 950 | F6: 950 | G6: 200 | H6: =IF(B6="","",MAX(0,IF(F6<>"",F6,N(E6))-N(G6))) | I6: 46319 | J6: =IF(B6="","",IF(H6<=0,"Paid",IF(I6="","To pay",IF(I6<TODAY(),"Late",IF(I6-TODAY()<=7,"Due soon","To pay"))))) | M6: =IF(B6="",0,IF(F6<>"",F6,N(E6)))
B7: Boxes, tape and bubble wrap | C7: Packing | D7: Box shop | E7: 90 | F7: 86.4 | G7: 86.4 | H7: =IF(B7="","",MAX(0,IF(F7<>"",F7,N(E7))-N(G7))) | J7: =IF(B7="","",IF(H7<=0,"Paid",IF(I7="","To pay",IF(I7<TODAY(),"Late",IF(I7-TODAY()<=7,"Due soon","To pay"))))) | M7: =IF(B7="",0,IF(F7<>"",F7,N(E7)))
B8: End of tenancy cleaning | C8: Cleaning | D8: Sparkle Clean | E8: 180 | F8: 180 | G8: 0 | H8: =IF(B8="","",MAX(0,IF(F8<>"",F8,N(E8))-N(G8))) | I8: 46320 | J8: =IF(B8="","",IF(H8<=0,"Paid",IF(I8="","To pay",IF(I8<TODAY(),"Late",IF(I8-TODAY()<=7,"Due soon","To pay"))))) | M8: =IF(B8="",0,IF(F8<>"",F8,N(E8)))
B9: Mail forwarding, 6 months | C9: Other | D9: Post office | E9: 35 | F9: 34.5 | G9: 34.5 | H9: =IF(B9="","",MAX(0,IF(F9<>"",F9,N(E9))-N(G9))) | J9: =IF(B9="","",IF(H9<=0,"Paid",IF(I9="","To pay",IF(I9<TODAY(),"Late",IF(I9-TODAY()<=7,"Due soon","To pay"))))) | M9: =IF(B9="",0,IF(F9<>"",F9,N(E9)))
B10: Internet set-up | C10: Utilities | D10: Fibre company | E10: 49 | G10: 0 | H10: =IF(B10="","",MAX(0,IF(F10<>"",F10,N(E10))-N(G10))) | I10: 46298 | J10: =IF(B10="","",IF(H10<=0,"Paid",IF(I10="","To pay",IF(I10<TODAY(),"Late",IF(I10-TODAY()<=7,"Due soon","To pay"))))) | M10: =IF(B10="",0,IF(F10<>"",F10,N(E10)))
B11: Van parking permit | C11: Van and fuel | D11: Council | E11: 25 | G11: 0 | H11: =IF(B11="","",MAX(0,IF(F11<>"",F11,N(E11))-N(G11))) | I11: 46309 | J11: =IF(B11="","",IF(H11<=0,"Paid",IF(I11="","To pay",IF(I11<TODAY(),"Late",IF(I11-TODAY()<=7,"Due soon","To pay"))))) | M11: =IF(B11="",0,IF(F11<>"",F11,N(E11)))
B12: Takeaway on moving day | C12: Other | E12: 40 | G12: 0 | H12: =IF(B12="","",MAX(0,IF(F12<>"",F12,N(E12))-N(G12))) | J12: =IF(B12="","",IF(H12<=0,"Paid",IF(I12="","To pay",IF(I12<TODAY(),"Late",IF(I12-TODAY()<=7,"Due soon","To pay"))))) | M12: =IF(B12="",0,IF(F12<>"",F12,N(E12)))
B13: Curtains for the new bedroom | C13: Furniture | E13: 120 | G13: 0 | H13: =IF(B13="","",MAX(0,IF(F13<>"",F13,N(E13))-N(G13))) | J13: =IF(B13="","",IF(H13<=0,"Paid",IF(I13="","To pay",IF(I13<TODAY(),"Late",IF(I13-TODAY()<=7,"Due soon","To pay"))))) | M13: =IF(B13="",0,IF(F13<>"",F13,N(E13)))
H14: =IF(B14="","",MAX(0,IF(F14<>"",F14,N(E14))-N(G14))) | J14: =IF(B14="","",IF(H14<=0,"Paid",IF(I14="","To pay",IF(I14<TODAY(),"Late",IF(I14-TODAY()<=7,"Due soon","To pay"))))) | M14: =IF(B14="",0,IF(F14<>"",F14,N(E14)))
H15: =IF(B15="","",MAX(0,IF(F15<>"",F15,N(E15))-N(G15))) | J15: =IF(B15="","",IF(H15<=0,"Paid",IF(I15="","To pay",IF(I15<TODAY(),"Late",IF(I15-TODAY()<=7,"Due soon","To pay"))))) | M15: =IF(B15="",0,IF(F15<>"",F15,N(E15)))
H16: =IF(B16="","",MAX(0,IF(F16<>"",F16,N(E16))-N(G16))) | J16: =IF(B16="","",IF(H16<=0,"Paid",IF(I16="","To pay",IF(I16<TODAY(),"Late",IF(I16-TODAY()<=7,"Due soon","To pay"))))) | M16: =IF(B16="",0,IF(F16<>"",F16,N(E16)))
H17: =IF(B17="","",MAX(0,IF(F17<>"",F17,N(E17))-N(G17))) | J17: =IF(B17="","",IF(H17<=0,"Paid",IF(I17="","To pay",IF(I17<TODAY(),"Late",IF(I17-TODAY()<=7,"Due soon","To pay"))))) | M17: =IF(B17="",0,IF(F17<>"",F17,N(E17)))
H18: =IF(B18="","",MAX(0,IF(F18<>"",F18,N(E18))-N(G18))) | J18: =IF(B18="","",IF(H18<=0,"Paid",IF(I18="","To pay",IF(I18<TODAY(),"Late",IF(I18-TODAY()<=7,"Due soon","To pay"))))) | M18: =IF(B18="",0,IF(F18<>"",F18,N(E18)))
H19: =IF(B19="","",MAX(0,IF(F19<>"",F19,N(E19))-N(G19))) | J19: =IF(B19="","",IF(H19<=0,"Paid",IF(I19="","To pay",IF(I19<TODAY(),"Late",IF(I19-TODAY()<=7,"Due soon","To pay"))))) | M19: =IF(B19="",0,IF(F19<>"",F19,N(E19)))
H20: =IF(B20="","",MAX(0,IF(F20<>"",F20,N(E20))-N(G20))) | J20: =IF(B20="","",IF(H20<=0,"Paid",IF(I20="","To pay",IF(I20<TODAY(),"Late",IF(I20-TODAY()<=7,"Due soon","To pay"))))) | M20: =IF(B20="",0,IF(F20<>"",F20,N(E20)))
H21: =IF(B21="","",MAX(0,IF(F21<>"",F21,N(E21))-N(G21))) | J21: =IF(B21="","",IF(H21<=0,"Paid",IF(I21="","To pay",IF(I21<TODAY(),"Late",IF(I21-TODAY()<=7,"Due soon","To pay"))))) | M21: =IF(B21="",0,IF(F21<>"",F21,N(E21)))
H22: =IF(B22="","",MAX(0,IF(F22<>"",F22,N(E22))-N(G22))) | J22: =IF(B22="","",IF(H22<=0,"Paid",IF(I22="","To pay",IF(I22<TODAY(),"Late",IF(I22-TODAY()<=7,"Due soon","To pay"))))) | M22: =IF(B22="",0,IF(F22<>"",F22,N(E22)))
H23: =IF(B23="","",MAX(0,IF(F23<>"",F23,N(E23))-N(G23))) | J23: =IF(B23="","",IF(H23<=0,"Paid",IF(I23="","To pay",IF(I23<TODAY(),"Late",IF(I23-TODAY()<=7,"Due soon","To pay"))))) | M23: =IF(B23="",0,IF(F23<>"",F23,N(E23)))
H24: =IF(B24="","",MAX(0,IF(F24<>"",F24,N(E24))-N(G24))) | J24: =IF(B24="","",IF(H24<=0,"Paid",IF(I24="","To pay",IF(I24<TODAY(),"Late",IF(I24-TODAY()<=7,"Due soon","To pay"))))) | M24: =IF(B24="",0,IF(F24<>"",F24,N(E24)))
H25: =IF(B25="","",MAX(0,IF(F25<>"",F25,N(E25))-N(G25))) | J25: =IF(B25="","",IF(H25<=0,"Paid",IF(I25="","To pay",IF(I25<TODAY(),"Late",IF(I25-TODAY()<=7,"Due soon","To pay"))))) | M25: =IF(B25="",0,IF(F25<>"",F25,N(E25)))
... H55: =IF(B55="","",MAX(0,IF(F55<>"",F55,N(E55))-N(G55))) | J55: =IF(B55="","",IF(H55<=0,"Paid",IF(I55="","To pay",IF(I55<TODAY(),"Late",IF(I55-TODAY()<=7,"Due soon","To pay"))))) | M55: =IF(B55="",0,IF(F55<>"",F55,N(E55)))
B56: The final price counts once you know it. Until then the estimate does.

Sheet New address
B2: New address
B3: Everyone who needs your new address. Put an x under Done when you have told them.
B5: Who | C5: Kind | D5: How | E5: Account or reference | F5: Done | G5: Notes | I5: Meter | J5: Old home | K5: New home | L5: Date
B6: Bank | C6: Money | D6: Online | E6: Current account | F6: x | I6: Electricity | L6: 46319
B7: Credit card | C7: Money | D7: App | F7: x | I7: Gas | L7: 46319
B8: Employer | C8: Work | D8: Email to HR | F8: x | I8: Water | L8: 46319
B9: Doctor | C9: Health | D9: Form at the surgery | I9: Other
B10: Dentist | C10: Health | D10: Phone
B11: Car insurance | C11: Money | D11: Online | E11: Policy number | I11: Take the readings on moving day, with a photo.
B12: Home insurance | C12: Money | D12: Phone | E12: Policy number
B13: Electricity | C13: Home | D13: Online | E13: Meter reading
B14: Gas | C14: Home | D14: Online | E14: Meter reading
B15: Water | C15: Home | D15: Phone
B16: Internet | C16: Home | D16: Online | E16: Booked for the new home | F16: x
B17: Local council | C17: Government | D17: Online form
B18: Tax office | C18: Government | D18: Online
B19: Driving licence | C19: Government | D19: Online
B20: Mail forwarding | C20: Post | D20: Post office | E20: 6 months | F20: x
B21: Mobile phone | C21: Subscriptions | D21: App | F21: x
B22: Streaming and magazines | C22: Subscriptions | D22: Online
B23: Gym | C23: Subscriptions | D23: At the desk
B24: School | C24: Other | D24: Letter | F24: x
B25: Family and friends | C25: People | D25: Card with the new address
B26: Vet | C26: Health | D26: Phone
B27: Online shops | C27: Subscriptions | D27: Each account

Sheet Settings
B2: Settings
B3: The rooms of the home you are leaving, for the boxes and the Dashboard.
B5: Rooms
B6: Kitchen | D6: The Dashboard counts the boxes of each room on this list.
B7: Living room
B8: Bedroom
B9: Kids room
B10: Bathroom
B11: Office
B12: Hallway
B13: Garage

Sheet Start Here
B2: Start here
B3: Type only in the yellow cells. Everything else is calculated.
B5: 1 | C5: Dashboard: moving day, the new home and your budget. Settings: the rooms of the home you leave.
B7: 2 | C7: Tasks: a checklist is ready, counted back from moving day. Put an x under Done as you go.
B9: 3 | C9: Boxes: write a number on each box and one line here. Put an x when it is packed and when it arrives.
B11: 4 | C11: Movers and Costs: compare the quotes, then note what you book, what you paid and when the rest is due.
B13: 5 | C13: New address: everyone who needs it, with the meter readings to take on moving day.
C16: The example move, its companies and its places are made up. Delete them and add your own.
C18: Change moving day and every task date moves with it.
C20: Works in Google Sheets and Microsoft Excel, in any currency.
