Workbook

Sheet Dashboard
B2: Order dashboard
B3: What is due, what you are owed, and what each month earned.
B5: Open orders | C5: Due in 7 days | D5: Late | F5: Owed to you | I5: Sales this month | J5: Profit this month | L5: Orders this month
B6: =COUNT(Orders!$T$6:$T$1005) | C6: =COUNTIFS(Orders!$T$6:$T$1005,">="&TODAY(),Orders!$T$6:$T$1005,"<"&(TODAY()+8)) | D6: =COUNTIFS(Orders!$T$6:$T$1005,"<"&TODAY()) | F6: =SUM(Orders!$J$6:$J$1005) | I6: =SUMIFS(Orders!$H$6:$H$1005,Orders!$B$6:$B$1005,">="&DATE(YEAR(TODAY()),MONTH(TODAY()),1),Orders!$B$6:$B$1005,"<="&EOMONTH(TODAY(),0),Orders!$L$6:$L$1005,"<>Cancelled") | J6: =SUMIFS(Orders!$Q$6:$Q$1005,Orders!$B$6:$B$1005,">="&DATE(YEAR(TODAY()),MONTH(TODAY()),1),Orders!$B$6:$B$1005,"<="&EOMONTH(TODAY(),0),Orders!$L$6:$L$1005,"<>Cancelled") | L6: =COUNTIFS(Orders!$B$6:$B$1005,">="&DATE(YEAR(TODAY()),MONTH(TODAY()),1),Orders!$B$6:$B$1005,"<="&EOMONTH(TODAY(),0),Orders!$L$6:$L$1005,"<>Cancelled")
B8: Due | C8: Customer | D8: Product | E8: Qty | F8: Status | G8: When | I8: Needs attention
B9: =IF(O9="","",INT(O9)) | C9: =IF(O9="","",INDEX(Orders!$C$6:$C$1005,MATCH(O9,Orders!$T$6:$T$1005,0))) | D9: =IF(O9="","",INDEX(Orders!$D$6:$D$1005,MATCH(O9,Orders!$T$6:$T$1005,0))) | E9: =IF(O9="","",INDEX(Orders!$E$6:$E$1005,MATCH(O9,Orders!$T$6:$T$1005,0))) | F9: =IF(O9="","",INDEX(Orders!$L$6:$L$1005,MATCH(O9,Orders!$T$6:$T$1005,0))) | G9: =IF(O9="","",INDEX(Orders!$R$6:$R$1005,MATCH(O9,Orders!$T$6:$T$1005,0))) | I9: =IF(COUNTIFS(Orders!$T$6:$T$1005,"<"&TODAY())=0,"No order is late",IF(COUNTIFS(Orders!$T$6:$T$1005,"<"&TODAY())=1,"1 order is",COUNTIFS(Orders!$T$6:$T$1005,"<"&TODAY())&" orders are")&" past its due date") | O9: =IFERROR(SMALL(Orders!$T$6:$T$1005,1),"")
B10: =IF(O10="","",INT(O10)) | C10: =IF(O10="","",INDEX(Orders!$C$6:$C$1005,MATCH(O10,Orders!$T$6:$T$1005,0))) | D10: =IF(O10="","",INDEX(Orders!$D$6:$D$1005,MATCH(O10,Orders!$T$6:$T$1005,0))) | E10: =IF(O10="","",INDEX(Orders!$E$6:$E$1005,MATCH(O10,Orders!$T$6:$T$1005,0))) | F10: =IF(O10="","",INDEX(Orders!$L$6:$L$1005,MATCH(O10,Orders!$T$6:$T$1005,0))) | G10: =IF(O10="","",INDEX(Orders!$R$6:$R$1005,MATCH(O10,Orders!$T$6:$T$1005,0))) | I10: =IF(COUNTIFS(Orders!$J$6:$J$1005,">0")=0,"Every order is paid",IF(COUNTIFS(Orders!$J$6:$J$1005,">0")=1,"1 order has",COUNTIFS(Orders!$J$6:$J$1005,">0")&" orders have")&" a balance to collect: "&FIXED(SUM(Orders!$J$6:$J$1005),2)) | O10: =IFERROR(SMALL(Orders!$T$6:$T$1005,2),"")
B11: =IF(O11="","",INT(O11)) | C11: =IF(O11="","",INDEX(Orders!$C$6:$C$1005,MATCH(O11,Orders!$T$6:$T$1005,0))) | D11: =IF(O11="","",INDEX(Orders!$D$6:$D$1005,MATCH(O11,Orders!$T$6:$T$1005,0))) | E11: =IF(O11="","",INDEX(Orders!$E$6:$E$1005,MATCH(O11,Orders!$T$6:$T$1005,0))) | F11: =IF(O11="","",INDEX(Orders!$L$6:$L$1005,MATCH(O11,Orders!$T$6:$T$1005,0))) | G11: =IF(O11="","",INDEX(Orders!$R$6:$R$1005,MATCH(O11,Orders!$T$6:$T$1005,0))) | I11: =IF(COUNTIFS(Materials!$I$6:$I$205,">0")=0,"You have the materials for every open order",IF(COUNTIFS(Materials!$I$6:$I$205,">0")=1,"1 material is",COUNTIFS(Materials!$I$6:$I$205,">0")&" materials are")&" short for the open orders") | O11: =IFERROR(SMALL(Orders!$T$6:$T$1005,3),"")
B12: =IF(O12="","",INT(O12)) | C12: =IF(O12="","",INDEX(Orders!$C$6:$C$1005,MATCH(O12,Orders!$T$6:$T$1005,0))) | D12: =IF(O12="","",INDEX(Orders!$D$6:$D$1005,MATCH(O12,Orders!$T$6:$T$1005,0))) | E12: =IF(O12="","",INDEX(Orders!$E$6:$E$1005,MATCH(O12,Orders!$T$6:$T$1005,0))) | F12: =IF(O12="","",INDEX(Orders!$L$6:$L$1005,MATCH(O12,Orders!$T$6:$T$1005,0))) | G12: =IF(O12="","",INDEX(Orders!$R$6:$R$1005,MATCH(O12,Orders!$T$6:$T$1005,0))) | I12: =IF(COUNTIFS('Product materials'!$E$6:$E$505,"Add it to Materials")=0,"Every product has its cost",IF(COUNTIFS('Product materials'!$E$6:$E$505,"Add it to Materials")=1,"1 material line is",COUNTIFS('Product materials'!$E$6:$E$505,"Add it to Materials")&" material lines are")&" missing from Materials") | O12: =IFERROR(SMALL(Orders!$T$6:$T$1005,4),"")
B13: =IF(O13="","",INT(O13)) | C13: =IF(O13="","",INDEX(Orders!$C$6:$C$1005,MATCH(O13,Orders!$T$6:$T$1005,0))) | D13: =IF(O13="","",INDEX(Orders!$D$6:$D$1005,MATCH(O13,Orders!$T$6:$T$1005,0))) | E13: =IF(O13="","",INDEX(Orders!$E$6:$E$1005,MATCH(O13,Orders!$T$6:$T$1005,0))) | F13: =IF(O13="","",INDEX(Orders!$L$6:$L$1005,MATCH(O13,Orders!$T$6:$T$1005,0))) | G13: =IF(O13="","",INDEX(Orders!$R$6:$R$1005,MATCH(O13,Orders!$T$6:$T$1005,0))) | O13: =IFERROR(SMALL(Orders!$T$6:$T$1005,5),"")
B14: =IF(O14="","",INT(O14)) | C14: =IF(O14="","",INDEX(Orders!$C$6:$C$1005,MATCH(O14,Orders!$T$6:$T$1005,0))) | D14: =IF(O14="","",INDEX(Orders!$D$6:$D$1005,MATCH(O14,Orders!$T$6:$T$1005,0))) | E14: =IF(O14="","",INDEX(Orders!$E$6:$E$1005,MATCH(O14,Orders!$T$6:$T$1005,0))) | F14: =IF(O14="","",INDEX(Orders!$L$6:$L$1005,MATCH(O14,Orders!$T$6:$T$1005,0))) | G14: =IF(O14="","",INDEX(Orders!$R$6:$R$1005,MATCH(O14,Orders!$T$6:$T$1005,0))) | I14: Channel this year | J14: Orders | K14: Sales | L14: Profit | O14: =IFERROR(SMALL(Orders!$T$6:$T$1005,6),"")
B15: =IF(O15="","",INT(O15)) | C15: =IF(O15="","",INDEX(Orders!$C$6:$C$1005,MATCH(O15,Orders!$T$6:$T$1005,0))) | D15: =IF(O15="","",INDEX(Orders!$D$6:$D$1005,MATCH(O15,Orders!$T$6:$T$1005,0))) | E15: =IF(O15="","",INDEX(Orders!$E$6:$E$1005,MATCH(O15,Orders!$T$6:$T$1005,0))) | F15: =IF(O15="","",INDEX(Orders!$L$6:$L$1005,MATCH(O15,Orders!$T$6:$T$1005,0))) | G15: =IF(O15="","",INDEX(Orders!$R$6:$R$1005,MATCH(O15,Orders!$T$6:$T$1005,0))) | I15: =IF(Settings!B6="","",Settings!B6) | J15: =IF(I15="","",COUNTIFS(Orders!$M$6:$M$1005,I15,Orders!$L$6:$L$1005,"<>Cancelled",Orders!$B$6:$B$1005,">="&DATE(YEAR(TODAY()),1,1))) | K15: =IF(I15="","",SUMIFS(Orders!$H$6:$H$1005,Orders!$M$6:$M$1005,I15,Orders!$L$6:$L$1005,"<>Cancelled",Orders!$B$6:$B$1005,">="&DATE(YEAR(TODAY()),1,1))) | L15: =IF(I15="","",SUMIFS(Orders!$Q$6:$Q$1005,Orders!$M$6:$M$1005,I15,Orders!$L$6:$L$1005,"<>Cancelled",Orders!$B$6:$B$1005,">="&DATE(YEAR(TODAY()),1,1))) | O15: =IFERROR(SMALL(Orders!$T$6:$T$1005,7),"")
B16: =IF(O16="","",INT(O16)) | C16: =IF(O16="","",INDEX(Orders!$C$6:$C$1005,MATCH(O16,Orders!$T$6:$T$1005,0))) | D16: =IF(O16="","",INDEX(Orders!$D$6:$D$1005,MATCH(O16,Orders!$T$6:$T$1005,0))) | E16: =IF(O16="","",INDEX(Orders!$E$6:$E$1005,MATCH(O16,Orders!$T$6:$T$1005,0))) | F16: =IF(O16="","",INDEX(Orders!$L$6:$L$1005,MATCH(O16,Orders!$T$6:$T$1005,0))) | G16: =IF(O16="","",INDEX(Orders!$R$6:$R$1005,MATCH(O16,Orders!$T$6:$T$1005,0))) | I16: =IF(Settings!B7="","",Settings!B7) | J16: =IF(I16="","",COUNTIFS(Orders!$M$6:$M$1005,I16,Orders!$L$6:$L$1005,"<>Cancelled",Orders!$B$6:$B$1005,">="&DATE(YEAR(TODAY()),1,1))) | K16: =IF(I16="","",SUMIFS(Orders!$H$6:$H$1005,Orders!$M$6:$M$1005,I16,Orders!$L$6:$L$1005,"<>Cancelled",Orders!$B$6:$B$1005,">="&DATE(YEAR(TODAY()),1,1))) | L16: =IF(I16="","",SUMIFS(Orders!$Q$6:$Q$1005,Orders!$M$6:$M$1005,I16,Orders!$L$6:$L$1005,"<>Cancelled",Orders!$B$6:$B$1005,">="&DATE(YEAR(TODAY()),1,1))) | O16: =IFERROR(SMALL(Orders!$T$6:$T$1005,8),"")
B17: =IF(O17="","",INT(O17)) | C17: =IF(O17="","",INDEX(Orders!$C$6:$C$1005,MATCH(O17,Orders!$T$6:$T$1005,0))) | D17: =IF(O17="","",INDEX(Orders!$D$6:$D$1005,MATCH(O17,Orders!$T$6:$T$1005,0))) | E17: =IF(O17="","",INDEX(Orders!$E$6:$E$1005,MATCH(O17,Orders!$T$6:$T$1005,0))) | F17: =IF(O17="","",INDEX(Orders!$L$6:$L$1005,MATCH(O17,Orders!$T$6:$T$1005,0))) | G17: =IF(O17="","",INDEX(Orders!$R$6:$R$1005,MATCH(O17,Orders!$T$6:$T$1005,0))) | I17: =IF(Settings!B8="","",Settings!B8) | J17: =IF(I17="","",COUNTIFS(Orders!$M$6:$M$1005,I17,Orders!$L$6:$L$1005,"<>Cancelled",Orders!$B$6:$B$1005,">="&DATE(YEAR(TODAY()),1,1))) | K17: =IF(I17="","",SUMIFS(Orders!$H$6:$H$1005,Orders!$M$6:$M$1005,I17,Orders!$L$6:$L$1005,"<>Cancelled",Orders!$B$6:$B$1005,">="&DATE(YEAR(TODAY()),1,1))) | L17: =IF(I17="","",SUMIFS(Orders!$Q$6:$Q$1005,Orders!$M$6:$M$1005,I17,Orders!$L$6:$L$1005,"<>Cancelled",Orders!$B$6:$B$1005,">="&DATE(YEAR(TODAY()),1,1))) | O17: =IFERROR(SMALL(Orders!$T$6:$T$1005,9),"")
B18: =IF(O18="","",INT(O18)) | C18: =IF(O18="","",INDEX(Orders!$C$6:$C$1005,MATCH(O18,Orders!$T$6:$T$1005,0))) | D18: =IF(O18="","",INDEX(Orders!$D$6:$D$1005,MATCH(O18,Orders!$T$6:$T$1005,0))) | E18: =IF(O18="","",INDEX(Orders!$E$6:$E$1005,MATCH(O18,Orders!$T$6:$T$1005,0))) | F18: =IF(O18="","",INDEX(Orders!$L$6:$L$1005,MATCH(O18,Orders!$T$6:$T$1005,0))) | G18: =IF(O18="","",INDEX(Orders!$R$6:$R$1005,MATCH(O18,Orders!$T$6:$T$1005,0))) | I18: =IF(Settings!B9="","",Settings!B9) | J18: =IF(I18="","",COUNTIFS(Orders!$M$6:$M$1005,I18,Orders!$L$6:$L$1005,"<>Cancelled",Orders!$B$6:$B$1005,">="&DATE(YEAR(TODAY()),1,1))) | K18: =IF(I18="","",SUMIFS(Orders!$H$6:$H$1005,Orders!$M$6:$M$1005,I18,Orders!$L$6:$L$1005,"<>Cancelled",Orders!$B$6:$B$1005,">="&DATE(YEAR(TODAY()),1,1))) | L18: =IF(I18="","",SUMIFS(Orders!$Q$6:$Q$1005,Orders!$M$6:$M$1005,I18,Orders!$L$6:$L$1005,"<>Cancelled",Orders!$B$6:$B$1005,">="&DATE(YEAR(TODAY()),1,1))) | O18: =IFERROR(SMALL(Orders!$T$6:$T$1005,10),"")
B19: Open orders, the soonest due first. Late orders come first. | I19: =IF(Settings!B10="","",Settings!B10) | J19: =IF(I19="","",COUNTIFS(Orders!$M$6:$M$1005,I19,Orders!$L$6:$L$1005,"<>Cancelled",Orders!$B$6:$B$1005,">="&DATE(YEAR(TODAY()),1,1))) | K19: =IF(I19="","",SUMIFS(Orders!$H$6:$H$1005,Orders!$M$6:$M$1005,I19,Orders!$L$6:$L$1005,"<>Cancelled",Orders!$B$6:$B$1005,">="&DATE(YEAR(TODAY()),1,1))) | L19: =IF(I19="","",SUMIFS(Orders!$Q$6:$Q$1005,Orders!$M$6:$M$1005,I19,Orders!$L$6:$L$1005,"<>Cancelled",Orders!$B$6:$B$1005,">="&DATE(YEAR(TODAY()),1,1)))
B21: Year | C21: 2026
B23: Month | C23: Orders | D23: Sales | F23: Materials | G23: Fees and postage | H23: Profit
B24: Jan | C24: =COUNTIFS(Orders!$B$6:$B$1005,">="&DATE($C$21,1,1),Orders!$B$6:$B$1005,"<="&EOMONTH(DATE($C$21,1,1),0),Orders!$L$6:$L$1005,"<>Cancelled") | D24: =SUMIFS(Orders!$H$6:$H$1005,Orders!$B$6:$B$1005,">="&DATE($C$21,1,1),Orders!$B$6:$B$1005,"<="&EOMONTH(DATE($C$21,1,1),0),Orders!$L$6:$L$1005,"<>Cancelled") | F24: =SUMIFS(Orders!$N$6:$N$1005,Orders!$B$6:$B$1005,">="&DATE($C$21,1,1),Orders!$B$6:$B$1005,"<="&EOMONTH(DATE($C$21,1,1),0),Orders!$L$6:$L$1005,"<>Cancelled") | G24: =SUMIFS(Orders!$O$6:$O$1005,Orders!$B$6:$B$1005,">="&DATE($C$21,1,1),Orders!$B$6:$B$1005,"<="&EOMONTH(DATE($C$21,1,1),0),Orders!$L$6:$L$1005,"<>Cancelled")+SUMIFS(Orders!$P$6:$P$1005,Orders!$B$6:$B$1005,">="&DATE($C$21,1,1),Orders!$B$6:$B$1005,"<="&EOMONTH(DATE($C$21,1,1),0),Orders!$L$6:$L$1005,"<>Cancelled") | H24: =D24-F24-G24
B25: Feb | C25: =COUNTIFS(Orders!$B$6:$B$1005,">="&DATE($C$21,2,1),Orders!$B$6:$B$1005,"<="&EOMONTH(DATE($C$21,2,1),0),Orders!$L$6:$L$1005,"<>Cancelled") | D25: =SUMIFS(Orders!$H$6:$H$1005,Orders!$B$6:$B$1005,">="&DATE($C$21,2,1),Orders!$B$6:$B$1005,"<="&EOMONTH(DATE($C$21,2,1),0),Orders!$L$6:$L$1005,"<>Cancelled") | F25: =SUMIFS(Orders!$N$6:$N$1005,Orders!$B$6:$B$1005,">="&DATE($C$21,2,1),Orders!$B$6:$B$1005,"<="&EOMONTH(DATE($C$21,2,1),0),Orders!$L$6:$L$1005,"<>Cancelled") | G25: =SUMIFS(Orders!$O$6:$O$1005,Orders!$B$6:$B$1005,">="&DATE($C$21,2,1),Orders!$B$6:$B$1005,"<="&EOMONTH(DATE($C$21,2,1),0),Orders!$L$6:$L$1005,"<>Cancelled")+SUMIFS(Orders!$P$6:$P$1005,Orders!$B$6:$B$1005,">="&DATE($C$21,2,1),Orders!$B$6:$B$1005,"<="&EOMONTH(DATE($C$21,2,1),0),Orders!$L$6:$L$1005,"<>Cancelled") | H25: =D25-F25-G25
B26: Mar | C26: =COUNTIFS(Orders!$B$6:$B$1005,">="&DATE($C$21,3,1),Orders!$B$6:$B$1005,"<="&EOMONTH(DATE($C$21,3,1),0),Orders!$L$6:$L$1005,"<>Cancelled") | D26: =SUMIFS(Orders!$H$6:$H$1005,Orders!$B$6:$B$1005,">="&DATE($C$21,3,1),Orders!$B$6:$B$1005,"<="&EOMONTH(DATE($C$21,3,1),0),Orders!$L$6:$L$1005,"<>Cancelled") | F26: =SUMIFS(Orders!$N$6:$N$1005,Orders!$B$6:$B$1005,">="&DATE($C$21,3,1),Orders!$B$6:$B$1005,"<="&EOMONTH(DATE($C$21,3,1),0),Orders!$L$6:$L$1005,"<>Cancelled") | G26: =SUMIFS(Orders!$O$6:$O$1005,Orders!$B$6:$B$1005,">="&DATE($C$21,3,1),Orders!$B$6:$B$1005,"<="&EOMONTH(DATE($C$21,3,1),0),Orders!$L$6:$L$1005,"<>Cancelled")+SUMIFS(Orders!$P$6:$P$1005,Orders!$B$6:$B$1005,">="&DATE($C$21,3,1),Orders!$B$6:$B$1005,"<="&EOMONTH(DATE($C$21,3,1),0),Orders!$L$6:$L$1005,"<>Cancelled") | H26: =D26-F26-G26
B27: Apr | C27: =COUNTIFS(Orders!$B$6:$B$1005,">="&DATE($C$21,4,1),Orders!$B$6:$B$1005,"<="&EOMONTH(DATE($C$21,4,1),0),Orders!$L$6:$L$1005,"<>Cancelled") | D27: =SUMIFS(Orders!$H$6:$H$1005,Orders!$B$6:$B$1005,">="&DATE($C$21,4,1),Orders!$B$6:$B$1005,"<="&EOMONTH(DATE($C$21,4,1),0),Orders!$L$6:$L$1005,"<>Cancelled") | F27: =SUMIFS(Orders!$N$6:$N$1005,Orders!$B$6:$B$1005,">="&DATE($C$21,4,1),Orders!$B$6:$B$1005,"<="&EOMONTH(DATE($C$21,4,1),0),Orders!$L$6:$L$1005,"<>Cancelled") | G27: =SUMIFS(Orders!$O$6:$O$1005,Orders!$B$6:$B$1005,">="&DATE($C$21,4,1),Orders!$B$6:$B$1005,"<="&EOMONTH(DATE($C$21,4,1),0),Orders!$L$6:$L$1005,"<>Cancelled")+SUMIFS(Orders!$P$6:$P$1005,Orders!$B$6:$B$1005,">="&DATE($C$21,4,1),Orders!$B$6:$B$1005,"<="&EOMONTH(DATE($C$21,4,1),0),Orders!$L$6:$L$1005,"<>Cancelled") | H27: =D27-F27-G27
B28: May | C28: =COUNTIFS(Orders!$B$6:$B$1005,">="&DATE($C$21,5,1),Orders!$B$6:$B$1005,"<="&EOMONTH(DATE($C$21,5,1),0),Orders!$L$6:$L$1005,"<>Cancelled") | D28: =SUMIFS(Orders!$H$6:$H$1005,Orders!$B$6:$B$1005,">="&DATE($C$21,5,1),Orders!$B$6:$B$1005,"<="&EOMONTH(DATE($C$21,5,1),0),Orders!$L$6:$L$1005,"<>Cancelled") | F28: =SUMIFS(Orders!$N$6:$N$1005,Orders!$B$6:$B$1005,">="&DATE($C$21,5,1),Orders!$B$6:$B$1005,"<="&EOMONTH(DATE($C$21,5,1),0),Orders!$L$6:$L$1005,"<>Cancelled") | G28: =SUMIFS(Orders!$O$6:$O$1005,Orders!$B$6:$B$1005,">="&DATE($C$21,5,1),Orders!$B$6:$B$1005,"<="&EOMONTH(DATE($C$21,5,1),0),Orders!$L$6:$L$1005,"<>Cancelled")+SUMIFS(Orders!$P$6:$P$1005,Orders!$B$6:$B$1005,">="&DATE($C$21,5,1),Orders!$B$6:$B$1005,"<="&EOMONTH(DATE($C$21,5,1),0),Orders!$L$6:$L$1005,"<>Cancelled") | H28: =D28-F28-G28
B29: Jun | C29: =COUNTIFS(Orders!$B$6:$B$1005,">="&DATE($C$21,6,1),Orders!$B$6:$B$1005,"<="&EOMONTH(DATE($C$21,6,1),0),Orders!$L$6:$L$1005,"<>Cancelled") | D29: =SUMIFS(Orders!$H$6:$H$1005,Orders!$B$6:$B$1005,">="&DATE($C$21,6,1),Orders!$B$6:$B$1005,"<="&EOMONTH(DATE($C$21,6,1),0),Orders!$L$6:$L$1005,"<>Cancelled") | F29: =SUMIFS(Orders!$N$6:$N$1005,Orders!$B$6:$B$1005,">="&DATE($C$21,6,1),Orders!$B$6:$B$1005,"<="&EOMONTH(DATE($C$21,6,1),0),Orders!$L$6:$L$1005,"<>Cancelled") | G29: =SUMIFS(Orders!$O$6:$O$1005,Orders!$B$6:$B$1005,">="&DATE($C$21,6,1),Orders!$B$6:$B$1005,"<="&EOMONTH(DATE($C$21,6,1),0),Orders!$L$6:$L$1005,"<>Cancelled")+SUMIFS(Orders!$P$6:$P$1005,Orders!$B$6:$B$1005,">="&DATE($C$21,6,1),Orders!$B$6:$B$1005,"<="&EOMONTH(DATE($C$21,6,1),0),Orders!$L$6:$L$1005,"<>Cancelled") | H29: =D29-F29-G29
B30: Jul | C30: =COUNTIFS(Orders!$B$6:$B$1005,">="&DATE($C$21,7,1),Orders!$B$6:$B$1005,"<="&EOMONTH(DATE($C$21,7,1),0),Orders!$L$6:$L$1005,"<>Cancelled") | D30: =SUMIFS(Orders!$H$6:$H$1005,Orders!$B$6:$B$1005,">="&DATE($C$21,7,1),Orders!$B$6:$B$1005,"<="&EOMONTH(DATE($C$21,7,1),0),Orders!$L$6:$L$1005,"<>Cancelled") | F30: =SUMIFS(Orders!$N$6:$N$1005,Orders!$B$6:$B$1005,">="&DATE($C$21,7,1),Orders!$B$6:$B$1005,"<="&EOMONTH(DATE($C$21,7,1),0),Orders!$L$6:$L$1005,"<>Cancelled") | G30: =SUMIFS(Orders!$O$6:$O$1005,Orders!$B$6:$B$1005,">="&DATE($C$21,7,1),Orders!$B$6:$B$1005,"<="&EOMONTH(DATE($C$21,7,1),0),Orders!$L$6:$L$1005,"<>Cancelled")+SUMIFS(Orders!$P$6:$P$1005,Orders!$B$6:$B$1005,">="&DATE($C$21,7,1),Orders!$B$6:$B$1005,"<="&EOMONTH(DATE($C$21,7,1),0),Orders!$L$6:$L$1005,"<>Cancelled") | H30: =D30-F30-G30
B31: Aug | C31: =COUNTIFS(Orders!$B$6:$B$1005,">="&DATE($C$21,8,1),Orders!$B$6:$B$1005,"<="&EOMONTH(DATE($C$21,8,1),0),Orders!$L$6:$L$1005,"<>Cancelled") | D31: =SUMIFS(Orders!$H$6:$H$1005,Orders!$B$6:$B$1005,">="&DATE($C$21,8,1),Orders!$B$6:$B$1005,"<="&EOMONTH(DATE($C$21,8,1),0),Orders!$L$6:$L$1005,"<>Cancelled") | F31: =SUMIFS(Orders!$N$6:$N$1005,Orders!$B$6:$B$1005,">="&DATE($C$21,8,1),Orders!$B$6:$B$1005,"<="&EOMONTH(DATE($C$21,8,1),0),Orders!$L$6:$L$1005,"<>Cancelled") | G31: =SUMIFS(Orders!$O$6:$O$1005,Orders!$B$6:$B$1005,">="&DATE($C$21,8,1),Orders!$B$6:$B$1005,"<="&EOMONTH(DATE($C$21,8,1),0),Orders!$L$6:$L$1005,"<>Cancelled")+SUMIFS(Orders!$P$6:$P$1005,Orders!$B$6:$B$1005,">="&DATE($C$21,8,1),Orders!$B$6:$B$1005,"<="&EOMONTH(DATE($C$21,8,1),0),Orders!$L$6:$L$1005,"<>Cancelled") | H31: =D31-F31-G31
B32: Sep | C32: =COUNTIFS(Orders!$B$6:$B$1005,">="&DATE($C$21,9,1),Orders!$B$6:$B$1005,"<="&EOMONTH(DATE($C$21,9,1),0),Orders!$L$6:$L$1005,"<>Cancelled") | D32: =SUMIFS(Orders!$H$6:$H$1005,Orders!$B$6:$B$1005,">="&DATE($C$21,9,1),Orders!$B$6:$B$1005,"<="&EOMONTH(DATE($C$21,9,1),0),Orders!$L$6:$L$1005,"<>Cancelled") | F32: =SUMIFS(Orders!$N$6:$N$1005,Orders!$B$6:$B$1005,">="&DATE($C$21,9,1),Orders!$B$6:$B$1005,"<="&EOMONTH(DATE($C$21,9,1),0),Orders!$L$6:$L$1005,"<>Cancelled") | G32: =SUMIFS(Orders!$O$6:$O$1005,Orders!$B$6:$B$1005,">="&DATE($C$21,9,1),Orders!$B$6:$B$1005,"<="&EOMONTH(DATE($C$21,9,1),0),Orders!$L$6:$L$1005,"<>Cancelled")+SUMIFS(Orders!$P$6:$P$1005,Orders!$B$6:$B$1005,">="&DATE($C$21,9,1),Orders!$B$6:$B$1005,"<="&EOMONTH(DATE($C$21,9,1),0),Orders!$L$6:$L$1005,"<>Cancelled") | H32: =D32-F32-G32
B33: Oct | C33: =COUNTIFS(Orders!$B$6:$B$1005,">="&DATE($C$21,10,1),Orders!$B$6:$B$1005,"<="&EOMONTH(DATE($C$21,10,1),0),Orders!$L$6:$L$1005,"<>Cancelled") | D33: =SUMIFS(Orders!$H$6:$H$1005,Orders!$B$6:$B$1005,">="&DATE($C$21,10,1),Orders!$B$6:$B$1005,"<="&EOMONTH(DATE($C$21,10,1),0),Orders!$L$6:$L$1005,"<>Cancelled") | F33: =SUMIFS(Orders!$N$6:$N$1005,Orders!$B$6:$B$1005,">="&DATE($C$21,10,1),Orders!$B$6:$B$1005,"<="&EOMONTH(DATE($C$21,10,1),0),Orders!$L$6:$L$1005,"<>Cancelled") | G33: =SUMIFS(Orders!$O$6:$O$1005,Orders!$B$6:$B$1005,">="&DATE($C$21,10,1),Orders!$B$6:$B$1005,"<="&EOMONTH(DATE($C$21,10,1),0),Orders!$L$6:$L$1005,"<>Cancelled")+SUMIFS(Orders!$P$6:$P$1005,Orders!$B$6:$B$1005,">="&DATE($C$21,10,1),Orders!$B$6:$B$1005,"<="&EOMONTH(DATE($C$21,10,1),0),Orders!$L$6:$L$1005,"<>Cancelled") | H33: =D33-F33-G33
B34: Nov | C34: =COUNTIFS(Orders!$B$6:$B$1005,">="&DATE($C$21,11,1),Orders!$B$6:$B$1005,"<="&EOMONTH(DATE($C$21,11,1),0),Orders!$L$6:$L$1005,"<>Cancelled") | D34: =SUMIFS(Orders!$H$6:$H$1005,Orders!$B$6:$B$1005,">="&DATE($C$21,11,1),Orders!$B$6:$B$1005,"<="&EOMONTH(DATE($C$21,11,1),0),Orders!$L$6:$L$1005,"<>Cancelled") | F34: =SUMIFS(Orders!$N$6:$N$1005,Orders!$B$6:$B$1005,">="&DATE($C$21,11,1),Orders!$B$6:$B$1005,"<="&EOMONTH(DATE($C$21,11,1),0),Orders!$L$6:$L$1005,"<>Cancelled") | G34: =SUMIFS(Orders!$O$6:$O$1005,Orders!$B$6:$B$1005,">="&DATE($C$21,11,1),Orders!$B$6:$B$1005,"<="&EOMONTH(DATE($C$21,11,1),0),Orders!$L$6:$L$1005,"<>Cancelled")+SUMIFS(Orders!$P$6:$P$1005,Orders!$B$6:$B$1005,">="&DATE($C$21,11,1),Orders!$B$6:$B$1005,"<="&EOMONTH(DATE($C$21,11,1),0),Orders!$L$6:$L$1005,"<>Cancelled") | H34: =D34-F34-G34
B35: Dec | C35: =COUNTIFS(Orders!$B$6:$B$1005,">="&DATE($C$21,12,1),Orders!$B$6:$B$1005,"<="&EOMONTH(DATE($C$21,12,1),0),Orders!$L$6:$L$1005,"<>Cancelled") | D35: =SUMIFS(Orders!$H$6:$H$1005,Orders!$B$6:$B$1005,">="&DATE($C$21,12,1),Orders!$B$6:$B$1005,"<="&EOMONTH(DATE($C$21,12,1),0),Orders!$L$6:$L$1005,"<>Cancelled") | F35: =SUMIFS(Orders!$N$6:$N$1005,Orders!$B$6:$B$1005,">="&DATE($C$21,12,1),Orders!$B$6:$B$1005,"<="&EOMONTH(DATE($C$21,12,1),0),Orders!$L$6:$L$1005,"<>Cancelled") | G35: =SUMIFS(Orders!$O$6:$O$1005,Orders!$B$6:$B$1005,">="&DATE($C$21,12,1),Orders!$B$6:$B$1005,"<="&EOMONTH(DATE($C$21,12,1),0),Orders!$L$6:$L$1005,"<>Cancelled")+SUMIFS(Orders!$P$6:$P$1005,Orders!$B$6:$B$1005,">="&DATE($C$21,12,1),Orders!$B$6:$B$1005,"<="&EOMONTH(DATE($C$21,12,1),0),Orders!$L$6:$L$1005,"<>Cancelled") | H35: =D35-F35-G35
B36: Year | C36: =SUM(C24:C35) | D36: =SUM(D24:D35) | F36: =SUM(F24:F35) | G36: =SUM(G24:G35) | H36: =SUM(H24:H35)

Sheet Orders
B2: Orders
B3: One line per order. The total, costs, fees and profit fill in from your products and channels.
B5: Order date | C5: Customer | D5: Product | E5: Qty | F5: Extras | G5: Shipping charged | H5: Total | I5: Paid so far | J5: Balance | K5: Due date | L5: Status | M5: Channel | N5: Materials | O5: Postage | P5: Fees | Q5: Profit | R5: Due | S5: Note
B6: 46028 | C6: Dan King | D6: Soy candle 8 oz | E6: 1 | G6: 6.95 | H6: =IF(OR(B6="",D6=""),"",IF(N(E6)=0,1,E6)*IFERROR(INDEX(Products!$C$6:$C$105,MATCH(D6,Products!$B$6:$B$105,0)),0)+N(F6)+N(G6)) | I6: 28.95 | J6: =IF(OR(H6="",L6="Cancelled"),"",IF(H6-N(I6)>0.005,H6-N(I6),"")) | K6: 46036 | L6: Sent | M6: Etsy | N6: =IF(OR(H6="",L6="Cancelled"),"",IF(N(E6)=0,1,E6)*IFERROR(INDEX(Products!$E$6:$E$105,MATCH(D6,Products!$B$6:$B$105,0)),0)) | O6: 6.6 | P6: =IF(OR(H6="",L6="Cancelled"),"",ROUND(IFERROR(H6*INDEX(Settings!$C$6:$C$15,MATCH(M6,Settings!$B$6:$B$15,0))+INDEX(Settings!$D$6:$D$15,MATCH(M6,Settings!$B$6:$B$15,0)),0),2)) | Q6: =IF(OR(H6="",L6="Cancelled"),"",H6-N(N6)-N(O6)-N(P6)) | R6: =IF(OR(B6="",K6=""),"",IF(OR(L6="Sent",L6="Picked up"),"Done",IF(L6="Cancelled","Cancelled",IF(K6<TODAY(),"Late by "&(TODAY()-K6)&IF((TODAY()-K6)=1," day"," days"),IF(K6=TODAY(),"Due today","Due in "&(K6-TODAY())&IF((K6-TODAY())=1," day"," days")))))) | T6: =IF(AND(B6<>"",K6<>"",L6<>"Sent",L6<>"Picked up",L6<>"Cancelled"),K6+ROW()/10000000,"") | U6: =IF(OR(B6="",C6=""),"",B6+ROW()/10000000) | V6: =IF(U6="","",IF(COUNTIFS(Orders!$C$6:$C$1005,C6,Orders!$U$6:$U$1005,">"&U6)=0,1,0)) | W6: =IF(AND(B6<>"",K6<>"",L6<>"Sent",L6<>"Picked up",L6<>"Cancelled"),IF(N(E6)=0,1,E6),0) | X6: =IF(OR(B6="",D6=""),"",IF(N(E6)=0,1,E6))
B7: 46028 | C7: Ava Adams | D7: Soy candle 8 oz | E7: 1 | G7: 6.95 | H7: =IF(OR(B7="",D7=""),"",IF(N(E7)=0,1,E7)*IFERROR(INDEX(Products!$C$6:$C$105,MATCH(D7,Products!$B$6:$B$105,0)),0)+N(F7)+N(G7)) | I7: 28.95 | J7: =IF(OR(H7="",L7="Cancelled"),"",IF(H7-N(I7)>0.005,H7-N(I7),"")) | K7: 46038 | L7: Sent | M7: Own website | N7: =IF(OR(H7="",L7="Cancelled"),"",IF(N(E7)=0,1,E7)*IFERROR(INDEX(Products!$E$6:$E$105,MATCH(D7,Products!$B$6:$B$105,0)),0)) | O7: 7.13 | P7: =IF(OR(H7="",L7="Cancelled"),"",ROUND(IFERROR(H7*INDEX(Settings!$C$6:$C$15,MATCH(M7,Settings!$B$6:$B$15,0))+INDEX(Settings!$D$6:$D$15,MATCH(M7,Settings!$B$6:$B$15,0)),0),2)) | Q7: =IF(OR(H7="",L7="Cancelled"),"",H7-N(N7)-N(O7)-N(P7)) | R7: =IF(OR(B7="",K7=""),"",IF(OR(L7="Sent",L7="Picked up"),"Done",IF(L7="Cancelled","Cancelled",IF(K7<TODAY(),"Late by "&(TODAY()-K7)&IF((TODAY()-K7)=1," day"," days"),IF(K7=TODAY(),"Due today","Due in "&(K7-TODAY())&IF((K7-TODAY())=1," day"," days")))))) | T7: =IF(AND(B7<>"",K7<>"",L7<>"Sent",L7<>"Picked up",L7<>"Cancelled"),K7+ROW()/10000000,"") | U7: =IF(OR(B7="",C7=""),"",B7+ROW()/10000000) | V7: =IF(U7="","",IF(COUNTIFS(Orders!$C$6:$C$1005,C7,Orders!$U$6:$U$1005,">"&U7)=0,1,0)) | W7: =IF(AND(B7<>"",K7<>"",L7<>"Sent",L7<>"Picked up",L7<>"Cancelled"),IF(N(E7)=0,1,E7),0) | X7: =IF(OR(B7="",D7=""),"",IF(N(E7)=0,1,E7))
B8: 46032 | C8: Nora Lewis | D8: Soy candle 16 oz | E8: 4 | G8: 6.95 | H8: =IF(OR(B8="",D8=""),"",IF(N(E8)=0,1,E8)*IFERROR(INDEX(Products!$C$6:$C$105,MATCH(D8,Products!$B$6:$B$105,0)),0)+N(F8)+N(G8)) | I8: 142.95 | J8: =IF(OR(H8="",L8="Cancelled"),"",IF(H8-N(I8)>0.005,H8-N(I8),"")) | K8: 46040 | L8: Sent | M8: Etsy | N8: =IF(OR(H8="",L8="Cancelled"),"",IF(N(E8)=0,1,E8)*IFERROR(INDEX(Products!$E$6:$E$105,MATCH(D8,Products!$B$6:$B$105,0)),0)) | O8: 6.77 | P8: =IF(OR(H8="",L8="Cancelled"),"",ROUND(IFERROR(H8*INDEX(Settings!$C$6:$C$15,MATCH(M8,Settings!$B$6:$B$15,0))+INDEX(Settings!$D$6:$D$15,MATCH(M8,Settings!$B$6:$B$15,0)),0),2)) | Q8: =IF(OR(H8="",L8="Cancelled"),"",H8-N(N8)-N(O8)-N(P8)) | R8: =IF(OR(B8="",K8=""),"",IF(OR(L8="Sent",L8="Picked up"),"Done",IF(L8="Cancelled","Cancelled",IF(K8<TODAY(),"Late by "&(TODAY()-K8)&IF((TODAY()-K8)=1," day"," days"),IF(K8=TODAY(),"Due today","Due in "&(K8-TODAY())&IF((K8-TODAY())=1," day"," days")))))) | T8: =IF(AND(B8<>"",K8<>"",L8<>"Sent",L8<>"Picked up",L8<>"Cancelled"),K8+ROW()/10000000,"") | U8: =IF(OR(B8="",C8=""),"",B8+ROW()/10000000) | V8: =IF(U8="","",IF(COUNTIFS(Orders!$C$6:$C$1005,C8,Orders!$U$6:$U$1005,">"&U8)=0,1,0)) | W8: =IF(AND(B8<>"",K8<>"",L8<>"Sent",L8<>"Picked up",L8<>"Cancelled"),IF(N(E8)=0,1,E8),0) | X8: =IF(OR(B8="",D8=""),"",IF(N(E8)=0,1,E8))
B9: 46032 | C9: George Hill | D9: Soap bar | E9: 1 | G9: 6.95 | H9: =IF(OR(B9="",D9=""),"",IF(N(E9)=0,1,E9)*IFERROR(INDEX(Products!$C$6:$C$105,MATCH(D9,Products!$B$6:$B$105,0)),0)+N(F9)+N(G9)) | I9: 14.95 | J9: =IF(OR(H9="",L9="Cancelled"),"",IF(H9-N(I9)>0.005,H9-N(I9),"")) | K9: 46044 | L9: Sent | M9: Etsy | N9: =IF(OR(H9="",L9="Cancelled"),"",IF(N(E9)=0,1,E9)*IFERROR(INDEX(Products!$E$6:$E$105,MATCH(D9,Products!$B$6:$B$105,0)),0)) | O9: 6.69 | P9: =IF(OR(H9="",L9="Cancelled"),"",ROUND(IFERROR(H9*INDEX(Settings!$C$6:$C$15,MATCH(M9,Settings!$B$6:$B$15,0))+INDEX(Settings!$D$6:$D$15,MATCH(M9,Settings!$B$6:$B$15,0)),0),2)) | Q9: =IF(OR(H9="",L9="Cancelled"),"",H9-N(N9)-N(O9)-N(P9)) | R9: =IF(OR(B9="",K9=""),"",IF(OR(L9="Sent",L9="Picked up"),"Done",IF(L9="Cancelled","Cancelled",IF(K9<TODAY(),"Late by "&(TODAY()-K9)&IF((TODAY()-K9)=1," day"," days"),IF(K9=TODAY(),"Due today","Due in "&(K9-TODAY())&IF((K9-TODAY())=1," day"," days")))))) | T9: =IF(AND(B9<>"",K9<>"",L9<>"Sent",L9<>"Picked up",L9<>"Cancelled"),K9+ROW()/10000000,"") | U9: =IF(OR(B9="",C9=""),"",B9+ROW()/10000000) | V9: =IF(U9="","",IF(COUNTIFS(Orders!$C$6:$C$1005,C9,Orders!$U$6:$U$1005,">"&U9)=0,1,0)) | W9: =IF(AND(B9<>"",K9<>"",L9<>"Sent",L9<>"Picked up",L9<>"Cancelled"),IF(N(E9)=0,1,E9),0) | X9: =IF(OR(B9="",D9=""),"",IF(N(E9)=0,1,E9))
B10: 46034 | C10: Clara Mason | D10: Wedding favours, 10 tins | E10: 8 | G10: 6.95 | H10: =IF(OR(B10="",D10=""),"",IF(N(E10)=0,1,E10)*IFERROR(INDEX(Products!$C$6:$C$105,MATCH(D10,Products!$B$6:$B$105,0)),0)+N(F10)+N(G10)) | I10: 486.95 | J10: =IF(OR(H10="",L10="Cancelled"),"",IF(H10-N(I10)>0.005,H10-N(I10),"")) | K10: 46078 | L10: Sent | M10: Etsy | N10: =IF(OR(H10="",L10="Cancelled"),"",IF(N(E10)=0,1,E10)*IFERROR(INDEX(Products!$E$6:$E$105,MATCH(D10,Products!$B$6:$B$105,0)),0)) | O10: 7.74 | P10: =IF(OR(H10="",L10="Cancelled"),"",ROUND(IFERROR(H10*INDEX(Settings!$C$6:$C$15,MATCH(M10,Settings!$B$6:$B$15,0))+INDEX(Settings!$D$6:$D$15,MATCH(M10,Settings!$B$6:$B$15,0)),0),2)) | Q10: =IF(OR(H10="",L10="Cancelled"),"",H10-N(N10)-N(O10)-N(P10)) | R10: =IF(OR(B10="",K10=""),"",IF(OR(L10="Sent",L10="Picked up"),"Done",IF(L10="Cancelled","Cancelled",IF(K10<TODAY(),"Late by "&(TODAY()-K10)&IF((TODAY()-K10)=1," day"," days"),IF(K10=TODAY(),"Due today","Due in "&(K10-TODAY())&IF((K10-TODAY())=1," day"," days")))))) | T10: =IF(AND(B10<>"",K10<>"",L10<>"Sent",L10<>"Picked up",L10<>"Cancelled"),K10+ROW()/10000000,"") | U10: =IF(OR(B10="",C10=""),"",B10+ROW()/10000000) | V10: =IF(U10="","",IF(COUNTIFS(Orders!$C$6:$C$1005,C10,Orders!$U$6:$U$1005,">"&U10)=0,1,0)) | W10: =IF(AND(B10<>"",K10<>"",L10<>"Sent",L10<>"Picked up",L10<>"Cancelled"),IF(N(E10)=0,1,E10),0) | X10: =IF(OR(B10="",D10=""),"",IF(N(E10)=0,1,E10))
B11: 46035 | C11: Adam Cox | D11: Soy candle 8 oz | E11: 3 | F11: 15 | H11: =IF(OR(B11="",D11=""),"",IF(N(E11)=0,1,E11)*IFERROR(INDEX(Products!$C$6:$C$105,MATCH(D11,Products!$B$6:$B$105,0)),0)+N(F11)+N(G11)) | I11: 81 | J11: =IF(OR(H11="",L11="Cancelled"),"",IF(H11-N(I11)>0.005,H11-N(I11),"")) | K11: 46046 | L11: Picked up | M11: Instagram | N11: =IF(OR(H11="",L11="Cancelled"),"",IF(N(E11)=0,1,E11)*IFERROR(INDEX(Products!$E$6:$E$105,MATCH(D11,Products!$B$6:$B$105,0)),0)) | P11: =IF(OR(H11="",L11="Cancelled"),"",ROUND(IFERROR(H11*INDEX(Settings!$C$6:$C$15,MATCH(M11,Settings!$B$6:$B$15,0))+INDEX(Settings!$D$6:$D$15,MATCH(M11,Settings!$B$6:$B$15,0)),0),2)) | Q11: =IF(OR(H11="",L11="Cancelled"),"",H11-N(N11)-N(O11)-N(P11)) | R11: =IF(OR(B11="",K11=""),"",IF(OR(L11="Sent",L11="Picked up"),"Done",IF(L11="Cancelled","Cancelled",IF(K11<TODAY(),"Late by "&(TODAY()-K11)&IF((TODAY()-K11)=1," day"," days"),IF(K11=TODAY(),"Due today","Due in "&(K11-TODAY())&IF((K11-TODAY())=1," day"," days")))))) | S11: Custom label | T11: =IF(AND(B11<>"",K11<>"",L11<>"Sent",L11<>"Picked up",L11<>"Cancelled"),K11+ROW()/10000000,"") | U11: =IF(OR(B11="",C11=""),"",B11+ROW()/10000000) | V11: =IF(U11="","",IF(COUNTIFS(Orders!$C$6:$C$1005,C11,Orders!$U$6:$U$1005,">"&U11)=0,1,0)) | W11: =IF(AND(B11<>"",K11<>"",L11<>"Sent",L11<>"Picked up",L11<>"Cancelled"),IF(N(E11)=0,1,E11),0) | X11: =IF(OR(B11="",D11=""),"",IF(N(E11)=0,1,E11))
B12: 46037 | C12: Rita Price | D12: Soy candle 16 oz | E12: 1 | F12: 5 | G12: 6.95 | H12: =IF(OR(B12="",D12=""),"",IF(N(E12)=0,1,E12)*IFERROR(INDEX(Products!$C$6:$C$105,MATCH(D12,Products!$B$6:$B$105,0)),0)+N(F12)+N(G12)) | I12: 45.95 | J12: =IF(OR(H12="",L12="Cancelled"),"",IF(H12-N(I12)>0.005,H12-N(I12),"")) | K12: 46047 | L12: Sent | M12: Own website | N12: =IF(OR(H12="",L12="Cancelled"),"",IF(N(E12)=0,1,E12)*IFERROR(INDEX(Products!$E$6:$E$105,MATCH(D12,Products!$B$6:$B$105,0)),0)) | O12: 5.92 | P12: =IF(OR(H12="",L12="Cancelled"),"",ROUND(IFERROR(H12*INDEX(Settings!$C$6:$C$15,MATCH(M12,Settings!$B$6:$B$15,0))+INDEX(Settings!$D$6:$D$15,MATCH(M12,Settings!$B$6:$B$15,0)),0),2)) | Q12: =IF(OR(H12="",L12="Cancelled"),"",H12-N(N12)-N(O12)-N(P12)) | R12: =IF(OR(B12="",K12=""),"",IF(OR(L12="Sent",L12="Picked up"),"Done",IF(L12="Cancelled","Cancelled",IF(K12<TODAY(),"Late by "&(TODAY()-K12)&IF((TODAY()-K12)=1," day"," days"),IF(K12=TODAY(),"Due today","Due in "&(K12-TODAY())&IF((K12-TODAY())=1," day"," days")))))) | S12: Custom label | T12: =IF(AND(B12<>"",K12<>"",L12<>"Sent",L12<>"Picked up",L12<>"Cancelled"),K12+ROW()/10000000,"") | U12: =IF(OR(B12="",C12=""),"",B12+ROW()/10000000) | V12: =IF(U12="","",IF(COUNTIFS(Orders!$C$6:$C$1005,C12,Orders!$U$6:$U$1005,">"&U12)=0,1,0)) | W12: =IF(AND(B12<>"",K12<>"",L12<>"Sent",L12<>"Picked up",L12<>"Cancelled"),IF(N(E12)=0,1,E12),0) | X12: =IF(OR(B12="",D12=""),"",IF(N(E12)=0,1,E12))
B13: 46037 | C13: Jade Reed | D13: Wax melts, 6 pack | E13: 2 | G13: 6.95 | H13: =IF(OR(B13="",D13=""),"",IF(N(E13)=0,1,E13)*IFERROR(INDEX(Products!$C$6:$C$105,MATCH(D13,Products!$B$6:$B$105,0)),0)+N(F13)+N(G13)) | I13: 24.95 | J13: =IF(OR(H13="",L13="Cancelled"),"",IF(H13-N(I13)>0.005,H13-N(I13),"")) | K13: 46048 | L13: Sent | M13: Etsy | N13: =IF(OR(H13="",L13="Cancelled"),"",IF(N(E13)=0,1,E13)*IFERROR(INDEX(Products!$E$6:$E$105,MATCH(D13,Products!$B$6:$B$105,0)),0)) | O13: 7.58 | P13: =IF(OR(H13="",L13="Cancelled"),"",ROUND(IFERROR(H13*INDEX(Settings!$C$6:$C$15,MATCH(M13,Settings!$B$6:$B$15,0))+INDEX(Settings!$D$6:$D$15,MATCH(M13,Settings!$B$6:$B$15,0)),0),2)) | Q13: =IF(OR(H13="",L13="Cancelled"),"",H13-N(N13)-N(O13)-N(P13)) | R13: =IF(OR(B13="",K13=""),"",IF(OR(L13="Sent",L13="Picked up"),"Done",IF(L13="Cancelled","Cancelled",IF(K13<TODAY(),"Late by "&(TODAY()-K13)&IF((TODAY()-K13)=1," day"," days"),IF(K13=TODAY(),"Due today","Due in "&(K13-TODAY())&IF((K13-TODAY())=1," day"," days")))))) | T13: =IF(AND(B13<>"",K13<>"",L13<>"Sent",L13<>"Picked up",L13<>"Cancelled"),K13+ROW()/10000000,"") | U13: =IF(OR(B13="",C13=""),"",B13+ROW()/10000000) | V13: =IF(U13="","",IF(COUNTIFS(Orders!$C$6:$C$1005,C13,Orders!$U$6:$U$1005,">"&U13)=0,1,0)) | W13: =IF(AND(B13<>"",K13<>"",L13<>"Sent",L13<>"Picked up",L13<>"Cancelled"),IF(N(E13)=0,1,E13),0) | X13: =IF(OR(B13="",D13=""),"",IF(N(E13)=0,1,E13))
B14: 46040 | C14: Helen Kelly | D14: Soy candle 8 oz | E14: 4 | G14: 6.95 | H14: =IF(OR(B14="",D14=""),"",IF(N(E14)=0,1,E14)*IFERROR(INDEX(Products!$C$6:$C$105,MATCH(D14,Products!$B$6:$B$105,0)),0)+N(F14)+N(G14)) | I14: 94.95 | J14: =IF(OR(H14="",L14="Cancelled"),"",IF(H14-N(I14)>0.005,H14-N(I14),"")) | K14: 46048 | L14: Sent | M14: Etsy | N14: =IF(OR(H14="",L14="Cancelled"),"",IF(N(E14)=0,1,E14)*IFERROR(INDEX(Products!$E$6:$E$105,MATCH(D14,Products!$B$6:$B$105,0)),0)) | O14: 7.58 | P14: =IF(OR(H14="",L14="Cancelled"),"",ROUND(IFERROR(H14*INDEX(Settings!$C$6:$C$15,MATCH(M14,Settings!$B$6:$B$15,0))+INDEX(Settings!$D$6:$D$15,MATCH(M14,Settings!$B$6:$B$15,0)),0),2)) | Q14: =IF(OR(H14="",L14="Cancelled"),"",H14-N(N14)-N(O14)-N(P14)) | R14: =IF(OR(B14="",K14=""),"",IF(OR(L14="Sent",L14="Picked up"),"Done",IF(L14="Cancelled","Cancelled",IF(K14<TODAY(),"Late by "&(TODAY()-K14)&IF((TODAY()-K14)=1," day"," days"),IF(K14=TODAY(),"Due today","Due in "&(K14-TODAY())&IF((K14-TODAY())=1," day"," days")))))) | T14: =IF(AND(B14<>"",K14<>"",L14<>"Sent",L14<>"Picked up",L14<>"Cancelled"),K14+ROW()/10000000,"") | U14: =IF(OR(B14="",C14=""),"",B14+ROW()/10000000) | V14: =IF(U14="","",IF(COUNTIFS(Orders!$C$6:$C$1005,C14,Orders!$U$6:$U$1005,">"&U14)=0,1,0)) | W14: =IF(AND(B14<>"",K14<>"",L14<>"Sent",L14<>"Picked up",L14<>"Cancelled"),IF(N(E14)=0,1,E14),0) | X14: =IF(OR(B14="",D14=""),"",IF(N(E14)=0,1,E14))
B15: 46040 | C15: Leah Hughes | D15: Soy candle 16 oz | E15: 1 | H15: =IF(OR(B15="",D15=""),"",IF(N(E15)=0,1,E15)*IFERROR(INDEX(Products!$C$6:$C$105,MATCH(D15,Products!$B$6:$B$105,0)),0)+N(F15)+N(G15)) | I15: 34 | J15: =IF(OR(H15="",L15="Cancelled"),"",IF(H15-N(I15)>0.005,H15-N(I15),"")) | K15: 46048 | L15: Picked up | M15: Instagram | N15: =IF(OR(H15="",L15="Cancelled"),"",IF(N(E15)=0,1,E15)*IFERROR(INDEX(Products!$E$6:$E$105,MATCH(D15,Products!$B$6:$B$105,0)),0)) | P15: =IF(OR(H15="",L15="Cancelled"),"",ROUND(IFERROR(H15*INDEX(Settings!$C$6:$C$15,MATCH(M15,Settings!$B$6:$B$15,0))+INDEX(Settings!$D$6:$D$15,MATCH(M15,Settings!$B$6:$B$15,0)),0),2)) | Q15: =IF(OR(H15="",L15="Cancelled"),"",H15-N(N15)-N(O15)-N(P15)) | R15: =IF(OR(B15="",K15=""),"",IF(OR(L15="Sent",L15="Picked up"),"Done",IF(L15="Cancelled","Cancelled",IF(K15<TODAY(),"Late by "&(TODAY()-K15)&IF((TODAY()-K15)=1," day"," days"),IF(K15=TODAY(),"Due today","Due in "&(K15-TODAY())&IF((K15-TODAY())=1," day"," days")))))) | T15: =IF(AND(B15<>"",K15<>"",L15<>"Sent",L15<>"Picked up",L15<>"Cancelled"),K15+ROW()/10000000,"") | U15: =IF(OR(B15="",C15=""),"",B15+ROW()/10000000) | V15: =IF(U15="","",IF(COUNTIFS(Orders!$C$6:$C$1005,C15,Orders!$U$6:$U$1005,">"&U15)=0,1,0)) | W15: =IF(AND(B15<>"",K15<>"",L15<>"Sent",L15<>"Picked up",L15<>"Cancelled"),IF(N(E15)=0,1,E15),0) | X15: =IF(OR(B15="",D15=""),"",IF(N(E15)=0,1,E15))
B16: 46041 | C16: Adam Baker | D16: Soy candle 8 oz | E16: 3 | G16: 6.95 | H16: =IF(OR(B16="",D16=""),"",IF(N(E16)=0,1,E16)*IFERROR(INDEX(Products!$C$6:$C$105,MATCH(D16,Products!$B$6:$B$105,0)),0)+N(F16)+N(G16)) | I16: 72.95 | J16: =IF(OR(H16="",L16="Cancelled"),"",IF(H16-N(I16)>0.005,H16-N(I16),"")) | K16: 46046 | L16: Sent | M16: Etsy | N16: =IF(OR(H16="",L16="Cancelled"),"",IF(N(E16)=0,1,E16)*IFERROR(INDEX(Products!$E$6:$E$105,MATCH(D16,Products!$B$6:$B$105,0)),0)) | O16: 5.63 | P16: =IF(OR(H16="",L16="Cancelled"),"",ROUND(IFERROR(H16*INDEX(Settings!$C$6:$C$15,MATCH(M16,Settings!$B$6:$B$15,0))+INDEX(Settings!$D$6:$D$15,MATCH(M16,Settings!$B$6:$B$15,0)),0),2)) | Q16: =IF(OR(H16="",L16="Cancelled"),"",H16-N(N16)-N(O16)-N(P16)) | R16: =IF(OR(B16="",K16=""),"",IF(OR(L16="Sent",L16="Picked up"),"Done",IF(L16="Cancelled","Cancelled",IF(K16<TODAY(),"Late by "&(TODAY()-K16)&IF((TODAY()-K16)=1," day"," days"),IF(K16=TODAY(),"Due today","Due in "&(K16-TODAY())&IF((K16-TODAY())=1," day"," days")))))) | T16: =IF(AND(B16<>"",K16<>"",L16<>"Sent",L16<>"Picked up",L16<>"Cancelled"),K16+ROW()/10000000,"") | U16: =IF(OR(B16="",C16=""),"",B16+ROW()/10000000) | V16: =IF(U16="","",IF(COUNTIFS(Orders!$C$6:$C$1005,C16,Orders!$U$6:$U$1005,">"&U16)=0,1,0)) | W16: =IF(AND(B16<>"",K16<>"",L16<>"Sent",L16<>"Picked up",L16<>"Cancelled"),IF(N(E16)=0,1,E16),0) | X16: =IF(OR(B16="",D16=""),"",IF(N(E16)=0,1,E16))
B17: 46042 | C17: Iris Cole | D17: Soy candle 8 oz | E17: 1 | F17: 5 | G17: 6.95 | H17: =IF(OR(B17="",D17=""),"",IF(N(E17)=0,1,E17)*IFERROR(INDEX(Products!$C$6:$C$105,MATCH(D17,Products!$B$6:$B$105,0)),0)+N(F17)+N(G17)) | I17: 33.95 | J17: =IF(OR(H17="",L17="Cancelled"),"",IF(H17-N(I17)>0.005,H17-N(I17),"")) | K17: 46046 | L17: Sent | M17: Etsy | N17: =IF(OR(H17="",L17="Cancelled"),"",IF(N(E17)=0,1,E17)*IFERROR(INDEX(Products!$E$6:$E$105,MATCH(D17,Products!$B$6:$B$105,0)),0)) | O17: 5.86 | P17: =IF(OR(H17="",L17="Cancelled"),"",ROUND(IFERROR(H17*INDEX(Settings!$C$6:$C$15,MATCH(M17,Settings!$B$6:$B$15,0))+INDEX(Settings!$D$6:$D$15,MATCH(M17,Settings!$B$6:$B$15,0)),0),2)) | Q17: =IF(OR(H17="",L17="Cancelled"),"",H17-N(N17)-N(O17)-N(P17)) | R17: =IF(OR(B17="",K17=""),"",IF(OR(L17="Sent",L17="Picked up"),"Done",IF(L17="Cancelled","Cancelled",IF(K17<TODAY(),"Late by "&(TODAY()-K17)&IF((TODAY()-K17)=1," day"," days"),IF(K17=TODAY(),"Due today","Due in "&(K17-TODAY())&IF((K17-TODAY())=1," day"," days")))))) | S17: Custom label | T17: =IF(AND(B17<>"",K17<>"",L17<>"Sent",L17<>"Picked up",L17<>"Cancelled"),K17+ROW()/10000000,"") | U17: =IF(OR(B17="",C17=""),"",B17+ROW()/10000000) | V17: =IF(U17="","",IF(COUNTIFS(Orders!$C$6:$C$1005,C17,Orders!$U$6:$U$1005,">"&U17)=0,1,0)) | W17: =IF(AND(B17<>"",K17<>"",L17<>"Sent",L17<>"Picked up",L17<>"Cancelled"),IF(N(E17)=0,1,E17),0) | X17: =IF(OR(B17="",D17=""),"",IF(N(E17)=0,1,E17))
B18: 46042 | C18: Paula Fox | D18: Soap bar | E18: 1 | G18: 6.95 | H18: =IF(OR(B18="",D18=""),"",IF(N(E18)=0,1,E18)*IFERROR(INDEX(Products!$C$6:$C$105,MATCH(D18,Products!$B$6:$B$105,0)),0)+N(F18)+N(G18)) | I18: 14.95 | J18: =IF(OR(H18="",L18="Cancelled"),"",IF(H18-N(I18)>0.005,H18-N(I18),"")) | K18: 46050 | L18: Sent | M18: Etsy | N18: =IF(OR(H18="",L18="Cancelled"),"",IF(N(E18)=0,1,E18)*IFERROR(INDEX(Products!$E$6:$E$105,MATCH(D18,Products!$B$6:$B$105,0)),0)) | O18: 5.61 | P18: =IF(OR(H18="",L18="Cancelled"),"",ROUND(IFERROR(H18*INDEX(Settings!$C$6:$C$15,MATCH(M18,Settings!$B$6:$B$15,0))+INDEX(Settings!$D$6:$D$15,MATCH(M18,Settings!$B$6:$B$15,0)),0),2)) | Q18: =IF(OR(H18="",L18="Cancelled"),"",H18-N(N18)-N(O18)-N(P18)) | R18: =IF(OR(B18="",K18=""),"",IF(OR(L18="Sent",L18="Picked up"),"Done",IF(L18="Cancelled","Cancelled",IF(K18<TODAY(),"Late by "&(TODAY()-K18)&IF((TODAY()-K18)=1," day"," days"),IF(K18=TODAY(),"Due today","Due in "&(K18-TODAY())&IF((K18-TODAY())=1," day"," days")))))) | T18: =IF(AND(B18<>"",K18<>"",L18<>"Sent",L18<>"Picked up",L18<>"Cancelled"),K18+ROW()/10000000,"") | U18: =IF(OR(B18="",C18=""),"",B18+ROW()/10000000) | V18: =IF(U18="","",IF(COUNTIFS(Orders!$C$6:$C$1005,C18,Orders!$U$6:$U$1005,">"&U18)=0,1,0)) | W18: =IF(AND(B18<>"",K18<>"",L18<>"Sent",L18<>"Picked up",L18<>"Cancelled"),IF(N(E18)=0,1,E18),0) | X18: =IF(OR(B18="",D18=""),"",IF(N(E18)=0,1,E18))
B19: 46043 | C19: Leah Morgan | D19: Soy candle 16 oz | E19: 3 | G19: 6.95 | H19: =IF(OR(B19="",D19=""),"",IF(N(E19)=0,1,E19)*IFERROR(INDEX(Products!$C$6:$C$105,MATCH(D19,Products!$B$6:$B$105,0)),0)+N(F19)+N(G19)) | I19: 108.95 | J19: =IF(OR(H19="",L19="Cancelled"),"",IF(H19-N(I19)>0.005,H19-N(I19),"")) | K19: 46053 | L19: Sent | M19: Etsy | N19: =IF(OR(H19="",L19="Cancelled"),"",IF(N(E19)=0,1,E19)*IFERROR(INDEX(Products!$E$6:$E$105,MATCH(D19,Products!$B$6:$B$105,0)),0)) | O19: 5.46 | P19: =IF(OR(H19="",L19="Cancelled"),"",ROUND(IFERROR(H19*INDEX(Settings!$C$6:$C$15,MATCH(M19,Settings!$B$6:$B$15,0))+INDEX(Settings!$D$6:$D$15,MATCH(M19,Settings!$B$6:$B$15,0)),0),2)) | Q19: =IF(OR(H19="",L19="Cancelled"),"",H19-N(N19)-N(O19)-N(P19)) | R19: =IF(OR(B19="",K19=""),"",IF(OR(L19="Sent",L19="Picked up"),"Done",IF(L19="Cancelled","Cancelled",IF(K19<TODAY(),"Late by "&(TODAY()-K19)&IF((TODAY()-K19)=1," day"," days"),IF(K19=TODAY(),"Due today","Due in "&(K19-TODAY())&IF((K19-TODAY())=1," day"," days")))))) | T19: =IF(AND(B19<>"",K19<>"",L19<>"Sent",L19<>"Picked up",L19<>"Cancelled"),K19+ROW()/10000000,"") | U19: =IF(OR(B19="",C19=""),"",B19+ROW()/10000000) | V19: =IF(U19="","",IF(COUNTIFS(Orders!$C$6:$C$1005,C19,Orders!$U$6:$U$1005,">"&U19)=0,1,0)) | W19: =IF(AND(B19<>"",K19<>"",L19<>"Sent",L19<>"Picked up",L19<>"Cancelled"),IF(N(E19)=0,1,E19),0) | X19: =IF(OR(B19="",D19=""),"",IF(N(E19)=0,1,E19))
B20: 46043 | C20: Holly Cox | D20: Wedding favours, 10 tins | E20: 8 | G20: 6.95 | H20: =IF(OR(B20="",D20=""),"",IF(N(E20)=0,1,E20)*IFERROR(INDEX(Products!$C$6:$C$105,MATCH(D20,Products!$B$6:$B$105,0)),0)+N(F20)+N(G20)) | I20: 486.95 | J20: =IF(OR(H20="",L20="Cancelled"),"",IF(H20-N(I20)>0.005,H20-N(I20),"")) | K20: 46070 | L20: Sent | M20: Etsy | N20: =IF(OR(H20="",L20="Cancelled"),"",IF(N(E20)=0,1,E20)*IFERROR(INDEX(Products!$E$6:$E$105,MATCH(D20,Products!$B$6:$B$105,0)),0)) | O20: 5.3 | P20: =IF(OR(H20="",L20="Cancelled"),"",ROUND(IFERROR(H20*INDEX(Settings!$C$6:$C$15,MATCH(M20,Settings!$B$6:$B$15,0))+INDEX(Settings!$D$6:$D$15,MATCH(M20,Settings!$B$6:$B$15,0)),0),2)) | Q20: =IF(OR(H20="",L20="Cancelled"),"",H20-N(N20)-N(O20)-N(P20)) | R20: =IF(OR(B20="",K20=""),"",IF(OR(L20="Sent",L20="Picked up"),"Done",IF(L20="Cancelled","Cancelled",IF(K20<TODAY(),"Late by "&(TODAY()-K20)&IF((TODAY()-K20)=1," day"," days"),IF(K20=TODAY(),"Due today","Due in "&(K20-TODAY())&IF((K20-TODAY())=1," day"," days")))))) | T20: =IF(AND(B20<>"",K20<>"",L20<>"Sent",L20<>"Picked up",L20<>"Cancelled"),K20+ROW()/10000000,"") | U20: =IF(OR(B20="",C20=""),"",B20+ROW()/10000000) | V20: =IF(U20="","",IF(COUNTIFS(Orders!$C$6:$C$1005,C20,Orders!$U$6:$U$1005,">"&U20)=0,1,0)) | W20: =IF(AND(B20<>"",K20<>"",L20<>"Sent",L20<>"Picked up",L20<>"Cancelled"),IF(N(E20)=0,1,E20),0) | X20: =IF(OR(B20="",D20=""),"",IF(N(E20)=0,1,E20))
B21: 46044 | C21: Nina Kelly | D21: Soap bar | E21: 1 | G21: 6.95 | H21: =IF(OR(B21="",D21=""),"",IF(N(E21)=0,1,E21)*IFERROR(INDEX(Products!$C$6:$C$105,MATCH(D21,Products!$B$6:$B$105,0)),0)+N(F21)+N(G21)) | I21: 14.95 | J21: =IF(OR(H21="",L21="Cancelled"),"",IF(H21-N(I21)>0.005,H21-N(I21),"")) | K21: 46052 | L21: Sent | M21: Etsy | N21: =IF(OR(H21="",L21="Cancelled"),"",IF(N(E21)=0,1,E21)*IFERROR(INDEX(Products!$E$6:$E$105,MATCH(D21,Products!$B$6:$B$105,0)),0)) | O21: 6.16 | P21: =IF(OR(H21="",L21="Cancelled"),"",ROUND(IFERROR(H21*INDEX(Settings!$C$6:$C$15,MATCH(M21,Settings!$B$6:$B$15,0))+INDEX(Settings!$D$6:$D$15,MATCH(M21,Settings!$B$6:$B$15,0)),0),2)) | Q21: =IF(OR(H21="",L21="Cancelled"),"",H21-N(N21)-N(O21)-N(P21)) | R21: =IF(OR(B21="",K21=""),"",IF(OR(L21="Sent",L21="Picked up"),"Done",IF(L21="Cancelled","Cancelled",IF(K21<TODAY(),"Late by "&(TODAY()-K21)&IF((TODAY()-K21)=1," day"," days"),IF(K21=TODAY(),"Due today","Due in "&(K21-TODAY())&IF((K21-TODAY())=1," day"," days")))))) | T21: =IF(AND(B21<>"",K21<>"",L21<>"Sent",L21<>"Picked up",L21<>"Cancelled"),K21+ROW()/10000000,"") | U21: =IF(OR(B21="",C21=""),"",B21+ROW()/10000000) | V21: =IF(U21="","",IF(COUNTIFS(Orders!$C$6:$C$1005,C21,Orders!$U$6:$U$1005,">"&U21)=0,1,0)) | W21: =IF(AND(B21<>"",K21<>"",L21<>"Sent",L21<>"Picked up",L21<>"Cancelled"),IF(N(E21)=0,1,E21),0) | X21: =IF(OR(B21="",D21=""),"",IF(N(E21)=0,1,E21))
B22: 46044 | C22: Dina Cole | D22: Soy candle 8 oz | E22: 2 | G22: 6.95 | H22: =IF(OR(B22="",D22=""),"",IF(N(E22)=0,1,E22)*IFERROR(INDEX(Products!$C$6:$C$105,MATCH(D22,Products!$B$6:$B$105,0)),0)+N(F22)+N(G22)) | I22: 50.95 | J22: =IF(OR(H22="",L22="Cancelled"),"",IF(H22-N(I22)>0.005,H22-N(I22),"")) | K22: 46052 | L22: Sent | M22: Etsy | N22: =IF(OR(H22="",L22="Cancelled"),"",IF(N(E22)=0,1,E22)*IFERROR(INDEX(Products!$E$6:$E$105,MATCH(D22,Products!$B$6:$B$105,0)),0)) | O22: 6.25 | P22: =IF(OR(H22="",L22="Cancelled"),"",ROUND(IFERROR(H22*INDEX(Settings!$C$6:$C$15,MATCH(M22,Settings!$B$6:$B$15,0))+INDEX(Settings!$D$6:$D$15,MATCH(M22,Settings!$B$6:$B$15,0)),0),2)) | Q22: =IF(OR(H22="",L22="Cancelled"),"",H22-N(N22)-N(O22)-N(P22)) | R22: =IF(OR(B22="",K22=""),"",IF(OR(L22="Sent",L22="Picked up"),"Done",IF(L22="Cancelled","Cancelled",IF(K22<TODAY(),"Late by "&(TODAY()-K22)&IF((TODAY()-K22)=1," day"," days"),IF(K22=TODAY(),"Due today","Due in "&(K22-TODAY())&IF((K22-TODAY())=1," day"," days")))))) | T22: =IF(AND(B22<>"",K22<>"",L22<>"Sent",L22<>"Picked up",L22<>"Cancelled"),K22+ROW()/10000000,"") | U22: =IF(OR(B22="",C22=""),"",B22+ROW()/10000000) | V22: =IF(U22="","",IF(COUNTIFS(Orders!$C$6:$C$1005,C22,Orders!$U$6:$U$1005,">"&U22)=0,1,0)) | W22: =IF(AND(B22<>"",K22<>"",L22<>"Sent",L22<>"Picked up",L22<>"Cancelled"),IF(N(E22)=0,1,E22),0) | X22: =IF(OR(B22="",D22=""),"",IF(N(E22)=0,1,E22))
B23: 46045 | C23: Jon Reed | D23: Soy candle 8 oz | E23: 4 | F23: 20 | H23: =IF(OR(B23="",D23=""),"",IF(N(E23)=0,1,E23)*IFERROR(INDEX(Products!$C$6:$C$105,MATCH(D23,Products!$B$6:$B$105,0)),0)+N(F23)+N(G23)) | I23: 108 | J23: =IF(OR(H23="",L23="Cancelled"),"",IF(H23-N(I23)>0.005,H23-N(I23),"")) | K23: 46050 | L23: Picked up | M23: Craft market | N23: =IF(OR(H23="",L23="Cancelled"),"",IF(N(E23)=0,1,E23)*IFERROR(INDEX(Products!$E$6:$E$105,MATCH(D23,Products!$B$6:$B$105,0)),0)) | P23: =IF(OR(H23="",L23="Cancelled"),"",ROUND(IFERROR(H23*INDEX(Settings!$C$6:$C$15,MATCH(M23,Settings!$B$6:$B$15,0))+INDEX(Settings!$D$6:$D$15,MATCH(M23,Settings!$B$6:$B$15,0)),0),2)) | Q23: =IF(OR(H23="",L23="Cancelled"),"",H23-N(N23)-N(O23)-N(P23)) | R23: =IF(OR(B23="",K23=""),"",IF(OR(L23="Sent",L23="Picked up"),"Done",IF(L23="Cancelled","Cancelled",IF(K23<TODAY(),"Late by "&(TODAY()-K23)&IF((TODAY()-K23)=1," day"," days"),IF(K23=TODAY(),"Due today","Due in "&(K23-TODAY())&IF((K23-TODAY())=1," day"," days")))))) | S23: Custom label | T23: =IF(AND(B23<>"",K23<>"",L23<>"Sent",L23<>"Picked up",L23<>"Cancelled"),K23+ROW()/10000000,"") | U23: =IF(OR(B23="",C23=""),"",B23+ROW()/10000000) | V23: =IF(U23="","",IF(COUNTIFS(Orders!$C$6:$C$1005,C23,Orders!$U$6:$U$1005,">"&U23)=0,1,0)) | W23: =IF(AND(B23<>"",K23<>"",L23<>"Sent",L23<>"Picked up",L23<>"Cancelled"),IF(N(E23)=0,1,E23),0) | X23: =IF(OR(B23="",D23=""),"",IF(N(E23)=0,1,E23))
B24: 46046 | C24: Nina Reed | D24: Soy candle 8 oz | E24: 2 | G24: 6.95 | H24: =IF(OR(B24="",D24=""),"",IF(N(E24)=0,1,E24)*IFERROR(INDEX(Products!$C$6:$C$105,MATCH(D24,Products!$B$6:$B$105,0)),0)+N(F24)+N(G24)) | I24: 50.95 | J24: =IF(OR(H24="",L24="Cancelled"),"",IF(H24-N(I24)>0.005,H24-N(I24),"")) | K24: 46055 | L24: Sent | M24: Own website | N24: =IF(OR(H24="",L24="Cancelled"),"",IF(N(E24)=0,1,E24)*IFERROR(INDEX(Products!$E$6:$E$105,MATCH(D24,Products!$B$6:$B$105,0)),0)) | O24: 5.6 | P24: =IF(OR(H24="",L24="Cancelled"),"",ROUND(IFERROR(H24*INDEX(Settings!$C$6:$C$15,MATCH(M24,Settings!$B$6:$B$15,0))+INDEX(Settings!$D$6:$D$15,MATCH(M24,Settings!$B$6:$B$15,0)),0),2)) | Q24: =IF(OR(H24="",L24="Cancelled"),"",H24-N(N24)-N(O24)-N(P24)) | R24: =IF(OR(B24="",K24=""),"",IF(OR(L24="Sent",L24="Picked up"),"Done",IF(L24="Cancelled","Cancelled",IF(K24<TODAY(),"Late by "&(TODAY()-K24)&IF((TODAY()-K24)=1," day"," days"),IF(K24=TODAY(),"Due today","Due in "&(K24-TODAY())&IF((K24-TODAY())=1," day"," days")))))) | T24: =IF(AND(B24<>"",K24<>"",L24<>"Sent",L24<>"Picked up",L24<>"Cancelled"),K24+ROW()/10000000,"") | U24: =IF(OR(B24="",C24=""),"",B24+ROW()/10000000) | V24: =IF(U24="","",IF(COUNTIFS(Orders!$C$6:$C$1005,C24,Orders!$U$6:$U$1005,">"&U24)=0,1,0)) | W24: =IF(AND(B24<>"",K24<>"",L24<>"Sent",L24<>"Picked up",L24<>"Cancelled"),IF(N(E24)=0,1,E24),0) | X24: =IF(OR(B24="",D24=""),"",IF(N(E24)=0,1,E24))
B25: 46047 | C25: Rita Price | D25: Soy candle 8 oz | E25: 3 | F25: 15 | H25: =IF(OR(B25="",D25=""),"",IF(N(E25)=0,1,E25)*IFERROR(INDEX(Products!$C$6:$C$105,MATCH(D25,Products!$B$6:$B$105,0)),0)+N(F25)+N(G25)) | I25: 81 | J25: =IF(OR(H25="",L25="Cancelled"),"",IF(H25-N(I25)>0.005,H25-N(I25),"")) | K25: 46059 | L25: Picked up | M25: Instagram | N25: =IF(OR(H25="",L25="Cancelled"),"",IF(N(E25)=0,1,E25)*IFERROR(INDEX(Products!$E$6:$E$105,MATCH(D25,Products!$B$6:$B$105,0)),0)) | P25: =IF(OR(H25="",L25="Cancelled"),"",ROUND(IFERROR(H25*INDEX(Settings!$C$6:$C$15,MATCH(M25,Settings!$B$6:$B$15,0))+INDEX(Settings!$D$6:$D$15,MATCH(M25,Settings!$B$6:$B$15,0)),0),2)) | Q25: =IF(OR(H25="",L25="Cancelled"),"",H25-N(N25)-N(O25)-N(P25)) | R25: =IF(OR(B25="",K25=""),"",IF(OR(L25="Sent",L25="Picked up"),"Done",IF(L25="Cancelled","Cancelled",IF(K25<TODAY(),"Late by "&(TODAY()-K25)&IF((TODAY()-K25)=1," day"," days"),IF(K25=TODAY(),"Due today","Due in "&(K25-TODAY())&IF((K25-TODAY())=1," day"," days")))))) | S25: Custom label | T25: =IF(AND(B25<>"",K25<>"",L25<>"Sent",L25<>"Picked up",L25<>"Cancelled"),K25+ROW()/10000000,"") | U25: =IF(OR(B25="",C25=""),"",B25+ROW()/10000000) | V25: =IF(U25="","",IF(COUNTIFS(Orders!$C$6:$C$1005,C25,Orders!$U$6:$U$1005,">"&U25)=0,1,0)) | W25: =IF(AND(B25<>"",K25<>"",L25<>"Sent",L25<>"Picked up",L25<>"Cancelled"),IF(N(E25)=0,1,E25),0) | X25: =IF(OR(B25="",D25=""),"",IF(N(E25)=0,1,E25))
B26: 46048 | C26: Megan Murphy | D26: Soy candle 16 oz | E26: 2 | G26: 6.95 | H26: =IF(OR(B26="",D26=""),"",IF(N(E26)=0,1,E26)*IFERROR(INDEX(Products!$C$6:$C$105,MATCH(D26,Products!$B$6:$B$105,0)),0)+N(F26)+N(G26)) | I26: 74.95 | J26: =IF(OR(H26="",L26="Cancelled"),"",IF(H26-N(I26)>0.005,H26-N(I26),"")) | K26: 46058 | L26: Sent | M26: Etsy | N26: =IF(OR(H26="",L26="Cancelled"),"",IF(N(E26)=0,1,E26)*IFERROR(INDEX(Products!$E$6:$E$105,MATCH(D26,Products!$B$6:$B$105,0)),0)) | O26: 5.47 | P26: =IF(OR(H26="",L26="Cancelled"),"",ROUND(IFERROR(H26*INDEX(Settings!$C$6:$C$15,MATCH(M26,Settings!$B$6:$B$15,0))+INDEX(Settings!$D$6:$D$15,MATCH(M26,Settings!$B$6:$B$15,0)),0),2)) | Q26: =IF(OR(H26="",L26="Cancelled"),"",H26-N(N26)-N(O26)-N(P26)) | R26: =IF(OR(B26="",K26=""),"",IF(OR(L26="Sent",L26="Picked up"),"Done",IF(L26="Cancelled","Cancelled",IF(K26<TODAY(),"Late by "&(TODAY()-K26)&IF((TODAY()-K26)=1," day"," days"),IF(K26=TODAY(),"Due today","Due in "&(K26-TODAY())&IF((K26-TODAY())=1," day"," days")))))) | T26: =IF(AND(B26<>"",K26<>"",L26<>"Sent",L26<>"Picked up",L26<>"Cancelled"),K26+ROW()/10000000,"") | U26: =IF(OR(B26="",C26=""),"",B26+ROW()/10000000) | V26: =IF(U26="","",IF(COUNTIFS(Orders!$C$6:$C$1005,C26,Orders!$U$6:$U$1005,">"&U26)=0,1,0)) | W26: =IF(AND(B26<>"",K26<>"",L26<>"Sent",L26<>"Picked up",L26<>"Cancelled"),IF(N(E26)=0,1,E26),0) | X26: =IF(OR(B26="",D26=""),"",IF(N(E26)=0,1,E26))
B27: 46049 | C27: Clara Mason | D27: Soy candle 16 oz | E27: 2 | F27: 10 | G27: 6.95 | H27: =IF(OR(B27="",D27=""),"",IF(N(E27)=0,1,E27)*IFERROR(INDEX(Products!$C$6:$C$105,MATCH(D27,Products!$B$6:$B$105,0)),0)+N(F27)+N(G27)) | I27: 84.95 | J27: =IF(OR(H27="",L27="Cancelled"),"",IF(H27-N(I27)>0.005,H27-N(I27),"")) | K27: 46056 | L27: Sent | M27: Etsy | N27: =IF(OR(H27="",L27="Cancelled"),"",IF(N(E27)=0,1,E27)*IFERROR(INDEX(Products!$E$6:$E$105,MATCH(D27,Products!$B$6:$B$105,0)),0)) | O27: 5.31 | P27: =IF(OR(H27="",L27="Cancelled"),"",ROUND(IFERROR(H27*INDEX(Settings!$C$6:$C$15,MATCH(M27,Settings!$B$6:$B$15,0))+INDEX(Settings!$D$6:$D$15,MATCH(M27,Settings!$B$6:$B$15,0)),0),2)) | Q27: =IF(OR(H27="",L27="Cancelled"),"",H27-N(N27)-N(O27)-N(P27)) | R27: =IF(OR(B27="",K27=""),"",IF(OR(L27="Sent",L27="Picked up"),"Done",IF(L27="Cancelled","Cancelled",IF(K27<TODAY(),"Late by "&(TODAY()-K27)&IF((TODAY()-K27)=1," day"," days"),IF(K27=TODAY(),"Due today","Due in "&(K27-TODAY())&IF((K27-TODAY())=1," day"," days")))))) | S27: Custom label | T27: =IF(AND(B27<>"",K27<>"",L27<>"Sent",L27<>"Picked up",L27<>"Cancelled"),K27+ROW()/10000000,"") | U27: =IF(OR(B27="",C27=""),"",B27+ROW()/10000000) | V27: =IF(U27="","",IF(COUNTIFS(Orders!$C$6:$C$1005,C27,Orders!$U$6:$U$1005,">"&U27)=0,1,0)) | W27: =IF(AND(B27<>"",K27<>"",L27<>"Sent",L27<>"Picked up",L27<>"Cancelled"),IF(N(E27)=0,1,E27),0) | X27: =IF(OR(B27="",D27=""),"",IF(N(E27)=0,1,E27))
B28: 46050 | C28: Adam Cox | D28: Wax melts, 6 pack | E28: 3 | H28: =IF(OR(B28="",D28=""),"",IF(N(E28)=0,1,E28)*IFERROR(INDEX(Products!$C$6:$C$105,MATCH(D28,Products!$B$6:$B$105,0)),0)+N(F28)+N(G28)) | I28: 27 | J28: =IF(OR(H28="",L28="Cancelled"),"",IF(H28-N(I28)>0.005,H28-N(I28),"")) | K28: 46061 | L28: Picked up | M28: Instagram | N28: =IF(OR(H28="",L28="Cancelled"),"",IF(N(E28)=0,1,E28)*IFERROR(INDEX(Products!$E$6:$E$105,MATCH(D28,Products!$B$6:$B$105,0)),0)) | P28: =IF(OR(H28="",L28="Cancelled"),"",ROUND(IFERROR(H28*INDEX(Settings!$C$6:$C$15,MATCH(M28,Settings!$B$6:$B$15,0))+INDEX(Settings!$D$6:$D$15,MATCH(M28,Settings!$B$6:$B$15,0)),0),2)) | Q28: =IF(OR(H28="",L28="Cancelled"),"",H28-N(N28)-N(O28)-N(P28)) | R28: =IF(OR(B28="",K28=""),"",IF(OR(L28="Sent",L28="Picked up"),"Done",IF(L28="Cancelled","Cancelled",IF(K28<TODAY(),"Late by "&(TODAY()-K28)&IF((TODAY()-K28)=1," day"," days"),IF(K28=TODAY(),"Due today","Due in "&(K28-TODAY())&IF((K28-TODAY())=1," day"," days")))))) | T28: =IF(AND(B28<>"",K28<>"",L28<>"Sent",L28<>"Picked up",L28<>"Cancelled"),K28+ROW()/10000000,"") | U28: =IF(OR(B28="",C28=""),"",B28+ROW()/10000000) | V28: =IF(U28="","",IF(COUNTIFS(Orders!$C$6:$C$1005,C28,Orders!$U$6:$U$1005,">"&U28)=0,1,0)) | W28: =IF(AND(B28<>"",K28<>"",L28<>"Sent",L28<>"Picked up",L28<>"Cancelled"),IF(N(E28)=0,1,E28),0) | X28: =IF(OR(B28="",D28=""),"",IF(N(E28)=0,1,E28))
B29: 46051 | C29: Helen Kelly | D29: Soap bar | E29: 3 | H29: =IF(OR(B29="",D29=""),"",IF(N(E29)=0,1,E29)*IFERROR(INDEX(Products!$C$6:$C$105,MATCH(D29,Products!$B$6:$B$105,0)),0)+N(F29)+N(G29)) | I29: 24 | J29: =IF(OR(H29="",L29="Cancelled"),"",IF(H29-N(I29)>0.005,H29-N(I29),"")) | K29: 46063 | L29: Picked up | M29: Friends and family | N29: =IF(OR(H29="",L29="Cancelled"),"",IF(N(E29)=0,1,E29)*IFERROR(INDEX(Products!$E$6:$E$105,MATCH(D29,Products!$B$6:$B$105,0)),0)) | P29: =IF(OR(H29="",L29="Cancelled"),"",ROUND(IFERROR(H29*INDEX(Settings!$C$6:$C$15,MATCH(M29,Settings!$B$6:$B$15,0))+INDEX(Settings!$D$6:$D$15,MATCH(M29,Settings!$B$6:$B$15,0)),0),2)) | Q29: =IF(OR(H29="",L29="Cancelled"),"",H29-N(N29)-N(O29)-N(P29)) | R29: =IF(OR(B29="",K29=""),"",IF(OR(L29="Sent",L29="Picked up"),"Done",IF(L29="Cancelled","Cancelled",IF(K29<TODAY(),"Late by "&(TODAY()-K29)&IF((TODAY()-K29)=1," day"," days"),IF(K29=TODAY(),"Due today","Due in "&(K29-TODAY())&IF((K29-TODAY())=1," day"," days")))))) | T29: =IF(AND(B29<>"",K29<>"",L29<>"Sent",L29<>"Picked up",L29<>"Cancelled"),K29+ROW()/10000000,"") | U29: =IF(OR(B29="",C29=""),"",B29+ROW()/10000000) | V29: =IF(U29="","",IF(COUNTIFS(Orders!$C$6:$C$1005,C29,Orders!$U$6:$U$1005,">"&U29)=0,1,0)) | W29: =IF(AND(B29<>"",K29<>"",L29<>"Sent",L29<>"Picked up",L29<>"Cancelled"),IF(N(E29)=0,1,E29),0) | X29: =IF(OR(B29="",D29=""),"",IF(N(E29)=0,1,E29))
B30: 46051 | C30: Ruby Brooks | D30: Soy candle 8 oz | E30: 3 | G30: 6.95 | H30: =IF(OR(B30="",D30=""),"",IF(N(E30)=0,1,E30)*IFERROR(INDEX(Products!$C$6:$C$105,MATCH(D30,Products!$B$6:$B$105,0)),0)+N(F30)+N(G30)) | I30: 72.95 | J30: =IF(OR(H30="",L30="Cancelled"),"",IF(H30-N(I30)>0.005,H30-N(I30),"")) | K30: 46055 | L30: Sent | M30: Etsy | N30: =IF(OR(H30="",L30="Cancelled"),"",IF(N(E30)=0,1,E30)*IFERROR(INDEX(Products!$E$6:$E$105,MATCH(D30,Products!$B$6:$B$105,0)),0)) | O30: 5.65 | P30: =IF(OR(H30="",L30="Cancelled"),"",ROUND(IFERROR(H30*INDEX(Settings!$C$6:$C$15,MATCH(M30,Settings!$B$6:$B$15,0))+INDEX(Settings!$D$6:$D$15,MATCH(M30,Settings!$B$6:$B$15,0)),0),2)) | Q30: =IF(OR(H30="",L30="Cancelled"),"",H30-N(N30)-N(O30)-N(P30)) | R30: =IF(OR(B30="",K30=""),"",IF(OR(L30="Sent",L30="Picked up"),"Done",IF(L30="Cancelled","Cancelled",IF(K30<TODAY(),"Late by "&(TODAY()-K30)&IF((TODAY()-K30)=1," day"," days"),IF(K30=TODAY(),"Due today","Due in "&(K30-TODAY())&IF((K30-TODAY())=1," day"," days")))))) | T30: =IF(AND(B30<>"",K30<>"",L30<>"Sent",L30<>"Picked up",L30<>"Cancelled"),K30+ROW()/10000000,"") | U30: =IF(OR(B30="",C30=""),"",B30+ROW()/10000000) | V30: =IF(U30="","",IF(COUNTIFS(Orders!$C$6:$C$1005,C30,Orders!$U$6:$U$1005,">"&U30)=0,1,0)) | W30: =IF(AND(B30<>"",K30<>"",L30<>"Sent",L30<>"Picked up",L30<>"Cancelled"),IF(N(E30)=0,1,E30),0) | X30: =IF(OR(B30="",D30=""),"",IF(N(E30)=0,1,E30))
B31: 46052 | C31: Holly Cox | D31: Wax melts, 6 pack | E31: 1 | H31: =IF(OR(B31="",D31=""),"",IF(N(E31)=0,1,E31)*IFERROR(INDEX(Products!$C$6:$C$105,MATCH(D31,Products!$B$6:$B$105,0)),0)+N(F31)+N(G31)) | I31: 9 | J31: =IF(OR(H31="",L31="Cancelled"),"",IF(H31-N(I31)>0.005,H31-N(I31),"")) | K31: 46064 | L31: Picked up | M31: Craft market | N31: =IF(OR(H31="",L31="Cancelled"),"",IF(N(E31)=0,1,E31)*IFERROR(INDEX(Products!$E$6:$E$105,MATCH(D31,Products!$B$6:$B$105,0)),0)) | P31: =IF(OR(H31="",L31="Cancelled"),"",ROUND(IFERROR(H31*INDEX(Settings!$C$6:$C$15,MATCH(M31,Settings!$B$6:$B$15,0))+INDEX(Settings!$D$6:$D$15,MATCH(M31,Settings!$B$6:$B$15,0)),0),2)) | Q31: =IF(OR(H31="",L31="Cancelled"),"",H31-N(N31)-N(O31)-N(P31)) | R31: =IF(OR(B31="",K31=""),"",IF(OR(L31="Sent",L31="Picked up"),"Done",IF(L31="Cancelled","Cancelled",IF(K31<TODAY(),"Late by "&(TODAY()-K31)&IF((TODAY()-K31)=1," day"," days"),IF(K31=TODAY(),"Due today","Due in "&(K31-TODAY())&IF((K31-TODAY())=1," day"," days")))))) | T31: =IF(AND(B31<>"",K31<>"",L31<>"Sent",L31<>"Picked up",L31<>"Cancelled"),K31+ROW()/10000000,"") | U31: =IF(OR(B31="",C31=""),"",B31+ROW()/10000000) | V31: =IF(U31="","",IF(COUNTIFS(Orders!$C$6:$C$1005,C31,Orders!$U$6:$U$1005,">"&U31)=0,1,0)) | W31: =IF(AND(B31<>"",K31<>"",L31<>"Sent",L31<>"Picked up",L31<>"Cancelled"),IF(N(E31)=0,1,E31),0) | X31: =IF(OR(B31="",D31=""),"",IF(N(E31)=0,1,E31))
B32: 46053 | C32: Mia Cox | D32: Soy candle 8 oz | E32: 3 | H32: =IF(OR(B32="",D32=""),"",IF(N(E32)=0,1,E32)*IFERROR(INDEX(Products!$C$6:$C$105,MATCH(D32,Products!$B$6:$B$105,0)),0)+N(F32)+N(G32)) | I32: 66 | J32: =IF(OR(H32="",L32="Cancelled"),"",IF(H32-N(I32)>0.005,H32-N(I32),"")) | K32: 46062 | L32: Picked up | M32: Friends and family | N32: =IF(OR(H32="",L32="Cancelled"),"",IF(N(E32)=0,1,E32)*IFERROR(INDEX(Products!$E$6:$E$105,MATCH(D32,Products!$B$6:$B$105,0)),0)) | P32: =IF(OR(H32="",L32="Cancelled"),"",ROUND(IFERROR(H32*INDEX(Settings!$C$6:$C$15,MATCH(M32,Settings!$B$6:$B$15,0))+INDEX(Settings!$D$6:$D$15,MATCH(M32,Settings!$B$6:$B$15,0)),0),2)) | Q32: =IF(OR(H32="",L32="Cancelled"),"",H32-N(N32)-N(O32)-N(P32)) | R32: =IF(OR(B32="",K32=""),"",IF(OR(L32="Sent",L32="Picked up"),"Done",IF(L32="Cancelled","Cancelled",IF(K32<TODAY(),"Late by "&(TODAY()-K32)&IF((TODAY()-K32)=1," day"," days"),IF(K32=TODAY(),"Due today","Due in "&(K32-TODAY())&IF((K32-TODAY())=1," day"," days")))))) | T32: =IF(AND(B32<>"",K32<>"",L32<>"Sent",L32<>"Picked up",L32<>"Cancelled"),K32+ROW()/10000000,"") | U32: =IF(OR(B32="",C32=""),"",B32+ROW()/10000000) | V32: =IF(U32="","",IF(COUNTIFS(Orders!$C$6:$C$1005,C32,Orders!$U$6:$U$1005,">"&U32)=0,1,0)) | W32: =IF(AND(B32<>"",K32<>"",L32<>"Sent",L32<>"Picked up",L32<>"Cancelled"),IF(N(E32)=0,1,E32),0) | X32: =IF(OR(B32="",D32=""),"",IF(N(E32)=0,1,E32))
B33: 46053 | C33: Ian Price | D33: Soy candle 8 oz | E33: 4 | G33: 6.95 | H33: =IF(OR(B33="",D33=""),"",IF(N(E33)=0,1,E33)*IFERROR(INDEX(Products!$C$6:$C$105,MATCH(D33,Products!$B$6:$B$105,0)),0)+N(F33)+N(G33)) | I33: 94.95 | J33: =IF(OR(H33="",L33="Cancelled"),"",IF(H33-N(I33)>0.005,H33-N(I33),"")) | K33: 46059 | L33: Sent | M33: Own website | N33: =IF(OR(H33="",L33="Cancelled"),"",IF(N(E33)=0,1,E33)*IFERROR(INDEX(Products!$E$6:$E$105,MATCH(D33,Products!$B$6:$B$105,0)),0)) | O33: 7.57 | P33: =IF(OR(H33="",L33="Cancelled"),"",ROUND(IFERROR(H33*INDEX(Settings!$C$6:$C$15,MATCH(M33,Settings!$B$6:$B$15,0))+INDEX(Settings!$D$6:$D$15,MATCH(M33,Settings!$B$6:$B$15,0)),0),2)) | Q33: =IF(OR(H33="",L33="Cancelled"),"",H33-N(N33)-N(O33)-N(P33)) | R33: =IF(OR(B33="",K33=""),"",IF(OR(L33="Sent",L33="Picked up"),"Done",IF(L33="Cancelled","Cancelled",IF(K33<TODAY(),"Late by "&(TODAY()-K33)&IF((TODAY()-K33)=1," day"," days"),IF(K33=TODAY(),"Due today","Due in "&(K33-TODAY())&IF((K33-TODAY())=1," day"," days")))))) | T33: =IF(AND(B33<>"",K33<>"",L33<>"Sent",L33<>"Picked up",L33<>"Cancelled"),K33+ROW()/10000000,"") | U33: =IF(OR(B33="",C33=""),"",B33+ROW()/10000000) | V33: =IF(U33="","",IF(COUNTIFS(Orders!$C$6:$C$1005,C33,Orders!$U$6:$U$1005,">"&U33)=0,1,0)) | W33: =IF(AND(B33<>"",K33<>"",L33<>"Sent",L33<>"Picked up",L33<>"Cancelled"),IF(N(E33)=0,1,E33),0) | X33: =IF(OR(B33="",D33=""),"",IF(N(E33)=0,1,E33))
