Workbook

Sheet Dashboard
B2: Student dashboard
B3: What is due, where your grades stand, and how much you studied.
B5: GPA so far | C5: Due in 7 days | E5: Late | F5: Studied this week | G5: Weekly goal
B6: =IF(SUM(Courses!$AF$6:$AF$15)=0,"",SUMPRODUCT(Courses!$AE$6:$AE$15,Courses!$D$6:$D$15)/SUM(Courses!$AF$6:$AF$15)) | C6: =COUNTIFS(Assignments!$M$6:$M$505,">="&TODAY(),Assignments!$M$6:$M$505,"<"&(TODAY()+8)) | E6: =COUNTIFS(Assignments!$M$6:$M$505,"<"&TODAY()) | F6: =SUMIFS('Study log'!$D$6:$D$1005,'Study log'!$F$6:$F$1005,TODAY()-WEEKDAY(TODAY(),3))/60 | G6: =Settings!$B$15
B8: Course | C8: Grade | D8: Letter | E8: Target | F8: Needed on final | G8: Due in 7 days | I8: Due | J8: Course | K8: Title | L8: When
B9: =IF(Courses!B6="","",Courses!B6) | C9: =IF(B9="","",Courses!M6) | D9: =IF(B9="","",Courses!N6) | E9: =IF(B9="","",Courses!K6) | F9: =IF(B9="","",Courses!O6) | G9: =IF(B9="","",Courses!P6) | I9: =IF(O9="","",INT(O9)) | J9: =IF(O9="","",INDEX(Assignments!$B$6:$B$505,MATCH(O9,Assignments!$M$6:$M$505,0))) | K9: =IF(O9="","",INDEX(Assignments!$C$6:$C$505,MATCH(O9,Assignments!$M$6:$M$505,0))) | L9: =IF(O9="","",INDEX(Assignments!$J$6:$J$505,MATCH(O9,Assignments!$M$6:$M$505,0))) | O9: =IFERROR(SMALL(Assignments!$M$6:$M$505,1),"")
B10: =IF(Courses!B7="","",Courses!B7) | C10: =IF(B10="","",Courses!M7) | D10: =IF(B10="","",Courses!N7) | E10: =IF(B10="","",Courses!K7) | F10: =IF(B10="","",Courses!O7) | G10: =IF(B10="","",Courses!P7) | I10: =IF(O10="","",INT(O10)) | J10: =IF(O10="","",INDEX(Assignments!$B$6:$B$505,MATCH(O10,Assignments!$M$6:$M$505,0))) | K10: =IF(O10="","",INDEX(Assignments!$C$6:$C$505,MATCH(O10,Assignments!$M$6:$M$505,0))) | L10: =IF(O10="","",INDEX(Assignments!$J$6:$J$505,MATCH(O10,Assignments!$M$6:$M$505,0))) | O10: =IFERROR(SMALL(Assignments!$M$6:$M$505,2),"")
B11: =IF(Courses!B8="","",Courses!B8) | C11: =IF(B11="","",Courses!M8) | D11: =IF(B11="","",Courses!N8) | E11: =IF(B11="","",Courses!K8) | F11: =IF(B11="","",Courses!O8) | G11: =IF(B11="","",Courses!P8) | I11: =IF(O11="","",INT(O11)) | J11: =IF(O11="","",INDEX(Assignments!$B$6:$B$505,MATCH(O11,Assignments!$M$6:$M$505,0))) | K11: =IF(O11="","",INDEX(Assignments!$C$6:$C$505,MATCH(O11,Assignments!$M$6:$M$505,0))) | L11: =IF(O11="","",INDEX(Assignments!$J$6:$J$505,MATCH(O11,Assignments!$M$6:$M$505,0))) | O11: =IFERROR(SMALL(Assignments!$M$6:$M$505,3),"")
B12: =IF(Courses!B9="","",Courses!B9) | C12: =IF(B12="","",Courses!M9) | D12: =IF(B12="","",Courses!N9) | E12: =IF(B12="","",Courses!K9) | F12: =IF(B12="","",Courses!O9) | G12: =IF(B12="","",Courses!P9) | I12: =IF(O12="","",INT(O12)) | J12: =IF(O12="","",INDEX(Assignments!$B$6:$B$505,MATCH(O12,Assignments!$M$6:$M$505,0))) | K12: =IF(O12="","",INDEX(Assignments!$C$6:$C$505,MATCH(O12,Assignments!$M$6:$M$505,0))) | L12: =IF(O12="","",INDEX(Assignments!$J$6:$J$505,MATCH(O12,Assignments!$M$6:$M$505,0))) | O12: =IFERROR(SMALL(Assignments!$M$6:$M$505,4),"")
B13: =IF(Courses!B10="","",Courses!B10) | C13: =IF(B13="","",Courses!M10) | D13: =IF(B13="","",Courses!N10) | E13: =IF(B13="","",Courses!K10) | F13: =IF(B13="","",Courses!O10) | G13: =IF(B13="","",Courses!P10) | I13: =IF(O13="","",INT(O13)) | J13: =IF(O13="","",INDEX(Assignments!$B$6:$B$505,MATCH(O13,Assignments!$M$6:$M$505,0))) | K13: =IF(O13="","",INDEX(Assignments!$C$6:$C$505,MATCH(O13,Assignments!$M$6:$M$505,0))) | L13: =IF(O13="","",INDEX(Assignments!$J$6:$J$505,MATCH(O13,Assignments!$M$6:$M$505,0))) | O13: =IFERROR(SMALL(Assignments!$M$6:$M$505,5),"")
B14: =IF(Courses!B11="","",Courses!B11) | C14: =IF(B14="","",Courses!M11) | D14: =IF(B14="","",Courses!N11) | E14: =IF(B14="","",Courses!K11) | F14: =IF(B14="","",Courses!O11) | G14: =IF(B14="","",Courses!P11) | I14: =IF(O14="","",INT(O14)) | J14: =IF(O14="","",INDEX(Assignments!$B$6:$B$505,MATCH(O14,Assignments!$M$6:$M$505,0))) | K14: =IF(O14="","",INDEX(Assignments!$C$6:$C$505,MATCH(O14,Assignments!$M$6:$M$505,0))) | L14: =IF(O14="","",INDEX(Assignments!$J$6:$J$505,MATCH(O14,Assignments!$M$6:$M$505,0))) | O14: =IFERROR(SMALL(Assignments!$M$6:$M$505,6),"")
B15: =IF(Courses!B12="","",Courses!B12) | C15: =IF(B15="","",Courses!M12) | D15: =IF(B15="","",Courses!N12) | E15: =IF(B15="","",Courses!K12) | F15: =IF(B15="","",Courses!O12) | G15: =IF(B15="","",Courses!P12) | I15: =IF(O15="","",INT(O15)) | J15: =IF(O15="","",INDEX(Assignments!$B$6:$B$505,MATCH(O15,Assignments!$M$6:$M$505,0))) | K15: =IF(O15="","",INDEX(Assignments!$C$6:$C$505,MATCH(O15,Assignments!$M$6:$M$505,0))) | L15: =IF(O15="","",INDEX(Assignments!$J$6:$J$505,MATCH(O15,Assignments!$M$6:$M$505,0))) | O15: =IFERROR(SMALL(Assignments!$M$6:$M$505,7),"")
B16: =IF(Courses!B13="","",Courses!B13) | C16: =IF(B16="","",Courses!M13) | D16: =IF(B16="","",Courses!N13) | E16: =IF(B16="","",Courses!K13) | F16: =IF(B16="","",Courses!O13) | G16: =IF(B16="","",Courses!P13) | I16: =IF(O16="","",INT(O16)) | J16: =IF(O16="","",INDEX(Assignments!$B$6:$B$505,MATCH(O16,Assignments!$M$6:$M$505,0))) | K16: =IF(O16="","",INDEX(Assignments!$C$6:$C$505,MATCH(O16,Assignments!$M$6:$M$505,0))) | L16: =IF(O16="","",INDEX(Assignments!$J$6:$J$505,MATCH(O16,Assignments!$M$6:$M$505,0))) | O16: =IFERROR(SMALL(Assignments!$M$6:$M$505,8),"")
B17: =IF(Courses!B14="","",Courses!B14) | C17: =IF(B17="","",Courses!M14) | D17: =IF(B17="","",Courses!N14) | E17: =IF(B17="","",Courses!K14) | F17: =IF(B17="","",Courses!O14) | G17: =IF(B17="","",Courses!P14) | I17: =IF(O17="","",INT(O17)) | J17: =IF(O17="","",INDEX(Assignments!$B$6:$B$505,MATCH(O17,Assignments!$M$6:$M$505,0))) | K17: =IF(O17="","",INDEX(Assignments!$C$6:$C$505,MATCH(O17,Assignments!$M$6:$M$505,0))) | L17: =IF(O17="","",INDEX(Assignments!$J$6:$J$505,MATCH(O17,Assignments!$M$6:$M$505,0))) | O17: =IFERROR(SMALL(Assignments!$M$6:$M$505,9),"")
B18: =IF(Courses!B15="","",Courses!B15) | C18: =IF(B18="","",Courses!M15) | D18: =IF(B18="","",Courses!N15) | E18: =IF(B18="","",Courses!K15) | F18: =IF(B18="","",Courses!O15) | G18: =IF(B18="","",Courses!P15) | I18: =IF(O18="","",INT(O18)) | J18: =IF(O18="","",INDEX(Assignments!$B$6:$B$505,MATCH(O18,Assignments!$M$6:$M$505,0))) | K18: =IF(O18="","",INDEX(Assignments!$C$6:$C$505,MATCH(O18,Assignments!$M$6:$M$505,0))) | L18: =IF(O18="","",INDEX(Assignments!$J$6:$J$505,MATCH(O18,Assignments!$M$6:$M$505,0))) | O18: =IFERROR(SMALL(Assignments!$M$6:$M$505,10),"")
I19: Everything not done yet, the soonest first. Late work comes first.
B21: Week of | C21: Hours | D21: Goal | K21: Course | L21: Hours this term
B22: =TODAY()-WEEKDAY(TODAY(),3)-35 | C22: =SUMIFS('Study log'!$D$6:$D$1005,'Study log'!$F$6:$F$1005,B22)/60 | D22: =Settings!$B$15 | K22: =B9 | L22: =IF(K22="","",SUMIFS('Study log'!$D$6:$D$1005,'Study log'!$C$6:$C$1005,K22)/60)
B23: =TODAY()-WEEKDAY(TODAY(),3)-28 | C23: =SUMIFS('Study log'!$D$6:$D$1005,'Study log'!$F$6:$F$1005,B23)/60 | D23: =Settings!$B$15 | K23: =B10 | L23: =IF(K23="","",SUMIFS('Study log'!$D$6:$D$1005,'Study log'!$C$6:$C$1005,K23)/60)
B24: =TODAY()-WEEKDAY(TODAY(),3)-21 | C24: =SUMIFS('Study log'!$D$6:$D$1005,'Study log'!$F$6:$F$1005,B24)/60 | D24: =Settings!$B$15 | K24: =B11 | L24: =IF(K24="","",SUMIFS('Study log'!$D$6:$D$1005,'Study log'!$C$6:$C$1005,K24)/60)
B25: =TODAY()-WEEKDAY(TODAY(),3)-14 | C25: =SUMIFS('Study log'!$D$6:$D$1005,'Study log'!$F$6:$F$1005,B25)/60 | D25: =Settings!$B$15 | K25: =B12 | L25: =IF(K25="","",SUMIFS('Study log'!$D$6:$D$1005,'Study log'!$C$6:$C$1005,K25)/60)
B26: =TODAY()-WEEKDAY(TODAY(),3)-7 | C26: =SUMIFS('Study log'!$D$6:$D$1005,'Study log'!$F$6:$F$1005,B26)/60 | D26: =Settings!$B$15 | K26: =B13 | L26: =IF(K26="","",SUMIFS('Study log'!$D$6:$D$1005,'Study log'!$C$6:$C$1005,K26)/60)
B27: =TODAY()-WEEKDAY(TODAY(),3)-0 | C27: =SUMIFS('Study log'!$D$6:$D$1005,'Study log'!$F$6:$F$1005,B27)/60 | D27: =Settings!$B$15 | K27: =B14 | L27: =IF(K27="","",SUMIFS('Study log'!$D$6:$D$1005,'Study log'!$C$6:$C$1005,K27)/60)
K28: =B15 | L28: =IF(K28="","",SUMIFS('Study log'!$D$6:$D$1005,'Study log'!$C$6:$C$1005,K28)/60)
K29: =B16 | L29: =IF(K29="","",SUMIFS('Study log'!$D$6:$D$1005,'Study log'!$C$6:$C$1005,K29)/60)
K30: =B17 | L30: =IF(K30="","",SUMIFS('Study log'!$D$6:$D$1005,'Study log'!$C$6:$C$1005,K30)/60)
K31: =B18 | L31: =IF(K31="","",SUMIFS('Study log'!$D$6:$D$1005,'Study log'!$C$6:$C$1005,K31)/60)

Sheet Assignments
B2: Assignments and exams
B3: One line per assignment, quiz or exam. Type the score when you get it back.
B5: Course | C5: Title | D5: Kind | E5: Due date | F5: Status | G5: Score | H5: Out of | I5: Percent | J5: When | K5: Note
B6: Spanish I | C6: Workbook, unit 1 | D6: Homework | E6: 46259 | F6: Done | G6: 9 | H6: 10 | I6: =IF(OR(G6="",N(H6)=0),"",G6/H6) | J6: =IF(OR(B6="",E6=""),"",IF(OR(F6="Done",G6<>""),"Done",IF(E6<TODAY(),"Late by "&(TODAY()-E6)&IF((TODAY()-E6)=1," day"," days"),IF(E6=TODAY(),"Due today",IF(E6=TODAY()+1,"Due tomorrow","Due in "&(E6-TODAY())&IF((E6-TODAY())=1," day"," days")))))) | L6: =IF(G6="","",N(H6)) | M6: =IF(OR(B6="",E6="",OR(F6="Done",G6<>"")),"",E6+ROW()/10000000)
B7: Calculus I | C7: Problem set 1 | D7: Homework | E7: 46261 | F7: Done | G7: 20 | H7: 20 | I7: =IF(OR(G7="",N(H7)=0),"",G7/H7) | J7: =IF(OR(B7="",E7=""),"",IF(OR(F7="Done",G7<>""),"Done",IF(E7<TODAY(),"Late by "&(TODAY()-E7)&IF((TODAY()-E7)=1," day"," days"),IF(E7=TODAY(),"Due today",IF(E7=TODAY()+1,"Due tomorrow","Due in "&(E7-TODAY())&IF((E7-TODAY())=1," day"," days")))))) | L7: =IF(G7="","",N(H7)) | M7: =IF(OR(B7="",E7="",OR(F7="Done",G7<>"")),"",E7+ROW()/10000000)
B8: Biology 101 | C8: Homework 1 | D8: Homework | E8: 46262 | F8: Done | G8: 18 | H8: 20 | I8: =IF(OR(G8="",N(H8)=0),"",G8/H8) | J8: =IF(OR(B8="",E8=""),"",IF(OR(F8="Done",G8<>""),"Done",IF(E8<TODAY(),"Late by "&(TODAY()-E8)&IF((TODAY()-E8)=1," day"," days"),IF(E8=TODAY(),"Due today",IF(E8=TODAY()+1,"Due tomorrow","Due in "&(E8-TODAY())&IF((E8-TODAY())=1," day"," days")))))) | L8: =IF(G8="","",N(H8)) | M8: =IF(OR(B8="",E8="",OR(F8="Done",G8<>"")),"",E8+ROW()/10000000)
B9: Biology 101 | C9: Quiz 1 | D9: Quizzes | E9: 46266 | F9: Done | G9: 12 | H9: 15 | I9: =IF(OR(G9="",N(H9)=0),"",G9/H9) | J9: =IF(OR(B9="",E9=""),"",IF(OR(F9="Done",G9<>""),"Done",IF(E9<TODAY(),"Late by "&(TODAY()-E9)&IF((TODAY()-E9)=1," day"," days"),IF(E9=TODAY(),"Due today",IF(E9=TODAY()+1,"Due tomorrow","Due in "&(E9-TODAY())&IF((E9-TODAY())=1," day"," days")))))) | L9: =IF(G9="","",N(H9)) | M9: =IF(OR(B9="",E9="",OR(F9="Done",G9<>"")),"",E9+ROW()/10000000)
B10: Spanish I | C10: Workbook, unit 2 | D10: Homework | E10: 46266 | F10: Done | G10: 9 | H10: 10 | I10: =IF(OR(G10="",N(H10)=0),"",G10/H10) | J10: =IF(OR(B10="",E10=""),"",IF(OR(F10="Done",G10<>""),"Done",IF(E10<TODAY(),"Late by "&(TODAY()-E10)&IF((TODAY()-E10)=1," day"," days"),IF(E10=TODAY(),"Due today",IF(E10=TODAY()+1,"Due tomorrow","Due in "&(E10-TODAY())&IF((E10-TODAY())=1," day"," days")))))) | L10: =IF(G10="","",N(H10)) | M10: =IF(OR(B10="",E10="",OR(F10="Done",G10<>"")),"",E10+ROW()/10000000)
B11: Calculus I | C11: Quiz 1 | D11: Quizzes | E11: 46267 | F11: Done | G11: 8 | H11: 10 | I11: =IF(OR(G11="",N(H11)=0),"",G11/H11) | J11: =IF(OR(B11="",E11=""),"",IF(OR(F11="Done",G11<>""),"Done",IF(E11<TODAY(),"Late by "&(TODAY()-E11)&IF((TODAY()-E11)=1," day"," days"),IF(E11=TODAY(),"Due today",IF(E11=TODAY()+1,"Due tomorrow","Due in "&(E11-TODAY())&IF((E11-TODAY())=1," day"," days")))))) | L11: =IF(G11="","",N(H11)) | M11: =IF(OR(B11="",E11="",OR(F11="Done",G11<>"")),"",E11+ROW()/10000000)
B12: Calculus I | C12: Problem set 2 | D12: Homework | E12: 46268 | F12: Done | G12: 17 | H12: 20 | I12: =IF(OR(G12="",N(H12)=0),"",G12/H12) | J12: =IF(OR(B12="",E12=""),"",IF(OR(F12="Done",G12<>""),"Done",IF(E12<TODAY(),"Late by "&(TODAY()-E12)&IF((TODAY()-E12)=1," day"," days"),IF(E12=TODAY(),"Due today",IF(E12=TODAY()+1,"Due tomorrow","Due in "&(E12-TODAY())&IF((E12-TODAY())=1," day"," days")))))) | L12: =IF(G12="","",N(H12)) | M12: =IF(OR(B12="",E12="",OR(F12="Done",G12<>"")),"",E12+ROW()/10000000)
B13: Biology 101 | C13: Homework 2 | D13: Homework | E13: 46269 | F13: Done | G13: 19 | H13: 20 | I13: =IF(OR(G13="",N(H13)=0),"",G13/H13) | J13: =IF(OR(B13="",E13=""),"",IF(OR(F13="Done",G13<>""),"Done",IF(E13<TODAY(),"Late by "&(TODAY()-E13)&IF((TODAY()-E13)=1," day"," days"),IF(E13=TODAY(),"Due today",IF(E13=TODAY()+1,"Due tomorrow","Due in "&(E13-TODAY())&IF((E13-TODAY())=1," day"," days")))))) | L13: =IF(G13="","",N(H13)) | M13: =IF(OR(B13="",E13="",OR(F13="Done",G13<>"")),"",E13+ROW()/10000000)
B14: Spanish I | C14: Vocabulary quiz 1 | D14: Quizzes | E14: 46269 | F14: Done | G14: 17 | H14: 20 | I14: =IF(OR(G14="",N(H14)=0),"",G14/H14) | J14: =IF(OR(B14="",E14=""),"",IF(OR(F14="Done",G14<>""),"Done",IF(E14<TODAY(),"Late by "&(TODAY()-E14)&IF((TODAY()-E14)=1," day"," days"),IF(E14=TODAY(),"Due today",IF(E14=TODAY()+1,"Due tomorrow","Due in "&(E14-TODAY())&IF((E14-TODAY())=1," day"," days")))))) | L14: =IF(G14="","",N(H14)) | M14: =IF(OR(B14="",E14="",OR(F14="Done",G14<>"")),"",E14+ROW()/10000000)
B15: Spanish I | C15: Workbook, unit 3 | D15: Homework | E15: 46273 | F15: Done | G15: 9 | H15: 10 | I15: =IF(OR(G15="",N(H15)=0),"",G15/H15) | J15: =IF(OR(B15="",E15=""),"",IF(OR(F15="Done",G15<>""),"Done",IF(E15<TODAY(),"Late by "&(TODAY()-E15)&IF((TODAY()-E15)=1," day"," days"),IF(E15=TODAY(),"Due today",IF(E15=TODAY()+1,"Due tomorrow","Due in "&(E15-TODAY())&IF((E15-TODAY())=1," day"," days")))))) | L15: =IF(G15="","",N(H15)) | M15: =IF(OR(B15="",E15="",OR(F15="Done",G15<>"")),"",E15+ROW()/10000000)
B16: Intro to Psychology | C16: Chapter quiz 1 | D16: Quizzes | E16: 46274 | F16: Done | G16: 22 | H16: 25 | I16: =IF(OR(G16="",N(H16)=0),"",G16/H16) | J16: =IF(OR(B16="",E16=""),"",IF(OR(F16="Done",G16<>""),"Done",IF(E16<TODAY(),"Late by "&(TODAY()-E16)&IF((TODAY()-E16)=1," day"," days"),IF(E16=TODAY(),"Due today",IF(E16=TODAY()+1,"Due tomorrow","Due in "&(E16-TODAY())&IF((E16-TODAY())=1," day"," days")))))) | L16: =IF(G16="","",N(H16)) | M16: =IF(OR(B16="",E16="",OR(F16="Done",G16<>"")),"",E16+ROW()/10000000)
B17: Biology 101 | C17: Lab report 1 | D17: Projects | E17: 46275 | F17: Done | G17: 46 | H17: 50 | I17: =IF(OR(G17="",N(H17)=0),"",G17/H17) | J17: =IF(OR(B17="",E17=""),"",IF(OR(F17="Done",G17<>""),"Done",IF(E17<TODAY(),"Late by "&(TODAY()-E17)&IF((TODAY()-E17)=1," day"," days"),IF(E17=TODAY(),"Due today",IF(E17=TODAY()+1,"Due tomorrow","Due in "&(E17-TODAY())&IF((E17-TODAY())=1," day"," days")))))) | L17: =IF(G17="","",N(H17)) | M17: =IF(OR(B17="",E17="",OR(F17="Done",G17<>"")),"",E17+ROW()/10000000)
... B27: Spanish I | C27: Workbook, unit 5 | D27: Homework | E27: 46287 | F27: Done | G27: 10 | H27: 10 | I27: =IF(OR(G27="",N(H27)=0),"",G27/H27) | J27: =IF(OR(B27="",E27=""),"",IF(OR(F27="Done",G27<>""),"Done",IF(E27<TODAY(),"Late by "&(TODAY()-E27)&IF((TODAY()-E27)=1," day"," days"),IF(E27=TODAY(),"Due today",IF(E27=TODAY()+1,"Due tomorrow","Due in "&(E27-TODAY())&IF((E27-TODAY())=1," day"," days")))))) | L27: =IF(G27="","",N(H27)) | M27: =IF(OR(B27="",E27="",OR(F27="Done",G27<>"")),"",E27+ROW()/10000000)
B28: Calculus I | C28: Problem set 5 | D28: Homework | E28: 46289 | F28: To do | H28: 20 | I28: =IF(OR(G28="",N(H28)=0),"",G28/H28) | J28: =IF(OR(B28="",E28=""),"",IF(OR(F28="Done",G28<>""),"Done",IF(E28<TODAY(),"Late by "&(TODAY()-E28)&IF((TODAY()-E28)=1," day"," days"),IF(E28=TODAY(),"Due today",IF(E28=TODAY()+1,"Due tomorrow","Due in "&(E28-TODAY())&IF((E28-TODAY())=1," day"," days")))))) | K28: Ask for an extension | L28: =IF(G28="","",N(H28)) | M28: =IF(OR(B28="",E28="",OR(F28="Done",G28<>"")),"",E28+ROW()/10000000)
B29: Biology 101 | C29: Homework 5 | D29: Homework | E29: 46290 | F29: Done | G29: 18 | H29: 20 | I29: =IF(OR(G29="",N(H29)=0),"",G29/H29) | J29: =IF(OR(B29="",E29=""),"",IF(OR(F29="Done",G29<>""),"Done",IF(E29<TODAY(),"Late by "&(TODAY()-E29)&IF((TODAY()-E29)=1," day"," days"),IF(E29=TODAY(),"Due today",IF(E29=TODAY()+1,"Due tomorrow","Due in "&(E29-TODAY())&IF((E29-TODAY())=1," day"," days")))))) | L29: =IF(G29="","",N(H29)) | M29: =IF(OR(B29="",E29="",OR(F29="Done",G29<>"")),"",E29+ROW()/10000000)
B30: Biology 101 | C30: Quiz 3 | D30: Quizzes | E30: 46294 | F30: To do | H30: 15 | I30: =IF(OR(G30="",N(H30)=0),"",G30/H30) | J30: =IF(OR(B30="",E30=""),"",IF(OR(F30="Done",G30<>""),"Done",IF(E30<TODAY(),"Late by "&(TODAY()-E30)&IF((TODAY()-E30)=1," day"," days"),IF(E30=TODAY(),"Due today",IF(E30=TODAY()+1,"Due tomorrow","Due in "&(E30-TODAY())&IF((E30-TODAY())=1," day"," days")))))) | L30: =IF(G30="","",N(H30)) | M30: =IF(OR(B30="",E30="",OR(F30="Done",G30<>"")),"",E30+ROW()/10000000)
B31: Spanish I | C31: Workbook, unit 6 | D31: Homework | E31: 46294 | F31: In progress | H31: 10 | I31: =IF(OR(G31="",N(H31)=0),"",G31/H31) | J31: =IF(OR(B31="",E31=""),"",IF(OR(F31="Done",G31<>""),"Done",IF(E31<TODAY(),"Late by "&(TODAY()-E31)&IF((TODAY()-E31)=1," day"," days"),IF(E31=TODAY(),"Due today",IF(E31=TODAY()+1,"Due tomorrow","Due in "&(E31-TODAY())&IF((E31-TODAY())=1," day"," days")))))) | L31: =IF(G31="","",N(H31)) | M31: =IF(OR(B31="",E31="",OR(F31="Done",G31<>"")),"",E31+ROW()/10000000)
B32: Calculus I | C32: Quiz 3 | D32: Quizzes | E32: 46295 | F32: To do | H32: 10 | I32: =IF(OR(G32="",N(H32)=0),"",G32/H32) | J32: =IF(OR(B32="",E32=""),"",IF(OR(F32="Done",G32<>""),"Done",IF(E32<TODAY(),"Late by "&(TODAY()-E32)&IF((TODAY()-E32)=1," day"," days"),IF(E32=TODAY(),"Due today",IF(E32=TODAY()+1,"Due tomorrow","Due in "&(E32-TODAY())&IF((E32-TODAY())=1," day"," days")))))) | L32: =IF(G32="","",N(H32)) | M32: =IF(OR(B32="",E32="",OR(F32="Done",G32<>"")),"",E32+ROW()/10000000)
B33: Intro to Psychology | C33: Chapter quiz 2 | D33: Quizzes | E33: 46295 | F33: To do | H33: 25 | I33: =IF(OR(G33="",N(H33)=0),"",G33/H33) | J33: =IF(OR(B33="",E33=""),"",IF(OR(F33="Done",G33<>""),"Done",IF(E33<TODAY(),"Late by "&(TODAY()-E33)&IF((TODAY()-E33)=1," day"," days"),IF(E33=TODAY(),"Due today",IF(E33=TODAY()+1,"Due tomorrow","Due in "&(E33-TODAY())&IF((E33-TODAY())=1," day"," days")))))) | L33: =IF(G33="","",N(H33)) | M33: =IF(OR(B33="",E33="",OR(F33="Done",G33<>"")),"",E33+ROW()/10000000)
B34: Biology 101 | C34: Lab report 2 | D34: Projects | E34: 46296 | F34: In progress | H34: 50 | I34: =IF(OR(G34="",N(H34)=0),"",G34/H34) | J34: =IF(OR(B34="",E34=""),"",IF(OR(F34="Done",G34<>""),"Done",IF(E34<TODAY(),"Late by "&(TODAY()-E34)&IF((TODAY()-E34)=1," day"," days"),IF(E34=TODAY(),"Due today",IF(E34=TODAY()+1,"Due tomorrow","Due in "&(E34-TODAY())&IF((E34-TODAY())=1," day"," days")))))) | L34: =IF(G34="","",N(H34)) | M34: =IF(OR(B34="",E34="",OR(F34="Done",G34<>"")),"",E34+ROW()/10000000)
B35: Calculus I | C35: Problem set 6 | D35: Homework | E35: 46296 | F35: To do | H35: 20 | I35: =IF(OR(G35="",N(H35)=0),"",G35/H35) | J35: =IF(OR(B35="",E35=""),"",IF(OR(F35="Done",G35<>""),"Done",IF(E35<TODAY(),"Late by "&(TODAY()-E35)&IF((TODAY()-E35)=1," day"," days"),IF(E35=TODAY(),"Due today",IF(E35=TODAY()+1,"Due tomorrow","Due in "&(E35-TODAY())&IF((E35-TODAY())=1," day"," days")))))) | L35: =IF(G35="","",N(H35)) | M35: =IF(OR(B35="",E35="",OR(F35="Done",G35<>"")),"",E35+ROW()/10000000)
B36: Spanish I | C36: Oral exam 1 | D36: Other | E36: 46296 | F36: To do | H36: 25 | I36: =IF(OR(G36="",N(H36)=0),"",G36/H36) | J36: =IF(OR(B36="",E36=""),"",IF(OR(F36="Done",G36<>""),"Done",IF(E36<TODAY(),"Late by "&(TODAY()-E36)&IF((TODAY()-E36)=1," day"," days"),IF(E36=TODAY(),"Due today",IF(E36=TODAY()+1,"Due tomorrow","Due in "&(E36-TODAY())&IF((E36-TODAY())=1," day"," days")))))) | L36: =IF(G36="","",N(H36)) | M36: =IF(OR(B36="",E36="",OR(F36="Done",G36<>"")),"",E36+ROW()/10000000)
B37: Biology 101 | C37: Homework 6 | D37: Homework | E37: 46297 | F37: In progress | H37: 20 | I37: =IF(OR(G37="",N(H37)=0),"",G37/H37) | J37: =IF(OR(B37="",E37=""),"",IF(OR(F37="Done",G37<>""),"Done",IF(E37<TODAY(),"Late by "&(TODAY()-E37)&IF((TODAY()-E37)=1," day"," days"),IF(E37=TODAY(),"Due today",IF(E37=TODAY()+1,"Due tomorrow","Due in "&(E37-TODAY())&IF((E37-TODAY())=1," day"," days")))))) | L37: =IF(G37="","",N(H37)) | M37: =IF(OR(B37="",E37="",OR(F37="Done",G37<>"")),"",E37+ROW()/10000000)
B38: Spanish I | C38: Vocabulary quiz 3 | D38: Quizzes | E38: 46297 | F38: In progress | H38: 20 | I38: =IF(OR(G38="",N(H38)=0),"",G38/H38) | J38: =IF(OR(B38="",E38=""),"",IF(OR(F38="Done",G38<>""),"Done",IF(E38<TODAY(),"Late by "&(TODAY()-E38)&IF((TODAY()-E38)=1," day"," days"),IF(E38=TODAY(),"Due today",IF(E38=TODAY()+1,"Due tomorrow","Due in "&(E38-TODAY())&IF((E38-TODAY())=1," day"," days")))))) | L38: =IF(G38="","",N(H38)) | M38: =IF(OR(B38="",E38="",OR(F38="Done",G38<>"")),"",E38+ROW()/10000000)
B39: Spanish I | C39: Workbook, unit 7 | D39: Homework | E39: 46301 | F39: To do | H39: 10 | I39: =IF(OR(G39="",N(H39)=0),"",G39/H39) | J39: =IF(OR(B39="",E39=""),"",IF(OR(F39="Done",G39<>""),"Done",IF(E39<TODAY(),"Late by "&(TODAY()-E39)&IF((TODAY()-E39)=1," day"," days"),IF(E39=TODAY(),"Due today",IF(E39=TODAY()+1,"Due tomorrow","Due in "&(E39-TODAY())&IF((E39-TODAY())=1," day"," days")))))) | L39: =IF(G39="","",N(H39)) | M39: =IF(OR(B39="",E39="",OR(F39="Done",G39<>"")),"",E39+ROW()/10000000)
B40: Calculus I | C40: Problem set 7 | D40: Homework | E40: 46303 | F40: To do | H40: 20 | I40: =IF(OR(G40="",N(H40)=0),"",G40/H40) | J40: =IF(OR(B40="",E40=""),"",IF(OR(F40="Done",G40<>""),"Done",IF(E40<TODAY(),"Late by "&(TODAY()-E40)&IF((TODAY()-E40)=1," day"," days"),IF(E40=TODAY(),"Due today",IF(E40=TODAY()+1,"Due tomorrow","Due in "&(E40-TODAY())&IF((E40-TODAY())=1," day"," days")))))) | L40: =IF(G40="","",N(H40)) | M40: =IF(OR(B40="",E40="",OR(F40="Done",G40<>"")),"",E40+ROW()/10000000)
B41: Biology 101 | C41: Homework 7 | D41: Homework | E41: 46304 | F41: To do | H41: 20 | I41: =IF(OR(G41="",N(H41)=0),"",G41/H41) | J41: =IF(OR(B41="",E41=""),"",IF(OR(F41="Done",G41<>""),"Done",IF(E41<TODAY(),"Late by "&(TODAY()-E41)&IF((TODAY()-E41)=1," day"," days"),IF(E41=TODAY(),"Due today",IF(E41=TODAY()+1,"Due tomorrow","Due in "&(E41-TODAY())&IF((E41-TODAY())=1," day"," days")))))) | L41: =IF(G41="","",N(H41)) | M41: =IF(OR(B41="",E41="",OR(F41="Done",G41<>"")),"",E41+ROW()/10000000)
... B97: Biology 101 | C97: Final exam | D97: Final | E97: 46367 | F97: To do | H97: 100 | I97: =IF(OR(G97="",N(H97)=0),"",G97/H97) | J97: =IF(OR(B97="",E97=""),"",IF(OR(F97="Done",G97<>""),"Done",IF(E97<TODAY(),"Late by "&(TODAY()-E97)&IF((TODAY()-E97)=1," day"," days"),IF(E97=TODAY(),"Due today",IF(E97=TODAY()+1,"Due tomorrow","Due in "&(E97-TODAY())&IF((E97-TODAY())=1," day"," days")))))) | L97: =IF(G97="","",N(H97)) | M97: =IF(OR(B97="",E97="",OR(F97="Done",G97<>"")),"",E97+ROW()/10000000)
I98: =IF(OR(G98="",N(H98)=0),"",G98/H98) | J98: =IF(OR(B98="",E98=""),"",IF(OR(F98="Done",G98<>""),"Done",IF(E98<TODAY(),"Late by "&(TODAY()-E98)&IF((TODAY()-E98)=1," day"," days"),IF(E98=TODAY(),"Due today",IF(E98=TODAY()+1,"Due tomorrow","Due in "&(E98-TODAY())&IF((E98-TODAY())=1," day"," days")))))) | L98: =IF(G98="","",N(H98)) | M98: =IF(OR(B98="",E98="",OR(F98="Done",G98<>"")),"",E98+ROW()/10000000)
I99: =IF(OR(G99="",N(H99)=0),"",G99/H99) | J99: =IF(OR(B99="",E99=""),"",IF(OR(F99="Done",G99<>""),"Done",IF(E99<TODAY(),"Late by "&(TODAY()-E99)&IF((TODAY()-E99)=1," day"," days"),IF(E99=TODAY(),"Due today",IF(E99=TODAY()+1,"Due tomorrow","Due in "&(E99-TODAY())&IF((E99-TODAY())=1," day"," days")))))) | L99: =IF(G99="","",N(H99)) | M99: =IF(OR(B99="",E99="",OR(F99="Done",G99<>"")),"",E99+ROW()/10000000)
I100: =IF(OR(G100="",N(H100)=0),"",G100/H100) | J100: =IF(OR(B100="",E100=""),"",IF(OR(F100="Done",G100<>""),"Done",IF(E100<TODAY(),"Late by "&(TODAY()-E100)&IF((TODAY()-E100)=1," day"," days"),IF(E100=TODAY(),"Due today",IF(E100=TODAY()+1,"Due tomorrow","Due in "&(E100-TODAY())&IF((E100-TODAY())=1," day"," days")))))) | L100: =IF(G100="","",N(H100)) | M100: =IF(OR(B100="",E100="",OR(F100="Done",G100<>"")),"",E100+ROW()/10000000)
I101: =IF(OR(G101="",N(H101)=0),"",G101/H101) | J101: =IF(OR(B101="",E101=""),"",IF(OR(F101="Done",G101<>""),"Done",IF(E101<TODAY(),"Late by "&(TODAY()-E101)&IF((TODAY()-E101)=1," day"," days"),IF(E101=TODAY(),"Due today",IF(E101=TODAY()+1,"Due tomorrow","Due in "&(E101-TODAY())&IF((E101-TODAY())=1," day"," days")))))) | L101: =IF(G101="","",N(H101)) | M101: =IF(OR(B101="",E101="",OR(F101="Done",G101<>"")),"",E101+ROW()/10000000)
I102: =IF(OR(G102="",N(H102)=0),"",G102/H102) | J102: =IF(OR(B102="",E102=""),"",IF(OR(F102="Done",G102<>""),"Done",IF(E102<TODAY(),"Late by "&(TODAY()-E102)&IF((TODAY()-E102)=1," day"," days"),IF(E102=TODAY(),"Due today",IF(E102=TODAY()+1,"Due tomorrow","Due in "&(E102-TODAY())&IF((E102-TODAY())=1," day"," days")))))) | L102: =IF(G102="","",N(H102)) | M102: =IF(OR(B102="",E102="",OR(F102="Done",G102<>"")),"",E102+ROW()/10000000)
I103: =IF(OR(G103="",N(H103)=0),"",G103/H103) | J103: =IF(OR(B103="",E103=""),"",IF(OR(F103="Done",G103<>""),"Done",IF(E103<TODAY(),"Late by "&(TODAY()-E103)&IF((TODAY()-E103)=1," day"," days"),IF(E103=TODAY(),"Due today",IF(E103=TODAY()+1,"Due tomorrow","Due in "&(E103-TODAY())&IF((E103-TODAY())=1," day"," days")))))) | L103: =IF(G103="","",N(H103)) | M103: =IF(OR(B103="",E103="",OR(F103="Done",G103<>"")),"",E103+ROW()/10000000)
I104: =IF(OR(G104="",N(H104)=0),"",G104/H104) | J104: =IF(OR(B104="",E104=""),"",IF(OR(F104="Done",G104<>""),"Done",IF(E104<TODAY(),"Late by "&(TODAY()-E104)&IF((TODAY()-E104)=1," day"," days"),IF(E104=TODAY(),"Due today",IF(E104=TODAY()+1,"Due tomorrow","Due in "&(E104-TODAY())&IF((E104-TODAY())=1," day"," days")))))) | L104: =IF(G104="","",N(H104)) | M104: =IF(OR(B104="",E104="",OR(F104="Done",G104<>"")),"",E104+ROW()/10000000)
I105: =IF(OR(G105="",N(H105)=0),"",G105/H105) | J105: =IF(OR(B105="",E105=""),"",IF(OR(F105="Done",G105<>""),"Done",IF(E105<TODAY(),"Late by "&(TODAY()-E105)&IF((TODAY()-E105)=1," day"," days"),IF(E105=TODAY(),"Due today",IF(E105=TODAY()+1,"Due tomorrow","Due in "&(E105-TODAY())&IF((E105-TODAY())=1," day"," days")))))) | L105: =IF(G105="","",N(H105)) | M105: =IF(OR(B105="",E105="",OR(F105="Done",G105<>"")),"",E105+ROW()/10000000)
I106: =IF(OR(G106="",N(H106)=0),"",G106/H106) | J106: =IF(OR(B106="",E106=""),"",IF(OR(F106="Done",G106<>""),"Done",IF(E106<TODAY(),"Late by "&(TODAY()-E106)&IF((TODAY()-E106)=1," day"," days"),IF(E106=TODAY(),"Due today",IF(E106=TODAY()+1,"Due tomorrow","Due in "&(E106-TODAY())&IF((E106-TODAY())=1," day"," days")))))) | L106: =IF(G106="","",N(H106)) | M106: =IF(OR(B106="",E106="",OR(F106="Done",G106<>"")),"",E106+ROW()/10000000)
...

Sheet Courses
B2: Courses
B3: Each course with its credits and how much each kind of work counts. The weights should add up to 100%.
B5: Course | C5: Teacher | D5: Credits | E5: =Settings!B6 | F5: =Settings!B7 | G5: =Settings!B8 | H5: =Settings!B9 | I5: =Settings!B10 | J5: =Settings!B11 | K5: Target | L5: Weights | M5: Grade now | N5: Letter | O5: Needed on final | P5: Due in 7 days
B6: Biology 101 | C6: Dr. Reyes | D6: 4 | E6: 0.15 | F6: 0.15 | G6: 0.2 | H6: 0.2 | I6: 0.3 | K6: 0.9 | L6: =IF(B6="","",SUM(E6:J6)) | M6: =IF(OR(B6="",SUM(X6:AC6)=0),"",SUMPRODUCT(E6:J6,R6:W6)/SUM(X6:AC6)) | N6: =IF(M6="","",INDEX(Settings!$E$6:$E$17,MATCH(M6+0.0000001,Settings!$D$6:$D$17,1))) | O6: =IF(OR(M6="",N(I6)=0,AB6>0,N(K6)=0),"",IF((N(K6)-M6*(1-N(I6)))/N(I6)<=0,"Any score",IF((N(K6)-M6*(1-N(I6)))/N(I6)>1,"Above 100%",(N(K6)-M6*(1-N(I6)))/N(I6)))) | P6: =IF(B6="","",COUNTIFS(Assignments!$B$6:$B$505,B6,Assignments!$M$6:$M$505,">="&TODAY(),Assignments!$M$6:$M$505,"<"&(TODAY()+8))) | R6: =IF(OR($B6="",SUMIFS(Assignments!$L$6:$L$505,Assignments!$B$6:$B$505,$B6,Assignments!$D$6:$D$505,Settings!$B$6)=0),0,SUMIFS(Assignments!$G$6:$G$505,Assignments!$B$6:$B$505,$B6,Assignments!$D$6:$D$505,Settings!$B$6)/SUMIFS(Assignments!$L$6:$L$505,Assignments!$B$6:$B$505,$B6,Assignments!$D$6:$D$505,Settings!$B$6)) | S6: =IF(OR($B6="",SUMIFS(Assignments!$L$6:$L$505,Assignments!$B$6:$B$505,$B6,Assignments!$D$6:$D$505,Settings!$B$7)=0),0,SUMIFS(Assignments!$G$6:$G$505,Assignments!$B$6:$B$505,$B6,Assignments!$D$6:$D$505,Settings!$B$7)/SUMIFS(Assignments!$L$6:$L$505,Assignments!$B$6:$B$505,$B6,Assignments!$D$6:$D$505,Settings!$B$7)) | T6: =IF(OR($B6="",SUMIFS(Assignments!$L$6:$L$505,Assignments!$B$6:$B$505,$B6,Assignments!$D$6:$D$505,Settings!$B$8)=0),0,SUMIFS(Assignments!$G$6:$G$505,Assignments!$B$6:$B$505,$B6,Assignments!$D$6:$D$505,Settings!$B$8)/SUMIFS(Assignments!$L$6:$L$505,Assignments!$B$6:$B$505,$B6,Assignments!$D$6:$D$505,Settings!$B$8)) | U6: =IF(OR($B6="",SUMIFS(Assignments!$L$6:$L$505,Assignments!$B$6:$B$505,$B6,Assignments!$D$6:$D$505,Settings!$B$9)=0),0,SUMIFS(Assignments!$G$6:$G$505,Assignments!$B$6:$B$505,$B6,Assignments!$D$6:$D$505,Settings!$B$9)/SUMIFS(Assignments!$L$6:$L$505,Assignments!$B$6:$B$505,$B6,Assignments!$D$6:$D$505,Settings!$B$9)) | V6: =IF(OR($B6="",SUMIFS(Assignments!$L$6:$L$505,Assignments!$B$6:$B$505,$B6,Assignments!$D$6:$D$505,Settings!$B$10)=0),0,SUMIFS(Assignments!$G$6:$G$505,Assignments!$B$6:$B$505,$B6,Assignments!$D$6:$D$505,Settings!$B$10)/SUMIFS(Assignments!$L$6:$L$505,Assignments!$B$6:$B$505,$B6,Assignments!$D$6:$D$505,Settings!$B$10)) | W6: =IF(OR($B6="",SUMIFS(Assignments!$L$6:$L$505,Assignments!$B$6:$B$505,$B6,Assignments!$D$6:$D$505,Settings!$B$11)=0),0,SUMIFS(Assignments!$G$6:$G$505,Assignments!$B$6:$B$505,$B6,Assignments!$D$6:$D$505,Settings!$B$11)/SUMIFS(Assignments!$L$6:$L$505,Assignments!$B$6:$B$505,$B6,Assignments!$D$6:$D$505,Settings!$B$11)) | X6: =IF(OR($B6="",SUMIFS(Assignments!$L$6:$L$505,Assignments!$B$6:$B$505,$B6,Assignments!$D$6:$D$505,Settings!$B$6)=0),0,N(E6)) | Y6: =IF(OR($B6="",SUMIFS(Assignments!$L$6:$L$505,Assignments!$B$6:$B$505,$B6,Assignments!$D$6:$D$505,Settings!$B$7)=0),0,N(F6)) | Z6: =IF(OR($B6="",SUMIFS(Assignments!$L$6:$L$505,Assignments!$B$6:$B$505,$B6,Assignments!$D$6:$D$505,Settings!$B$8)=0),0,N(G6)) | AA6: =IF(OR($B6="",SUMIFS(Assignments!$L$6:$L$505,Assignments!$B$6:$B$505,$B6,Assignments!$D$6:$D$505,Settings!$B$9)=0),0,N(H6)) | AB6: =IF(OR($B6="",SUMIFS(Assignments!$L$6:$L$505,Assignments!$B$6:$B$505,$B6,Assignments!$D$6:$D$505,Settings!$B$10)=0),0,N(I6)) | AC6: =IF(OR($B6="",SUMIFS(Assignments!$L$6:$L$505,Assignments!$B$6:$B$505,$B6,Assignments!$D$6:$D$505,Settings!$B$11)=0),0,N(J6)) | AD6: =IF(N6="","",IFERROR(INDEX(Settings!$F$6:$F$17,MATCH(N6,Settings!$E$6:$E$17,0)),"")) | AE6: =IF(OR(B6="",AD6=""),0,AD6) | AF6: =IF(OR(B6="",AD6=""),0,N(D6))
B7: Calculus I | C7: Prof. Chen | D7: 4 | E7: 0.2 | F7: 0.2 | H7: 0.25 | I7: 0.35 | K7: 0.85 | L7: =IF(B7="","",SUM(E7:J7)) | M7: =IF(OR(B7="",SUM(X7:AC7)=0),"",SUMPRODUCT(E7:J7,R7:W7)/SUM(X7:AC7)) | N7: =IF(M7="","",INDEX(Settings!$E$6:$E$17,MATCH(M7+0.0000001,Settings!$D$6:$D$17,1))) | O7: =IF(OR(M7="",N(I7)=0,AB7>0,N(K7)=0),"",IF((N(K7)-M7*(1-N(I7)))/N(I7)<=0,"Any score",IF((N(K7)-M7*(1-N(I7)))/N(I7)>1,"Above 100%",(N(K7)-M7*(1-N(I7)))/N(I7)))) | P7: =IF(B7="","",COUNTIFS(Assignments!$B$6:$B$505,B7,Assignments!$M$6:$M$505,">="&TODAY(),Assignments!$M$6:$M$505,"<"&(TODAY()+8))) | R7: =IF(OR($B7="",SUMIFS(Assignments!$L$6:$L$505,Assignments!$B$6:$B$505,$B7,Assignments!$D$6:$D$505,Settings!$B$6)=0),0,SUMIFS(Assignments!$G$6:$G$505,Assignments!$B$6:$B$505,$B7,Assignments!$D$6:$D$505,Settings!$B$6)/SUMIFS(Assignments!$L$6:$L$505,Assignments!$B$6:$B$505,$B7,Assignments!$D$6:$D$505,Settings!$B$6)) | S7: =IF(OR($B7="",SUMIFS(Assignments!$L$6:$L$505,Assignments!$B$6:$B$505,$B7,Assignments!$D$6:$D$505,Settings!$B$7)=0),0,SUMIFS(Assignments!$G$6:$G$505,Assignments!$B$6:$B$505,$B7,Assignments!$D$6:$D$505,Settings!$B$7)/SUMIFS(Assignments!$L$6:$L$505,Assignments!$B$6:$B$505,$B7,Assignments!$D$6:$D$505,Settings!$B$7)) | T7: =IF(OR($B7="",SUMIFS(Assignments!$L$6:$L$505,Assignments!$B$6:$B$505,$B7,Assignments!$D$6:$D$505,Settings!$B$8)=0),0,SUMIFS(Assignments!$G$6:$G$505,Assignments!$B$6:$B$505,$B7,Assignments!$D$6:$D$505,Settings!$B$8)/SUMIFS(Assignments!$L$6:$L$505,Assignments!$B$6:$B$505,$B7,Assignments!$D$6:$D$505,Settings!$B$8)) | U7: =IF(OR($B7="",SUMIFS(Assignments!$L$6:$L$505,Assignments!$B$6:$B$505,$B7,Assignments!$D$6:$D$505,Settings!$B$9)=0),0,SUMIFS(Assignments!$G$6:$G$505,Assignments!$B$6:$B$505,$B7,Assignments!$D$6:$D$505,Settings!$B$9)/SUMIFS(Assignments!$L$6:$L$505,Assignments!$B$6:$B$505,$B7,Assignments!$D$6:$D$505,Settings!$B$9)) | V7: =IF(OR($B7="",SUMIFS(Assignments!$L$6:$L$505,Assignments!$B$6:$B$505,$B7,Assignments!$D$6:$D$505,Settings!$B$10)=0),0,SUMIFS(Assignments!$G$6:$G$505,Assignments!$B$6:$B$505,$B7,Assignments!$D$6:$D$505,Settings!$B$10)/SUMIFS(Assignments!$L$6:$L$505,Assignments!$B$6:$B$505,$B7,Assignments!$D$6:$D$505,Settings!$B$10)) | W7: =IF(OR($B7="",SUMIFS(Assignments!$L$6:$L$505,Assignments!$B$6:$B$505,$B7,Assignments!$D$6:$D$505,Settings!$B$11)=0),0,SUMIFS(Assignments!$G$6:$G$505,Assignments!$B$6:$B$505,$B7,Assignments!$D$6:$D$505,Settings!$B$11)/SUMIFS(Assignments!$L$6:$L$505,Assignments!$B$6:$B$505,$B7,Assignments!$D$6:$D$505,Settings!$B$11)) | X7: =IF(OR($B7="",SUMIFS(Assignments!$L$6:$L$505,Assignments!$B$6:$B$505,$B7,Assignments!$D$6:$D$505,Settings!$B$6)=0),0,N(E7)) | Y7: =IF(OR($B7="",SUMIFS(Assignments!$L$6:$L$505,Assignments!$B$6:$B$505,$B7,Assignments!$D$6:$D$505,Settings!$B$7)=0),0,N(F7)) | Z7: =IF(OR($B7="",SUMIFS(Assignments!$L$6:$L$505,Assignments!$B$6:$B$505,$B7,Assignments!$D$6:$D$505,Settings!$B$8)=0),0,N(G7)) | AA7: =IF(OR($B7="",SUMIFS(Assignments!$L$6:$L$505,Assignments!$B$6:$B$505,$B7,Assignments!$D$6:$D$505,Settings!$B$9)=0),0,N(H7)) | AB7: =IF(OR($B7="",SUMIFS(Assignments!$L$6:$L$505,Assignments!$B$6:$B$505,$B7,Assignments!$D$6:$D$505,Settings!$B$10)=0),0,N(I7)) | AC7: =IF(OR($B7="",SUMIFS(Assignments!$L$6:$L$505,Assignments!$B$6:$B$505,$B7,Assignments!$D$6:$D$505,Settings!$B$11)=0),0,N(J7)) | AD7: =IF(N7="","",IFERROR(INDEX(Settings!$F$6:$F$17,MATCH(N7,Settings!$E$6:$E$17,0)),"")) | AE7: =IF(OR(B7="",AD7=""),0,AD7) | AF7: =IF(OR(B7="",AD7=""),0,N(D7))
B8: English Composition | C8: Ms. Porter | D8: 3 | G8: 0.6 | I8: 0.3 | J8: 0.1 | K8: 0.9 | L8: =IF(B8="","",SUM(E8:J8)) | M8: =IF(OR(B8="",SUM(X8:AC8)=0),"",SUMPRODUCT(E8:J8,R8:W8)/SUM(X8:AC8)) | N8: =IF(M8="","",INDEX(Settings!$E$6:$E$17,MATCH(M8+0.0000001,Settings!$D$6:$D$17,1))) | O8: =IF(OR(M8="",N(I8)=0,AB8>0,N(K8)=0),"",IF((N(K8)-M8*(1-N(I8)))/N(I8)<=0,"Any score",IF((N(K8)-M8*(1-N(I8)))/N(I8)>1,"Above 100%",(N(K8)-M8*(1-N(I8)))/N(I8)))) | P8: =IF(B8="","",COUNTIFS(Assignments!$B$6:$B$505,B8,Assignments!$M$6:$M$505,">="&TODAY(),Assignments!$M$6:$M$505,"<"&(TODAY()+8))) | R8: =IF(OR($B8="",SUMIFS(Assignments!$L$6:$L$505,Assignments!$B$6:$B$505,$B8,Assignments!$D$6:$D$505,Settings!$B$6)=0),0,SUMIFS(Assignments!$G$6:$G$505,Assignments!$B$6:$B$505,$B8,Assignments!$D$6:$D$505,Settings!$B$6)/SUMIFS(Assignments!$L$6:$L$505,Assignments!$B$6:$B$505,$B8,Assignments!$D$6:$D$505,Settings!$B$6)) | S8: =IF(OR($B8="",SUMIFS(Assignments!$L$6:$L$505,Assignments!$B$6:$B$505,$B8,Assignments!$D$6:$D$505,Settings!$B$7)=0),0,SUMIFS(Assignments!$G$6:$G$505,Assignments!$B$6:$B$505,$B8,Assignments!$D$6:$D$505,Settings!$B$7)/SUMIFS(Assignments!$L$6:$L$505,Assignments!$B$6:$B$505,$B8,Assignments!$D$6:$D$505,Settings!$B$7)) | T8: =IF(OR($B8="",SUMIFS(Assignments!$L$6:$L$505,Assignments!$B$6:$B$505,$B8,Assignments!$D$6:$D$505,Settings!$B$8)=0),0,SUMIFS(Assignments!$G$6:$G$505,Assignments!$B$6:$B$505,$B8,Assignments!$D$6:$D$505,Settings!$B$8)/SUMIFS(Assignments!$L$6:$L$505,Assignments!$B$6:$B$505,$B8,Assignments!$D$6:$D$505,Settings!$B$8)) | U8: =IF(OR($B8="",SUMIFS(Assignments!$L$6:$L$505,Assignments!$B$6:$B$505,$B8,Assignments!$D$6:$D$505,Settings!$B$9)=0),0,SUMIFS(Assignments!$G$6:$G$505,Assignments!$B$6:$B$505,$B8,Assignments!$D$6:$D$505,Settings!$B$9)/SUMIFS(Assignments!$L$6:$L$505,Assignments!$B$6:$B$505,$B8,Assignments!$D$6:$D$505,Settings!$B$9)) | V8: =IF(OR($B8="",SUMIFS(Assignments!$L$6:$L$505,Assignments!$B$6:$B$505,$B8,Assignments!$D$6:$D$505,Settings!$B$10)=0),0,SUMIFS(Assignments!$G$6:$G$505,Assignments!$B$6:$B$505,$B8,Assignments!$D$6:$D$505,Settings!$B$10)/SUMIFS(Assignments!$L$6:$L$505,Assignments!$B$6:$B$505,$B8,Assignments!$D$6:$D$505,Settings!$B$10)) | W8: =IF(OR($B8="",SUMIFS(Assignments!$L$6:$L$505,Assignments!$B$6:$B$505,$B8,Assignments!$D$6:$D$505,Settings!$B$11)=0),0,SUMIFS(Assignments!$G$6:$G$505,Assignments!$B$6:$B$505,$B8,Assignments!$D$6:$D$505,Settings!$B$11)/SUMIFS(Assignments!$L$6:$L$505,Assignments!$B$6:$B$505,$B8,Assignments!$D$6:$D$505,Settings!$B$11)) | X8: =IF(OR($B8="",SUMIFS(Assignments!$L$6:$L$505,Assignments!$B$6:$B$505,$B8,Assignments!$D$6:$D$505,Settings!$B$6)=0),0,N(E8)) | Y8: =IF(OR($B8="",SUMIFS(Assignments!$L$6:$L$505,Assignments!$B$6:$B$505,$B8,Assignments!$D$6:$D$505,Settings!$B$7)=0),0,N(F8)) | Z8: =IF(OR($B8="",SUMIFS(Assignments!$L$6:$L$505,Assignments!$B$6:$B$505,$B8,Assignments!$D$6:$D$505,Settings!$B$8)=0),0,N(G8)) | AA8: =IF(OR($B8="",SUMIFS(Assignments!$L$6:$L$505,Assignments!$B$6:$B$505,$B8,Assignments!$D$6:$D$505,Settings!$B$9)=0),0,N(H8)) | AB8: =IF(OR($B8="",SUMIFS(Assignments!$L$6:$L$505,Assignments!$B$6:$B$505,$B8,Assignments!$D$6:$D$505,Settings!$B$10)=0),0,N(I8)) | AC8: =IF(OR($B8="",SUMIFS(Assignments!$L$6:$L$505,Assignments!$B$6:$B$505,$B8,Assignments!$D$6:$D$505,Settings!$B$11)=0),0,N(J8)) | AD8: =IF(N8="","",IFERROR(INDEX(Settings!$F$6:$F$17,MATCH(N8,Settings!$E$6:$E$17,0)),"")) | AE8: =IF(OR(B8="",AD8=""),0,AD8) | AF8: =IF(OR(B8="",AD8=""),0,N(D8))
B9: Intro to Psychology | C9: Dr. Walsh | D9: 3 | F9: 0.3 | G9: 0.2 | H9: 0.2 | I9: 0.3 | K9: 0.9 | L9: =IF(B9="","",SUM(E9:J9)) | M9: =IF(OR(B9="",SUM(X9:AC9)=0),"",SUMPRODUCT(E9:J9,R9:W9)/SUM(X9:AC9)) | N9: =IF(M9="","",INDEX(Settings!$E$6:$E$17,MATCH(M9+0.0000001,Settings!$D$6:$D$17,1))) | O9: =IF(OR(M9="",N(I9)=0,AB9>0,N(K9)=0),"",IF((N(K9)-M9*(1-N(I9)))/N(I9)<=0,"Any score",IF((N(K9)-M9*(1-N(I9)))/N(I9)>1,"Above 100%",(N(K9)-M9*(1-N(I9)))/N(I9)))) | P9: =IF(B9="","",COUNTIFS(Assignments!$B$6:$B$505,B9,Assignments!$M$6:$M$505,">="&TODAY(),Assignments!$M$6:$M$505,"<"&(TODAY()+8))) | R9: =IF(OR($B9="",SUMIFS(Assignments!$L$6:$L$505,Assignments!$B$6:$B$505,$B9,Assignments!$D$6:$D$505,Settings!$B$6)=0),0,SUMIFS(Assignments!$G$6:$G$505,Assignments!$B$6:$B$505,$B9,Assignments!$D$6:$D$505,Settings!$B$6)/SUMIFS(Assignments!$L$6:$L$505,Assignments!$B$6:$B$505,$B9,Assignments!$D$6:$D$505,Settings!$B$6)) | S9: =IF(OR($B9="",SUMIFS(Assignments!$L$6:$L$505,Assignments!$B$6:$B$505,$B9,Assignments!$D$6:$D$505,Settings!$B$7)=0),0,SUMIFS(Assignments!$G$6:$G$505,Assignments!$B$6:$B$505,$B9,Assignments!$D$6:$D$505,Settings!$B$7)/SUMIFS(Assignments!$L$6:$L$505,Assignments!$B$6:$B$505,$B9,Assignments!$D$6:$D$505,Settings!$B$7)) | T9: =IF(OR($B9="",SUMIFS(Assignments!$L$6:$L$505,Assignments!$B$6:$B$505,$B9,Assignments!$D$6:$D$505,Settings!$B$8)=0),0,SUMIFS(Assignments!$G$6:$G$505,Assignments!$B$6:$B$505,$B9,Assignments!$D$6:$D$505,Settings!$B$8)/SUMIFS(Assignments!$L$6:$L$505,Assignments!$B$6:$B$505,$B9,Assignments!$D$6:$D$505,Settings!$B$8)) | U9: =IF(OR($B9="",SUMIFS(Assignments!$L$6:$L$505,Assignments!$B$6:$B$505,$B9,Assignments!$D$6:$D$505,Settings!$B$9)=0),0,SUMIFS(Assignments!$G$6:$G$505,Assignments!$B$6:$B$505,$B9,Assignments!$D$6:$D$505,Settings!$B$9)/SUMIFS(Assignments!$L$6:$L$505,Assignments!$B$6:$B$505,$B9,Assignments!$D$6:$D$505,Settings!$B$9)) | V9: =IF(OR($B9="",SUMIFS(Assignments!$L$6:$L$505,Assignments!$B$6:$B$505,$B9,Assignments!$D$6:$D$505,Settings!$B$10)=0),0,SUMIFS(Assignments!$G$6:$G$505,Assignments!$B$6:$B$505,$B9,Assignments!$D$6:$D$505,Settings!$B$10)/SUMIFS(Assignments!$L$6:$L$505,Assignments!$B$6:$B$505,$B9,Assignments!$D$6:$D$505,Settings!$B$10)) | W9: =IF(OR($B9="",SUMIFS(Assignments!$L$6:$L$505,Assignments!$B$6:$B$505,$B9,Assignments!$D$6:$D$505,Settings!$B$11)=0),0,SUMIFS(Assignments!$G$6:$G$505,Assignments!$B$6:$B$505,$B9,Assignments!$D$6:$D$505,Settings!$B$11)/SUMIFS(Assignments!$L$6:$L$505,Assignments!$B$6:$B$505,$B9,Assignments!$D$6:$D$505,Settings!$B$11)) | X9: =IF(OR($B9="",SUMIFS(Assignments!$L$6:$L$505,Assignments!$B$6:$B$505,$B9,Assignments!$D$6:$D$505,Settings!$B$6)=0),0,N(E9)) | Y9: =IF(OR($B9="",SUMIFS(Assignments!$L$6:$L$505,Assignments!$B$6:$B$505,$B9,Assignments!$D$6:$D$505,Settings!$B$7)=0),0,N(F9)) | Z9: =IF(OR($B9="",SUMIFS(Assignments!$L$6:$L$505,Assignments!$B$6:$B$505,$B9,Assignments!$D$6:$D$505,Settings!$B$8)=0),0,N(G9)) | AA9: =IF(OR($B9="",SUMIFS(Assignments!$L$6:$L$505,Assignments!$B$6:$B$505,$B9,Assignments!$D$6:$D$505,Settings!$B$9)=0),0,N(H9)) | AB9: =IF(OR($B9="",SUMIFS(Assignments!$L$6:$L$505,Assignments!$B$6:$B$505,$B9,Assignments!$D$6:$D$505,Settings!$B$10)=0),0,N(I9)) | AC9: =IF(OR($B9="",SUMIFS(Assignments!$L$6:$L$505,Assignments!$B$6:$B$505,$B9,Assignments!$D$6:$D$505,Settings!$B$11)=0),0,N(J9)) | AD9: =IF(N9="","",IFERROR(INDEX(Settings!$F$6:$F$17,MATCH(N9,Settings!$E$6:$E$17,0)),"")) | AE9: =IF(OR(B9="",AD9=""),0,AD9) | AF9: =IF(OR(B9="",AD9=""),0,N(D9))
B10: Spanish I | C10: Sra. Molina | D10: 3 | E10: 0.2 | F10: 0.2 | H10: 0.15 | I10: 0.25 | J10: 0.2 | K10: 0.9 | L10: =IF(B10="","",SUM(E10:J10)) | M10: =IF(OR(B10="",SUM(X10:AC10)=0),"",SUMPRODUCT(E10:J10,R10:W10)/SUM(X10:AC10)) | N10: =IF(M10="","",INDEX(Settings!$E$6:$E$17,MATCH(M10+0.0000001,Settings!$D$6:$D$17,1))) | O10: =IF(OR(M10="",N(I10)=0,AB10>0,N(K10)=0),"",IF((N(K10)-M10*(1-N(I10)))/N(I10)<=0,"Any score",IF((N(K10)-M10*(1-N(I10)))/N(I10)>1,"Above 100%",(N(K10)-M10*(1-N(I10)))/N(I10)))) | P10: =IF(B10="","",COUNTIFS(Assignments!$B$6:$B$505,B10,Assignments!$M$6:$M$505,">="&TODAY(),Assignments!$M$6:$M$505,"<"&(TODAY()+8))) | R10: =IF(OR($B10="",SUMIFS(Assignments!$L$6:$L$505,Assignments!$B$6:$B$505,$B10,Assignments!$D$6:$D$505,Settings!$B$6)=0),0,SUMIFS(Assignments!$G$6:$G$505,Assignments!$B$6:$B$505,$B10,Assignments!$D$6:$D$505,Settings!$B$6)/SUMIFS(Assignments!$L$6:$L$505,Assignments!$B$6:$B$505,$B10,Assignments!$D$6:$D$505,Settings!$B$6)) | S10: =IF(OR($B10="",SUMIFS(Assignments!$L$6:$L$505,Assignments!$B$6:$B$505,$B10,Assignments!$D$6:$D$505,Settings!$B$7)=0),0,SUMIFS(Assignments!$G$6:$G$505,Assignments!$B$6:$B$505,$B10,Assignments!$D$6:$D$505,Settings!$B$7)/SUMIFS(Assignments!$L$6:$L$505,Assignments!$B$6:$B$505,$B10,Assignments!$D$6:$D$505,Settings!$B$7)) | T10: =IF(OR($B10="",SUMIFS(Assignments!$L$6:$L$505,Assignments!$B$6:$B$505,$B10,Assignments!$D$6:$D$505,Settings!$B$8)=0),0,SUMIFS(Assignments!$G$6:$G$505,Assignments!$B$6:$B$505,$B10,Assignments!$D$6:$D$505,Settings!$B$8)/SUMIFS(Assignments!$L$6:$L$505,Assignments!$B$6:$B$505,$B10,Assignments!$D$6:$D$505,Settings!$B$8)) | U10: =IF(OR($B10="",SUMIFS(Assignments!$L$6:$L$505,Assignments!$B$6:$B$505,$B10,Assignments!$D$6:$D$505,Settings!$B$9)=0),0,SUMIFS(Assignments!$G$6:$G$505,Assignments!$B$6:$B$505,$B10,Assignments!$D$6:$D$505,Settings!$B$9)/SUMIFS(Assignments!$L$6:$L$505,Assignments!$B$6:$B$505,$B10,Assignments!$D$6:$D$505,Settings!$B$9)) | V10: =IF(OR($B10="",SUMIFS(Assignments!$L$6:$L$505,Assignments!$B$6:$B$505,$B10,Assignments!$D$6:$D$505,Settings!$B$10)=0),0,SUMIFS(Assignments!$G$6:$G$505,Assignments!$B$6:$B$505,$B10,Assignments!$D$6:$D$505,Settings!$B$10)/SUMIFS(Assignments!$L$6:$L$505,Assignments!$B$6:$B$505,$B10,Assignments!$D$6:$D$505,Settings!$B$10)) | W10: =IF(OR($B10="",SUMIFS(Assignments!$L$6:$L$505,Assignments!$B$6:$B$505,$B10,Assignments!$D$6:$D$505,Settings!$B$11)=0),0,SUMIFS(Assignments!$G$6:$G$505,Assignments!$B$6:$B$505,$B10,Assignments!$D$6:$D$505,Settings!$B$11)/SUMIFS(Assignments!$L$6:$L$505,Assignments!$B$6:$B$505,$B10,Assignments!$D$6:$D$505,Settings!$B$11)) | X10: =IF(OR($B10="",SUMIFS(Assignments!$L$6:$L$505,Assignments!$B$6:$B$505,$B10,Assignments!$D$6:$D$505,Settings!$B$6)=0),0,N(E10)) | Y10: =IF(OR($B10="",SUMIFS(Assignments!$L$6:$L$505,Assignments!$B$6:$B$505,$B10,Assignments!$D$6:$D$505,Settings!$B$7)=0),0,N(F10)) | Z10: =IF(OR($B10="",SUMIFS(Assignments!$L$6:$L$505,Assignments!$B$6:$B$505,$B10,Assignments!$D$6:$D$505,Settings!$B$8)=0),0,N(G10)) | AA10: =IF(OR($B10="",SUMIFS(Assignments!$L$6:$L$505,Assignments!$B$6:$B$505,$B10,Assignments!$D$6:$D$505,Settings!$B$9)=0),0,N(H10)) | AB10: =IF(OR($B10="",SUMIFS(Assignments!$L$6:$L$505,Assignments!$B$6:$B$505,$B10,Assignments!$D$6:$D$505,Settings!$B$10)=0),0,N(I10)) | AC10: =IF(OR($B10="",SUMIFS(Assignments!$L$6:$L$505,Assignments!$B$6:$B$505,$B10,Assignments!$D$6:$D$505,Settings!$B$11)=0),0,N(J10)) | AD10: =IF(N10="","",IFERROR(INDEX(Settings!$F$6:$F$17,MATCH(N10,Settings!$E$6:$E$17,0)),"")) | AE10: =IF(OR(B10="",AD10=""),0,AD10) | AF10: =IF(OR(B10="",AD10=""),0,N(D10))
L11: =IF(B11="","",SUM(E11:J11)) | M11: =IF(OR(B11="",SUM(X11:AC11)=0),"",SUMPRODUCT(E11:J11,R11:W11)/SUM(X11:AC11)) | N11: =IF(M11="","",INDEX(Settings!$E$6:$E$17,MATCH(M11+0.0000001,Settings!$D$6:$D$17,1))) | O11: =IF(OR(M11="",N(I11)=0,AB11>0,N(K11)=0),"",IF((N(K11)-M11*(1-N(I11)))/N(I11)<=0,"Any score",IF((N(K11)-M11*(1-N(I11)))/N(I11)>1,"Above 100%",(N(K11)-M11*(1-N(I11)))/N(I11)))) | P11: =IF(B11="","",COUNTIFS(Assignments!$B$6:$B$505,B11,Assignments!$M$6:$M$505,">="&TODAY(),Assignments!$M$6:$M$505,"<"&(TODAY()+8))) | R11: =IF(OR($B11="",SUMIFS(Assignments!$L$6:$L$505,Assignments!$B$6:$B$505,$B11,Assignments!$D$6:$D$505,Settings!$B$6)=0),0,SUMIFS(Assignments!$G$6:$G$505,Assignments!$B$6:$B$505,$B11,Assignments!$D$6:$D$505,Settings!$B$6)/SUMIFS(Assignments!$L$6:$L$505,Assignments!$B$6:$B$505,$B11,Assignments!$D$6:$D$505,Settings!$B$6)) | S11: =IF(OR($B11="",SUMIFS(Assignments!$L$6:$L$505,Assignments!$B$6:$B$505,$B11,Assignments!$D$6:$D$505,Settings!$B$7)=0),0,SUMIFS(Assignments!$G$6:$G$505,Assignments!$B$6:$B$505,$B11,Assignments!$D$6:$D$505,Settings!$B$7)/SUMIFS(Assignments!$L$6:$L$505,Assignments!$B$6:$B$505,$B11,Assignments!$D$6:$D$505,Settings!$B$7)) | T11: =IF(OR($B11="",SUMIFS(Assignments!$L$6:$L$505,Assignments!$B$6:$B$505,$B11,Assignments!$D$6:$D$505,Settings!$B$8)=0),0,SUMIFS(Assignments!$G$6:$G$505,Assignments!$B$6:$B$505,$B11,Assignments!$D$6:$D$505,Settings!$B$8)/SUMIFS(Assignments!$L$6:$L$505,Assignments!$B$6:$B$505,$B11,Assignments!$D$6:$D$505,Settings!$B$8)) | U11: =IF(OR($B11="",SUMIFS(Assignments!$L$6:$L$505,Assignments!$B$6:$B$505,$B11,Assignments!$D$6:$D$505,Settings!$B$9)=0),0,SUMIFS(Assignments!$G$6:$G$505,Assignments!$B$6:$B$505,$B11,Assignments!$D$6:$D$505,Settings!$B$9)/SUMIFS(Assignments!$L$6:$L$505,Assignments!$B$6:$B$505,$B11,Assignments!$D$6:$D$505,Settings!$B$9)) | V11: =IF(OR($B11="",SUMIFS(Assignments!$L$6:$L$505,Assignments!$B$6:$B$505,$B11,Assignments!$D$6:$D$505,Settings!$B$10)=0),0,SUMIFS(Assignments!$G$6:$G$505,Assignments!$B$6:$B$505,$B11,Assignments!$D$6:$D$505,Settings!$B$10)/SUMIFS(Assignments!$L$6:$L$505,Assignments!$B$6:$B$505,$B11,Assignments!$D$6:$D$505,Settings!$B$10)) | W11: =IF(OR($B11="",SUMIFS(Assignments!$L$6:$L$505,Assignments!$B$6:$B$505,$B11,Assignments!$D$6:$D$505,Settings!$B$11)=0),0,SUMIFS(Assignments!$G$6:$G$505,Assignments!$B$6:$B$505,$B11,Assignments!$D$6:$D$505,Settings!$B$11)/SUMIFS(Assignments!$L$6:$L$505,Assignments!$B$6:$B$505,$B11,Assignments!$D$6:$D$505,Settings!$B$11)) | X11: =IF(OR($B11="",SUMIFS(Assignments!$L$6:$L$505,Assignments!$B$6:$B$505,$B11,Assignments!$D$6:$D$505,Settings!$B$6)=0),0,N(E11)) | Y11: =IF(OR($B11="",SUMIFS(Assignments!$L$6:$L$505,Assignments!$B$6:$B$505,$B11,Assignments!$D$6:$D$505,Settings!$B$7)=0),0,N(F11)) | Z11: =IF(OR($B11="",SUMIFS(Assignments!$L$6:$L$505,Assignments!$B$6:$B$505,$B11,Assignments!$D$6:$D$505,Settings!$B$8)=0),0,N(G11)) | AA11: =IF(OR($B11="",SUMIFS(Assignments!$L$6:$L$505,Assignments!$B$6:$B$505,$B11,Assignments!$D$6:$D$505,Settings!$B$9)=0),0,N(H11)) | AB11: =IF(OR($B11="",SUMIFS(Assignments!$L$6:$L$505,Assignments!$B$6:$B$505,$B11,Assignments!$D$6:$D$505,Settings!$B$10)=0),0,N(I11)) | AC11: =IF(OR($B11="",SUMIFS(Assignments!$L$6:$L$505,Assignments!$B$6:$B$505,$B11,Assignments!$D$6:$D$505,Settings!$B$11)=0),0,N(J11)) | AD11: =IF(N11="","",IFERROR(INDEX(Settings!$F$6:$F$17,MATCH(N11,Settings!$E$6:$E$17,0)),"")) | AE11: =IF(OR(B11="",AD11=""),0,AD11) | AF11: =IF(OR(B11="",AD11=""),0,N(D11))
L12: =IF(B12="","",SUM(E12:J12)) | M12: =IF(OR(B12="",SUM(X12:AC12)=0),"",SUMPRODUCT(E12:J12,R12:W12)/SUM(X12:AC12)) | N12: =IF(M12="","",INDEX(Settings!$E$6:$E$17,MATCH(M12+0.0000001,Settings!$D$6:$D$17,1))) | O12: =IF(OR(M12="",N(I12)=0,AB12>0,N(K12)=0),"",IF((N(K12)-M12*(1-N(I12)))/N(I12)<=0,"Any score",IF((N(K12)-M12*(1-N(I12)))/N(I12)>1,"Above 100%",(N(K12)-M12*(1-N(I12)))/N(I12)))) | P12: =IF(B12="","",COUNTIFS(Assignments!$B$6:$B$505,B12,Assignments!$M$6:$M$505,">="&TODAY(),Assignments!$M$6:$M$505,"<"&(TODAY()+8))) | R12: =IF(OR($B12="",SUMIFS(Assignments!$L$6:$L$505,Assignments!$B$6:$B$505,$B12,Assignments!$D$6:$D$505,Settings!$B$6)=0),0,SUMIFS(Assignments!$G$6:$G$505,Assignments!$B$6:$B$505,$B12,Assignments!$D$6:$D$505,Settings!$B$6)/SUMIFS(Assignments!$L$6:$L$505,Assignments!$B$6:$B$505,$B12,Assignments!$D$6:$D$505,Settings!$B$6)) | S12: =IF(OR($B12="",SUMIFS(Assignments!$L$6:$L$505,Assignments!$B$6:$B$505,$B12,Assignments!$D$6:$D$505,Settings!$B$7)=0),0,SUMIFS(Assignments!$G$6:$G$505,Assignments!$B$6:$B$505,$B12,Assignments!$D$6:$D$505,Settings!$B$7)/SUMIFS(Assignments!$L$6:$L$505,Assignments!$B$6:$B$505,$B12,Assignments!$D$6:$D$505,Settings!$B$7)) | T12: =IF(OR($B12="",SUMIFS(Assignments!$L$6:$L$505,Assignments!$B$6:$B$505,$B12,Assignments!$D$6:$D$505,Settings!$B$8)=0),0,SUMIFS(Assignments!$G$6:$G$505,Assignments!$B$6:$B$505,$B12,Assignments!$D$6:$D$505,Settings!$B$8)/SUMIFS(Assignments!$L$6:$L$505,Assignments!$B$6:$B$505,$B12,Assignments!$D$6:$D$505,Settings!$B$8)) | U12: =IF(OR($B12="",SUMIFS(Assignments!$L$6:$L$505,Assignments!$B$6:$B$505,$B12,Assignments!$D$6:$D$505,Settings!$B$9)=0),0,SUMIFS(Assignments!$G$6:$G$505,Assignments!$B$6:$B$505,$B12,Assignments!$D$6:$D$505,Settings!$B$9)/SUMIFS(Assignments!$L$6:$L$505,Assignments!$B$6:$B$505,$B12,Assignments!$D$6:$D$505,Settings!$B$9)) | V12: =IF(OR($B12="",SUMIFS(Assignments!$L$6:$L$505,Assignments!$B$6:$B$505,$B12,Assignments!$D$6:$D$505,Settings!$B$10)=0),0,SUMIFS(Assignments!$G$6:$G$505,Assignments!$B$6:$B$505,$B12,Assignments!$D$6:$D$505,Settings!$B$10)/SUMIFS(Assignments!$L$6:$L$505,Assignments!$B$6:$B$505,$B12,Assignments!$D$6:$D$505,Settings!$B$10)) | W12: =IF(OR($B12="",SUMIFS(Assignments!$L$6:$L$505,Assignments!$B$6:$B$505,$B12,Assignments!$D$6:$D$505,Settings!$B$11)=0),0,SUMIFS(Assignments!$G$6:$G$505,Assignments!$B$6:$B$505,$B12,Assignments!$D$6:$D$505,Settings!$B$11)/SUMIFS(Assignments!$L$6:$L$505,Assignments!$B$6:$B$505,$B12,Assignments!$D$6:$D$505,Settings!$B$11)) | X12: =IF(OR($B12="",SUMIFS(Assignments!$L$6:$L$505,Assignments!$B$6:$B$505,$B12,Assignments!$D$6:$D$505,Settings!$B$6)=0),0,N(E12)) | Y12: =IF(OR($B12="",SUMIFS(Assignments!$L$6:$L$505,Assignments!$B$6:$B$505,$B12,Assignments!$D$6:$D$505,Settings!$B$7)=0),0,N(F12)) | Z12: =IF(OR($B12="",SUMIFS(Assignments!$L$6:$L$505,Assignments!$B$6:$B$505,$B12,Assignments!$D$6:$D$505,Settings!$B$8)=0),0,N(G12)) | AA12: =IF(OR($B12="",SUMIFS(Assignments!$L$6:$L$505,Assignments!$B$6:$B$505,$B12,Assignments!$D$6:$D$505,Settings!$B$9)=0),0,N(H12)) | AB12: =IF(OR($B12="",SUMIFS(Assignments!$L$6:$L$505,Assignments!$B$6:$B$505,$B12,Assignments!$D$6:$D$505,Settings!$B$10)=0),0,N(I12)) | AC12: =IF(OR($B12="",SUMIFS(Assignments!$L$6:$L$505,Assignments!$B$6:$B$505,$B12,Assignments!$D$6:$D$505,Settings!$B$11)=0),0,N(J12)) | AD12: =IF(N12="","",IFERROR(INDEX(Settings!$F$6:$F$17,MATCH(N12,Settings!$E$6:$E$17,0)),"")) | AE12: =IF(OR(B12="",AD12=""),0,AD12) | AF12: =IF(OR(B12="",AD12=""),0,N(D12))
L13: =IF(B13="","",SUM(E13:J13)) | M13: =IF(OR(B13="",SUM(X13:AC13)=0),"",SUMPRODUCT(E13:J13,R13:W13)/SUM(X13:AC13)) | N13: =IF(M13="","",INDEX(Settings!$E$6:$E$17,MATCH(M13+0.0000001,Settings!$D$6:$D$17,1))) | O13: =IF(OR(M13="",N(I13)=0,AB13>0,N(K13)=0),"",IF((N(K13)-M13*(1-N(I13)))/N(I13)<=0,"Any score",IF((N(K13)-M13*(1-N(I13)))/N(I13)>1,"Above 100%",(N(K13)-M13*(1-N(I13)))/N(I13)))) | P13: =IF(B13="","",COUNTIFS(Assignments!$B$6:$B$505,B13,Assignments!$M$6:$M$505,">="&TODAY(),Assignments!$M$6:$M$505,"<"&(TODAY()+8))) | R13: =IF(OR($B13="",SUMIFS(Assignments!$L$6:$L$505,Assignments!$B$6:$B$505,$B13,Assignments!$D$6:$D$505,Settings!$B$6)=0),0,SUMIFS(Assignments!$G$6:$G$505,Assignments!$B$6:$B$505,$B13,Assignments!$D$6:$D$505,Settings!$B$6)/SUMIFS(Assignments!$L$6:$L$505,Assignments!$B$6:$B$505,$B13,Assignments!$D$6:$D$505,Settings!$B$6)) | S13: =IF(OR($B13="",SUMIFS(Assignments!$L$6:$L$505,Assignments!$B$6:$B$505,$B13,Assignments!$D$6:$D$505,Settings!$B$7)=0),0,SUMIFS(Assignments!$G$6:$G$505,Assignments!$B$6:$B$505,$B13,Assignments!$D$6:$D$505,Settings!$B$7)/SUMIFS(Assignments!$L$6:$L$505,Assignments!$B$6:$B$505,$B13,Assignments!$D$6:$D$505,Settings!$B$7)) | T13: =IF(OR($B13="",SUMIFS(Assignments!$L$6:$L$505,Assignments!$B$6:$B$505,$B13,Assignments!$D$6:$D$505,Settings!$B$8)=0),0,SUMIFS(Assignments!$G$6:$G$505,Assignments!$B$6:$B$505,$B13,Assignments!$D$6:$D$505,Settings!$B$8)/SUMIFS(Assignments!$L$6:$L$505,Assignments!$B$6:$B$505,$B13,Assignments!$D$6:$D$505,Settings!$B$8)) | U13: =IF(OR($B13="",SUMIFS(Assignments!$L$6:$L$505,Assignments!$B$6:$B$505,$B13,Assignments!$D$6:$D$505,Settings!$B$9)=0),0,SUMIFS(Assignments!$G$6:$G$505,Assignments!$B$6:$B$505,$B13,Assignments!$D$6:$D$505,Settings!$B$9)/SUMIFS(Assignments!$L$6:$L$505,Assignments!$B$6:$B$505,$B13,Assignments!$D$6:$D$505,Settings!$B$9)) | V13: =IF(OR($B13="",SUMIFS(Assignments!$L$6:$L$505,Assignments!$B$6:$B$505,$B13,Assignments!$D$6:$D$505,Settings!$B$10)=0),0,SUMIFS(Assignments!$G$6:$G$505,Assignments!$B$6:$B$505,$B13,Assignments!$D$6:$D$505,Settings!$B$10)/SUMIFS(Assignments!$L$6:$L$505,Assignments!$B$6:$B$505,$B13,Assignments!$D$6:$D$505,Settings!$B$10)) | W13: =IF(OR($B13="",SUMIFS(Assignments!$L$6:$L$505,Assignments!$B$6:$B$505,$B13,Assignments!$D$6:$D$505,Settings!$B$11)=0),0,SUMIFS(Assignments!$G$6:$G$505,Assignments!$B$6:$B$505,$B13,Assignments!$D$6:$D$505,Settings!$B$11)/SUMIFS(Assignments!$L$6:$L$505,Assignments!$B$6:$B$505,$B13,Assignments!$D$6:$D$505,Settings!$B$11)) | X13: =IF(OR($B13="",SUMIFS(Assignments!$L$6:$L$505,Assignments!$B$6:$B$505,$B13,Assignments!$D$6:$D$505,Settings!$B$6)=0),0,N(E13)) | Y13: =IF(OR($B13="",SUMIFS(Assignments!$L$6:$L$505,Assignments!$B$6:$B$505,$B13,Assignments!$D$6:$D$505,Settings!$B$7)=0),0,N(F13)) | Z13: =IF(OR($B13="",SUMIFS(Assignments!$L$6:$L$505,Assignments!$B$6:$B$505,$B13,Assignments!$D$6:$D$505,Settings!$B$8)=0),0,N(G13)) | AA13: =IF(OR($B13="",SUMIFS(Assignments!$L$6:$L$505,Assignments!$B$6:$B$505,$B13,Assignments!$D$6:$D$505,Settings!$B$9)=0),0,N(H13)) | AB13: =IF(OR($B13="",SUMIFS(Assignments!$L$6:$L$505,Assignments!$B$6:$B$505,$B13,Assignments!$D$6:$D$505,Settings!$B$10)=0),0,N(I13)) | AC13: =IF(OR($B13="",SUMIFS(Assignments!$L$6:$L$505,Assignments!$B$6:$B$505,$B13,Assignments!$D$6:$D$505,Settings!$B$11)=0),0,N(J13)) | AD13: =IF(N13="","",IFERROR(INDEX(Settings!$F$6:$F$17,MATCH(N13,Settings!$E$6:$E$17,0)),"")) | AE13: =IF(OR(B13="",AD13=""),0,AD13) | AF13: =IF(OR(B13="",AD13=""),0,N(D13))
L14: =IF(B14="","",SUM(E14:J14)) | M14: =IF(OR(B14="",SUM(X14:AC14)=0),"",SUMPRODUCT(E14:J14,R14:W14)/SUM(X14:AC14)) | N14: =IF(M14="","",INDEX(Settings!$E$6:$E$17,MATCH(M14+0.0000001,Settings!$D$6:$D$17,1))) | O14: =IF(OR(M14="",N(I14)=0,AB14>0,N(K14)=0),"",IF((N(K14)-M14*(1-N(I14)))/N(I14)<=0,"Any score",IF((N(K14)-M14*(1-N(I14)))/N(I14)>1,"Above 100%",(N(K14)-M14*(1-N(I14)))/N(I14)))) | P14: =IF(B14="","",COUNTIFS(Assignments!$B$6:$B$505,B14,Assignments!$M$6:$M$505,">="&TODAY(),Assignments!$M$6:$M$505,"<"&(TODAY()+8))) | R14: =IF(OR($B14="",SUMIFS(Assignments!$L$6:$L$505,Assignments!$B$6:$B$505,$B14,Assignments!$D$6:$D$505,Settings!$B$6)=0),0,SUMIFS(Assignments!$G$6:$G$505,Assignments!$B$6:$B$505,$B14,Assignments!$D$6:$D$505,Settings!$B$6)/SUMIFS(Assignments!$L$6:$L$505,Assignments!$B$6:$B$505,$B14,Assignments!$D$6:$D$505,Settings!$B$6)) | S14: =IF(OR($B14="",SUMIFS(Assignments!$L$6:$L$505,Assignments!$B$6:$B$505,$B14,Assignments!$D$6:$D$505,Settings!$B$7)=0),0,SUMIFS(Assignments!$G$6:$G$505,Assignments!$B$6:$B$505,$B14,Assignments!$D$6:$D$505,Settings!$B$7)/SUMIFS(Assignments!$L$6:$L$505,Assignments!$B$6:$B$505,$B14,Assignments!$D$6:$D$505,Settings!$B$7)) | T14: =IF(OR($B14="",SUMIFS(Assignments!$L$6:$L$505,Assignments!$B$6:$B$505,$B14,Assignments!$D$6:$D$505,Settings!$B$8)=0),0,SUMIFS(Assignments!$G$6:$G$505,Assignments!$B$6:$B$505,$B14,Assignments!$D$6:$D$505,Settings!$B$8)/SUMIFS(Assignments!$L$6:$L$505,Assignments!$B$6:$B$505,$B14,Assignments!$D$6:$D$505,Settings!$B$8)) | U14: =IF(OR($B14="",SUMIFS(Assignments!$L$6:$L$505,Assignments!$B$6:$B$505,$B14,Assignments!$D$6:$D$505,Settings!$B$9)=0),0,SUMIFS(Assignments!$G$6:$G$505,Assignments!$B$6:$B$505,$B14,Assignments!$D$6:$D$505,Settings!$B$9)/SUMIFS(Assignments!$L$6:$L$505,Assignments!$B$6:$B$505,$B14,Assignments!$D$6:$D$505,Settings!$B$9)) | V14: =IF(OR($B14="",SUMIFS(Assignments!$L$6:$L$505,Assignments!$B$6:$B$505,$B14,Assignments!$D$6:$D$505,Settings!$B$10)=0),0,SUMIFS(Assignments!$G$6:$G$505,Assignments!$B$6:$B$505,$B14,Assignments!$D$6:$D$505,Settings!$B$10)/SUMIFS(Assignments!$L$6:$L$505,Assignments!$B$6:$B$505,$B14,Assignments!$D$6:$D$505,Settings!$B$10)) | W14: =IF(OR($B14="",SUMIFS(Assignments!$L$6:$L$505,Assignments!$B$6:$B$505,$B14,Assignments!$D$6:$D$505,Settings!$B$11)=0),0,SUMIFS(Assignments!$G$6:$G$505,Assignments!$B$6:$B$505,$B14,Assignments!$D$6:$D$505,Settings!$B$11)/SUMIFS(Assignments!$L$6:$L$505,Assignments!$B$6:$B$505,$B14,Assignments!$D$6:$D$505,Settings!$B$11)) | X14: =IF(OR($B14="",SUMIFS(Assignments!$L$6:$L$505,Assignments!$B$6:$B$505,$B14,Assignments!$D$6:$D$505,Settings!$B$6)=0),0,N(E14)) | Y14: =IF(OR($B14="",SUMIFS(Assignments!$L$6:$L$505,Assignments!$B$6:$B$505,$B14,Assignments!$D$6:$D$505,Settings!$B$7)=0),0,N(F14)) | Z14: =IF(OR($B14="",SUMIFS(Assignments!$L$6:$L$505,Assignments!$B$6:$B$505,$B14,Assignments!$D$6:$D$505,Settings!$B$8)=0),0,N(G14)) | AA14: =IF(OR($B14="",SUMIFS(Assignments!$L$6:$L$505,Assignments!$B$6:$B$505,$B14,Assignments!$D$6:$D$505,Settings!$B$9)=0),0,N(H14)) | AB14: =IF(OR($B14="",SUMIFS(Assignments!$L$6:$L$505,Assignments!$B$6:$B$505,$B14,Assignments!$D$6:$D$505,Settings!$B$10)=0),0,N(I14)) | AC14: =IF(OR($B14="",SUMIFS(Assignments!$L$6:$L$505,Assignments!$B$6:$B$505,$B14,Assignments!$D$6:$D$505,Settings!$B$11)=0),0,N(J14)) | AD14: =IF(N14="","",IFERROR(INDEX(Settings!$F$6:$F$17,MATCH(N14,Settings!$E$6:$E$17,0)),"")) | AE14: =IF(OR(B14="",AD14=""),0,AD14) | AF14: =IF(OR(B14="",AD14=""),0,N(D14))
