Workbook

Sheet Dashboard
B2: =IF(Settings!$C$4="","Vegetable garden",Settings!$C$4)
B3: =Settings!$C$5&": the harvest at shop prices, what the garden cost, and what to do in "&CHOOSE(MONTH(TODAY()),"January","February","March","April","May","June","July","August","September","October","November","December")&"."
B4: Harvest value | C4: Spent | D4: Value less costs | E4: Crops picked | G4: Plantings | H4: In the ground | I4: Beds to water
B5: =SUMIFS(Harvest!$H$6:$H$1505,Harvest!$J$6:$J$1505,Settings!$C$5) | C5: =SUMIFS(Costs!$E$6:$E$505,Costs!$G$6:$G$505,Settings!$C$5) | D5: =B5-C5 | E5: =COUNTIF(Crops!$O$6:$O$65,">0") | G5: =SUMIFS(Plantings!$S$6:$S$505,Plantings!$N$6:$N$505,Settings!$C$5) | H5: =SUM(Plantings!$Q$6:$Q$505) | I5: =COUNTIF(Beds!$J$6:$J$35,"Water")
B7: Harvest this year | C7: Picked | D7: Unit | E7: Value | G7: Sow now | H7: Plant out now | I7: Harvest now
B8: =IF(L8="","",INDEX(Crops!$B$1:$B$65,1000-MOD(L8,1000))) | C8: =IF(L8="","",INDEX(Crops!$O$1:$O$65,1000-MOD(L8,1000))) | D8: =IF(L8="","",IF(INDEX(Crops!$D$1:$D$65,1000-MOD(L8,1000))="","",INDEX(Crops!$D$1:$D$65,1000-MOD(L8,1000)))) | E8: =IF(L8="","",INDEX(Crops!$P$1:$P$65,1000-MOD(L8,1000))) | G8: =IF(M8="","",INDEX(Crops!$B$1:$B$65,M8)) | H8: =IF(N8="","",INDEX(Crops!$B$1:$B$65,N8)) | I8: =IF(O8="","",INDEX(Crops!$B$1:$B$65,O8)) | L8: =IFERROR(LARGE(Crops!$AA$6:$AA$65,1),"") | M8: =IFERROR(SMALL(Crops!$X$6:$X$65,1),"") | N8: =IFERROR(SMALL(Crops!$Y$6:$Y$65,1),"") | O8: =IFERROR(SMALL(Crops!$Z$6:$Z$65,1),"")
B9: =IF(L9="","",INDEX(Crops!$B$1:$B$65,1000-MOD(L9,1000))) | C9: =IF(L9="","",INDEX(Crops!$O$1:$O$65,1000-MOD(L9,1000))) | D9: =IF(L9="","",IF(INDEX(Crops!$D$1:$D$65,1000-MOD(L9,1000))="","",INDEX(Crops!$D$1:$D$65,1000-MOD(L9,1000)))) | E9: =IF(L9="","",INDEX(Crops!$P$1:$P$65,1000-MOD(L9,1000))) | G9: =IF(M9="","",INDEX(Crops!$B$1:$B$65,M9)) | H9: =IF(N9="","",INDEX(Crops!$B$1:$B$65,N9)) | I9: =IF(O9="","",INDEX(Crops!$B$1:$B$65,O9)) | L9: =IFERROR(LARGE(Crops!$AA$6:$AA$65,2),"") | M9: =IFERROR(SMALL(Crops!$X$6:$X$65,2),"") | N9: =IFERROR(SMALL(Crops!$Y$6:$Y$65,2),"") | O9: =IFERROR(SMALL(Crops!$Z$6:$Z$65,2),"")
B10: =IF(L10="","",INDEX(Crops!$B$1:$B$65,1000-MOD(L10,1000))) | C10: =IF(L10="","",INDEX(Crops!$O$1:$O$65,1000-MOD(L10,1000))) | D10: =IF(L10="","",IF(INDEX(Crops!$D$1:$D$65,1000-MOD(L10,1000))="","",INDEX(Crops!$D$1:$D$65,1000-MOD(L10,1000)))) | E10: =IF(L10="","",INDEX(Crops!$P$1:$P$65,1000-MOD(L10,1000))) | G10: =IF(M10="","",INDEX(Crops!$B$1:$B$65,M10)) | H10: =IF(N10="","",INDEX(Crops!$B$1:$B$65,N10)) | I10: =IF(O10="","",INDEX(Crops!$B$1:$B$65,O10)) | L10: =IFERROR(LARGE(Crops!$AA$6:$AA$65,3),"") | M10: =IFERROR(SMALL(Crops!$X$6:$X$65,3),"") | N10: =IFERROR(SMALL(Crops!$Y$6:$Y$65,3),"") | O10: =IFERROR(SMALL(Crops!$Z$6:$Z$65,3),"")
B11: =IF(L11="","",INDEX(Crops!$B$1:$B$65,1000-MOD(L11,1000))) | C11: =IF(L11="","",INDEX(Crops!$O$1:$O$65,1000-MOD(L11,1000))) | D11: =IF(L11="","",IF(INDEX(Crops!$D$1:$D$65,1000-MOD(L11,1000))="","",INDEX(Crops!$D$1:$D$65,1000-MOD(L11,1000)))) | E11: =IF(L11="","",INDEX(Crops!$P$1:$P$65,1000-MOD(L11,1000))) | G11: =IF(M11="","",INDEX(Crops!$B$1:$B$65,M11)) | H11: =IF(N11="","",INDEX(Crops!$B$1:$B$65,N11)) | I11: =IF(O11="","",INDEX(Crops!$B$1:$B$65,O11)) | L11: =IFERROR(LARGE(Crops!$AA$6:$AA$65,4),"") | M11: =IFERROR(SMALL(Crops!$X$6:$X$65,4),"") | N11: =IFERROR(SMALL(Crops!$Y$6:$Y$65,4),"") | O11: =IFERROR(SMALL(Crops!$Z$6:$Z$65,4),"")
B12: =IF(L12="","",INDEX(Crops!$B$1:$B$65,1000-MOD(L12,1000))) | C12: =IF(L12="","",INDEX(Crops!$O$1:$O$65,1000-MOD(L12,1000))) | D12: =IF(L12="","",IF(INDEX(Crops!$D$1:$D$65,1000-MOD(L12,1000))="","",INDEX(Crops!$D$1:$D$65,1000-MOD(L12,1000)))) | E12: =IF(L12="","",INDEX(Crops!$P$1:$P$65,1000-MOD(L12,1000))) | G12: =IF(M12="","",INDEX(Crops!$B$1:$B$65,M12)) | H12: =IF(N12="","",INDEX(Crops!$B$1:$B$65,N12)) | I12: =IF(O12="","",INDEX(Crops!$B$1:$B$65,O12)) | L12: =IFERROR(LARGE(Crops!$AA$6:$AA$65,5),"") | M12: =IFERROR(SMALL(Crops!$X$6:$X$65,5),"") | N12: =IFERROR(SMALL(Crops!$Y$6:$Y$65,5),"") | O12: =IFERROR(SMALL(Crops!$Z$6:$Z$65,5),"")
B13: =IF(L13="","",INDEX(Crops!$B$1:$B$65,1000-MOD(L13,1000))) | C13: =IF(L13="","",INDEX(Crops!$O$1:$O$65,1000-MOD(L13,1000))) | D13: =IF(L13="","",IF(INDEX(Crops!$D$1:$D$65,1000-MOD(L13,1000))="","",INDEX(Crops!$D$1:$D$65,1000-MOD(L13,1000)))) | E13: =IF(L13="","",INDEX(Crops!$P$1:$P$65,1000-MOD(L13,1000))) | G13: =IF(M13="","",INDEX(Crops!$B$1:$B$65,M13)) | H13: =IF(N13="","",INDEX(Crops!$B$1:$B$65,N13)) | I13: =IF(O13="","",INDEX(Crops!$B$1:$B$65,O13)) | L13: =IFERROR(LARGE(Crops!$AA$6:$AA$65,6),"") | M13: =IFERROR(SMALL(Crops!$X$6:$X$65,6),"") | N13: =IFERROR(SMALL(Crops!$Y$6:$Y$65,6),"") | O13: =IFERROR(SMALL(Crops!$Z$6:$Z$65,6),"")
B14: =IF(L14="","",INDEX(Crops!$B$1:$B$65,1000-MOD(L14,1000))) | C14: =IF(L14="","",INDEX(Crops!$O$1:$O$65,1000-MOD(L14,1000))) | D14: =IF(L14="","",IF(INDEX(Crops!$D$1:$D$65,1000-MOD(L14,1000))="","",INDEX(Crops!$D$1:$D$65,1000-MOD(L14,1000)))) | E14: =IF(L14="","",INDEX(Crops!$P$1:$P$65,1000-MOD(L14,1000))) | G14: =IF(M14="","",INDEX(Crops!$B$1:$B$65,M14)) | H14: =IF(N14="","",INDEX(Crops!$B$1:$B$65,N14)) | I14: =IF(O14="","",INDEX(Crops!$B$1:$B$65,O14)) | L14: =IFERROR(LARGE(Crops!$AA$6:$AA$65,7),"") | M14: =IFERROR(SMALL(Crops!$X$6:$X$65,7),"") | N14: =IFERROR(SMALL(Crops!$Y$6:$Y$65,7),"") | O14: =IFERROR(SMALL(Crops!$Z$6:$Z$65,7),"")
B15: =IF(L15="","",INDEX(Crops!$B$1:$B$65,1000-MOD(L15,1000))) | C15: =IF(L15="","",INDEX(Crops!$O$1:$O$65,1000-MOD(L15,1000))) | D15: =IF(L15="","",IF(INDEX(Crops!$D$1:$D$65,1000-MOD(L15,1000))="","",INDEX(Crops!$D$1:$D$65,1000-MOD(L15,1000)))) | E15: =IF(L15="","",INDEX(Crops!$P$1:$P$65,1000-MOD(L15,1000))) | G15: =IF(M15="","",INDEX(Crops!$B$1:$B$65,M15)) | H15: =IF(N15="","",INDEX(Crops!$B$1:$B$65,N15)) | I15: =IF(O15="","",INDEX(Crops!$B$1:$B$65,O15)) | L15: =IFERROR(LARGE(Crops!$AA$6:$AA$65,8),"") | M15: =IFERROR(SMALL(Crops!$X$6:$X$65,8),"") | N15: =IFERROR(SMALL(Crops!$Y$6:$Y$65,8),"") | O15: =IFERROR(SMALL(Crops!$Z$6:$Z$65,8),"")
B16: =IF(L16="","",INDEX(Crops!$B$1:$B$65,1000-MOD(L16,1000))) | C16: =IF(L16="","",INDEX(Crops!$O$1:$O$65,1000-MOD(L16,1000))) | D16: =IF(L16="","",IF(INDEX(Crops!$D$1:$D$65,1000-MOD(L16,1000))="","",INDEX(Crops!$D$1:$D$65,1000-MOD(L16,1000)))) | E16: =IF(L16="","",INDEX(Crops!$P$1:$P$65,1000-MOD(L16,1000))) | G16: =IF(M16="","",INDEX(Crops!$B$1:$B$65,M16)) | H16: =IF(N16="","",INDEX(Crops!$B$1:$B$65,N16)) | I16: =IF(O16="","",INDEX(Crops!$B$1:$B$65,O16)) | L16: =IFERROR(LARGE(Crops!$AA$6:$AA$65,9),"") | M16: =IFERROR(SMALL(Crops!$X$6:$X$65,9),"") | N16: =IFERROR(SMALL(Crops!$Y$6:$Y$65,9),"") | O16: =IFERROR(SMALL(Crops!$Z$6:$Z$65,9),"")
B17: =IF(L17="","",INDEX(Crops!$B$1:$B$65,1000-MOD(L17,1000))) | C17: =IF(L17="","",INDEX(Crops!$O$1:$O$65,1000-MOD(L17,1000))) | D17: =IF(L17="","",IF(INDEX(Crops!$D$1:$D$65,1000-MOD(L17,1000))="","",INDEX(Crops!$D$1:$D$65,1000-MOD(L17,1000)))) | E17: =IF(L17="","",INDEX(Crops!$P$1:$P$65,1000-MOD(L17,1000))) | G17: =IF(M17="","",INDEX(Crops!$B$1:$B$65,M17)) | H17: =IF(N17="","",INDEX(Crops!$B$1:$B$65,N17)) | I17: =IF(O17="","",INDEX(Crops!$B$1:$B$65,O17)) | L17: =IFERROR(LARGE(Crops!$AA$6:$AA$65,10),"") | M17: =IFERROR(SMALL(Crops!$X$6:$X$65,10),"") | N17: =IFERROR(SMALL(Crops!$Y$6:$Y$65,10),"") | O17: =IFERROR(SMALL(Crops!$Z$6:$Z$65,10),"")
G18: =IF(COUNT(Crops!$Z$6:$Z$65)>10,"And "&(COUNT(Crops!$Z$6:$Z$65)-10)&" more to harvest","")
B20: Bed | C20: Growing | D20: Last watered | E20: Status | G20: Month | H20: Harvest value | I20: Spent
B21: =IF(INDEX(Beds!$B$6:$B$35,1)="","",INDEX(Beds!$B$6:$B$35,1)) | C21: =IF(B21="","",INDEX(Beds!$F$6:$F$35,1)) | D21: =IF(B21="","",IF(INDEX(Beds!$H$6:$H$35,1)="","",INDEX(Beds!$H$6:$H$35,1))) | E21: =IF(B21="","",INDEX(Beds!$J$6:$J$35,1)) | G21: Jan | H21: =SUMIFS(Harvest!$H$6:$H$1505,Harvest!$K$6:$K$1505,(Settings!$C$5*100+1)) | I21: =SUMIFS(Costs!$E$6:$E$505,Costs!$H$6:$H$505,(Settings!$C$5*100+1))
B22: =IF(INDEX(Beds!$B$6:$B$35,2)="","",INDEX(Beds!$B$6:$B$35,2)) | C22: =IF(B22="","",INDEX(Beds!$F$6:$F$35,2)) | D22: =IF(B22="","",IF(INDEX(Beds!$H$6:$H$35,2)="","",INDEX(Beds!$H$6:$H$35,2))) | E22: =IF(B22="","",INDEX(Beds!$J$6:$J$35,2)) | G22: Feb | H22: =SUMIFS(Harvest!$H$6:$H$1505,Harvest!$K$6:$K$1505,(Settings!$C$5*100+2)) | I22: =SUMIFS(Costs!$E$6:$E$505,Costs!$H$6:$H$505,(Settings!$C$5*100+2))
B23: =IF(INDEX(Beds!$B$6:$B$35,3)="","",INDEX(Beds!$B$6:$B$35,3)) | C23: =IF(B23="","",INDEX(Beds!$F$6:$F$35,3)) | D23: =IF(B23="","",IF(INDEX(Beds!$H$6:$H$35,3)="","",INDEX(Beds!$H$6:$H$35,3))) | E23: =IF(B23="","",INDEX(Beds!$J$6:$J$35,3)) | G23: Mar | H23: =SUMIFS(Harvest!$H$6:$H$1505,Harvest!$K$6:$K$1505,(Settings!$C$5*100+3)) | I23: =SUMIFS(Costs!$E$6:$E$505,Costs!$H$6:$H$505,(Settings!$C$5*100+3))
B24: =IF(INDEX(Beds!$B$6:$B$35,4)="","",INDEX(Beds!$B$6:$B$35,4)) | C24: =IF(B24="","",INDEX(Beds!$F$6:$F$35,4)) | D24: =IF(B24="","",IF(INDEX(Beds!$H$6:$H$35,4)="","",INDEX(Beds!$H$6:$H$35,4))) | E24: =IF(B24="","",INDEX(Beds!$J$6:$J$35,4)) | G24: Apr | H24: =SUMIFS(Harvest!$H$6:$H$1505,Harvest!$K$6:$K$1505,(Settings!$C$5*100+4)) | I24: =SUMIFS(Costs!$E$6:$E$505,Costs!$H$6:$H$505,(Settings!$C$5*100+4))
B25: =IF(INDEX(Beds!$B$6:$B$35,5)="","",INDEX(Beds!$B$6:$B$35,5)) | C25: =IF(B25="","",INDEX(Beds!$F$6:$F$35,5)) | D25: =IF(B25="","",IF(INDEX(Beds!$H$6:$H$35,5)="","",INDEX(Beds!$H$6:$H$35,5))) | E25: =IF(B25="","",INDEX(Beds!$J$6:$J$35,5)) | G25: May | H25: =SUMIFS(Harvest!$H$6:$H$1505,Harvest!$K$6:$K$1505,(Settings!$C$5*100+5)) | I25: =SUMIFS(Costs!$E$6:$E$505,Costs!$H$6:$H$505,(Settings!$C$5*100+5))
B26: =IF(INDEX(Beds!$B$6:$B$35,6)="","",INDEX(Beds!$B$6:$B$35,6)) | C26: =IF(B26="","",INDEX(Beds!$F$6:$F$35,6)) | D26: =IF(B26="","",IF(INDEX(Beds!$H$6:$H$35,6)="","",INDEX(Beds!$H$6:$H$35,6))) | E26: =IF(B26="","",INDEX(Beds!$J$6:$J$35,6)) | G26: Jun | H26: =SUMIFS(Harvest!$H$6:$H$1505,Harvest!$K$6:$K$1505,(Settings!$C$5*100+6)) | I26: =SUMIFS(Costs!$E$6:$E$505,Costs!$H$6:$H$505,(Settings!$C$5*100+6))
B27: =IF(INDEX(Beds!$B$6:$B$35,7)="","",INDEX(Beds!$B$6:$B$35,7)) | C27: =IF(B27="","",INDEX(Beds!$F$6:$F$35,7)) | D27: =IF(B27="","",IF(INDEX(Beds!$H$6:$H$35,7)="","",INDEX(Beds!$H$6:$H$35,7))) | E27: =IF(B27="","",INDEX(Beds!$J$6:$J$35,7)) | G27: Jul | H27: =SUMIFS(Harvest!$H$6:$H$1505,Harvest!$K$6:$K$1505,(Settings!$C$5*100+7)) | I27: =SUMIFS(Costs!$E$6:$E$505,Costs!$H$6:$H$505,(Settings!$C$5*100+7))
B28: =IF(INDEX(Beds!$B$6:$B$35,8)="","",INDEX(Beds!$B$6:$B$35,8)) | C28: =IF(B28="","",INDEX(Beds!$F$6:$F$35,8)) | D28: =IF(B28="","",IF(INDEX(Beds!$H$6:$H$35,8)="","",INDEX(Beds!$H$6:$H$35,8))) | E28: =IF(B28="","",INDEX(Beds!$J$6:$J$35,8)) | G28: Aug | H28: =SUMIFS(Harvest!$H$6:$H$1505,Harvest!$K$6:$K$1505,(Settings!$C$5*100+8)) | I28: =SUMIFS(Costs!$E$6:$E$505,Costs!$H$6:$H$505,(Settings!$C$5*100+8))
G29: Sep | H29: =SUMIFS(Harvest!$H$6:$H$1505,Harvest!$K$6:$K$1505,(Settings!$C$5*100+9)) | I29: =SUMIFS(Costs!$E$6:$E$505,Costs!$H$6:$H$505,(Settings!$C$5*100+9))
G30: Oct | H30: =SUMIFS(Harvest!$H$6:$H$1505,Harvest!$K$6:$K$1505,(Settings!$C$5*100+10)) | I30: =SUMIFS(Costs!$E$6:$E$505,Costs!$H$6:$H$505,(Settings!$C$5*100+10))
G31: Nov | H31: =SUMIFS(Harvest!$H$6:$H$1505,Harvest!$K$6:$K$1505,(Settings!$C$5*100+11)) | I31: =SUMIFS(Costs!$E$6:$E$505,Costs!$H$6:$H$505,(Settings!$C$5*100+11))
G32: Dec | H32: =SUMIFS(Harvest!$H$6:$H$1505,Harvest!$K$6:$K$1505,(Settings!$C$5*100+12)) | I32: =SUMIFS(Costs!$E$6:$E$505,Costs!$H$6:$H$505,(Settings!$C$5*100+12))

Sheet Plantings
B2: Plantings
B3: Each time you sow or plant something, with the bed. A date under Cleared once it is finished.
B5: Date | C5: Crop | D5: Bed | E5: How | F5: How many | G5: Cleared | H5: Note | I5: Ready about | J5: Status | K5: Days | L5: Check | M5: Rotation
B6: 45736 | C6: Potatoes | D6: Bed 2 | E6: Sown outside | F6: 20 | G6: 45889 | H6: Seed potatoes | I6: =IF(NOT(AND(C6<>"",ISNUMBER(B6))),"",IF(N(IFERROR(INDEX(Crops!$F$6:$F$65,MATCH(C6,Crops!$B$6:$B$65,0)),0))>0,INT(B6)+N(IFERROR(INDEX(Crops!$F$6:$F$65,MATCH(C6,Crops!$B$6:$B$65,0)),0)),"")) | J6: =IF(NOT(AND(C6<>"",ISNUMBER(B6))),"",IF(ISNUMBER(G6),"Done",IF(INT(B6)>TODAY(),"Planned",IF(COUNTIFS(Harvest!$C$6:$C$1505,C6,Harvest!$D$6:$D$1505,D6&"",Harvest!$L$6:$L$1505,">="&INT(B6))>0,"Picking","Growing")))) | K6: =IF(OR(NOT(AND(C6<>"",ISNUMBER(B6))),J6="Planned"),"",IF(ISNUMBER(G6),INT(G6),TODAY())-INT(B6)) | L6: =IF(AND(B6="",C6="",D6=""),"",IF(NOT(ISNUMBER(B6)),"Needs a date",IF(C6="","Needs a crop",IF(COUNTIF(Crops!$B$6:$B$65,C6)=0,"Not on Crops",IF(AND(D6<>"",COUNTIF(Beds!$B$6:$B$35,D6)=0),"Not on Beds",IF(AND(ISNUMBER(G6),G6<B6),"Cleared before it was planted","")))))) | M6: =IF(OR(L6<>"",D6="",O6=""),"",IF(COUNTIFS(Plantings!$D$6:$D$505,D6,Plantings!$O$6:$O$505,O6,Plantings!$N$6:$N$505,N6-1)>0,"Same family here last year","")) | N6: =IF(ISNUMBER(B6),YEAR(B6),"") | O6: =IF(C6="","",IFERROR(INDEX(Crops!$C$6:$C$65,MATCH(C6,Crops!$B$6:$B$65,0))&"","")) | P6: =IF(ISNUMBER(B6),INT(B6),0) | Q6: =IF(AND(L6="",OR(J6="Growing",J6="Picking")),1,0) | R6: =IF(AND(Q6=1,D6<>""),P6*1000+ROW(),0) | S6: =IF(AND(AND(C6<>"",ISNUMBER(B6)),L6=""),1,0)
B7: 45749 | C7: Onions | D7: Bed 4 | E7: Sown outside | F7: 60 | G7: 45897 | H7: Sets | I7: =IF(NOT(AND(C7<>"",ISNUMBER(B7))),"",IF(N(IFERROR(INDEX(Crops!$F$6:$F$65,MATCH(C7,Crops!$B$6:$B$65,0)),0))>0,INT(B7)+N(IFERROR(INDEX(Crops!$F$6:$F$65,MATCH(C7,Crops!$B$6:$B$65,0)),0)),"")) | J7: =IF(NOT(AND(C7<>"",ISNUMBER(B7))),"",IF(ISNUMBER(G7),"Done",IF(INT(B7)>TODAY(),"Planned",IF(COUNTIFS(Harvest!$C$6:$C$1505,C7,Harvest!$D$6:$D$1505,D7&"",Harvest!$L$6:$L$1505,">="&INT(B7))>0,"Picking","Growing")))) | K7: =IF(OR(NOT(AND(C7<>"",ISNUMBER(B7))),J7="Planned"),"",IF(ISNUMBER(G7),INT(G7),TODAY())-INT(B7)) | L7: =IF(AND(B7="",C7="",D7=""),"",IF(NOT(ISNUMBER(B7)),"Needs a date",IF(C7="","Needs a crop",IF(COUNTIF(Crops!$B$6:$B$65,C7)=0,"Not on Crops",IF(AND(D7<>"",COUNTIF(Beds!$B$6:$B$35,D7)=0),"Not on Beds",IF(AND(ISNUMBER(G7),G7<B7),"Cleared before it was planted","")))))) | M7: =IF(OR(L7<>"",D7="",O7=""),"",IF(COUNTIFS(Plantings!$D$6:$D$505,D7,Plantings!$O$6:$O$505,O7,Plantings!$N$6:$N$505,N7-1)>0,"Same family here last year","")) | N7: =IF(ISNUMBER(B7),YEAR(B7),"") | O7: =IF(C7="","",IFERROR(INDEX(Crops!$C$6:$C$65,MATCH(C7,Crops!$B$6:$B$65,0))&"","")) | P7: =IF(ISNUMBER(B7),INT(B7),0) | Q7: =IF(AND(L7="",OR(J7="Growing",J7="Picking")),1,0) | R7: =IF(AND(Q7=1,D7<>""),P7*1000+ROW(),0) | S7: =IF(AND(AND(C7<>"",ISNUMBER(B7)),L7=""),1,0)
B8: 45772 | C8: Carrots | D8: Bed 3 | E8: Sown outside | F8: 1 | G8: 45971 | H8: One row | I8: =IF(NOT(AND(C8<>"",ISNUMBER(B8))),"",IF(N(IFERROR(INDEX(Crops!$F$6:$F$65,MATCH(C8,Crops!$B$6:$B$65,0)),0))>0,INT(B8)+N(IFERROR(INDEX(Crops!$F$6:$F$65,MATCH(C8,Crops!$B$6:$B$65,0)),0)),"")) | J8: =IF(NOT(AND(C8<>"",ISNUMBER(B8))),"",IF(ISNUMBER(G8),"Done",IF(INT(B8)>TODAY(),"Planned",IF(COUNTIFS(Harvest!$C$6:$C$1505,C8,Harvest!$D$6:$D$1505,D8&"",Harvest!$L$6:$L$1505,">="&INT(B8))>0,"Picking","Growing")))) | K8: =IF(OR(NOT(AND(C8<>"",ISNUMBER(B8))),J8="Planned"),"",IF(ISNUMBER(G8),INT(G8),TODAY())-INT(B8)) | L8: =IF(AND(B8="",C8="",D8=""),"",IF(NOT(ISNUMBER(B8)),"Needs a date",IF(C8="","Needs a crop",IF(COUNTIF(Crops!$B$6:$B$65,C8)=0,"Not on Crops",IF(AND(D8<>"",COUNTIF(Beds!$B$6:$B$35,D8)=0),"Not on Beds",IF(AND(ISNUMBER(G8),G8<B8),"Cleared before it was planted","")))))) | M8: =IF(OR(L8<>"",D8="",O8=""),"",IF(COUNTIFS(Plantings!$D$6:$D$505,D8,Plantings!$O$6:$O$505,O8,Plantings!$N$6:$N$505,N8-1)>0,"Same family here last year","")) | N8: =IF(ISNUMBER(B8),YEAR(B8),"") | O8: =IF(C8="","",IFERROR(INDEX(Crops!$C$6:$C$65,MATCH(C8,Crops!$B$6:$B$65,0))&"","")) | P8: =IF(ISNUMBER(B8),INT(B8),0) | Q8: =IF(AND(L8="",OR(J8="Growing",J8="Picking")),1,0) | R8: =IF(AND(Q8=1,D8<>""),P8*1000+ROW(),0) | S8: =IF(AND(AND(C8<>"",ISNUMBER(B8)),L8=""),1,0)
B9: 45797 | C9: Tomatoes | D9: Bed 1 | E9: Planted out | F9: 8 | G9: 45945 | I9: =IF(NOT(AND(C9<>"",ISNUMBER(B9))),"",IF(N(IFERROR(INDEX(Crops!$F$6:$F$65,MATCH(C9,Crops!$B$6:$B$65,0)),0))>0,INT(B9)+N(IFERROR(INDEX(Crops!$F$6:$F$65,MATCH(C9,Crops!$B$6:$B$65,0)),0)),"")) | J9: =IF(NOT(AND(C9<>"",ISNUMBER(B9))),"",IF(ISNUMBER(G9),"Done",IF(INT(B9)>TODAY(),"Planned",IF(COUNTIFS(Harvest!$C$6:$C$1505,C9,Harvest!$D$6:$D$1505,D9&"",Harvest!$L$6:$L$1505,">="&INT(B9))>0,"Picking","Growing")))) | K9: =IF(OR(NOT(AND(C9<>"",ISNUMBER(B9))),J9="Planned"),"",IF(ISNUMBER(G9),INT(G9),TODAY())-INT(B9)) | L9: =IF(AND(B9="",C9="",D9=""),"",IF(NOT(ISNUMBER(B9)),"Needs a date",IF(C9="","Needs a crop",IF(COUNTIF(Crops!$B$6:$B$65,C9)=0,"Not on Crops",IF(AND(D9<>"",COUNTIF(Beds!$B$6:$B$35,D9)=0),"Not on Beds",IF(AND(ISNUMBER(G9),G9<B9),"Cleared before it was planted","")))))) | M9: =IF(OR(L9<>"",D9="",O9=""),"",IF(COUNTIFS(Plantings!$D$6:$D$505,D9,Plantings!$O$6:$O$505,O9,Plantings!$N$6:$N$505,N9-1)>0,"Same family here last year","")) | N9: =IF(ISNUMBER(B9),YEAR(B9),"") | O9: =IF(C9="","",IFERROR(INDEX(Crops!$C$6:$C$65,MATCH(C9,Crops!$B$6:$B$65,0))&"","")) | P9: =IF(ISNUMBER(B9),INT(B9),0) | Q9: =IF(AND(L9="",OR(J9="Growing",J9="Picking")),1,0) | R9: =IF(AND(Q9=1,D9<>""),P9*1000+ROW(),0) | S9: =IF(AND(AND(C9<>"",ISNUMBER(B9)),L9=""),1,0)
B10: 45809 | C10: Runner beans | D10: Bed 3 | E10: Planted out | F10: 12 | G10: 45950 | I10: =IF(NOT(AND(C10<>"",ISNUMBER(B10))),"",IF(N(IFERROR(INDEX(Crops!$F$6:$F$65,MATCH(C10,Crops!$B$6:$B$65,0)),0))>0,INT(B10)+N(IFERROR(INDEX(Crops!$F$6:$F$65,MATCH(C10,Crops!$B$6:$B$65,0)),0)),"")) | J10: =IF(NOT(AND(C10<>"",ISNUMBER(B10))),"",IF(ISNUMBER(G10),"Done",IF(INT(B10)>TODAY(),"Planned",IF(COUNTIFS(Harvest!$C$6:$C$1505,C10,Harvest!$D$6:$D$1505,D10&"",Harvest!$L$6:$L$1505,">="&INT(B10))>0,"Picking","Growing")))) | K10: =IF(OR(NOT(AND(C10<>"",ISNUMBER(B10))),J10="Planned"),"",IF(ISNUMBER(G10),INT(G10),TODAY())-INT(B10)) | L10: =IF(AND(B10="",C10="",D10=""),"",IF(NOT(ISNUMBER(B10)),"Needs a date",IF(C10="","Needs a crop",IF(COUNTIF(Crops!$B$6:$B$65,C10)=0,"Not on Crops",IF(AND(D10<>"",COUNTIF(Beds!$B$6:$B$35,D10)=0),"Not on Beds",IF(AND(ISNUMBER(G10),G10<B10),"Cleared before it was planted","")))))) | M10: =IF(OR(L10<>"",D10="",O10=""),"",IF(COUNTIFS(Plantings!$D$6:$D$505,D10,Plantings!$O$6:$O$505,O10,Plantings!$N$6:$N$505,N10-1)>0,"Same family here last year","")) | N10: =IF(ISNUMBER(B10),YEAR(B10),"") | O10: =IF(C10="","",IFERROR(INDEX(Crops!$C$6:$C$65,MATCH(C10,Crops!$B$6:$B$65,0))&"","")) | P10: =IF(ISNUMBER(B10),INT(B10),0) | Q10: =IF(AND(L10="",OR(J10="Growing",J10="Picking")),1,0) | R10: =IF(AND(Q10=1,D10<>""),P10*1000+ROW(),0) | S10: =IF(AND(AND(C10<>"",ISNUMBER(B10)),L10=""),1,0)
B11: 45950 | C11: Garlic | D11: Bed 3 | E11: Sown outside | F11: 24 | G11: 46208 | I11: =IF(NOT(AND(C11<>"",ISNUMBER(B11))),"",IF(N(IFERROR(INDEX(Crops!$F$6:$F$65,MATCH(C11,Crops!$B$6:$B$65,0)),0))>0,INT(B11)+N(IFERROR(INDEX(Crops!$F$6:$F$65,MATCH(C11,Crops!$B$6:$B$65,0)),0)),"")) | J11: =IF(NOT(AND(C11<>"",ISNUMBER(B11))),"",IF(ISNUMBER(G11),"Done",IF(INT(B11)>TODAY(),"Planned",IF(COUNTIFS(Harvest!$C$6:$C$1505,C11,Harvest!$D$6:$D$1505,D11&"",Harvest!$L$6:$L$1505,">="&INT(B11))>0,"Picking","Growing")))) | K11: =IF(OR(NOT(AND(C11<>"",ISNUMBER(B11))),J11="Planned"),"",IF(ISNUMBER(G11),INT(G11),TODAY())-INT(B11)) | L11: =IF(AND(B11="",C11="",D11=""),"",IF(NOT(ISNUMBER(B11)),"Needs a date",IF(C11="","Needs a crop",IF(COUNTIF(Crops!$B$6:$B$65,C11)=0,"Not on Crops",IF(AND(D11<>"",COUNTIF(Beds!$B$6:$B$35,D11)=0),"Not on Beds",IF(AND(ISNUMBER(G11),G11<B11),"Cleared before it was planted","")))))) | M11: =IF(OR(L11<>"",D11="",O11=""),"",IF(COUNTIFS(Plantings!$D$6:$D$505,D11,Plantings!$O$6:$O$505,O11,Plantings!$N$6:$N$505,N11-1)>0,"Same family here last year","")) | N11: =IF(ISNUMBER(B11),YEAR(B11),"") | O11: =IF(C11="","",IFERROR(INDEX(Crops!$C$6:$C$65,MATCH(C11,Crops!$B$6:$B$65,0))&"","")) | P11: =IF(ISNUMBER(B11),INT(B11),0) | Q11: =IF(AND(L11="",OR(J11="Growing",J11="Picking")),1,0) | R11: =IF(AND(Q11=1,D11<>""),P11*1000+ROW(),0) | S11: =IF(AND(AND(C11<>"",ISNUMBER(B11)),L11=""),1,0)
B12: 46096 | C12: Tomatoes | D12: Greenhouse | E12: Sown inside | F12: 12 | G12: 46160 | H12: Seed trays, planted out in May | I12: =IF(NOT(AND(C12<>"",ISNUMBER(B12))),"",IF(N(IFERROR(INDEX(Crops!$F$6:$F$65,MATCH(C12,Crops!$B$6:$B$65,0)),0))>0,INT(B12)+N(IFERROR(INDEX(Crops!$F$6:$F$65,MATCH(C12,Crops!$B$6:$B$65,0)),0)),"")) | J12: =IF(NOT(AND(C12<>"",ISNUMBER(B12))),"",IF(ISNUMBER(G12),"Done",IF(INT(B12)>TODAY(),"Planned",IF(COUNTIFS(Harvest!$C$6:$C$1505,C12,Harvest!$D$6:$D$1505,D12&"",Harvest!$L$6:$L$1505,">="&INT(B12))>0,"Picking","Growing")))) | K12: =IF(OR(NOT(AND(C12<>"",ISNUMBER(B12))),J12="Planned"),"",IF(ISNUMBER(G12),INT(G12),TODAY())-INT(B12)) | L12: =IF(AND(B12="",C12="",D12=""),"",IF(NOT(ISNUMBER(B12)),"Needs a date",IF(C12="","Needs a crop",IF(COUNTIF(Crops!$B$6:$B$65,C12)=0,"Not on Crops",IF(AND(D12<>"",COUNTIF(Beds!$B$6:$B$35,D12)=0),"Not on Beds",IF(AND(ISNUMBER(G12),G12<B12),"Cleared before it was planted","")))))) | M12: =IF(OR(L12<>"",D12="",O12=""),"",IF(COUNTIFS(Plantings!$D$6:$D$505,D12,Plantings!$O$6:$O$505,O12,Plantings!$N$6:$N$505,N12-1)>0,"Same family here last year","")) | N12: =IF(ISNUMBER(B12),YEAR(B12),"") | O12: =IF(C12="","",IFERROR(INDEX(Crops!$C$6:$C$65,MATCH(C12,Crops!$B$6:$B$65,0))&"","")) | P12: =IF(ISNUMBER(B12),INT(B12),0) | Q12: =IF(AND(L12="",OR(J12="Growing",J12="Picking")),1,0) | R12: =IF(AND(Q12=1,D12<>""),P12*1000+ROW(),0) | S12: =IF(AND(AND(C12<>"",ISNUMBER(B12)),L12=""),1,0)
B13: 46103 | C13: Peas | D13: Bed 1 | E13: Sown outside | F13: 2 | G13: 46228 | H13: Two rows | I13: =IF(NOT(AND(C13<>"",ISNUMBER(B13))),"",IF(N(IFERROR(INDEX(Crops!$F$6:$F$65,MATCH(C13,Crops!$B$6:$B$65,0)),0))>0,INT(B13)+N(IFERROR(INDEX(Crops!$F$6:$F$65,MATCH(C13,Crops!$B$6:$B$65,0)),0)),"")) | J13: =IF(NOT(AND(C13<>"",ISNUMBER(B13))),"",IF(ISNUMBER(G13),"Done",IF(INT(B13)>TODAY(),"Planned",IF(COUNTIFS(Harvest!$C$6:$C$1505,C13,Harvest!$D$6:$D$1505,D13&"",Harvest!$L$6:$L$1505,">="&INT(B13))>0,"Picking","Growing")))) | K13: =IF(OR(NOT(AND(C13<>"",ISNUMBER(B13))),J13="Planned"),"",IF(ISNUMBER(G13),INT(G13),TODAY())-INT(B13)) | L13: =IF(AND(B13="",C13="",D13=""),"",IF(NOT(ISNUMBER(B13)),"Needs a date",IF(C13="","Needs a crop",IF(COUNTIF(Crops!$B$6:$B$65,C13)=0,"Not on Crops",IF(AND(D13<>"",COUNTIF(Beds!$B$6:$B$35,D13)=0),"Not on Beds",IF(AND(ISNUMBER(G13),G13<B13),"Cleared before it was planted","")))))) | M13: =IF(OR(L13<>"",D13="",O13=""),"",IF(COUNTIFS(Plantings!$D$6:$D$505,D13,Plantings!$O$6:$O$505,O13,Plantings!$N$6:$N$505,N13-1)>0,"Same family here last year","")) | N13: =IF(ISNUMBER(B13),YEAR(B13),"") | O13: =IF(C13="","",IFERROR(INDEX(Crops!$C$6:$C$65,MATCH(C13,Crops!$B$6:$B$65,0))&"","")) | P13: =IF(ISNUMBER(B13),INT(B13),0) | Q13: =IF(AND(L13="",OR(J13="Growing",J13="Picking")),1,0) | R13: =IF(AND(Q13=1,D13<>""),P13*1000+ROW(),0) | S13: =IF(AND(AND(C13<>"",ISNUMBER(B13)),L13=""),1,0)
B14: 46117 | C14: Potatoes | D14: Bed 4 | E14: Sown outside | F14: 20 | G14: 46264 | H14: Seed potatoes | I14: =IF(NOT(AND(C14<>"",ISNUMBER(B14))),"",IF(N(IFERROR(INDEX(Crops!$F$6:$F$65,MATCH(C14,Crops!$B$6:$B$65,0)),0))>0,INT(B14)+N(IFERROR(INDEX(Crops!$F$6:$F$65,MATCH(C14,Crops!$B$6:$B$65,0)),0)),"")) | J14: =IF(NOT(AND(C14<>"",ISNUMBER(B14))),"",IF(ISNUMBER(G14),"Done",IF(INT(B14)>TODAY(),"Planned",IF(COUNTIFS(Harvest!$C$6:$C$1505,C14,Harvest!$D$6:$D$1505,D14&"",Harvest!$L$6:$L$1505,">="&INT(B14))>0,"Picking","Growing")))) | K14: =IF(OR(NOT(AND(C14<>"",ISNUMBER(B14))),J14="Planned"),"",IF(ISNUMBER(G14),INT(G14),TODAY())-INT(B14)) | L14: =IF(AND(B14="",C14="",D14=""),"",IF(NOT(ISNUMBER(B14)),"Needs a date",IF(C14="","Needs a crop",IF(COUNTIF(Crops!$B$6:$B$65,C14)=0,"Not on Crops",IF(AND(D14<>"",COUNTIF(Beds!$B$6:$B$35,D14)=0),"Not on Beds",IF(AND(ISNUMBER(G14),G14<B14),"Cleared before it was planted","")))))) | M14: =IF(OR(L14<>"",D14="",O14=""),"",IF(COUNTIFS(Plantings!$D$6:$D$505,D14,Plantings!$O$6:$O$505,O14,Plantings!$N$6:$N$505,N14-1)>0,"Same family here last year","")) | N14: =IF(ISNUMBER(B14),YEAR(B14),"") | O14: =IF(C14="","",IFERROR(INDEX(Crops!$C$6:$C$65,MATCH(C14,Crops!$B$6:$B$65,0))&"","")) | P14: =IF(ISNUMBER(B14),INT(B14),0) | Q14: =IF(AND(L14="",OR(J14="Growing",J14="Picking")),1,0) | R14: =IF(AND(Q14=1,D14<>""),P14*1000+ROW(),0) | S14: =IF(AND(AND(C14<>"",ISNUMBER(B14)),L14=""),1,0)
B15: 46124 | C15: Onions | D15: Bed 2 | E15: Sown outside | F15: 60 | G15: 46270 | H15: Sets | I15: =IF(NOT(AND(C15<>"",ISNUMBER(B15))),"",IF(N(IFERROR(INDEX(Crops!$F$6:$F$65,MATCH(C15,Crops!$B$6:$B$65,0)),0))>0,INT(B15)+N(IFERROR(INDEX(Crops!$F$6:$F$65,MATCH(C15,Crops!$B$6:$B$65,0)),0)),"")) | J15: =IF(NOT(AND(C15<>"",ISNUMBER(B15))),"",IF(ISNUMBER(G15),"Done",IF(INT(B15)>TODAY(),"Planned",IF(COUNTIFS(Harvest!$C$6:$C$1505,C15,Harvest!$D$6:$D$1505,D15&"",Harvest!$L$6:$L$1505,">="&INT(B15))>0,"Picking","Growing")))) | K15: =IF(OR(NOT(AND(C15<>"",ISNUMBER(B15))),J15="Planned"),"",IF(ISNUMBER(G15),INT(G15),TODAY())-INT(B15)) | L15: =IF(AND(B15="",C15="",D15=""),"",IF(NOT(ISNUMBER(B15)),"Needs a date",IF(C15="","Needs a crop",IF(COUNTIF(Crops!$B$6:$B$65,C15)=0,"Not on Crops",IF(AND(D15<>"",COUNTIF(Beds!$B$6:$B$35,D15)=0),"Not on Beds",IF(AND(ISNUMBER(G15),G15<B15),"Cleared before it was planted","")))))) | M15: =IF(OR(L15<>"",D15="",O15=""),"",IF(COUNTIFS(Plantings!$D$6:$D$505,D15,Plantings!$O$6:$O$505,O15,Plantings!$N$6:$N$505,N15-1)>0,"Same family here last year","")) | N15: =IF(ISNUMBER(B15),YEAR(B15),"") | O15: =IF(C15="","",IFERROR(INDEX(Crops!$C$6:$C$65,MATCH(C15,Crops!$B$6:$B$65,0))&"","")) | P15: =IF(ISNUMBER(B15),INT(B15),0) | Q15: =IF(AND(L15="",OR(J15="Growing",J15="Picking")),1,0) | R15: =IF(AND(Q15=1,D15<>""),P15*1000+ROW(),0) | S15: =IF(AND(AND(C15<>"",ISNUMBER(B15)),L15=""),1,0)
B16: 46132 | C16: Carrots | D16: Bed 2 | E16: Sown outside | F16: 1 | H16: One row | I16: =IF(NOT(AND(C16<>"",ISNUMBER(B16))),"",IF(N(IFERROR(INDEX(Crops!$F$6:$F$65,MATCH(C16,Crops!$B$6:$B$65,0)),0))>0,INT(B16)+N(IFERROR(INDEX(Crops!$F$6:$F$65,MATCH(C16,Crops!$B$6:$B$65,0)),0)),"")) | J16: =IF(NOT(AND(C16<>"",ISNUMBER(B16))),"",IF(ISNUMBER(G16),"Done",IF(INT(B16)>TODAY(),"Planned",IF(COUNTIFS(Harvest!$C$6:$C$1505,C16,Harvest!$D$6:$D$1505,D16&"",Harvest!$L$6:$L$1505,">="&INT(B16))>0,"Picking","Growing")))) | K16: =IF(OR(NOT(AND(C16<>"",ISNUMBER(B16))),J16="Planned"),"",IF(ISNUMBER(G16),INT(G16),TODAY())-INT(B16)) | L16: =IF(AND(B16="",C16="",D16=""),"",IF(NOT(ISNUMBER(B16)),"Needs a date",IF(C16="","Needs a crop",IF(COUNTIF(Crops!$B$6:$B$65,C16)=0,"Not on Crops",IF(AND(D16<>"",COUNTIF(Beds!$B$6:$B$35,D16)=0),"Not on Beds",IF(AND(ISNUMBER(G16),G16<B16),"Cleared before it was planted","")))))) | M16: =IF(OR(L16<>"",D16="",O16=""),"",IF(COUNTIFS(Plantings!$D$6:$D$505,D16,Plantings!$O$6:$O$505,O16,Plantings!$N$6:$N$505,N16-1)>0,"Same family here last year","")) | N16: =IF(ISNUMBER(B16),YEAR(B16),"") | O16: =IF(C16="","",IFERROR(INDEX(Crops!$C$6:$C$65,MATCH(C16,Crops!$B$6:$B$65,0))&"","")) | P16: =IF(ISNUMBER(B16),INT(B16),0) | Q16: =IF(AND(L16="",OR(J16="Growing",J16="Picking")),1,0) | R16: =IF(AND(Q16=1,D16<>""),P16*1000+ROW(),0) | S16: =IF(AND(AND(C16<>"",ISNUMBER(B16)),L16=""),1,0)
B17: 46138 | C17: Lettuce | D17: Herb bed | E17: Sown outside | F17: 1 | G17: 46213 | I17: =IF(NOT(AND(C17<>"",ISNUMBER(B17))),"",IF(N(IFERROR(INDEX(Crops!$F$6:$F$65,MATCH(C17,Crops!$B$6:$B$65,0)),0))>0,INT(B17)+N(IFERROR(INDEX(Crops!$F$6:$F$65,MATCH(C17,Crops!$B$6:$B$65,0)),0)),"")) | J17: =IF(NOT(AND(C17<>"",ISNUMBER(B17))),"",IF(ISNUMBER(G17),"Done",IF(INT(B17)>TODAY(),"Planned",IF(COUNTIFS(Harvest!$C$6:$C$1505,C17,Harvest!$D$6:$D$1505,D17&"",Harvest!$L$6:$L$1505,">="&INT(B17))>0,"Picking","Growing")))) | K17: =IF(OR(NOT(AND(C17<>"",ISNUMBER(B17))),J17="Planned"),"",IF(ISNUMBER(G17),INT(G17),TODAY())-INT(B17)) | L17: =IF(AND(B17="",C17="",D17=""),"",IF(NOT(ISNUMBER(B17)),"Needs a date",IF(C17="","Needs a crop",IF(COUNTIF(Crops!$B$6:$B$65,C17)=0,"Not on Crops",IF(AND(D17<>"",COUNTIF(Beds!$B$6:$B$35,D17)=0),"Not on Beds",IF(AND(ISNUMBER(G17),G17<B17),"Cleared before it was planted","")))))) | M17: =IF(OR(L17<>"",D17="",O17=""),"",IF(COUNTIFS(Plantings!$D$6:$D$505,D17,Plantings!$O$6:$O$505,O17,Plantings!$N$6:$N$505,N17-1)>0,"Same family here last year","")) | N17: =IF(ISNUMBER(B17),YEAR(B17),"") | O17: =IF(C17="","",IFERROR(INDEX(Crops!$C$6:$C$65,MATCH(C17,Crops!$B$6:$B$65,0))&"","")) | P17: =IF(ISNUMBER(B17),INT(B17),0) | Q17: =IF(AND(L17="",OR(J17="Growing",J17="Picking")),1,0) | R17: =IF(AND(Q17=1,D17<>""),P17*1000+ROW(),0) | S17: =IF(AND(AND(C17<>"",ISNUMBER(B17)),L17=""),1,0)
B18: 46142 | C18: Strawberries | D18: Patio pots | E18: Bought plants | F18: 6 | I18: =IF(NOT(AND(C18<>"",ISNUMBER(B18))),"",IF(N(IFERROR(INDEX(Crops!$F$6:$F$65,MATCH(C18,Crops!$B$6:$B$65,0)),0))>0,INT(B18)+N(IFERROR(INDEX(Crops!$F$6:$F$65,MATCH(C18,Crops!$B$6:$B$65,0)),0)),"")) | J18: =IF(NOT(AND(C18<>"",ISNUMBER(B18))),"",IF(ISNUMBER(G18),"Done",IF(INT(B18)>TODAY(),"Planned",IF(COUNTIFS(Harvest!$C$6:$C$1505,C18,Harvest!$D$6:$D$1505,D18&"",Harvest!$L$6:$L$1505,">="&INT(B18))>0,"Picking","Growing")))) | K18: =IF(OR(NOT(AND(C18<>"",ISNUMBER(B18))),J18="Planned"),"",IF(ISNUMBER(G18),INT(G18),TODAY())-INT(B18)) | L18: =IF(AND(B18="",C18="",D18=""),"",IF(NOT(ISNUMBER(B18)),"Needs a date",IF(C18="","Needs a crop",IF(COUNTIF(Crops!$B$6:$B$65,C18)=0,"Not on Crops",IF(AND(D18<>"",COUNTIF(Beds!$B$6:$B$35,D18)=0),"Not on Beds",IF(AND(ISNUMBER(G18),G18<B18),"Cleared before it was planted","")))))) | M18: =IF(OR(L18<>"",D18="",O18=""),"",IF(COUNTIFS(Plantings!$D$6:$D$505,D18,Plantings!$O$6:$O$505,O18,Plantings!$N$6:$N$505,N18-1)>0,"Same family here last year","")) | N18: =IF(ISNUMBER(B18),YEAR(B18),"") | O18: =IF(C18="","",IFERROR(INDEX(Crops!$C$6:$C$65,MATCH(C18,Crops!$B$6:$B$65,0))&"","")) | P18: =IF(ISNUMBER(B18),INT(B18),0) | Q18: =IF(AND(L18="",OR(J18="Growing",J18="Picking")),1,0) | R18: =IF(AND(Q18=1,D18<>""),P18*1000+ROW(),0) | S18: =IF(AND(AND(C18<>"",ISNUMBER(B18)),L18=""),1,0)
B19: 46152 | C19: Peppers | D19: Bed 2 | E19: Planted out | F19: 6 | I19: =IF(NOT(AND(C19<>"",ISNUMBER(B19))),"",IF(N(IFERROR(INDEX(Crops!$F$6:$F$65,MATCH(C19,Crops!$B$6:$B$65,0)),0))>0,INT(B19)+N(IFERROR(INDEX(Crops!$F$6:$F$65,MATCH(C19,Crops!$B$6:$B$65,0)),0)),"")) | J19: =IF(NOT(AND(C19<>"",ISNUMBER(B19))),"",IF(ISNUMBER(G19),"Done",IF(INT(B19)>TODAY(),"Planned",IF(COUNTIFS(Harvest!$C$6:$C$1505,C19,Harvest!$D$6:$D$1505,D19&"",Harvest!$L$6:$L$1505,">="&INT(B19))>0,"Picking","Growing")))) | K19: =IF(OR(NOT(AND(C19<>"",ISNUMBER(B19))),J19="Planned"),"",IF(ISNUMBER(G19),INT(G19),TODAY())-INT(B19)) | L19: =IF(AND(B19="",C19="",D19=""),"",IF(NOT(ISNUMBER(B19)),"Needs a date",IF(C19="","Needs a crop",IF(COUNTIF(Crops!$B$6:$B$65,C19)=0,"Not on Crops",IF(AND(D19<>"",COUNTIF(Beds!$B$6:$B$35,D19)=0),"Not on Beds",IF(AND(ISNUMBER(G19),G19<B19),"Cleared before it was planted","")))))) | M19: =IF(OR(L19<>"",D19="",O19=""),"",IF(COUNTIFS(Plantings!$D$6:$D$505,D19,Plantings!$O$6:$O$505,O19,Plantings!$N$6:$N$505,N19-1)>0,"Same family here last year","")) | N19: =IF(ISNUMBER(B19),YEAR(B19),"") | O19: =IF(C19="","",IFERROR(INDEX(Crops!$C$6:$C$65,MATCH(C19,Crops!$B$6:$B$65,0))&"","")) | P19: =IF(ISNUMBER(B19),INT(B19),0) | Q19: =IF(AND(L19="",OR(J19="Growing",J19="Picking")),1,0) | R19: =IF(AND(Q19=1,D19<>""),P19*1000+ROW(),0) | S19: =IF(AND(AND(C19<>"",ISNUMBER(B19)),L19=""),1,0)
B20: 46160 | C20: Tomatoes | D20: Greenhouse | E20: Planted out | F20: 8 | I20: =IF(NOT(AND(C20<>"",ISNUMBER(B20))),"",IF(N(IFERROR(INDEX(Crops!$F$6:$F$65,MATCH(C20,Crops!$B$6:$B$65,0)),0))>0,INT(B20)+N(IFERROR(INDEX(Crops!$F$6:$F$65,MATCH(C20,Crops!$B$6:$B$65,0)),0)),"")) | J20: =IF(NOT(AND(C20<>"",ISNUMBER(B20))),"",IF(ISNUMBER(G20),"Done",IF(INT(B20)>TODAY(),"Planned",IF(COUNTIFS(Harvest!$C$6:$C$1505,C20,Harvest!$D$6:$D$1505,D20&"",Harvest!$L$6:$L$1505,">="&INT(B20))>0,"Picking","Growing")))) | K20: =IF(OR(NOT(AND(C20<>"",ISNUMBER(B20))),J20="Planned"),"",IF(ISNUMBER(G20),INT(G20),TODAY())-INT(B20)) | L20: =IF(AND(B20="",C20="",D20=""),"",IF(NOT(ISNUMBER(B20)),"Needs a date",IF(C20="","Needs a crop",IF(COUNTIF(Crops!$B$6:$B$65,C20)=0,"Not on Crops",IF(AND(D20<>"",COUNTIF(Beds!$B$6:$B$35,D20)=0),"Not on Beds",IF(AND(ISNUMBER(G20),G20<B20),"Cleared before it was planted","")))))) | M20: =IF(OR(L20<>"",D20="",O20=""),"",IF(COUNTIFS(Plantings!$D$6:$D$505,D20,Plantings!$O$6:$O$505,O20,Plantings!$N$6:$N$505,N20-1)>0,"Same family here last year","")) | N20: =IF(ISNUMBER(B20),YEAR(B20),"") | O20: =IF(C20="","",IFERROR(INDEX(Crops!$C$6:$C$65,MATCH(C20,Crops!$B$6:$B$65,0))&"","")) | P20: =IF(ISNUMBER(B20),INT(B20),0) | Q20: =IF(AND(L20="",OR(J20="Growing",J20="Picking")),1,0) | R20: =IF(AND(Q20=1,D20<>""),P20*1000+ROW(),0) | S20: =IF(AND(AND(C20<>"",ISNUMBER(B20)),L20=""),1,0)
B21: 46166 | C21: Zucchini | D21: Bed 3 | E21: Planted out | F21: 3 | I21: =IF(NOT(AND(C21<>"",ISNUMBER(B21))),"",IF(N(IFERROR(INDEX(Crops!$F$6:$F$65,MATCH(C21,Crops!$B$6:$B$65,0)),0))>0,INT(B21)+N(IFERROR(INDEX(Crops!$F$6:$F$65,MATCH(C21,Crops!$B$6:$B$65,0)),0)),"")) | J21: =IF(NOT(AND(C21<>"",ISNUMBER(B21))),"",IF(ISNUMBER(G21),"Done",IF(INT(B21)>TODAY(),"Planned",IF(COUNTIFS(Harvest!$C$6:$C$1505,C21,Harvest!$D$6:$D$1505,D21&"",Harvest!$L$6:$L$1505,">="&INT(B21))>0,"Picking","Growing")))) | K21: =IF(OR(NOT(AND(C21<>"",ISNUMBER(B21))),J21="Planned"),"",IF(ISNUMBER(G21),INT(G21),TODAY())-INT(B21)) | L21: =IF(AND(B21="",C21="",D21=""),"",IF(NOT(ISNUMBER(B21)),"Needs a date",IF(C21="","Needs a crop",IF(COUNTIF(Crops!$B$6:$B$65,C21)=0,"Not on Crops",IF(AND(D21<>"",COUNTIF(Beds!$B$6:$B$35,D21)=0),"Not on Beds",IF(AND(ISNUMBER(G21),G21<B21),"Cleared before it was planted","")))))) | M21: =IF(OR(L21<>"",D21="",O21=""),"",IF(COUNTIFS(Plantings!$D$6:$D$505,D21,Plantings!$O$6:$O$505,O21,Plantings!$N$6:$N$505,N21-1)>0,"Same family here last year","")) | N21: =IF(ISNUMBER(B21),YEAR(B21),"") | O21: =IF(C21="","",IFERROR(INDEX(Crops!$C$6:$C$65,MATCH(C21,Crops!$B$6:$B$65,0))&"","")) | P21: =IF(ISNUMBER(B21),INT(B21),0) | Q21: =IF(AND(L21="",OR(J21="Growing",J21="Picking")),1,0) | R21: =IF(AND(Q21=1,D21<>""),P21*1000+ROW(),0) | S21: =IF(AND(AND(C21<>"",ISNUMBER(B21)),L21=""),1,0)
B22: 46166 | C22: Cucumbers | D22: Greenhouse | E22: Planted out | F22: 4 | I22: =IF(NOT(AND(C22<>"",ISNUMBER(B22))),"",IF(N(IFERROR(INDEX(Crops!$F$6:$F$65,MATCH(C22,Crops!$B$6:$B$65,0)),0))>0,INT(B22)+N(IFERROR(INDEX(Crops!$F$6:$F$65,MATCH(C22,Crops!$B$6:$B$65,0)),0)),"")) | J22: =IF(NOT(AND(C22<>"",ISNUMBER(B22))),"",IF(ISNUMBER(G22),"Done",IF(INT(B22)>TODAY(),"Planned",IF(COUNTIFS(Harvest!$C$6:$C$1505,C22,Harvest!$D$6:$D$1505,D22&"",Harvest!$L$6:$L$1505,">="&INT(B22))>0,"Picking","Growing")))) | K22: =IF(OR(NOT(AND(C22<>"",ISNUMBER(B22))),J22="Planned"),"",IF(ISNUMBER(G22),INT(G22),TODAY())-INT(B22)) | L22: =IF(AND(B22="",C22="",D22=""),"",IF(NOT(ISNUMBER(B22)),"Needs a date",IF(C22="","Needs a crop",IF(COUNTIF(Crops!$B$6:$B$65,C22)=0,"Not on Crops",IF(AND(D22<>"",COUNTIF(Beds!$B$6:$B$35,D22)=0),"Not on Beds",IF(AND(ISNUMBER(G22),G22<B22),"Cleared before it was planted","")))))) | M22: =IF(OR(L22<>"",D22="",O22=""),"",IF(COUNTIFS(Plantings!$D$6:$D$505,D22,Plantings!$O$6:$O$505,O22,Plantings!$N$6:$N$505,N22-1)>0,"Same family here last year","")) | N22: =IF(ISNUMBER(B22),YEAR(B22),"") | O22: =IF(C22="","",IFERROR(INDEX(Crops!$C$6:$C$65,MATCH(C22,Crops!$B$6:$B$65,0))&"","")) | P22: =IF(ISNUMBER(B22),INT(B22),0) | Q22: =IF(AND(L22="",OR(J22="Growing",J22="Picking")),1,0) | R22: =IF(AND(Q22=1,D22<>""),P22*1000+ROW(),0) | S22: =IF(AND(AND(C22<>"",ISNUMBER(B22)),L22=""),1,0)
B23: 46172 | C23: Basil | D23: Patio pots | E23: Planted out | F23: 6 | I23: =IF(NOT(AND(C23<>"",ISNUMBER(B23))),"",IF(N(IFERROR(INDEX(Crops!$F$6:$F$65,MATCH(C23,Crops!$B$6:$B$65,0)),0))>0,INT(B23)+N(IFERROR(INDEX(Crops!$F$6:$F$65,MATCH(C23,Crops!$B$6:$B$65,0)),0)),"")) | J23: =IF(NOT(AND(C23<>"",ISNUMBER(B23))),"",IF(ISNUMBER(G23),"Done",IF(INT(B23)>TODAY(),"Planned",IF(COUNTIFS(Harvest!$C$6:$C$1505,C23,Harvest!$D$6:$D$1505,D23&"",Harvest!$L$6:$L$1505,">="&INT(B23))>0,"Picking","Growing")))) | K23: =IF(OR(NOT(AND(C23<>"",ISNUMBER(B23))),J23="Planned"),"",IF(ISNUMBER(G23),INT(G23),TODAY())-INT(B23)) | L23: =IF(AND(B23="",C23="",D23=""),"",IF(NOT(ISNUMBER(B23)),"Needs a date",IF(C23="","Needs a crop",IF(COUNTIF(Crops!$B$6:$B$65,C23)=0,"Not on Crops",IF(AND(D23<>"",COUNTIF(Beds!$B$6:$B$35,D23)=0),"Not on Beds",IF(AND(ISNUMBER(G23),G23<B23),"Cleared before it was planted","")))))) | M23: =IF(OR(L23<>"",D23="",O23=""),"",IF(COUNTIFS(Plantings!$D$6:$D$505,D23,Plantings!$O$6:$O$505,O23,Plantings!$N$6:$N$505,N23-1)>0,"Same family here last year","")) | N23: =IF(ISNUMBER(B23),YEAR(B23),"") | O23: =IF(C23="","",IFERROR(INDEX(Crops!$C$6:$C$65,MATCH(C23,Crops!$B$6:$B$65,0))&"","")) | P23: =IF(ISNUMBER(B23),INT(B23),0) | Q23: =IF(AND(L23="",OR(J23="Growing",J23="Picking")),1,0) | R23: =IF(AND(Q23=1,D23<>""),P23*1000+ROW(),0) | S23: =IF(AND(AND(C23<>"",ISNUMBER(B23)),L23=""),1,0)
B24: 46175 | C24: Runner beans | D24: Bed 1 | E24: Planted out | F24: 12 | I24: =IF(NOT(AND(C24<>"",ISNUMBER(B24))),"",IF(N(IFERROR(INDEX(Crops!$F$6:$F$65,MATCH(C24,Crops!$B$6:$B$65,0)),0))>0,INT(B24)+N(IFERROR(INDEX(Crops!$F$6:$F$65,MATCH(C24,Crops!$B$6:$B$65,0)),0)),"")) | J24: =IF(NOT(AND(C24<>"",ISNUMBER(B24))),"",IF(ISNUMBER(G24),"Done",IF(INT(B24)>TODAY(),"Planned",IF(COUNTIFS(Harvest!$C$6:$C$1505,C24,Harvest!$D$6:$D$1505,D24&"",Harvest!$L$6:$L$1505,">="&INT(B24))>0,"Picking","Growing")))) | K24: =IF(OR(NOT(AND(C24<>"",ISNUMBER(B24))),J24="Planned"),"",IF(ISNUMBER(G24),INT(G24),TODAY())-INT(B24)) | L24: =IF(AND(B24="",C24="",D24=""),"",IF(NOT(ISNUMBER(B24)),"Needs a date",IF(C24="","Needs a crop",IF(COUNTIF(Crops!$B$6:$B$65,C24)=0,"Not on Crops",IF(AND(D24<>"",COUNTIF(Beds!$B$6:$B$35,D24)=0),"Not on Beds",IF(AND(ISNUMBER(G24),G24<B24),"Cleared before it was planted","")))))) | M24: =IF(OR(L24<>"",D24="",O24=""),"",IF(COUNTIFS(Plantings!$D$6:$D$505,D24,Plantings!$O$6:$O$505,O24,Plantings!$N$6:$N$505,N24-1)>0,"Same family here last year","")) | N24: =IF(ISNUMBER(B24),YEAR(B24),"") | O24: =IF(C24="","",IFERROR(INDEX(Crops!$C$6:$C$65,MATCH(C24,Crops!$B$6:$B$65,0))&"","")) | P24: =IF(ISNUMBER(B24),INT(B24),0) | Q24: =IF(AND(L24="",OR(J24="Growing",J24="Picking")),1,0) | R24: =IF(AND(Q24=1,D24<>""),P24*1000+ROW(),0) | S24: =IF(AND(AND(C24<>"",ISNUMBER(B24)),L24=""),1,0)
B25: 46187 | C25: Beetroot | D25: Bed 4 | E25: Sown outside | F25: 1 | H25: After the potatoes come out | I25: =IF(NOT(AND(C25<>"",ISNUMBER(B25))),"",IF(N(IFERROR(INDEX(Crops!$F$6:$F$65,MATCH(C25,Crops!$B$6:$B$65,0)),0))>0,INT(B25)+N(IFERROR(INDEX(Crops!$F$6:$F$65,MATCH(C25,Crops!$B$6:$B$65,0)),0)),"")) | J25: =IF(NOT(AND(C25<>"",ISNUMBER(B25))),"",IF(ISNUMBER(G25),"Done",IF(INT(B25)>TODAY(),"Planned",IF(COUNTIFS(Harvest!$C$6:$C$1505,C25,Harvest!$D$6:$D$1505,D25&"",Harvest!$L$6:$L$1505,">="&INT(B25))>0,"Picking","Growing")))) | K25: =IF(OR(NOT(AND(C25<>"",ISNUMBER(B25))),J25="Planned"),"",IF(ISNUMBER(G25),INT(G25),TODAY())-INT(B25)) | L25: =IF(AND(B25="",C25="",D25=""),"",IF(NOT(ISNUMBER(B25)),"Needs a date",IF(C25="","Needs a crop",IF(COUNTIF(Crops!$B$6:$B$65,C25)=0,"Not on Crops",IF(AND(D25<>"",COUNTIF(Beds!$B$6:$B$35,D25)=0),"Not on Beds",IF(AND(ISNUMBER(G25),G25<B25),"Cleared before it was planted","")))))) | M25: =IF(OR(L25<>"",D25="",O25=""),"",IF(COUNTIFS(Plantings!$D$6:$D$505,D25,Plantings!$O$6:$O$505,O25,Plantings!$N$6:$N$505,N25-1)>0,"Same family here last year","")) | N25: =IF(ISNUMBER(B25),YEAR(B25),"") | O25: =IF(C25="","",IFERROR(INDEX(Crops!$C$6:$C$65,MATCH(C25,Crops!$B$6:$B$65,0))&"","")) | P25: =IF(ISNUMBER(B25),INT(B25),0) | Q25: =IF(AND(L25="",OR(J25="Growing",J25="Picking")),1,0) | R25: =IF(AND(Q25=1,D25<>""),P25*1000+ROW(),0) | S25: =IF(AND(AND(C25<>"",ISNUMBER(B25)),L25=""),1,0)
B26: 46193 | C26: Kale | D26: Bed 3 | E26: Planted out | F26: 6 | I26: =IF(NOT(AND(C26<>"",ISNUMBER(B26))),"",IF(N(IFERROR(INDEX(Crops!$F$6:$F$65,MATCH(C26,Crops!$B$6:$B$65,0)),0))>0,INT(B26)+N(IFERROR(INDEX(Crops!$F$6:$F$65,MATCH(C26,Crops!$B$6:$B$65,0)),0)),"")) | J26: =IF(NOT(AND(C26<>"",ISNUMBER(B26))),"",IF(ISNUMBER(G26),"Done",IF(INT(B26)>TODAY(),"Planned",IF(COUNTIFS(Harvest!$C$6:$C$1505,C26,Harvest!$D$6:$D$1505,D26&"",Harvest!$L$6:$L$1505,">="&INT(B26))>0,"Picking","Growing")))) | K26: =IF(OR(NOT(AND(C26<>"",ISNUMBER(B26))),J26="Planned"),"",IF(ISNUMBER(G26),INT(G26),TODAY())-INT(B26)) | L26: =IF(AND(B26="",C26="",D26=""),"",IF(NOT(ISNUMBER(B26)),"Needs a date",IF(C26="","Needs a crop",IF(COUNTIF(Crops!$B$6:$B$65,C26)=0,"Not on Crops",IF(AND(D26<>"",COUNTIF(Beds!$B$6:$B$35,D26)=0),"Not on Beds",IF(AND(ISNUMBER(G26),G26<B26),"Cleared before it was planted","")))))) | M26: =IF(OR(L26<>"",D26="",O26=""),"",IF(COUNTIFS(Plantings!$D$6:$D$505,D26,Plantings!$O$6:$O$505,O26,Plantings!$N$6:$N$505,N26-1)>0,"Same family here last year","")) | N26: =IF(ISNUMBER(B26),YEAR(B26),"") | O26: =IF(C26="","",IFERROR(INDEX(Crops!$C$6:$C$65,MATCH(C26,Crops!$B$6:$B$65,0))&"","")) | P26: =IF(ISNUMBER(B26),INT(B26),0) | Q26: =IF(AND(L26="",OR(J26="Growing",J26="Picking")),1,0) | R26: =IF(AND(Q26=1,D26<>""),P26*1000+ROW(),0) | S26: =IF(AND(AND(C26<>"",ISNUMBER(B26)),L26=""),1,0)
B27: 46244 | C27: Lettuce | D27: Herb bed | E27: Sown outside | F27: 1 | H27: Second sowing | I27: =IF(NOT(AND(C27<>"",ISNUMBER(B27))),"",IF(N(IFERROR(INDEX(Crops!$F$6:$F$65,MATCH(C27,Crops!$B$6:$B$65,0)),0))>0,INT(B27)+N(IFERROR(INDEX(Crops!$F$6:$F$65,MATCH(C27,Crops!$B$6:$B$65,0)),0)),"")) | J27: =IF(NOT(AND(C27<>"",ISNUMBER(B27))),"",IF(ISNUMBER(G27),"Done",IF(INT(B27)>TODAY(),"Planned",IF(COUNTIFS(Harvest!$C$6:$C$1505,C27,Harvest!$D$6:$D$1505,D27&"",Harvest!$L$6:$L$1505,">="&INT(B27))>0,"Picking","Growing")))) | K27: =IF(OR(NOT(AND(C27<>"",ISNUMBER(B27))),J27="Planned"),"",IF(ISNUMBER(G27),INT(G27),TODAY())-INT(B27)) | L27: =IF(AND(B27="",C27="",D27=""),"",IF(NOT(ISNUMBER(B27)),"Needs a date",IF(C27="","Needs a crop",IF(COUNTIF(Crops!$B$6:$B$65,C27)=0,"Not on Crops",IF(AND(D27<>"",COUNTIF(Beds!$B$6:$B$35,D27)=0),"Not on Beds",IF(AND(ISNUMBER(G27),G27<B27),"Cleared before it was planted","")))))) | M27: =IF(OR(L27<>"",D27="",O27=""),"",IF(COUNTIFS(Plantings!$D$6:$D$505,D27,Plantings!$O$6:$O$505,O27,Plantings!$N$6:$N$505,N27-1)>0,"Same family here last year","")) | N27: =IF(ISNUMBER(B27),YEAR(B27),"") | O27: =IF(C27="","",IFERROR(INDEX(Crops!$C$6:$C$65,MATCH(C27,Crops!$B$6:$B$65,0))&"","")) | P27: =IF(ISNUMBER(B27),INT(B27),0) | Q27: =IF(AND(L27="",OR(J27="Growing",J27="Picking")),1,0) | R27: =IF(AND(Q27=1,D27<>""),P27*1000+ROW(),0) | S27: =IF(AND(AND(C27<>"",ISNUMBER(B27)),L27=""),1,0)
B28: 46277 | C28: Spinach | D28: Bed 1 | E28: Sown outside | F28: 1 | H28: Under the beans | I28: =IF(NOT(AND(C28<>"",ISNUMBER(B28))),"",IF(N(IFERROR(INDEX(Crops!$F$6:$F$65,MATCH(C28,Crops!$B$6:$B$65,0)),0))>0,INT(B28)+N(IFERROR(INDEX(Crops!$F$6:$F$65,MATCH(C28,Crops!$B$6:$B$65,0)),0)),"")) | J28: =IF(NOT(AND(C28<>"",ISNUMBER(B28))),"",IF(ISNUMBER(G28),"Done",IF(INT(B28)>TODAY(),"Planned",IF(COUNTIFS(Harvest!$C$6:$C$1505,C28,Harvest!$D$6:$D$1505,D28&"",Harvest!$L$6:$L$1505,">="&INT(B28))>0,"Picking","Growing")))) | K28: =IF(OR(NOT(AND(C28<>"",ISNUMBER(B28))),J28="Planned"),"",IF(ISNUMBER(G28),INT(G28),TODAY())-INT(B28)) | L28: =IF(AND(B28="",C28="",D28=""),"",IF(NOT(ISNUMBER(B28)),"Needs a date",IF(C28="","Needs a crop",IF(COUNTIF(Crops!$B$6:$B$65,C28)=0,"Not on Crops",IF(AND(D28<>"",COUNTIF(Beds!$B$6:$B$35,D28)=0),"Not on Beds",IF(AND(ISNUMBER(G28),G28<B28),"Cleared before it was planted","")))))) | M28: =IF(OR(L28<>"",D28="",O28=""),"",IF(COUNTIFS(Plantings!$D$6:$D$505,D28,Plantings!$O$6:$O$505,O28,Plantings!$N$6:$N$505,N28-1)>0,"Same family here last year","")) | N28: =IF(ISNUMBER(B28),YEAR(B28),"") | O28: =IF(C28="","",IFERROR(INDEX(Crops!$C$6:$C$65,MATCH(C28,Crops!$B$6:$B$65,0))&"","")) | P28: =IF(ISNUMBER(B28),INT(B28),0) | Q28: =IF(AND(L28="",OR(J28="Growing",J28="Picking")),1,0) | R28: =IF(AND(Q28=1,D28<>""),P28*1000+ROW(),0) | S28: =IF(AND(AND(C28<>"",ISNUMBER(B28)),L28=""),1,0)
I29: =IF(NOT(AND(C29<>"",ISNUMBER(B29))),"",IF(N(IFERROR(INDEX(Crops!$F$6:$F$65,MATCH(C29,Crops!$B$6:$B$65,0)),0))>0,INT(B29)+N(IFERROR(INDEX(Crops!$F$6:$F$65,MATCH(C29,Crops!$B$6:$B$65,0)),0)),"")) | J29: =IF(NOT(AND(C29<>"",ISNUMBER(B29))),"",IF(ISNUMBER(G29),"Done",IF(INT(B29)>TODAY(),"Planned",IF(COUNTIFS(Harvest!$C$6:$C$1505,C29,Harvest!$D$6:$D$1505,D29&"",Harvest!$L$6:$L$1505,">="&INT(B29))>0,"Picking","Growing")))) | K29: =IF(OR(NOT(AND(C29<>"",ISNUMBER(B29))),J29="Planned"),"",IF(ISNUMBER(G29),INT(G29),TODAY())-INT(B29)) | L29: =IF(AND(B29="",C29="",D29=""),"",IF(NOT(ISNUMBER(B29)),"Needs a date",IF(C29="","Needs a crop",IF(COUNTIF(Crops!$B$6:$B$65,C29)=0,"Not on Crops",IF(AND(D29<>"",COUNTIF(Beds!$B$6:$B$35,D29)=0),"Not on Beds",IF(AND(ISNUMBER(G29),G29<B29),"Cleared before it was planted","")))))) | M29: =IF(OR(L29<>"",D29="",O29=""),"",IF(COUNTIFS(Plantings!$D$6:$D$505,D29,Plantings!$O$6:$O$505,O29,Plantings!$N$6:$N$505,N29-1)>0,"Same family here last year","")) | N29: =IF(ISNUMBER(B29),YEAR(B29),"") | O29: =IF(C29="","",IFERROR(INDEX(Crops!$C$6:$C$65,MATCH(C29,Crops!$B$6:$B$65,0))&"","")) | P29: =IF(ISNUMBER(B29),INT(B29),0) | Q29: =IF(AND(L29="",OR(J29="Growing",J29="Picking")),1,0) | R29: =IF(AND(Q29=1,D29<>""),P29*1000+ROW(),0) | S29: =IF(AND(AND(C29<>"",ISNUMBER(B29)),L29=""),1,0)
I30: =IF(NOT(AND(C30<>"",ISNUMBER(B30))),"",IF(N(IFERROR(INDEX(Crops!$F$6:$F$65,MATCH(C30,Crops!$B$6:$B$65,0)),0))>0,INT(B30)+N(IFERROR(INDEX(Crops!$F$6:$F$65,MATCH(C30,Crops!$B$6:$B$65,0)),0)),"")) | J30: =IF(NOT(AND(C30<>"",ISNUMBER(B30))),"",IF(ISNUMBER(G30),"Done",IF(INT(B30)>TODAY(),"Planned",IF(COUNTIFS(Harvest!$C$6:$C$1505,C30,Harvest!$D$6:$D$1505,D30&"",Harvest!$L$6:$L$1505,">="&INT(B30))>0,"Picking","Growing")))) | K30: =IF(OR(NOT(AND(C30<>"",ISNUMBER(B30))),J30="Planned"),"",IF(ISNUMBER(G30),INT(G30),TODAY())-INT(B30)) | L30: =IF(AND(B30="",C30="",D30=""),"",IF(NOT(ISNUMBER(B30)),"Needs a date",IF(C30="","Needs a crop",IF(COUNTIF(Crops!$B$6:$B$65,C30)=0,"Not on Crops",IF(AND(D30<>"",COUNTIF(Beds!$B$6:$B$35,D30)=0),"Not on Beds",IF(AND(ISNUMBER(G30),G30<B30),"Cleared before it was planted","")))))) | M30: =IF(OR(L30<>"",D30="",O30=""),"",IF(COUNTIFS(Plantings!$D$6:$D$505,D30,Plantings!$O$6:$O$505,O30,Plantings!$N$6:$N$505,N30-1)>0,"Same family here last year","")) | N30: =IF(ISNUMBER(B30),YEAR(B30),"") | O30: =IF(C30="","",IFERROR(INDEX(Crops!$C$6:$C$65,MATCH(C30,Crops!$B$6:$B$65,0))&"","")) | P30: =IF(ISNUMBER(B30),INT(B30),0) | Q30: =IF(AND(L30="",OR(J30="Growing",J30="Picking")),1,0) | R30: =IF(AND(Q30=1,D30<>""),P30*1000+ROW(),0) | S30: =IF(AND(AND(C30<>"",ISNUMBER(B30)),L30=""),1,0)
I31: =IF(NOT(AND(C31<>"",ISNUMBER(B31))),"",IF(N(IFERROR(INDEX(Crops!$F$6:$F$65,MATCH(C31,Crops!$B$6:$B$65,0)),0))>0,INT(B31)+N(IFERROR(INDEX(Crops!$F$6:$F$65,MATCH(C31,Crops!$B$6:$B$65,0)),0)),"")) | J31: =IF(NOT(AND(C31<>"",ISNUMBER(B31))),"",IF(ISNUMBER(G31),"Done",IF(INT(B31)>TODAY(),"Planned",IF(COUNTIFS(Harvest!$C$6:$C$1505,C31,Harvest!$D$6:$D$1505,D31&"",Harvest!$L$6:$L$1505,">="&INT(B31))>0,"Picking","Growing")))) | K31: =IF(OR(NOT(AND(C31<>"",ISNUMBER(B31))),J31="Planned"),"",IF(ISNUMBER(G31),INT(G31),TODAY())-INT(B31)) | L31: =IF(AND(B31="",C31="",D31=""),"",IF(NOT(ISNUMBER(B31)),"Needs a date",IF(C31="","Needs a crop",IF(COUNTIF(Crops!$B$6:$B$65,C31)=0,"Not on Crops",IF(AND(D31<>"",COUNTIF(Beds!$B$6:$B$35,D31)=0),"Not on Beds",IF(AND(ISNUMBER(G31),G31<B31),"Cleared before it was planted","")))))) | M31: =IF(OR(L31<>"",D31="",O31=""),"",IF(COUNTIFS(Plantings!$D$6:$D$505,D31,Plantings!$O$6:$O$505,O31,Plantings!$N$6:$N$505,N31-1)>0,"Same family here last year","")) | N31: =IF(ISNUMBER(B31),YEAR(B31),"") | O31: =IF(C31="","",IFERROR(INDEX(Crops!$C$6:$C$65,MATCH(C31,Crops!$B$6:$B$65,0))&"","")) | P31: =IF(ISNUMBER(B31),INT(B31),0) | Q31: =IF(AND(L31="",OR(J31="Growing",J31="Picking")),1,0) | R31: =IF(AND(Q31=1,D31<>""),P31*1000+ROW(),0) | S31: =IF(AND(AND(C31<>"",ISNUMBER(B31)),L31=""),1,0)
I32: =IF(NOT(AND(C32<>"",ISNUMBER(B32))),"",IF(N(IFERROR(INDEX(Crops!$F$6:$F$65,MATCH(C32,Crops!$B$6:$B$65,0)),0))>0,INT(B32)+N(IFERROR(INDEX(Crops!$F$6:$F$65,MATCH(C32,Crops!$B$6:$B$65,0)),0)),"")) | J32: =IF(NOT(AND(C32<>"",ISNUMBER(B32))),"",IF(ISNUMBER(G32),"Done",IF(INT(B32)>TODAY(),"Planned",IF(COUNTIFS(Harvest!$C$6:$C$1505,C32,Harvest!$D$6:$D$1505,D32&"",Harvest!$L$6:$L$1505,">="&INT(B32))>0,"Picking","Growing")))) | K32: =IF(OR(NOT(AND(C32<>"",ISNUMBER(B32))),J32="Planned"),"",IF(ISNUMBER(G32),INT(G32),TODAY())-INT(B32)) | L32: =IF(AND(B32="",C32="",D32=""),"",IF(NOT(ISNUMBER(B32)),"Needs a date",IF(C32="","Needs a crop",IF(COUNTIF(Crops!$B$6:$B$65,C32)=0,"Not on Crops",IF(AND(D32<>"",COUNTIF(Beds!$B$6:$B$35,D32)=0),"Not on Beds",IF(AND(ISNUMBER(G32),G32<B32),"Cleared before it was planted","")))))) | M32: =IF(OR(L32<>"",D32="",O32=""),"",IF(COUNTIFS(Plantings!$D$6:$D$505,D32,Plantings!$O$6:$O$505,O32,Plantings!$N$6:$N$505,N32-1)>0,"Same family here last year","")) | N32: =IF(ISNUMBER(B32),YEAR(B32),"") | O32: =IF(C32="","",IFERROR(INDEX(Crops!$C$6:$C$65,MATCH(C32,Crops!$B$6:$B$65,0))&"","")) | P32: =IF(ISNUMBER(B32),INT(B32),0) | Q32: =IF(AND(L32="",OR(J32="Growing",J32="Picking")),1,0) | R32: =IF(AND(Q32=1,D32<>""),P32*1000+ROW(),0) | S32: =IF(AND(AND(C32<>"",ISNUMBER(B32)),L32=""),1,0)
I33: =IF(NOT(AND(C33<>"",ISNUMBER(B33))),"",IF(N(IFERROR(INDEX(Crops!$F$6:$F$65,MATCH(C33,Crops!$B$6:$B$65,0)),0))>0,INT(B33)+N(IFERROR(INDEX(Crops!$F$6:$F$65,MATCH(C33,Crops!$B$6:$B$65,0)),0)),"")) | J33: =IF(NOT(AND(C33<>"",ISNUMBER(B33))),"",IF(ISNUMBER(G33),"Done",IF(INT(B33)>TODAY(),"Planned",IF(COUNTIFS(Harvest!$C$6:$C$1505,C33,Harvest!$D$6:$D$1505,D33&"",Harvest!$L$6:$L$1505,">="&INT(B33))>0,"Picking","Growing")))) | K33: =IF(OR(NOT(AND(C33<>"",ISNUMBER(B33))),J33="Planned"),"",IF(ISNUMBER(G33),INT(G33),TODAY())-INT(B33)) | L33: =IF(AND(B33="",C33="",D33=""),"",IF(NOT(ISNUMBER(B33)),"Needs a date",IF(C33="","Needs a crop",IF(COUNTIF(Crops!$B$6:$B$65,C33)=0,"Not on Crops",IF(AND(D33<>"",COUNTIF(Beds!$B$6:$B$35,D33)=0),"Not on Beds",IF(AND(ISNUMBER(G33),G33<B33),"Cleared before it was planted","")))))) | M33: =IF(OR(L33<>"",D33="",O33=""),"",IF(COUNTIFS(Plantings!$D$6:$D$505,D33,Plantings!$O$6:$O$505,O33,Plantings!$N$6:$N$505,N33-1)>0,"Same family here last year","")) | N33: =IF(ISNUMBER(B33),YEAR(B33),"") | O33: =IF(C33="","",IFERROR(INDEX(Crops!$C$6:$C$65,MATCH(C33,Crops!$B$6:$B$65,0))&"","")) | P33: =IF(ISNUMBER(B33),INT(B33),0) | Q33: =IF(AND(L33="",OR(J33="Growing",J33="Picking")),1,0) | R33: =IF(AND(Q33=1,D33<>""),P33*1000+ROW(),0) | S33: =IF(AND(AND(C33<>"",ISNUMBER(B33)),L33=""),1,0)
I34: =IF(NOT(AND(C34<>"",ISNUMBER(B34))),"",IF(N(IFERROR(INDEX(Crops!$F$6:$F$65,MATCH(C34,Crops!$B$6:$B$65,0)),0))>0,INT(B34)+N(IFERROR(INDEX(Crops!$F$6:$F$65,MATCH(C34,Crops!$B$6:$B$65,0)),0)),"")) | J34: =IF(NOT(AND(C34<>"",ISNUMBER(B34))),"",IF(ISNUMBER(G34),"Done",IF(INT(B34)>TODAY(),"Planned",IF(COUNTIFS(Harvest!$C$6:$C$1505,C34,Harvest!$D$6:$D$1505,D34&"",Harvest!$L$6:$L$1505,">="&INT(B34))>0,"Picking","Growing")))) | K34: =IF(OR(NOT(AND(C34<>"",ISNUMBER(B34))),J34="Planned"),"",IF(ISNUMBER(G34),INT(G34),TODAY())-INT(B34)) | L34: =IF(AND(B34="",C34="",D34=""),"",IF(NOT(ISNUMBER(B34)),"Needs a date",IF(C34="","Needs a crop",IF(COUNTIF(Crops!$B$6:$B$65,C34)=0,"Not on Crops",IF(AND(D34<>"",COUNTIF(Beds!$B$6:$B$35,D34)=0),"Not on Beds",IF(AND(ISNUMBER(G34),G34<B34),"Cleared before it was planted","")))))) | M34: =IF(OR(L34<>"",D34="",O34=""),"",IF(COUNTIFS(Plantings!$D$6:$D$505,D34,Plantings!$O$6:$O$505,O34,Plantings!$N$6:$N$505,N34-1)>0,"Same family here last year","")) | N34: =IF(ISNUMBER(B34),YEAR(B34),"") | O34: =IF(C34="","",IFERROR(INDEX(Crops!$C$6:$C$65,MATCH(C34,Crops!$B$6:$B$65,0))&"","")) | P34: =IF(ISNUMBER(B34),INT(B34),0) | Q34: =IF(AND(L34="",OR(J34="Growing",J34="Picking")),1,0) | R34: =IF(AND(Q34=1,D34<>""),P34*1000+ROW(),0) | S34: =IF(AND(AND(C34<>"",ISNUMBER(B34)),L34=""),1,0)
I35: =IF(NOT(AND(C35<>"",ISNUMBER(B35))),"",IF(N(IFERROR(INDEX(Crops!$F$6:$F$65,MATCH(C35,Crops!$B$6:$B$65,0)),0))>0,INT(B35)+N(IFERROR(INDEX(Crops!$F$6:$F$65,MATCH(C35,Crops!$B$6:$B$65,0)),0)),"")) | J35: =IF(NOT(AND(C35<>"",ISNUMBER(B35))),"",IF(ISNUMBER(G35),"Done",IF(INT(B35)>TODAY(),"Planned",IF(COUNTIFS(Harvest!$C$6:$C$1505,C35,Harvest!$D$6:$D$1505,D35&"",Harvest!$L$6:$L$1505,">="&INT(B35))>0,"Picking","Growing")))) | K35: =IF(OR(NOT(AND(C35<>"",ISNUMBER(B35))),J35="Planned"),"",IF(ISNUMBER(G35),INT(G35),TODAY())-INT(B35)) | L35: =IF(AND(B35="",C35="",D35=""),"",IF(NOT(ISNUMBER(B35)),"Needs a date",IF(C35="","Needs a crop",IF(COUNTIF(Crops!$B$6:$B$65,C35)=0,"Not on Crops",IF(AND(D35<>"",COUNTIF(Beds!$B$6:$B$35,D35)=0),"Not on Beds",IF(AND(ISNUMBER(G35),G35<B35),"Cleared before it was planted","")))))) | M35: =IF(OR(L35<>"",D35="",O35=""),"",IF(COUNTIFS(Plantings!$D$6:$D$505,D35,Plantings!$O$6:$O$505,O35,Plantings!$N$6:$N$505,N35-1)>0,"Same family here last year","")) | N35: =IF(ISNUMBER(B35),YEAR(B35),"") | O35: =IF(C35="","",IFERROR(INDEX(Crops!$C$6:$C$65,MATCH(C35,Crops!$B$6:$B$65,0))&"","")) | P35: =IF(ISNUMBER(B35),INT(B35),0) | Q35: =IF(AND(L35="",OR(J35="Growing",J35="Picking")),1,0) | R35: =IF(AND(Q35=1,D35<>""),P35*1000+ROW(),0) | S35: =IF(AND(AND(C35<>"",ISNUMBER(B35)),L35=""),1,0)
I36: =IF(NOT(AND(C36<>"",ISNUMBER(B36))),"",IF(N(IFERROR(INDEX(Crops!$F$6:$F$65,MATCH(C36,Crops!$B$6:$B$65,0)),0))>0,INT(B36)+N(IFERROR(INDEX(Crops!$F$6:$F$65,MATCH(C36,Crops!$B$6:$B$65,0)),0)),"")) | J36: =IF(NOT(AND(C36<>"",ISNUMBER(B36))),"",IF(ISNUMBER(G36),"Done",IF(INT(B36)>TODAY(),"Planned",IF(COUNTIFS(Harvest!$C$6:$C$1505,C36,Harvest!$D$6:$D$1505,D36&"",Harvest!$L$6:$L$1505,">="&INT(B36))>0,"Picking","Growing")))) | K36: =IF(OR(NOT(AND(C36<>"",ISNUMBER(B36))),J36="Planned"),"",IF(ISNUMBER(G36),INT(G36),TODAY())-INT(B36)) | L36: =IF(AND(B36="",C36="",D36=""),"",IF(NOT(ISNUMBER(B36)),"Needs a date",IF(C36="","Needs a crop",IF(COUNTIF(Crops!$B$6:$B$65,C36)=0,"Not on Crops",IF(AND(D36<>"",COUNTIF(Beds!$B$6:$B$35,D36)=0),"Not on Beds",IF(AND(ISNUMBER(G36),G36<B36),"Cleared before it was planted","")))))) | M36: =IF(OR(L36<>"",D36="",O36=""),"",IF(COUNTIFS(Plantings!$D$6:$D$505,D36,Plantings!$O$6:$O$505,O36,Plantings!$N$6:$N$505,N36-1)>0,"Same family here last year","")) | N36: =IF(ISNUMBER(B36),YEAR(B36),"") | O36: =IF(C36="","",IFERROR(INDEX(Crops!$C$6:$C$65,MATCH(C36,Crops!$B$6:$B$65,0))&"","")) | P36: =IF(ISNUMBER(B36),INT(B36),0) | Q36: =IF(AND(L36="",OR(J36="Growing",J36="Picking")),1,0) | R36: =IF(AND(Q36=1,D36<>""),P36*1000+ROW(),0) | S36: =IF(AND(AND(C36<>"",ISNUMBER(B36)),L36=""),1,0)
I37: =IF(NOT(AND(C37<>"",ISNUMBER(B37))),"",IF(N(IFERROR(INDEX(Crops!$F$6:$F$65,MATCH(C37,Crops!$B$6:$B$65,0)),0))>0,INT(B37)+N(IFERROR(INDEX(Crops!$F$6:$F$65,MATCH(C37,Crops!$B$6:$B$65,0)),0)),"")) | J37: =IF(NOT(AND(C37<>"",ISNUMBER(B37))),"",IF(ISNUMBER(G37),"Done",IF(INT(B37)>TODAY(),"Planned",IF(COUNTIFS(Harvest!$C$6:$C$1505,C37,Harvest!$D$6:$D$1505,D37&"",Harvest!$L$6:$L$1505,">="&INT(B37))>0,"Picking","Growing")))) | K37: =IF(OR(NOT(AND(C37<>"",ISNUMBER(B37))),J37="Planned"),"",IF(ISNUMBER(G37),INT(G37),TODAY())-INT(B37)) | L37: =IF(AND(B37="",C37="",D37=""),"",IF(NOT(ISNUMBER(B37)),"Needs a date",IF(C37="","Needs a crop",IF(COUNTIF(Crops!$B$6:$B$65,C37)=0,"Not on Crops",IF(AND(D37<>"",COUNTIF(Beds!$B$6:$B$35,D37)=0),"Not on Beds",IF(AND(ISNUMBER(G37),G37<B37),"Cleared before it was planted","")))))) | M37: =IF(OR(L37<>"",D37="",O37=""),"",IF(COUNTIFS(Plantings!$D$6:$D$505,D37,Plantings!$O$6:$O$505,O37,Plantings!$N$6:$N$505,N37-1)>0,"Same family here last year","")) | N37: =IF(ISNUMBER(B37),YEAR(B37),"") | O37: =IF(C37="","",IFERROR(INDEX(Crops!$C$6:$C$65,MATCH(C37,Crops!$B$6:$B$65,0))&"","")) | P37: =IF(ISNUMBER(B37),INT(B37),0) | Q37: =IF(AND(L37="",OR(J37="Growing",J37="Picking")),1,0) | R37: =IF(AND(Q37=1,D37<>""),P37*1000+ROW(),0) | S37: =IF(AND(AND(C37<>"",ISNUMBER(B37)),L37=""),1,0)
I38: =IF(NOT(AND(C38<>"",ISNUMBER(B38))),"",IF(N(IFERROR(INDEX(Crops!$F$6:$F$65,MATCH(C38,Crops!$B$6:$B$65,0)),0))>0,INT(B38)+N(IFERROR(INDEX(Crops!$F$6:$F$65,MATCH(C38,Crops!$B$6:$B$65,0)),0)),"")) | J38: =IF(NOT(AND(C38<>"",ISNUMBER(B38))),"",IF(ISNUMBER(G38),"Done",IF(INT(B38)>TODAY(),"Planned",IF(COUNTIFS(Harvest!$C$6:$C$1505,C38,Harvest!$D$6:$D$1505,D38&"",Harvest!$L$6:$L$1505,">="&INT(B38))>0,"Picking","Growing")))) | K38: =IF(OR(NOT(AND(C38<>"",ISNUMBER(B38))),J38="Planned"),"",IF(ISNUMBER(G38),INT(G38),TODAY())-INT(B38)) | L38: =IF(AND(B38="",C38="",D38=""),"",IF(NOT(ISNUMBER(B38)),"Needs a date",IF(C38="","Needs a crop",IF(COUNTIF(Crops!$B$6:$B$65,C38)=0,"Not on Crops",IF(AND(D38<>"",COUNTIF(Beds!$B$6:$B$35,D38)=0),"Not on Beds",IF(AND(ISNUMBER(G38),G38<B38),"Cleared before it was planted","")))))) | M38: =IF(OR(L38<>"",D38="",O38=""),"",IF(COUNTIFS(Plantings!$D$6:$D$505,D38,Plantings!$O$6:$O$505,O38,Plantings!$N$6:$N$505,N38-1)>0,"Same family here last year","")) | N38: =IF(ISNUMBER(B38),YEAR(B38),"") | O38: =IF(C38="","",IFERROR(INDEX(Crops!$C$6:$C$65,MATCH(C38,Crops!$B$6:$B$65,0))&"","")) | P38: =IF(ISNUMBER(B38),INT(B38),0) | Q38: =IF(AND(L38="",OR(J38="Growing",J38="Picking")),1,0) | R38: =IF(AND(Q38=1,D38<>""),P38*1000+ROW(),0) | S38: =IF(AND(AND(C38<>"",ISNUMBER(B38)),L38=""),1,0)
I39: =IF(NOT(AND(C39<>"",ISNUMBER(B39))),"",IF(N(IFERROR(INDEX(Crops!$F$6:$F$65,MATCH(C39,Crops!$B$6:$B$65,0)),0))>0,INT(B39)+N(IFERROR(INDEX(Crops!$F$6:$F$65,MATCH(C39,Crops!$B$6:$B$65,0)),0)),"")) | J39: =IF(NOT(AND(C39<>"",ISNUMBER(B39))),"",IF(ISNUMBER(G39),"Done",IF(INT(B39)>TODAY(),"Planned",IF(COUNTIFS(Harvest!$C$6:$C$1505,C39,Harvest!$D$6:$D$1505,D39&"",Harvest!$L$6:$L$1505,">="&INT(B39))>0,"Picking","Growing")))) | K39: =IF(OR(NOT(AND(C39<>"",ISNUMBER(B39))),J39="Planned"),"",IF(ISNUMBER(G39),INT(G39),TODAY())-INT(B39)) | L39: =IF(AND(B39="",C39="",D39=""),"",IF(NOT(ISNUMBER(B39)),"Needs a date",IF(C39="","Needs a crop",IF(COUNTIF(Crops!$B$6:$B$65,C39)=0,"Not on Crops",IF(AND(D39<>"",COUNTIF(Beds!$B$6:$B$35,D39)=0),"Not on Beds",IF(AND(ISNUMBER(G39),G39<B39),"Cleared before it was planted","")))))) | M39: =IF(OR(L39<>"",D39="",O39=""),"",IF(COUNTIFS(Plantings!$D$6:$D$505,D39,Plantings!$O$6:$O$505,O39,Plantings!$N$6:$N$505,N39-1)>0,"Same family here last year","")) | N39: =IF(ISNUMBER(B39),YEAR(B39),"") | O39: =IF(C39="","",IFERROR(INDEX(Crops!$C$6:$C$65,MATCH(C39,Crops!$B$6:$B$65,0))&"","")) | P39: =IF(ISNUMBER(B39),INT(B39),0) | Q39: =IF(AND(L39="",OR(J39="Growing",J39="Picking")),1,0) | R39: =IF(AND(Q39=1,D39<>""),P39*1000+ROW(),0) | S39: =IF(AND(AND(C39<>"",ISNUMBER(B39)),L39=""),1,0)
I40: =IF(NOT(AND(C40<>"",ISNUMBER(B40))),"",IF(N(IFERROR(INDEX(Crops!$F$6:$F$65,MATCH(C40,Crops!$B$6:$B$65,0)),0))>0,INT(B40)+N(IFERROR(INDEX(Crops!$F$6:$F$65,MATCH(C40,Crops!$B$6:$B$65,0)),0)),"")) | J40: =IF(NOT(AND(C40<>"",ISNUMBER(B40))),"",IF(ISNUMBER(G40),"Done",IF(INT(B40)>TODAY(),"Planned",IF(COUNTIFS(Harvest!$C$6:$C$1505,C40,Harvest!$D$6:$D$1505,D40&"",Harvest!$L$6:$L$1505,">="&INT(B40))>0,"Picking","Growing")))) | K40: =IF(OR(NOT(AND(C40<>"",ISNUMBER(B40))),J40="Planned"),"",IF(ISNUMBER(G40),INT(G40),TODAY())-INT(B40)) | L40: =IF(AND(B40="",C40="",D40=""),"",IF(NOT(ISNUMBER(B40)),"Needs a date",IF(C40="","Needs a crop",IF(COUNTIF(Crops!$B$6:$B$65,C40)=0,"Not on Crops",IF(AND(D40<>"",COUNTIF(Beds!$B$6:$B$35,D40)=0),"Not on Beds",IF(AND(ISNUMBER(G40),G40<B40),"Cleared before it was planted","")))))) | M40: =IF(OR(L40<>"",D40="",O40=""),"",IF(COUNTIFS(Plantings!$D$6:$D$505,D40,Plantings!$O$6:$O$505,O40,Plantings!$N$6:$N$505,N40-1)>0,"Same family here last year","")) | N40: =IF(ISNUMBER(B40),YEAR(B40),"") | O40: =IF(C40="","",IFERROR(INDEX(Crops!$C$6:$C$65,MATCH(C40,Crops!$B$6:$B$65,0))&"","")) | P40: =IF(ISNUMBER(B40),INT(B40),0) | Q40: =IF(AND(L40="",OR(J40="Growing",J40="Picking")),1,0) | R40: =IF(AND(Q40=1,D40<>""),P40*1000+ROW(),0) | S40: =IF(AND(AND(C40<>"",ISNUMBER(B40)),L40=""),1,0)
