Workbook

Sheet Dashboard
B2: Giving and volunteering
B3: ="The year "&Settings!$C$7&", with the campaigns and the thank-you notes still to send."
B4: Given this year | C4: Gifts | D4: Average gift | E4: Donors | G4: New donors | H4: Lapsed | I4: To thank | J4: Volunteer hours
B5: =SUMIFS(Gifts!$D$6:$D$1005,Gifts!$K$6:$K$1005,Settings!$C$7,Gifts!$D$6:$D$1005,">0") | C5: =SUMIFS(Gifts!$Q$6:$Q$1005,Gifts!$K$6:$K$1005,Settings!$C$7) | D5: =IF(COUNTIFS(Gifts!$K$6:$K$1005,Settings!$C$7,Gifts!$D$6:$D$1005,">0")=0,"",B5/COUNTIFS(Gifts!$K$6:$K$1005,Settings!$C$7,Gifts!$D$6:$D$1005,">0")) | E5: =COUNTIF(Donors!$N$6:$N$305,">0") | G5: =COUNTIFS(Donors!$F$6:$F$305,">="&DATE(N(Settings!$C$7),1,1),Donors!$F$6:$F$305,"<"&DATE(N(Settings!$C$7)+1,1,1)) | H5: =COUNTIF(Donors!$K$6:$K$305,"Lapsed") | I5: =COUNT(Gifts!$O$6:$O$1005) | J5: =SUMIFS(Hours!$D$6:$D$1005,Hours!$I$6:$I$1005,Settings!$C$7,Hours!$D$6:$D$1005,">0")
B7: Campaign | C7: Goal | D7: Raised | E7: Of goal | G7: To thank | H7: Date | I7: Amount | J7: Campaign
B8: =IF(Campaigns!B6="","",Campaigns!B6) | C8: =IF(B8="","",IF(N(Campaigns!C6)=0,"",Campaigns!C6)) | D8: =IF(B8="","",Campaigns!F6) | E8: =IF(B8="","",Campaigns!G6) | G8: =IF(N8="","",INDEX(Gifts!$C$1:$C$1005,MOD(N8,10000))) | H8: =IF(N8="","",INDEX(Gifts!$B$1:$B$1005,MOD(N8,10000))) | I8: =IF(N8="","",IF(N(INDEX(Gifts!$D$1:$D$1005,MOD(N8,10000)))=0,"Goods",INDEX(Gifts!$D$1:$D$1005,MOD(N8,10000)))) | J8: =IF(N8="","",IF(INDEX(Gifts!$F$1:$F$1005,MOD(N8,10000))="","",INDEX(Gifts!$F$1:$F$1005,MOD(N8,10000)))) | N8: =IFERROR(SMALL(Gifts!$O$6:$O$1005,1),"")
B9: =IF(Campaigns!B7="","",Campaigns!B7) | C9: =IF(B9="","",IF(N(Campaigns!C7)=0,"",Campaigns!C7)) | D9: =IF(B9="","",Campaigns!F7) | E9: =IF(B9="","",Campaigns!G7) | G9: =IF(N9="","",INDEX(Gifts!$C$1:$C$1005,MOD(N9,10000))) | H9: =IF(N9="","",INDEX(Gifts!$B$1:$B$1005,MOD(N9,10000))) | I9: =IF(N9="","",IF(N(INDEX(Gifts!$D$1:$D$1005,MOD(N9,10000)))=0,"Goods",INDEX(Gifts!$D$1:$D$1005,MOD(N9,10000)))) | J9: =IF(N9="","",IF(INDEX(Gifts!$F$1:$F$1005,MOD(N9,10000))="","",INDEX(Gifts!$F$1:$F$1005,MOD(N9,10000)))) | N9: =IFERROR(SMALL(Gifts!$O$6:$O$1005,2),"")
B10: =IF(Campaigns!B8="","",Campaigns!B8) | C10: =IF(B10="","",IF(N(Campaigns!C8)=0,"",Campaigns!C8)) | D10: =IF(B10="","",Campaigns!F8) | E10: =IF(B10="","",Campaigns!G8) | G10: =IF(N10="","",INDEX(Gifts!$C$1:$C$1005,MOD(N10,10000))) | H10: =IF(N10="","",INDEX(Gifts!$B$1:$B$1005,MOD(N10,10000))) | I10: =IF(N10="","",IF(N(INDEX(Gifts!$D$1:$D$1005,MOD(N10,10000)))=0,"Goods",INDEX(Gifts!$D$1:$D$1005,MOD(N10,10000)))) | J10: =IF(N10="","",IF(INDEX(Gifts!$F$1:$F$1005,MOD(N10,10000))="","",INDEX(Gifts!$F$1:$F$1005,MOD(N10,10000)))) | N10: =IFERROR(SMALL(Gifts!$O$6:$O$1005,3),"")
B11: =IF(Campaigns!B9="","",Campaigns!B9) | C11: =IF(B11="","",IF(N(Campaigns!C9)=0,"",Campaigns!C9)) | D11: =IF(B11="","",Campaigns!F9) | E11: =IF(B11="","",Campaigns!G9) | G11: =IF(N11="","",INDEX(Gifts!$C$1:$C$1005,MOD(N11,10000))) | H11: =IF(N11="","",INDEX(Gifts!$B$1:$B$1005,MOD(N11,10000))) | I11: =IF(N11="","",IF(N(INDEX(Gifts!$D$1:$D$1005,MOD(N11,10000)))=0,"Goods",INDEX(Gifts!$D$1:$D$1005,MOD(N11,10000)))) | J11: =IF(N11="","",IF(INDEX(Gifts!$F$1:$F$1005,MOD(N11,10000))="","",INDEX(Gifts!$F$1:$F$1005,MOD(N11,10000)))) | N11: =IFERROR(SMALL(Gifts!$O$6:$O$1005,4),"")
B12: =IF(Campaigns!B10="","",Campaigns!B10) | C12: =IF(B12="","",IF(N(Campaigns!C10)=0,"",Campaigns!C10)) | D12: =IF(B12="","",Campaigns!F10) | E12: =IF(B12="","",Campaigns!G10) | G12: =IF(N12="","",INDEX(Gifts!$C$1:$C$1005,MOD(N12,10000))) | H12: =IF(N12="","",INDEX(Gifts!$B$1:$B$1005,MOD(N12,10000))) | I12: =IF(N12="","",IF(N(INDEX(Gifts!$D$1:$D$1005,MOD(N12,10000)))=0,"Goods",INDEX(Gifts!$D$1:$D$1005,MOD(N12,10000)))) | J12: =IF(N12="","",IF(INDEX(Gifts!$F$1:$F$1005,MOD(N12,10000))="","",INDEX(Gifts!$F$1:$F$1005,MOD(N12,10000)))) | N12: =IFERROR(SMALL(Gifts!$O$6:$O$1005,5),"")
B13: =IF(Campaigns!B11="","",Campaigns!B11) | C13: =IF(B13="","",IF(N(Campaigns!C11)=0,"",Campaigns!C11)) | D13: =IF(B13="","",Campaigns!F11) | E13: =IF(B13="","",Campaigns!G11) | G13: =IF(N13="","",INDEX(Gifts!$C$1:$C$1005,MOD(N13,10000))) | H13: =IF(N13="","",INDEX(Gifts!$B$1:$B$1005,MOD(N13,10000))) | I13: =IF(N13="","",IF(N(INDEX(Gifts!$D$1:$D$1005,MOD(N13,10000)))=0,"Goods",INDEX(Gifts!$D$1:$D$1005,MOD(N13,10000)))) | J13: =IF(N13="","",IF(INDEX(Gifts!$F$1:$F$1005,MOD(N13,10000))="","",INDEX(Gifts!$F$1:$F$1005,MOD(N13,10000)))) | N13: =IFERROR(SMALL(Gifts!$O$6:$O$1005,6),"")
B15: Month | C15: Given | D15: Gifts | E15: Hours | G15: Top donors | H15: This year | I15: Gifts | J15: Last gift
B16: Jan | C16: =SUMIFS(Gifts!$D$6:$D$1005,Gifts!$L$6:$L$1005,(Settings!$C$7*100+1),Gifts!$D$6:$D$1005,">0") | D16: =SUMIFS(Gifts!$Q$6:$Q$1005,Gifts!$L$6:$L$1005,(Settings!$C$7*100+1)) | E16: =SUMIFS(Hours!$D$6:$D$1005,Hours!$J$6:$J$1005,(Settings!$C$7*100+1),Hours!$D$6:$D$1005,">0") | G16: =IF(O16="","",INDEX(Donors!$B$1:$B$305,1000-MOD(O16,1000))) | H16: =IF(O16="","",INDEX(Donors!$H$1:$H$305,1000-MOD(O16,1000))) | I16: =IF(O16="","",INDEX(Donors!$N$1:$N$305,1000-MOD(O16,1000))) | J16: =IF(O16="","",INDEX(Donors!$G$1:$G$305,1000-MOD(O16,1000))) | O16: =IFERROR(LARGE(Donors!$M$6:$M$305,1),"")
B17: Feb | C17: =SUMIFS(Gifts!$D$6:$D$1005,Gifts!$L$6:$L$1005,(Settings!$C$7*100+2),Gifts!$D$6:$D$1005,">0") | D17: =SUMIFS(Gifts!$Q$6:$Q$1005,Gifts!$L$6:$L$1005,(Settings!$C$7*100+2)) | E17: =SUMIFS(Hours!$D$6:$D$1005,Hours!$J$6:$J$1005,(Settings!$C$7*100+2),Hours!$D$6:$D$1005,">0") | G17: =IF(O17="","",INDEX(Donors!$B$1:$B$305,1000-MOD(O17,1000))) | H17: =IF(O17="","",INDEX(Donors!$H$1:$H$305,1000-MOD(O17,1000))) | I17: =IF(O17="","",INDEX(Donors!$N$1:$N$305,1000-MOD(O17,1000))) | J17: =IF(O17="","",INDEX(Donors!$G$1:$G$305,1000-MOD(O17,1000))) | O17: =IFERROR(LARGE(Donors!$M$6:$M$305,2),"")
B18: Mar | C18: =SUMIFS(Gifts!$D$6:$D$1005,Gifts!$L$6:$L$1005,(Settings!$C$7*100+3),Gifts!$D$6:$D$1005,">0") | D18: =SUMIFS(Gifts!$Q$6:$Q$1005,Gifts!$L$6:$L$1005,(Settings!$C$7*100+3)) | E18: =SUMIFS(Hours!$D$6:$D$1005,Hours!$J$6:$J$1005,(Settings!$C$7*100+3),Hours!$D$6:$D$1005,">0") | G18: =IF(O18="","",INDEX(Donors!$B$1:$B$305,1000-MOD(O18,1000))) | H18: =IF(O18="","",INDEX(Donors!$H$1:$H$305,1000-MOD(O18,1000))) | I18: =IF(O18="","",INDEX(Donors!$N$1:$N$305,1000-MOD(O18,1000))) | J18: =IF(O18="","",INDEX(Donors!$G$1:$G$305,1000-MOD(O18,1000))) | O18: =IFERROR(LARGE(Donors!$M$6:$M$305,3),"")
B19: Apr | C19: =SUMIFS(Gifts!$D$6:$D$1005,Gifts!$L$6:$L$1005,(Settings!$C$7*100+4),Gifts!$D$6:$D$1005,">0") | D19: =SUMIFS(Gifts!$Q$6:$Q$1005,Gifts!$L$6:$L$1005,(Settings!$C$7*100+4)) | E19: =SUMIFS(Hours!$D$6:$D$1005,Hours!$J$6:$J$1005,(Settings!$C$7*100+4),Hours!$D$6:$D$1005,">0") | G19: =IF(O19="","",INDEX(Donors!$B$1:$B$305,1000-MOD(O19,1000))) | H19: =IF(O19="","",INDEX(Donors!$H$1:$H$305,1000-MOD(O19,1000))) | I19: =IF(O19="","",INDEX(Donors!$N$1:$N$305,1000-MOD(O19,1000))) | J19: =IF(O19="","",INDEX(Donors!$G$1:$G$305,1000-MOD(O19,1000))) | O19: =IFERROR(LARGE(Donors!$M$6:$M$305,4),"")
B20: May | C20: =SUMIFS(Gifts!$D$6:$D$1005,Gifts!$L$6:$L$1005,(Settings!$C$7*100+5),Gifts!$D$6:$D$1005,">0") | D20: =SUMIFS(Gifts!$Q$6:$Q$1005,Gifts!$L$6:$L$1005,(Settings!$C$7*100+5)) | E20: =SUMIFS(Hours!$D$6:$D$1005,Hours!$J$6:$J$1005,(Settings!$C$7*100+5),Hours!$D$6:$D$1005,">0") | G20: =IF(O20="","",INDEX(Donors!$B$1:$B$305,1000-MOD(O20,1000))) | H20: =IF(O20="","",INDEX(Donors!$H$1:$H$305,1000-MOD(O20,1000))) | I20: =IF(O20="","",INDEX(Donors!$N$1:$N$305,1000-MOD(O20,1000))) | J20: =IF(O20="","",INDEX(Donors!$G$1:$G$305,1000-MOD(O20,1000))) | O20: =IFERROR(LARGE(Donors!$M$6:$M$305,5),"")
B21: Jun | C21: =SUMIFS(Gifts!$D$6:$D$1005,Gifts!$L$6:$L$1005,(Settings!$C$7*100+6),Gifts!$D$6:$D$1005,">0") | D21: =SUMIFS(Gifts!$Q$6:$Q$1005,Gifts!$L$6:$L$1005,(Settings!$C$7*100+6)) | E21: =SUMIFS(Hours!$D$6:$D$1005,Hours!$J$6:$J$1005,(Settings!$C$7*100+6),Hours!$D$6:$D$1005,">0") | G21: =IF(O21="","",INDEX(Donors!$B$1:$B$305,1000-MOD(O21,1000))) | H21: =IF(O21="","",INDEX(Donors!$H$1:$H$305,1000-MOD(O21,1000))) | I21: =IF(O21="","",INDEX(Donors!$N$1:$N$305,1000-MOD(O21,1000))) | J21: =IF(O21="","",INDEX(Donors!$G$1:$G$305,1000-MOD(O21,1000))) | O21: =IFERROR(LARGE(Donors!$M$6:$M$305,6),"")
B22: Jul | C22: =SUMIFS(Gifts!$D$6:$D$1005,Gifts!$L$6:$L$1005,(Settings!$C$7*100+7),Gifts!$D$6:$D$1005,">0") | D22: =SUMIFS(Gifts!$Q$6:$Q$1005,Gifts!$L$6:$L$1005,(Settings!$C$7*100+7)) | E22: =SUMIFS(Hours!$D$6:$D$1005,Hours!$J$6:$J$1005,(Settings!$C$7*100+7),Hours!$D$6:$D$1005,">0") | G22: =IF(O22="","",INDEX(Donors!$B$1:$B$305,1000-MOD(O22,1000))) | H22: =IF(O22="","",INDEX(Donors!$H$1:$H$305,1000-MOD(O22,1000))) | I22: =IF(O22="","",INDEX(Donors!$N$1:$N$305,1000-MOD(O22,1000))) | J22: =IF(O22="","",INDEX(Donors!$G$1:$G$305,1000-MOD(O22,1000))) | O22: =IFERROR(LARGE(Donors!$M$6:$M$305,7),"")
B23: Aug | C23: =SUMIFS(Gifts!$D$6:$D$1005,Gifts!$L$6:$L$1005,(Settings!$C$7*100+8),Gifts!$D$6:$D$1005,">0") | D23: =SUMIFS(Gifts!$Q$6:$Q$1005,Gifts!$L$6:$L$1005,(Settings!$C$7*100+8)) | E23: =SUMIFS(Hours!$D$6:$D$1005,Hours!$J$6:$J$1005,(Settings!$C$7*100+8),Hours!$D$6:$D$1005,">0") | G23: =IF(O23="","",INDEX(Donors!$B$1:$B$305,1000-MOD(O23,1000))) | H23: =IF(O23="","",INDEX(Donors!$H$1:$H$305,1000-MOD(O23,1000))) | I23: =IF(O23="","",INDEX(Donors!$N$1:$N$305,1000-MOD(O23,1000))) | J23: =IF(O23="","",INDEX(Donors!$G$1:$G$305,1000-MOD(O23,1000))) | O23: =IFERROR(LARGE(Donors!$M$6:$M$305,8),"")
B24: Sep | C24: =SUMIFS(Gifts!$D$6:$D$1005,Gifts!$L$6:$L$1005,(Settings!$C$7*100+9),Gifts!$D$6:$D$1005,">0") | D24: =SUMIFS(Gifts!$Q$6:$Q$1005,Gifts!$L$6:$L$1005,(Settings!$C$7*100+9)) | E24: =SUMIFS(Hours!$D$6:$D$1005,Hours!$J$6:$J$1005,(Settings!$C$7*100+9),Hours!$D$6:$D$1005,">0")
B25: Oct | C25: =SUMIFS(Gifts!$D$6:$D$1005,Gifts!$L$6:$L$1005,(Settings!$C$7*100+10),Gifts!$D$6:$D$1005,">0") | D25: =SUMIFS(Gifts!$Q$6:$Q$1005,Gifts!$L$6:$L$1005,(Settings!$C$7*100+10)) | E25: =SUMIFS(Hours!$D$6:$D$1005,Hours!$J$6:$J$1005,(Settings!$C$7*100+10),Hours!$D$6:$D$1005,">0")
B26: Nov | C26: =SUMIFS(Gifts!$D$6:$D$1005,Gifts!$L$6:$L$1005,(Settings!$C$7*100+11),Gifts!$D$6:$D$1005,">0") | D26: =SUMIFS(Gifts!$Q$6:$Q$1005,Gifts!$L$6:$L$1005,(Settings!$C$7*100+11)) | E26: =SUMIFS(Hours!$D$6:$D$1005,Hours!$J$6:$J$1005,(Settings!$C$7*100+11),Hours!$D$6:$D$1005,">0")
B27: Dec | C27: =SUMIFS(Gifts!$D$6:$D$1005,Gifts!$L$6:$L$1005,(Settings!$C$7*100+12),Gifts!$D$6:$D$1005,">0") | D27: =SUMIFS(Gifts!$Q$6:$Q$1005,Gifts!$L$6:$L$1005,(Settings!$C$7*100+12)) | E27: =SUMIFS(Hours!$D$6:$D$1005,Hours!$J$6:$J$1005,(Settings!$C$7*100+12),Hours!$D$6:$D$1005,">0")

Sheet Gifts
B2: Gifts
B3: Every gift, with its campaign. For goods, leave the amount empty and say what was given. An x once the donor has been thanked.
B5: Date | C5: Donor | D5: Amount | E5: How | F5: Campaign | G5: Goods given | H5: Thanked | I5: Note | J5: Check
B6: 45843 | C6: Grace Holloway | D6: 25 | E6: Bank transfer | F6: General fund | H6: x | I6: Monthly | J6: =IF(AND(C6="",D6="",G6=""),"",IF(NOT(ISNUMBER(B6)),"Needs a date",IF(AND(D6<>"",NOT(ISNUMBER(D6))),"Amount not a number",IF(N(D6)<0,"Amount below zero",IF(AND(N(D6)=0,G6=""),"Needs an amount or goods",IF(C6="","",IF(COUNTIF(Donors!$B$6:$B$305,C6)=0,"Not on Donors",""))))))) | K6: =IF(ISNUMBER(B6),YEAR(B6),"") | L6: =IF(ISNUMBER(B6),YEAR(B6)*100+MONTH(B6),"") | M6: =IF(ISNUMBER(B6),INT(B6),0) | N6: =IF(OR(C6="",F6="",Q6=0),0,IF(COUNTIFS(C$6:C6,C6,F$6:F6,F6,Q$6:Q6,1)=1,1,0)) | O6: =IF(OR(C6="",Q6=0,H6<>""),"",M6*10000+ROW()) | P6: =IF(OR(C6="",Q6=0),"",IF(AND(C6=Statement!$C$4,K6=Statement!$C$5),M6*10000+ROW(),"")) | Q6: =IF(AND(ISNUMBER(B6),OR(N(D6)>0,G6<>"")),1,0)
B7: 45846 | C7: Ravi Patel | D7: 20 | E7: Bank transfer | F7: General fund | H7: x | I7: Monthly | J7: =IF(AND(C7="",D7="",G7=""),"",IF(NOT(ISNUMBER(B7)),"Needs a date",IF(AND(D7<>"",NOT(ISNUMBER(D7))),"Amount not a number",IF(N(D7)<0,"Amount below zero",IF(AND(N(D7)=0,G7=""),"Needs an amount or goods",IF(C7="","",IF(COUNTIF(Donors!$B$6:$B$305,C7)=0,"Not on Donors",""))))))) | K7: =IF(ISNUMBER(B7),YEAR(B7),"") | L7: =IF(ISNUMBER(B7),YEAR(B7)*100+MONTH(B7),"") | M7: =IF(ISNUMBER(B7),INT(B7),0) | N7: =IF(OR(C7="",F7="",Q7=0),0,IF(COUNTIFS(C$6:C7,C7,F$6:F7,F7,Q$6:Q7,1)=1,1,0)) | O7: =IF(OR(C7="",Q7=0,H7<>""),"",M7*10000+ROW()) | P7: =IF(OR(C7="",Q7=0),"",IF(AND(C7=Statement!$C$4,K7=Statement!$C$5),M7*10000+ROW(),"")) | Q7: =IF(AND(ISNUMBER(B7),OR(N(D7)>0,G7<>"")),1,0)
B8: 45847 | C8: Helen Price | D8: 10 | E8: Bank transfer | F8: General fund | H8: x | I8: Monthly | J8: =IF(AND(C8="",D8="",G8=""),"",IF(NOT(ISNUMBER(B8)),"Needs a date",IF(AND(D8<>"",NOT(ISNUMBER(D8))),"Amount not a number",IF(N(D8)<0,"Amount below zero",IF(AND(N(D8)=0,G8=""),"Needs an amount or goods",IF(C8="","",IF(COUNTIF(Donors!$B$6:$B$305,C8)=0,"Not on Donors",""))))))) | K8: =IF(ISNUMBER(B8),YEAR(B8),"") | L8: =IF(ISNUMBER(B8),YEAR(B8)*100+MONTH(B8),"") | M8: =IF(ISNUMBER(B8),INT(B8),0) | N8: =IF(OR(C8="",F8="",Q8=0),0,IF(COUNTIFS(C$6:C8,C8,F$6:F8,F8,Q$6:Q8,1)=1,1,0)) | O8: =IF(OR(C8="",Q8=0,H8<>""),"",M8*10000+ROW()) | P8: =IF(OR(C8="",Q8=0),"",IF(AND(C8=Statement!$C$4,K8=Statement!$C$5),M8*10000+ROW(),"")) | Q8: =IF(AND(ISNUMBER(B8),OR(N(D8)>0,G8<>"")),1,0)
B9: 45847 | C9: Amina Yusuf | D9: 15 | E9: Bank transfer | F9: General fund | H9: x | I9: Monthly | J9: =IF(AND(C9="",D9="",G9=""),"",IF(NOT(ISNUMBER(B9)),"Needs a date",IF(AND(D9<>"",NOT(ISNUMBER(D9))),"Amount not a number",IF(N(D9)<0,"Amount below zero",IF(AND(N(D9)=0,G9=""),"Needs an amount or goods",IF(C9="","",IF(COUNTIF(Donors!$B$6:$B$305,C9)=0,"Not on Donors",""))))))) | K9: =IF(ISNUMBER(B9),YEAR(B9),"") | L9: =IF(ISNUMBER(B9),YEAR(B9)*100+MONTH(B9),"") | M9: =IF(ISNUMBER(B9),INT(B9),0) | N9: =IF(OR(C9="",F9="",Q9=0),0,IF(COUNTIFS(C$6:C9,C9,F$6:F9,F9,Q$6:Q9,1)=1,1,0)) | O9: =IF(OR(C9="",Q9=0,H9<>""),"",M9*10000+ROW()) | P9: =IF(OR(C9="",Q9=0),"",IF(AND(C9=Statement!$C$4,K9=Statement!$C$5),M9*10000+ROW(),"")) | Q9: =IF(AND(ISNUMBER(B9),OR(N(D9)>0,G9<>"")),1,0)
B10: 45874 | C10: Grace Holloway | D10: 25 | E10: Bank transfer | F10: General fund | H10: x | I10: Monthly | J10: =IF(AND(C10="",D10="",G10=""),"",IF(NOT(ISNUMBER(B10)),"Needs a date",IF(AND(D10<>"",NOT(ISNUMBER(D10))),"Amount not a number",IF(N(D10)<0,"Amount below zero",IF(AND(N(D10)=0,G10=""),"Needs an amount or goods",IF(C10="","",IF(COUNTIF(Donors!$B$6:$B$305,C10)=0,"Not on Donors",""))))))) | K10: =IF(ISNUMBER(B10),YEAR(B10),"") | L10: =IF(ISNUMBER(B10),YEAR(B10)*100+MONTH(B10),"") | M10: =IF(ISNUMBER(B10),INT(B10),0) | N10: =IF(OR(C10="",F10="",Q10=0),0,IF(COUNTIFS(C$6:C10,C10,F$6:F10,F10,Q$6:Q10,1)=1,1,0)) | O10: =IF(OR(C10="",Q10=0,H10<>""),"",M10*10000+ROW()) | P10: =IF(OR(C10="",Q10=0),"",IF(AND(C10=Statement!$C$4,K10=Statement!$C$5),M10*10000+ROW(),"")) | Q10: =IF(AND(ISNUMBER(B10),OR(N(D10)>0,G10<>"")),1,0)
B11: 45877 | C11: Ravi Patel | D11: 20 | E11: Bank transfer | F11: General fund | H11: x | I11: Monthly | J11: =IF(AND(C11="",D11="",G11=""),"",IF(NOT(ISNUMBER(B11)),"Needs a date",IF(AND(D11<>"",NOT(ISNUMBER(D11))),"Amount not a number",IF(N(D11)<0,"Amount below zero",IF(AND(N(D11)=0,G11=""),"Needs an amount or goods",IF(C11="","",IF(COUNTIF(Donors!$B$6:$B$305,C11)=0,"Not on Donors",""))))))) | K11: =IF(ISNUMBER(B11),YEAR(B11),"") | L11: =IF(ISNUMBER(B11),YEAR(B11)*100+MONTH(B11),"") | M11: =IF(ISNUMBER(B11),INT(B11),0) | N11: =IF(OR(C11="",F11="",Q11=0),0,IF(COUNTIFS(C$6:C11,C11,F$6:F11,F11,Q$6:Q11,1)=1,1,0)) | O11: =IF(OR(C11="",Q11=0,H11<>""),"",M11*10000+ROW()) | P11: =IF(OR(C11="",Q11=0),"",IF(AND(C11=Statement!$C$4,K11=Statement!$C$5),M11*10000+ROW(),"")) | Q11: =IF(AND(ISNUMBER(B11),OR(N(D11)>0,G11<>"")),1,0)
B12: 45878 | C12: Helen Price | D12: 10 | E12: Bank transfer | F12: General fund | H12: x | I12: Monthly | J12: =IF(AND(C12="",D12="",G12=""),"",IF(NOT(ISNUMBER(B12)),"Needs a date",IF(AND(D12<>"",NOT(ISNUMBER(D12))),"Amount not a number",IF(N(D12)<0,"Amount below zero",IF(AND(N(D12)=0,G12=""),"Needs an amount or goods",IF(C12="","",IF(COUNTIF(Donors!$B$6:$B$305,C12)=0,"Not on Donors",""))))))) | K12: =IF(ISNUMBER(B12),YEAR(B12),"") | L12: =IF(ISNUMBER(B12),YEAR(B12)*100+MONTH(B12),"") | M12: =IF(ISNUMBER(B12),INT(B12),0) | N12: =IF(OR(C12="",F12="",Q12=0),0,IF(COUNTIFS(C$6:C12,C12,F$6:F12,F12,Q$6:Q12,1)=1,1,0)) | O12: =IF(OR(C12="",Q12=0,H12<>""),"",M12*10000+ROW()) | P12: =IF(OR(C12="",Q12=0),"",IF(AND(C12=Statement!$C$4,K12=Statement!$C$5),M12*10000+ROW(),"")) | Q12: =IF(AND(ISNUMBER(B12),OR(N(D12)>0,G12<>"")),1,0)
B13: 45878 | C13: Amina Yusuf | D13: 15 | E13: Bank transfer | F13: General fund | H13: x | I13: Monthly | J13: =IF(AND(C13="",D13="",G13=""),"",IF(NOT(ISNUMBER(B13)),"Needs a date",IF(AND(D13<>"",NOT(ISNUMBER(D13))),"Amount not a number",IF(N(D13)<0,"Amount below zero",IF(AND(N(D13)=0,G13=""),"Needs an amount or goods",IF(C13="","",IF(COUNTIF(Donors!$B$6:$B$305,C13)=0,"Not on Donors",""))))))) | K13: =IF(ISNUMBER(B13),YEAR(B13),"") | L13: =IF(ISNUMBER(B13),YEAR(B13)*100+MONTH(B13),"") | M13: =IF(ISNUMBER(B13),INT(B13),0) | N13: =IF(OR(C13="",F13="",Q13=0),0,IF(COUNTIFS(C$6:C13,C13,F$6:F13,F13,Q$6:Q13,1)=1,1,0)) | O13: =IF(OR(C13="",Q13=0,H13<>""),"",M13*10000+ROW()) | P13: =IF(OR(C13="",Q13=0),"",IF(AND(C13=Statement!$C$4,K13=Statement!$C$5),M13*10000+ROW(),"")) | Q13: =IF(AND(ISNUMBER(B13),OR(N(D13)>0,G13<>"")),1,0)
B14: 45893 | C14: Riverton Hardware | D14: 400 | E14: Check | F14: General fund | H14: x | J14: =IF(AND(C14="",D14="",G14=""),"",IF(NOT(ISNUMBER(B14)),"Needs a date",IF(AND(D14<>"",NOT(ISNUMBER(D14))),"Amount not a number",IF(N(D14)<0,"Amount below zero",IF(AND(N(D14)=0,G14=""),"Needs an amount or goods",IF(C14="","",IF(COUNTIF(Donors!$B$6:$B$305,C14)=0,"Not on Donors",""))))))) | K14: =IF(ISNUMBER(B14),YEAR(B14),"") | L14: =IF(ISNUMBER(B14),YEAR(B14)*100+MONTH(B14),"") | M14: =IF(ISNUMBER(B14),INT(B14),0) | N14: =IF(OR(C14="",F14="",Q14=0),0,IF(COUNTIFS(C$6:C14,C14,F$6:F14,F14,Q$6:Q14,1)=1,1,0)) | O14: =IF(OR(C14="",Q14=0,H14<>""),"",M14*10000+ROW()) | P14: =IF(OR(C14="",Q14=0),"",IF(AND(C14=Statement!$C$4,K14=Statement!$C$5),M14*10000+ROW(),"")) | Q14: =IF(AND(ISNUMBER(B14),OR(N(D14)>0,G14<>"")),1,0)
B15: 45905 | C15: Grace Holloway | D15: 25 | E15: Bank transfer | F15: General fund | H15: x | I15: Monthly | J15: =IF(AND(C15="",D15="",G15=""),"",IF(NOT(ISNUMBER(B15)),"Needs a date",IF(AND(D15<>"",NOT(ISNUMBER(D15))),"Amount not a number",IF(N(D15)<0,"Amount below zero",IF(AND(N(D15)=0,G15=""),"Needs an amount or goods",IF(C15="","",IF(COUNTIF(Donors!$B$6:$B$305,C15)=0,"Not on Donors",""))))))) | K15: =IF(ISNUMBER(B15),YEAR(B15),"") | L15: =IF(ISNUMBER(B15),YEAR(B15)*100+MONTH(B15),"") | M15: =IF(ISNUMBER(B15),INT(B15),0) | N15: =IF(OR(C15="",F15="",Q15=0),0,IF(COUNTIFS(C$6:C15,C15,F$6:F15,F15,Q$6:Q15,1)=1,1,0)) | O15: =IF(OR(C15="",Q15=0,H15<>""),"",M15*10000+ROW()) | P15: =IF(OR(C15="",Q15=0),"",IF(AND(C15=Statement!$C$4,K15=Statement!$C$5),M15*10000+ROW(),"")) | Q15: =IF(AND(ISNUMBER(B15),OR(N(D15)>0,G15<>"")),1,0)
B16: 45908 | C16: Ravi Patel | D16: 20 | E16: Bank transfer | F16: General fund | H16: x | I16: Monthly | J16: =IF(AND(C16="",D16="",G16=""),"",IF(NOT(ISNUMBER(B16)),"Needs a date",IF(AND(D16<>"",NOT(ISNUMBER(D16))),"Amount not a number",IF(N(D16)<0,"Amount below zero",IF(AND(N(D16)=0,G16=""),"Needs an amount or goods",IF(C16="","",IF(COUNTIF(Donors!$B$6:$B$305,C16)=0,"Not on Donors",""))))))) | K16: =IF(ISNUMBER(B16),YEAR(B16),"") | L16: =IF(ISNUMBER(B16),YEAR(B16)*100+MONTH(B16),"") | M16: =IF(ISNUMBER(B16),INT(B16),0) | N16: =IF(OR(C16="",F16="",Q16=0),0,IF(COUNTIFS(C$6:C16,C16,F$6:F16,F16,Q$6:Q16,1)=1,1,0)) | O16: =IF(OR(C16="",Q16=0,H16<>""),"",M16*10000+ROW()) | P16: =IF(OR(C16="",Q16=0),"",IF(AND(C16=Statement!$C$4,K16=Statement!$C$5),M16*10000+ROW(),"")) | Q16: =IF(AND(ISNUMBER(B16),OR(N(D16)>0,G16<>"")),1,0)
B17: 45909 | C17: Amina Yusuf | D17: 15 | E17: Bank transfer | F17: General fund | H17: x | I17: Monthly | J17: =IF(AND(C17="",D17="",G17=""),"",IF(NOT(ISNUMBER(B17)),"Needs a date",IF(AND(D17<>"",NOT(ISNUMBER(D17))),"Amount not a number",IF(N(D17)<0,"Amount below zero",IF(AND(N(D17)=0,G17=""),"Needs an amount or goods",IF(C17="","",IF(COUNTIF(Donors!$B$6:$B$305,C17)=0,"Not on Donors",""))))))) | K17: =IF(ISNUMBER(B17),YEAR(B17),"") | L17: =IF(ISNUMBER(B17),YEAR(B17)*100+MONTH(B17),"") | M17: =IF(ISNUMBER(B17),INT(B17),0) | N17: =IF(OR(C17="",F17="",Q17=0),0,IF(COUNTIFS(C$6:C17,C17,F$6:F17,F17,Q$6:Q17,1)=1,1,0)) | O17: =IF(OR(C17="",Q17=0,H17<>""),"",M17*10000+ROW()) | P17: =IF(OR(C17="",Q17=0),"",IF(AND(C17=Statement!$C$4,K17=Statement!$C$5),M17*10000+ROW(),"")) | Q17: =IF(AND(ISNUMBER(B17),OR(N(D17)>0,G17<>"")),1,0)
B18: 45913 | C18: Old Mill Trust | D18: 2000 | E18: Bank transfer | F18: General fund | H18: x | I18: Yearly grant | J18: =IF(AND(C18="",D18="",G18=""),"",IF(NOT(ISNUMBER(B18)),"Needs a date",IF(AND(D18<>"",NOT(ISNUMBER(D18))),"Amount not a number",IF(N(D18)<0,"Amount below zero",IF(AND(N(D18)=0,G18=""),"Needs an amount or goods",IF(C18="","",IF(COUNTIF(Donors!$B$6:$B$305,C18)=0,"Not on Donors",""))))))) | K18: =IF(ISNUMBER(B18),YEAR(B18),"") | L18: =IF(ISNUMBER(B18),YEAR(B18)*100+MONTH(B18),"") | M18: =IF(ISNUMBER(B18),INT(B18),0) | N18: =IF(OR(C18="",F18="",Q18=0),0,IF(COUNTIFS(C$6:C18,C18,F$6:F18,F18,Q$6:Q18,1)=1,1,0)) | O18: =IF(OR(C18="",Q18=0,H18<>""),"",M18*10000+ROW()) | P18: =IF(OR(C18="",Q18=0),"",IF(AND(C18=Statement!$C$4,K18=Statement!$C$5),M18*10000+ROW(),"")) | Q18: =IF(AND(ISNUMBER(B18),OR(N(D18)>0,G18<>"")),1,0)
B19: 45935 | C19: Grace Holloway | D19: 25 | E19: Bank transfer | F19: General fund | H19: x | I19: Monthly | J19: =IF(AND(C19="",D19="",G19=""),"",IF(NOT(ISNUMBER(B19)),"Needs a date",IF(AND(D19<>"",NOT(ISNUMBER(D19))),"Amount not a number",IF(N(D19)<0,"Amount below zero",IF(AND(N(D19)=0,G19=""),"Needs an amount or goods",IF(C19="","",IF(COUNTIF(Donors!$B$6:$B$305,C19)=0,"Not on Donors",""))))))) | K19: =IF(ISNUMBER(B19),YEAR(B19),"") | L19: =IF(ISNUMBER(B19),YEAR(B19)*100+MONTH(B19),"") | M19: =IF(ISNUMBER(B19),INT(B19),0) | N19: =IF(OR(C19="",F19="",Q19=0),0,IF(COUNTIFS(C$6:C19,C19,F$6:F19,F19,Q$6:Q19,1)=1,1,0)) | O19: =IF(OR(C19="",Q19=0,H19<>""),"",M19*10000+ROW()) | P19: =IF(OR(C19="",Q19=0),"",IF(AND(C19=Statement!$C$4,K19=Statement!$C$5),M19*10000+ROW(),"")) | Q19: =IF(AND(ISNUMBER(B19),OR(N(D19)>0,G19<>"")),1,0)
B20: 45938 | C20: Ravi Patel | D20: 20 | E20: Bank transfer | F20: General fund | H20: x | I20: Monthly | J20: =IF(AND(C20="",D20="",G20=""),"",IF(NOT(ISNUMBER(B20)),"Needs a date",IF(AND(D20<>"",NOT(ISNUMBER(D20))),"Amount not a number",IF(N(D20)<0,"Amount below zero",IF(AND(N(D20)=0,G20=""),"Needs an amount or goods",IF(C20="","",IF(COUNTIF(Donors!$B$6:$B$305,C20)=0,"Not on Donors",""))))))) | K20: =IF(ISNUMBER(B20),YEAR(B20),"") | L20: =IF(ISNUMBER(B20),YEAR(B20)*100+MONTH(B20),"") | M20: =IF(ISNUMBER(B20),INT(B20),0) | N20: =IF(OR(C20="",F20="",Q20=0),0,IF(COUNTIFS(C$6:C20,C20,F$6:F20,F20,Q$6:Q20,1)=1,1,0)) | O20: =IF(OR(C20="",Q20=0,H20<>""),"",M20*10000+ROW()) | P20: =IF(OR(C20="",Q20=0),"",IF(AND(C20=Statement!$C$4,K20=Statement!$C$5),M20*10000+ROW(),"")) | Q20: =IF(AND(ISNUMBER(B20),OR(N(D20)>0,G20<>"")),1,0)
B21: 45939 | C21: Amina Yusuf | D21: 15 | E21: Bank transfer | F21: General fund | H21: x | I21: Monthly | J21: =IF(AND(C21="",D21="",G21=""),"",IF(NOT(ISNUMBER(B21)),"Needs a date",IF(AND(D21<>"",NOT(ISNUMBER(D21))),"Amount not a number",IF(N(D21)<0,"Amount below zero",IF(AND(N(D21)=0,G21=""),"Needs an amount or goods",IF(C21="","",IF(COUNTIF(Donors!$B$6:$B$305,C21)=0,"Not on Donors",""))))))) | K21: =IF(ISNUMBER(B21),YEAR(B21),"") | L21: =IF(ISNUMBER(B21),YEAR(B21)*100+MONTH(B21),"") | M21: =IF(ISNUMBER(B21),INT(B21),0) | N21: =IF(OR(C21="",F21="",Q21=0),0,IF(COUNTIFS(C$6:C21,C21,F$6:F21,F21,Q$6:Q21,1)=1,1,0)) | O21: =IF(OR(C21="",Q21=0,H21<>""),"",M21*10000+ROW()) | P21: =IF(OR(C21="",Q21=0),"",IF(AND(C21=Statement!$C$4,K21=Statement!$C$5),M21*10000+ROW(),"")) | Q21: =IF(AND(ISNUMBER(B21),OR(N(D21)>0,G21<>"")),1,0)
B22: 45963 | C22: Corner Bakery | D22: 120 | E22: Card | F22: General fund | H22: x | J22: =IF(AND(C22="",D22="",G22=""),"",IF(NOT(ISNUMBER(B22)),"Needs a date",IF(AND(D22<>"",NOT(ISNUMBER(D22))),"Amount not a number",IF(N(D22)<0,"Amount below zero",IF(AND(N(D22)=0,G22=""),"Needs an amount or goods",IF(C22="","",IF(COUNTIF(Donors!$B$6:$B$305,C22)=0,"Not on Donors",""))))))) | K22: =IF(ISNUMBER(B22),YEAR(B22),"") | L22: =IF(ISNUMBER(B22),YEAR(B22)*100+MONTH(B22),"") | M22: =IF(ISNUMBER(B22),INT(B22),0) | N22: =IF(OR(C22="",F22="",Q22=0),0,IF(COUNTIFS(C$6:C22,C22,F$6:F22,F22,Q$6:Q22,1)=1,1,0)) | O22: =IF(OR(C22="",Q22=0,H22<>""),"",M22*10000+ROW()) | P22: =IF(OR(C22="",Q22=0),"",IF(AND(C22=Statement!$C$4,K22=Statement!$C$5),M22*10000+ROW(),"")) | Q22: =IF(AND(ISNUMBER(B22),OR(N(D22)>0,G22<>"")),1,0)
B23: 45966 | C23: Grace Holloway | D23: 25 | E23: Bank transfer | F23: General fund | H23: x | I23: Monthly | J23: =IF(AND(C23="",D23="",G23=""),"",IF(NOT(ISNUMBER(B23)),"Needs a date",IF(AND(D23<>"",NOT(ISNUMBER(D23))),"Amount not a number",IF(N(D23)<0,"Amount below zero",IF(AND(N(D23)=0,G23=""),"Needs an amount or goods",IF(C23="","",IF(COUNTIF(Donors!$B$6:$B$305,C23)=0,"Not on Donors",""))))))) | K23: =IF(ISNUMBER(B23),YEAR(B23),"") | L23: =IF(ISNUMBER(B23),YEAR(B23)*100+MONTH(B23),"") | M23: =IF(ISNUMBER(B23),INT(B23),0) | N23: =IF(OR(C23="",F23="",Q23=0),0,IF(COUNTIFS(C$6:C23,C23,F$6:F23,F23,Q$6:Q23,1)=1,1,0)) | O23: =IF(OR(C23="",Q23=0,H23<>""),"",M23*10000+ROW()) | P23: =IF(OR(C23="",Q23=0),"",IF(AND(C23=Statement!$C$4,K23=Statement!$C$5),M23*10000+ROW(),"")) | Q23: =IF(AND(ISNUMBER(B23),OR(N(D23)>0,G23<>"")),1,0)
B24: 45969 | C24: Ravi Patel | D24: 20 | E24: Bank transfer | F24: General fund | H24: x | I24: Monthly | J24: =IF(AND(C24="",D24="",G24=""),"",IF(NOT(ISNUMBER(B24)),"Needs a date",IF(AND(D24<>"",NOT(ISNUMBER(D24))),"Amount not a number",IF(N(D24)<0,"Amount below zero",IF(AND(N(D24)=0,G24=""),"Needs an amount or goods",IF(C24="","",IF(COUNTIF(Donors!$B$6:$B$305,C24)=0,"Not on Donors",""))))))) | K24: =IF(ISNUMBER(B24),YEAR(B24),"") | L24: =IF(ISNUMBER(B24),YEAR(B24)*100+MONTH(B24),"") | M24: =IF(ISNUMBER(B24),INT(B24),0) | N24: =IF(OR(C24="",F24="",Q24=0),0,IF(COUNTIFS(C$6:C24,C24,F$6:F24,F24,Q$6:Q24,1)=1,1,0)) | O24: =IF(OR(C24="",Q24=0,H24<>""),"",M24*10000+ROW()) | P24: =IF(OR(C24="",Q24=0),"",IF(AND(C24=Statement!$C$4,K24=Statement!$C$5),M24*10000+ROW(),"")) | Q24: =IF(AND(ISNUMBER(B24),OR(N(D24)>0,G24<>"")),1,0)
B25: 45970 | C25: Amina Yusuf | D25: 15 | E25: Bank transfer | F25: General fund | H25: x | I25: Monthly | J25: =IF(AND(C25="",D25="",G25=""),"",IF(NOT(ISNUMBER(B25)),"Needs a date",IF(AND(D25<>"",NOT(ISNUMBER(D25))),"Amount not a number",IF(N(D25)<0,"Amount below zero",IF(AND(N(D25)=0,G25=""),"Needs an amount or goods",IF(C25="","",IF(COUNTIF(Donors!$B$6:$B$305,C25)=0,"Not on Donors",""))))))) | K25: =IF(ISNUMBER(B25),YEAR(B25),"") | L25: =IF(ISNUMBER(B25),YEAR(B25)*100+MONTH(B25),"") | M25: =IF(ISNUMBER(B25),INT(B25),0) | N25: =IF(OR(C25="",F25="",Q25=0),0,IF(COUNTIFS(C$6:C25,C25,F$6:F25,F25,Q$6:Q25,1)=1,1,0)) | O25: =IF(OR(C25="",Q25=0,H25<>""),"",M25*10000+ROW()) | P25: =IF(OR(C25="",Q25=0),"",IF(AND(C25=Statement!$C$4,K25=Statement!$C$5),M25*10000+ROW(),"")) | Q25: =IF(AND(ISNUMBER(B25),OR(N(D25)>0,G25<>"")),1,0)
B26: 45993 | C26: St Luke's Youth Group | D26: 260 | E26: Cash | F26: General fund | H26: x | I26: Carol singing | J26: =IF(AND(C26="",D26="",G26=""),"",IF(NOT(ISNUMBER(B26)),"Needs a date",IF(AND(D26<>"",NOT(ISNUMBER(D26))),"Amount not a number",IF(N(D26)<0,"Amount below zero",IF(AND(N(D26)=0,G26=""),"Needs an amount or goods",IF(C26="","",IF(COUNTIF(Donors!$B$6:$B$305,C26)=0,"Not on Donors",""))))))) | K26: =IF(ISNUMBER(B26),YEAR(B26),"") | L26: =IF(ISNUMBER(B26),YEAR(B26)*100+MONTH(B26),"") | M26: =IF(ISNUMBER(B26),INT(B26),0) | N26: =IF(OR(C26="",F26="",Q26=0),0,IF(COUNTIFS(C$6:C26,C26,F$6:F26,F26,Q$6:Q26,1)=1,1,0)) | O26: =IF(OR(C26="",Q26=0,H26<>""),"",M26*10000+ROW()) | P26: =IF(OR(C26="",Q26=0),"",IF(AND(C26=Statement!$C$4,K26=Statement!$C$5),M26*10000+ROW(),"")) | Q26: =IF(AND(ISNUMBER(B26),OR(N(D26)>0,G26<>"")),1,0)
B27: 45996 | C27: Grace Holloway | D27: 25 | E27: Bank transfer | F27: General fund | H27: x | I27: Monthly | J27: =IF(AND(C27="",D27="",G27=""),"",IF(NOT(ISNUMBER(B27)),"Needs a date",IF(AND(D27<>"",NOT(ISNUMBER(D27))),"Amount not a number",IF(N(D27)<0,"Amount below zero",IF(AND(N(D27)=0,G27=""),"Needs an amount or goods",IF(C27="","",IF(COUNTIF(Donors!$B$6:$B$305,C27)=0,"Not on Donors",""))))))) | K27: =IF(ISNUMBER(B27),YEAR(B27),"") | L27: =IF(ISNUMBER(B27),YEAR(B27)*100+MONTH(B27),"") | M27: =IF(ISNUMBER(B27),INT(B27),0) | N27: =IF(OR(C27="",F27="",Q27=0),0,IF(COUNTIFS(C$6:C27,C27,F$6:F27,F27,Q$6:Q27,1)=1,1,0)) | O27: =IF(OR(C27="",Q27=0,H27<>""),"",M27*10000+ROW()) | P27: =IF(OR(C27="",Q27=0),"",IF(AND(C27=Statement!$C$4,K27=Statement!$C$5),M27*10000+ROW(),"")) | Q27: =IF(AND(ISNUMBER(B27),OR(N(D27)>0,G27<>"")),1,0)
B28: 45999 | C28: Ravi Patel | D28: 20 | E28: Bank transfer | F28: General fund | H28: x | I28: Monthly | J28: =IF(AND(C28="",D28="",G28=""),"",IF(NOT(ISNUMBER(B28)),"Needs a date",IF(AND(D28<>"",NOT(ISNUMBER(D28))),"Amount not a number",IF(N(D28)<0,"Amount below zero",IF(AND(N(D28)=0,G28=""),"Needs an amount or goods",IF(C28="","",IF(COUNTIF(Donors!$B$6:$B$305,C28)=0,"Not on Donors",""))))))) | K28: =IF(ISNUMBER(B28),YEAR(B28),"") | L28: =IF(ISNUMBER(B28),YEAR(B28)*100+MONTH(B28),"") | M28: =IF(ISNUMBER(B28),INT(B28),0) | N28: =IF(OR(C28="",F28="",Q28=0),0,IF(COUNTIFS(C$6:C28,C28,F$6:F28,F28,Q$6:Q28,1)=1,1,0)) | O28: =IF(OR(C28="",Q28=0,H28<>""),"",M28*10000+ROW()) | P28: =IF(OR(C28="",Q28=0),"",IF(AND(C28=Statement!$C$4,K28=Statement!$C$5),M28*10000+ROW(),"")) | Q28: =IF(AND(ISNUMBER(B28),OR(N(D28)>0,G28<>"")),1,0)
B29: 46000 | C29: Amina Yusuf | D29: 15 | E29: Bank transfer | F29: General fund | H29: x | I29: Monthly | J29: =IF(AND(C29="",D29="",G29=""),"",IF(NOT(ISNUMBER(B29)),"Needs a date",IF(AND(D29<>"",NOT(ISNUMBER(D29))),"Amount not a number",IF(N(D29)<0,"Amount below zero",IF(AND(N(D29)=0,G29=""),"Needs an amount or goods",IF(C29="","",IF(COUNTIF(Donors!$B$6:$B$305,C29)=0,"Not on Donors",""))))))) | K29: =IF(ISNUMBER(B29),YEAR(B29),"") | L29: =IF(ISNUMBER(B29),YEAR(B29)*100+MONTH(B29),"") | M29: =IF(ISNUMBER(B29),INT(B29),0) | N29: =IF(OR(C29="",F29="",Q29=0),0,IF(COUNTIFS(C$6:C29,C29,F$6:F29,F29,Q$6:Q29,1)=1,1,0)) | O29: =IF(OR(C29="",Q29=0,H29<>""),"",M29*10000+ROW()) | P29: =IF(OR(C29="",Q29=0),"",IF(AND(C29=Statement!$C$4,K29=Statement!$C$5),M29*10000+ROW(),"")) | Q29: =IF(AND(ISNUMBER(B29),OR(N(D29)>0,G29<>"")),1,0)
B30: 46027 | C30: Grace Holloway | D30: 25 | E30: Bank transfer | F30: General fund | H30: x | I30: Monthly | J30: =IF(AND(C30="",D30="",G30=""),"",IF(NOT(ISNUMBER(B30)),"Needs a date",IF(AND(D30<>"",NOT(ISNUMBER(D30))),"Amount not a number",IF(N(D30)<0,"Amount below zero",IF(AND(N(D30)=0,G30=""),"Needs an amount or goods",IF(C30="","",IF(COUNTIF(Donors!$B$6:$B$305,C30)=0,"Not on Donors",""))))))) | K30: =IF(ISNUMBER(B30),YEAR(B30),"") | L30: =IF(ISNUMBER(B30),YEAR(B30)*100+MONTH(B30),"") | M30: =IF(ISNUMBER(B30),INT(B30),0) | N30: =IF(OR(C30="",F30="",Q30=0),0,IF(COUNTIFS(C$6:C30,C30,F$6:F30,F30,Q$6:Q30,1)=1,1,0)) | O30: =IF(OR(C30="",Q30=0,H30<>""),"",M30*10000+ROW()) | P30: =IF(OR(C30="",Q30=0),"",IF(AND(C30=Statement!$C$4,K30=Statement!$C$5),M30*10000+ROW(),"")) | Q30: =IF(AND(ISNUMBER(B30),OR(N(D30)>0,G30<>"")),1,0)
B31: 46030 | C31: Ravi Patel | D31: 20 | E31: Bank transfer | F31: General fund | H31: x | I31: Monthly | J31: =IF(AND(C31="",D31="",G31=""),"",IF(NOT(ISNUMBER(B31)),"Needs a date",IF(AND(D31<>"",NOT(ISNUMBER(D31))),"Amount not a number",IF(N(D31)<0,"Amount below zero",IF(AND(N(D31)=0,G31=""),"Needs an amount or goods",IF(C31="","",IF(COUNTIF(Donors!$B$6:$B$305,C31)=0,"Not on Donors",""))))))) | K31: =IF(ISNUMBER(B31),YEAR(B31),"") | L31: =IF(ISNUMBER(B31),YEAR(B31)*100+MONTH(B31),"") | M31: =IF(ISNUMBER(B31),INT(B31),0) | N31: =IF(OR(C31="",F31="",Q31=0),0,IF(COUNTIFS(C$6:C31,C31,F$6:F31,F31,Q$6:Q31,1)=1,1,0)) | O31: =IF(OR(C31="",Q31=0,H31<>""),"",M31*10000+ROW()) | P31: =IF(OR(C31="",Q31=0),"",IF(AND(C31=Statement!$C$4,K31=Statement!$C$5),M31*10000+ROW(),"")) | Q31: =IF(AND(ISNUMBER(B31),OR(N(D31)>0,G31<>"")),1,0)
B32: 46031 | C32: Amina Yusuf | D32: 15 | E32: Bank transfer | F32: General fund | H32: x | I32: Monthly | J32: =IF(AND(C32="",D32="",G32=""),"",IF(NOT(ISNUMBER(B32)),"Needs a date",IF(AND(D32<>"",NOT(ISNUMBER(D32))),"Amount not a number",IF(N(D32)<0,"Amount below zero",IF(AND(N(D32)=0,G32=""),"Needs an amount or goods",IF(C32="","",IF(COUNTIF(Donors!$B$6:$B$305,C32)=0,"Not on Donors",""))))))) | K32: =IF(ISNUMBER(B32),YEAR(B32),"") | L32: =IF(ISNUMBER(B32),YEAR(B32)*100+MONTH(B32),"") | M32: =IF(ISNUMBER(B32),INT(B32),0) | N32: =IF(OR(C32="",F32="",Q32=0),0,IF(COUNTIFS(C$6:C32,C32,F$6:F32,F32,Q$6:Q32,1)=1,1,0)) | O32: =IF(OR(C32="",Q32=0,H32<>""),"",M32*10000+ROW()) | P32: =IF(OR(C32="",Q32=0),"",IF(AND(C32=Statement!$C$4,K32=Statement!$C$5),M32*10000+ROW(),"")) | Q32: =IF(AND(ISNUMBER(B32),OR(N(D32)>0,G32<>"")),1,0)
B33: 46058 | C33: Grace Holloway | D33: 25 | E33: Bank transfer | F33: General fund | H33: x | I33: Monthly | J33: =IF(AND(C33="",D33="",G33=""),"",IF(NOT(ISNUMBER(B33)),"Needs a date",IF(AND(D33<>"",NOT(ISNUMBER(D33))),"Amount not a number",IF(N(D33)<0,"Amount below zero",IF(AND(N(D33)=0,G33=""),"Needs an amount or goods",IF(C33="","",IF(COUNTIF(Donors!$B$6:$B$305,C33)=0,"Not on Donors",""))))))) | K33: =IF(ISNUMBER(B33),YEAR(B33),"") | L33: =IF(ISNUMBER(B33),YEAR(B33)*100+MONTH(B33),"") | M33: =IF(ISNUMBER(B33),INT(B33),0) | N33: =IF(OR(C33="",F33="",Q33=0),0,IF(COUNTIFS(C$6:C33,C33,F$6:F33,F33,Q$6:Q33,1)=1,1,0)) | O33: =IF(OR(C33="",Q33=0,H33<>""),"",M33*10000+ROW()) | P33: =IF(OR(C33="",Q33=0),"",IF(AND(C33=Statement!$C$4,K33=Statement!$C$5),M33*10000+ROW(),"")) | Q33: =IF(AND(ISNUMBER(B33),OR(N(D33)>0,G33<>"")),1,0)
B34: 46061 | C34: Ravi Patel | D34: 20 | E34: Bank transfer | F34: General fund | H34: x | I34: Monthly | J34: =IF(AND(C34="",D34="",G34=""),"",IF(NOT(ISNUMBER(B34)),"Needs a date",IF(AND(D34<>"",NOT(ISNUMBER(D34))),"Amount not a number",IF(N(D34)<0,"Amount below zero",IF(AND(N(D34)=0,G34=""),"Needs an amount or goods",IF(C34="","",IF(COUNTIF(Donors!$B$6:$B$305,C34)=0,"Not on Donors",""))))))) | K34: =IF(ISNUMBER(B34),YEAR(B34),"") | L34: =IF(ISNUMBER(B34),YEAR(B34)*100+MONTH(B34),"") | M34: =IF(ISNUMBER(B34),INT(B34),0) | N34: =IF(OR(C34="",F34="",Q34=0),0,IF(COUNTIFS(C$6:C34,C34,F$6:F34,F34,Q$6:Q34,1)=1,1,0)) | O34: =IF(OR(C34="",Q34=0,H34<>""),"",M34*10000+ROW()) | P34: =IF(OR(C34="",Q34=0),"",IF(AND(C34=Statement!$C$4,K34=Statement!$C$5),M34*10000+ROW(),"")) | Q34: =IF(AND(ISNUMBER(B34),OR(N(D34)>0,G34<>"")),1,0)
... B44: 46151 | C44: Amina Yusuf | D44: 15 | E44: Bank transfer | F44: General fund | H44: x | I44: Monthly | J44: =IF(AND(C44="",D44="",G44=""),"",IF(NOT(ISNUMBER(B44)),"Needs a date",IF(AND(D44<>"",NOT(ISNUMBER(D44))),"Amount not a number",IF(N(D44)<0,"Amount below zero",IF(AND(N(D44)=0,G44=""),"Needs an amount or goods",IF(C44="","",IF(COUNTIF(Donors!$B$6:$B$305,C44)=0,"Not on Donors",""))))))) | K44: =IF(ISNUMBER(B44),YEAR(B44),"") | L44: =IF(ISNUMBER(B44),YEAR(B44)*100+MONTH(B44),"") | M44: =IF(ISNUMBER(B44),INT(B44),0) | N44: =IF(OR(C44="",F44="",Q44=0),0,IF(COUNTIFS(C$6:C44,C44,F$6:F44,F44,Q$6:Q44,1)=1,1,0)) | O44: =IF(OR(C44="",Q44=0,H44<>""),"",M44*10000+ROW()) | P44: =IF(OR(C44="",Q44=0),"",IF(AND(C44=Statement!$C$4,K44=Statement!$C$5),M44*10000+ROW(),"")) | Q44: =IF(AND(ISNUMBER(B44),OR(N(D44)>0,G44<>"")),1,0)
B45: 46153 | C45: Riverton Hardware | D45: 500 | E45: Check | F45: New freezer | H45: x | J45: =IF(AND(C45="",D45="",G45=""),"",IF(NOT(ISNUMBER(B45)),"Needs a date",IF(AND(D45<>"",NOT(ISNUMBER(D45))),"Amount not a number",IF(N(D45)<0,"Amount below zero",IF(AND(N(D45)=0,G45=""),"Needs an amount or goods",IF(C45="","",IF(COUNTIF(Donors!$B$6:$B$305,C45)=0,"Not on Donors",""))))))) | K45: =IF(ISNUMBER(B45),YEAR(B45),"") | L45: =IF(ISNUMBER(B45),YEAR(B45)*100+MONTH(B45),"") | M45: =IF(ISNUMBER(B45),INT(B45),0) | N45: =IF(OR(C45="",F45="",Q45=0),0,IF(COUNTIFS(C$6:C45,C45,F$6:F45,F45,Q$6:Q45,1)=1,1,0)) | O45: =IF(OR(C45="",Q45=0,H45<>""),"",M45*10000+ROW()) | P45: =IF(OR(C45="",Q45=0),"",IF(AND(C45=Statement!$C$4,K45=Statement!$C$5),M45*10000+ROW(),"")) | Q45: =IF(AND(ISNUMBER(B45),OR(N(D45)>0,G45<>"")),1,0)
B46: 46173 | C46: Old Mill Trust | D46: 2500 | E46: Bank transfer | F46: New freezer | H46: x | I46: Yearly grant | J46: =IF(AND(C46="",D46="",G46=""),"",IF(NOT(ISNUMBER(B46)),"Needs a date",IF(AND(D46<>"",NOT(ISNUMBER(D46))),"Amount not a number",IF(N(D46)<0,"Amount below zero",IF(AND(N(D46)=0,G46=""),"Needs an amount or goods",IF(C46="","",IF(COUNTIF(Donors!$B$6:$B$305,C46)=0,"Not on Donors",""))))))) | K46: =IF(ISNUMBER(B46),YEAR(B46),"") | L46: =IF(ISNUMBER(B46),YEAR(B46)*100+MONTH(B46),"") | M46: =IF(ISNUMBER(B46),INT(B46),0) | N46: =IF(OR(C46="",F46="",Q46=0),0,IF(COUNTIFS(C$6:C46,C46,F$6:F46,F46,Q$6:Q46,1)=1,1,0)) | O46: =IF(OR(C46="",Q46=0,H46<>""),"",M46*10000+ROW()) | P46: =IF(OR(C46="",Q46=0),"",IF(AND(C46=Statement!$C$4,K46=Statement!$C$5),M46*10000+ROW(),"")) | Q46: =IF(AND(ISNUMBER(B46),OR(N(D46)>0,G46<>"")),1,0)
B47: 46178 | C47: Grace Holloway | D47: 25 | E47: Bank transfer | F47: General fund | H47: x | I47: Monthly | J47: =IF(AND(C47="",D47="",G47=""),"",IF(NOT(ISNUMBER(B47)),"Needs a date",IF(AND(D47<>"",NOT(ISNUMBER(D47))),"Amount not a number",IF(N(D47)<0,"Amount below zero",IF(AND(N(D47)=0,G47=""),"Needs an amount or goods",IF(C47="","",IF(COUNTIF(Donors!$B$6:$B$305,C47)=0,"Not on Donors",""))))))) | K47: =IF(ISNUMBER(B47),YEAR(B47),"") | L47: =IF(ISNUMBER(B47),YEAR(B47)*100+MONTH(B47),"") | M47: =IF(ISNUMBER(B47),INT(B47),0) | N47: =IF(OR(C47="",F47="",Q47=0),0,IF(COUNTIFS(C$6:C47,C47,F$6:F47,F47,Q$6:Q47,1)=1,1,0)) | O47: =IF(OR(C47="",Q47=0,H47<>""),"",M47*10000+ROW()) | P47: =IF(OR(C47="",Q47=0),"",IF(AND(C47=Statement!$C$4,K47=Statement!$C$5),M47*10000+ROW(),"")) | Q47: =IF(AND(ISNUMBER(B47),OR(N(D47)>0,G47<>"")),1,0)
B48: 46181 | C48: Ravi Patel | D48: 20 | E48: Bank transfer | F48: General fund | H48: x | I48: Monthly | J48: =IF(AND(C48="",D48="",G48=""),"",IF(NOT(ISNUMBER(B48)),"Needs a date",IF(AND(D48<>"",NOT(ISNUMBER(D48))),"Amount not a number",IF(N(D48)<0,"Amount below zero",IF(AND(N(D48)=0,G48=""),"Needs an amount or goods",IF(C48="","",IF(COUNTIF(Donors!$B$6:$B$305,C48)=0,"Not on Donors",""))))))) | K48: =IF(ISNUMBER(B48),YEAR(B48),"") | L48: =IF(ISNUMBER(B48),YEAR(B48)*100+MONTH(B48),"") | M48: =IF(ISNUMBER(B48),INT(B48),0) | N48: =IF(OR(C48="",F48="",Q48=0),0,IF(COUNTIFS(C$6:C48,C48,F$6:F48,F48,Q$6:Q48,1)=1,1,0)) | O48: =IF(OR(C48="",Q48=0,H48<>""),"",M48*10000+ROW()) | P48: =IF(OR(C48="",Q48=0),"",IF(AND(C48=Statement!$C$4,K48=Statement!$C$5),M48*10000+ROW(),"")) | Q48: =IF(AND(ISNUMBER(B48),OR(N(D48)>0,G48<>"")),1,0)
B49: 46182 | C49: Amina Yusuf | D49: 15 | E49: Bank transfer | F49: General fund | H49: x | I49: Monthly | J49: =IF(AND(C49="",D49="",G49=""),"",IF(NOT(ISNUMBER(B49)),"Needs a date",IF(AND(D49<>"",NOT(ISNUMBER(D49))),"Amount not a number",IF(N(D49)<0,"Amount below zero",IF(AND(N(D49)=0,G49=""),"Needs an amount or goods",IF(C49="","",IF(COUNTIF(Donors!$B$6:$B$305,C49)=0,"Not on Donors",""))))))) | K49: =IF(ISNUMBER(B49),YEAR(B49),"") | L49: =IF(ISNUMBER(B49),YEAR(B49)*100+MONTH(B49),"") | M49: =IF(ISNUMBER(B49),INT(B49),0) | N49: =IF(OR(C49="",F49="",Q49=0),0,IF(COUNTIFS(C$6:C49,C49,F$6:F49,F49,Q$6:Q49,1)=1,1,0)) | O49: =IF(OR(C49="",Q49=0,H49<>""),"",M49*10000+ROW()) | P49: =IF(OR(C49="",Q49=0),"",IF(AND(C49=Statement!$C$4,K49=Statement!$C$5),M49*10000+ROW(),"")) | Q49: =IF(AND(ISNUMBER(B49),OR(N(D49)>0,G49<>"")),1,0)
B50: 46193 | C50: Corner Bakery | D50: 150 | E50: Card | F50: Back to school | H50: x | J50: =IF(AND(C50="",D50="",G50=""),"",IF(NOT(ISNUMBER(B50)),"Needs a date",IF(AND(D50<>"",NOT(ISNUMBER(D50))),"Amount not a number",IF(N(D50)<0,"Amount below zero",IF(AND(N(D50)=0,G50=""),"Needs an amount or goods",IF(C50="","",IF(COUNTIF(Donors!$B$6:$B$305,C50)=0,"Not on Donors",""))))))) | K50: =IF(ISNUMBER(B50),YEAR(B50),"") | L50: =IF(ISNUMBER(B50),YEAR(B50)*100+MONTH(B50),"") | M50: =IF(ISNUMBER(B50),INT(B50),0) | N50: =IF(OR(C50="",F50="",Q50=0),0,IF(COUNTIFS(C$6:C50,C50,F$6:F50,F50,Q$6:Q50,1)=1,1,0)) | O50: =IF(OR(C50="",Q50=0,H50<>""),"",M50*10000+ROW()) | P50: =IF(OR(C50="",Q50=0),"",IF(AND(C50=Statement!$C$4,K50=Statement!$C$5),M50*10000+ROW(),"")) | Q50: =IF(AND(ISNUMBER(B50),OR(N(D50)>0,G50<>"")),1,0)
B51: 46198 | C51: St Luke's Youth Group | D51: 320 | E51: Cash | F51: Back to school | H51: x | I51: Car wash | J51: =IF(AND(C51="",D51="",G51=""),"",IF(NOT(ISNUMBER(B51)),"Needs a date",IF(AND(D51<>"",NOT(ISNUMBER(D51))),"Amount not a number",IF(N(D51)<0,"Amount below zero",IF(AND(N(D51)=0,G51=""),"Needs an amount or goods",IF(C51="","",IF(COUNTIF(Donors!$B$6:$B$305,C51)=0,"Not on Donors",""))))))) | K51: =IF(ISNUMBER(B51),YEAR(B51),"") | L51: =IF(ISNUMBER(B51),YEAR(B51)*100+MONTH(B51),"") | M51: =IF(ISNUMBER(B51),INT(B51),0) | N51: =IF(OR(C51="",F51="",Q51=0),0,IF(COUNTIFS(C$6:C51,C51,F$6:F51,F51,Q$6:Q51,1)=1,1,0)) | O51: =IF(OR(C51="",Q51=0,H51<>""),"",M51*10000+ROW()) | P51: =IF(OR(C51="",Q51=0),"",IF(AND(C51=Statement!$C$4,K51=Statement!$C$5),M51*10000+ROW(),"")) | Q51: =IF(AND(ISNUMBER(B51),OR(N(D51)>0,G51<>"")),1,0)
...

Sheet Donors
B2: Donors
B3: Each donor once. Their gifts add up from the Gifts tab.
B5: Donor | C5: Type | D5: Email | E5: Address | F5: First gift | G5: Last gift | H5: This year | I5: All time | J5: Gifts | K5: Status
B6: Grace Holloway | C6: Person | D6: grace@mail.example | E6: 12 Birch Road, Riverton | F6: =IF(OR(B6="",N(J6)=0),"",SUMPRODUCT(MIN((Gifts!$C$6:$C$1005=B6)*Gifts!$Q$6:$Q$1005*Gifts!$M$6:$M$1005+(1-(Gifts!$C$6:$C$1005=B6)*Gifts!$Q$6:$Q$1005)*1E9))) | G6: =IF(OR(B6="",N(J6)=0),"",SUMPRODUCT(MAX((Gifts!$C$6:$C$1005=B6)*Gifts!$Q$6:$Q$1005*Gifts!$M$6:$M$1005))) | H6: =IF(B6="","",SUMIFS(Gifts!$D$6:$D$1005,Gifts!$C$6:$C$1005,B6,Gifts!$K$6:$K$1005,Settings!$C$7,Gifts!$D$6:$D$1005,">0")) | I6: =IF(B6="","",SUMIFS(Gifts!$D$6:$D$1005,Gifts!$C$6:$C$1005,B6,Gifts!$D$6:$D$1005,">0",Gifts!$M$6:$M$1005,">0")) | J6: =IF(B6="","",SUMIFS(Gifts!$Q$6:$Q$1005,Gifts!$C$6:$C$1005,B6)) | K6: =IF(B6="","",IF(N(J6)=0,"No gifts yet",IF(AND(N(Settings!$C$9)>0,G6<EDATE(TODAY(),-N(Settings!$C$9))),"Lapsed",IF(YEAR(F6)=N(Settings!$C$7),"New","Active")))) | M6: =IF(OR(B6="",N(H6)<=0),"",ROUND(H6*100,0)*1000+1000-ROW()) | N6: =IF(B6="","",SUMIFS(Gifts!$Q$6:$Q$1005,Gifts!$C$6:$C$1005,B6,Gifts!$K$6:$K$1005,Settings!$C$7))
B7: Daniel Mercer | C7: Person | D7: dan.mercer@mail.example | E7: 4 Quay Street, Riverton | F7: =IF(OR(B7="",N(J7)=0),"",SUMPRODUCT(MIN((Gifts!$C$6:$C$1005=B7)*Gifts!$Q$6:$Q$1005*Gifts!$M$6:$M$1005+(1-(Gifts!$C$6:$C$1005=B7)*Gifts!$Q$6:$Q$1005)*1E9))) | G7: =IF(OR(B7="",N(J7)=0),"",SUMPRODUCT(MAX((Gifts!$C$6:$C$1005=B7)*Gifts!$Q$6:$Q$1005*Gifts!$M$6:$M$1005))) | H7: =IF(B7="","",SUMIFS(Gifts!$D$6:$D$1005,Gifts!$C$6:$C$1005,B7,Gifts!$K$6:$K$1005,Settings!$C$7,Gifts!$D$6:$D$1005,">0")) | I7: =IF(B7="","",SUMIFS(Gifts!$D$6:$D$1005,Gifts!$C$6:$C$1005,B7,Gifts!$D$6:$D$1005,">0",Gifts!$M$6:$M$1005,">0")) | J7: =IF(B7="","",SUMIFS(Gifts!$Q$6:$Q$1005,Gifts!$C$6:$C$1005,B7)) | K7: =IF(B7="","",IF(N(J7)=0,"No gifts yet",IF(AND(N(Settings!$C$9)>0,G7<EDATE(TODAY(),-N(Settings!$C$9))),"Lapsed",IF(YEAR(F7)=N(Settings!$C$7),"New","Active")))) | M7: =IF(OR(B7="",N(H7)<=0),"",ROUND(H7*100,0)*1000+1000-ROW()) | N7: =IF(B7="","",SUMIFS(Gifts!$Q$6:$Q$1005,Gifts!$C$6:$C$1005,B7,Gifts!$K$6:$K$1005,Settings!$C$7))
B8: Riverton Hardware | C8: Business | D8: shop@rivertonhardware.example | E8: 88 High Street, Riverton | F8: =IF(OR(B8="",N(J8)=0),"",SUMPRODUCT(MIN((Gifts!$C$6:$C$1005=B8)*Gifts!$Q$6:$Q$1005*Gifts!$M$6:$M$1005+(1-(Gifts!$C$6:$C$1005=B8)*Gifts!$Q$6:$Q$1005)*1E9))) | G8: =IF(OR(B8="",N(J8)=0),"",SUMPRODUCT(MAX((Gifts!$C$6:$C$1005=B8)*Gifts!$Q$6:$Q$1005*Gifts!$M$6:$M$1005))) | H8: =IF(B8="","",SUMIFS(Gifts!$D$6:$D$1005,Gifts!$C$6:$C$1005,B8,Gifts!$K$6:$K$1005,Settings!$C$7,Gifts!$D$6:$D$1005,">0")) | I8: =IF(B8="","",SUMIFS(Gifts!$D$6:$D$1005,Gifts!$C$6:$C$1005,B8,Gifts!$D$6:$D$1005,">0",Gifts!$M$6:$M$1005,">0")) | J8: =IF(B8="","",SUMIFS(Gifts!$Q$6:$Q$1005,Gifts!$C$6:$C$1005,B8)) | K8: =IF(B8="","",IF(N(J8)=0,"No gifts yet",IF(AND(N(Settings!$C$9)>0,G8<EDATE(TODAY(),-N(Settings!$C$9))),"Lapsed",IF(YEAR(F8)=N(Settings!$C$7),"New","Active")))) | M8: =IF(OR(B8="",N(H8)<=0),"",ROUND(H8*100,0)*1000+1000-ROW()) | N8: =IF(B8="","",SUMIFS(Gifts!$Q$6:$Q$1005,Gifts!$C$6:$C$1005,B8,Gifts!$K$6:$K$1005,Settings!$C$7))
B9: Amina Yusuf | C9: Person | D9: amina.y@mail.example | E9: 31 Elm Close, Riverton | F9: =IF(OR(B9="",N(J9)=0),"",SUMPRODUCT(MIN((Gifts!$C$6:$C$1005=B9)*Gifts!$Q$6:$Q$1005*Gifts!$M$6:$M$1005+(1-(Gifts!$C$6:$C$1005=B9)*Gifts!$Q$6:$Q$1005)*1E9))) | G9: =IF(OR(B9="",N(J9)=0),"",SUMPRODUCT(MAX((Gifts!$C$6:$C$1005=B9)*Gifts!$Q$6:$Q$1005*Gifts!$M$6:$M$1005))) | H9: =IF(B9="","",SUMIFS(Gifts!$D$6:$D$1005,Gifts!$C$6:$C$1005,B9,Gifts!$K$6:$K$1005,Settings!$C$7,Gifts!$D$6:$D$1005,">0")) | I9: =IF(B9="","",SUMIFS(Gifts!$D$6:$D$1005,Gifts!$C$6:$C$1005,B9,Gifts!$D$6:$D$1005,">0",Gifts!$M$6:$M$1005,">0")) | J9: =IF(B9="","",SUMIFS(Gifts!$Q$6:$Q$1005,Gifts!$C$6:$C$1005,B9)) | K9: =IF(B9="","",IF(N(J9)=0,"No gifts yet",IF(AND(N(Settings!$C$9)>0,G9<EDATE(TODAY(),-N(Settings!$C$9))),"Lapsed",IF(YEAR(F9)=N(Settings!$C$7),"New","Active")))) | M9: =IF(OR(B9="",N(H9)<=0),"",ROUND(H9*100,0)*1000+1000-ROW()) | N9: =IF(B9="","",SUMIFS(Gifts!$Q$6:$Q$1005,Gifts!$C$6:$C$1005,B9,Gifts!$K$6:$K$1005,Settings!$C$7))
B10: St Luke's Youth Group | C10: Group | E10: Church Lane, Riverton | F10: =IF(OR(B10="",N(J10)=0),"",SUMPRODUCT(MIN((Gifts!$C$6:$C$1005=B10)*Gifts!$Q$6:$Q$1005*Gifts!$M$6:$M$1005+(1-(Gifts!$C$6:$C$1005=B10)*Gifts!$Q$6:$Q$1005)*1E9))) | G10: =IF(OR(B10="",N(J10)=0),"",SUMPRODUCT(MAX((Gifts!$C$6:$C$1005=B10)*Gifts!$Q$6:$Q$1005*Gifts!$M$6:$M$1005))) | H10: =IF(B10="","",SUMIFS(Gifts!$D$6:$D$1005,Gifts!$C$6:$C$1005,B10,Gifts!$K$6:$K$1005,Settings!$C$7,Gifts!$D$6:$D$1005,">0")) | I10: =IF(B10="","",SUMIFS(Gifts!$D$6:$D$1005,Gifts!$C$6:$C$1005,B10,Gifts!$D$6:$D$1005,">0",Gifts!$M$6:$M$1005,">0")) | J10: =IF(B10="","",SUMIFS(Gifts!$Q$6:$Q$1005,Gifts!$C$6:$C$1005,B10)) | K10: =IF(B10="","",IF(N(J10)=0,"No gifts yet",IF(AND(N(Settings!$C$9)>0,G10<EDATE(TODAY(),-N(Settings!$C$9))),"Lapsed",IF(YEAR(F10)=N(Settings!$C$7),"New","Active")))) | M10: =IF(OR(B10="",N(H10)<=0),"",ROUND(H10*100,0)*1000+1000-ROW()) | N10: =IF(B10="","",SUMIFS(Gifts!$Q$6:$Q$1005,Gifts!$C$6:$C$1005,B10,Gifts!$K$6:$K$1005,Settings!$C$7))
B11: Tom and Jess Carter | C11: Person | D11: carters@mail.example | E11: 7 Mill Yard, Riverton | F11: =IF(OR(B11="",N(J11)=0),"",SUMPRODUCT(MIN((Gifts!$C$6:$C$1005=B11)*Gifts!$Q$6:$Q$1005*Gifts!$M$6:$M$1005+(1-(Gifts!$C$6:$C$1005=B11)*Gifts!$Q$6:$Q$1005)*1E9))) | G11: =IF(OR(B11="",N(J11)=0),"",SUMPRODUCT(MAX((Gifts!$C$6:$C$1005=B11)*Gifts!$Q$6:$Q$1005*Gifts!$M$6:$M$1005))) | H11: =IF(B11="","",SUMIFS(Gifts!$D$6:$D$1005,Gifts!$C$6:$C$1005,B11,Gifts!$K$6:$K$1005,Settings!$C$7,Gifts!$D$6:$D$1005,">0")) | I11: =IF(B11="","",SUMIFS(Gifts!$D$6:$D$1005,Gifts!$C$6:$C$1005,B11,Gifts!$D$6:$D$1005,">0",Gifts!$M$6:$M$1005,">0")) | J11: =IF(B11="","",SUMIFS(Gifts!$Q$6:$Q$1005,Gifts!$C$6:$C$1005,B11)) | K11: =IF(B11="","",IF(N(J11)=0,"No gifts yet",IF(AND(N(Settings!$C$9)>0,G11<EDATE(TODAY(),-N(Settings!$C$9))),"Lapsed",IF(YEAR(F11)=N(Settings!$C$7),"New","Active")))) | M11: =IF(OR(B11="",N(H11)<=0),"",ROUND(H11*100,0)*1000+1000-ROW()) | N11: =IF(B11="","",SUMIFS(Gifts!$Q$6:$Q$1005,Gifts!$C$6:$C$1005,B11,Gifts!$K$6:$K$1005,Settings!$C$7))
B12: Corner Bakery | C12: Business | D12: hello@cornerbakery.example | E12: 2 Market Square, Riverton | F12: =IF(OR(B12="",N(J12)=0),"",SUMPRODUCT(MIN((Gifts!$C$6:$C$1005=B12)*Gifts!$Q$6:$Q$1005*Gifts!$M$6:$M$1005+(1-(Gifts!$C$6:$C$1005=B12)*Gifts!$Q$6:$Q$1005)*1E9))) | G12: =IF(OR(B12="",N(J12)=0),"",SUMPRODUCT(MAX((Gifts!$C$6:$C$1005=B12)*Gifts!$Q$6:$Q$1005*Gifts!$M$6:$M$1005))) | H12: =IF(B12="","",SUMIFS(Gifts!$D$6:$D$1005,Gifts!$C$6:$C$1005,B12,Gifts!$K$6:$K$1005,Settings!$C$7,Gifts!$D$6:$D$1005,">0")) | I12: =IF(B12="","",SUMIFS(Gifts!$D$6:$D$1005,Gifts!$C$6:$C$1005,B12,Gifts!$D$6:$D$1005,">0",Gifts!$M$6:$M$1005,">0")) | J12: =IF(B12="","",SUMIFS(Gifts!$Q$6:$Q$1005,Gifts!$C$6:$C$1005,B12)) | K12: =IF(B12="","",IF(N(J12)=0,"No gifts yet",IF(AND(N(Settings!$C$9)>0,G12<EDATE(TODAY(),-N(Settings!$C$9))),"Lapsed",IF(YEAR(F12)=N(Settings!$C$7),"New","Active")))) | M12: =IF(OR(B12="",N(H12)<=0),"",ROUND(H12*100,0)*1000+1000-ROW()) | N12: =IF(B12="","",SUMIFS(Gifts!$Q$6:$Q$1005,Gifts!$C$6:$C$1005,B12,Gifts!$K$6:$K$1005,Settings!$C$7))
B13: Helen Price | C13: Person | E13: 19 Orchard Way, Riverton | F13: =IF(OR(B13="",N(J13)=0),"",SUMPRODUCT(MIN((Gifts!$C$6:$C$1005=B13)*Gifts!$Q$6:$Q$1005*Gifts!$M$6:$M$1005+(1-(Gifts!$C$6:$C$1005=B13)*Gifts!$Q$6:$Q$1005)*1E9))) | G13: =IF(OR(B13="",N(J13)=0),"",SUMPRODUCT(MAX((Gifts!$C$6:$C$1005=B13)*Gifts!$Q$6:$Q$1005*Gifts!$M$6:$M$1005))) | H13: =IF(B13="","",SUMIFS(Gifts!$D$6:$D$1005,Gifts!$C$6:$C$1005,B13,Gifts!$K$6:$K$1005,Settings!$C$7,Gifts!$D$6:$D$1005,">0")) | I13: =IF(B13="","",SUMIFS(Gifts!$D$6:$D$1005,Gifts!$C$6:$C$1005,B13,Gifts!$D$6:$D$1005,">0",Gifts!$M$6:$M$1005,">0")) | J13: =IF(B13="","",SUMIFS(Gifts!$Q$6:$Q$1005,Gifts!$C$6:$C$1005,B13)) | K13: =IF(B13="","",IF(N(J13)=0,"No gifts yet",IF(AND(N(Settings!$C$9)>0,G13<EDATE(TODAY(),-N(Settings!$C$9))),"Lapsed",IF(YEAR(F13)=N(Settings!$C$7),"New","Active")))) | M13: =IF(OR(B13="",N(H13)<=0),"",ROUND(H13*100,0)*1000+1000-ROW()) | N13: =IF(B13="","",SUMIFS(Gifts!$Q$6:$Q$1005,Gifts!$C$6:$C$1005,B13,Gifts!$K$6:$K$1005,Settings!$C$7))
B14: Ravi Patel | C14: Person | D14: ravi.patel@mail.example | E14: 5 Station Road, Riverton | F14: =IF(OR(B14="",N(J14)=0),"",SUMPRODUCT(MIN((Gifts!$C$6:$C$1005=B14)*Gifts!$Q$6:$Q$1005*Gifts!$M$6:$M$1005+(1-(Gifts!$C$6:$C$1005=B14)*Gifts!$Q$6:$Q$1005)*1E9))) | G14: =IF(OR(B14="",N(J14)=0),"",SUMPRODUCT(MAX((Gifts!$C$6:$C$1005=B14)*Gifts!$Q$6:$Q$1005*Gifts!$M$6:$M$1005))) | H14: =IF(B14="","",SUMIFS(Gifts!$D$6:$D$1005,Gifts!$C$6:$C$1005,B14,Gifts!$K$6:$K$1005,Settings!$C$7,Gifts!$D$6:$D$1005,">0")) | I14: =IF(B14="","",SUMIFS(Gifts!$D$6:$D$1005,Gifts!$C$6:$C$1005,B14,Gifts!$D$6:$D$1005,">0",Gifts!$M$6:$M$1005,">0")) | J14: =IF(B14="","",SUMIFS(Gifts!$Q$6:$Q$1005,Gifts!$C$6:$C$1005,B14)) | K14: =IF(B14="","",IF(N(J14)=0,"No gifts yet",IF(AND(N(Settings!$C$9)>0,G14<EDATE(TODAY(),-N(Settings!$C$9))),"Lapsed",IF(YEAR(F14)=N(Settings!$C$7),"New","Active")))) | M14: =IF(OR(B14="",N(H14)<=0),"",ROUND(H14*100,0)*1000+1000-ROW()) | N14: =IF(B14="","",SUMIFS(Gifts!$Q$6:$Q$1005,Gifts!$C$6:$C$1005,B14,Gifts!$K$6:$K$1005,Settings!$C$7))
B15: Riverton Rotary | C15: Group | D15: rotary@mail.example | F15: =IF(OR(B15="",N(J15)=0),"",SUMPRODUCT(MIN((Gifts!$C$6:$C$1005=B15)*Gifts!$Q$6:$Q$1005*Gifts!$M$6:$M$1005+(1-(Gifts!$C$6:$C$1005=B15)*Gifts!$Q$6:$Q$1005)*1E9))) | G15: =IF(OR(B15="",N(J15)=0),"",SUMPRODUCT(MAX((Gifts!$C$6:$C$1005=B15)*Gifts!$Q$6:$Q$1005*Gifts!$M$6:$M$1005))) | H15: =IF(B15="","",SUMIFS(Gifts!$D$6:$D$1005,Gifts!$C$6:$C$1005,B15,Gifts!$K$6:$K$1005,Settings!$C$7,Gifts!$D$6:$D$1005,">0")) | I15: =IF(B15="","",SUMIFS(Gifts!$D$6:$D$1005,Gifts!$C$6:$C$1005,B15,Gifts!$D$6:$D$1005,">0",Gifts!$M$6:$M$1005,">0")) | J15: =IF(B15="","",SUMIFS(Gifts!$Q$6:$Q$1005,Gifts!$C$6:$C$1005,B15)) | K15: =IF(B15="","",IF(N(J15)=0,"No gifts yet",IF(AND(N(Settings!$C$9)>0,G15<EDATE(TODAY(),-N(Settings!$C$9))),"Lapsed",IF(YEAR(F15)=N(Settings!$C$7),"New","Active")))) | M15: =IF(OR(B15="",N(H15)<=0),"",ROUND(H15*100,0)*1000+1000-ROW()) | N15: =IF(B15="","",SUMIFS(Gifts!$Q$6:$Q$1005,Gifts!$C$6:$C$1005,B15,Gifts!$K$6:$K$1005,Settings!$C$7))
B16: Sofia Rossi | C16: Person | D16: sofia.r@mail.example | E16: 40 Hill Street, Riverton | F16: =IF(OR(B16="",N(J16)=0),"",SUMPRODUCT(MIN((Gifts!$C$6:$C$1005=B16)*Gifts!$Q$6:$Q$1005*Gifts!$M$6:$M$1005+(1-(Gifts!$C$6:$C$1005=B16)*Gifts!$Q$6:$Q$1005)*1E9))) | G16: =IF(OR(B16="",N(J16)=0),"",SUMPRODUCT(MAX((Gifts!$C$6:$C$1005=B16)*Gifts!$Q$6:$Q$1005*Gifts!$M$6:$M$1005))) | H16: =IF(B16="","",SUMIFS(Gifts!$D$6:$D$1005,Gifts!$C$6:$C$1005,B16,Gifts!$K$6:$K$1005,Settings!$C$7,Gifts!$D$6:$D$1005,">0")) | I16: =IF(B16="","",SUMIFS(Gifts!$D$6:$D$1005,Gifts!$C$6:$C$1005,B16,Gifts!$D$6:$D$1005,">0",Gifts!$M$6:$M$1005,">0")) | J16: =IF(B16="","",SUMIFS(Gifts!$Q$6:$Q$1005,Gifts!$C$6:$C$1005,B16)) | K16: =IF(B16="","",IF(N(J16)=0,"No gifts yet",IF(AND(N(Settings!$C$9)>0,G16<EDATE(TODAY(),-N(Settings!$C$9))),"Lapsed",IF(YEAR(F16)=N(Settings!$C$7),"New","Active")))) | M16: =IF(OR(B16="",N(H16)<=0),"",ROUND(H16*100,0)*1000+1000-ROW()) | N16: =IF(B16="","",SUMIFS(Gifts!$Q$6:$Q$1005,Gifts!$C$6:$C$1005,B16,Gifts!$K$6:$K$1005,Settings!$C$7))
B17: Old Mill Trust | C17: Foundation | D17: grants@oldmill.example | E17: The Old Mill, Riverton | F17: =IF(OR(B17="",N(J17)=0),"",SUMPRODUCT(MIN((Gifts!$C$6:$C$1005=B17)*Gifts!$Q$6:$Q$1005*Gifts!$M$6:$M$1005+(1-(Gifts!$C$6:$C$1005=B17)*Gifts!$Q$6:$Q$1005)*1E9))) | G17: =IF(OR(B17="",N(J17)=0),"",SUMPRODUCT(MAX((Gifts!$C$6:$C$1005=B17)*Gifts!$Q$6:$Q$1005*Gifts!$M$6:$M$1005))) | H17: =IF(B17="","",SUMIFS(Gifts!$D$6:$D$1005,Gifts!$C$6:$C$1005,B17,Gifts!$K$6:$K$1005,Settings!$C$7,Gifts!$D$6:$D$1005,">0")) | I17: =IF(B17="","",SUMIFS(Gifts!$D$6:$D$1005,Gifts!$C$6:$C$1005,B17,Gifts!$D$6:$D$1005,">0",Gifts!$M$6:$M$1005,">0")) | J17: =IF(B17="","",SUMIFS(Gifts!$Q$6:$Q$1005,Gifts!$C$6:$C$1005,B17)) | K17: =IF(B17="","",IF(N(J17)=0,"No gifts yet",IF(AND(N(Settings!$C$9)>0,G17<EDATE(TODAY(),-N(Settings!$C$9))),"Lapsed",IF(YEAR(F17)=N(Settings!$C$7),"New","Active")))) | M17: =IF(OR(B17="",N(H17)<=0),"",ROUND(H17*100,0)*1000+1000-ROW()) | N17: =IF(B17="","",SUMIFS(Gifts!$Q$6:$Q$1005,Gifts!$C$6:$C$1005,B17,Gifts!$K$6:$K$1005,Settings!$C$7))
F18: =IF(OR(B18="",N(J18)=0),"",SUMPRODUCT(MIN((Gifts!$C$6:$C$1005=B18)*Gifts!$Q$6:$Q$1005*Gifts!$M$6:$M$1005+(1-(Gifts!$C$6:$C$1005=B18)*Gifts!$Q$6:$Q$1005)*1E9))) | G18: =IF(OR(B18="",N(J18)=0),"",SUMPRODUCT(MAX((Gifts!$C$6:$C$1005=B18)*Gifts!$Q$6:$Q$1005*Gifts!$M$6:$M$1005))) | H18: =IF(B18="","",SUMIFS(Gifts!$D$6:$D$1005,Gifts!$C$6:$C$1005,B18,Gifts!$K$6:$K$1005,Settings!$C$7,Gifts!$D$6:$D$1005,">0")) | I18: =IF(B18="","",SUMIFS(Gifts!$D$6:$D$1005,Gifts!$C$6:$C$1005,B18,Gifts!$D$6:$D$1005,">0",Gifts!$M$6:$M$1005,">0")) | J18: =IF(B18="","",SUMIFS(Gifts!$Q$6:$Q$1005,Gifts!$C$6:$C$1005,B18)) | K18: =IF(B18="","",IF(N(J18)=0,"No gifts yet",IF(AND(N(Settings!$C$9)>0,G18<EDATE(TODAY(),-N(Settings!$C$9))),"Lapsed",IF(YEAR(F18)=N(Settings!$C$7),"New","Active")))) | M18: =IF(OR(B18="",N(H18)<=0),"",ROUND(H18*100,0)*1000+1000-ROW()) | N18: =IF(B18="","",SUMIFS(Gifts!$Q$6:$Q$1005,Gifts!$C$6:$C$1005,B18,Gifts!$K$6:$K$1005,Settings!$C$7))
F19: =IF(OR(B19="",N(J19)=0),"",SUMPRODUCT(MIN((Gifts!$C$6:$C$1005=B19)*Gifts!$Q$6:$Q$1005*Gifts!$M$6:$M$1005+(1-(Gifts!$C$6:$C$1005=B19)*Gifts!$Q$6:$Q$1005)*1E9))) | G19: =IF(OR(B19="",N(J19)=0),"",SUMPRODUCT(MAX((Gifts!$C$6:$C$1005=B19)*Gifts!$Q$6:$Q$1005*Gifts!$M$6:$M$1005))) | H19: =IF(B19="","",SUMIFS(Gifts!$D$6:$D$1005,Gifts!$C$6:$C$1005,B19,Gifts!$K$6:$K$1005,Settings!$C$7,Gifts!$D$6:$D$1005,">0")) | I19: =IF(B19="","",SUMIFS(Gifts!$D$6:$D$1005,Gifts!$C$6:$C$1005,B19,Gifts!$D$6:$D$1005,">0",Gifts!$M$6:$M$1005,">0")) | J19: =IF(B19="","",SUMIFS(Gifts!$Q$6:$Q$1005,Gifts!$C$6:$C$1005,B19)) | K19: =IF(B19="","",IF(N(J19)=0,"No gifts yet",IF(AND(N(Settings!$C$9)>0,G19<EDATE(TODAY(),-N(Settings!$C$9))),"Lapsed",IF(YEAR(F19)=N(Settings!$C$7),"New","Active")))) | M19: =IF(OR(B19="",N(H19)<=0),"",ROUND(H19*100,0)*1000+1000-ROW()) | N19: =IF(B19="","",SUMIFS(Gifts!$Q$6:$Q$1005,Gifts!$C$6:$C$1005,B19,Gifts!$K$6:$K$1005,Settings!$C$7))
F20: =IF(OR(B20="",N(J20)=0),"",SUMPRODUCT(MIN((Gifts!$C$6:$C$1005=B20)*Gifts!$Q$6:$Q$1005*Gifts!$M$6:$M$1005+(1-(Gifts!$C$6:$C$1005=B20)*Gifts!$Q$6:$Q$1005)*1E9))) | G20: =IF(OR(B20="",N(J20)=0),"",SUMPRODUCT(MAX((Gifts!$C$6:$C$1005=B20)*Gifts!$Q$6:$Q$1005*Gifts!$M$6:$M$1005))) | H20: =IF(B20="","",SUMIFS(Gifts!$D$6:$D$1005,Gifts!$C$6:$C$1005,B20,Gifts!$K$6:$K$1005,Settings!$C$7,Gifts!$D$6:$D$1005,">0")) | I20: =IF(B20="","",SUMIFS(Gifts!$D$6:$D$1005,Gifts!$C$6:$C$1005,B20,Gifts!$D$6:$D$1005,">0",Gifts!$M$6:$M$1005,">0")) | J20: =IF(B20="","",SUMIFS(Gifts!$Q$6:$Q$1005,Gifts!$C$6:$C$1005,B20)) | K20: =IF(B20="","",IF(N(J20)=0,"No gifts yet",IF(AND(N(Settings!$C$9)>0,G20<EDATE(TODAY(),-N(Settings!$C$9))),"Lapsed",IF(YEAR(F20)=N(Settings!$C$7),"New","Active")))) | M20: =IF(OR(B20="",N(H20)<=0),"",ROUND(H20*100,0)*1000+1000-ROW()) | N20: =IF(B20="","",SUMIFS(Gifts!$Q$6:$Q$1005,Gifts!$C$6:$C$1005,B20,Gifts!$K$6:$K$1005,Settings!$C$7))
F21: =IF(OR(B21="",N(J21)=0),"",SUMPRODUCT(MIN((Gifts!$C$6:$C$1005=B21)*Gifts!$Q$6:$Q$1005*Gifts!$M$6:$M$1005+(1-(Gifts!$C$6:$C$1005=B21)*Gifts!$Q$6:$Q$1005)*1E9))) | G21: =IF(OR(B21="",N(J21)=0),"",SUMPRODUCT(MAX((Gifts!$C$6:$C$1005=B21)*Gifts!$Q$6:$Q$1005*Gifts!$M$6:$M$1005))) | H21: =IF(B21="","",SUMIFS(Gifts!$D$6:$D$1005,Gifts!$C$6:$C$1005,B21,Gifts!$K$6:$K$1005,Settings!$C$7,Gifts!$D$6:$D$1005,">0")) | I21: =IF(B21="","",SUMIFS(Gifts!$D$6:$D$1005,Gifts!$C$6:$C$1005,B21,Gifts!$D$6:$D$1005,">0",Gifts!$M$6:$M$1005,">0")) | J21: =IF(B21="","",SUMIFS(Gifts!$Q$6:$Q$1005,Gifts!$C$6:$C$1005,B21)) | K21: =IF(B21="","",IF(N(J21)=0,"No gifts yet",IF(AND(N(Settings!$C$9)>0,G21<EDATE(TODAY(),-N(Settings!$C$9))),"Lapsed",IF(YEAR(F21)=N(Settings!$C$7),"New","Active")))) | M21: =IF(OR(B21="",N(H21)<=0),"",ROUND(H21*100,0)*1000+1000-ROW()) | N21: =IF(B21="","",SUMIFS(Gifts!$Q$6:$Q$1005,Gifts!$C$6:$C$1005,B21,Gifts!$K$6:$K$1005,Settings!$C$7))
F22: =IF(OR(B22="",N(J22)=0),"",SUMPRODUCT(MIN((Gifts!$C$6:$C$1005=B22)*Gifts!$Q$6:$Q$1005*Gifts!$M$6:$M$1005+(1-(Gifts!$C$6:$C$1005=B22)*Gifts!$Q$6:$Q$1005)*1E9))) | G22: =IF(OR(B22="",N(J22)=0),"",SUMPRODUCT(MAX((Gifts!$C$6:$C$1005=B22)*Gifts!$Q$6:$Q$1005*Gifts!$M$6:$M$1005))) | H22: =IF(B22="","",SUMIFS(Gifts!$D$6:$D$1005,Gifts!$C$6:$C$1005,B22,Gifts!$K$6:$K$1005,Settings!$C$7,Gifts!$D$6:$D$1005,">0")) | I22: =IF(B22="","",SUMIFS(Gifts!$D$6:$D$1005,Gifts!$C$6:$C$1005,B22,Gifts!$D$6:$D$1005,">0",Gifts!$M$6:$M$1005,">0")) | J22: =IF(B22="","",SUMIFS(Gifts!$Q$6:$Q$1005,Gifts!$C$6:$C$1005,B22)) | K22: =IF(B22="","",IF(N(J22)=0,"No gifts yet",IF(AND(N(Settings!$C$9)>0,G22<EDATE(TODAY(),-N(Settings!$C$9))),"Lapsed",IF(YEAR(F22)=N(Settings!$C$7),"New","Active")))) | M22: =IF(OR(B22="",N(H22)<=0),"",ROUND(H22*100,0)*1000+1000-ROW()) | N22: =IF(B22="","",SUMIFS(Gifts!$Q$6:$Q$1005,Gifts!$C$6:$C$1005,B22,Gifts!$K$6:$K$1005,Settings!$C$7))
F23: =IF(OR(B23="",N(J23)=0),"",SUMPRODUCT(MIN((Gifts!$C$6:$C$1005=B23)*Gifts!$Q$6:$Q$1005*Gifts!$M$6:$M$1005+(1-(Gifts!$C$6:$C$1005=B23)*Gifts!$Q$6:$Q$1005)*1E9))) | G23: =IF(OR(B23="",N(J23)=0),"",SUMPRODUCT(MAX((Gifts!$C$6:$C$1005=B23)*Gifts!$Q$6:$Q$1005*Gifts!$M$6:$M$1005))) | H23: =IF(B23="","",SUMIFS(Gifts!$D$6:$D$1005,Gifts!$C$6:$C$1005,B23,Gifts!$K$6:$K$1005,Settings!$C$7,Gifts!$D$6:$D$1005,">0")) | I23: =IF(B23="","",SUMIFS(Gifts!$D$6:$D$1005,Gifts!$C$6:$C$1005,B23,Gifts!$D$6:$D$1005,">0",Gifts!$M$6:$M$1005,">0")) | J23: =IF(B23="","",SUMIFS(Gifts!$Q$6:$Q$1005,Gifts!$C$6:$C$1005,B23)) | K23: =IF(B23="","",IF(N(J23)=0,"No gifts yet",IF(AND(N(Settings!$C$9)>0,G23<EDATE(TODAY(),-N(Settings!$C$9))),"Lapsed",IF(YEAR(F23)=N(Settings!$C$7),"New","Active")))) | M23: =IF(OR(B23="",N(H23)<=0),"",ROUND(H23*100,0)*1000+1000-ROW()) | N23: =IF(B23="","",SUMIFS(Gifts!$Q$6:$Q$1005,Gifts!$C$6:$C$1005,B23,Gifts!$K$6:$K$1005,Settings!$C$7))
