Workbook

Sheet Dashboard
B2: Job search
B3: Where every application stands, and what to do next.
B4: Applied | C4: This week | D4: Replies | E4: Interviews | G4: Offers | H4: To follow up | I4: No reply | J4: Days searching
B5: =COUNT(Applications!$J$6:$J$305) | C5: =COUNTIFS(Applications!$J$6:$J$305,">="&(TODAY()-WEEKDAY(TODAY(),3)),Applications!$J$6:$J$305,"<="&((TODAY()-WEEKDAY(TODAY(),3))+6))&" of "&N(Settings!$C$4) | D5: =IF(COUNT(Applications!$J$6:$J$305)=0,"",(COUNTIF(Applications!$K$6:$K$305,"Screening")+COUNTIF(Applications!$K$6:$K$305,"Interview")+COUNTIF(Applications!$K$6:$K$305,"Final interview")+COUNTIF(Applications!$K$6:$K$305,"Offer")+COUNTIF(Applications!$K$6:$K$305,"Accepted")+COUNTIF(Applications!$K$6:$K$305,"Rejected"))/COUNT(Applications!$J$6:$J$305)) | E5: =COUNTIFS(Interviews!$B$6:$B$205,"<="&TODAY()) | G5: =COUNTIF(Applications!$K$6:$K$305,"Offer")+COUNTIF(Applications!$K$6:$K$305,"Accepted") | H5: =COUNTIF(Applications!$R$6:$R$305,"Follow up")+COUNTIF(Applications!$R$6:$R$305,"Due*") | I5: =COUNTIF(Applications!$R$6:$R$305,"No reply") | J5: =IF(COUNT(Applications!$J$6:$J$305)=0,"",TODAY()-MIN(Applications!$J$6:$J$305))
B8: Pipeline | C8: Now | D8: Share | G8: Next steps | H8: Role | I8: What | J8: When
B9: =Settings!B11 | C9: =COUNTIF(Applications!$K$6:$K$305,B9) | D9: =IF(COUNTA(Applications!$B$6:$B$305)=0,"",C9/COUNTA(Applications!$B$6:$B$305)) | E9: =IF(OR(D9="",N(D9)=0),"",REPT("█",MIN(12,MAX(0,ROUND((D9)*12,0))))&REPT("░",12-MIN(12,MAX(0,ROUND((D9)*12,0))))) | G9: =IF(O9="","Nothing to do yet",INDEX(Applications!$B$6:$B$305,MATCH(O9,Applications!$V$6:$V$305,0))) | H9: =IF(O9="","",INDEX(Applications!$C$6:$C$305,MATCH(O9,Applications!$V$6:$V$305,0))) | I9: =IF(O9="","",INDEX(Applications!$W$6:$W$305,MATCH(O9,Applications!$V$6:$V$305,0))) | J9: =IF(O9="","",INT(O9)) | O9: =IFERROR(SMALL(Applications!$V$6:$V$305,1),"")
B10: =Settings!B12 | C10: =COUNTIF(Applications!$K$6:$K$305,B10) | D10: =IF(COUNTA(Applications!$B$6:$B$305)=0,"",C10/COUNTA(Applications!$B$6:$B$305)) | E10: =IF(OR(D10="",N(D10)=0),"",REPT("█",MIN(12,MAX(0,ROUND((D10)*12,0))))&REPT("░",12-MIN(12,MAX(0,ROUND((D10)*12,0))))) | G10: =IF(O10="","",INDEX(Applications!$B$6:$B$305,MATCH(O10,Applications!$V$6:$V$305,0))) | H10: =IF(O10="","",INDEX(Applications!$C$6:$C$305,MATCH(O10,Applications!$V$6:$V$305,0))) | I10: =IF(O10="","",INDEX(Applications!$W$6:$W$305,MATCH(O10,Applications!$V$6:$V$305,0))) | J10: =IF(O10="","",INT(O10)) | O10: =IFERROR(SMALL(Applications!$V$6:$V$305,2),"")
B11: =Settings!B13 | C11: =COUNTIF(Applications!$K$6:$K$305,B11) | D11: =IF(COUNTA(Applications!$B$6:$B$305)=0,"",C11/COUNTA(Applications!$B$6:$B$305)) | E11: =IF(OR(D11="",N(D11)=0),"",REPT("█",MIN(12,MAX(0,ROUND((D11)*12,0))))&REPT("░",12-MIN(12,MAX(0,ROUND((D11)*12,0))))) | G11: =IF(O11="","",INDEX(Applications!$B$6:$B$305,MATCH(O11,Applications!$V$6:$V$305,0))) | H11: =IF(O11="","",INDEX(Applications!$C$6:$C$305,MATCH(O11,Applications!$V$6:$V$305,0))) | I11: =IF(O11="","",INDEX(Applications!$W$6:$W$305,MATCH(O11,Applications!$V$6:$V$305,0))) | J11: =IF(O11="","",INT(O11)) | O11: =IFERROR(SMALL(Applications!$V$6:$V$305,3),"")
B12: =Settings!B14 | C12: =COUNTIF(Applications!$K$6:$K$305,B12) | D12: =IF(COUNTA(Applications!$B$6:$B$305)=0,"",C12/COUNTA(Applications!$B$6:$B$305)) | E12: =IF(OR(D12="",N(D12)=0),"",REPT("█",MIN(12,MAX(0,ROUND((D12)*12,0))))&REPT("░",12-MIN(12,MAX(0,ROUND((D12)*12,0))))) | G12: =IF(O12="","",INDEX(Applications!$B$6:$B$305,MATCH(O12,Applications!$V$6:$V$305,0))) | H12: =IF(O12="","",INDEX(Applications!$C$6:$C$305,MATCH(O12,Applications!$V$6:$V$305,0))) | I12: =IF(O12="","",INDEX(Applications!$W$6:$W$305,MATCH(O12,Applications!$V$6:$V$305,0))) | J12: =IF(O12="","",INT(O12)) | O12: =IFERROR(SMALL(Applications!$V$6:$V$305,4),"")
B13: =Settings!B15 | C13: =COUNTIF(Applications!$K$6:$K$305,B13) | D13: =IF(COUNTA(Applications!$B$6:$B$305)=0,"",C13/COUNTA(Applications!$B$6:$B$305)) | E13: =IF(OR(D13="",N(D13)=0),"",REPT("█",MIN(12,MAX(0,ROUND((D13)*12,0))))&REPT("░",12-MIN(12,MAX(0,ROUND((D13)*12,0))))) | G13: =IF(O13="","",INDEX(Applications!$B$6:$B$305,MATCH(O13,Applications!$V$6:$V$305,0))) | H13: =IF(O13="","",INDEX(Applications!$C$6:$C$305,MATCH(O13,Applications!$V$6:$V$305,0))) | I13: =IF(O13="","",INDEX(Applications!$W$6:$W$305,MATCH(O13,Applications!$V$6:$V$305,0))) | J13: =IF(O13="","",INT(O13)) | O13: =IFERROR(SMALL(Applications!$V$6:$V$305,5),"")
B14: =Settings!B16 | C14: =COUNTIF(Applications!$K$6:$K$305,B14) | D14: =IF(COUNTA(Applications!$B$6:$B$305)=0,"",C14/COUNTA(Applications!$B$6:$B$305)) | E14: =IF(OR(D14="",N(D14)=0),"",REPT("█",MIN(12,MAX(0,ROUND((D14)*12,0))))&REPT("░",12-MIN(12,MAX(0,ROUND((D14)*12,0))))) | G14: =IF(O14="","",INDEX(Applications!$B$6:$B$305,MATCH(O14,Applications!$V$6:$V$305,0))) | H14: =IF(O14="","",INDEX(Applications!$C$6:$C$305,MATCH(O14,Applications!$V$6:$V$305,0))) | I14: =IF(O14="","",INDEX(Applications!$W$6:$W$305,MATCH(O14,Applications!$V$6:$V$305,0))) | J14: =IF(O14="","",INT(O14)) | O14: =IFERROR(SMALL(Applications!$V$6:$V$305,6),"")
B15: =Settings!B17 | C15: =COUNTIF(Applications!$K$6:$K$305,B15) | D15: =IF(COUNTA(Applications!$B$6:$B$305)=0,"",C15/COUNTA(Applications!$B$6:$B$305)) | E15: =IF(OR(D15="",N(D15)=0),"",REPT("█",MIN(12,MAX(0,ROUND((D15)*12,0))))&REPT("░",12-MIN(12,MAX(0,ROUND((D15)*12,0))))) | G15: =IF(O15="","",INDEX(Applications!$B$6:$B$305,MATCH(O15,Applications!$V$6:$V$305,0))) | H15: =IF(O15="","",INDEX(Applications!$C$6:$C$305,MATCH(O15,Applications!$V$6:$V$305,0))) | I15: =IF(O15="","",INDEX(Applications!$W$6:$W$305,MATCH(O15,Applications!$V$6:$V$305,0))) | J15: =IF(O15="","",INT(O15)) | O15: =IFERROR(SMALL(Applications!$V$6:$V$305,7),"")
B16: =Settings!B18 | C16: =COUNTIF(Applications!$K$6:$K$305,B16) | D16: =IF(COUNTA(Applications!$B$6:$B$305)=0,"",C16/COUNTA(Applications!$B$6:$B$305)) | E16: =IF(OR(D16="",N(D16)=0),"",REPT("█",MIN(12,MAX(0,ROUND((D16)*12,0))))&REPT("░",12-MIN(12,MAX(0,ROUND((D16)*12,0))))) | G16: =IF(O16="","",INDEX(Applications!$B$6:$B$305,MATCH(O16,Applications!$V$6:$V$305,0))) | H16: =IF(O16="","",INDEX(Applications!$C$6:$C$305,MATCH(O16,Applications!$V$6:$V$305,0))) | I16: =IF(O16="","",INDEX(Applications!$W$6:$W$305,MATCH(O16,Applications!$V$6:$V$305,0))) | J16: =IF(O16="","",INT(O16)) | O16: =IFERROR(SMALL(Applications!$V$6:$V$305,8),"")
B17: =Settings!B19 | C17: =COUNTIF(Applications!$K$6:$K$305,B17) | D17: =IF(COUNTA(Applications!$B$6:$B$305)=0,"",C17/COUNTA(Applications!$B$6:$B$305)) | E17: =IF(OR(D17="",N(D17)=0),"",REPT("█",MIN(12,MAX(0,ROUND((D17)*12,0))))&REPT("░",12-MIN(12,MAX(0,ROUND((D17)*12,0))))) | G17: =IF(O17="","",INDEX(Applications!$B$6:$B$305,MATCH(O17,Applications!$V$6:$V$305,0))) | H17: =IF(O17="","",INDEX(Applications!$C$6:$C$305,MATCH(O17,Applications!$V$6:$V$305,0))) | I17: =IF(O17="","",INDEX(Applications!$W$6:$W$305,MATCH(O17,Applications!$V$6:$V$305,0))) | J17: =IF(O17="","",INT(O17)) | O17: =IFERROR(SMALL(Applications!$V$6:$V$305,9),"")
G18: =IF(O18="","",INDEX(Applications!$B$6:$B$305,MATCH(O18,Applications!$V$6:$V$305,0))) | H18: =IF(O18="","",INDEX(Applications!$C$6:$C$305,MATCH(O18,Applications!$V$6:$V$305,0))) | I18: =IF(O18="","",INDEX(Applications!$W$6:$W$305,MATCH(O18,Applications!$V$6:$V$305,0))) | J18: =IF(O18="","",INT(O18)) | O18: =IFERROR(SMALL(Applications!$V$6:$V$305,10),"")
B21: Week of | C21: Applied | D21: Goal | G21: Coming interviews | H21: Company | I21: Type | J21: Time
B22: =((TODAY()-WEEKDAY(TODAY(),3))-49) | C22: =COUNTIFS(Applications!$J$6:$J$305,">="&B22,Applications!$J$6:$J$305,"<="&(B22+6)) | D22: =N(Settings!$C$4) | G22: =IF(P22="","None booked yet",INT(P22)) | H22: =IF(P22="","",INDEX(Interviews!$D$6:$D$205,MATCH(P22,Interviews!$L$6:$L$205,0))) | I22: =IF(P22="","",IF(INDEX(Interviews!$F$6:$F$205,MATCH(P22,Interviews!$L$6:$L$205,0))="","",INDEX(Interviews!$F$6:$F$205,MATCH(P22,Interviews!$L$6:$L$205,0)))) | J22: =IF(P22="","",IF(INDEX(Interviews!$C$6:$C$205,MATCH(P22,Interviews!$L$6:$L$205,0))="","",INDEX(Interviews!$C$6:$C$205,MATCH(P22,Interviews!$L$6:$L$205,0)))) | P22: =IFERROR(SMALL(Interviews!$L$6:$L$205,1),"")
B23: =((TODAY()-WEEKDAY(TODAY(),3))-42) | C23: =COUNTIFS(Applications!$J$6:$J$305,">="&B23,Applications!$J$6:$J$305,"<="&(B23+6)) | D23: =N(Settings!$C$4) | G23: =IF(P23="","",INT(P23)) | H23: =IF(P23="","",INDEX(Interviews!$D$6:$D$205,MATCH(P23,Interviews!$L$6:$L$205,0))) | I23: =IF(P23="","",IF(INDEX(Interviews!$F$6:$F$205,MATCH(P23,Interviews!$L$6:$L$205,0))="","",INDEX(Interviews!$F$6:$F$205,MATCH(P23,Interviews!$L$6:$L$205,0)))) | J23: =IF(P23="","",IF(INDEX(Interviews!$C$6:$C$205,MATCH(P23,Interviews!$L$6:$L$205,0))="","",INDEX(Interviews!$C$6:$C$205,MATCH(P23,Interviews!$L$6:$L$205,0)))) | P23: =IFERROR(SMALL(Interviews!$L$6:$L$205,2),"")
B24: =((TODAY()-WEEKDAY(TODAY(),3))-35) | C24: =COUNTIFS(Applications!$J$6:$J$305,">="&B24,Applications!$J$6:$J$305,"<="&(B24+6)) | D24: =N(Settings!$C$4) | G24: =IF(P24="","",INT(P24)) | H24: =IF(P24="","",INDEX(Interviews!$D$6:$D$205,MATCH(P24,Interviews!$L$6:$L$205,0))) | I24: =IF(P24="","",IF(INDEX(Interviews!$F$6:$F$205,MATCH(P24,Interviews!$L$6:$L$205,0))="","",INDEX(Interviews!$F$6:$F$205,MATCH(P24,Interviews!$L$6:$L$205,0)))) | J24: =IF(P24="","",IF(INDEX(Interviews!$C$6:$C$205,MATCH(P24,Interviews!$L$6:$L$205,0))="","",INDEX(Interviews!$C$6:$C$205,MATCH(P24,Interviews!$L$6:$L$205,0)))) | P24: =IFERROR(SMALL(Interviews!$L$6:$L$205,3),"")
B25: =((TODAY()-WEEKDAY(TODAY(),3))-28) | C25: =COUNTIFS(Applications!$J$6:$J$305,">="&B25,Applications!$J$6:$J$305,"<="&(B25+6)) | D25: =N(Settings!$C$4) | G25: =IF(P25="","",INT(P25)) | H25: =IF(P25="","",INDEX(Interviews!$D$6:$D$205,MATCH(P25,Interviews!$L$6:$L$205,0))) | I25: =IF(P25="","",IF(INDEX(Interviews!$F$6:$F$205,MATCH(P25,Interviews!$L$6:$L$205,0))="","",INDEX(Interviews!$F$6:$F$205,MATCH(P25,Interviews!$L$6:$L$205,0)))) | J25: =IF(P25="","",IF(INDEX(Interviews!$C$6:$C$205,MATCH(P25,Interviews!$L$6:$L$205,0))="","",INDEX(Interviews!$C$6:$C$205,MATCH(P25,Interviews!$L$6:$L$205,0)))) | P25: =IFERROR(SMALL(Interviews!$L$6:$L$205,4),"")
B26: =((TODAY()-WEEKDAY(TODAY(),3))-21) | C26: =COUNTIFS(Applications!$J$6:$J$305,">="&B26,Applications!$J$6:$J$305,"<="&(B26+6)) | D26: =N(Settings!$C$4) | G26: =IF(P26="","",INT(P26)) | H26: =IF(P26="","",INDEX(Interviews!$D$6:$D$205,MATCH(P26,Interviews!$L$6:$L$205,0))) | I26: =IF(P26="","",IF(INDEX(Interviews!$F$6:$F$205,MATCH(P26,Interviews!$L$6:$L$205,0))="","",INDEX(Interviews!$F$6:$F$205,MATCH(P26,Interviews!$L$6:$L$205,0)))) | J26: =IF(P26="","",IF(INDEX(Interviews!$C$6:$C$205,MATCH(P26,Interviews!$L$6:$L$205,0))="","",INDEX(Interviews!$C$6:$C$205,MATCH(P26,Interviews!$L$6:$L$205,0)))) | P26: =IFERROR(SMALL(Interviews!$L$6:$L$205,5),"")
B27: =((TODAY()-WEEKDAY(TODAY(),3))-14) | C27: =COUNTIFS(Applications!$J$6:$J$305,">="&B27,Applications!$J$6:$J$305,"<="&(B27+6)) | D27: =N(Settings!$C$4) | G27: =IF(P27="","",INT(P27)) | H27: =IF(P27="","",INDEX(Interviews!$D$6:$D$205,MATCH(P27,Interviews!$L$6:$L$205,0))) | I27: =IF(P27="","",IF(INDEX(Interviews!$F$6:$F$205,MATCH(P27,Interviews!$L$6:$L$205,0))="","",INDEX(Interviews!$F$6:$F$205,MATCH(P27,Interviews!$L$6:$L$205,0)))) | J27: =IF(P27="","",IF(INDEX(Interviews!$C$6:$C$205,MATCH(P27,Interviews!$L$6:$L$205,0))="","",INDEX(Interviews!$C$6:$C$205,MATCH(P27,Interviews!$L$6:$L$205,0)))) | P27: =IFERROR(SMALL(Interviews!$L$6:$L$205,6),"")
B28: =((TODAY()-WEEKDAY(TODAY(),3))-7) | C28: =COUNTIFS(Applications!$J$6:$J$305,">="&B28,Applications!$J$6:$J$305,"<="&(B28+6)) | D28: =N(Settings!$C$4)
B29: =((TODAY()-WEEKDAY(TODAY(),3))-0) | C29: =COUNTIFS(Applications!$J$6:$J$305,">="&B29,Applications!$J$6:$J$305,"<="&(B29+6)) | D29: =N(Settings!$C$4)

Sheet Applications
B2: Applications
B3: One line per job. Keep the stage and the last contact up to date: the status and the next steps follow.
B5: Company | C5: Role | D5: Where | E5: Link | F5: Pay from | G5: Pay to | H5: Source | I5: Saved on | J5: Applied on | K5: Stage | L5: Last contact | M5: Next step | N5: Next step on | O5: Priority | P5: Contact | Q5: Days | R5: Status
B6: Fernhill Labs | C6: Product Designer | D6: Remote | E6: fernhill.example/jobs/41 | F6: 90000 | G6: 105000 | H6: Job board | I6: 46245 | J6: 46246 | K6: Rejected | L6: 46263 | O6: Medium | Q6: =IF(OR(B6="",J6=""),"",TODAY()-J6) | R6: =IF(B6="","",IF(OR(K6="Accepted",K6="Rejected",K6="Withdrawn"),K6,IF(K6="Offer",IF(N6="","Offer","Offer, reply by "&DAY(N6)&" "&CHOOSE(MONTH(N6),"Jan","Feb","Mar","Apr","May","Jun","Jul","Aug","Sep","Oct","Nov","Dec")),IF(OR(K6="",K6="Saved"),IF(N6="","To apply",IF(N6<TODAY(),"Closing date passed","Apply by "&DAY(N6)&" "&CHOOSE(MONTH(N6),"Jan","Feb","Mar","Apr","May","Jun","Jul","Aug","Sep","Oct","Nov","Dec"))),IF(AND(N6="",T6>0,TODAY()-T6>=N(Settings!$C$6)),"No reply",IF(U6="","Waiting",IF(U6<TODAY(),"Follow up",IF(U6-TODAY()<=2,"Due "&DAY(U6)&" "&CHOOSE(MONTH(U6),"Jan","Feb","Mar","Apr","May","Jun","Jul","Aug","Sep","Oct","Nov","Dec"),"Waiting")))))))) | T6: =MAX(N(J6),N(L6)) | U6: =IF(N6<>"",N6,IF(T6=0,"",T6+N(Settings!$C$5))) | V6: =IF(AND(B6<>"",U6<>"",OR(R6="Follow up",LEFT(R6,3)="Due",R6="Waiting",LEFT(R6,5)="Apply",LEFT(R6,5)="Offer")),U6+ROW()/10000000,"") | W6: =IF(B6="","",IF(M6<>"",M6,IF(OR(K6="",K6="Saved"),"Apply",IF(K6="Offer","Reply to the offer","Follow up"))))
B7: Quillmark | C7: UX Designer | D7: Hybrid, Riverton | E7: quillmark.example/careers | F7: 85000 | G7: 95000 | H7: Company site | I7: 46247 | J7: 46248 | K7: Applied | O7: Low | Q7: =IF(OR(B7="",J7=""),"",TODAY()-J7) | R7: =IF(B7="","",IF(OR(K7="Accepted",K7="Rejected",K7="Withdrawn"),K7,IF(K7="Offer",IF(N7="","Offer","Offer, reply by "&DAY(N7)&" "&CHOOSE(MONTH(N7),"Jan","Feb","Mar","Apr","May","Jun","Jul","Aug","Sep","Oct","Nov","Dec")),IF(OR(K7="",K7="Saved"),IF(N7="","To apply",IF(N7<TODAY(),"Closing date passed","Apply by "&DAY(N7)&" "&CHOOSE(MONTH(N7),"Jan","Feb","Mar","Apr","May","Jun","Jul","Aug","Sep","Oct","Nov","Dec"))),IF(AND(N7="",T7>0,TODAY()-T7>=N(Settings!$C$6)),"No reply",IF(U7="","Waiting",IF(U7<TODAY(),"Follow up",IF(U7-TODAY()<=2,"Due "&DAY(U7)&" "&CHOOSE(MONTH(U7),"Jan","Feb","Mar","Apr","May","Jun","Jul","Aug","Sep","Oct","Nov","Dec"),"Waiting")))))))) | T7: =MAX(N(J7),N(L7)) | U7: =IF(N7<>"",N7,IF(T7=0,"",T7+N(Settings!$C$5))) | V7: =IF(AND(B7<>"",U7<>"",OR(R7="Follow up",LEFT(R7,3)="Due",R7="Waiting",LEFT(R7,5)="Apply",LEFT(R7,5)="Offer")),U7+ROW()/10000000,"") | W7: =IF(B7="","",IF(M7<>"",M7,IF(OR(K7="",K7="Saved"),"Apply",IF(K7="Offer","Reply to the offer","Follow up"))))
B8: Tidewell Health | C8: Senior Product Designer | D8: Remote | E8: tidewell.example/jobs/ux | F8: 105000 | G8: 120000 | H8: Referral | I8: 46249 | J8: 46251 | K8: Final interview | L8: 46291 | M8: Final round | N8: 46296 | O8: High | P8: Nina Park | Q8: =IF(OR(B8="",J8=""),"",TODAY()-J8) | R8: =IF(B8="","",IF(OR(K8="Accepted",K8="Rejected",K8="Withdrawn"),K8,IF(K8="Offer",IF(N8="","Offer","Offer, reply by "&DAY(N8)&" "&CHOOSE(MONTH(N8),"Jan","Feb","Mar","Apr","May","Jun","Jul","Aug","Sep","Oct","Nov","Dec")),IF(OR(K8="",K8="Saved"),IF(N8="","To apply",IF(N8<TODAY(),"Closing date passed","Apply by "&DAY(N8)&" "&CHOOSE(MONTH(N8),"Jan","Feb","Mar","Apr","May","Jun","Jul","Aug","Sep","Oct","Nov","Dec"))),IF(AND(N8="",T8>0,TODAY()-T8>=N(Settings!$C$6)),"No reply",IF(U8="","Waiting",IF(U8<TODAY(),"Follow up",IF(U8-TODAY()<=2,"Due "&DAY(U8)&" "&CHOOSE(MONTH(U8),"Jan","Feb","Mar","Apr","May","Jun","Jul","Aug","Sep","Oct","Nov","Dec"),"Waiting")))))))) | T8: =MAX(N(J8),N(L8)) | U8: =IF(N8<>"",N8,IF(T8=0,"",T8+N(Settings!$C$5))) | V8: =IF(AND(B8<>"",U8<>"",OR(R8="Follow up",LEFT(R8,3)="Due",R8="Waiting",LEFT(R8,5)="Apply",LEFT(R8,5)="Offer")),U8+ROW()/10000000,"") | W8: =IF(B8="","",IF(M8<>"",M8,IF(OR(K8="",K8="Saved"),"Apply",IF(K8="Offer","Reply to the offer","Follow up"))))
B9: Brambleton Bank | C9: UI Designer | D9: On site, Eastbridge | E9: brambleton.example/jobs | F9: 80000 | G9: 92000 | H9: Recruiter | I9: 46253 | J9: 46254 | K9: Rejected | L9: 46273 | O9: Low | P9: Owen Hart | Q9: =IF(OR(B9="",J9=""),"",TODAY()-J9) | R9: =IF(B9="","",IF(OR(K9="Accepted",K9="Rejected",K9="Withdrawn"),K9,IF(K9="Offer",IF(N9="","Offer","Offer, reply by "&DAY(N9)&" "&CHOOSE(MONTH(N9),"Jan","Feb","Mar","Apr","May","Jun","Jul","Aug","Sep","Oct","Nov","Dec")),IF(OR(K9="",K9="Saved"),IF(N9="","To apply",IF(N9<TODAY(),"Closing date passed","Apply by "&DAY(N9)&" "&CHOOSE(MONTH(N9),"Jan","Feb","Mar","Apr","May","Jun","Jul","Aug","Sep","Oct","Nov","Dec"))),IF(AND(N9="",T9>0,TODAY()-T9>=N(Settings!$C$6)),"No reply",IF(U9="","Waiting",IF(U9<TODAY(),"Follow up",IF(U9-TODAY()<=2,"Due "&DAY(U9)&" "&CHOOSE(MONTH(U9),"Jan","Feb","Mar","Apr","May","Jun","Jul","Aug","Sep","Oct","Nov","Dec"),"Waiting")))))))) | T9: =MAX(N(J9),N(L9)) | U9: =IF(N9<>"",N9,IF(T9=0,"",T9+N(Settings!$C$5))) | V9: =IF(AND(B9<>"",U9<>"",OR(R9="Follow up",LEFT(R9,3)="Due",R9="Waiting",LEFT(R9,5)="Apply",LEFT(R9,5)="Offer")),U9+ROW()/10000000,"") | W9: =IF(B9="","",IF(M9<>"",M9,IF(OR(K9="",K9="Saved"),"Apply",IF(K9="Offer","Reply to the offer","Follow up"))))
B10: Copperleaf Books | C10: UX Designer | D10: Remote | E10: copperleaf.example/jobs | F10: 80000 | G10: 90000 | H10: Job board | I10: 46255 | J10: 46256 | K10: Applied | O10: Low | Q10: =IF(OR(B10="",J10=""),"",TODAY()-J10) | R10: =IF(B10="","",IF(OR(K10="Accepted",K10="Rejected",K10="Withdrawn"),K10,IF(K10="Offer",IF(N10="","Offer","Offer, reply by "&DAY(N10)&" "&CHOOSE(MONTH(N10),"Jan","Feb","Mar","Apr","May","Jun","Jul","Aug","Sep","Oct","Nov","Dec")),IF(OR(K10="",K10="Saved"),IF(N10="","To apply",IF(N10<TODAY(),"Closing date passed","Apply by "&DAY(N10)&" "&CHOOSE(MONTH(N10),"Jan","Feb","Mar","Apr","May","Jun","Jul","Aug","Sep","Oct","Nov","Dec"))),IF(AND(N10="",T10>0,TODAY()-T10>=N(Settings!$C$6)),"No reply",IF(U10="","Waiting",IF(U10<TODAY(),"Follow up",IF(U10-TODAY()<=2,"Due "&DAY(U10)&" "&CHOOSE(MONTH(U10),"Jan","Feb","Mar","Apr","May","Jun","Jul","Aug","Sep","Oct","Nov","Dec"),"Waiting")))))))) | T10: =MAX(N(J10),N(L10)) | U10: =IF(N10<>"",N10,IF(T10=0,"",T10+N(Settings!$C$5))) | V10: =IF(AND(B10<>"",U10<>"",OR(R10="Follow up",LEFT(R10,3)="Due",R10="Waiting",LEFT(R10,5)="Apply",LEFT(R10,5)="Offer")),U10+ROW()/10000000,"") | W10: =IF(B10="","",IF(M10<>"",M10,IF(OR(K10="",K10="Saved"),"Apply",IF(K10="Offer","Reply to the offer","Follow up"))))
B11: Larkspur Learning | C11: Product Designer | D11: Remote | E11: larkspur.example/join | F11: 88000 | G11: 100000 | H11: Job board | I11: 46257 | J11: 46258 | K11: Offer | L11: 46292 | M11: Reply to the offer | N11: 46297 | O11: High | Q11: =IF(OR(B11="",J11=""),"",TODAY()-J11) | R11: =IF(B11="","",IF(OR(K11="Accepted",K11="Rejected",K11="Withdrawn"),K11,IF(K11="Offer",IF(N11="","Offer","Offer, reply by "&DAY(N11)&" "&CHOOSE(MONTH(N11),"Jan","Feb","Mar","Apr","May","Jun","Jul","Aug","Sep","Oct","Nov","Dec")),IF(OR(K11="",K11="Saved"),IF(N11="","To apply",IF(N11<TODAY(),"Closing date passed","Apply by "&DAY(N11)&" "&CHOOSE(MONTH(N11),"Jan","Feb","Mar","Apr","May","Jun","Jul","Aug","Sep","Oct","Nov","Dec"))),IF(AND(N11="",T11>0,TODAY()-T11>=N(Settings!$C$6)),"No reply",IF(U11="","Waiting",IF(U11<TODAY(),"Follow up",IF(U11-TODAY()<=2,"Due "&DAY(U11)&" "&CHOOSE(MONTH(U11),"Jan","Feb","Mar","Apr","May","Jun","Jul","Aug","Sep","Oct","Nov","Dec"),"Waiting")))))))) | T11: =MAX(N(J11),N(L11)) | U11: =IF(N11<>"",N11,IF(T11=0,"",T11+N(Settings!$C$5))) | V11: =IF(AND(B11<>"",U11<>"",OR(R11="Follow up",LEFT(R11,3)="Due",R11="Waiting",LEFT(R11,5)="Apply",LEFT(R11,5)="Offer")),U11+ROW()/10000000,"") | W11: =IF(B11="","",IF(M11<>"",M11,IF(OR(K11="",K11="Saved"),"Apply",IF(K11="Offer","Reply to the offer","Follow up"))))
B12: Oakhaven Foods | C12: UX Designer | D12: Hybrid, Riverton | E12: oakhaven.example/careers/12 | F12: 82000 | G12: 90000 | H12: Job board | I12: 46260 | J12: 46260 | K12: Applied | O12: Medium | Q12: =IF(OR(B12="",J12=""),"",TODAY()-J12) | R12: =IF(B12="","",IF(OR(K12="Accepted",K12="Rejected",K12="Withdrawn"),K12,IF(K12="Offer",IF(N12="","Offer","Offer, reply by "&DAY(N12)&" "&CHOOSE(MONTH(N12),"Jan","Feb","Mar","Apr","May","Jun","Jul","Aug","Sep","Oct","Nov","Dec")),IF(OR(K12="",K12="Saved"),IF(N12="","To apply",IF(N12<TODAY(),"Closing date passed","Apply by "&DAY(N12)&" "&CHOOSE(MONTH(N12),"Jan","Feb","Mar","Apr","May","Jun","Jul","Aug","Sep","Oct","Nov","Dec"))),IF(AND(N12="",T12>0,TODAY()-T12>=N(Settings!$C$6)),"No reply",IF(U12="","Waiting",IF(U12<TODAY(),"Follow up",IF(U12-TODAY()<=2,"Due "&DAY(U12)&" "&CHOOSE(MONTH(U12),"Jan","Feb","Mar","Apr","May","Jun","Jul","Aug","Sep","Oct","Nov","Dec"),"Waiting")))))))) | T12: =MAX(N(J12),N(L12)) | U12: =IF(N12<>"",N12,IF(T12=0,"",T12+N(Settings!$C$5))) | V12: =IF(AND(B12<>"",U12<>"",OR(R12="Follow up",LEFT(R12,3)="Due",R12="Waiting",LEFT(R12,5)="Apply",LEFT(R12,5)="Offer")),U12+ROW()/10000000,"") | W12: =IF(B12="","",IF(M12<>"",M12,IF(OR(K12="",K12="Saved"),"Apply",IF(K12="Offer","Reply to the offer","Follow up"))))
B13: Driftwood Hotels | C13: Product Designer | D13: On site, Seaford | E13: driftwood.example/careers | F13: 84000 | G13: 94000 | H13: Job board | I13: 46262 | J13: 46263 | K13: Rejected | L13: 46275 | O13: Medium | Q13: =IF(OR(B13="",J13=""),"",TODAY()-J13) | R13: =IF(B13="","",IF(OR(K13="Accepted",K13="Rejected",K13="Withdrawn"),K13,IF(K13="Offer",IF(N13="","Offer","Offer, reply by "&DAY(N13)&" "&CHOOSE(MONTH(N13),"Jan","Feb","Mar","Apr","May","Jun","Jul","Aug","Sep","Oct","Nov","Dec")),IF(OR(K13="",K13="Saved"),IF(N13="","To apply",IF(N13<TODAY(),"Closing date passed","Apply by "&DAY(N13)&" "&CHOOSE(MONTH(N13),"Jan","Feb","Mar","Apr","May","Jun","Jul","Aug","Sep","Oct","Nov","Dec"))),IF(AND(N13="",T13>0,TODAY()-T13>=N(Settings!$C$6)),"No reply",IF(U13="","Waiting",IF(U13<TODAY(),"Follow up",IF(U13-TODAY()<=2,"Due "&DAY(U13)&" "&CHOOSE(MONTH(U13),"Jan","Feb","Mar","Apr","May","Jun","Jul","Aug","Sep","Oct","Nov","Dec"),"Waiting")))))))) | T13: =MAX(N(J13),N(L13)) | U13: =IF(N13<>"",N13,IF(T13=0,"",T13+N(Settings!$C$5))) | V13: =IF(AND(B13<>"",U13<>"",OR(R13="Follow up",LEFT(R13,3)="Due",R13="Waiting",LEFT(R13,5)="Apply",LEFT(R13,5)="Offer")),U13+ROW()/10000000,"") | W13: =IF(B13="","",IF(M13<>"",M13,IF(OR(K13="",K13="Saved"),"Apply",IF(K13="Offer","Reply to the offer","Follow up"))))
B14: Wrenfield Travel | C14: Product Designer | D14: Remote | E14: wrenfield.example/jobs/7 | F14: 92000 | G14: 104000 | H14: Company site | I14: 46263 | J14: 46264 | K14: Interview | L14: 46288 | M14: Portfolio review | N14: 46299 | O14: High | Q14: =IF(OR(B14="",J14=""),"",TODAY()-J14) | R14: =IF(B14="","",IF(OR(K14="Accepted",K14="Rejected",K14="Withdrawn"),K14,IF(K14="Offer",IF(N14="","Offer","Offer, reply by "&DAY(N14)&" "&CHOOSE(MONTH(N14),"Jan","Feb","Mar","Apr","May","Jun","Jul","Aug","Sep","Oct","Nov","Dec")),IF(OR(K14="",K14="Saved"),IF(N14="","To apply",IF(N14<TODAY(),"Closing date passed","Apply by "&DAY(N14)&" "&CHOOSE(MONTH(N14),"Jan","Feb","Mar","Apr","May","Jun","Jul","Aug","Sep","Oct","Nov","Dec"))),IF(AND(N14="",T14>0,TODAY()-T14>=N(Settings!$C$6)),"No reply",IF(U14="","Waiting",IF(U14<TODAY(),"Follow up",IF(U14-TODAY()<=2,"Due "&DAY(U14)&" "&CHOOSE(MONTH(U14),"Jan","Feb","Mar","Apr","May","Jun","Jul","Aug","Sep","Oct","Nov","Dec"),"Waiting")))))))) | T14: =MAX(N(J14),N(L14)) | U14: =IF(N14<>"",N14,IF(T14=0,"",T14+N(Settings!$C$5))) | V14: =IF(AND(B14<>"",U14<>"",OR(R14="Follow up",LEFT(R14,3)="Due",R14="Waiting",LEFT(R14,5)="Apply",LEFT(R14,5)="Offer")),U14+ROW()/10000000,"") | W14: =IF(B14="","",IF(M14<>"",M14,IF(OR(K14="",K14="Saved"),"Apply",IF(K14="Offer","Reply to the offer","Follow up"))))
B15: Cloverdale Logistics | C15: UX Designer | D15: On site, Northam | E15: cloverdale.example/jobs | F15: 78000 | G15: 88000 | H15: Job board | I15: 46266 | J15: 46267 | K15: Withdrawn | L15: 46278 | O15: Low | Q15: =IF(OR(B15="",J15=""),"",TODAY()-J15) | R15: =IF(B15="","",IF(OR(K15="Accepted",K15="Rejected",K15="Withdrawn"),K15,IF(K15="Offer",IF(N15="","Offer","Offer, reply by "&DAY(N15)&" "&CHOOSE(MONTH(N15),"Jan","Feb","Mar","Apr","May","Jun","Jul","Aug","Sep","Oct","Nov","Dec")),IF(OR(K15="",K15="Saved"),IF(N15="","To apply",IF(N15<TODAY(),"Closing date passed","Apply by "&DAY(N15)&" "&CHOOSE(MONTH(N15),"Jan","Feb","Mar","Apr","May","Jun","Jul","Aug","Sep","Oct","Nov","Dec"))),IF(AND(N15="",T15>0,TODAY()-T15>=N(Settings!$C$6)),"No reply",IF(U15="","Waiting",IF(U15<TODAY(),"Follow up",IF(U15-TODAY()<=2,"Due "&DAY(U15)&" "&CHOOSE(MONTH(U15),"Jan","Feb","Mar","Apr","May","Jun","Jul","Aug","Sep","Oct","Nov","Dec"),"Waiting")))))))) | T15: =MAX(N(J15),N(L15)) | U15: =IF(N15<>"",N15,IF(T15=0,"",T15+N(Settings!$C$5))) | V15: =IF(AND(B15<>"",U15<>"",OR(R15="Follow up",LEFT(R15,3)="Due",R15="Waiting",LEFT(R15,5)="Apply",LEFT(R15,5)="Offer")),U15+ROW()/10000000,"") | W15: =IF(B15="","",IF(M15<>"",M15,IF(OR(K15="",K15="Saved"),"Apply",IF(K15="Offer","Reply to the offer","Follow up"))))
B16: Hollowbrook Media | C16: Design Lead | D16: Remote | E16: hollowbrook.example/careers/3 | F16: 115000 | G16: 130000 | H16: Recruiter | I16: 46269 | J16: 46270 | K16: Screening | L16: 46284 | O16: Medium | P16: Owen Hart | Q16: =IF(OR(B16="",J16=""),"",TODAY()-J16) | R16: =IF(B16="","",IF(OR(K16="Accepted",K16="Rejected",K16="Withdrawn"),K16,IF(K16="Offer",IF(N16="","Offer","Offer, reply by "&DAY(N16)&" "&CHOOSE(MONTH(N16),"Jan","Feb","Mar","Apr","May","Jun","Jul","Aug","Sep","Oct","Nov","Dec")),IF(OR(K16="",K16="Saved"),IF(N16="","To apply",IF(N16<TODAY(),"Closing date passed","Apply by "&DAY(N16)&" "&CHOOSE(MONTH(N16),"Jan","Feb","Mar","Apr","May","Jun","Jul","Aug","Sep","Oct","Nov","Dec"))),IF(AND(N16="",T16>0,TODAY()-T16>=N(Settings!$C$6)),"No reply",IF(U16="","Waiting",IF(U16<TODAY(),"Follow up",IF(U16-TODAY()<=2,"Due "&DAY(U16)&" "&CHOOSE(MONTH(U16),"Jan","Feb","Mar","Apr","May","Jun","Jul","Aug","Sep","Oct","Nov","Dec"),"Waiting")))))))) | T16: =MAX(N(J16),N(L16)) | U16: =IF(N16<>"",N16,IF(T16=0,"",T16+N(Settings!$C$5))) | V16: =IF(AND(B16<>"",U16<>"",OR(R16="Follow up",LEFT(R16,3)="Due",R16="Waiting",LEFT(R16,5)="Apply",LEFT(R16,5)="Offer")),U16+ROW()/10000000,"") | W16: =IF(B16="","",IF(M16<>"",M16,IF(OR(K16="",K16="Saved"),"Apply",IF(K16="Offer","Reply to the offer","Follow up"))))
B17: Emberly Home | C17: UI Designer | D17: Remote | E17: emberly.example/jobs/4 | F17: 78000 | G17: 90000 | H17: Company site | I17: 46269 | J17: 46271 | K17: Rejected | L17: 46283 | O17: Low | Q17: =IF(OR(B17="",J17=""),"",TODAY()-J17) | R17: =IF(B17="","",IF(OR(K17="Accepted",K17="Rejected",K17="Withdrawn"),K17,IF(K17="Offer",IF(N17="","Offer","Offer, reply by "&DAY(N17)&" "&CHOOSE(MONTH(N17),"Jan","Feb","Mar","Apr","May","Jun","Jul","Aug","Sep","Oct","Nov","Dec")),IF(OR(K17="",K17="Saved"),IF(N17="","To apply",IF(N17<TODAY(),"Closing date passed","Apply by "&DAY(N17)&" "&CHOOSE(MONTH(N17),"Jan","Feb","Mar","Apr","May","Jun","Jul","Aug","Sep","Oct","Nov","Dec"))),IF(AND(N17="",T17>0,TODAY()-T17>=N(Settings!$C$6)),"No reply",IF(U17="","Waiting",IF(U17<TODAY(),"Follow up",IF(U17-TODAY()<=2,"Due "&DAY(U17)&" "&CHOOSE(MONTH(U17),"Jan","Feb","Mar","Apr","May","Jun","Jul","Aug","Sep","Oct","Nov","Dec"),"Waiting")))))))) | T17: =MAX(N(J17),N(L17)) | U17: =IF(N17<>"",N17,IF(T17=0,"",T17+N(Settings!$C$5))) | V17: =IF(AND(B17<>"",U17<>"",OR(R17="Follow up",LEFT(R17,3)="Due",R17="Waiting",LEFT(R17,5)="Apply",LEFT(R17,5)="Offer")),U17+ROW()/10000000,"") | W17: =IF(B17="","",IF(M17<>"",M17,IF(OR(K17="",K17="Saved"),"Apply",IF(K17="Offer","Reply to the offer","Follow up"))))
B18: Starling Software | C18: Senior Product Designer | D18: Remote | E18: starling.example/jobs/22 | F18: 110000 | G18: 125000 | H18: Referral | I18: 46273 | J18: 46274 | K18: Interview | L18: 46290 | M18: Take-home task due | N18: 46294 | O18: High | P18: Leo Grant | Q18: =IF(OR(B18="",J18=""),"",TODAY()-J18) | R18: =IF(B18="","",IF(OR(K18="Accepted",K18="Rejected",K18="Withdrawn"),K18,IF(K18="Offer",IF(N18="","Offer","Offer, reply by "&DAY(N18)&" "&CHOOSE(MONTH(N18),"Jan","Feb","Mar","Apr","May","Jun","Jul","Aug","Sep","Oct","Nov","Dec")),IF(OR(K18="",K18="Saved"),IF(N18="","To apply",IF(N18<TODAY(),"Closing date passed","Apply by "&DAY(N18)&" "&CHOOSE(MONTH(N18),"Jan","Feb","Mar","Apr","May","Jun","Jul","Aug","Sep","Oct","Nov","Dec"))),IF(AND(N18="",T18>0,TODAY()-T18>=N(Settings!$C$6)),"No reply",IF(U18="","Waiting",IF(U18<TODAY(),"Follow up",IF(U18-TODAY()<=2,"Due "&DAY(U18)&" "&CHOOSE(MONTH(U18),"Jan","Feb","Mar","Apr","May","Jun","Jul","Aug","Sep","Oct","Nov","Dec"),"Waiting")))))))) | T18: =MAX(N(J18),N(L18)) | U18: =IF(N18<>"",N18,IF(T18=0,"",T18+N(Settings!$C$5))) | V18: =IF(AND(B18<>"",U18<>"",OR(R18="Follow up",LEFT(R18,3)="Due",R18="Waiting",LEFT(R18,5)="Apply",LEFT(R18,5)="Offer")),U18+ROW()/10000000,"") | W18: =IF(B18="","",IF(M18<>"",M18,IF(OR(K18="",K18="Saved"),"Apply",IF(K18="Offer","Reply to the offer","Follow up"))))
B19: Pebblestone Games | C19: UI Designer | D19: Hybrid, Riverton | E19: pebblestone.example/jobs | F19: 80000 | G19: 95000 | H19: Job board | I19: 46276 | J19: 46277 | K19: Rejected | L19: 46289 | O19: Medium | Q19: =IF(OR(B19="",J19=""),"",TODAY()-J19) | R19: =IF(B19="","",IF(OR(K19="Accepted",K19="Rejected",K19="Withdrawn"),K19,IF(K19="Offer",IF(N19="","Offer","Offer, reply by "&DAY(N19)&" "&CHOOSE(MONTH(N19),"Jan","Feb","Mar","Apr","May","Jun","Jul","Aug","Sep","Oct","Nov","Dec")),IF(OR(K19="",K19="Saved"),IF(N19="","To apply",IF(N19<TODAY(),"Closing date passed","Apply by "&DAY(N19)&" "&CHOOSE(MONTH(N19),"Jan","Feb","Mar","Apr","May","Jun","Jul","Aug","Sep","Oct","Nov","Dec"))),IF(AND(N19="",T19>0,TODAY()-T19>=N(Settings!$C$6)),"No reply",IF(U19="","Waiting",IF(U19<TODAY(),"Follow up",IF(U19-TODAY()<=2,"Due "&DAY(U19)&" "&CHOOSE(MONTH(U19),"Jan","Feb","Mar","Apr","May","Jun","Jul","Aug","Sep","Oct","Nov","Dec"),"Waiting")))))))) | T19: =MAX(N(J19),N(L19)) | U19: =IF(N19<>"",N19,IF(T19=0,"",T19+N(Settings!$C$5))) | V19: =IF(AND(B19<>"",U19<>"",OR(R19="Follow up",LEFT(R19,3)="Due",R19="Waiting",LEFT(R19,5)="Apply",LEFT(R19,5)="Offer")),U19+ROW()/10000000,"") | W19: =IF(B19="","",IF(M19<>"",M19,IF(OR(K19="",K19="Saved"),"Apply",IF(K19="Offer","Reply to the offer","Follow up"))))
B20: Foxglove Health | C20: Product Designer | D20: Hybrid, Riverton | E20: foxglove.example/jobs | F20: 90000 | G20: 102000 | H20: Job board | I20: 46279 | J20: 46280 | K20: Applied | O20: Medium | Q20: =IF(OR(B20="",J20=""),"",TODAY()-J20) | R20: =IF(B20="","",IF(OR(K20="Accepted",K20="Rejected",K20="Withdrawn"),K20,IF(K20="Offer",IF(N20="","Offer","Offer, reply by "&DAY(N20)&" "&CHOOSE(MONTH(N20),"Jan","Feb","Mar","Apr","May","Jun","Jul","Aug","Sep","Oct","Nov","Dec")),IF(OR(K20="",K20="Saved"),IF(N20="","To apply",IF(N20<TODAY(),"Closing date passed","Apply by "&DAY(N20)&" "&CHOOSE(MONTH(N20),"Jan","Feb","Mar","Apr","May","Jun","Jul","Aug","Sep","Oct","Nov","Dec"))),IF(AND(N20="",T20>0,TODAY()-T20>=N(Settings!$C$6)),"No reply",IF(U20="","Waiting",IF(U20<TODAY(),"Follow up",IF(U20-TODAY()<=2,"Due "&DAY(U20)&" "&CHOOSE(MONTH(U20),"Jan","Feb","Mar","Apr","May","Jun","Jul","Aug","Sep","Oct","Nov","Dec"),"Waiting")))))))) | T20: =MAX(N(J20),N(L20)) | U20: =IF(N20<>"",N20,IF(T20=0,"",T20+N(Settings!$C$5))) | V20: =IF(AND(B20<>"",U20<>"",OR(R20="Follow up",LEFT(R20,3)="Due",R20="Waiting",LEFT(R20,5)="Apply",LEFT(R20,5)="Offer")),U20+ROW()/10000000,"") | W20: =IF(B20="","",IF(M20<>"",M20,IF(OR(K20="",K20="Saved"),"Apply",IF(K20="Offer","Reply to the offer","Follow up"))))
B21: Thistle Insurance | C21: Product Designer | D21: On site, Westford | E21: thistle.example/careers | F21: 86000 | G21: 98000 | H21: Job board | I21: 46281 | J21: 46282 | K21: Applied | O21: Low | Q21: =IF(OR(B21="",J21=""),"",TODAY()-J21) | R21: =IF(B21="","",IF(OR(K21="Accepted",K21="Rejected",K21="Withdrawn"),K21,IF(K21="Offer",IF(N21="","Offer","Offer, reply by "&DAY(N21)&" "&CHOOSE(MONTH(N21),"Jan","Feb","Mar","Apr","May","Jun","Jul","Aug","Sep","Oct","Nov","Dec")),IF(OR(K21="",K21="Saved"),IF(N21="","To apply",IF(N21<TODAY(),"Closing date passed","Apply by "&DAY(N21)&" "&CHOOSE(MONTH(N21),"Jan","Feb","Mar","Apr","May","Jun","Jul","Aug","Sep","Oct","Nov","Dec"))),IF(AND(N21="",T21>0,TODAY()-T21>=N(Settings!$C$6)),"No reply",IF(U21="","Waiting",IF(U21<TODAY(),"Follow up",IF(U21-TODAY()<=2,"Due "&DAY(U21)&" "&CHOOSE(MONTH(U21),"Jan","Feb","Mar","Apr","May","Jun","Jul","Aug","Sep","Oct","Nov","Dec"),"Waiting")))))))) | T21: =MAX(N(J21),N(L21)) | U21: =IF(N21<>"",N21,IF(T21=0,"",T21+N(Settings!$C$5))) | V21: =IF(AND(B21<>"",U21<>"",OR(R21="Follow up",LEFT(R21,3)="Due",R21="Waiting",LEFT(R21,5)="Apply",LEFT(R21,5)="Offer")),U21+ROW()/10000000,"") | W21: =IF(B21="","",IF(M21<>"",M21,IF(OR(K21="",K21="Saved"),"Apply",IF(K21="Offer","Reply to the offer","Follow up"))))
B22: Marigold Retail | C22: UX Designer | D22: Remote | E22: marigold.example/jobs/9 | F22: 84000 | G22: 96000 | H22: Company site | I22: 46285 | J22: 46285 | K22: Applied | O22: Medium | Q22: =IF(OR(B22="",J22=""),"",TODAY()-J22) | R22: =IF(B22="","",IF(OR(K22="Accepted",K22="Rejected",K22="Withdrawn"),K22,IF(K22="Offer",IF(N22="","Offer","Offer, reply by "&DAY(N22)&" "&CHOOSE(MONTH(N22),"Jan","Feb","Mar","Apr","May","Jun","Jul","Aug","Sep","Oct","Nov","Dec")),IF(OR(K22="",K22="Saved"),IF(N22="","To apply",IF(N22<TODAY(),"Closing date passed","Apply by "&DAY(N22)&" "&CHOOSE(MONTH(N22),"Jan","Feb","Mar","Apr","May","Jun","Jul","Aug","Sep","Oct","Nov","Dec"))),IF(AND(N22="",T22>0,TODAY()-T22>=N(Settings!$C$6)),"No reply",IF(U22="","Waiting",IF(U22<TODAY(),"Follow up",IF(U22-TODAY()<=2,"Due "&DAY(U22)&" "&CHOOSE(MONTH(U22),"Jan","Feb","Mar","Apr","May","Jun","Jul","Aug","Sep","Oct","Nov","Dec"),"Waiting")))))))) | T22: =MAX(N(J22),N(L22)) | U22: =IF(N22<>"",N22,IF(T22=0,"",T22+N(Settings!$C$5))) | V22: =IF(AND(B22<>"",U22<>"",OR(R22="Follow up",LEFT(R22,3)="Due",R22="Waiting",LEFT(R22,5)="Apply",LEFT(R22,5)="Offer")),U22+ROW()/10000000,"") | W22: =IF(B22="","",IF(M22<>"",M22,IF(OR(K22="",K22="Saved"),"Apply",IF(K22="Offer","Reply to the offer","Follow up"))))
B23: Silverfin Travel | C23: Design Lead | D23: On site, Eastbridge | E23: silverfin.example/jobs | F23: 120000 | G23: 135000 | H23: Recruiter | I23: 46287 | K23: Saved | M23: Apply before it closes | N23: 46292 | O23: Low | P23: Owen Hart | Q23: =IF(OR(B23="",J23=""),"",TODAY()-J23) | R23: =IF(B23="","",IF(OR(K23="Accepted",K23="Rejected",K23="Withdrawn"),K23,IF(K23="Offer",IF(N23="","Offer","Offer, reply by "&DAY(N23)&" "&CHOOSE(MONTH(N23),"Jan","Feb","Mar","Apr","May","Jun","Jul","Aug","Sep","Oct","Nov","Dec")),IF(OR(K23="",K23="Saved"),IF(N23="","To apply",IF(N23<TODAY(),"Closing date passed","Apply by "&DAY(N23)&" "&CHOOSE(MONTH(N23),"Jan","Feb","Mar","Apr","May","Jun","Jul","Aug","Sep","Oct","Nov","Dec"))),IF(AND(N23="",T23>0,TODAY()-T23>=N(Settings!$C$6)),"No reply",IF(U23="","Waiting",IF(U23<TODAY(),"Follow up",IF(U23-TODAY()<=2,"Due "&DAY(U23)&" "&CHOOSE(MONTH(U23),"Jan","Feb","Mar","Apr","May","Jun","Jul","Aug","Sep","Oct","Nov","Dec"),"Waiting")))))))) | T23: =MAX(N(J23),N(L23)) | U23: =IF(N23<>"",N23,IF(T23=0,"",T23+N(Settings!$C$5))) | V23: =IF(AND(B23<>"",U23<>"",OR(R23="Follow up",LEFT(R23,3)="Due",R23="Waiting",LEFT(R23,5)="Apply",LEFT(R23,5)="Offer")),U23+ROW()/10000000,"") | W23: =IF(B23="","",IF(M23<>"",M23,IF(OR(K23="",K23="Saved"),"Apply",IF(K23="Offer","Reply to the offer","Follow up"))))
B24: Kestrel Analytics | C24: Product Designer | D24: Remote | E24: kestrel.example/jobs/5 | F24: 95000 | G24: 110000 | H24: Job board | I24: 46288 | J24: 46289 | K24: Applied | O24: High | Q24: =IF(OR(B24="",J24=""),"",TODAY()-J24) | R24: =IF(B24="","",IF(OR(K24="Accepted",K24="Rejected",K24="Withdrawn"),K24,IF(K24="Offer",IF(N24="","Offer","Offer, reply by "&DAY(N24)&" "&CHOOSE(MONTH(N24),"Jan","Feb","Mar","Apr","May","Jun","Jul","Aug","Sep","Oct","Nov","Dec")),IF(OR(K24="",K24="Saved"),IF(N24="","To apply",IF(N24<TODAY(),"Closing date passed","Apply by "&DAY(N24)&" "&CHOOSE(MONTH(N24),"Jan","Feb","Mar","Apr","May","Jun","Jul","Aug","Sep","Oct","Nov","Dec"))),IF(AND(N24="",T24>0,TODAY()-T24>=N(Settings!$C$6)),"No reply",IF(U24="","Waiting",IF(U24<TODAY(),"Follow up",IF(U24-TODAY()<=2,"Due "&DAY(U24)&" "&CHOOSE(MONTH(U24),"Jan","Feb","Mar","Apr","May","Jun","Jul","Aug","Sep","Oct","Nov","Dec"),"Waiting")))))))) | T24: =MAX(N(J24),N(L24)) | U24: =IF(N24<>"",N24,IF(T24=0,"",T24+N(Settings!$C$5))) | V24: =IF(AND(B24<>"",U24<>"",OR(R24="Follow up",LEFT(R24,3)="Due",R24="Waiting",LEFT(R24,5)="Apply",LEFT(R24,5)="Offer")),U24+ROW()/10000000,"") | W24: =IF(B24="","",IF(M24<>"",M24,IF(OR(K24="",K24="Saved"),"Apply",IF(K24="Offer","Reply to the offer","Follow up"))))
B25: Ashgrove Studio | C25: Senior Product Designer | D25: Hybrid, Riverton | E25: ashgrove.example/jobs | F25: 100000 | G25: 115000 | H25: Referral | I25: 46290 | J25: 46291 | K25: Screening | L25: 46292 | M25: Call with the recruiter | N25: 46295 | O25: High | P25: Nina Park | Q25: =IF(OR(B25="",J25=""),"",TODAY()-J25) | R25: =IF(B25="","",IF(OR(K25="Accepted",K25="Rejected",K25="Withdrawn"),K25,IF(K25="Offer",IF(N25="","Offer","Offer, reply by "&DAY(N25)&" "&CHOOSE(MONTH(N25),"Jan","Feb","Mar","Apr","May","Jun","Jul","Aug","Sep","Oct","Nov","Dec")),IF(OR(K25="",K25="Saved"),IF(N25="","To apply",IF(N25<TODAY(),"Closing date passed","Apply by "&DAY(N25)&" "&CHOOSE(MONTH(N25),"Jan","Feb","Mar","Apr","May","Jun","Jul","Aug","Sep","Oct","Nov","Dec"))),IF(AND(N25="",T25>0,TODAY()-T25>=N(Settings!$C$6)),"No reply",IF(U25="","Waiting",IF(U25<TODAY(),"Follow up",IF(U25-TODAY()<=2,"Due "&DAY(U25)&" "&CHOOSE(MONTH(U25),"Jan","Feb","Mar","Apr","May","Jun","Jul","Aug","Sep","Oct","Nov","Dec"),"Waiting")))))))) | T25: =MAX(N(J25),N(L25)) | U25: =IF(N25<>"",N25,IF(T25=0,"",T25+N(Settings!$C$5))) | V25: =IF(AND(B25<>"",U25<>"",OR(R25="Follow up",LEFT(R25,3)="Due",R25="Waiting",LEFT(R25,5)="Apply",LEFT(R25,5)="Offer")),U25+ROW()/10000000,"") | W25: =IF(B25="","",IF(M25<>"",M25,IF(OR(K25="",K25="Saved"),"Apply",IF(K25="Offer","Reply to the offer","Follow up"))))
B26: Glimmerglass Energy | C26: UX Designer | D26: Remote | E26: glimmerglass.example/careers | F26: 90000 | G26: 100000 | H26: Job board | I26: 46291 | K26: Saved | M26: Apply | N26: 46298 | O26: Medium | Q26: =IF(OR(B26="",J26=""),"",TODAY()-J26) | R26: =IF(B26="","",IF(OR(K26="Accepted",K26="Rejected",K26="Withdrawn"),K26,IF(K26="Offer",IF(N26="","Offer","Offer, reply by "&DAY(N26)&" "&CHOOSE(MONTH(N26),"Jan","Feb","Mar","Apr","May","Jun","Jul","Aug","Sep","Oct","Nov","Dec")),IF(OR(K26="",K26="Saved"),IF(N26="","To apply",IF(N26<TODAY(),"Closing date passed","Apply by "&DAY(N26)&" "&CHOOSE(MONTH(N26),"Jan","Feb","Mar","Apr","May","Jun","Jul","Aug","Sep","Oct","Nov","Dec"))),IF(AND(N26="",T26>0,TODAY()-T26>=N(Settings!$C$6)),"No reply",IF(U26="","Waiting",IF(U26<TODAY(),"Follow up",IF(U26-TODAY()<=2,"Due "&DAY(U26)&" "&CHOOSE(MONTH(U26),"Jan","Feb","Mar","Apr","May","Jun","Jul","Aug","Sep","Oct","Nov","Dec"),"Waiting")))))))) | T26: =MAX(N(J26),N(L26)) | U26: =IF(N26<>"",N26,IF(T26=0,"",T26+N(Settings!$C$5))) | V26: =IF(AND(B26<>"",U26<>"",OR(R26="Follow up",LEFT(R26,3)="Due",R26="Waiting",LEFT(R26,5)="Apply",LEFT(R26,5)="Offer")),U26+ROW()/10000000,"") | W26: =IF(B26="","",IF(M26<>"",M26,IF(OR(K26="",K26="Saved"),"Apply",IF(K26="Offer","Reply to the offer","Follow up"))))
B27: Pinecrest Studio | C27: Product Designer | D27: Remote | E27: pinecrest.example/jobs/2 | F27: 88000 | G27: 99000 | H27: Company site | I27: 46292 | K27: Saved | O27: Medium | Q27: =IF(OR(B27="",J27=""),"",TODAY()-J27) | R27: =IF(B27="","",IF(OR(K27="Accepted",K27="Rejected",K27="Withdrawn"),K27,IF(K27="Offer",IF(N27="","Offer","Offer, reply by "&DAY(N27)&" "&CHOOSE(MONTH(N27),"Jan","Feb","Mar","Apr","May","Jun","Jul","Aug","Sep","Oct","Nov","Dec")),IF(OR(K27="",K27="Saved"),IF(N27="","To apply",IF(N27<TODAY(),"Closing date passed","Apply by "&DAY(N27)&" "&CHOOSE(MONTH(N27),"Jan","Feb","Mar","Apr","May","Jun","Jul","Aug","Sep","Oct","Nov","Dec"))),IF(AND(N27="",T27>0,TODAY()-T27>=N(Settings!$C$6)),"No reply",IF(U27="","Waiting",IF(U27<TODAY(),"Follow up",IF(U27-TODAY()<=2,"Due "&DAY(U27)&" "&CHOOSE(MONTH(U27),"Jan","Feb","Mar","Apr","May","Jun","Jul","Aug","Sep","Oct","Nov","Dec"),"Waiting")))))))) | T27: =MAX(N(J27),N(L27)) | U27: =IF(N27<>"",N27,IF(T27=0,"",T27+N(Settings!$C$5))) | V27: =IF(AND(B27<>"",U27<>"",OR(R27="Follow up",LEFT(R27,3)="Due",R27="Waiting",LEFT(R27,5)="Apply",LEFT(R27,5)="Offer")),U27+ROW()/10000000,"") | W27: =IF(B27="","",IF(M27<>"",M27,IF(OR(K27="",K27="Saved"),"Apply",IF(K27="Offer","Reply to the offer","Follow up"))))
B28: Juniper Bank | C28: Product Designer | D28: Remote | E28: juniper.example/careers/8 | F28: 95000 | G28: 108000 | H28: Recruiter | I28: 46292 | J28: 46293 | K28: Applied | O28: High | P28: Owen Hart | Q28: =IF(OR(B28="",J28=""),"",TODAY()-J28) | R28: =IF(B28="","",IF(OR(K28="Accepted",K28="Rejected",K28="Withdrawn"),K28,IF(K28="Offer",IF(N28="","Offer","Offer, reply by "&DAY(N28)&" "&CHOOSE(MONTH(N28),"Jan","Feb","Mar","Apr","May","Jun","Jul","Aug","Sep","Oct","Nov","Dec")),IF(OR(K28="",K28="Saved"),IF(N28="","To apply",IF(N28<TODAY(),"Closing date passed","Apply by "&DAY(N28)&" "&CHOOSE(MONTH(N28),"Jan","Feb","Mar","Apr","May","Jun","Jul","Aug","Sep","Oct","Nov","Dec"))),IF(AND(N28="",T28>0,TODAY()-T28>=N(Settings!$C$6)),"No reply",IF(U28="","Waiting",IF(U28<TODAY(),"Follow up",IF(U28-TODAY()<=2,"Due "&DAY(U28)&" "&CHOOSE(MONTH(U28),"Jan","Feb","Mar","Apr","May","Jun","Jul","Aug","Sep","Oct","Nov","Dec"),"Waiting")))))))) | T28: =MAX(N(J28),N(L28)) | U28: =IF(N28<>"",N28,IF(T28=0,"",T28+N(Settings!$C$5))) | V28: =IF(AND(B28<>"",U28<>"",OR(R28="Follow up",LEFT(R28,3)="Due",R28="Waiting",LEFT(R28,5)="Apply",LEFT(R28,5)="Offer")),U28+ROW()/10000000,"") | W28: =IF(B28="","",IF(M28<>"",M28,IF(OR(K28="",K28="Saved"),"Apply",IF(K28="Offer","Reply to the offer","Follow up"))))
Q29: =IF(OR(B29="",J29=""),"",TODAY()-J29) | R29: =IF(B29="","",IF(OR(K29="Accepted",K29="Rejected",K29="Withdrawn"),K29,IF(K29="Offer",IF(N29="","Offer","Offer, reply by "&DAY(N29)&" "&CHOOSE(MONTH(N29),"Jan","Feb","Mar","Apr","May","Jun","Jul","Aug","Sep","Oct","Nov","Dec")),IF(OR(K29="",K29="Saved"),IF(N29="","To apply",IF(N29<TODAY(),"Closing date passed","Apply by "&DAY(N29)&" "&CHOOSE(MONTH(N29),"Jan","Feb","Mar","Apr","May","Jun","Jul","Aug","Sep","Oct","Nov","Dec"))),IF(AND(N29="",T29>0,TODAY()-T29>=N(Settings!$C$6)),"No reply",IF(U29="","Waiting",IF(U29<TODAY(),"Follow up",IF(U29-TODAY()<=2,"Due "&DAY(U29)&" "&CHOOSE(MONTH(U29),"Jan","Feb","Mar","Apr","May","Jun","Jul","Aug","Sep","Oct","Nov","Dec"),"Waiting")))))))) | T29: =MAX(N(J29),N(L29)) | U29: =IF(N29<>"",N29,IF(T29=0,"",T29+N(Settings!$C$5))) | V29: =IF(AND(B29<>"",U29<>"",OR(R29="Follow up",LEFT(R29,3)="Due",R29="Waiting",LEFT(R29,5)="Apply",LEFT(R29,5)="Offer")),U29+ROW()/10000000,"") | W29: =IF(B29="","",IF(M29<>"",M29,IF(OR(K29="",K29="Saved"),"Apply",IF(K29="Offer","Reply to the offer","Follow up"))))
Q30: =IF(OR(B30="",J30=""),"",TODAY()-J30) | R30: =IF(B30="","",IF(OR(K30="Accepted",K30="Rejected",K30="Withdrawn"),K30,IF(K30="Offer",IF(N30="","Offer","Offer, reply by "&DAY(N30)&" "&CHOOSE(MONTH(N30),"Jan","Feb","Mar","Apr","May","Jun","Jul","Aug","Sep","Oct","Nov","Dec")),IF(OR(K30="",K30="Saved"),IF(N30="","To apply",IF(N30<TODAY(),"Closing date passed","Apply by "&DAY(N30)&" "&CHOOSE(MONTH(N30),"Jan","Feb","Mar","Apr","May","Jun","Jul","Aug","Sep","Oct","Nov","Dec"))),IF(AND(N30="",T30>0,TODAY()-T30>=N(Settings!$C$6)),"No reply",IF(U30="","Waiting",IF(U30<TODAY(),"Follow up",IF(U30-TODAY()<=2,"Due "&DAY(U30)&" "&CHOOSE(MONTH(U30),"Jan","Feb","Mar","Apr","May","Jun","Jul","Aug","Sep","Oct","Nov","Dec"),"Waiting")))))))) | T30: =MAX(N(J30),N(L30)) | U30: =IF(N30<>"",N30,IF(T30=0,"",T30+N(Settings!$C$5))) | V30: =IF(AND(B30<>"",U30<>"",OR(R30="Follow up",LEFT(R30,3)="Due",R30="Waiting",LEFT(R30,5)="Apply",LEFT(R30,5)="Offer")),U30+ROW()/10000000,"") | W30: =IF(B30="","",IF(M30<>"",M30,IF(OR(K30="",K30="Saved"),"Apply",IF(K30="Offer","Reply to the offer","Follow up"))))
Q31: =IF(OR(B31="",J31=""),"",TODAY()-J31) | R31: =IF(B31="","",IF(OR(K31="Accepted",K31="Rejected",K31="Withdrawn"),K31,IF(K31="Offer",IF(N31="","Offer","Offer, reply by "&DAY(N31)&" "&CHOOSE(MONTH(N31),"Jan","Feb","Mar","Apr","May","Jun","Jul","Aug","Sep","Oct","Nov","Dec")),IF(OR(K31="",K31="Saved"),IF(N31="","To apply",IF(N31<TODAY(),"Closing date passed","Apply by "&DAY(N31)&" "&CHOOSE(MONTH(N31),"Jan","Feb","Mar","Apr","May","Jun","Jul","Aug","Sep","Oct","Nov","Dec"))),IF(AND(N31="",T31>0,TODAY()-T31>=N(Settings!$C$6)),"No reply",IF(U31="","Waiting",IF(U31<TODAY(),"Follow up",IF(U31-TODAY()<=2,"Due "&DAY(U31)&" "&CHOOSE(MONTH(U31),"Jan","Feb","Mar","Apr","May","Jun","Jul","Aug","Sep","Oct","Nov","Dec"),"Waiting")))))))) | T31: =MAX(N(J31),N(L31)) | U31: =IF(N31<>"",N31,IF(T31=0,"",T31+N(Settings!$C$5))) | V31: =IF(AND(B31<>"",U31<>"",OR(R31="Follow up",LEFT(R31,3)="Due",R31="Waiting",LEFT(R31,5)="Apply",LEFT(R31,5)="Offer")),U31+ROW()/10000000,"") | W31: =IF(B31="","",IF(M31<>"",M31,IF(OR(K31="",K31="Saved"),"Apply",IF(K31="Offer","Reply to the offer","Follow up"))))
Q32: =IF(OR(B32="",J32=""),"",TODAY()-J32) | R32: =IF(B32="","",IF(OR(K32="Accepted",K32="Rejected",K32="Withdrawn"),K32,IF(K32="Offer",IF(N32="","Offer","Offer, reply by "&DAY(N32)&" "&CHOOSE(MONTH(N32),"Jan","Feb","Mar","Apr","May","Jun","Jul","Aug","Sep","Oct","Nov","Dec")),IF(OR(K32="",K32="Saved"),IF(N32="","To apply",IF(N32<TODAY(),"Closing date passed","Apply by "&DAY(N32)&" "&CHOOSE(MONTH(N32),"Jan","Feb","Mar","Apr","May","Jun","Jul","Aug","Sep","Oct","Nov","Dec"))),IF(AND(N32="",T32>0,TODAY()-T32>=N(Settings!$C$6)),"No reply",IF(U32="","Waiting",IF(U32<TODAY(),"Follow up",IF(U32-TODAY()<=2,"Due "&DAY(U32)&" "&CHOOSE(MONTH(U32),"Jan","Feb","Mar","Apr","May","Jun","Jul","Aug","Sep","Oct","Nov","Dec"),"Waiting")))))))) | T32: =MAX(N(J32),N(L32)) | U32: =IF(N32<>"",N32,IF(T32=0,"",T32+N(Settings!$C$5))) | V32: =IF(AND(B32<>"",U32<>"",OR(R32="Follow up",LEFT(R32,3)="Due",R32="Waiting",LEFT(R32,5)="Apply",LEFT(R32,5)="Offer")),U32+ROW()/10000000,"") | W32: =IF(B32="","",IF(M32<>"",M32,IF(OR(K32="",K32="Saved"),"Apply",IF(K32="Offer","Reply to the offer","Follow up"))))
Q33: =IF(OR(B33="",J33=""),"",TODAY()-J33) | R33: =IF(B33="","",IF(OR(K33="Accepted",K33="Rejected",K33="Withdrawn"),K33,IF(K33="Offer",IF(N33="","Offer","Offer, reply by "&DAY(N33)&" "&CHOOSE(MONTH(N33),"Jan","Feb","Mar","Apr","May","Jun","Jul","Aug","Sep","Oct","Nov","Dec")),IF(OR(K33="",K33="Saved"),IF(N33="","To apply",IF(N33<TODAY(),"Closing date passed","Apply by "&DAY(N33)&" "&CHOOSE(MONTH(N33),"Jan","Feb","Mar","Apr","May","Jun","Jul","Aug","Sep","Oct","Nov","Dec"))),IF(AND(N33="",T33>0,TODAY()-T33>=N(Settings!$C$6)),"No reply",IF(U33="","Waiting",IF(U33<TODAY(),"Follow up",IF(U33-TODAY()<=2,"Due "&DAY(U33)&" "&CHOOSE(MONTH(U33),"Jan","Feb","Mar","Apr","May","Jun","Jul","Aug","Sep","Oct","Nov","Dec"),"Waiting")))))))) | T33: =MAX(N(J33),N(L33)) | U33: =IF(N33<>"",N33,IF(T33=0,"",T33+N(Settings!$C$5))) | V33: =IF(AND(B33<>"",U33<>"",OR(R33="Follow up",LEFT(R33,3)="Due",R33="Waiting",LEFT(R33,5)="Apply",LEFT(R33,5)="Offer")),U33+ROW()/10000000,"") | W33: =IF(B33="","",IF(M33<>"",M33,IF(OR(K33="",K33="Saved"),"Apply",IF(K33="Offer","Reply to the offer","Follow up"))))
Q34: =IF(OR(B34="",J34=""),"",TODAY()-J34) | R34: =IF(B34="","",IF(OR(K34="Accepted",K34="Rejected",K34="Withdrawn"),K34,IF(K34="Offer",IF(N34="","Offer","Offer, reply by "&DAY(N34)&" "&CHOOSE(MONTH(N34),"Jan","Feb","Mar","Apr","May","Jun","Jul","Aug","Sep","Oct","Nov","Dec")),IF(OR(K34="",K34="Saved"),IF(N34="","To apply",IF(N34<TODAY(),"Closing date passed","Apply by "&DAY(N34)&" "&CHOOSE(MONTH(N34),"Jan","Feb","Mar","Apr","May","Jun","Jul","Aug","Sep","Oct","Nov","Dec"))),IF(AND(N34="",T34>0,TODAY()-T34>=N(Settings!$C$6)),"No reply",IF(U34="","Waiting",IF(U34<TODAY(),"Follow up",IF(U34-TODAY()<=2,"Due "&DAY(U34)&" "&CHOOSE(MONTH(U34),"Jan","Feb","Mar","Apr","May","Jun","Jul","Aug","Sep","Oct","Nov","Dec"),"Waiting")))))))) | T34: =MAX(N(J34),N(L34)) | U34: =IF(N34<>"",N34,IF(T34=0,"",T34+N(Settings!$C$5))) | V34: =IF(AND(B34<>"",U34<>"",OR(R34="Follow up",LEFT(R34,3)="Due",R34="Waiting",LEFT(R34,5)="Apply",LEFT(R34,5)="Offer")),U34+ROW()/10000000,"") | W34: =IF(B34="","",IF(M34<>"",M34,IF(OR(K34="",K34="Saved"),"Apply",IF(K34="Offer","Reply to the offer","Follow up"))))
Q35: =IF(OR(B35="",J35=""),"",TODAY()-J35) | R35: =IF(B35="","",IF(OR(K35="Accepted",K35="Rejected",K35="Withdrawn"),K35,IF(K35="Offer",IF(N35="","Offer","Offer, reply by "&DAY(N35)&" "&CHOOSE(MONTH(N35),"Jan","Feb","Mar","Apr","May","Jun","Jul","Aug","Sep","Oct","Nov","Dec")),IF(OR(K35="",K35="Saved"),IF(N35="","To apply",IF(N35<TODAY(),"Closing date passed","Apply by "&DAY(N35)&" "&CHOOSE(MONTH(N35),"Jan","Feb","Mar","Apr","May","Jun","Jul","Aug","Sep","Oct","Nov","Dec"))),IF(AND(N35="",T35>0,TODAY()-T35>=N(Settings!$C$6)),"No reply",IF(U35="","Waiting",IF(U35<TODAY(),"Follow up",IF(U35-TODAY()<=2,"Due "&DAY(U35)&" "&CHOOSE(MONTH(U35),"Jan","Feb","Mar","Apr","May","Jun","Jul","Aug","Sep","Oct","Nov","Dec"),"Waiting")))))))) | T35: =MAX(N(J35),N(L35)) | U35: =IF(N35<>"",N35,IF(T35=0,"",T35+N(Settings!$C$5))) | V35: =IF(AND(B35<>"",U35<>"",OR(R35="Follow up",LEFT(R35,3)="Due",R35="Waiting",LEFT(R35,5)="Apply",LEFT(R35,5)="Offer")),U35+ROW()/10000000,"") | W35: =IF(B35="","",IF(M35<>"",M35,IF(OR(K35="",K35="Saved"),"Apply",IF(K35="Offer","Reply to the offer","Follow up"))))
Q36: =IF(OR(B36="",J36=""),"",TODAY()-J36) | R36: =IF(B36="","",IF(OR(K36="Accepted",K36="Rejected",K36="Withdrawn"),K36,IF(K36="Offer",IF(N36="","Offer","Offer, reply by "&DAY(N36)&" "&CHOOSE(MONTH(N36),"Jan","Feb","Mar","Apr","May","Jun","Jul","Aug","Sep","Oct","Nov","Dec")),IF(OR(K36="",K36="Saved"),IF(N36="","To apply",IF(N36<TODAY(),"Closing date passed","Apply by "&DAY(N36)&" "&CHOOSE(MONTH(N36),"Jan","Feb","Mar","Apr","May","Jun","Jul","Aug","Sep","Oct","Nov","Dec"))),IF(AND(N36="",T36>0,TODAY()-T36>=N(Settings!$C$6)),"No reply",IF(U36="","Waiting",IF(U36<TODAY(),"Follow up",IF(U36-TODAY()<=2,"Due "&DAY(U36)&" "&CHOOSE(MONTH(U36),"Jan","Feb","Mar","Apr","May","Jun","Jul","Aug","Sep","Oct","Nov","Dec"),"Waiting")))))))) | T36: =MAX(N(J36),N(L36)) | U36: =IF(N36<>"",N36,IF(T36=0,"",T36+N(Settings!$C$5))) | V36: =IF(AND(B36<>"",U36<>"",OR(R36="Follow up",LEFT(R36,3)="Due",R36="Waiting",LEFT(R36,5)="Apply",LEFT(R36,5)="Offer")),U36+ROW()/10000000,"") | W36: =IF(B36="","",IF(M36<>"",M36,IF(OR(K36="",K36="Saved"),"Apply",IF(K36="Offer","Reply to the offer","Follow up"))))
Q37: =IF(OR(B37="",J37=""),"",TODAY()-J37) | R37: =IF(B37="","",IF(OR(K37="Accepted",K37="Rejected",K37="Withdrawn"),K37,IF(K37="Offer",IF(N37="","Offer","Offer, reply by "&DAY(N37)&" "&CHOOSE(MONTH(N37),"Jan","Feb","Mar","Apr","May","Jun","Jul","Aug","Sep","Oct","Nov","Dec")),IF(OR(K37="",K37="Saved"),IF(N37="","To apply",IF(N37<TODAY(),"Closing date passed","Apply by "&DAY(N37)&" "&CHOOSE(MONTH(N37),"Jan","Feb","Mar","Apr","May","Jun","Jul","Aug","Sep","Oct","Nov","Dec"))),IF(AND(N37="",T37>0,TODAY()-T37>=N(Settings!$C$6)),"No reply",IF(U37="","Waiting",IF(U37<TODAY(),"Follow up",IF(U37-TODAY()<=2,"Due "&DAY(U37)&" "&CHOOSE(MONTH(U37),"Jan","Feb","Mar","Apr","May","Jun","Jul","Aug","Sep","Oct","Nov","Dec"),"Waiting")))))))) | T37: =MAX(N(J37),N(L37)) | U37: =IF(N37<>"",N37,IF(T37=0,"",T37+N(Settings!$C$5))) | V37: =IF(AND(B37<>"",U37<>"",OR(R37="Follow up",LEFT(R37,3)="Due",R37="Waiting",LEFT(R37,5)="Apply",LEFT(R37,5)="Offer")),U37+ROW()/10000000,"") | W37: =IF(B37="","",IF(M37<>"",M37,IF(OR(K37="",K37="Saved"),"Apply",IF(K37="Offer","Reply to the offer","Follow up"))))
Q38: =IF(OR(B38="",J38=""),"",TODAY()-J38) | R38: =IF(B38="","",IF(OR(K38="Accepted",K38="Rejected",K38="Withdrawn"),K38,IF(K38="Offer",IF(N38="","Offer","Offer, reply by "&DAY(N38)&" "&CHOOSE(MONTH(N38),"Jan","Feb","Mar","Apr","May","Jun","Jul","Aug","Sep","Oct","Nov","Dec")),IF(OR(K38="",K38="Saved"),IF(N38="","To apply",IF(N38<TODAY(),"Closing date passed","Apply by "&DAY(N38)&" "&CHOOSE(MONTH(N38),"Jan","Feb","Mar","Apr","May","Jun","Jul","Aug","Sep","Oct","Nov","Dec"))),IF(AND(N38="",T38>0,TODAY()-T38>=N(Settings!$C$6)),"No reply",IF(U38="","Waiting",IF(U38<TODAY(),"Follow up",IF(U38-TODAY()<=2,"Due "&DAY(U38)&" "&CHOOSE(MONTH(U38),"Jan","Feb","Mar","Apr","May","Jun","Jul","Aug","Sep","Oct","Nov","Dec"),"Waiting")))))))) | T38: =MAX(N(J38),N(L38)) | U38: =IF(N38<>"",N38,IF(T38=0,"",T38+N(Settings!$C$5))) | V38: =IF(AND(B38<>"",U38<>"",OR(R38="Follow up",LEFT(R38,3)="Due",R38="Waiting",LEFT(R38,5)="Apply",LEFT(R38,5)="Offer")),U38+ROW()/10000000,"") | W38: =IF(B38="","",IF(M38<>"",M38,IF(OR(K38="",K38="Saved"),"Apply",IF(K38="Offer","Reply to the offer","Follow up"))))
Q39: =IF(OR(B39="",J39=""),"",TODAY()-J39) | R39: =IF(B39="","",IF(OR(K39="Accepted",K39="Rejected",K39="Withdrawn"),K39,IF(K39="Offer",IF(N39="","Offer","Offer, reply by "&DAY(N39)&" "&CHOOSE(MONTH(N39),"Jan","Feb","Mar","Apr","May","Jun","Jul","Aug","Sep","Oct","Nov","Dec")),IF(OR(K39="",K39="Saved"),IF(N39="","To apply",IF(N39<TODAY(),"Closing date passed","Apply by "&DAY(N39)&" "&CHOOSE(MONTH(N39),"Jan","Feb","Mar","Apr","May","Jun","Jul","Aug","Sep","Oct","Nov","Dec"))),IF(AND(N39="",T39>0,TODAY()-T39>=N(Settings!$C$6)),"No reply",IF(U39="","Waiting",IF(U39<TODAY(),"Follow up",IF(U39-TODAY()<=2,"Due "&DAY(U39)&" "&CHOOSE(MONTH(U39),"Jan","Feb","Mar","Apr","May","Jun","Jul","Aug","Sep","Oct","Nov","Dec"),"Waiting")))))))) | T39: =MAX(N(J39),N(L39)) | U39: =IF(N39<>"",N39,IF(T39=0,"",T39+N(Settings!$C$5))) | V39: =IF(AND(B39<>"",U39<>"",OR(R39="Follow up",LEFT(R39,3)="Due",R39="Waiting",LEFT(R39,5)="Apply",LEFT(R39,5)="Offer")),U39+ROW()/10000000,"") | W39: =IF(B39="","",IF(M39<>"",M39,IF(OR(K39="",K39="Saved"),"Apply",IF(K39="Offer","Reply to the offer","Follow up"))))
Q40: =IF(OR(B40="",J40=""),"",TODAY()-J40) | R40: =IF(B40="","",IF(OR(K40="Accepted",K40="Rejected",K40="Withdrawn"),K40,IF(K40="Offer",IF(N40="","Offer","Offer, reply by "&DAY(N40)&" "&CHOOSE(MONTH(N40),"Jan","Feb","Mar","Apr","May","Jun","Jul","Aug","Sep","Oct","Nov","Dec")),IF(OR(K40="",K40="Saved"),IF(N40="","To apply",IF(N40<TODAY(),"Closing date passed","Apply by "&DAY(N40)&" "&CHOOSE(MONTH(N40),"Jan","Feb","Mar","Apr","May","Jun","Jul","Aug","Sep","Oct","Nov","Dec"))),IF(AND(N40="",T40>0,TODAY()-T40>=N(Settings!$C$6)),"No reply",IF(U40="","Waiting",IF(U40<TODAY(),"Follow up",IF(U40-TODAY()<=2,"Due "&DAY(U40)&" "&CHOOSE(MONTH(U40),"Jan","Feb","Mar","Apr","May","Jun","Jul","Aug","Sep","Oct","Nov","Dec"),"Waiting")))))))) | T40: =MAX(N(J40),N(L40)) | U40: =IF(N40<>"",N40,IF(T40=0,"",T40+N(Settings!$C$5))) | V40: =IF(AND(B40<>"",U40<>"",OR(R40="Follow up",LEFT(R40,3)="Due",R40="Waiting",LEFT(R40,5)="Apply",LEFT(R40,5)="Offer")),U40+ROW()/10000000,"") | W40: =IF(B40="","",IF(M40<>"",M40,IF(OR(K40="",K40="Saved"),"Apply",IF(K40="Offer","Reply to the offer","Follow up"))))
... Q305: =IF(OR(B305="",J305=""),"",TODAY()-J305) | R305: =IF(B305="","",IF(OR(K305="Accepted",K305="Rejected",K305="Withdrawn"),K305,IF(K305="Offer",IF(N305="","Offer","Offer, reply by "&DAY(N305)&" "&CHOOSE(MONTH(N305),"Jan","Feb","Mar","Apr","May","Jun","Jul","Aug","Sep","Oct","Nov","Dec")),IF(OR(K305="",K305="Saved"),IF(N305="","To apply",IF(N305<TODAY(),"Closing date passed","Apply by "&DAY(N305)&" "&CHOOSE(MONTH(N305),"Jan","Feb","Mar","Apr","May","Jun","Jul","Aug","Sep","Oct","Nov","Dec"))),IF(AND(N305="",T305>0,TODAY()-T305>=N(Settings!$C$6)),"No reply",IF(U305="","Waiting",IF(U305<TODAY(),"Follow up",IF(U305-TODAY()<=2,"Due "&DAY(U305)&" "&CHOOSE(MONTH(U305),"Jan","Feb","Mar","Apr","May","Jun","Jul","Aug","Sep","Oct","Nov","Dec"),"Waiting")))))))) | T305: =MAX(N(J305),N(L305)) | U305: =IF(N305<>"",N305,IF(T305=0,"",T305+N(Settings!$C$5))) | V305: =IF(AND(B305<>"",U305<>"",OR(R305="Follow up",LEFT(R305,3)="Due",R305="Waiting",LEFT(R305,5)="Apply",LEFT(R305,5)="Offer")),U305+ROW()/10000000,"") | W305: =IF(B305="","",IF(M305<>"",M305,IF(OR(K305="",K305="Saved"),"Apply",IF(K305="Offer","Reply to the offer","Follow up"))))

Sheet Interviews
B2: Interviews
B3: Each call, video, visit or task, with what to prepare and whether the thank-you went out.
B5: Date | C5: Time | D5: Company | E5: Role | F5: Type | G5: With | H5: To prepare | I5: How it went | J5: Thank-you sent | K5: Status
B6: 46257 | C6: 0.41666667 | D6: Fernhill Labs | E6: Product Designer | F6: Phone screen | G6: Recruiter | I6: Friendly, 20 min | J6: x | K6: =IF(B6="","",IF(B6>TODAY(),"Coming up",IF(B6=TODAY(),"Today",IF(J6<>"","Done","Send thank-you")))) | L6: =IF(OR(B6="",B6<TODAY()),"",B6+MOD(N(C6),1)+ROW()/10000000)
B7: 46262 | C7: 0.58333333 | D7: Tidewell Health | E7: Senior Product Designer | F7: Video | G7: Head of design | H7: Case study on the booking flow | I7: Went well | J7: x | K7: =IF(B7="","",IF(B7>TODAY(),"Coming up",IF(B7=TODAY(),"Today",IF(J7<>"","Done","Send thank-you")))) | L7: =IF(OR(B7="",B7<TODAY()),"",B7+MOD(N(C7),1)+ROW()/10000000)
B8: 46271 | C8: 0.47916667 | D8: Brambleton Bank | E8: UI Designer | F8: On site | G8: Two designers | I8: Hard questions on accessibility | J8: x | K8: =IF(B8="","",IF(B8>TODAY(),"Coming up",IF(B8=TODAY(),"Today",IF(J8<>"","Done","Send thank-you")))) | L8: =IF(OR(B8="",B8<TODAY()),"",B8+MOD(N(C8),1)+ROW()/10000000)
B9: 46279 | C9: 0.39583333 | D9: Larkspur Learning | E9: Product Designer | F9: Video | G9: Design manager | H9: Their mobile app | I9: Good, they liked the research work | J9: x | K9: =IF(B9="","",IF(B9>TODAY(),"Coming up",IF(B9=TODAY(),"Today",IF(J9<>"","Done","Send thank-you")))) | L9: =IF(OR(B9="",B9<TODAY()),"",B9+MOD(N(C9),1)+ROW()/10000000)
B10: 46284 | C10: 0.625 | D10: Tidewell Health | E10: Senior Product Designer | F10: Task | G10: Design team | H10: Two-hour exercise | I10: Presented the task | J10: x | K10: =IF(B10="","",IF(B10>TODAY(),"Coming up",IF(B10=TODAY(),"Today",IF(J10<>"","Done","Send thank-you")))) | L10: =IF(OR(B10="",B10<TODAY()),"",B10+MOD(N(C10),1)+ROW()/10000000)
B11: 46288 | C11: 0.54166667 | D11: Wrenfield Travel | E11: Product Designer | F11: Phone screen | G11: Recruiter | I11: Short and clear | K11: =IF(B11="","",IF(B11>TODAY(),"Coming up",IF(B11=TODAY(),"Today",IF(J11<>"","Done","Send thank-you")))) | L11: =IF(OR(B11="",B11<TODAY()),"",B11+MOD(N(C11),1)+ROW()/10000000)
B12: 46290 | C12: 0.66666667 | D12: Starling Software | E12: Senior Product Designer | F12: Video | G12: Lead designer | H12: Their design system | I12: Asked for a take-home task | J12: x | K12: =IF(B12="","",IF(B12>TODAY(),"Coming up",IF(B12=TODAY(),"Today",IF(J12<>"","Done","Send thank-you")))) | L12: =IF(OR(B12="",B12<TODAY()),"",B12+MOD(N(C12),1)+ROW()/10000000)
B13: 46296 | C13: 0.41666667 | D13: Tidewell Health | E13: Senior Product Designer | F13: Final | G13: Design team and VP | H13: Walk through two projects | K13: =IF(B13="","",IF(B13>TODAY(),"Coming up",IF(B13=TODAY(),"Today",IF(J13<>"","Done","Send thank-you")))) | L13: =IF(OR(B13="",B13<TODAY()),"",B13+MOD(N(C13),1)+ROW()/10000000)
B14: 46299 | C14: 0.45833333 | D14: Wrenfield Travel | E14: Product Designer | F14: Video | G14: Design manager | H14: Portfolio review, 45 min | K14: =IF(B14="","",IF(B14>TODAY(),"Coming up",IF(B14=TODAY(),"Today",IF(J14<>"","Done","Send thank-you")))) | L14: =IF(OR(B14="",B14<TODAY()),"",B14+MOD(N(C14),1)+ROW()/10000000)
K15: =IF(B15="","",IF(B15>TODAY(),"Coming up",IF(B15=TODAY(),"Today",IF(J15<>"","Done","Send thank-you")))) | L15: =IF(OR(B15="",B15<TODAY()),"",B15+MOD(N(C15),1)+ROW()/10000000)
K16: =IF(B16="","",IF(B16>TODAY(),"Coming up",IF(B16=TODAY(),"Today",IF(J16<>"","Done","Send thank-you")))) | L16: =IF(OR(B16="",B16<TODAY()),"",B16+MOD(N(C16),1)+ROW()/10000000)
K17: =IF(B17="","",IF(B17>TODAY(),"Coming up",IF(B17=TODAY(),"Today",IF(J17<>"","Done","Send thank-you")))) | L17: =IF(OR(B17="",B17<TODAY()),"",B17+MOD(N(C17),1)+ROW()/10000000)
