Workbook

Sheet Dashboard
B2: ="Trip expenses: "&Setup!$D$4
B3: Who paid what, what everyone's share came to, and who pays whom to settle up.
B4: ="All amounts in "&Setup!$D$5
B6: Spent in total | C6: Per person | D6: Per day | E6: Days | F6: Expenses
B7: =SUMIFS(Expenses!$T$6:$T$505,Expenses!$D$6:$D$505,"<>Paying back") | C7: =IF(COUNTIF(Setup!$B$9:$B$20,"?*")=0,"",SUMIFS(Expenses!$T$6:$T$505,Expenses!$D$6:$D$505,"<>Paying back")/COUNTIF(Setup!$B$9:$B$20,"?*")) | D7: =IF(MIN(Expenses!$B$6:$B$505)=0,"",SUMIFS(Expenses!$T$6:$T$505,Expenses!$D$6:$D$505,"<>Paying back")/(MAX(Expenses!$B$6:$B$505)-MIN(Expenses!$B$6:$B$505)+1)) | E7: =IF(MIN(Expenses!$B$6:$B$505)=0,"",MAX(Expenses!$B$6:$B$505)-MIN(Expenses!$B$6:$B$505)+1) | F7: =COUNTIFS(Expenses!$T$6:$T$505,">0")
B9: Person | C9: Paid | D9: Share of costs | E9: Balance | F9: Status | H9: Settle up | I9: Amount
B10: =IF(Setup!B9="","",Setup!B9) | C10: =IF(B10="","",SUMIFS(Expenses!$T$6:$T$505,Expenses!$G$6:$G$505,B10)) | D10: =IF(B10="","",SUMIFS(Expenses!$W$6:$W$505,Expenses!$D$6:$D$505,"<>Paying back")) | E10: =IF(B10="","",ROUND(C10-SUM(Expenses!$W$6:$W$505),2)) | F10: =IF(B10="","",IF(ABS(E10)<0.005,"Settled",IF(E10>0,"Gets back "&FIXED(E10,2),"Owes "&FIXED(-E10,2)))) | H10: =IF(N(AA75)<0.01,"Everyone is settled",INDEX($B$10:$B$21,AA77)&" pays "&INDEX($B$10:$B$21,AA76)) | I10: =IF(N(AA75)<0.01,"",AA75)
B11: =IF(Setup!B10="","",Setup!B10) | C11: =IF(B11="","",SUMIFS(Expenses!$T$6:$T$505,Expenses!$G$6:$G$505,B11)) | D11: =IF(B11="","",SUMIFS(Expenses!$X$6:$X$505,Expenses!$D$6:$D$505,"<>Paying back")) | E11: =IF(B11="","",ROUND(C11-SUM(Expenses!$X$6:$X$505),2)) | F11: =IF(B11="","",IF(ABS(E11)<0.005,"Settled",IF(E11>0,"Gets back "&FIXED(E11,2),"Owes "&FIXED(-E11,2)))) | H11: =IF(N(AB75)<0.01,"",INDEX($B$10:$B$21,AB77)&" pays "&INDEX($B$10:$B$21,AB76)) | I11: =IF(N(AB75)<0.01,"",AB75)
B12: =IF(Setup!B11="","",Setup!B11) | C12: =IF(B12="","",SUMIFS(Expenses!$T$6:$T$505,Expenses!$G$6:$G$505,B12)) | D12: =IF(B12="","",SUMIFS(Expenses!$Y$6:$Y$505,Expenses!$D$6:$D$505,"<>Paying back")) | E12: =IF(B12="","",ROUND(C12-SUM(Expenses!$Y$6:$Y$505),2)) | F12: =IF(B12="","",IF(ABS(E12)<0.005,"Settled",IF(E12>0,"Gets back "&FIXED(E12,2),"Owes "&FIXED(-E12,2)))) | H12: =IF(N(AC75)<0.01,"",INDEX($B$10:$B$21,AC77)&" pays "&INDEX($B$10:$B$21,AC76)) | I12: =IF(N(AC75)<0.01,"",AC75)
B13: =IF(Setup!B12="","",Setup!B12) | C13: =IF(B13="","",SUMIFS(Expenses!$T$6:$T$505,Expenses!$G$6:$G$505,B13)) | D13: =IF(B13="","",SUMIFS(Expenses!$Z$6:$Z$505,Expenses!$D$6:$D$505,"<>Paying back")) | E13: =IF(B13="","",ROUND(C13-SUM(Expenses!$Z$6:$Z$505),2)) | F13: =IF(B13="","",IF(ABS(E13)<0.005,"Settled",IF(E13>0,"Gets back "&FIXED(E13,2),"Owes "&FIXED(-E13,2)))) | H13: =IF(N(AD75)<0.01,"",INDEX($B$10:$B$21,AD77)&" pays "&INDEX($B$10:$B$21,AD76)) | I13: =IF(N(AD75)<0.01,"",AD75)
B14: =IF(Setup!B13="","",Setup!B13) | C14: =IF(B14="","",SUMIFS(Expenses!$T$6:$T$505,Expenses!$G$6:$G$505,B14)) | D14: =IF(B14="","",SUMIFS(Expenses!$AA$6:$AA$505,Expenses!$D$6:$D$505,"<>Paying back")) | E14: =IF(B14="","",ROUND(C14-SUM(Expenses!$AA$6:$AA$505),2)) | F14: =IF(B14="","",IF(ABS(E14)<0.005,"Settled",IF(E14>0,"Gets back "&FIXED(E14,2),"Owes "&FIXED(-E14,2)))) | H14: =IF(N(AE75)<0.01,"",INDEX($B$10:$B$21,AE77)&" pays "&INDEX($B$10:$B$21,AE76)) | I14: =IF(N(AE75)<0.01,"",AE75)
B15: =IF(Setup!B14="","",Setup!B14) | C15: =IF(B15="","",SUMIFS(Expenses!$T$6:$T$505,Expenses!$G$6:$G$505,B15)) | D15: =IF(B15="","",SUMIFS(Expenses!$AB$6:$AB$505,Expenses!$D$6:$D$505,"<>Paying back")) | E15: =IF(B15="","",ROUND(C15-SUM(Expenses!$AB$6:$AB$505),2)) | F15: =IF(B15="","",IF(ABS(E15)<0.005,"Settled",IF(E15>0,"Gets back "&FIXED(E15,2),"Owes "&FIXED(-E15,2)))) | H15: =IF(N(AF75)<0.01,"",INDEX($B$10:$B$21,AF77)&" pays "&INDEX($B$10:$B$21,AF76)) | I15: =IF(N(AF75)<0.01,"",AF75)
B16: =IF(Setup!B15="","",Setup!B15) | C16: =IF(B16="","",SUMIFS(Expenses!$T$6:$T$505,Expenses!$G$6:$G$505,B16)) | D16: =IF(B16="","",SUMIFS(Expenses!$AC$6:$AC$505,Expenses!$D$6:$D$505,"<>Paying back")) | E16: =IF(B16="","",ROUND(C16-SUM(Expenses!$AC$6:$AC$505),2)) | F16: =IF(B16="","",IF(ABS(E16)<0.005,"Settled",IF(E16>0,"Gets back "&FIXED(E16,2),"Owes "&FIXED(-E16,2)))) | H16: =IF(N(AG75)<0.01,"",INDEX($B$10:$B$21,AG77)&" pays "&INDEX($B$10:$B$21,AG76)) | I16: =IF(N(AG75)<0.01,"",AG75)
B17: =IF(Setup!B16="","",Setup!B16) | C17: =IF(B17="","",SUMIFS(Expenses!$T$6:$T$505,Expenses!$G$6:$G$505,B17)) | D17: =IF(B17="","",SUMIFS(Expenses!$AD$6:$AD$505,Expenses!$D$6:$D$505,"<>Paying back")) | E17: =IF(B17="","",ROUND(C17-SUM(Expenses!$AD$6:$AD$505),2)) | F17: =IF(B17="","",IF(ABS(E17)<0.005,"Settled",IF(E17>0,"Gets back "&FIXED(E17,2),"Owes "&FIXED(-E17,2)))) | H17: =IF(N(AH75)<0.01,"",INDEX($B$10:$B$21,AH77)&" pays "&INDEX($B$10:$B$21,AH76)) | I17: =IF(N(AH75)<0.01,"",AH75)
B18: =IF(Setup!B17="","",Setup!B17) | C18: =IF(B18="","",SUMIFS(Expenses!$T$6:$T$505,Expenses!$G$6:$G$505,B18)) | D18: =IF(B18="","",SUMIFS(Expenses!$AE$6:$AE$505,Expenses!$D$6:$D$505,"<>Paying back")) | E18: =IF(B18="","",ROUND(C18-SUM(Expenses!$AE$6:$AE$505),2)) | F18: =IF(B18="","",IF(ABS(E18)<0.005,"Settled",IF(E18>0,"Gets back "&FIXED(E18,2),"Owes "&FIXED(-E18,2)))) | H18: =IF(N(AI75)<0.01,"",INDEX($B$10:$B$21,AI77)&" pays "&INDEX($B$10:$B$21,AI76)) | I18: =IF(N(AI75)<0.01,"",AI75)
B19: =IF(Setup!B18="","",Setup!B18) | C19: =IF(B19="","",SUMIFS(Expenses!$T$6:$T$505,Expenses!$G$6:$G$505,B19)) | D19: =IF(B19="","",SUMIFS(Expenses!$AF$6:$AF$505,Expenses!$D$6:$D$505,"<>Paying back")) | E19: =IF(B19="","",ROUND(C19-SUM(Expenses!$AF$6:$AF$505),2)) | F19: =IF(B19="","",IF(ABS(E19)<0.005,"Settled",IF(E19>0,"Gets back "&FIXED(E19,2),"Owes "&FIXED(-E19,2)))) | H19: =IF(N(AJ75)<0.01,"",INDEX($B$10:$B$21,AJ77)&" pays "&INDEX($B$10:$B$21,AJ76)) | I19: =IF(N(AJ75)<0.01,"",AJ75)
B20: =IF(Setup!B19="","",Setup!B19) | C20: =IF(B20="","",SUMIFS(Expenses!$T$6:$T$505,Expenses!$G$6:$G$505,B20)) | D20: =IF(B20="","",SUMIFS(Expenses!$AG$6:$AG$505,Expenses!$D$6:$D$505,"<>Paying back")) | E20: =IF(B20="","",ROUND(C20-SUM(Expenses!$AG$6:$AG$505),2)) | F20: =IF(B20="","",IF(ABS(E20)<0.005,"Settled",IF(E20>0,"Gets back "&FIXED(E20,2),"Owes "&FIXED(-E20,2)))) | H20: =IF(N(AK75)<0.01,"",INDEX($B$10:$B$21,AK77)&" pays "&INDEX($B$10:$B$21,AK76)) | I20: =IF(N(AK75)<0.01,"",AK75)
B21: =IF(Setup!B20="","",Setup!B20) | C21: =IF(B21="","",SUMIFS(Expenses!$T$6:$T$505,Expenses!$G$6:$G$505,B21)) | D21: =IF(B21="","",SUMIFS(Expenses!$AH$6:$AH$505,Expenses!$D$6:$D$505,"<>Paying back")) | E21: =IF(B21="","",ROUND(C21-SUM(Expenses!$AH$6:$AH$505),2)) | F21: =IF(B21="","",IF(ABS(E21)<0.005,"Settled",IF(E21>0,"Gets back "&FIXED(E21,2),"Owes "&FIXED(-E21,2))))
B22: Share of costs leaves out money paid back between you. Balance counts it. | H22: The fewest payments that bring every balance to zero.
B25: Category | C25: Spent | D25: Share | K25: Day | L25: Spent
B26: Lodging | C26: =SUMIFS(Expenses!$T$6:$T$505,Expenses!$D$6:$D$505,B26) | D26: =IF(N($B$7)=0,"",C26/$B$7) | K26: =IF(OR(MIN(Expenses!$B$6:$B$505)=0,(MIN(Expenses!$B$6:$B$505)+0)>MAX(Expenses!$B$6:$B$505)),"",(MIN(Expenses!$B$6:$B$505)+0)) | L26: =IF(K26="","",SUMIFS(Expenses!$T$6:$T$505,Expenses!$B$6:$B$505,K26,Expenses!$D$6:$D$505,"<>Paying back"))
B27: Food | C27: =SUMIFS(Expenses!$T$6:$T$505,Expenses!$D$6:$D$505,B27) | D27: =IF(N($B$7)=0,"",C27/$B$7) | K27: =IF(OR(MIN(Expenses!$B$6:$B$505)=0,(MIN(Expenses!$B$6:$B$505)+1)>MAX(Expenses!$B$6:$B$505)),"",(MIN(Expenses!$B$6:$B$505)+1)) | L27: =IF(K27="","",SUMIFS(Expenses!$T$6:$T$505,Expenses!$B$6:$B$505,K27,Expenses!$D$6:$D$505,"<>Paying back"))
B28: Transport | C28: =SUMIFS(Expenses!$T$6:$T$505,Expenses!$D$6:$D$505,B28) | D28: =IF(N($B$7)=0,"",C28/$B$7) | K28: =IF(OR(MIN(Expenses!$B$6:$B$505)=0,(MIN(Expenses!$B$6:$B$505)+2)>MAX(Expenses!$B$6:$B$505)),"",(MIN(Expenses!$B$6:$B$505)+2)) | L28: =IF(K28="","",SUMIFS(Expenses!$T$6:$T$505,Expenses!$B$6:$B$505,K28,Expenses!$D$6:$D$505,"<>Paying back"))
B29: Activities | C29: =SUMIFS(Expenses!$T$6:$T$505,Expenses!$D$6:$D$505,B29) | D29: =IF(N($B$7)=0,"",C29/$B$7) | K29: =IF(OR(MIN(Expenses!$B$6:$B$505)=0,(MIN(Expenses!$B$6:$B$505)+3)>MAX(Expenses!$B$6:$B$505)),"",(MIN(Expenses!$B$6:$B$505)+3)) | L29: =IF(K29="","",SUMIFS(Expenses!$T$6:$T$505,Expenses!$B$6:$B$505,K29,Expenses!$D$6:$D$505,"<>Paying back"))
B30: Groceries | C30: =SUMIFS(Expenses!$T$6:$T$505,Expenses!$D$6:$D$505,B30) | D30: =IF(N($B$7)=0,"",C30/$B$7) | K30: =IF(OR(MIN(Expenses!$B$6:$B$505)=0,(MIN(Expenses!$B$6:$B$505)+4)>MAX(Expenses!$B$6:$B$505)),"",(MIN(Expenses!$B$6:$B$505)+4)) | L30: =IF(K30="","",SUMIFS(Expenses!$T$6:$T$505,Expenses!$B$6:$B$505,K30,Expenses!$D$6:$D$505,"<>Paying back"))
B31: Other | C31: =SUMIFS(Expenses!$T$6:$T$505,Expenses!$D$6:$D$505,B31) | D31: =IF(N($B$7)=0,"",C31/$B$7) | K31: =IF(OR(MIN(Expenses!$B$6:$B$505)=0,(MIN(Expenses!$B$6:$B$505)+5)>MAX(Expenses!$B$6:$B$505)),"",(MIN(Expenses!$B$6:$B$505)+5)) | L31: =IF(K31="","",SUMIFS(Expenses!$T$6:$T$505,Expenses!$B$6:$B$505,K31,Expenses!$D$6:$D$505,"<>Paying back"))
K32: =IF(OR(MIN(Expenses!$B$6:$B$505)=0,(MIN(Expenses!$B$6:$B$505)+6)>MAX(Expenses!$B$6:$B$505)),"",(MIN(Expenses!$B$6:$B$505)+6)) | L32: =IF(K32="","",SUMIFS(Expenses!$T$6:$T$505,Expenses!$B$6:$B$505,K32,Expenses!$D$6:$D$505,"<>Paying back"))
K33: =IF(OR(MIN(Expenses!$B$6:$B$505)=0,(MIN(Expenses!$B$6:$B$505)+7)>MAX(Expenses!$B$6:$B$505)),"",(MIN(Expenses!$B$6:$B$505)+7)) | L33: =IF(K33="","",SUMIFS(Expenses!$T$6:$T$505,Expenses!$B$6:$B$505,K33,Expenses!$D$6:$D$505,"<>Paying back"))
K34: =IF(OR(MIN(Expenses!$B$6:$B$505)=0,(MIN(Expenses!$B$6:$B$505)+8)>MAX(Expenses!$B$6:$B$505)),"",(MIN(Expenses!$B$6:$B$505)+8)) | L34: =IF(K34="","",SUMIFS(Expenses!$T$6:$T$505,Expenses!$B$6:$B$505,K34,Expenses!$D$6:$D$505,"<>Paying back"))
K35: =IF(OR(MIN(Expenses!$B$6:$B$505)=0,(MIN(Expenses!$B$6:$B$505)+9)>MAX(Expenses!$B$6:$B$505)),"",(MIN(Expenses!$B$6:$B$505)+9)) | L35: =IF(K35="","",SUMIFS(Expenses!$T$6:$T$505,Expenses!$B$6:$B$505,K35,Expenses!$D$6:$D$505,"<>Paying back"))
K36: =IF(OR(MIN(Expenses!$B$6:$B$505)=0,(MIN(Expenses!$B$6:$B$505)+10)>MAX(Expenses!$B$6:$B$505)),"",(MIN(Expenses!$B$6:$B$505)+10)) | L36: =IF(K36="","",SUMIFS(Expenses!$T$6:$T$505,Expenses!$B$6:$B$505,K36,Expenses!$D$6:$D$505,"<>Paying back"))
K37: =IF(OR(MIN(Expenses!$B$6:$B$505)=0,(MIN(Expenses!$B$6:$B$505)+11)>MAX(Expenses!$B$6:$B$505)),"",(MIN(Expenses!$B$6:$B$505)+11)) | L37: =IF(K37="","",SUMIFS(Expenses!$T$6:$T$505,Expenses!$B$6:$B$505,K37,Expenses!$D$6:$D$505,"<>Paying back"))
K38: =IF(OR(MIN(Expenses!$B$6:$B$505)=0,(MIN(Expenses!$B$6:$B$505)+12)>MAX(Expenses!$B$6:$B$505)),"",(MIN(Expenses!$B$6:$B$505)+12)) | L38: =IF(K38="","",SUMIFS(Expenses!$T$6:$T$505,Expenses!$B$6:$B$505,K38,Expenses!$D$6:$D$505,"<>Paying back"))
K39: =IF(OR(MIN(Expenses!$B$6:$B$505)=0,(MIN(Expenses!$B$6:$B$505)+13)>MAX(Expenses!$B$6:$B$505)),"",(MIN(Expenses!$B$6:$B$505)+13)) | L39: =IF(K39="","",SUMIFS(Expenses!$T$6:$T$505,Expenses!$B$6:$B$505,K39,Expenses!$D$6:$D$505,"<>Paying back"))
K40: =IF(OR(MIN(Expenses!$B$6:$B$505)=0,(MIN(Expenses!$B$6:$B$505)+14)>MAX(Expenses!$B$6:$B$505)),"",(MIN(Expenses!$B$6:$B$505)+14)) | L40: =IF(K40="","",SUMIFS(Expenses!$T$6:$T$505,Expenses!$B$6:$B$505,K40,Expenses!$D$6:$D$505,"<>Paying back"))
K41: =IF(OR(MIN(Expenses!$B$6:$B$505)=0,(MIN(Expenses!$B$6:$B$505)+15)>MAX(Expenses!$B$6:$B$505)),"",(MIN(Expenses!$B$6:$B$505)+15)) | L41: =IF(K41="","",SUMIFS(Expenses!$T$6:$T$505,Expenses!$B$6:$B$505,K41,Expenses!$D$6:$D$505,"<>Paying back"))
K42: =IF(OR(MIN(Expenses!$B$6:$B$505)=0,(MIN(Expenses!$B$6:$B$505)+16)>MAX(Expenses!$B$6:$B$505)),"",(MIN(Expenses!$B$6:$B$505)+16)) | L42: =IF(K42="","",SUMIFS(Expenses!$T$6:$T$505,Expenses!$B$6:$B$505,K42,Expenses!$D$6:$D$505,"<>Paying back"))
K43: =IF(OR(MIN(Expenses!$B$6:$B$505)=0,(MIN(Expenses!$B$6:$B$505)+17)>MAX(Expenses!$B$6:$B$505)),"",(MIN(Expenses!$B$6:$B$505)+17)) | L43: =IF(K43="","",SUMIFS(Expenses!$T$6:$T$505,Expenses!$B$6:$B$505,K43,Expenses!$D$6:$D$505,"<>Paying back"))
K44: =IF(OR(MIN(Expenses!$B$6:$B$505)=0,(MIN(Expenses!$B$6:$B$505)+18)>MAX(Expenses!$B$6:$B$505)),"",(MIN(Expenses!$B$6:$B$505)+18)) | L44: =IF(K44="","",SUMIFS(Expenses!$T$6:$T$505,Expenses!$B$6:$B$505,K44,Expenses!$D$6:$D$505,"<>Paying back"))
K45: =IF(OR(MIN(Expenses!$B$6:$B$505)=0,(MIN(Expenses!$B$6:$B$505)+19)>MAX(Expenses!$B$6:$B$505)),"",(MIN(Expenses!$B$6:$B$505)+19)) | L45: =IF(K45="","",SUMIFS(Expenses!$T$6:$T$505,Expenses!$B$6:$B$505,K45,Expenses!$D$6:$D$505,"<>Paying back"))
...

Sheet Setup
B2: Setup
B3: The trip, the people on it, and the currencies you pay in.
B4: Trip | D4: Lisbon and Porto
B5: Home currency | D5: USD
B8: People | D8: Currency | E8: 1 unit is worth
B9: Ana | D9: =$D$5 | E9: 1 | G9: Up to 12 people. The Expenses tab gets one column for each.
B10: Ben | D10: EUR | E10: 1.08 | G10: Each currency's worth in your home currency, for example 1 EUR is worth 1.08 USD.
B11: Chloe | D11: GBP | E11: 1.27 | G11: Every total on the Dashboard is in the home currency.
B12: Dev | D12: CAD | E12: 0.74
B13: Emma

Sheet Expenses
B2: Expenses
B3: One line per expense. Leave the shares empty to split it between everyone, or put an x under the people who share it. A number gives someone more or less than one share.
B5: Date | C5: What | D5: Category | E5: Amount | F5: Currency | G5: Paid by | H5: =IF(Setup!B9="","",Setup!B9) | I5: =IF(Setup!B10="","",Setup!B10) | J5: =IF(Setup!B11="","",Setup!B11) | K5: =IF(Setup!B12="","",Setup!B12) | L5: =IF(Setup!B13="","",Setup!B13) | M5: =IF(Setup!B14="","",Setup!B14) | N5: =IF(Setup!B15="","",Setup!B15) | O5: =IF(Setup!B16="","",Setup!B16) | P5: =IF(Setup!B17="","",Setup!B17) | Q5: =IF(Setup!B18="","",Setup!B18) | R5: =IF(Setup!B19="","",Setup!B19) | S5: =IF(Setup!B20="","",Setup!B20) | T5: In home currency | U5: Shared by
B6: 46275 | C6: Taxi from the airport | D6: Transport | E6: 38 | F6: EUR | G6: Ana | T6: =IF(N(E6)=0,"",E6*IF(F6="",1,IFERROR(INDEX(Setup!$E$9:$E$18,MATCH(F6,Setup!$D$9:$D$18,0)),0))) | U6: =IF(T6="","",IF(V6=0,"Everyone",IF(COUNTIF(AI6:AT6,">0")=COUNTIF(Setup!$B$9:$B$20,"?*"),"Everyone",COUNTIF(AI6:AT6,">0")&IF(COUNTIF(AI6:AT6,">0")=1," person"," people")))) | V6: =SUM(AI6:AT6) | W6: =IF(OR(T6="",Setup!$B$9=""),0,IF(V6=0,T6/COUNTIF(Setup!$B$9:$B$20,"?*"),T6*AI6/V6)) | X6: =IF(OR(T6="",Setup!$B$10=""),0,IF(V6=0,T6/COUNTIF(Setup!$B$9:$B$20,"?*"),T6*AJ6/V6)) | Y6: =IF(OR(T6="",Setup!$B$11=""),0,IF(V6=0,T6/COUNTIF(Setup!$B$9:$B$20,"?*"),T6*AK6/V6)) | Z6: =IF(OR(T6="",Setup!$B$12=""),0,IF(V6=0,T6/COUNTIF(Setup!$B$9:$B$20,"?*"),T6*AL6/V6)) | AA6: =IF(OR(T6="",Setup!$B$13=""),0,IF(V6=0,T6/COUNTIF(Setup!$B$9:$B$20,"?*"),T6*AM6/V6)) | AB6: =IF(OR(T6="",Setup!$B$14=""),0,IF(V6=0,T6/COUNTIF(Setup!$B$9:$B$20,"?*"),T6*AN6/V6)) | AC6: =IF(OR(T6="",Setup!$B$15=""),0,IF(V6=0,T6/COUNTIF(Setup!$B$9:$B$20,"?*"),T6*AO6/V6)) | AD6: =IF(OR(T6="",Setup!$B$16=""),0,IF(V6=0,T6/COUNTIF(Setup!$B$9:$B$20,"?*"),T6*AP6/V6)) | AE6: =IF(OR(T6="",Setup!$B$17=""),0,IF(V6=0,T6/COUNTIF(Setup!$B$9:$B$20,"?*"),T6*AQ6/V6)) | AF6: =IF(OR(T6="",Setup!$B$18=""),0,IF(V6=0,T6/COUNTIF(Setup!$B$9:$B$20,"?*"),T6*AR6/V6)) | AG6: =IF(OR(T6="",Setup!$B$19=""),0,IF(V6=0,T6/COUNTIF(Setup!$B$9:$B$20,"?*"),T6*AS6/V6)) | AH6: =IF(OR(T6="",Setup!$B$20=""),0,IF(V6=0,T6/COUNTIF(Setup!$B$9:$B$20,"?*"),T6*AT6/V6)) | AI6: =IF(Setup!$B$9="",0,IF(H6="",0,IF(ISNUMBER(H6),H6,1))) | AJ6: =IF(Setup!$B$10="",0,IF(I6="",0,IF(ISNUMBER(I6),I6,1))) | AK6: =IF(Setup!$B$11="",0,IF(J6="",0,IF(ISNUMBER(J6),J6,1))) | AL6: =IF(Setup!$B$12="",0,IF(K6="",0,IF(ISNUMBER(K6),K6,1))) | AM6: =IF(Setup!$B$13="",0,IF(L6="",0,IF(ISNUMBER(L6),L6,1))) | AN6: =IF(Setup!$B$14="",0,IF(M6="",0,IF(ISNUMBER(M6),M6,1))) | AO6: =IF(Setup!$B$15="",0,IF(N6="",0,IF(ISNUMBER(N6),N6,1))) | AP6: =IF(Setup!$B$16="",0,IF(O6="",0,IF(ISNUMBER(O6),O6,1))) | AQ6: =IF(Setup!$B$17="",0,IF(P6="",0,IF(ISNUMBER(P6),P6,1))) | AR6: =IF(Setup!$B$18="",0,IF(Q6="",0,IF(ISNUMBER(Q6),Q6,1))) | AS6: =IF(Setup!$B$19="",0,IF(R6="",0,IF(ISNUMBER(R6),R6,1))) | AT6: =IF(Setup!$B$20="",0,IF(S6="",0,IF(ISNUMBER(S6),S6,1)))
B7: 46275 | C7: Flat in Lisbon, 4 nights | D7: Lodging | E7: 780 | F7: EUR | G7: Ben | T7: =IF(N(E7)=0,"",E7*IF(F7="",1,IFERROR(INDEX(Setup!$E$9:$E$18,MATCH(F7,Setup!$D$9:$D$18,0)),0))) | U7: =IF(T7="","",IF(V7=0,"Everyone",IF(COUNTIF(AI7:AT7,">0")=COUNTIF(Setup!$B$9:$B$20,"?*"),"Everyone",COUNTIF(AI7:AT7,">0")&IF(COUNTIF(AI7:AT7,">0")=1," person"," people")))) | V7: =SUM(AI7:AT7) | W7: =IF(OR(T7="",Setup!$B$9=""),0,IF(V7=0,T7/COUNTIF(Setup!$B$9:$B$20,"?*"),T7*AI7/V7)) | X7: =IF(OR(T7="",Setup!$B$10=""),0,IF(V7=0,T7/COUNTIF(Setup!$B$9:$B$20,"?*"),T7*AJ7/V7)) | Y7: =IF(OR(T7="",Setup!$B$11=""),0,IF(V7=0,T7/COUNTIF(Setup!$B$9:$B$20,"?*"),T7*AK7/V7)) | Z7: =IF(OR(T7="",Setup!$B$12=""),0,IF(V7=0,T7/COUNTIF(Setup!$B$9:$B$20,"?*"),T7*AL7/V7)) | AA7: =IF(OR(T7="",Setup!$B$13=""),0,IF(V7=0,T7/COUNTIF(Setup!$B$9:$B$20,"?*"),T7*AM7/V7)) | AB7: =IF(OR(T7="",Setup!$B$14=""),0,IF(V7=0,T7/COUNTIF(Setup!$B$9:$B$20,"?*"),T7*AN7/V7)) | AC7: =IF(OR(T7="",Setup!$B$15=""),0,IF(V7=0,T7/COUNTIF(Setup!$B$9:$B$20,"?*"),T7*AO7/V7)) | AD7: =IF(OR(T7="",Setup!$B$16=""),0,IF(V7=0,T7/COUNTIF(Setup!$B$9:$B$20,"?*"),T7*AP7/V7)) | AE7: =IF(OR(T7="",Setup!$B$17=""),0,IF(V7=0,T7/COUNTIF(Setup!$B$9:$B$20,"?*"),T7*AQ7/V7)) | AF7: =IF(OR(T7="",Setup!$B$18=""),0,IF(V7=0,T7/COUNTIF(Setup!$B$9:$B$20,"?*"),T7*AR7/V7)) | AG7: =IF(OR(T7="",Setup!$B$19=""),0,IF(V7=0,T7/COUNTIF(Setup!$B$9:$B$20,"?*"),T7*AS7/V7)) | AH7: =IF(OR(T7="",Setup!$B$20=""),0,IF(V7=0,T7/COUNTIF(Setup!$B$9:$B$20,"?*"),T7*AT7/V7)) | AI7: =IF(Setup!$B$9="",0,IF(H7="",0,IF(ISNUMBER(H7),H7,1))) | AJ7: =IF(Setup!$B$10="",0,IF(I7="",0,IF(ISNUMBER(I7),I7,1))) | AK7: =IF(Setup!$B$11="",0,IF(J7="",0,IF(ISNUMBER(J7),J7,1))) | AL7: =IF(Setup!$B$12="",0,IF(K7="",0,IF(ISNUMBER(K7),K7,1))) | AM7: =IF(Setup!$B$13="",0,IF(L7="",0,IF(ISNUMBER(L7),L7,1))) | AN7: =IF(Setup!$B$14="",0,IF(M7="",0,IF(ISNUMBER(M7),M7,1))) | AO7: =IF(Setup!$B$15="",0,IF(N7="",0,IF(ISNUMBER(N7),N7,1))) | AP7: =IF(Setup!$B$16="",0,IF(O7="",0,IF(ISNUMBER(O7),O7,1))) | AQ7: =IF(Setup!$B$17="",0,IF(P7="",0,IF(ISNUMBER(P7),P7,1))) | AR7: =IF(Setup!$B$18="",0,IF(Q7="",0,IF(ISNUMBER(Q7),Q7,1))) | AS7: =IF(Setup!$B$19="",0,IF(R7="",0,IF(ISNUMBER(R7),R7,1))) | AT7: =IF(Setup!$B$20="",0,IF(S7="",0,IF(ISNUMBER(S7),S7,1)))
B8: 46275 | C8: Groceries for the flat | D8: Groceries | E8: 64.3 | F8: EUR | G8: Chloe | T8: =IF(N(E8)=0,"",E8*IF(F8="",1,IFERROR(INDEX(Setup!$E$9:$E$18,MATCH(F8,Setup!$D$9:$D$18,0)),0))) | U8: =IF(T8="","",IF(V8=0,"Everyone",IF(COUNTIF(AI8:AT8,">0")=COUNTIF(Setup!$B$9:$B$20,"?*"),"Everyone",COUNTIF(AI8:AT8,">0")&IF(COUNTIF(AI8:AT8,">0")=1," person"," people")))) | V8: =SUM(AI8:AT8) | W8: =IF(OR(T8="",Setup!$B$9=""),0,IF(V8=0,T8/COUNTIF(Setup!$B$9:$B$20,"?*"),T8*AI8/V8)) | X8: =IF(OR(T8="",Setup!$B$10=""),0,IF(V8=0,T8/COUNTIF(Setup!$B$9:$B$20,"?*"),T8*AJ8/V8)) | Y8: =IF(OR(T8="",Setup!$B$11=""),0,IF(V8=0,T8/COUNTIF(Setup!$B$9:$B$20,"?*"),T8*AK8/V8)) | Z8: =IF(OR(T8="",Setup!$B$12=""),0,IF(V8=0,T8/COUNTIF(Setup!$B$9:$B$20,"?*"),T8*AL8/V8)) | AA8: =IF(OR(T8="",Setup!$B$13=""),0,IF(V8=0,T8/COUNTIF(Setup!$B$9:$B$20,"?*"),T8*AM8/V8)) | AB8: =IF(OR(T8="",Setup!$B$14=""),0,IF(V8=0,T8/COUNTIF(Setup!$B$9:$B$20,"?*"),T8*AN8/V8)) | AC8: =IF(OR(T8="",Setup!$B$15=""),0,IF(V8=0,T8/COUNTIF(Setup!$B$9:$B$20,"?*"),T8*AO8/V8)) | AD8: =IF(OR(T8="",Setup!$B$16=""),0,IF(V8=0,T8/COUNTIF(Setup!$B$9:$B$20,"?*"),T8*AP8/V8)) | AE8: =IF(OR(T8="",Setup!$B$17=""),0,IF(V8=0,T8/COUNTIF(Setup!$B$9:$B$20,"?*"),T8*AQ8/V8)) | AF8: =IF(OR(T8="",Setup!$B$18=""),0,IF(V8=0,T8/COUNTIF(Setup!$B$9:$B$20,"?*"),T8*AR8/V8)) | AG8: =IF(OR(T8="",Setup!$B$19=""),0,IF(V8=0,T8/COUNTIF(Setup!$B$9:$B$20,"?*"),T8*AS8/V8)) | AH8: =IF(OR(T8="",Setup!$B$20=""),0,IF(V8=0,T8/COUNTIF(Setup!$B$9:$B$20,"?*"),T8*AT8/V8)) | AI8: =IF(Setup!$B$9="",0,IF(H8="",0,IF(ISNUMBER(H8),H8,1))) | AJ8: =IF(Setup!$B$10="",0,IF(I8="",0,IF(ISNUMBER(I8),I8,1))) | AK8: =IF(Setup!$B$11="",0,IF(J8="",0,IF(ISNUMBER(J8),J8,1))) | AL8: =IF(Setup!$B$12="",0,IF(K8="",0,IF(ISNUMBER(K8),K8,1))) | AM8: =IF(Setup!$B$13="",0,IF(L8="",0,IF(ISNUMBER(L8),L8,1))) | AN8: =IF(Setup!$B$14="",0,IF(M8="",0,IF(ISNUMBER(M8),M8,1))) | AO8: =IF(Setup!$B$15="",0,IF(N8="",0,IF(ISNUMBER(N8),N8,1))) | AP8: =IF(Setup!$B$16="",0,IF(O8="",0,IF(ISNUMBER(O8),O8,1))) | AQ8: =IF(Setup!$B$17="",0,IF(P8="",0,IF(ISNUMBER(P8),P8,1))) | AR8: =IF(Setup!$B$18="",0,IF(Q8="",0,IF(ISNUMBER(Q8),Q8,1))) | AS8: =IF(Setup!$B$19="",0,IF(R8="",0,IF(ISNUMBER(R8),R8,1))) | AT8: =IF(Setup!$B$20="",0,IF(S8="",0,IF(ISNUMBER(S8),S8,1)))
B9: 46275 | C9: Dinner in Alfama | D9: Food | E9: 142 | F9: EUR | G9: Dev | T9: =IF(N(E9)=0,"",E9*IF(F9="",1,IFERROR(INDEX(Setup!$E$9:$E$18,MATCH(F9,Setup!$D$9:$D$18,0)),0))) | U9: =IF(T9="","",IF(V9=0,"Everyone",IF(COUNTIF(AI9:AT9,">0")=COUNTIF(Setup!$B$9:$B$20,"?*"),"Everyone",COUNTIF(AI9:AT9,">0")&IF(COUNTIF(AI9:AT9,">0")=1," person"," people")))) | V9: =SUM(AI9:AT9) | W9: =IF(OR(T9="",Setup!$B$9=""),0,IF(V9=0,T9/COUNTIF(Setup!$B$9:$B$20,"?*"),T9*AI9/V9)) | X9: =IF(OR(T9="",Setup!$B$10=""),0,IF(V9=0,T9/COUNTIF(Setup!$B$9:$B$20,"?*"),T9*AJ9/V9)) | Y9: =IF(OR(T9="",Setup!$B$11=""),0,IF(V9=0,T9/COUNTIF(Setup!$B$9:$B$20,"?*"),T9*AK9/V9)) | Z9: =IF(OR(T9="",Setup!$B$12=""),0,IF(V9=0,T9/COUNTIF(Setup!$B$9:$B$20,"?*"),T9*AL9/V9)) | AA9: =IF(OR(T9="",Setup!$B$13=""),0,IF(V9=0,T9/COUNTIF(Setup!$B$9:$B$20,"?*"),T9*AM9/V9)) | AB9: =IF(OR(T9="",Setup!$B$14=""),0,IF(V9=0,T9/COUNTIF(Setup!$B$9:$B$20,"?*"),T9*AN9/V9)) | AC9: =IF(OR(T9="",Setup!$B$15=""),0,IF(V9=0,T9/COUNTIF(Setup!$B$9:$B$20,"?*"),T9*AO9/V9)) | AD9: =IF(OR(T9="",Setup!$B$16=""),0,IF(V9=0,T9/COUNTIF(Setup!$B$9:$B$20,"?*"),T9*AP9/V9)) | AE9: =IF(OR(T9="",Setup!$B$17=""),0,IF(V9=0,T9/COUNTIF(Setup!$B$9:$B$20,"?*"),T9*AQ9/V9)) | AF9: =IF(OR(T9="",Setup!$B$18=""),0,IF(V9=0,T9/COUNTIF(Setup!$B$9:$B$20,"?*"),T9*AR9/V9)) | AG9: =IF(OR(T9="",Setup!$B$19=""),0,IF(V9=0,T9/COUNTIF(Setup!$B$9:$B$20,"?*"),T9*AS9/V9)) | AH9: =IF(OR(T9="",Setup!$B$20=""),0,IF(V9=0,T9/COUNTIF(Setup!$B$9:$B$20,"?*"),T9*AT9/V9)) | AI9: =IF(Setup!$B$9="",0,IF(H9="",0,IF(ISNUMBER(H9),H9,1))) | AJ9: =IF(Setup!$B$10="",0,IF(I9="",0,IF(ISNUMBER(I9),I9,1))) | AK9: =IF(Setup!$B$11="",0,IF(J9="",0,IF(ISNUMBER(J9),J9,1))) | AL9: =IF(Setup!$B$12="",0,IF(K9="",0,IF(ISNUMBER(K9),K9,1))) | AM9: =IF(Setup!$B$13="",0,IF(L9="",0,IF(ISNUMBER(L9),L9,1))) | AN9: =IF(Setup!$B$14="",0,IF(M9="",0,IF(ISNUMBER(M9),M9,1))) | AO9: =IF(Setup!$B$15="",0,IF(N9="",0,IF(ISNUMBER(N9),N9,1))) | AP9: =IF(Setup!$B$16="",0,IF(O9="",0,IF(ISNUMBER(O9),O9,1))) | AQ9: =IF(Setup!$B$17="",0,IF(P9="",0,IF(ISNUMBER(P9),P9,1))) | AR9: =IF(Setup!$B$18="",0,IF(Q9="",0,IF(ISNUMBER(Q9),Q9,1))) | AS9: =IF(Setup!$B$19="",0,IF(R9="",0,IF(ISNUMBER(R9),R9,1))) | AT9: =IF(Setup!$B$20="",0,IF(S9="",0,IF(ISNUMBER(S9),S9,1)))
B10: 46276 | C10: Tram day passes | D10: Transport | E10: 32 | F10: EUR | G10: Emma | T10: =IF(N(E10)=0,"",E10*IF(F10="",1,IFERROR(INDEX(Setup!$E$9:$E$18,MATCH(F10,Setup!$D$9:$D$18,0)),0))) | U10: =IF(T10="","",IF(V10=0,"Everyone",IF(COUNTIF(AI10:AT10,">0")=COUNTIF(Setup!$B$9:$B$20,"?*"),"Everyone",COUNTIF(AI10:AT10,">0")&IF(COUNTIF(AI10:AT10,">0")=1," person"," people")))) | V10: =SUM(AI10:AT10) | W10: =IF(OR(T10="",Setup!$B$9=""),0,IF(V10=0,T10/COUNTIF(Setup!$B$9:$B$20,"?*"),T10*AI10/V10)) | X10: =IF(OR(T10="",Setup!$B$10=""),0,IF(V10=0,T10/COUNTIF(Setup!$B$9:$B$20,"?*"),T10*AJ10/V10)) | Y10: =IF(OR(T10="",Setup!$B$11=""),0,IF(V10=0,T10/COUNTIF(Setup!$B$9:$B$20,"?*"),T10*AK10/V10)) | Z10: =IF(OR(T10="",Setup!$B$12=""),0,IF(V10=0,T10/COUNTIF(Setup!$B$9:$B$20,"?*"),T10*AL10/V10)) | AA10: =IF(OR(T10="",Setup!$B$13=""),0,IF(V10=0,T10/COUNTIF(Setup!$B$9:$B$20,"?*"),T10*AM10/V10)) | AB10: =IF(OR(T10="",Setup!$B$14=""),0,IF(V10=0,T10/COUNTIF(Setup!$B$9:$B$20,"?*"),T10*AN10/V10)) | AC10: =IF(OR(T10="",Setup!$B$15=""),0,IF(V10=0,T10/COUNTIF(Setup!$B$9:$B$20,"?*"),T10*AO10/V10)) | AD10: =IF(OR(T10="",Setup!$B$16=""),0,IF(V10=0,T10/COUNTIF(Setup!$B$9:$B$20,"?*"),T10*AP10/V10)) | AE10: =IF(OR(T10="",Setup!$B$17=""),0,IF(V10=0,T10/COUNTIF(Setup!$B$9:$B$20,"?*"),T10*AQ10/V10)) | AF10: =IF(OR(T10="",Setup!$B$18=""),0,IF(V10=0,T10/COUNTIF(Setup!$B$9:$B$20,"?*"),T10*AR10/V10)) | AG10: =IF(OR(T10="",Setup!$B$19=""),0,IF(V10=0,T10/COUNTIF(Setup!$B$9:$B$20,"?*"),T10*AS10/V10)) | AH10: =IF(OR(T10="",Setup!$B$20=""),0,IF(V10=0,T10/COUNTIF(Setup!$B$9:$B$20,"?*"),T10*AT10/V10)) | AI10: =IF(Setup!$B$9="",0,IF(H10="",0,IF(ISNUMBER(H10),H10,1))) | AJ10: =IF(Setup!$B$10="",0,IF(I10="",0,IF(ISNUMBER(I10),I10,1))) | AK10: =IF(Setup!$B$11="",0,IF(J10="",0,IF(ISNUMBER(J10),J10,1))) | AL10: =IF(Setup!$B$12="",0,IF(K10="",0,IF(ISNUMBER(K10),K10,1))) | AM10: =IF(Setup!$B$13="",0,IF(L10="",0,IF(ISNUMBER(L10),L10,1))) | AN10: =IF(Setup!$B$14="",0,IF(M10="",0,IF(ISNUMBER(M10),M10,1))) | AO10: =IF(Setup!$B$15="",0,IF(N10="",0,IF(ISNUMBER(N10),N10,1))) | AP10: =IF(Setup!$B$16="",0,IF(O10="",0,IF(ISNUMBER(O10),O10,1))) | AQ10: =IF(Setup!$B$17="",0,IF(P10="",0,IF(ISNUMBER(P10),P10,1))) | AR10: =IF(Setup!$B$18="",0,IF(Q10="",0,IF(ISNUMBER(Q10),Q10,1))) | AS10: =IF(Setup!$B$19="",0,IF(R10="",0,IF(ISNUMBER(R10),R10,1))) | AT10: =IF(Setup!$B$20="",0,IF(S10="",0,IF(ISNUMBER(S10),S10,1)))
B11: 46276 | C11: Lunch at the market | D11: Food | E11: 88.5 | F11: EUR | G11: Ana | T11: =IF(N(E11)=0,"",E11*IF(F11="",1,IFERROR(INDEX(Setup!$E$9:$E$18,MATCH(F11,Setup!$D$9:$D$18,0)),0))) | U11: =IF(T11="","",IF(V11=0,"Everyone",IF(COUNTIF(AI11:AT11,">0")=COUNTIF(Setup!$B$9:$B$20,"?*"),"Everyone",COUNTIF(AI11:AT11,">0")&IF(COUNTIF(AI11:AT11,">0")=1," person"," people")))) | V11: =SUM(AI11:AT11) | W11: =IF(OR(T11="",Setup!$B$9=""),0,IF(V11=0,T11/COUNTIF(Setup!$B$9:$B$20,"?*"),T11*AI11/V11)) | X11: =IF(OR(T11="",Setup!$B$10=""),0,IF(V11=0,T11/COUNTIF(Setup!$B$9:$B$20,"?*"),T11*AJ11/V11)) | Y11: =IF(OR(T11="",Setup!$B$11=""),0,IF(V11=0,T11/COUNTIF(Setup!$B$9:$B$20,"?*"),T11*AK11/V11)) | Z11: =IF(OR(T11="",Setup!$B$12=""),0,IF(V11=0,T11/COUNTIF(Setup!$B$9:$B$20,"?*"),T11*AL11/V11)) | AA11: =IF(OR(T11="",Setup!$B$13=""),0,IF(V11=0,T11/COUNTIF(Setup!$B$9:$B$20,"?*"),T11*AM11/V11)) | AB11: =IF(OR(T11="",Setup!$B$14=""),0,IF(V11=0,T11/COUNTIF(Setup!$B$9:$B$20,"?*"),T11*AN11/V11)) | AC11: =IF(OR(T11="",Setup!$B$15=""),0,IF(V11=0,T11/COUNTIF(Setup!$B$9:$B$20,"?*"),T11*AO11/V11)) | AD11: =IF(OR(T11="",Setup!$B$16=""),0,IF(V11=0,T11/COUNTIF(Setup!$B$9:$B$20,"?*"),T11*AP11/V11)) | AE11: =IF(OR(T11="",Setup!$B$17=""),0,IF(V11=0,T11/COUNTIF(Setup!$B$9:$B$20,"?*"),T11*AQ11/V11)) | AF11: =IF(OR(T11="",Setup!$B$18=""),0,IF(V11=0,T11/COUNTIF(Setup!$B$9:$B$20,"?*"),T11*AR11/V11)) | AG11: =IF(OR(T11="",Setup!$B$19=""),0,IF(V11=0,T11/COUNTIF(Setup!$B$9:$B$20,"?*"),T11*AS11/V11)) | AH11: =IF(OR(T11="",Setup!$B$20=""),0,IF(V11=0,T11/COUNTIF(Setup!$B$9:$B$20,"?*"),T11*AT11/V11)) | AI11: =IF(Setup!$B$9="",0,IF(H11="",0,IF(ISNUMBER(H11),H11,1))) | AJ11: =IF(Setup!$B$10="",0,IF(I11="",0,IF(ISNUMBER(I11),I11,1))) | AK11: =IF(Setup!$B$11="",0,IF(J11="",0,IF(ISNUMBER(J11),J11,1))) | AL11: =IF(Setup!$B$12="",0,IF(K11="",0,IF(ISNUMBER(K11),K11,1))) | AM11: =IF(Setup!$B$13="",0,IF(L11="",0,IF(ISNUMBER(L11),L11,1))) | AN11: =IF(Setup!$B$14="",0,IF(M11="",0,IF(ISNUMBER(M11),M11,1))) | AO11: =IF(Setup!$B$15="",0,IF(N11="",0,IF(ISNUMBER(N11),N11,1))) | AP11: =IF(Setup!$B$16="",0,IF(O11="",0,IF(ISNUMBER(O11),O11,1))) | AQ11: =IF(Setup!$B$17="",0,IF(P11="",0,IF(ISNUMBER(P11),P11,1))) | AR11: =IF(Setup!$B$18="",0,IF(Q11="",0,IF(ISNUMBER(Q11),Q11,1))) | AS11: =IF(Setup!$B$19="",0,IF(R11="",0,IF(ISNUMBER(R11),R11,1))) | AT11: =IF(Setup!$B$20="",0,IF(S11="",0,IF(ISNUMBER(S11),S11,1)))
B12: 46276 | C12: Castle tickets | D12: Activities | E12: 60 | F12: EUR | G12: Ben | H12: x | I12: x | J12: x | K12: x | T12: =IF(N(E12)=0,"",E12*IF(F12="",1,IFERROR(INDEX(Setup!$E$9:$E$18,MATCH(F12,Setup!$D$9:$D$18,0)),0))) | U12: =IF(T12="","",IF(V12=0,"Everyone",IF(COUNTIF(AI12:AT12,">0")=COUNTIF(Setup!$B$9:$B$20,"?*"),"Everyone",COUNTIF(AI12:AT12,">0")&IF(COUNTIF(AI12:AT12,">0")=1," person"," people")))) | V12: =SUM(AI12:AT12) | W12: =IF(OR(T12="",Setup!$B$9=""),0,IF(V12=0,T12/COUNTIF(Setup!$B$9:$B$20,"?*"),T12*AI12/V12)) | X12: =IF(OR(T12="",Setup!$B$10=""),0,IF(V12=0,T12/COUNTIF(Setup!$B$9:$B$20,"?*"),T12*AJ12/V12)) | Y12: =IF(OR(T12="",Setup!$B$11=""),0,IF(V12=0,T12/COUNTIF(Setup!$B$9:$B$20,"?*"),T12*AK12/V12)) | Z12: =IF(OR(T12="",Setup!$B$12=""),0,IF(V12=0,T12/COUNTIF(Setup!$B$9:$B$20,"?*"),T12*AL12/V12)) | AA12: =IF(OR(T12="",Setup!$B$13=""),0,IF(V12=0,T12/COUNTIF(Setup!$B$9:$B$20,"?*"),T12*AM12/V12)) | AB12: =IF(OR(T12="",Setup!$B$14=""),0,IF(V12=0,T12/COUNTIF(Setup!$B$9:$B$20,"?*"),T12*AN12/V12)) | AC12: =IF(OR(T12="",Setup!$B$15=""),0,IF(V12=0,T12/COUNTIF(Setup!$B$9:$B$20,"?*"),T12*AO12/V12)) | AD12: =IF(OR(T12="",Setup!$B$16=""),0,IF(V12=0,T12/COUNTIF(Setup!$B$9:$B$20,"?*"),T12*AP12/V12)) | AE12: =IF(OR(T12="",Setup!$B$17=""),0,IF(V12=0,T12/COUNTIF(Setup!$B$9:$B$20,"?*"),T12*AQ12/V12)) | AF12: =IF(OR(T12="",Setup!$B$18=""),0,IF(V12=0,T12/COUNTIF(Setup!$B$9:$B$20,"?*"),T12*AR12/V12)) | AG12: =IF(OR(T12="",Setup!$B$19=""),0,IF(V12=0,T12/COUNTIF(Setup!$B$9:$B$20,"?*"),T12*AS12/V12)) | AH12: =IF(OR(T12="",Setup!$B$20=""),0,IF(V12=0,T12/COUNTIF(Setup!$B$9:$B$20,"?*"),T12*AT12/V12)) | AI12: =IF(Setup!$B$9="",0,IF(H12="",0,IF(ISNUMBER(H12),H12,1))) | AJ12: =IF(Setup!$B$10="",0,IF(I12="",0,IF(ISNUMBER(I12),I12,1))) | AK12: =IF(Setup!$B$11="",0,IF(J12="",0,IF(ISNUMBER(J12),J12,1))) | AL12: =IF(Setup!$B$12="",0,IF(K12="",0,IF(ISNUMBER(K12),K12,1))) | AM12: =IF(Setup!$B$13="",0,IF(L12="",0,IF(ISNUMBER(L12),L12,1))) | AN12: =IF(Setup!$B$14="",0,IF(M12="",0,IF(ISNUMBER(M12),M12,1))) | AO12: =IF(Setup!$B$15="",0,IF(N12="",0,IF(ISNUMBER(N12),N12,1))) | AP12: =IF(Setup!$B$16="",0,IF(O12="",0,IF(ISNUMBER(O12),O12,1))) | AQ12: =IF(Setup!$B$17="",0,IF(P12="",0,IF(ISNUMBER(P12),P12,1))) | AR12: =IF(Setup!$B$18="",0,IF(Q12="",0,IF(ISNUMBER(Q12),Q12,1))) | AS12: =IF(Setup!$B$19="",0,IF(R12="",0,IF(ISNUMBER(R12),R12,1))) | AT12: =IF(Setup!$B$20="",0,IF(S12="",0,IF(ISNUMBER(S12),S12,1)))
B13: 46276 | C13: Dinner and fado | D13: Food | E13: 196 | F13: EUR | G13: Chloe | T13: =IF(N(E13)=0,"",E13*IF(F13="",1,IFERROR(INDEX(Setup!$E$9:$E$18,MATCH(F13,Setup!$D$9:$D$18,0)),0))) | U13: =IF(T13="","",IF(V13=0,"Everyone",IF(COUNTIF(AI13:AT13,">0")=COUNTIF(Setup!$B$9:$B$20,"?*"),"Everyone",COUNTIF(AI13:AT13,">0")&IF(COUNTIF(AI13:AT13,">0")=1," person"," people")))) | V13: =SUM(AI13:AT13) | W13: =IF(OR(T13="",Setup!$B$9=""),0,IF(V13=0,T13/COUNTIF(Setup!$B$9:$B$20,"?*"),T13*AI13/V13)) | X13: =IF(OR(T13="",Setup!$B$10=""),0,IF(V13=0,T13/COUNTIF(Setup!$B$9:$B$20,"?*"),T13*AJ13/V13)) | Y13: =IF(OR(T13="",Setup!$B$11=""),0,IF(V13=0,T13/COUNTIF(Setup!$B$9:$B$20,"?*"),T13*AK13/V13)) | Z13: =IF(OR(T13="",Setup!$B$12=""),0,IF(V13=0,T13/COUNTIF(Setup!$B$9:$B$20,"?*"),T13*AL13/V13)) | AA13: =IF(OR(T13="",Setup!$B$13=""),0,IF(V13=0,T13/COUNTIF(Setup!$B$9:$B$20,"?*"),T13*AM13/V13)) | AB13: =IF(OR(T13="",Setup!$B$14=""),0,IF(V13=0,T13/COUNTIF(Setup!$B$9:$B$20,"?*"),T13*AN13/V13)) | AC13: =IF(OR(T13="",Setup!$B$15=""),0,IF(V13=0,T13/COUNTIF(Setup!$B$9:$B$20,"?*"),T13*AO13/V13)) | AD13: =IF(OR(T13="",Setup!$B$16=""),0,IF(V13=0,T13/COUNTIF(Setup!$B$9:$B$20,"?*"),T13*AP13/V13)) | AE13: =IF(OR(T13="",Setup!$B$17=""),0,IF(V13=0,T13/COUNTIF(Setup!$B$9:$B$20,"?*"),T13*AQ13/V13)) | AF13: =IF(OR(T13="",Setup!$B$18=""),0,IF(V13=0,T13/COUNTIF(Setup!$B$9:$B$20,"?*"),T13*AR13/V13)) | AG13: =IF(OR(T13="",Setup!$B$19=""),0,IF(V13=0,T13/COUNTIF(Setup!$B$9:$B$20,"?*"),T13*AS13/V13)) | AH13: =IF(OR(T13="",Setup!$B$20=""),0,IF(V13=0,T13/COUNTIF(Setup!$B$9:$B$20,"?*"),T13*AT13/V13)) | AI13: =IF(Setup!$B$9="",0,IF(H13="",0,IF(ISNUMBER(H13),H13,1))) | AJ13: =IF(Setup!$B$10="",0,IF(I13="",0,IF(ISNUMBER(I13),I13,1))) | AK13: =IF(Setup!$B$11="",0,IF(J13="",0,IF(ISNUMBER(J13),J13,1))) | AL13: =IF(Setup!$B$12="",0,IF(K13="",0,IF(ISNUMBER(K13),K13,1))) | AM13: =IF(Setup!$B$13="",0,IF(L13="",0,IF(ISNUMBER(L13),L13,1))) | AN13: =IF(Setup!$B$14="",0,IF(M13="",0,IF(ISNUMBER(M13),M13,1))) | AO13: =IF(Setup!$B$15="",0,IF(N13="",0,IF(ISNUMBER(N13),N13,1))) | AP13: =IF(Setup!$B$16="",0,IF(O13="",0,IF(ISNUMBER(O13),O13,1))) | AQ13: =IF(Setup!$B$17="",0,IF(P13="",0,IF(ISNUMBER(P13),P13,1))) | AR13: =IF(Setup!$B$18="",0,IF(Q13="",0,IF(ISNUMBER(Q13),Q13,1))) | AS13: =IF(Setup!$B$19="",0,IF(R13="",0,IF(ISNUMBER(R13),R13,1))) | AT13: =IF(Setup!$B$20="",0,IF(S13="",0,IF(ISNUMBER(S13),S13,1)))
B14: 46277 | C14: Sintra train and palace | D14: Activities | E14: 115 | F14: EUR | G14: Dev | T14: =IF(N(E14)=0,"",E14*IF(F14="",1,IFERROR(INDEX(Setup!$E$9:$E$18,MATCH(F14,Setup!$D$9:$D$18,0)),0))) | U14: =IF(T14="","",IF(V14=0,"Everyone",IF(COUNTIF(AI14:AT14,">0")=COUNTIF(Setup!$B$9:$B$20,"?*"),"Everyone",COUNTIF(AI14:AT14,">0")&IF(COUNTIF(AI14:AT14,">0")=1," person"," people")))) | V14: =SUM(AI14:AT14) | W14: =IF(OR(T14="",Setup!$B$9=""),0,IF(V14=0,T14/COUNTIF(Setup!$B$9:$B$20,"?*"),T14*AI14/V14)) | X14: =IF(OR(T14="",Setup!$B$10=""),0,IF(V14=0,T14/COUNTIF(Setup!$B$9:$B$20,"?*"),T14*AJ14/V14)) | Y14: =IF(OR(T14="",Setup!$B$11=""),0,IF(V14=0,T14/COUNTIF(Setup!$B$9:$B$20,"?*"),T14*AK14/V14)) | Z14: =IF(OR(T14="",Setup!$B$12=""),0,IF(V14=0,T14/COUNTIF(Setup!$B$9:$B$20,"?*"),T14*AL14/V14)) | AA14: =IF(OR(T14="",Setup!$B$13=""),0,IF(V14=0,T14/COUNTIF(Setup!$B$9:$B$20,"?*"),T14*AM14/V14)) | AB14: =IF(OR(T14="",Setup!$B$14=""),0,IF(V14=0,T14/COUNTIF(Setup!$B$9:$B$20,"?*"),T14*AN14/V14)) | AC14: =IF(OR(T14="",Setup!$B$15=""),0,IF(V14=0,T14/COUNTIF(Setup!$B$9:$B$20,"?*"),T14*AO14/V14)) | AD14: =IF(OR(T14="",Setup!$B$16=""),0,IF(V14=0,T14/COUNTIF(Setup!$B$9:$B$20,"?*"),T14*AP14/V14)) | AE14: =IF(OR(T14="",Setup!$B$17=""),0,IF(V14=0,T14/COUNTIF(Setup!$B$9:$B$20,"?*"),T14*AQ14/V14)) | AF14: =IF(OR(T14="",Setup!$B$18=""),0,IF(V14=0,T14/COUNTIF(Setup!$B$9:$B$20,"?*"),T14*AR14/V14)) | AG14: =IF(OR(T14="",Setup!$B$19=""),0,IF(V14=0,T14/COUNTIF(Setup!$B$9:$B$20,"?*"),T14*AS14/V14)) | AH14: =IF(OR(T14="",Setup!$B$20=""),0,IF(V14=0,T14/COUNTIF(Setup!$B$9:$B$20,"?*"),T14*AT14/V14)) | AI14: =IF(Setup!$B$9="",0,IF(H14="",0,IF(ISNUMBER(H14),H14,1))) | AJ14: =IF(Setup!$B$10="",0,IF(I14="",0,IF(ISNUMBER(I14),I14,1))) | AK14: =IF(Setup!$B$11="",0,IF(J14="",0,IF(ISNUMBER(J14),J14,1))) | AL14: =IF(Setup!$B$12="",0,IF(K14="",0,IF(ISNUMBER(K14),K14,1))) | AM14: =IF(Setup!$B$13="",0,IF(L14="",0,IF(ISNUMBER(L14),L14,1))) | AN14: =IF(Setup!$B$14="",0,IF(M14="",0,IF(ISNUMBER(M14),M14,1))) | AO14: =IF(Setup!$B$15="",0,IF(N14="",0,IF(ISNUMBER(N14),N14,1))) | AP14: =IF(Setup!$B$16="",0,IF(O14="",0,IF(ISNUMBER(O14),O14,1))) | AQ14: =IF(Setup!$B$17="",0,IF(P14="",0,IF(ISNUMBER(P14),P14,1))) | AR14: =IF(Setup!$B$18="",0,IF(Q14="",0,IF(ISNUMBER(Q14),Q14,1))) | AS14: =IF(Setup!$B$19="",0,IF(R14="",0,IF(ISNUMBER(R14),R14,1))) | AT14: =IF(Setup!$B$20="",0,IF(S14="",0,IF(ISNUMBER(S14),S14,1)))
B15: 46277 | C15: Surf lesson | D15: Activities | E15: 90 | F15: EUR | G15: Ben | I15: x | K15: x | T15: =IF(N(E15)=0,"",E15*IF(F15="",1,IFERROR(INDEX(Setup!$E$9:$E$18,MATCH(F15,Setup!$D$9:$D$18,0)),0))) | U15: =IF(T15="","",IF(V15=0,"Everyone",IF(COUNTIF(AI15:AT15,">0")=COUNTIF(Setup!$B$9:$B$20,"?*"),"Everyone",COUNTIF(AI15:AT15,">0")&IF(COUNTIF(AI15:AT15,">0")=1," person"," people")))) | V15: =SUM(AI15:AT15) | W15: =IF(OR(T15="",Setup!$B$9=""),0,IF(V15=0,T15/COUNTIF(Setup!$B$9:$B$20,"?*"),T15*AI15/V15)) | X15: =IF(OR(T15="",Setup!$B$10=""),0,IF(V15=0,T15/COUNTIF(Setup!$B$9:$B$20,"?*"),T15*AJ15/V15)) | Y15: =IF(OR(T15="",Setup!$B$11=""),0,IF(V15=0,T15/COUNTIF(Setup!$B$9:$B$20,"?*"),T15*AK15/V15)) | Z15: =IF(OR(T15="",Setup!$B$12=""),0,IF(V15=0,T15/COUNTIF(Setup!$B$9:$B$20,"?*"),T15*AL15/V15)) | AA15: =IF(OR(T15="",Setup!$B$13=""),0,IF(V15=0,T15/COUNTIF(Setup!$B$9:$B$20,"?*"),T15*AM15/V15)) | AB15: =IF(OR(T15="",Setup!$B$14=""),0,IF(V15=0,T15/COUNTIF(Setup!$B$9:$B$20,"?*"),T15*AN15/V15)) | AC15: =IF(OR(T15="",Setup!$B$15=""),0,IF(V15=0,T15/COUNTIF(Setup!$B$9:$B$20,"?*"),T15*AO15/V15)) | AD15: =IF(OR(T15="",Setup!$B$16=""),0,IF(V15=0,T15/COUNTIF(Setup!$B$9:$B$20,"?*"),T15*AP15/V15)) | AE15: =IF(OR(T15="",Setup!$B$17=""),0,IF(V15=0,T15/COUNTIF(Setup!$B$9:$B$20,"?*"),T15*AQ15/V15)) | AF15: =IF(OR(T15="",Setup!$B$18=""),0,IF(V15=0,T15/COUNTIF(Setup!$B$9:$B$20,"?*"),T15*AR15/V15)) | AG15: =IF(OR(T15="",Setup!$B$19=""),0,IF(V15=0,T15/COUNTIF(Setup!$B$9:$B$20,"?*"),T15*AS15/V15)) | AH15: =IF(OR(T15="",Setup!$B$20=""),0,IF(V15=0,T15/COUNTIF(Setup!$B$9:$B$20,"?*"),T15*AT15/V15)) | AI15: =IF(Setup!$B$9="",0,IF(H15="",0,IF(ISNUMBER(H15),H15,1))) | AJ15: =IF(Setup!$B$10="",0,IF(I15="",0,IF(ISNUMBER(I15),I15,1))) | AK15: =IF(Setup!$B$11="",0,IF(J15="",0,IF(ISNUMBER(J15),J15,1))) | AL15: =IF(Setup!$B$12="",0,IF(K15="",0,IF(ISNUMBER(K15),K15,1))) | AM15: =IF(Setup!$B$13="",0,IF(L15="",0,IF(ISNUMBER(L15),L15,1))) | AN15: =IF(Setup!$B$14="",0,IF(M15="",0,IF(ISNUMBER(M15),M15,1))) | AO15: =IF(Setup!$B$15="",0,IF(N15="",0,IF(ISNUMBER(N15),N15,1))) | AP15: =IF(Setup!$B$16="",0,IF(O15="",0,IF(ISNUMBER(O15),O15,1))) | AQ15: =IF(Setup!$B$17="",0,IF(P15="",0,IF(ISNUMBER(P15),P15,1))) | AR15: =IF(Setup!$B$18="",0,IF(Q15="",0,IF(ISNUMBER(Q15),Q15,1))) | AS15: =IF(Setup!$B$19="",0,IF(R15="",0,IF(ISNUMBER(R15),R15,1))) | AT15: =IF(Setup!$B$20="",0,IF(S15="",0,IF(ISNUMBER(S15),S15,1)))
B16: 46277 | C16: Pastries in Belem | D16: Food | E16: 21.6 | F16: EUR | G16: Emma | T16: =IF(N(E16)=0,"",E16*IF(F16="",1,IFERROR(INDEX(Setup!$E$9:$E$18,MATCH(F16,Setup!$D$9:$D$18,0)),0))) | U16: =IF(T16="","",IF(V16=0,"Everyone",IF(COUNTIF(AI16:AT16,">0")=COUNTIF(Setup!$B$9:$B$20,"?*"),"Everyone",COUNTIF(AI16:AT16,">0")&IF(COUNTIF(AI16:AT16,">0")=1," person"," people")))) | V16: =SUM(AI16:AT16) | W16: =IF(OR(T16="",Setup!$B$9=""),0,IF(V16=0,T16/COUNTIF(Setup!$B$9:$B$20,"?*"),T16*AI16/V16)) | X16: =IF(OR(T16="",Setup!$B$10=""),0,IF(V16=0,T16/COUNTIF(Setup!$B$9:$B$20,"?*"),T16*AJ16/V16)) | Y16: =IF(OR(T16="",Setup!$B$11=""),0,IF(V16=0,T16/COUNTIF(Setup!$B$9:$B$20,"?*"),T16*AK16/V16)) | Z16: =IF(OR(T16="",Setup!$B$12=""),0,IF(V16=0,T16/COUNTIF(Setup!$B$9:$B$20,"?*"),T16*AL16/V16)) | AA16: =IF(OR(T16="",Setup!$B$13=""),0,IF(V16=0,T16/COUNTIF(Setup!$B$9:$B$20,"?*"),T16*AM16/V16)) | AB16: =IF(OR(T16="",Setup!$B$14=""),0,IF(V16=0,T16/COUNTIF(Setup!$B$9:$B$20,"?*"),T16*AN16/V16)) | AC16: =IF(OR(T16="",Setup!$B$15=""),0,IF(V16=0,T16/COUNTIF(Setup!$B$9:$B$20,"?*"),T16*AO16/V16)) | AD16: =IF(OR(T16="",Setup!$B$16=""),0,IF(V16=0,T16/COUNTIF(Setup!$B$9:$B$20,"?*"),T16*AP16/V16)) | AE16: =IF(OR(T16="",Setup!$B$17=""),0,IF(V16=0,T16/COUNTIF(Setup!$B$9:$B$20,"?*"),T16*AQ16/V16)) | AF16: =IF(OR(T16="",Setup!$B$18=""),0,IF(V16=0,T16/COUNTIF(Setup!$B$9:$B$20,"?*"),T16*AR16/V16)) | AG16: =IF(OR(T16="",Setup!$B$19=""),0,IF(V16=0,T16/COUNTIF(Setup!$B$9:$B$20,"?*"),T16*AS16/V16)) | AH16: =IF(OR(T16="",Setup!$B$20=""),0,IF(V16=0,T16/COUNTIF(Setup!$B$9:$B$20,"?*"),T16*AT16/V16)) | AI16: =IF(Setup!$B$9="",0,IF(H16="",0,IF(ISNUMBER(H16),H16,1))) | AJ16: =IF(Setup!$B$10="",0,IF(I16="",0,IF(ISNUMBER(I16),I16,1))) | AK16: =IF(Setup!$B$11="",0,IF(J16="",0,IF(ISNUMBER(J16),J16,1))) | AL16: =IF(Setup!$B$12="",0,IF(K16="",0,IF(ISNUMBER(K16),K16,1))) | AM16: =IF(Setup!$B$13="",0,IF(L16="",0,IF(ISNUMBER(L16),L16,1))) | AN16: =IF(Setup!$B$14="",0,IF(M16="",0,IF(ISNUMBER(M16),M16,1))) | AO16: =IF(Setup!$B$15="",0,IF(N16="",0,IF(ISNUMBER(N16),N16,1))) | AP16: =IF(Setup!$B$16="",0,IF(O16="",0,IF(ISNUMBER(O16),O16,1))) | AQ16: =IF(Setup!$B$17="",0,IF(P16="",0,IF(ISNUMBER(P16),P16,1))) | AR16: =IF(Setup!$B$18="",0,IF(Q16="",0,IF(ISNUMBER(Q16),Q16,1))) | AS16: =IF(Setup!$B$19="",0,IF(R16="",0,IF(ISNUMBER(R16),R16,1))) | AT16: =IF(Setup!$B$20="",0,IF(S16="",0,IF(ISNUMBER(S16),S16,1)))
B17: 46277 | C17: Dinner | D17: Food | E17: 128 | F17: EUR | G17: Ana | T17: =IF(N(E17)=0,"",E17*IF(F17="",1,IFERROR(INDEX(Setup!$E$9:$E$18,MATCH(F17,Setup!$D$9:$D$18,0)),0))) | U17: =IF(T17="","",IF(V17=0,"Everyone",IF(COUNTIF(AI17:AT17,">0")=COUNTIF(Setup!$B$9:$B$20,"?*"),"Everyone",COUNTIF(AI17:AT17,">0")&IF(COUNTIF(AI17:AT17,">0")=1," person"," people")))) | V17: =SUM(AI17:AT17) | W17: =IF(OR(T17="",Setup!$B$9=""),0,IF(V17=0,T17/COUNTIF(Setup!$B$9:$B$20,"?*"),T17*AI17/V17)) | X17: =IF(OR(T17="",Setup!$B$10=""),0,IF(V17=0,T17/COUNTIF(Setup!$B$9:$B$20,"?*"),T17*AJ17/V17)) | Y17: =IF(OR(T17="",Setup!$B$11=""),0,IF(V17=0,T17/COUNTIF(Setup!$B$9:$B$20,"?*"),T17*AK17/V17)) | Z17: =IF(OR(T17="",Setup!$B$12=""),0,IF(V17=0,T17/COUNTIF(Setup!$B$9:$B$20,"?*"),T17*AL17/V17)) | AA17: =IF(OR(T17="",Setup!$B$13=""),0,IF(V17=0,T17/COUNTIF(Setup!$B$9:$B$20,"?*"),T17*AM17/V17)) | AB17: =IF(OR(T17="",Setup!$B$14=""),0,IF(V17=0,T17/COUNTIF(Setup!$B$9:$B$20,"?*"),T17*AN17/V17)) | AC17: =IF(OR(T17="",Setup!$B$15=""),0,IF(V17=0,T17/COUNTIF(Setup!$B$9:$B$20,"?*"),T17*AO17/V17)) | AD17: =IF(OR(T17="",Setup!$B$16=""),0,IF(V17=0,T17/COUNTIF(Setup!$B$9:$B$20,"?*"),T17*AP17/V17)) | AE17: =IF(OR(T17="",Setup!$B$17=""),0,IF(V17=0,T17/COUNTIF(Setup!$B$9:$B$20,"?*"),T17*AQ17/V17)) | AF17: =IF(OR(T17="",Setup!$B$18=""),0,IF(V17=0,T17/COUNTIF(Setup!$B$9:$B$20,"?*"),T17*AR17/V17)) | AG17: =IF(OR(T17="",Setup!$B$19=""),0,IF(V17=0,T17/COUNTIF(Setup!$B$9:$B$20,"?*"),T17*AS17/V17)) | AH17: =IF(OR(T17="",Setup!$B$20=""),0,IF(V17=0,T17/COUNTIF(Setup!$B$9:$B$20,"?*"),T17*AT17/V17)) | AI17: =IF(Setup!$B$9="",0,IF(H17="",0,IF(ISNUMBER(H17),H17,1))) | AJ17: =IF(Setup!$B$10="",0,IF(I17="",0,IF(ISNUMBER(I17),I17,1))) | AK17: =IF(Setup!$B$11="",0,IF(J17="",0,IF(ISNUMBER(J17),J17,1))) | AL17: =IF(Setup!$B$12="",0,IF(K17="",0,IF(ISNUMBER(K17),K17,1))) | AM17: =IF(Setup!$B$13="",0,IF(L17="",0,IF(ISNUMBER(L17),L17,1))) | AN17: =IF(Setup!$B$14="",0,IF(M17="",0,IF(ISNUMBER(M17),M17,1))) | AO17: =IF(Setup!$B$15="",0,IF(N17="",0,IF(ISNUMBER(N17),N17,1))) | AP17: =IF(Setup!$B$16="",0,IF(O17="",0,IF(ISNUMBER(O17),O17,1))) | AQ17: =IF(Setup!$B$17="",0,IF(P17="",0,IF(ISNUMBER(P17),P17,1))) | AR17: =IF(Setup!$B$18="",0,IF(Q17="",0,IF(ISNUMBER(Q17),Q17,1))) | AS17: =IF(Setup!$B$19="",0,IF(R17="",0,IF(ISNUMBER(R17),R17,1))) | AT17: =IF(Setup!$B$20="",0,IF(S17="",0,IF(ISNUMBER(S17),S17,1)))
B18: 46277 | C18: Ana pays Ben back | D18: Paying back | E18: 100 | F18: EUR | G18: Ana | I18: x | T18: =IF(N(E18)=0,"",E18*IF(F18="",1,IFERROR(INDEX(Setup!$E$9:$E$18,MATCH(F18,Setup!$D$9:$D$18,0)),0))) | U18: =IF(T18="","",IF(V18=0,"Everyone",IF(COUNTIF(AI18:AT18,">0")=COUNTIF(Setup!$B$9:$B$20,"?*"),"Everyone",COUNTIF(AI18:AT18,">0")&IF(COUNTIF(AI18:AT18,">0")=1," person"," people")))) | V18: =SUM(AI18:AT18) | W18: =IF(OR(T18="",Setup!$B$9=""),0,IF(V18=0,T18/COUNTIF(Setup!$B$9:$B$20,"?*"),T18*AI18/V18)) | X18: =IF(OR(T18="",Setup!$B$10=""),0,IF(V18=0,T18/COUNTIF(Setup!$B$9:$B$20,"?*"),T18*AJ18/V18)) | Y18: =IF(OR(T18="",Setup!$B$11=""),0,IF(V18=0,T18/COUNTIF(Setup!$B$9:$B$20,"?*"),T18*AK18/V18)) | Z18: =IF(OR(T18="",Setup!$B$12=""),0,IF(V18=0,T18/COUNTIF(Setup!$B$9:$B$20,"?*"),T18*AL18/V18)) | AA18: =IF(OR(T18="",Setup!$B$13=""),0,IF(V18=0,T18/COUNTIF(Setup!$B$9:$B$20,"?*"),T18*AM18/V18)) | AB18: =IF(OR(T18="",Setup!$B$14=""),0,IF(V18=0,T18/COUNTIF(Setup!$B$9:$B$20,"?*"),T18*AN18/V18)) | AC18: =IF(OR(T18="",Setup!$B$15=""),0,IF(V18=0,T18/COUNTIF(Setup!$B$9:$B$20,"?*"),T18*AO18/V18)) | AD18: =IF(OR(T18="",Setup!$B$16=""),0,IF(V18=0,T18/COUNTIF(Setup!$B$9:$B$20,"?*"),T18*AP18/V18)) | AE18: =IF(OR(T18="",Setup!$B$17=""),0,IF(V18=0,T18/COUNTIF(Setup!$B$9:$B$20,"?*"),T18*AQ18/V18)) | AF18: =IF(OR(T18="",Setup!$B$18=""),0,IF(V18=0,T18/COUNTIF(Setup!$B$9:$B$20,"?*"),T18*AR18/V18)) | AG18: =IF(OR(T18="",Setup!$B$19=""),0,IF(V18=0,T18/COUNTIF(Setup!$B$9:$B$20,"?*"),T18*AS18/V18)) | AH18: =IF(OR(T18="",Setup!$B$20=""),0,IF(V18=0,T18/COUNTIF(Setup!$B$9:$B$20,"?*"),T18*AT18/V18)) | AI18: =IF(Setup!$B$9="",0,IF(H18="",0,IF(ISNUMBER(H18),H18,1))) | AJ18: =IF(Setup!$B$10="",0,IF(I18="",0,IF(ISNUMBER(I18),I18,1))) | AK18: =IF(Setup!$B$11="",0,IF(J18="",0,IF(ISNUMBER(J18),J18,1))) | AL18: =IF(Setup!$B$12="",0,IF(K18="",0,IF(ISNUMBER(K18),K18,1))) | AM18: =IF(Setup!$B$13="",0,IF(L18="",0,IF(ISNUMBER(L18),L18,1))) | AN18: =IF(Setup!$B$14="",0,IF(M18="",0,IF(ISNUMBER(M18),M18,1))) | AO18: =IF(Setup!$B$15="",0,IF(N18="",0,IF(ISNUMBER(N18),N18,1))) | AP18: =IF(Setup!$B$16="",0,IF(O18="",0,IF(ISNUMBER(O18),O18,1))) | AQ18: =IF(Setup!$B$17="",0,IF(P18="",0,IF(ISNUMBER(P18),P18,1))) | AR18: =IF(Setup!$B$18="",0,IF(Q18="",0,IF(ISNUMBER(Q18),Q18,1))) | AS18: =IF(Setup!$B$19="",0,IF(R18="",0,IF(ISNUMBER(R18),R18,1))) | AT18: =IF(Setup!$B$20="",0,IF(S18="",0,IF(ISNUMBER(S18),S18,1)))
B19: 46278 | C19: Train to Porto | D19: Transport | E19: 125 | F19: EUR | G19: Dev | T19: =IF(N(E19)=0,"",E19*IF(F19="",1,IFERROR(INDEX(Setup!$E$9:$E$18,MATCH(F19,Setup!$D$9:$D$18,0)),0))) | U19: =IF(T19="","",IF(V19=0,"Everyone",IF(COUNTIF(AI19:AT19,">0")=COUNTIF(Setup!$B$9:$B$20,"?*"),"Everyone",COUNTIF(AI19:AT19,">0")&IF(COUNTIF(AI19:AT19,">0")=1," person"," people")))) | V19: =SUM(AI19:AT19) | W19: =IF(OR(T19="",Setup!$B$9=""),0,IF(V19=0,T19/COUNTIF(Setup!$B$9:$B$20,"?*"),T19*AI19/V19)) | X19: =IF(OR(T19="",Setup!$B$10=""),0,IF(V19=0,T19/COUNTIF(Setup!$B$9:$B$20,"?*"),T19*AJ19/V19)) | Y19: =IF(OR(T19="",Setup!$B$11=""),0,IF(V19=0,T19/COUNTIF(Setup!$B$9:$B$20,"?*"),T19*AK19/V19)) | Z19: =IF(OR(T19="",Setup!$B$12=""),0,IF(V19=0,T19/COUNTIF(Setup!$B$9:$B$20,"?*"),T19*AL19/V19)) | AA19: =IF(OR(T19="",Setup!$B$13=""),0,IF(V19=0,T19/COUNTIF(Setup!$B$9:$B$20,"?*"),T19*AM19/V19)) | AB19: =IF(OR(T19="",Setup!$B$14=""),0,IF(V19=0,T19/COUNTIF(Setup!$B$9:$B$20,"?*"),T19*AN19/V19)) | AC19: =IF(OR(T19="",Setup!$B$15=""),0,IF(V19=0,T19/COUNTIF(Setup!$B$9:$B$20,"?*"),T19*AO19/V19)) | AD19: =IF(OR(T19="",Setup!$B$16=""),0,IF(V19=0,T19/COUNTIF(Setup!$B$9:$B$20,"?*"),T19*AP19/V19)) | AE19: =IF(OR(T19="",Setup!$B$17=""),0,IF(V19=0,T19/COUNTIF(Setup!$B$9:$B$20,"?*"),T19*AQ19/V19)) | AF19: =IF(OR(T19="",Setup!$B$18=""),0,IF(V19=0,T19/COUNTIF(Setup!$B$9:$B$20,"?*"),T19*AR19/V19)) | AG19: =IF(OR(T19="",Setup!$B$19=""),0,IF(V19=0,T19/COUNTIF(Setup!$B$9:$B$20,"?*"),T19*AS19/V19)) | AH19: =IF(OR(T19="",Setup!$B$20=""),0,IF(V19=0,T19/COUNTIF(Setup!$B$9:$B$20,"?*"),T19*AT19/V19)) | AI19: =IF(Setup!$B$9="",0,IF(H19="",0,IF(ISNUMBER(H19),H19,1))) | AJ19: =IF(Setup!$B$10="",0,IF(I19="",0,IF(ISNUMBER(I19),I19,1))) | AK19: =IF(Setup!$B$11="",0,IF(J19="",0,IF(ISNUMBER(J19),J19,1))) | AL19: =IF(Setup!$B$12="",0,IF(K19="",0,IF(ISNUMBER(K19),K19,1))) | AM19: =IF(Setup!$B$13="",0,IF(L19="",0,IF(ISNUMBER(L19),L19,1))) | AN19: =IF(Setup!$B$14="",0,IF(M19="",0,IF(ISNUMBER(M19),M19,1))) | AO19: =IF(Setup!$B$15="",0,IF(N19="",0,IF(ISNUMBER(N19),N19,1))) | AP19: =IF(Setup!$B$16="",0,IF(O19="",0,IF(ISNUMBER(O19),O19,1))) | AQ19: =IF(Setup!$B$17="",0,IF(P19="",0,IF(ISNUMBER(P19),P19,1))) | AR19: =IF(Setup!$B$18="",0,IF(Q19="",0,IF(ISNUMBER(Q19),Q19,1))) | AS19: =IF(Setup!$B$19="",0,IF(R19="",0,IF(ISNUMBER(R19),R19,1))) | AT19: =IF(Setup!$B$20="",0,IF(S19="",0,IF(ISNUMBER(S19),S19,1)))
B20: 46278 | C20: Hotel in Porto, 3 nights | D20: Lodging | E20: 540 | F20: EUR | G20: Chloe | T20: =IF(N(E20)=0,"",E20*IF(F20="",1,IFERROR(INDEX(Setup!$E$9:$E$18,MATCH(F20,Setup!$D$9:$D$18,0)),0))) | U20: =IF(T20="","",IF(V20=0,"Everyone",IF(COUNTIF(AI20:AT20,">0")=COUNTIF(Setup!$B$9:$B$20,"?*"),"Everyone",COUNTIF(AI20:AT20,">0")&IF(COUNTIF(AI20:AT20,">0")=1," person"," people")))) | V20: =SUM(AI20:AT20) | W20: =IF(OR(T20="",Setup!$B$9=""),0,IF(V20=0,T20/COUNTIF(Setup!$B$9:$B$20,"?*"),T20*AI20/V20)) | X20: =IF(OR(T20="",Setup!$B$10=""),0,IF(V20=0,T20/COUNTIF(Setup!$B$9:$B$20,"?*"),T20*AJ20/V20)) | Y20: =IF(OR(T20="",Setup!$B$11=""),0,IF(V20=0,T20/COUNTIF(Setup!$B$9:$B$20,"?*"),T20*AK20/V20)) | Z20: =IF(OR(T20="",Setup!$B$12=""),0,IF(V20=0,T20/COUNTIF(Setup!$B$9:$B$20,"?*"),T20*AL20/V20)) | AA20: =IF(OR(T20="",Setup!$B$13=""),0,IF(V20=0,T20/COUNTIF(Setup!$B$9:$B$20,"?*"),T20*AM20/V20)) | AB20: =IF(OR(T20="",Setup!$B$14=""),0,IF(V20=0,T20/COUNTIF(Setup!$B$9:$B$20,"?*"),T20*AN20/V20)) | AC20: =IF(OR(T20="",Setup!$B$15=""),0,IF(V20=0,T20/COUNTIF(Setup!$B$9:$B$20,"?*"),T20*AO20/V20)) | AD20: =IF(OR(T20="",Setup!$B$16=""),0,IF(V20=0,T20/COUNTIF(Setup!$B$9:$B$20,"?*"),T20*AP20/V20)) | AE20: =IF(OR(T20="",Setup!$B$17=""),0,IF(V20=0,T20/COUNTIF(Setup!$B$9:$B$20,"?*"),T20*AQ20/V20)) | AF20: =IF(OR(T20="",Setup!$B$18=""),0,IF(V20=0,T20/COUNTIF(Setup!$B$9:$B$20,"?*"),T20*AR20/V20)) | AG20: =IF(OR(T20="",Setup!$B$19=""),0,IF(V20=0,T20/COUNTIF(Setup!$B$9:$B$20,"?*"),T20*AS20/V20)) | AH20: =IF(OR(T20="",Setup!$B$20=""),0,IF(V20=0,T20/COUNTIF(Setup!$B$9:$B$20,"?*"),T20*AT20/V20)) | AI20: =IF(Setup!$B$9="",0,IF(H20="",0,IF(ISNUMBER(H20),H20,1))) | AJ20: =IF(Setup!$B$10="",0,IF(I20="",0,IF(ISNUMBER(I20),I20,1))) | AK20: =IF(Setup!$B$11="",0,IF(J20="",0,IF(ISNUMBER(J20),J20,1))) | AL20: =IF(Setup!$B$12="",0,IF(K20="",0,IF(ISNUMBER(K20),K20,1))) | AM20: =IF(Setup!$B$13="",0,IF(L20="",0,IF(ISNUMBER(L20),L20,1))) | AN20: =IF(Setup!$B$14="",0,IF(M20="",0,IF(ISNUMBER(M20),M20,1))) | AO20: =IF(Setup!$B$15="",0,IF(N20="",0,IF(ISNUMBER(N20),N20,1))) | AP20: =IF(Setup!$B$16="",0,IF(O20="",0,IF(ISNUMBER(O20),O20,1))) | AQ20: =IF(Setup!$B$17="",0,IF(P20="",0,IF(ISNUMBER(P20),P20,1))) | AR20: =IF(Setup!$B$18="",0,IF(Q20="",0,IF(ISNUMBER(Q20),Q20,1))) | AS20: =IF(Setup!$B$19="",0,IF(R20="",0,IF(ISNUMBER(R20),R20,1))) | AT20: =IF(Setup!$B$20="",0,IF(S20="",0,IF(ISNUMBER(S20),S20,1)))
B21: 46278 | C21: Dinner by the river | D21: Food | E21: 154 | F21: EUR | G21: Emma | T21: =IF(N(E21)=0,"",E21*IF(F21="",1,IFERROR(INDEX(Setup!$E$9:$E$18,MATCH(F21,Setup!$D$9:$D$18,0)),0))) | U21: =IF(T21="","",IF(V21=0,"Everyone",IF(COUNTIF(AI21:AT21,">0")=COUNTIF(Setup!$B$9:$B$20,"?*"),"Everyone",COUNTIF(AI21:AT21,">0")&IF(COUNTIF(AI21:AT21,">0")=1," person"," people")))) | V21: =SUM(AI21:AT21) | W21: =IF(OR(T21="",Setup!$B$9=""),0,IF(V21=0,T21/COUNTIF(Setup!$B$9:$B$20,"?*"),T21*AI21/V21)) | X21: =IF(OR(T21="",Setup!$B$10=""),0,IF(V21=0,T21/COUNTIF(Setup!$B$9:$B$20,"?*"),T21*AJ21/V21)) | Y21: =IF(OR(T21="",Setup!$B$11=""),0,IF(V21=0,T21/COUNTIF(Setup!$B$9:$B$20,"?*"),T21*AK21/V21)) | Z21: =IF(OR(T21="",Setup!$B$12=""),0,IF(V21=0,T21/COUNTIF(Setup!$B$9:$B$20,"?*"),T21*AL21/V21)) | AA21: =IF(OR(T21="",Setup!$B$13=""),0,IF(V21=0,T21/COUNTIF(Setup!$B$9:$B$20,"?*"),T21*AM21/V21)) | AB21: =IF(OR(T21="",Setup!$B$14=""),0,IF(V21=0,T21/COUNTIF(Setup!$B$9:$B$20,"?*"),T21*AN21/V21)) | AC21: =IF(OR(T21="",Setup!$B$15=""),0,IF(V21=0,T21/COUNTIF(Setup!$B$9:$B$20,"?*"),T21*AO21/V21)) | AD21: =IF(OR(T21="",Setup!$B$16=""),0,IF(V21=0,T21/COUNTIF(Setup!$B$9:$B$20,"?*"),T21*AP21/V21)) | AE21: =IF(OR(T21="",Setup!$B$17=""),0,IF(V21=0,T21/COUNTIF(Setup!$B$9:$B$20,"?*"),T21*AQ21/V21)) | AF21: =IF(OR(T21="",Setup!$B$18=""),0,IF(V21=0,T21/COUNTIF(Setup!$B$9:$B$20,"?*"),T21*AR21/V21)) | AG21: =IF(OR(T21="",Setup!$B$19=""),0,IF(V21=0,T21/COUNTIF(Setup!$B$9:$B$20,"?*"),T21*AS21/V21)) | AH21: =IF(OR(T21="",Setup!$B$20=""),0,IF(V21=0,T21/COUNTIF(Setup!$B$9:$B$20,"?*"),T21*AT21/V21)) | AI21: =IF(Setup!$B$9="",0,IF(H21="",0,IF(ISNUMBER(H21),H21,1))) | AJ21: =IF(Setup!$B$10="",0,IF(I21="",0,IF(ISNUMBER(I21),I21,1))) | AK21: =IF(Setup!$B$11="",0,IF(J21="",0,IF(ISNUMBER(J21),J21,1))) | AL21: =IF(Setup!$B$12="",0,IF(K21="",0,IF(ISNUMBER(K21),K21,1))) | AM21: =IF(Setup!$B$13="",0,IF(L21="",0,IF(ISNUMBER(L21),L21,1))) | AN21: =IF(Setup!$B$14="",0,IF(M21="",0,IF(ISNUMBER(M21),M21,1))) | AO21: =IF(Setup!$B$15="",0,IF(N21="",0,IF(ISNUMBER(N21),N21,1))) | AP21: =IF(Setup!$B$16="",0,IF(O21="",0,IF(ISNUMBER(O21),O21,1))) | AQ21: =IF(Setup!$B$17="",0,IF(P21="",0,IF(ISNUMBER(P21),P21,1))) | AR21: =IF(Setup!$B$18="",0,IF(Q21="",0,IF(ISNUMBER(Q21),Q21,1))) | AS21: =IF(Setup!$B$19="",0,IF(R21="",0,IF(ISNUMBER(R21),R21,1))) | AT21: =IF(Setup!$B$20="",0,IF(S21="",0,IF(ISNUMBER(S21),S21,1)))
B22: 46279 | C22: Port wine tasting | D22: Activities | E22: 75 | F22: EUR | G22: Ben | T22: =IF(N(E22)=0,"",E22*IF(F22="",1,IFERROR(INDEX(Setup!$E$9:$E$18,MATCH(F22,Setup!$D$9:$D$18,0)),0))) | U22: =IF(T22="","",IF(V22=0,"Everyone",IF(COUNTIF(AI22:AT22,">0")=COUNTIF(Setup!$B$9:$B$20,"?*"),"Everyone",COUNTIF(AI22:AT22,">0")&IF(COUNTIF(AI22:AT22,">0")=1," person"," people")))) | V22: =SUM(AI22:AT22) | W22: =IF(OR(T22="",Setup!$B$9=""),0,IF(V22=0,T22/COUNTIF(Setup!$B$9:$B$20,"?*"),T22*AI22/V22)) | X22: =IF(OR(T22="",Setup!$B$10=""),0,IF(V22=0,T22/COUNTIF(Setup!$B$9:$B$20,"?*"),T22*AJ22/V22)) | Y22: =IF(OR(T22="",Setup!$B$11=""),0,IF(V22=0,T22/COUNTIF(Setup!$B$9:$B$20,"?*"),T22*AK22/V22)) | Z22: =IF(OR(T22="",Setup!$B$12=""),0,IF(V22=0,T22/COUNTIF(Setup!$B$9:$B$20,"?*"),T22*AL22/V22)) | AA22: =IF(OR(T22="",Setup!$B$13=""),0,IF(V22=0,T22/COUNTIF(Setup!$B$9:$B$20,"?*"),T22*AM22/V22)) | AB22: =IF(OR(T22="",Setup!$B$14=""),0,IF(V22=0,T22/COUNTIF(Setup!$B$9:$B$20,"?*"),T22*AN22/V22)) | AC22: =IF(OR(T22="",Setup!$B$15=""),0,IF(V22=0,T22/COUNTIF(Setup!$B$9:$B$20,"?*"),T22*AO22/V22)) | AD22: =IF(OR(T22="",Setup!$B$16=""),0,IF(V22=0,T22/COUNTIF(Setup!$B$9:$B$20,"?*"),T22*AP22/V22)) | AE22: =IF(OR(T22="",Setup!$B$17=""),0,IF(V22=0,T22/COUNTIF(Setup!$B$9:$B$20,"?*"),T22*AQ22/V22)) | AF22: =IF(OR(T22="",Setup!$B$18=""),0,IF(V22=0,T22/COUNTIF(Setup!$B$9:$B$20,"?*"),T22*AR22/V22)) | AG22: =IF(OR(T22="",Setup!$B$19=""),0,IF(V22=0,T22/COUNTIF(Setup!$B$9:$B$20,"?*"),T22*AS22/V22)) | AH22: =IF(OR(T22="",Setup!$B$20=""),0,IF(V22=0,T22/COUNTIF(Setup!$B$9:$B$20,"?*"),T22*AT22/V22)) | AI22: =IF(Setup!$B$9="",0,IF(H22="",0,IF(ISNUMBER(H22),H22,1))) | AJ22: =IF(Setup!$B$10="",0,IF(I22="",0,IF(ISNUMBER(I22),I22,1))) | AK22: =IF(Setup!$B$11="",0,IF(J22="",0,IF(ISNUMBER(J22),J22,1))) | AL22: =IF(Setup!$B$12="",0,IF(K22="",0,IF(ISNUMBER(K22),K22,1))) | AM22: =IF(Setup!$B$13="",0,IF(L22="",0,IF(ISNUMBER(L22),L22,1))) | AN22: =IF(Setup!$B$14="",0,IF(M22="",0,IF(ISNUMBER(M22),M22,1))) | AO22: =IF(Setup!$B$15="",0,IF(N22="",0,IF(ISNUMBER(N22),N22,1))) | AP22: =IF(Setup!$B$16="",0,IF(O22="",0,IF(ISNUMBER(O22),O22,1))) | AQ22: =IF(Setup!$B$17="",0,IF(P22="",0,IF(ISNUMBER(P22),P22,1))) | AR22: =IF(Setup!$B$18="",0,IF(Q22="",0,IF(ISNUMBER(Q22),Q22,1))) | AS22: =IF(Setup!$B$19="",0,IF(R22="",0,IF(ISNUMBER(R22),R22,1))) | AT22: =IF(Setup!$B$20="",0,IF(S22="",0,IF(ISNUMBER(S22),S22,1)))
B23: 46279 | C23: Wine to take home | D23: Other | E23: 72 | F23: EUR | G23: Chloe | H23: 2 | J23: 1 | L23: 1 | T23: =IF(N(E23)=0,"",E23*IF(F23="",1,IFERROR(INDEX(Setup!$E$9:$E$18,MATCH(F23,Setup!$D$9:$D$18,0)),0))) | U23: =IF(T23="","",IF(V23=0,"Everyone",IF(COUNTIF(AI23:AT23,">0")=COUNTIF(Setup!$B$9:$B$20,"?*"),"Everyone",COUNTIF(AI23:AT23,">0")&IF(COUNTIF(AI23:AT23,">0")=1," person"," people")))) | V23: =SUM(AI23:AT23) | W23: =IF(OR(T23="",Setup!$B$9=""),0,IF(V23=0,T23/COUNTIF(Setup!$B$9:$B$20,"?*"),T23*AI23/V23)) | X23: =IF(OR(T23="",Setup!$B$10=""),0,IF(V23=0,T23/COUNTIF(Setup!$B$9:$B$20,"?*"),T23*AJ23/V23)) | Y23: =IF(OR(T23="",Setup!$B$11=""),0,IF(V23=0,T23/COUNTIF(Setup!$B$9:$B$20,"?*"),T23*AK23/V23)) | Z23: =IF(OR(T23="",Setup!$B$12=""),0,IF(V23=0,T23/COUNTIF(Setup!$B$9:$B$20,"?*"),T23*AL23/V23)) | AA23: =IF(OR(T23="",Setup!$B$13=""),0,IF(V23=0,T23/COUNTIF(Setup!$B$9:$B$20,"?*"),T23*AM23/V23)) | AB23: =IF(OR(T23="",Setup!$B$14=""),0,IF(V23=0,T23/COUNTIF(Setup!$B$9:$B$20,"?*"),T23*AN23/V23)) | AC23: =IF(OR(T23="",Setup!$B$15=""),0,IF(V23=0,T23/COUNTIF(Setup!$B$9:$B$20,"?*"),T23*AO23/V23)) | AD23: =IF(OR(T23="",Setup!$B$16=""),0,IF(V23=0,T23/COUNTIF(Setup!$B$9:$B$20,"?*"),T23*AP23/V23)) | AE23: =IF(OR(T23="",Setup!$B$17=""),0,IF(V23=0,T23/COUNTIF(Setup!$B$9:$B$20,"?*"),T23*AQ23/V23)) | AF23: =IF(OR(T23="",Setup!$B$18=""),0,IF(V23=0,T23/COUNTIF(Setup!$B$9:$B$20,"?*"),T23*AR23/V23)) | AG23: =IF(OR(T23="",Setup!$B$19=""),0,IF(V23=0,T23/COUNTIF(Setup!$B$9:$B$20,"?*"),T23*AS23/V23)) | AH23: =IF(OR(T23="",Setup!$B$20=""),0,IF(V23=0,T23/COUNTIF(Setup!$B$9:$B$20,"?*"),T23*AT23/V23)) | AI23: =IF(Setup!$B$9="",0,IF(H23="",0,IF(ISNUMBER(H23),H23,1))) | AJ23: =IF(Setup!$B$10="",0,IF(I23="",0,IF(ISNUMBER(I23),I23,1))) | AK23: =IF(Setup!$B$11="",0,IF(J23="",0,IF(ISNUMBER(J23),J23,1))) | AL23: =IF(Setup!$B$12="",0,IF(K23="",0,IF(ISNUMBER(K23),K23,1))) | AM23: =IF(Setup!$B$13="",0,IF(L23="",0,IF(ISNUMBER(L23),L23,1))) | AN23: =IF(Setup!$B$14="",0,IF(M23="",0,IF(ISNUMBER(M23),M23,1))) | AO23: =IF(Setup!$B$15="",0,IF(N23="",0,IF(ISNUMBER(N23),N23,1))) | AP23: =IF(Setup!$B$16="",0,IF(O23="",0,IF(ISNUMBER(O23),O23,1))) | AQ23: =IF(Setup!$B$17="",0,IF(P23="",0,IF(ISNUMBER(P23),P23,1))) | AR23: =IF(Setup!$B$18="",0,IF(Q23="",0,IF(ISNUMBER(Q23),Q23,1))) | AS23: =IF(Setup!$B$19="",0,IF(R23="",0,IF(ISNUMBER(R23),R23,1))) | AT23: =IF(Setup!$B$20="",0,IF(S23="",0,IF(ISNUMBER(S23),S23,1)))
B24: 46279 | C24: Bookshop tickets | D24: Activities | E24: 50 | F24: EUR | G24: Emma | T24: =IF(N(E24)=0,"",E24*IF(F24="",1,IFERROR(INDEX(Setup!$E$9:$E$18,MATCH(F24,Setup!$D$9:$D$18,0)),0))) | U24: =IF(T24="","",IF(V24=0,"Everyone",IF(COUNTIF(AI24:AT24,">0")=COUNTIF(Setup!$B$9:$B$20,"?*"),"Everyone",COUNTIF(AI24:AT24,">0")&IF(COUNTIF(AI24:AT24,">0")=1," person"," people")))) | V24: =SUM(AI24:AT24) | W24: =IF(OR(T24="",Setup!$B$9=""),0,IF(V24=0,T24/COUNTIF(Setup!$B$9:$B$20,"?*"),T24*AI24/V24)) | X24: =IF(OR(T24="",Setup!$B$10=""),0,IF(V24=0,T24/COUNTIF(Setup!$B$9:$B$20,"?*"),T24*AJ24/V24)) | Y24: =IF(OR(T24="",Setup!$B$11=""),0,IF(V24=0,T24/COUNTIF(Setup!$B$9:$B$20,"?*"),T24*AK24/V24)) | Z24: =IF(OR(T24="",Setup!$B$12=""),0,IF(V24=0,T24/COUNTIF(Setup!$B$9:$B$20,"?*"),T24*AL24/V24)) | AA24: =IF(OR(T24="",Setup!$B$13=""),0,IF(V24=0,T24/COUNTIF(Setup!$B$9:$B$20,"?*"),T24*AM24/V24)) | AB24: =IF(OR(T24="",Setup!$B$14=""),0,IF(V24=0,T24/COUNTIF(Setup!$B$9:$B$20,"?*"),T24*AN24/V24)) | AC24: =IF(OR(T24="",Setup!$B$15=""),0,IF(V24=0,T24/COUNTIF(Setup!$B$9:$B$20,"?*"),T24*AO24/V24)) | AD24: =IF(OR(T24="",Setup!$B$16=""),0,IF(V24=0,T24/COUNTIF(Setup!$B$9:$B$20,"?*"),T24*AP24/V24)) | AE24: =IF(OR(T24="",Setup!$B$17=""),0,IF(V24=0,T24/COUNTIF(Setup!$B$9:$B$20,"?*"),T24*AQ24/V24)) | AF24: =IF(OR(T24="",Setup!$B$18=""),0,IF(V24=0,T24/COUNTIF(Setup!$B$9:$B$20,"?*"),T24*AR24/V24)) | AG24: =IF(OR(T24="",Setup!$B$19=""),0,IF(V24=0,T24/COUNTIF(Setup!$B$9:$B$20,"?*"),T24*AS24/V24)) | AH24: =IF(OR(T24="",Setup!$B$20=""),0,IF(V24=0,T24/COUNTIF(Setup!$B$9:$B$20,"?*"),T24*AT24/V24)) | AI24: =IF(Setup!$B$9="",0,IF(H24="",0,IF(ISNUMBER(H24),H24,1))) | AJ24: =IF(Setup!$B$10="",0,IF(I24="",0,IF(ISNUMBER(I24),I24,1))) | AK24: =IF(Setup!$B$11="",0,IF(J24="",0,IF(ISNUMBER(J24),J24,1))) | AL24: =IF(Setup!$B$12="",0,IF(K24="",0,IF(ISNUMBER(K24),K24,1))) | AM24: =IF(Setup!$B$13="",0,IF(L24="",0,IF(ISNUMBER(L24),L24,1))) | AN24: =IF(Setup!$B$14="",0,IF(M24="",0,IF(ISNUMBER(M24),M24,1))) | AO24: =IF(Setup!$B$15="",0,IF(N24="",0,IF(ISNUMBER(N24),N24,1))) | AP24: =IF(Setup!$B$16="",0,IF(O24="",0,IF(ISNUMBER(O24),O24,1))) | AQ24: =IF(Setup!$B$17="",0,IF(P24="",0,IF(ISNUMBER(P24),P24,1))) | AR24: =IF(Setup!$B$18="",0,IF(Q24="",0,IF(ISNUMBER(Q24),Q24,1))) | AS24: =IF(Setup!$B$19="",0,IF(R24="",0,IF(ISNUMBER(R24),R24,1))) | AT24: =IF(Setup!$B$20="",0,IF(S24="",0,IF(ISNUMBER(S24),S24,1)))
