Workbook

Sheet Dashboard
B2: Training dashboard
B3: The last 7 days, the last 12 weeks, your new bests and your weight.
B4: Units | C4: lb | E4: Goal weight | F4: 178
B6: Workouts, 7 days | C6: Sets, 7 days | D6: Volume, 7 days | E6: New bests, 30 days | F6: Weight now | G6: Since start | I6: To goal
B7: =COUNTIFS(Log!$V$6:$V$1505,1,Log!$B$6:$B$1505,">"&TODAY()-7,Log!$B$6:$B$1505,"<="&TODAY()) | C7: =SUMIFS(Log!$O$6:$O$1505,Log!$B$6:$B$1505,">"&TODAY()-7,Log!$B$6:$B$1505,"<="&TODAY()) | D7: =SUMIFS(Log!$P$6:$P$1505,Log!$B$6:$B$1505,">"&TODAY()-7,Log!$B$6:$B$1505,"<="&TODAY()) | E7: =COUNTIFS(Log!$S$6:$S$1505,"New best",Log!$B$6:$B$1505,">"&TODAY()-30) | F7: =IFERROR(FIXED(INDEX(Body!$C$6:$C$405,MATCH(MAX(Body!$P$6:$P$405),Body!$P$6:$P$405,0)),1)&" "&$C$4,"") | G7: =IFERROR(FIXED(INDEX(Body!$C$6:$C$405,MATCH(MAX(Body!$P$6:$P$405),Body!$P$6:$P$405,0))-INDEX(Body!$C$6:$C$405,MATCH(MIN(Body!$P$6:$P$405),Body!$P$6:$P$405,0)),1)&" "&$C$4,"") | I7: =IFERROR(IF(N($F$4)=0,"",FIXED(INDEX(Body!$C$6:$C$405,MATCH(MAX(Body!$P$6:$P$405),Body!$P$6:$P$405,0))-$F$4,1)&" "&$C$4),"")
B9: Week of | C9: Workouts | D9: Sets | E9: Volume | I9: Muscle group | J9: Sets, 7 days | K9: Sets, week before
B10: =TODAY()-WEEKDAY(TODAY(),3)-77 | C10: =COUNTIFS(Log!$V$6:$V$1505,1,Log!$W$6:$W$1505,B10) | D10: =SUMIFS(Log!$O$6:$O$1505,Log!$W$6:$W$1505,B10) | E10: =SUMIFS(Log!$P$6:$P$1505,Log!$W$6:$W$1505,B10) | I10: Chest | J10: =SUMIFS(Log!$O$6:$O$1505,Log!$U$6:$U$1505,I10,Log!$B$6:$B$1505,">"&TODAY()-7,Log!$B$6:$B$1505,"<="&TODAY()) | K10: =SUMIFS(Log!$O$6:$O$1505,Log!$U$6:$U$1505,I10,Log!$B$6:$B$1505,">"&TODAY()-14,Log!$B$6:$B$1505,"<="&TODAY()-7) | L10: =IF(N(J10)=0,"",IF(J10<10,"Low",IF(J10>20,"High","")))
B11: =TODAY()-WEEKDAY(TODAY(),3)-70 | C11: =COUNTIFS(Log!$V$6:$V$1505,1,Log!$W$6:$W$1505,B11) | D11: =SUMIFS(Log!$O$6:$O$1505,Log!$W$6:$W$1505,B11) | E11: =SUMIFS(Log!$P$6:$P$1505,Log!$W$6:$W$1505,B11) | I11: Back | J11: =SUMIFS(Log!$O$6:$O$1505,Log!$U$6:$U$1505,I11,Log!$B$6:$B$1505,">"&TODAY()-7,Log!$B$6:$B$1505,"<="&TODAY()) | K11: =SUMIFS(Log!$O$6:$O$1505,Log!$U$6:$U$1505,I11,Log!$B$6:$B$1505,">"&TODAY()-14,Log!$B$6:$B$1505,"<="&TODAY()-7) | L11: =IF(N(J11)=0,"",IF(J11<10,"Low",IF(J11>20,"High","")))
B12: =TODAY()-WEEKDAY(TODAY(),3)-63 | C12: =COUNTIFS(Log!$V$6:$V$1505,1,Log!$W$6:$W$1505,B12) | D12: =SUMIFS(Log!$O$6:$O$1505,Log!$W$6:$W$1505,B12) | E12: =SUMIFS(Log!$P$6:$P$1505,Log!$W$6:$W$1505,B12) | I12: Shoulders | J12: =SUMIFS(Log!$O$6:$O$1505,Log!$U$6:$U$1505,I12,Log!$B$6:$B$1505,">"&TODAY()-7,Log!$B$6:$B$1505,"<="&TODAY()) | K12: =SUMIFS(Log!$O$6:$O$1505,Log!$U$6:$U$1505,I12,Log!$B$6:$B$1505,">"&TODAY()-14,Log!$B$6:$B$1505,"<="&TODAY()-7) | L12: =IF(N(J12)=0,"",IF(J12<10,"Low",IF(J12>20,"High","")))
B13: =TODAY()-WEEKDAY(TODAY(),3)-56 | C13: =COUNTIFS(Log!$V$6:$V$1505,1,Log!$W$6:$W$1505,B13) | D13: =SUMIFS(Log!$O$6:$O$1505,Log!$W$6:$W$1505,B13) | E13: =SUMIFS(Log!$P$6:$P$1505,Log!$W$6:$W$1505,B13) | I13: Arms | J13: =SUMIFS(Log!$O$6:$O$1505,Log!$U$6:$U$1505,I13,Log!$B$6:$B$1505,">"&TODAY()-7,Log!$B$6:$B$1505,"<="&TODAY()) | K13: =SUMIFS(Log!$O$6:$O$1505,Log!$U$6:$U$1505,I13,Log!$B$6:$B$1505,">"&TODAY()-14,Log!$B$6:$B$1505,"<="&TODAY()-7) | L13: =IF(N(J13)=0,"",IF(J13<10,"Low",IF(J13>20,"High","")))
B14: =TODAY()-WEEKDAY(TODAY(),3)-49 | C14: =COUNTIFS(Log!$V$6:$V$1505,1,Log!$W$6:$W$1505,B14) | D14: =SUMIFS(Log!$O$6:$O$1505,Log!$W$6:$W$1505,B14) | E14: =SUMIFS(Log!$P$6:$P$1505,Log!$W$6:$W$1505,B14) | I14: Legs | J14: =SUMIFS(Log!$O$6:$O$1505,Log!$U$6:$U$1505,I14,Log!$B$6:$B$1505,">"&TODAY()-7,Log!$B$6:$B$1505,"<="&TODAY()) | K14: =SUMIFS(Log!$O$6:$O$1505,Log!$U$6:$U$1505,I14,Log!$B$6:$B$1505,">"&TODAY()-14,Log!$B$6:$B$1505,"<="&TODAY()-7) | L14: =IF(N(J14)=0,"",IF(J14<10,"Low",IF(J14>20,"High","")))
B15: =TODAY()-WEEKDAY(TODAY(),3)-42 | C15: =COUNTIFS(Log!$V$6:$V$1505,1,Log!$W$6:$W$1505,B15) | D15: =SUMIFS(Log!$O$6:$O$1505,Log!$W$6:$W$1505,B15) | E15: =SUMIFS(Log!$P$6:$P$1505,Log!$W$6:$W$1505,B15) | I15: Glutes | J15: =SUMIFS(Log!$O$6:$O$1505,Log!$U$6:$U$1505,I15,Log!$B$6:$B$1505,">"&TODAY()-7,Log!$B$6:$B$1505,"<="&TODAY()) | K15: =SUMIFS(Log!$O$6:$O$1505,Log!$U$6:$U$1505,I15,Log!$B$6:$B$1505,">"&TODAY()-14,Log!$B$6:$B$1505,"<="&TODAY()-7) | L15: =IF(N(J15)=0,"",IF(J15<10,"Low",IF(J15>20,"High","")))
B16: =TODAY()-WEEKDAY(TODAY(),3)-35 | C16: =COUNTIFS(Log!$V$6:$V$1505,1,Log!$W$6:$W$1505,B16) | D16: =SUMIFS(Log!$O$6:$O$1505,Log!$W$6:$W$1505,B16) | E16: =SUMIFS(Log!$P$6:$P$1505,Log!$W$6:$W$1505,B16) | I16: Core | J16: =SUMIFS(Log!$O$6:$O$1505,Log!$U$6:$U$1505,I16,Log!$B$6:$B$1505,">"&TODAY()-7,Log!$B$6:$B$1505,"<="&TODAY()) | K16: =SUMIFS(Log!$O$6:$O$1505,Log!$U$6:$U$1505,I16,Log!$B$6:$B$1505,">"&TODAY()-14,Log!$B$6:$B$1505,"<="&TODAY()-7) | L16: =IF(N(J16)=0,"",IF(J16<10,"Low",IF(J16>20,"High","")))
B17: =TODAY()-WEEKDAY(TODAY(),3)-28 | C17: =COUNTIFS(Log!$V$6:$V$1505,1,Log!$W$6:$W$1505,B17) | D17: =SUMIFS(Log!$O$6:$O$1505,Log!$W$6:$W$1505,B17) | E17: =SUMIFS(Log!$P$6:$P$1505,Log!$W$6:$W$1505,B17) | I17: Many programs aim for 10 to 20 hard sets per muscle group each week.
B18: =TODAY()-WEEKDAY(TODAY(),3)-21 | C18: =COUNTIFS(Log!$V$6:$V$1505,1,Log!$W$6:$W$1505,B18) | D18: =SUMIFS(Log!$O$6:$O$1505,Log!$W$6:$W$1505,B18) | E18: =SUMIFS(Log!$P$6:$P$1505,Log!$W$6:$W$1505,B18)
B19: =TODAY()-WEEKDAY(TODAY(),3)-14 | C19: =COUNTIFS(Log!$V$6:$V$1505,1,Log!$W$6:$W$1505,B19) | D19: =SUMIFS(Log!$O$6:$O$1505,Log!$W$6:$W$1505,B19) | E19: =SUMIFS(Log!$P$6:$P$1505,Log!$W$6:$W$1505,B19) | I19: New bests | J19: Best set | K19: Est. max | L19: Date
B20: =TODAY()-WEEKDAY(TODAY(),3)-7 | C20: =COUNTIFS(Log!$V$6:$V$1505,1,Log!$W$6:$W$1505,B20) | D20: =SUMIFS(Log!$O$6:$O$1505,Log!$W$6:$W$1505,B20) | E20: =SUMIFS(Log!$P$6:$P$1505,Log!$W$6:$W$1505,B20) | I20: =IF(O20="","",INDEX(Log!$D$6:$D$1505,MATCH(O20,Log!$AC$6:$AC$1505,0))) | J20: =IF(O20="","",INDEX(Log!$Q$6:$Q$1505,MATCH(O20,Log!$AC$6:$AC$1505,0))) | K20: =IF(O20="","",INDEX(Log!$R$6:$R$1505,MATCH(O20,Log!$AC$6:$AC$1505,0))) | L20: =IF(O20="","",INT(O20)) | O20: =IFERROR(LARGE(Log!$AC$6:$AC$1505,1),"")
B21: =TODAY()-WEEKDAY(TODAY(),3)-0 | C21: =COUNTIFS(Log!$V$6:$V$1505,1,Log!$W$6:$W$1505,B21) | D21: =SUMIFS(Log!$O$6:$O$1505,Log!$W$6:$W$1505,B21) | E21: =SUMIFS(Log!$P$6:$P$1505,Log!$W$6:$W$1505,B21) | I21: =IF(O21="","",INDEX(Log!$D$6:$D$1505,MATCH(O21,Log!$AC$6:$AC$1505,0))) | J21: =IF(O21="","",INDEX(Log!$Q$6:$Q$1505,MATCH(O21,Log!$AC$6:$AC$1505,0))) | K21: =IF(O21="","",INDEX(Log!$R$6:$R$1505,MATCH(O21,Log!$AC$6:$AC$1505,0))) | L21: =IF(O21="","",INT(O21)) | O21: =IFERROR(LARGE(Log!$AC$6:$AC$1505,2),"")
I22: =IF(O22="","",INDEX(Log!$D$6:$D$1505,MATCH(O22,Log!$AC$6:$AC$1505,0))) | J22: =IF(O22="","",INDEX(Log!$Q$6:$Q$1505,MATCH(O22,Log!$AC$6:$AC$1505,0))) | K22: =IF(O22="","",INDEX(Log!$R$6:$R$1505,MATCH(O22,Log!$AC$6:$AC$1505,0))) | L22: =IF(O22="","",INT(O22)) | O22: =IFERROR(LARGE(Log!$AC$6:$AC$1505,3),"")
I23: =IF(O23="","",INDEX(Log!$D$6:$D$1505,MATCH(O23,Log!$AC$6:$AC$1505,0))) | J23: =IF(O23="","",INDEX(Log!$Q$6:$Q$1505,MATCH(O23,Log!$AC$6:$AC$1505,0))) | K23: =IF(O23="","",INDEX(Log!$R$6:$R$1505,MATCH(O23,Log!$AC$6:$AC$1505,0))) | L23: =IF(O23="","",INT(O23)) | O23: =IFERROR(LARGE(Log!$AC$6:$AC$1505,4),"")
I24: =IF(O24="","",INDEX(Log!$D$6:$D$1505,MATCH(O24,Log!$AC$6:$AC$1505,0))) | J24: =IF(O24="","",INDEX(Log!$Q$6:$Q$1505,MATCH(O24,Log!$AC$6:$AC$1505,0))) | K24: =IF(O24="","",INDEX(Log!$R$6:$R$1505,MATCH(O24,Log!$AC$6:$AC$1505,0))) | L24: =IF(O24="","",INT(O24)) | O24: =IFERROR(LARGE(Log!$AC$6:$AC$1505,5),"")
I25: =IF(O25="","",INDEX(Log!$D$6:$D$1505,MATCH(O25,Log!$AC$6:$AC$1505,0))) | J25: =IF(O25="","",INDEX(Log!$Q$6:$Q$1505,MATCH(O25,Log!$AC$6:$AC$1505,0))) | K25: =IF(O25="","",INDEX(Log!$R$6:$R$1505,MATCH(O25,Log!$AC$6:$AC$1505,0))) | L25: =IF(O25="","",INT(O25)) | O25: =IFERROR(LARGE(Log!$AC$6:$AC$1505,6),"")

Sheet Log
B2: Workout log
B3: One line per exercise, with up to five sets. For a bodyweight exercise leave the weight empty.
B5: Date | C5: Workout | D5: Exercise | E5: Set 1 | F5: Reps | G5: Set 2 | H5: Reps | I5: Set 3 | J5: Reps | K5: Set 4 | L5: Reps | M5: Set 5 | N5: Reps | O5: Sets | P5: Volume | Q5: Best set | R5: Est. max | S5: New best | T5: Note
B6: 46209 | C6: Push | D6: Bench press | E6: 135 | F6: 7 | G6: 135 | H6: 7 | I6: 135 | J6: 6 | K6: 135 | L6: 6 | O6: =IF(D6="","",COUNT(F6,H6,J6,L6,N6)) | P6: =IF(D6="","",N(E6)*N(F6)+N(G6)*N(H6)+N(I6)*N(J6)+N(K6)*N(L6)+N(M6)*N(N6)) | Q6: =IF(N(X6)=0,"",IF(IF(N(F6)=0,0,IF(N(E6)>0,E6*(1+F6/30),F6))=X6,IF(N(E6)>0,E6&" x "&F6,F6&" reps"),IF(IF(N(H6)=0,0,IF(N(G6)>0,G6*(1+H6/30),H6))=X6,IF(N(G6)>0,G6&" x "&H6,H6&" reps"),IF(IF(N(J6)=0,0,IF(N(I6)>0,I6*(1+J6/30),J6))=X6,IF(N(I6)>0,I6&" x "&J6,J6&" reps"),IF(IF(N(L6)=0,0,IF(N(K6)>0,K6*(1+L6/30),L6))=X6,IF(N(K6)>0,K6&" x "&L6,L6&" reps"),IF(IF(N(N6)=0,0,IF(N(M6)>0,M6*(1+N6/30),N6))=X6,IF(N(M6)>0,M6&" x "&N6,N6&" reps"),"")))))) | R6: =IF(N(X6)=0,"",ROUND(X6,1)) | S6: =IF(N(X6)=0,"",IF(AND(COUNTIFS(Log!$D$6:$D$1505,D6,Log!$B$6:$B$1505,"<"&B6)>0,COUNTIFS(Log!$D$6:$D$1505,D6,Log!$B$6:$B$1505,"<"&B6,Log!$X$6:$X$1505,">="&X6)=0),"New best","")) | U6: =IF(D6="","",IFERROR(INDEX(Exercises!$C$6:$C$105,MATCH(D6,Exercises!$B$6:$B$105,0)),"Other")) | V6: =IF(B6="","",IF(COUNTIF($B$6:B6,B6)=1,1,0)) | W6: =IF(B6="","",B6-WEEKDAY(B6,3)) | X6: =IF(D6="","",MAX(IF(N(F6)=0,0,IF(N(E6)>0,E6*(1+F6/30),F6)),IF(N(H6)=0,0,IF(N(G6)>0,G6*(1+H6/30),H6)),IF(N(J6)=0,0,IF(N(I6)>0,I6*(1+J6/30),J6)),IF(N(L6)=0,0,IF(N(K6)>0,K6*(1+L6/30),L6)),IF(N(N6)=0,0,IF(N(M6)>0,M6*(1+N6/30),N6)))) | Y6: =IF(N(X6)=0,"",X6+ROW()/1000000000) | Z6: =IF(Y6="","",IF(COUNTIFS(Log!$D$6:$D$1505,D6,Log!$Y$6:$Y$1505,">"&Y6)=0,1,0)) | AA6: =IF(OR(B6="",D6=""),"",B6+ROW()/10000000) | AB6: =IF(AA6="","",IF(COUNTIFS(Log!$D$6:$D$1505,D6,Log!$AA$6:$AA$1505,">"&AA6)=0,1,0)) | AC6: =IF(S6="New best",AA6,"") | AD6: =ROW()
B7: 46209 | C7: Push | D7: Overhead press | E7: 85 | F7: 10 | G7: 85 | H7: 9 | I7: 85 | J7: 8 | O7: =IF(D7="","",COUNT(F7,H7,J7,L7,N7)) | P7: =IF(D7="","",N(E7)*N(F7)+N(G7)*N(H7)+N(I7)*N(J7)+N(K7)*N(L7)+N(M7)*N(N7)) | Q7: =IF(N(X7)=0,"",IF(IF(N(F7)=0,0,IF(N(E7)>0,E7*(1+F7/30),F7))=X7,IF(N(E7)>0,E7&" x "&F7,F7&" reps"),IF(IF(N(H7)=0,0,IF(N(G7)>0,G7*(1+H7/30),H7))=X7,IF(N(G7)>0,G7&" x "&H7,H7&" reps"),IF(IF(N(J7)=0,0,IF(N(I7)>0,I7*(1+J7/30),J7))=X7,IF(N(I7)>0,I7&" x "&J7,J7&" reps"),IF(IF(N(L7)=0,0,IF(N(K7)>0,K7*(1+L7/30),L7))=X7,IF(N(K7)>0,K7&" x "&L7,L7&" reps"),IF(IF(N(N7)=0,0,IF(N(M7)>0,M7*(1+N7/30),N7))=X7,IF(N(M7)>0,M7&" x "&N7,N7&" reps"),"")))))) | R7: =IF(N(X7)=0,"",ROUND(X7,1)) | S7: =IF(N(X7)=0,"",IF(AND(COUNTIFS(Log!$D$6:$D$1505,D7,Log!$B$6:$B$1505,"<"&B7)>0,COUNTIFS(Log!$D$6:$D$1505,D7,Log!$B$6:$B$1505,"<"&B7,Log!$X$6:$X$1505,">="&X7)=0),"New best","")) | T7: Short on time | U7: =IF(D7="","",IFERROR(INDEX(Exercises!$C$6:$C$105,MATCH(D7,Exercises!$B$6:$B$105,0)),"Other")) | V7: =IF(B7="","",IF(COUNTIF($B$6:B7,B7)=1,1,0)) | W7: =IF(B7="","",B7-WEEKDAY(B7,3)) | X7: =IF(D7="","",MAX(IF(N(F7)=0,0,IF(N(E7)>0,E7*(1+F7/30),F7)),IF(N(H7)=0,0,IF(N(G7)>0,G7*(1+H7/30),H7)),IF(N(J7)=0,0,IF(N(I7)>0,I7*(1+J7/30),J7)),IF(N(L7)=0,0,IF(N(K7)>0,K7*(1+L7/30),L7)),IF(N(N7)=0,0,IF(N(M7)>0,M7*(1+N7/30),N7)))) | Y7: =IF(N(X7)=0,"",X7+ROW()/1000000000) | Z7: =IF(Y7="","",IF(COUNTIFS(Log!$D$6:$D$1505,D7,Log!$Y$6:$Y$1505,">"&Y7)=0,1,0)) | AA7: =IF(OR(B7="",D7=""),"",B7+ROW()/10000000) | AB7: =IF(AA7="","",IF(COUNTIFS(Log!$D$6:$D$1505,D7,Log!$AA$6:$AA$1505,">"&AA7)=0,1,0)) | AC7: =IF(S7="New best",AA7,"") | AD7: =ROW()
B8: 46209 | C8: Push | D8: Incline dumbbell press | E8: 45 | F8: 12 | G8: 45 | H8: 10 | I8: 45 | J8: 10 | O8: =IF(D8="","",COUNT(F8,H8,J8,L8,N8)) | P8: =IF(D8="","",N(E8)*N(F8)+N(G8)*N(H8)+N(I8)*N(J8)+N(K8)*N(L8)+N(M8)*N(N8)) | Q8: =IF(N(X8)=0,"",IF(IF(N(F8)=0,0,IF(N(E8)>0,E8*(1+F8/30),F8))=X8,IF(N(E8)>0,E8&" x "&F8,F8&" reps"),IF(IF(N(H8)=0,0,IF(N(G8)>0,G8*(1+H8/30),H8))=X8,IF(N(G8)>0,G8&" x "&H8,H8&" reps"),IF(IF(N(J8)=0,0,IF(N(I8)>0,I8*(1+J8/30),J8))=X8,IF(N(I8)>0,I8&" x "&J8,J8&" reps"),IF(IF(N(L8)=0,0,IF(N(K8)>0,K8*(1+L8/30),L8))=X8,IF(N(K8)>0,K8&" x "&L8,L8&" reps"),IF(IF(N(N8)=0,0,IF(N(M8)>0,M8*(1+N8/30),N8))=X8,IF(N(M8)>0,M8&" x "&N8,N8&" reps"),"")))))) | R8: =IF(N(X8)=0,"",ROUND(X8,1)) | S8: =IF(N(X8)=0,"",IF(AND(COUNTIFS(Log!$D$6:$D$1505,D8,Log!$B$6:$B$1505,"<"&B8)>0,COUNTIFS(Log!$D$6:$D$1505,D8,Log!$B$6:$B$1505,"<"&B8,Log!$X$6:$X$1505,">="&X8)=0),"New best","")) | U8: =IF(D8="","",IFERROR(INDEX(Exercises!$C$6:$C$105,MATCH(D8,Exercises!$B$6:$B$105,0)),"Other")) | V8: =IF(B8="","",IF(COUNTIF($B$6:B8,B8)=1,1,0)) | W8: =IF(B8="","",B8-WEEKDAY(B8,3)) | X8: =IF(D8="","",MAX(IF(N(F8)=0,0,IF(N(E8)>0,E8*(1+F8/30),F8)),IF(N(H8)=0,0,IF(N(G8)>0,G8*(1+H8/30),H8)),IF(N(J8)=0,0,IF(N(I8)>0,I8*(1+J8/30),J8)),IF(N(L8)=0,0,IF(N(K8)>0,K8*(1+L8/30),L8)),IF(N(N8)=0,0,IF(N(M8)>0,M8*(1+N8/30),N8)))) | Y8: =IF(N(X8)=0,"",X8+ROW()/1000000000) | Z8: =IF(Y8="","",IF(COUNTIFS(Log!$D$6:$D$1505,D8,Log!$Y$6:$Y$1505,">"&Y8)=0,1,0)) | AA8: =IF(OR(B8="",D8=""),"",B8+ROW()/10000000) | AB8: =IF(AA8="","",IF(COUNTIFS(Log!$D$6:$D$1505,D8,Log!$AA$6:$AA$1505,">"&AA8)=0,1,0)) | AC8: =IF(S8="New best",AA8,"") | AD8: =ROW()
B9: 46209 | C9: Push | D9: Lateral raise | E9: 15 | F9: 15 | G9: 15 | H9: 14 | I9: 15 | J9: 12 | O9: =IF(D9="","",COUNT(F9,H9,J9,L9,N9)) | P9: =IF(D9="","",N(E9)*N(F9)+N(G9)*N(H9)+N(I9)*N(J9)+N(K9)*N(L9)+N(M9)*N(N9)) | Q9: =IF(N(X9)=0,"",IF(IF(N(F9)=0,0,IF(N(E9)>0,E9*(1+F9/30),F9))=X9,IF(N(E9)>0,E9&" x "&F9,F9&" reps"),IF(IF(N(H9)=0,0,IF(N(G9)>0,G9*(1+H9/30),H9))=X9,IF(N(G9)>0,G9&" x "&H9,H9&" reps"),IF(IF(N(J9)=0,0,IF(N(I9)>0,I9*(1+J9/30),J9))=X9,IF(N(I9)>0,I9&" x "&J9,J9&" reps"),IF(IF(N(L9)=0,0,IF(N(K9)>0,K9*(1+L9/30),L9))=X9,IF(N(K9)>0,K9&" x "&L9,L9&" reps"),IF(IF(N(N9)=0,0,IF(N(M9)>0,M9*(1+N9/30),N9))=X9,IF(N(M9)>0,M9&" x "&N9,N9&" reps"),"")))))) | R9: =IF(N(X9)=0,"",ROUND(X9,1)) | S9: =IF(N(X9)=0,"",IF(AND(COUNTIFS(Log!$D$6:$D$1505,D9,Log!$B$6:$B$1505,"<"&B9)>0,COUNTIFS(Log!$D$6:$D$1505,D9,Log!$B$6:$B$1505,"<"&B9,Log!$X$6:$X$1505,">="&X9)=0),"New best","")) | U9: =IF(D9="","",IFERROR(INDEX(Exercises!$C$6:$C$105,MATCH(D9,Exercises!$B$6:$B$105,0)),"Other")) | V9: =IF(B9="","",IF(COUNTIF($B$6:B9,B9)=1,1,0)) | W9: =IF(B9="","",B9-WEEKDAY(B9,3)) | X9: =IF(D9="","",MAX(IF(N(F9)=0,0,IF(N(E9)>0,E9*(1+F9/30),F9)),IF(N(H9)=0,0,IF(N(G9)>0,G9*(1+H9/30),H9)),IF(N(J9)=0,0,IF(N(I9)>0,I9*(1+J9/30),J9)),IF(N(L9)=0,0,IF(N(K9)>0,K9*(1+L9/30),L9)),IF(N(N9)=0,0,IF(N(M9)>0,M9*(1+N9/30),N9)))) | Y9: =IF(N(X9)=0,"",X9+ROW()/1000000000) | Z9: =IF(Y9="","",IF(COUNTIFS(Log!$D$6:$D$1505,D9,Log!$Y$6:$Y$1505,">"&Y9)=0,1,0)) | AA9: =IF(OR(B9="",D9=""),"",B9+ROW()/10000000) | AB9: =IF(AA9="","",IF(COUNTIFS(Log!$D$6:$D$1505,D9,Log!$AA$6:$AA$1505,">"&AA9)=0,1,0)) | AC9: =IF(S9="New best",AA9,"") | AD9: =ROW()
B10: 46209 | C10: Push | D10: Triceps pushdown | E10: 40 | F10: 12 | G10: 40 | H10: 10 | I10: 40 | J10: 10 | O10: =IF(D10="","",COUNT(F10,H10,J10,L10,N10)) | P10: =IF(D10="","",N(E10)*N(F10)+N(G10)*N(H10)+N(I10)*N(J10)+N(K10)*N(L10)+N(M10)*N(N10)) | Q10: =IF(N(X10)=0,"",IF(IF(N(F10)=0,0,IF(N(E10)>0,E10*(1+F10/30),F10))=X10,IF(N(E10)>0,E10&" x "&F10,F10&" reps"),IF(IF(N(H10)=0,0,IF(N(G10)>0,G10*(1+H10/30),H10))=X10,IF(N(G10)>0,G10&" x "&H10,H10&" reps"),IF(IF(N(J10)=0,0,IF(N(I10)>0,I10*(1+J10/30),J10))=X10,IF(N(I10)>0,I10&" x "&J10,J10&" reps"),IF(IF(N(L10)=0,0,IF(N(K10)>0,K10*(1+L10/30),L10))=X10,IF(N(K10)>0,K10&" x "&L10,L10&" reps"),IF(IF(N(N10)=0,0,IF(N(M10)>0,M10*(1+N10/30),N10))=X10,IF(N(M10)>0,M10&" x "&N10,N10&" reps"),"")))))) | R10: =IF(N(X10)=0,"",ROUND(X10,1)) | S10: =IF(N(X10)=0,"",IF(AND(COUNTIFS(Log!$D$6:$D$1505,D10,Log!$B$6:$B$1505,"<"&B10)>0,COUNTIFS(Log!$D$6:$D$1505,D10,Log!$B$6:$B$1505,"<"&B10,Log!$X$6:$X$1505,">="&X10)=0),"New best","")) | U10: =IF(D10="","",IFERROR(INDEX(Exercises!$C$6:$C$105,MATCH(D10,Exercises!$B$6:$B$105,0)),"Other")) | V10: =IF(B10="","",IF(COUNTIF($B$6:B10,B10)=1,1,0)) | W10: =IF(B10="","",B10-WEEKDAY(B10,3)) | X10: =IF(D10="","",MAX(IF(N(F10)=0,0,IF(N(E10)>0,E10*(1+F10/30),F10)),IF(N(H10)=0,0,IF(N(G10)>0,G10*(1+H10/30),H10)),IF(N(J10)=0,0,IF(N(I10)>0,I10*(1+J10/30),J10)),IF(N(L10)=0,0,IF(N(K10)>0,K10*(1+L10/30),L10)),IF(N(N10)=0,0,IF(N(M10)>0,M10*(1+N10/30),N10)))) | Y10: =IF(N(X10)=0,"",X10+ROW()/1000000000) | Z10: =IF(Y10="","",IF(COUNTIFS(Log!$D$6:$D$1505,D10,Log!$Y$6:$Y$1505,">"&Y10)=0,1,0)) | AA10: =IF(OR(B10="",D10=""),"",B10+ROW()/10000000) | AB10: =IF(AA10="","",IF(COUNTIFS(Log!$D$6:$D$1505,D10,Log!$AA$6:$AA$1505,">"&AA10)=0,1,0)) | AC10: =IF(S10="New best",AA10,"") | AD10: =ROW()
B11: 46210 | C11: Pull | D11: Deadlift | E11: 225 | F11: 5 | G11: 225 | H11: 5 | I11: 225 | J11: 5 | O11: =IF(D11="","",COUNT(F11,H11,J11,L11,N11)) | P11: =IF(D11="","",N(E11)*N(F11)+N(G11)*N(H11)+N(I11)*N(J11)+N(K11)*N(L11)+N(M11)*N(N11)) | Q11: =IF(N(X11)=0,"",IF(IF(N(F11)=0,0,IF(N(E11)>0,E11*(1+F11/30),F11))=X11,IF(N(E11)>0,E11&" x "&F11,F11&" reps"),IF(IF(N(H11)=0,0,IF(N(G11)>0,G11*(1+H11/30),H11))=X11,IF(N(G11)>0,G11&" x "&H11,H11&" reps"),IF(IF(N(J11)=0,0,IF(N(I11)>0,I11*(1+J11/30),J11))=X11,IF(N(I11)>0,I11&" x "&J11,J11&" reps"),IF(IF(N(L11)=0,0,IF(N(K11)>0,K11*(1+L11/30),L11))=X11,IF(N(K11)>0,K11&" x "&L11,L11&" reps"),IF(IF(N(N11)=0,0,IF(N(M11)>0,M11*(1+N11/30),N11))=X11,IF(N(M11)>0,M11&" x "&N11,N11&" reps"),"")))))) | R11: =IF(N(X11)=0,"",ROUND(X11,1)) | S11: =IF(N(X11)=0,"",IF(AND(COUNTIFS(Log!$D$6:$D$1505,D11,Log!$B$6:$B$1505,"<"&B11)>0,COUNTIFS(Log!$D$6:$D$1505,D11,Log!$B$6:$B$1505,"<"&B11,Log!$X$6:$X$1505,">="&X11)=0),"New best","")) | U11: =IF(D11="","",IFERROR(INDEX(Exercises!$C$6:$C$105,MATCH(D11,Exercises!$B$6:$B$105,0)),"Other")) | V11: =IF(B11="","",IF(COUNTIF($B$6:B11,B11)=1,1,0)) | W11: =IF(B11="","",B11-WEEKDAY(B11,3)) | X11: =IF(D11="","",MAX(IF(N(F11)=0,0,IF(N(E11)>0,E11*(1+F11/30),F11)),IF(N(H11)=0,0,IF(N(G11)>0,G11*(1+H11/30),H11)),IF(N(J11)=0,0,IF(N(I11)>0,I11*(1+J11/30),J11)),IF(N(L11)=0,0,IF(N(K11)>0,K11*(1+L11/30),L11)),IF(N(N11)=0,0,IF(N(M11)>0,M11*(1+N11/30),N11)))) | Y11: =IF(N(X11)=0,"",X11+ROW()/1000000000) | Z11: =IF(Y11="","",IF(COUNTIFS(Log!$D$6:$D$1505,D11,Log!$Y$6:$Y$1505,">"&Y11)=0,1,0)) | AA11: =IF(OR(B11="",D11=""),"",B11+ROW()/10000000) | AB11: =IF(AA11="","",IF(COUNTIFS(Log!$D$6:$D$1505,D11,Log!$AA$6:$AA$1505,">"&AA11)=0,1,0)) | AC11: =IF(S11="New best",AA11,"") | AD11: =ROW()
B12: 46210 | C12: Pull | D12: Pull-up | F12: 6 | H12: 5 | J12: 4 | O12: =IF(D12="","",COUNT(F12,H12,J12,L12,N12)) | P12: =IF(D12="","",N(E12)*N(F12)+N(G12)*N(H12)+N(I12)*N(J12)+N(K12)*N(L12)+N(M12)*N(N12)) | Q12: =IF(N(X12)=0,"",IF(IF(N(F12)=0,0,IF(N(E12)>0,E12*(1+F12/30),F12))=X12,IF(N(E12)>0,E12&" x "&F12,F12&" reps"),IF(IF(N(H12)=0,0,IF(N(G12)>0,G12*(1+H12/30),H12))=X12,IF(N(G12)>0,G12&" x "&H12,H12&" reps"),IF(IF(N(J12)=0,0,IF(N(I12)>0,I12*(1+J12/30),J12))=X12,IF(N(I12)>0,I12&" x "&J12,J12&" reps"),IF(IF(N(L12)=0,0,IF(N(K12)>0,K12*(1+L12/30),L12))=X12,IF(N(K12)>0,K12&" x "&L12,L12&" reps"),IF(IF(N(N12)=0,0,IF(N(M12)>0,M12*(1+N12/30),N12))=X12,IF(N(M12)>0,M12&" x "&N12,N12&" reps"),"")))))) | R12: =IF(N(X12)=0,"",ROUND(X12,1)) | S12: =IF(N(X12)=0,"",IF(AND(COUNTIFS(Log!$D$6:$D$1505,D12,Log!$B$6:$B$1505,"<"&B12)>0,COUNTIFS(Log!$D$6:$D$1505,D12,Log!$B$6:$B$1505,"<"&B12,Log!$X$6:$X$1505,">="&X12)=0),"New best","")) | U12: =IF(D12="","",IFERROR(INDEX(Exercises!$C$6:$C$105,MATCH(D12,Exercises!$B$6:$B$105,0)),"Other")) | V12: =IF(B12="","",IF(COUNTIF($B$6:B12,B12)=1,1,0)) | W12: =IF(B12="","",B12-WEEKDAY(B12,3)) | X12: =IF(D12="","",MAX(IF(N(F12)=0,0,IF(N(E12)>0,E12*(1+F12/30),F12)),IF(N(H12)=0,0,IF(N(G12)>0,G12*(1+H12/30),H12)),IF(N(J12)=0,0,IF(N(I12)>0,I12*(1+J12/30),J12)),IF(N(L12)=0,0,IF(N(K12)>0,K12*(1+L12/30),L12)),IF(N(N12)=0,0,IF(N(M12)>0,M12*(1+N12/30),N12)))) | Y12: =IF(N(X12)=0,"",X12+ROW()/1000000000) | Z12: =IF(Y12="","",IF(COUNTIFS(Log!$D$6:$D$1505,D12,Log!$Y$6:$Y$1505,">"&Y12)=0,1,0)) | AA12: =IF(OR(B12="",D12=""),"",B12+ROW()/10000000) | AB12: =IF(AA12="","",IF(COUNTIFS(Log!$D$6:$D$1505,D12,Log!$AA$6:$AA$1505,">"&AA12)=0,1,0)) | AC12: =IF(S12="New best",AA12,"") | AD12: =ROW()
B13: 46210 | C13: Pull | D13: Barbell row | E13: 115 | F13: 10 | G13: 115 | H13: 8 | I13: 115 | J13: 8 | O13: =IF(D13="","",COUNT(F13,H13,J13,L13,N13)) | P13: =IF(D13="","",N(E13)*N(F13)+N(G13)*N(H13)+N(I13)*N(J13)+N(K13)*N(L13)+N(M13)*N(N13)) | Q13: =IF(N(X13)=0,"",IF(IF(N(F13)=0,0,IF(N(E13)>0,E13*(1+F13/30),F13))=X13,IF(N(E13)>0,E13&" x "&F13,F13&" reps"),IF(IF(N(H13)=0,0,IF(N(G13)>0,G13*(1+H13/30),H13))=X13,IF(N(G13)>0,G13&" x "&H13,H13&" reps"),IF(IF(N(J13)=0,0,IF(N(I13)>0,I13*(1+J13/30),J13))=X13,IF(N(I13)>0,I13&" x "&J13,J13&" reps"),IF(IF(N(L13)=0,0,IF(N(K13)>0,K13*(1+L13/30),L13))=X13,IF(N(K13)>0,K13&" x "&L13,L13&" reps"),IF(IF(N(N13)=0,0,IF(N(M13)>0,M13*(1+N13/30),N13))=X13,IF(N(M13)>0,M13&" x "&N13,N13&" reps"),"")))))) | R13: =IF(N(X13)=0,"",ROUND(X13,1)) | S13: =IF(N(X13)=0,"",IF(AND(COUNTIFS(Log!$D$6:$D$1505,D13,Log!$B$6:$B$1505,"<"&B13)>0,COUNTIFS(Log!$D$6:$D$1505,D13,Log!$B$6:$B$1505,"<"&B13,Log!$X$6:$X$1505,">="&X13)=0),"New best","")) | U13: =IF(D13="","",IFERROR(INDEX(Exercises!$C$6:$C$105,MATCH(D13,Exercises!$B$6:$B$105,0)),"Other")) | V13: =IF(B13="","",IF(COUNTIF($B$6:B13,B13)=1,1,0)) | W13: =IF(B13="","",B13-WEEKDAY(B13,3)) | X13: =IF(D13="","",MAX(IF(N(F13)=0,0,IF(N(E13)>0,E13*(1+F13/30),F13)),IF(N(H13)=0,0,IF(N(G13)>0,G13*(1+H13/30),H13)),IF(N(J13)=0,0,IF(N(I13)>0,I13*(1+J13/30),J13)),IF(N(L13)=0,0,IF(N(K13)>0,K13*(1+L13/30),L13)),IF(N(N13)=0,0,IF(N(M13)>0,M13*(1+N13/30),N13)))) | Y13: =IF(N(X13)=0,"",X13+ROW()/1000000000) | Z13: =IF(Y13="","",IF(COUNTIFS(Log!$D$6:$D$1505,D13,Log!$Y$6:$Y$1505,">"&Y13)=0,1,0)) | AA13: =IF(OR(B13="",D13=""),"",B13+ROW()/10000000) | AB13: =IF(AA13="","",IF(COUNTIFS(Log!$D$6:$D$1505,D13,Log!$AA$6:$AA$1505,">"&AA13)=0,1,0)) | AC13: =IF(S13="New best",AA13,"") | AD13: =ROW()
B14: 46210 | C14: Pull | D14: Lat pulldown | E14: 100 | F14: 12 | G14: 100 | H14: 11 | I14: 100 | J14: 10 | O14: =IF(D14="","",COUNT(F14,H14,J14,L14,N14)) | P14: =IF(D14="","",N(E14)*N(F14)+N(G14)*N(H14)+N(I14)*N(J14)+N(K14)*N(L14)+N(M14)*N(N14)) | Q14: =IF(N(X14)=0,"",IF(IF(N(F14)=0,0,IF(N(E14)>0,E14*(1+F14/30),F14))=X14,IF(N(E14)>0,E14&" x "&F14,F14&" reps"),IF(IF(N(H14)=0,0,IF(N(G14)>0,G14*(1+H14/30),H14))=X14,IF(N(G14)>0,G14&" x "&H14,H14&" reps"),IF(IF(N(J14)=0,0,IF(N(I14)>0,I14*(1+J14/30),J14))=X14,IF(N(I14)>0,I14&" x "&J14,J14&" reps"),IF(IF(N(L14)=0,0,IF(N(K14)>0,K14*(1+L14/30),L14))=X14,IF(N(K14)>0,K14&" x "&L14,L14&" reps"),IF(IF(N(N14)=0,0,IF(N(M14)>0,M14*(1+N14/30),N14))=X14,IF(N(M14)>0,M14&" x "&N14,N14&" reps"),"")))))) | R14: =IF(N(X14)=0,"",ROUND(X14,1)) | S14: =IF(N(X14)=0,"",IF(AND(COUNTIFS(Log!$D$6:$D$1505,D14,Log!$B$6:$B$1505,"<"&B14)>0,COUNTIFS(Log!$D$6:$D$1505,D14,Log!$B$6:$B$1505,"<"&B14,Log!$X$6:$X$1505,">="&X14)=0),"New best","")) | U14: =IF(D14="","",IFERROR(INDEX(Exercises!$C$6:$C$105,MATCH(D14,Exercises!$B$6:$B$105,0)),"Other")) | V14: =IF(B14="","",IF(COUNTIF($B$6:B14,B14)=1,1,0)) | W14: =IF(B14="","",B14-WEEKDAY(B14,3)) | X14: =IF(D14="","",MAX(IF(N(F14)=0,0,IF(N(E14)>0,E14*(1+F14/30),F14)),IF(N(H14)=0,0,IF(N(G14)>0,G14*(1+H14/30),H14)),IF(N(J14)=0,0,IF(N(I14)>0,I14*(1+J14/30),J14)),IF(N(L14)=0,0,IF(N(K14)>0,K14*(1+L14/30),L14)),IF(N(N14)=0,0,IF(N(M14)>0,M14*(1+N14/30),N14)))) | Y14: =IF(N(X14)=0,"",X14+ROW()/1000000000) | Z14: =IF(Y14="","",IF(COUNTIFS(Log!$D$6:$D$1505,D14,Log!$Y$6:$Y$1505,">"&Y14)=0,1,0)) | AA14: =IF(OR(B14="",D14=""),"",B14+ROW()/10000000) | AB14: =IF(AA14="","",IF(COUNTIFS(Log!$D$6:$D$1505,D14,Log!$AA$6:$AA$1505,">"&AA14)=0,1,0)) | AC14: =IF(S14="New best",AA14,"") | AD14: =ROW()
B15: 46210 | C15: Pull | D15: Biceps curl | E15: 25 | F15: 11 | G15: 25 | H15: 11 | I15: 25 | J15: 10 | O15: =IF(D15="","",COUNT(F15,H15,J15,L15,N15)) | P15: =IF(D15="","",N(E15)*N(F15)+N(G15)*N(H15)+N(I15)*N(J15)+N(K15)*N(L15)+N(M15)*N(N15)) | Q15: =IF(N(X15)=0,"",IF(IF(N(F15)=0,0,IF(N(E15)>0,E15*(1+F15/30),F15))=X15,IF(N(E15)>0,E15&" x "&F15,F15&" reps"),IF(IF(N(H15)=0,0,IF(N(G15)>0,G15*(1+H15/30),H15))=X15,IF(N(G15)>0,G15&" x "&H15,H15&" reps"),IF(IF(N(J15)=0,0,IF(N(I15)>0,I15*(1+J15/30),J15))=X15,IF(N(I15)>0,I15&" x "&J15,J15&" reps"),IF(IF(N(L15)=0,0,IF(N(K15)>0,K15*(1+L15/30),L15))=X15,IF(N(K15)>0,K15&" x "&L15,L15&" reps"),IF(IF(N(N15)=0,0,IF(N(M15)>0,M15*(1+N15/30),N15))=X15,IF(N(M15)>0,M15&" x "&N15,N15&" reps"),"")))))) | R15: =IF(N(X15)=0,"",ROUND(X15,1)) | S15: =IF(N(X15)=0,"",IF(AND(COUNTIFS(Log!$D$6:$D$1505,D15,Log!$B$6:$B$1505,"<"&B15)>0,COUNTIFS(Log!$D$6:$D$1505,D15,Log!$B$6:$B$1505,"<"&B15,Log!$X$6:$X$1505,">="&X15)=0),"New best","")) | U15: =IF(D15="","",IFERROR(INDEX(Exercises!$C$6:$C$105,MATCH(D15,Exercises!$B$6:$B$105,0)),"Other")) | V15: =IF(B15="","",IF(COUNTIF($B$6:B15,B15)=1,1,0)) | W15: =IF(B15="","",B15-WEEKDAY(B15,3)) | X15: =IF(D15="","",MAX(IF(N(F15)=0,0,IF(N(E15)>0,E15*(1+F15/30),F15)),IF(N(H15)=0,0,IF(N(G15)>0,G15*(1+H15/30),H15)),IF(N(J15)=0,0,IF(N(I15)>0,I15*(1+J15/30),J15)),IF(N(L15)=0,0,IF(N(K15)>0,K15*(1+L15/30),L15)),IF(N(N15)=0,0,IF(N(M15)>0,M15*(1+N15/30),N15)))) | Y15: =IF(N(X15)=0,"",X15+ROW()/1000000000) | Z15: =IF(Y15="","",IF(COUNTIFS(Log!$D$6:$D$1505,D15,Log!$Y$6:$Y$1505,">"&Y15)=0,1,0)) | AA15: =IF(OR(B15="",D15=""),"",B15+ROW()/10000000) | AB15: =IF(AA15="","",IF(COUNTIFS(Log!$D$6:$D$1505,D15,Log!$AA$6:$AA$1505,">"&AA15)=0,1,0)) | AC15: =IF(S15="New best",AA15,"") | AD15: =ROW()
B16: 46211 | C16: Legs | D16: Squat | E16: 185 | F16: 6 | G16: 185 | H16: 5 | I16: 185 | J16: 5 | K16: 185 | L16: 5 | O16: =IF(D16="","",COUNT(F16,H16,J16,L16,N16)) | P16: =IF(D16="","",N(E16)*N(F16)+N(G16)*N(H16)+N(I16)*N(J16)+N(K16)*N(L16)+N(M16)*N(N16)) | Q16: =IF(N(X16)=0,"",IF(IF(N(F16)=0,0,IF(N(E16)>0,E16*(1+F16/30),F16))=X16,IF(N(E16)>0,E16&" x "&F16,F16&" reps"),IF(IF(N(H16)=0,0,IF(N(G16)>0,G16*(1+H16/30),H16))=X16,IF(N(G16)>0,G16&" x "&H16,H16&" reps"),IF(IF(N(J16)=0,0,IF(N(I16)>0,I16*(1+J16/30),J16))=X16,IF(N(I16)>0,I16&" x "&J16,J16&" reps"),IF(IF(N(L16)=0,0,IF(N(K16)>0,K16*(1+L16/30),L16))=X16,IF(N(K16)>0,K16&" x "&L16,L16&" reps"),IF(IF(N(N16)=0,0,IF(N(M16)>0,M16*(1+N16/30),N16))=X16,IF(N(M16)>0,M16&" x "&N16,N16&" reps"),"")))))) | R16: =IF(N(X16)=0,"",ROUND(X16,1)) | S16: =IF(N(X16)=0,"",IF(AND(COUNTIFS(Log!$D$6:$D$1505,D16,Log!$B$6:$B$1505,"<"&B16)>0,COUNTIFS(Log!$D$6:$D$1505,D16,Log!$B$6:$B$1505,"<"&B16,Log!$X$6:$X$1505,">="&X16)=0),"New best","")) | U16: =IF(D16="","",IFERROR(INDEX(Exercises!$C$6:$C$105,MATCH(D16,Exercises!$B$6:$B$105,0)),"Other")) | V16: =IF(B16="","",IF(COUNTIF($B$6:B16,B16)=1,1,0)) | W16: =IF(B16="","",B16-WEEKDAY(B16,3)) | X16: =IF(D16="","",MAX(IF(N(F16)=0,0,IF(N(E16)>0,E16*(1+F16/30),F16)),IF(N(H16)=0,0,IF(N(G16)>0,G16*(1+H16/30),H16)),IF(N(J16)=0,0,IF(N(I16)>0,I16*(1+J16/30),J16)),IF(N(L16)=0,0,IF(N(K16)>0,K16*(1+L16/30),L16)),IF(N(N16)=0,0,IF(N(M16)>0,M16*(1+N16/30),N16)))) | Y16: =IF(N(X16)=0,"",X16+ROW()/1000000000) | Z16: =IF(Y16="","",IF(COUNTIFS(Log!$D$6:$D$1505,D16,Log!$Y$6:$Y$1505,">"&Y16)=0,1,0)) | AA16: =IF(OR(B16="",D16=""),"",B16+ROW()/10000000) | AB16: =IF(AA16="","",IF(COUNTIFS(Log!$D$6:$D$1505,D16,Log!$AA$6:$AA$1505,">"&AA16)=0,1,0)) | AC16: =IF(S16="New best",AA16,"") | AD16: =ROW()
B17: 46211 | C17: Legs | D17: Romanian deadlift | E17: 155 | F17: 10 | G17: 155 | H17: 8 | I17: 155 | J17: 8 | O17: =IF(D17="","",COUNT(F17,H17,J17,L17,N17)) | P17: =IF(D17="","",N(E17)*N(F17)+N(G17)*N(H17)+N(I17)*N(J17)+N(K17)*N(L17)+N(M17)*N(N17)) | Q17: =IF(N(X17)=0,"",IF(IF(N(F17)=0,0,IF(N(E17)>0,E17*(1+F17/30),F17))=X17,IF(N(E17)>0,E17&" x "&F17,F17&" reps"),IF(IF(N(H17)=0,0,IF(N(G17)>0,G17*(1+H17/30),H17))=X17,IF(N(G17)>0,G17&" x "&H17,H17&" reps"),IF(IF(N(J17)=0,0,IF(N(I17)>0,I17*(1+J17/30),J17))=X17,IF(N(I17)>0,I17&" x "&J17,J17&" reps"),IF(IF(N(L17)=0,0,IF(N(K17)>0,K17*(1+L17/30),L17))=X17,IF(N(K17)>0,K17&" x "&L17,L17&" reps"),IF(IF(N(N17)=0,0,IF(N(M17)>0,M17*(1+N17/30),N17))=X17,IF(N(M17)>0,M17&" x "&N17,N17&" reps"),"")))))) | R17: =IF(N(X17)=0,"",ROUND(X17,1)) | S17: =IF(N(X17)=0,"",IF(AND(COUNTIFS(Log!$D$6:$D$1505,D17,Log!$B$6:$B$1505,"<"&B17)>0,COUNTIFS(Log!$D$6:$D$1505,D17,Log!$B$6:$B$1505,"<"&B17,Log!$X$6:$X$1505,">="&X17)=0),"New best","")) | U17: =IF(D17="","",IFERROR(INDEX(Exercises!$C$6:$C$105,MATCH(D17,Exercises!$B$6:$B$105,0)),"Other")) | V17: =IF(B17="","",IF(COUNTIF($B$6:B17,B17)=1,1,0)) | W17: =IF(B17="","",B17-WEEKDAY(B17,3)) | X17: =IF(D17="","",MAX(IF(N(F17)=0,0,IF(N(E17)>0,E17*(1+F17/30),F17)),IF(N(H17)=0,0,IF(N(G17)>0,G17*(1+H17/30),H17)),IF(N(J17)=0,0,IF(N(I17)>0,I17*(1+J17/30),J17)),IF(N(L17)=0,0,IF(N(K17)>0,K17*(1+L17/30),L17)),IF(N(N17)=0,0,IF(N(M17)>0,M17*(1+N17/30),N17)))) | Y17: =IF(N(X17)=0,"",X17+ROW()/1000000000) | Z17: =IF(Y17="","",IF(COUNTIFS(Log!$D$6:$D$1505,D17,Log!$Y$6:$Y$1505,">"&Y17)=0,1,0)) | AA17: =IF(OR(B17="",D17=""),"",B17+ROW()/10000000) | AB17: =IF(AA17="","",IF(COUNTIFS(Log!$D$6:$D$1505,D17,Log!$AA$6:$AA$1505,">"&AA17)=0,1,0)) | AC17: =IF(S17="New best",AA17,"") | AD17: =ROW()
B18: 46211 | C18: Legs | D18: Leg press | E18: 270 | F18: 11 | G18: 270 | H18: 10 | I18: 270 | J18: 10 | O18: =IF(D18="","",COUNT(F18,H18,J18,L18,N18)) | P18: =IF(D18="","",N(E18)*N(F18)+N(G18)*N(H18)+N(I18)*N(J18)+N(K18)*N(L18)+N(M18)*N(N18)) | Q18: =IF(N(X18)=0,"",IF(IF(N(F18)=0,0,IF(N(E18)>0,E18*(1+F18/30),F18))=X18,IF(N(E18)>0,E18&" x "&F18,F18&" reps"),IF(IF(N(H18)=0,0,IF(N(G18)>0,G18*(1+H18/30),H18))=X18,IF(N(G18)>0,G18&" x "&H18,H18&" reps"),IF(IF(N(J18)=0,0,IF(N(I18)>0,I18*(1+J18/30),J18))=X18,IF(N(I18)>0,I18&" x "&J18,J18&" reps"),IF(IF(N(L18)=0,0,IF(N(K18)>0,K18*(1+L18/30),L18))=X18,IF(N(K18)>0,K18&" x "&L18,L18&" reps"),IF(IF(N(N18)=0,0,IF(N(M18)>0,M18*(1+N18/30),N18))=X18,IF(N(M18)>0,M18&" x "&N18,N18&" reps"),"")))))) | R18: =IF(N(X18)=0,"",ROUND(X18,1)) | S18: =IF(N(X18)=0,"",IF(AND(COUNTIFS(Log!$D$6:$D$1505,D18,Log!$B$6:$B$1505,"<"&B18)>0,COUNTIFS(Log!$D$6:$D$1505,D18,Log!$B$6:$B$1505,"<"&B18,Log!$X$6:$X$1505,">="&X18)=0),"New best","")) | U18: =IF(D18="","",IFERROR(INDEX(Exercises!$C$6:$C$105,MATCH(D18,Exercises!$B$6:$B$105,0)),"Other")) | V18: =IF(B18="","",IF(COUNTIF($B$6:B18,B18)=1,1,0)) | W18: =IF(B18="","",B18-WEEKDAY(B18,3)) | X18: =IF(D18="","",MAX(IF(N(F18)=0,0,IF(N(E18)>0,E18*(1+F18/30),F18)),IF(N(H18)=0,0,IF(N(G18)>0,G18*(1+H18/30),H18)),IF(N(J18)=0,0,IF(N(I18)>0,I18*(1+J18/30),J18)),IF(N(L18)=0,0,IF(N(K18)>0,K18*(1+L18/30),L18)),IF(N(N18)=0,0,IF(N(M18)>0,M18*(1+N18/30),N18)))) | Y18: =IF(N(X18)=0,"",X18+ROW()/1000000000) | Z18: =IF(Y18="","",IF(COUNTIFS(Log!$D$6:$D$1505,D18,Log!$Y$6:$Y$1505,">"&Y18)=0,1,0)) | AA18: =IF(OR(B18="",D18=""),"",B18+ROW()/10000000) | AB18: =IF(AA18="","",IF(COUNTIFS(Log!$D$6:$D$1505,D18,Log!$AA$6:$AA$1505,">"&AA18)=0,1,0)) | AC18: =IF(S18="New best",AA18,"") | AD18: =ROW()
B19: 46211 | C19: Legs | D19: Leg curl | E19: 70 | F19: 12 | G19: 70 | H19: 10 | I19: 70 | J19: 10 | O19: =IF(D19="","",COUNT(F19,H19,J19,L19,N19)) | P19: =IF(D19="","",N(E19)*N(F19)+N(G19)*N(H19)+N(I19)*N(J19)+N(K19)*N(L19)+N(M19)*N(N19)) | Q19: =IF(N(X19)=0,"",IF(IF(N(F19)=0,0,IF(N(E19)>0,E19*(1+F19/30),F19))=X19,IF(N(E19)>0,E19&" x "&F19,F19&" reps"),IF(IF(N(H19)=0,0,IF(N(G19)>0,G19*(1+H19/30),H19))=X19,IF(N(G19)>0,G19&" x "&H19,H19&" reps"),IF(IF(N(J19)=0,0,IF(N(I19)>0,I19*(1+J19/30),J19))=X19,IF(N(I19)>0,I19&" x "&J19,J19&" reps"),IF(IF(N(L19)=0,0,IF(N(K19)>0,K19*(1+L19/30),L19))=X19,IF(N(K19)>0,K19&" x "&L19,L19&" reps"),IF(IF(N(N19)=0,0,IF(N(M19)>0,M19*(1+N19/30),N19))=X19,IF(N(M19)>0,M19&" x "&N19,N19&" reps"),"")))))) | R19: =IF(N(X19)=0,"",ROUND(X19,1)) | S19: =IF(N(X19)=0,"",IF(AND(COUNTIFS(Log!$D$6:$D$1505,D19,Log!$B$6:$B$1505,"<"&B19)>0,COUNTIFS(Log!$D$6:$D$1505,D19,Log!$B$6:$B$1505,"<"&B19,Log!$X$6:$X$1505,">="&X19)=0),"New best","")) | U19: =IF(D19="","",IFERROR(INDEX(Exercises!$C$6:$C$105,MATCH(D19,Exercises!$B$6:$B$105,0)),"Other")) | V19: =IF(B19="","",IF(COUNTIF($B$6:B19,B19)=1,1,0)) | W19: =IF(B19="","",B19-WEEKDAY(B19,3)) | X19: =IF(D19="","",MAX(IF(N(F19)=0,0,IF(N(E19)>0,E19*(1+F19/30),F19)),IF(N(H19)=0,0,IF(N(G19)>0,G19*(1+H19/30),H19)),IF(N(J19)=0,0,IF(N(I19)>0,I19*(1+J19/30),J19)),IF(N(L19)=0,0,IF(N(K19)>0,K19*(1+L19/30),L19)),IF(N(N19)=0,0,IF(N(M19)>0,M19*(1+N19/30),N19)))) | Y19: =IF(N(X19)=0,"",X19+ROW()/1000000000) | Z19: =IF(Y19="","",IF(COUNTIFS(Log!$D$6:$D$1505,D19,Log!$Y$6:$Y$1505,">"&Y19)=0,1,0)) | AA19: =IF(OR(B19="",D19=""),"",B19+ROW()/10000000) | AB19: =IF(AA19="","",IF(COUNTIFS(Log!$D$6:$D$1505,D19,Log!$AA$6:$AA$1505,">"&AA19)=0,1,0)) | AC19: =IF(S19="New best",AA19,"") | AD19: =ROW()
B20: 46211 | C20: Legs | D20: Calf raise | E20: 90 | F20: 15 | G20: 90 | H20: 13 | I20: 90 | J20: 13 | K20: 90 | L20: 12 | O20: =IF(D20="","",COUNT(F20,H20,J20,L20,N20)) | P20: =IF(D20="","",N(E20)*N(F20)+N(G20)*N(H20)+N(I20)*N(J20)+N(K20)*N(L20)+N(M20)*N(N20)) | Q20: =IF(N(X20)=0,"",IF(IF(N(F20)=0,0,IF(N(E20)>0,E20*(1+F20/30),F20))=X20,IF(N(E20)>0,E20&" x "&F20,F20&" reps"),IF(IF(N(H20)=0,0,IF(N(G20)>0,G20*(1+H20/30),H20))=X20,IF(N(G20)>0,G20&" x "&H20,H20&" reps"),IF(IF(N(J20)=0,0,IF(N(I20)>0,I20*(1+J20/30),J20))=X20,IF(N(I20)>0,I20&" x "&J20,J20&" reps"),IF(IF(N(L20)=0,0,IF(N(K20)>0,K20*(1+L20/30),L20))=X20,IF(N(K20)>0,K20&" x "&L20,L20&" reps"),IF(IF(N(N20)=0,0,IF(N(M20)>0,M20*(1+N20/30),N20))=X20,IF(N(M20)>0,M20&" x "&N20,N20&" reps"),"")))))) | R20: =IF(N(X20)=0,"",ROUND(X20,1)) | S20: =IF(N(X20)=0,"",IF(AND(COUNTIFS(Log!$D$6:$D$1505,D20,Log!$B$6:$B$1505,"<"&B20)>0,COUNTIFS(Log!$D$6:$D$1505,D20,Log!$B$6:$B$1505,"<"&B20,Log!$X$6:$X$1505,">="&X20)=0),"New best","")) | U20: =IF(D20="","",IFERROR(INDEX(Exercises!$C$6:$C$105,MATCH(D20,Exercises!$B$6:$B$105,0)),"Other")) | V20: =IF(B20="","",IF(COUNTIF($B$6:B20,B20)=1,1,0)) | W20: =IF(B20="","",B20-WEEKDAY(B20,3)) | X20: =IF(D20="","",MAX(IF(N(F20)=0,0,IF(N(E20)>0,E20*(1+F20/30),F20)),IF(N(H20)=0,0,IF(N(G20)>0,G20*(1+H20/30),H20)),IF(N(J20)=0,0,IF(N(I20)>0,I20*(1+J20/30),J20)),IF(N(L20)=0,0,IF(N(K20)>0,K20*(1+L20/30),L20)),IF(N(N20)=0,0,IF(N(M20)>0,M20*(1+N20/30),N20)))) | Y20: =IF(N(X20)=0,"",X20+ROW()/1000000000) | Z20: =IF(Y20="","",IF(COUNTIFS(Log!$D$6:$D$1505,D20,Log!$Y$6:$Y$1505,">"&Y20)=0,1,0)) | AA20: =IF(OR(B20="",D20=""),"",B20+ROW()/10000000) | AB20: =IF(AA20="","",IF(COUNTIFS(Log!$D$6:$D$1505,D20,Log!$AA$6:$AA$1505,">"&AA20)=0,1,0)) | AC20: =IF(S20="New best",AA20,"") | AD20: =ROW()
B21: 46214 | C21: Lower | D21: Squat | E21: 165 | F21: 8 | G21: 165 | H21: 8 | I21: 165 | J21: 8 | O21: =IF(D21="","",COUNT(F21,H21,J21,L21,N21)) | P21: =IF(D21="","",N(E21)*N(F21)+N(G21)*N(H21)+N(I21)*N(J21)+N(K21)*N(L21)+N(M21)*N(N21)) | Q21: =IF(N(X21)=0,"",IF(IF(N(F21)=0,0,IF(N(E21)>0,E21*(1+F21/30),F21))=X21,IF(N(E21)>0,E21&" x "&F21,F21&" reps"),IF(IF(N(H21)=0,0,IF(N(G21)>0,G21*(1+H21/30),H21))=X21,IF(N(G21)>0,G21&" x "&H21,H21&" reps"),IF(IF(N(J21)=0,0,IF(N(I21)>0,I21*(1+J21/30),J21))=X21,IF(N(I21)>0,I21&" x "&J21,J21&" reps"),IF(IF(N(L21)=0,0,IF(N(K21)>0,K21*(1+L21/30),L21))=X21,IF(N(K21)>0,K21&" x "&L21,L21&" reps"),IF(IF(N(N21)=0,0,IF(N(M21)>0,M21*(1+N21/30),N21))=X21,IF(N(M21)>0,M21&" x "&N21,N21&" reps"),"")))))) | R21: =IF(N(X21)=0,"",ROUND(X21,1)) | S21: =IF(N(X21)=0,"",IF(AND(COUNTIFS(Log!$D$6:$D$1505,D21,Log!$B$6:$B$1505,"<"&B21)>0,COUNTIFS(Log!$D$6:$D$1505,D21,Log!$B$6:$B$1505,"<"&B21,Log!$X$6:$X$1505,">="&X21)=0),"New best","")) | T21: Felt strong | U21: =IF(D21="","",IFERROR(INDEX(Exercises!$C$6:$C$105,MATCH(D21,Exercises!$B$6:$B$105,0)),"Other")) | V21: =IF(B21="","",IF(COUNTIF($B$6:B21,B21)=1,1,0)) | W21: =IF(B21="","",B21-WEEKDAY(B21,3)) | X21: =IF(D21="","",MAX(IF(N(F21)=0,0,IF(N(E21)>0,E21*(1+F21/30),F21)),IF(N(H21)=0,0,IF(N(G21)>0,G21*(1+H21/30),H21)),IF(N(J21)=0,0,IF(N(I21)>0,I21*(1+J21/30),J21)),IF(N(L21)=0,0,IF(N(K21)>0,K21*(1+L21/30),L21)),IF(N(N21)=0,0,IF(N(M21)>0,M21*(1+N21/30),N21)))) | Y21: =IF(N(X21)=0,"",X21+ROW()/1000000000) | Z21: =IF(Y21="","",IF(COUNTIFS(Log!$D$6:$D$1505,D21,Log!$Y$6:$Y$1505,">"&Y21)=0,1,0)) | AA21: =IF(OR(B21="",D21=""),"",B21+ROW()/10000000) | AB21: =IF(AA21="","",IF(COUNTIFS(Log!$D$6:$D$1505,D21,Log!$AA$6:$AA$1505,">"&AA21)=0,1,0)) | AC21: =IF(S21="New best",AA21,"") | AD21: =ROW()
B22: 46214 | C22: Lower | D22: Romanian deadlift | E22: 140 | F22: 10 | G22: 140 | H22: 9 | I22: 140 | J22: 8 | O22: =IF(D22="","",COUNT(F22,H22,J22,L22,N22)) | P22: =IF(D22="","",N(E22)*N(F22)+N(G22)*N(H22)+N(I22)*N(J22)+N(K22)*N(L22)+N(M22)*N(N22)) | Q22: =IF(N(X22)=0,"",IF(IF(N(F22)=0,0,IF(N(E22)>0,E22*(1+F22/30),F22))=X22,IF(N(E22)>0,E22&" x "&F22,F22&" reps"),IF(IF(N(H22)=0,0,IF(N(G22)>0,G22*(1+H22/30),H22))=X22,IF(N(G22)>0,G22&" x "&H22,H22&" reps"),IF(IF(N(J22)=0,0,IF(N(I22)>0,I22*(1+J22/30),J22))=X22,IF(N(I22)>0,I22&" x "&J22,J22&" reps"),IF(IF(N(L22)=0,0,IF(N(K22)>0,K22*(1+L22/30),L22))=X22,IF(N(K22)>0,K22&" x "&L22,L22&" reps"),IF(IF(N(N22)=0,0,IF(N(M22)>0,M22*(1+N22/30),N22))=X22,IF(N(M22)>0,M22&" x "&N22,N22&" reps"),"")))))) | R22: =IF(N(X22)=0,"",ROUND(X22,1)) | S22: =IF(N(X22)=0,"",IF(AND(COUNTIFS(Log!$D$6:$D$1505,D22,Log!$B$6:$B$1505,"<"&B22)>0,COUNTIFS(Log!$D$6:$D$1505,D22,Log!$B$6:$B$1505,"<"&B22,Log!$X$6:$X$1505,">="&X22)=0),"New best","")) | U22: =IF(D22="","",IFERROR(INDEX(Exercises!$C$6:$C$105,MATCH(D22,Exercises!$B$6:$B$105,0)),"Other")) | V22: =IF(B22="","",IF(COUNTIF($B$6:B22,B22)=1,1,0)) | W22: =IF(B22="","",B22-WEEKDAY(B22,3)) | X22: =IF(D22="","",MAX(IF(N(F22)=0,0,IF(N(E22)>0,E22*(1+F22/30),F22)),IF(N(H22)=0,0,IF(N(G22)>0,G22*(1+H22/30),H22)),IF(N(J22)=0,0,IF(N(I22)>0,I22*(1+J22/30),J22)),IF(N(L22)=0,0,IF(N(K22)>0,K22*(1+L22/30),L22)),IF(N(N22)=0,0,IF(N(M22)>0,M22*(1+N22/30),N22)))) | Y22: =IF(N(X22)=0,"",X22+ROW()/1000000000) | Z22: =IF(Y22="","",IF(COUNTIFS(Log!$D$6:$D$1505,D22,Log!$Y$6:$Y$1505,">"&Y22)=0,1,0)) | AA22: =IF(OR(B22="",D22=""),"",B22+ROW()/10000000) | AB22: =IF(AA22="","",IF(COUNTIFS(Log!$D$6:$D$1505,D22,Log!$AA$6:$AA$1505,">"&AA22)=0,1,0)) | AC22: =IF(S22="New best",AA22,"") | AD22: =ROW()
B23: 46214 | C23: Lower | D23: Leg press | E23: 245 | F23: 15 | G23: 245 | H23: 13 | I23: 245 | J23: 12 | O23: =IF(D23="","",COUNT(F23,H23,J23,L23,N23)) | P23: =IF(D23="","",N(E23)*N(F23)+N(G23)*N(H23)+N(I23)*N(J23)+N(K23)*N(L23)+N(M23)*N(N23)) | Q23: =IF(N(X23)=0,"",IF(IF(N(F23)=0,0,IF(N(E23)>0,E23*(1+F23/30),F23))=X23,IF(N(E23)>0,E23&" x "&F23,F23&" reps"),IF(IF(N(H23)=0,0,IF(N(G23)>0,G23*(1+H23/30),H23))=X23,IF(N(G23)>0,G23&" x "&H23,H23&" reps"),IF(IF(N(J23)=0,0,IF(N(I23)>0,I23*(1+J23/30),J23))=X23,IF(N(I23)>0,I23&" x "&J23,J23&" reps"),IF(IF(N(L23)=0,0,IF(N(K23)>0,K23*(1+L23/30),L23))=X23,IF(N(K23)>0,K23&" x "&L23,L23&" reps"),IF(IF(N(N23)=0,0,IF(N(M23)>0,M23*(1+N23/30),N23))=X23,IF(N(M23)>0,M23&" x "&N23,N23&" reps"),"")))))) | R23: =IF(N(X23)=0,"",ROUND(X23,1)) | S23: =IF(N(X23)=0,"",IF(AND(COUNTIFS(Log!$D$6:$D$1505,D23,Log!$B$6:$B$1505,"<"&B23)>0,COUNTIFS(Log!$D$6:$D$1505,D23,Log!$B$6:$B$1505,"<"&B23,Log!$X$6:$X$1505,">="&X23)=0),"New best","")) | T23: Slept badly | U23: =IF(D23="","",IFERROR(INDEX(Exercises!$C$6:$C$105,MATCH(D23,Exercises!$B$6:$B$105,0)),"Other")) | V23: =IF(B23="","",IF(COUNTIF($B$6:B23,B23)=1,1,0)) | W23: =IF(B23="","",B23-WEEKDAY(B23,3)) | X23: =IF(D23="","",MAX(IF(N(F23)=0,0,IF(N(E23)>0,E23*(1+F23/30),F23)),IF(N(H23)=0,0,IF(N(G23)>0,G23*(1+H23/30),H23)),IF(N(J23)=0,0,IF(N(I23)>0,I23*(1+J23/30),J23)),IF(N(L23)=0,0,IF(N(K23)>0,K23*(1+L23/30),L23)),IF(N(N23)=0,0,IF(N(M23)>0,M23*(1+N23/30),N23)))) | Y23: =IF(N(X23)=0,"",X23+ROW()/1000000000) | Z23: =IF(Y23="","",IF(COUNTIFS(Log!$D$6:$D$1505,D23,Log!$Y$6:$Y$1505,">"&Y23)=0,1,0)) | AA23: =IF(OR(B23="",D23=""),"",B23+ROW()/10000000) | AB23: =IF(AA23="","",IF(COUNTIFS(Log!$D$6:$D$1505,D23,Log!$AA$6:$AA$1505,">"&AA23)=0,1,0)) | AC23: =IF(S23="New best",AA23,"") | AD23: =ROW()
B24: 46214 | C24: Lower | D24: Calf raise | E24: 80 | F24: 15 | G24: 80 | H24: 15 | I24: 80 | J24: 15 | O24: =IF(D24="","",COUNT(F24,H24,J24,L24,N24)) | P24: =IF(D24="","",N(E24)*N(F24)+N(G24)*N(H24)+N(I24)*N(J24)+N(K24)*N(L24)+N(M24)*N(N24)) | Q24: =IF(N(X24)=0,"",IF(IF(N(F24)=0,0,IF(N(E24)>0,E24*(1+F24/30),F24))=X24,IF(N(E24)>0,E24&" x "&F24,F24&" reps"),IF(IF(N(H24)=0,0,IF(N(G24)>0,G24*(1+H24/30),H24))=X24,IF(N(G24)>0,G24&" x "&H24,H24&" reps"),IF(IF(N(J24)=0,0,IF(N(I24)>0,I24*(1+J24/30),J24))=X24,IF(N(I24)>0,I24&" x "&J24,J24&" reps"),IF(IF(N(L24)=0,0,IF(N(K24)>0,K24*(1+L24/30),L24))=X24,IF(N(K24)>0,K24&" x "&L24,L24&" reps"),IF(IF(N(N24)=0,0,IF(N(M24)>0,M24*(1+N24/30),N24))=X24,IF(N(M24)>0,M24&" x "&N24,N24&" reps"),"")))))) | R24: =IF(N(X24)=0,"",ROUND(X24,1)) | S24: =IF(N(X24)=0,"",IF(AND(COUNTIFS(Log!$D$6:$D$1505,D24,Log!$B$6:$B$1505,"<"&B24)>0,COUNTIFS(Log!$D$6:$D$1505,D24,Log!$B$6:$B$1505,"<"&B24,Log!$X$6:$X$1505,">="&X24)=0),"New best","")) | U24: =IF(D24="","",IFERROR(INDEX(Exercises!$C$6:$C$105,MATCH(D24,Exercises!$B$6:$B$105,0)),"Other")) | V24: =IF(B24="","",IF(COUNTIF($B$6:B24,B24)=1,1,0)) | W24: =IF(B24="","",B24-WEEKDAY(B24,3)) | X24: =IF(D24="","",MAX(IF(N(F24)=0,0,IF(N(E24)>0,E24*(1+F24/30),F24)),IF(N(H24)=0,0,IF(N(G24)>0,G24*(1+H24/30),H24)),IF(N(J24)=0,0,IF(N(I24)>0,I24*(1+J24/30),J24)),IF(N(L24)=0,0,IF(N(K24)>0,K24*(1+L24/30),L24)),IF(N(N24)=0,0,IF(N(M24)>0,M24*(1+N24/30),N24)))) | Y24: =IF(N(X24)=0,"",X24+ROW()/1000000000) | Z24: =IF(Y24="","",IF(COUNTIFS(Log!$D$6:$D$1505,D24,Log!$Y$6:$Y$1505,">"&Y24)=0,1,0)) | AA24: =IF(OR(B24="",D24=""),"",B24+ROW()/10000000) | AB24: =IF(AA24="","",IF(COUNTIFS(Log!$D$6:$D$1505,D24,Log!$AA$6:$AA$1505,">"&AA24)=0,1,0)) | AC24: =IF(S24="New best",AA24,"") | AD24: =ROW()
B25: 46216 | C25: Push | D25: Bench press | E25: 135 | F25: 7 | G25: 135 | H25: 6 | I25: 135 | J25: 6 | K25: 135 | L25: 6 | O25: =IF(D25="","",COUNT(F25,H25,J25,L25,N25)) | P25: =IF(D25="","",N(E25)*N(F25)+N(G25)*N(H25)+N(I25)*N(J25)+N(K25)*N(L25)+N(M25)*N(N25)) | Q25: =IF(N(X25)=0,"",IF(IF(N(F25)=0,0,IF(N(E25)>0,E25*(1+F25/30),F25))=X25,IF(N(E25)>0,E25&" x "&F25,F25&" reps"),IF(IF(N(H25)=0,0,IF(N(G25)>0,G25*(1+H25/30),H25))=X25,IF(N(G25)>0,G25&" x "&H25,H25&" reps"),IF(IF(N(J25)=0,0,IF(N(I25)>0,I25*(1+J25/30),J25))=X25,IF(N(I25)>0,I25&" x "&J25,J25&" reps"),IF(IF(N(L25)=0,0,IF(N(K25)>0,K25*(1+L25/30),L25))=X25,IF(N(K25)>0,K25&" x "&L25,L25&" reps"),IF(IF(N(N25)=0,0,IF(N(M25)>0,M25*(1+N25/30),N25))=X25,IF(N(M25)>0,M25&" x "&N25,N25&" reps"),"")))))) | R25: =IF(N(X25)=0,"",ROUND(X25,1)) | S25: =IF(N(X25)=0,"",IF(AND(COUNTIFS(Log!$D$6:$D$1505,D25,Log!$B$6:$B$1505,"<"&B25)>0,COUNTIFS(Log!$D$6:$D$1505,D25,Log!$B$6:$B$1505,"<"&B25,Log!$X$6:$X$1505,">="&X25)=0),"New best","")) | U25: =IF(D25="","",IFERROR(INDEX(Exercises!$C$6:$C$105,MATCH(D25,Exercises!$B$6:$B$105,0)),"Other")) | V25: =IF(B25="","",IF(COUNTIF($B$6:B25,B25)=1,1,0)) | W25: =IF(B25="","",B25-WEEKDAY(B25,3)) | X25: =IF(D25="","",MAX(IF(N(F25)=0,0,IF(N(E25)>0,E25*(1+F25/30),F25)),IF(N(H25)=0,0,IF(N(G25)>0,G25*(1+H25/30),H25)),IF(N(J25)=0,0,IF(N(I25)>0,I25*(1+J25/30),J25)),IF(N(L25)=0,0,IF(N(K25)>0,K25*(1+L25/30),L25)),IF(N(N25)=0,0,IF(N(M25)>0,M25*(1+N25/30),N25)))) | Y25: =IF(N(X25)=0,"",X25+ROW()/1000000000) | Z25: =IF(Y25="","",IF(COUNTIFS(Log!$D$6:$D$1505,D25,Log!$Y$6:$Y$1505,">"&Y25)=0,1,0)) | AA25: =IF(OR(B25="",D25=""),"",B25+ROW()/10000000) | AB25: =IF(AA25="","",IF(COUNTIFS(Log!$D$6:$D$1505,D25,Log!$AA$6:$AA$1505,">"&AA25)=0,1,0)) | AC25: =IF(S25="New best",AA25,"") | AD25: =ROW()
B26: 46216 | C26: Push | D26: Overhead press | E26: 85 | F26: 10 | G26: 85 | H26: 8 | I26: 85 | J26: 8 | O26: =IF(D26="","",COUNT(F26,H26,J26,L26,N26)) | P26: =IF(D26="","",N(E26)*N(F26)+N(G26)*N(H26)+N(I26)*N(J26)+N(K26)*N(L26)+N(M26)*N(N26)) | Q26: =IF(N(X26)=0,"",IF(IF(N(F26)=0,0,IF(N(E26)>0,E26*(1+F26/30),F26))=X26,IF(N(E26)>0,E26&" x "&F26,F26&" reps"),IF(IF(N(H26)=0,0,IF(N(G26)>0,G26*(1+H26/30),H26))=X26,IF(N(G26)>0,G26&" x "&H26,H26&" reps"),IF(IF(N(J26)=0,0,IF(N(I26)>0,I26*(1+J26/30),J26))=X26,IF(N(I26)>0,I26&" x "&J26,J26&" reps"),IF(IF(N(L26)=0,0,IF(N(K26)>0,K26*(1+L26/30),L26))=X26,IF(N(K26)>0,K26&" x "&L26,L26&" reps"),IF(IF(N(N26)=0,0,IF(N(M26)>0,M26*(1+N26/30),N26))=X26,IF(N(M26)>0,M26&" x "&N26,N26&" reps"),"")))))) | R26: =IF(N(X26)=0,"",ROUND(X26,1)) | S26: =IF(N(X26)=0,"",IF(AND(COUNTIFS(Log!$D$6:$D$1505,D26,Log!$B$6:$B$1505,"<"&B26)>0,COUNTIFS(Log!$D$6:$D$1505,D26,Log!$B$6:$B$1505,"<"&B26,Log!$X$6:$X$1505,">="&X26)=0),"New best","")) | U26: =IF(D26="","",IFERROR(INDEX(Exercises!$C$6:$C$105,MATCH(D26,Exercises!$B$6:$B$105,0)),"Other")) | V26: =IF(B26="","",IF(COUNTIF($B$6:B26,B26)=1,1,0)) | W26: =IF(B26="","",B26-WEEKDAY(B26,3)) | X26: =IF(D26="","",MAX(IF(N(F26)=0,0,IF(N(E26)>0,E26*(1+F26/30),F26)),IF(N(H26)=0,0,IF(N(G26)>0,G26*(1+H26/30),H26)),IF(N(J26)=0,0,IF(N(I26)>0,I26*(1+J26/30),J26)),IF(N(L26)=0,0,IF(N(K26)>0,K26*(1+L26/30),L26)),IF(N(N26)=0,0,IF(N(M26)>0,M26*(1+N26/30),N26)))) | Y26: =IF(N(X26)=0,"",X26+ROW()/1000000000) | Z26: =IF(Y26="","",IF(COUNTIFS(Log!$D$6:$D$1505,D26,Log!$Y$6:$Y$1505,">"&Y26)=0,1,0)) | AA26: =IF(OR(B26="",D26=""),"",B26+ROW()/10000000) | AB26: =IF(AA26="","",IF(COUNTIFS(Log!$D$6:$D$1505,D26,Log!$AA$6:$AA$1505,">"&AA26)=0,1,0)) | AC26: =IF(S26="New best",AA26,"") | AD26: =ROW()
B27: 46216 | C27: Push | D27: Incline dumbbell press | E27: 45 | F27: 11 | G27: 45 | H27: 10 | I27: 45 | J27: 10 | O27: =IF(D27="","",COUNT(F27,H27,J27,L27,N27)) | P27: =IF(D27="","",N(E27)*N(F27)+N(G27)*N(H27)+N(I27)*N(J27)+N(K27)*N(L27)+N(M27)*N(N27)) | Q27: =IF(N(X27)=0,"",IF(IF(N(F27)=0,0,IF(N(E27)>0,E27*(1+F27/30),F27))=X27,IF(N(E27)>0,E27&" x "&F27,F27&" reps"),IF(IF(N(H27)=0,0,IF(N(G27)>0,G27*(1+H27/30),H27))=X27,IF(N(G27)>0,G27&" x "&H27,H27&" reps"),IF(IF(N(J27)=0,0,IF(N(I27)>0,I27*(1+J27/30),J27))=X27,IF(N(I27)>0,I27&" x "&J27,J27&" reps"),IF(IF(N(L27)=0,0,IF(N(K27)>0,K27*(1+L27/30),L27))=X27,IF(N(K27)>0,K27&" x "&L27,L27&" reps"),IF(IF(N(N27)=0,0,IF(N(M27)>0,M27*(1+N27/30),N27))=X27,IF(N(M27)>0,M27&" x "&N27,N27&" reps"),"")))))) | R27: =IF(N(X27)=0,"",ROUND(X27,1)) | S27: =IF(N(X27)=0,"",IF(AND(COUNTIFS(Log!$D$6:$D$1505,D27,Log!$B$6:$B$1505,"<"&B27)>0,COUNTIFS(Log!$D$6:$D$1505,D27,Log!$B$6:$B$1505,"<"&B27,Log!$X$6:$X$1505,">="&X27)=0),"New best","")) | U27: =IF(D27="","",IFERROR(INDEX(Exercises!$C$6:$C$105,MATCH(D27,Exercises!$B$6:$B$105,0)),"Other")) | V27: =IF(B27="","",IF(COUNTIF($B$6:B27,B27)=1,1,0)) | W27: =IF(B27="","",B27-WEEKDAY(B27,3)) | X27: =IF(D27="","",MAX(IF(N(F27)=0,0,IF(N(E27)>0,E27*(1+F27/30),F27)),IF(N(H27)=0,0,IF(N(G27)>0,G27*(1+H27/30),H27)),IF(N(J27)=0,0,IF(N(I27)>0,I27*(1+J27/30),J27)),IF(N(L27)=0,0,IF(N(K27)>0,K27*(1+L27/30),L27)),IF(N(N27)=0,0,IF(N(M27)>0,M27*(1+N27/30),N27)))) | Y27: =IF(N(X27)=0,"",X27+ROW()/1000000000) | Z27: =IF(Y27="","",IF(COUNTIFS(Log!$D$6:$D$1505,D27,Log!$Y$6:$Y$1505,">"&Y27)=0,1,0)) | AA27: =IF(OR(B27="",D27=""),"",B27+ROW()/10000000) | AB27: =IF(AA27="","",IF(COUNTIFS(Log!$D$6:$D$1505,D27,Log!$AA$6:$AA$1505,">"&AA27)=0,1,0)) | AC27: =IF(S27="New best",AA27,"") | AD27: =ROW()
B28: 46216 | C28: Push | D28: Lateral raise | E28: 15 | F28: 14 | G28: 15 | H28: 13 | I28: 15 | J28: 13 | O28: =IF(D28="","",COUNT(F28,H28,J28,L28,N28)) | P28: =IF(D28="","",N(E28)*N(F28)+N(G28)*N(H28)+N(I28)*N(J28)+N(K28)*N(L28)+N(M28)*N(N28)) | Q28: =IF(N(X28)=0,"",IF(IF(N(F28)=0,0,IF(N(E28)>0,E28*(1+F28/30),F28))=X28,IF(N(E28)>0,E28&" x "&F28,F28&" reps"),IF(IF(N(H28)=0,0,IF(N(G28)>0,G28*(1+H28/30),H28))=X28,IF(N(G28)>0,G28&" x "&H28,H28&" reps"),IF(IF(N(J28)=0,0,IF(N(I28)>0,I28*(1+J28/30),J28))=X28,IF(N(I28)>0,I28&" x "&J28,J28&" reps"),IF(IF(N(L28)=0,0,IF(N(K28)>0,K28*(1+L28/30),L28))=X28,IF(N(K28)>0,K28&" x "&L28,L28&" reps"),IF(IF(N(N28)=0,0,IF(N(M28)>0,M28*(1+N28/30),N28))=X28,IF(N(M28)>0,M28&" x "&N28,N28&" reps"),"")))))) | R28: =IF(N(X28)=0,"",ROUND(X28,1)) | S28: =IF(N(X28)=0,"",IF(AND(COUNTIFS(Log!$D$6:$D$1505,D28,Log!$B$6:$B$1505,"<"&B28)>0,COUNTIFS(Log!$D$6:$D$1505,D28,Log!$B$6:$B$1505,"<"&B28,Log!$X$6:$X$1505,">="&X28)=0),"New best","")) | U28: =IF(D28="","",IFERROR(INDEX(Exercises!$C$6:$C$105,MATCH(D28,Exercises!$B$6:$B$105,0)),"Other")) | V28: =IF(B28="","",IF(COUNTIF($B$6:B28,B28)=1,1,0)) | W28: =IF(B28="","",B28-WEEKDAY(B28,3)) | X28: =IF(D28="","",MAX(IF(N(F28)=0,0,IF(N(E28)>0,E28*(1+F28/30),F28)),IF(N(H28)=0,0,IF(N(G28)>0,G28*(1+H28/30),H28)),IF(N(J28)=0,0,IF(N(I28)>0,I28*(1+J28/30),J28)),IF(N(L28)=0,0,IF(N(K28)>0,K28*(1+L28/30),L28)),IF(N(N28)=0,0,IF(N(M28)>0,M28*(1+N28/30),N28)))) | Y28: =IF(N(X28)=0,"",X28+ROW()/1000000000) | Z28: =IF(Y28="","",IF(COUNTIFS(Log!$D$6:$D$1505,D28,Log!$Y$6:$Y$1505,">"&Y28)=0,1,0)) | AA28: =IF(OR(B28="",D28=""),"",B28+ROW()/10000000) | AB28: =IF(AA28="","",IF(COUNTIFS(Log!$D$6:$D$1505,D28,Log!$AA$6:$AA$1505,">"&AA28)=0,1,0)) | AC28: =IF(S28="New best",AA28,"") | AD28: =ROW()
B29: 46216 | C29: Push | D29: Triceps pushdown | E29: 40 | F29: 12 | G29: 40 | H29: 10 | I29: 40 | J29: 10 | O29: =IF(D29="","",COUNT(F29,H29,J29,L29,N29)) | P29: =IF(D29="","",N(E29)*N(F29)+N(G29)*N(H29)+N(I29)*N(J29)+N(K29)*N(L29)+N(M29)*N(N29)) | Q29: =IF(N(X29)=0,"",IF(IF(N(F29)=0,0,IF(N(E29)>0,E29*(1+F29/30),F29))=X29,IF(N(E29)>0,E29&" x "&F29,F29&" reps"),IF(IF(N(H29)=0,0,IF(N(G29)>0,G29*(1+H29/30),H29))=X29,IF(N(G29)>0,G29&" x "&H29,H29&" reps"),IF(IF(N(J29)=0,0,IF(N(I29)>0,I29*(1+J29/30),J29))=X29,IF(N(I29)>0,I29&" x "&J29,J29&" reps"),IF(IF(N(L29)=0,0,IF(N(K29)>0,K29*(1+L29/30),L29))=X29,IF(N(K29)>0,K29&" x "&L29,L29&" reps"),IF(IF(N(N29)=0,0,IF(N(M29)>0,M29*(1+N29/30),N29))=X29,IF(N(M29)>0,M29&" x "&N29,N29&" reps"),"")))))) | R29: =IF(N(X29)=0,"",ROUND(X29,1)) | S29: =IF(N(X29)=0,"",IF(AND(COUNTIFS(Log!$D$6:$D$1505,D29,Log!$B$6:$B$1505,"<"&B29)>0,COUNTIFS(Log!$D$6:$D$1505,D29,Log!$B$6:$B$1505,"<"&B29,Log!$X$6:$X$1505,">="&X29)=0),"New best","")) | U29: =IF(D29="","",IFERROR(INDEX(Exercises!$C$6:$C$105,MATCH(D29,Exercises!$B$6:$B$105,0)),"Other")) | V29: =IF(B29="","",IF(COUNTIF($B$6:B29,B29)=1,1,0)) | W29: =IF(B29="","",B29-WEEKDAY(B29,3)) | X29: =IF(D29="","",MAX(IF(N(F29)=0,0,IF(N(E29)>0,E29*(1+F29/30),F29)),IF(N(H29)=0,0,IF(N(G29)>0,G29*(1+H29/30),H29)),IF(N(J29)=0,0,IF(N(I29)>0,I29*(1+J29/30),J29)),IF(N(L29)=0,0,IF(N(K29)>0,K29*(1+L29/30),L29)),IF(N(N29)=0,0,IF(N(M29)>0,M29*(1+N29/30),N29)))) | Y29: =IF(N(X29)=0,"",X29+ROW()/1000000000) | Z29: =IF(Y29="","",IF(COUNTIFS(Log!$D$6:$D$1505,D29,Log!$Y$6:$Y$1505,">"&Y29)=0,1,0)) | AA29: =IF(OR(B29="",D29=""),"",B29+ROW()/10000000) | AB29: =IF(AA29="","",IF(COUNTIFS(Log!$D$6:$D$1505,D29,Log!$AA$6:$AA$1505,">"&AA29)=0,1,0)) | AC29: =IF(S29="New best",AA29,"") | AD29: =ROW()
B30: 46217 | C30: Pull | D30: Deadlift | E30: 225 | F30: 5 | G30: 225 | H30: 5 | I30: 225 | J30: 5 | O30: =IF(D30="","",COUNT(F30,H30,J30,L30,N30)) | P30: =IF(D30="","",N(E30)*N(F30)+N(G30)*N(H30)+N(I30)*N(J30)+N(K30)*N(L30)+N(M30)*N(N30)) | Q30: =IF(N(X30)=0,"",IF(IF(N(F30)=0,0,IF(N(E30)>0,E30*(1+F30/30),F30))=X30,IF(N(E30)>0,E30&" x "&F30,F30&" reps"),IF(IF(N(H30)=0,0,IF(N(G30)>0,G30*(1+H30/30),H30))=X30,IF(N(G30)>0,G30&" x "&H30,H30&" reps"),IF(IF(N(J30)=0,0,IF(N(I30)>0,I30*(1+J30/30),J30))=X30,IF(N(I30)>0,I30&" x "&J30,J30&" reps"),IF(IF(N(L30)=0,0,IF(N(K30)>0,K30*(1+L30/30),L30))=X30,IF(N(K30)>0,K30&" x "&L30,L30&" reps"),IF(IF(N(N30)=0,0,IF(N(M30)>0,M30*(1+N30/30),N30))=X30,IF(N(M30)>0,M30&" x "&N30,N30&" reps"),"")))))) | R30: =IF(N(X30)=0,"",ROUND(X30,1)) | S30: =IF(N(X30)=0,"",IF(AND(COUNTIFS(Log!$D$6:$D$1505,D30,Log!$B$6:$B$1505,"<"&B30)>0,COUNTIFS(Log!$D$6:$D$1505,D30,Log!$B$6:$B$1505,"<"&B30,Log!$X$6:$X$1505,">="&X30)=0),"New best","")) | U30: =IF(D30="","",IFERROR(INDEX(Exercises!$C$6:$C$105,MATCH(D30,Exercises!$B$6:$B$105,0)),"Other")) | V30: =IF(B30="","",IF(COUNTIF($B$6:B30,B30)=1,1,0)) | W30: =IF(B30="","",B30-WEEKDAY(B30,3)) | X30: =IF(D30="","",MAX(IF(N(F30)=0,0,IF(N(E30)>0,E30*(1+F30/30),F30)),IF(N(H30)=0,0,IF(N(G30)>0,G30*(1+H30/30),H30)),IF(N(J30)=0,0,IF(N(I30)>0,I30*(1+J30/30),J30)),IF(N(L30)=0,0,IF(N(K30)>0,K30*(1+L30/30),L30)),IF(N(N30)=0,0,IF(N(M30)>0,M30*(1+N30/30),N30)))) | Y30: =IF(N(X30)=0,"",X30+ROW()/1000000000) | Z30: =IF(Y30="","",IF(COUNTIFS(Log!$D$6:$D$1505,D30,Log!$Y$6:$Y$1505,">"&Y30)=0,1,0)) | AA30: =IF(OR(B30="",D30=""),"",B30+ROW()/10000000) | AB30: =IF(AA30="","",IF(COUNTIFS(Log!$D$6:$D$1505,D30,Log!$AA$6:$AA$1505,">"&AA30)=0,1,0)) | AC30: =IF(S30="New best",AA30,"") | AD30: =ROW()
B31: 46217 | C31: Pull | D31: Pull-up | F31: 5 | H31: 4 | J31: 3 | O31: =IF(D31="","",COUNT(F31,H31,J31,L31,N31)) | P31: =IF(D31="","",N(E31)*N(F31)+N(G31)*N(H31)+N(I31)*N(J31)+N(K31)*N(L31)+N(M31)*N(N31)) | Q31: =IF(N(X31)=0,"",IF(IF(N(F31)=0,0,IF(N(E31)>0,E31*(1+F31/30),F31))=X31,IF(N(E31)>0,E31&" x "&F31,F31&" reps"),IF(IF(N(H31)=0,0,IF(N(G31)>0,G31*(1+H31/30),H31))=X31,IF(N(G31)>0,G31&" x "&H31,H31&" reps"),IF(IF(N(J31)=0,0,IF(N(I31)>0,I31*(1+J31/30),J31))=X31,IF(N(I31)>0,I31&" x "&J31,J31&" reps"),IF(IF(N(L31)=0,0,IF(N(K31)>0,K31*(1+L31/30),L31))=X31,IF(N(K31)>0,K31&" x "&L31,L31&" reps"),IF(IF(N(N31)=0,0,IF(N(M31)>0,M31*(1+N31/30),N31))=X31,IF(N(M31)>0,M31&" x "&N31,N31&" reps"),"")))))) | R31: =IF(N(X31)=0,"",ROUND(X31,1)) | S31: =IF(N(X31)=0,"",IF(AND(COUNTIFS(Log!$D$6:$D$1505,D31,Log!$B$6:$B$1505,"<"&B31)>0,COUNTIFS(Log!$D$6:$D$1505,D31,Log!$B$6:$B$1505,"<"&B31,Log!$X$6:$X$1505,">="&X31)=0),"New best","")) | U31: =IF(D31="","",IFERROR(INDEX(Exercises!$C$6:$C$105,MATCH(D31,Exercises!$B$6:$B$105,0)),"Other")) | V31: =IF(B31="","",IF(COUNTIF($B$6:B31,B31)=1,1,0)) | W31: =IF(B31="","",B31-WEEKDAY(B31,3)) | X31: =IF(D31="","",MAX(IF(N(F31)=0,0,IF(N(E31)>0,E31*(1+F31/30),F31)),IF(N(H31)=0,0,IF(N(G31)>0,G31*(1+H31/30),H31)),IF(N(J31)=0,0,IF(N(I31)>0,I31*(1+J31/30),J31)),IF(N(L31)=0,0,IF(N(K31)>0,K31*(1+L31/30),L31)),IF(N(N31)=0,0,IF(N(M31)>0,M31*(1+N31/30),N31)))) | Y31: =IF(N(X31)=0,"",X31+ROW()/1000000000) | Z31: =IF(Y31="","",IF(COUNTIFS(Log!$D$6:$D$1505,D31,Log!$Y$6:$Y$1505,">"&Y31)=0,1,0)) | AA31: =IF(OR(B31="",D31=""),"",B31+ROW()/10000000) | AB31: =IF(AA31="","",IF(COUNTIFS(Log!$D$6:$D$1505,D31,Log!$AA$6:$AA$1505,">"&AA31)=0,1,0)) | AC31: =IF(S31="New best",AA31,"") | AD31: =ROW()
B32: 46217 | C32: Pull | D32: Barbell row | E32: 115 | F32: 10 | G32: 115 | H32: 9 | I32: 115 | J32: 8 | O32: =IF(D32="","",COUNT(F32,H32,J32,L32,N32)) | P32: =IF(D32="","",N(E32)*N(F32)+N(G32)*N(H32)+N(I32)*N(J32)+N(K32)*N(L32)+N(M32)*N(N32)) | Q32: =IF(N(X32)=0,"",IF(IF(N(F32)=0,0,IF(N(E32)>0,E32*(1+F32/30),F32))=X32,IF(N(E32)>0,E32&" x "&F32,F32&" reps"),IF(IF(N(H32)=0,0,IF(N(G32)>0,G32*(1+H32/30),H32))=X32,IF(N(G32)>0,G32&" x "&H32,H32&" reps"),IF(IF(N(J32)=0,0,IF(N(I32)>0,I32*(1+J32/30),J32))=X32,IF(N(I32)>0,I32&" x "&J32,J32&" reps"),IF(IF(N(L32)=0,0,IF(N(K32)>0,K32*(1+L32/30),L32))=X32,IF(N(K32)>0,K32&" x "&L32,L32&" reps"),IF(IF(N(N32)=0,0,IF(N(M32)>0,M32*(1+N32/30),N32))=X32,IF(N(M32)>0,M32&" x "&N32,N32&" reps"),"")))))) | R32: =IF(N(X32)=0,"",ROUND(X32,1)) | S32: =IF(N(X32)=0,"",IF(AND(COUNTIFS(Log!$D$6:$D$1505,D32,Log!$B$6:$B$1505,"<"&B32)>0,COUNTIFS(Log!$D$6:$D$1505,D32,Log!$B$6:$B$1505,"<"&B32,Log!$X$6:$X$1505,">="&X32)=0),"New best","")) | T32: Short on time | U32: =IF(D32="","",IFERROR(INDEX(Exercises!$C$6:$C$105,MATCH(D32,Exercises!$B$6:$B$105,0)),"Other")) | V32: =IF(B32="","",IF(COUNTIF($B$6:B32,B32)=1,1,0)) | W32: =IF(B32="","",B32-WEEKDAY(B32,3)) | X32: =IF(D32="","",MAX(IF(N(F32)=0,0,IF(N(E32)>0,E32*(1+F32/30),F32)),IF(N(H32)=0,0,IF(N(G32)>0,G32*(1+H32/30),H32)),IF(N(J32)=0,0,IF(N(I32)>0,I32*(1+J32/30),J32)),IF(N(L32)=0,0,IF(N(K32)>0,K32*(1+L32/30),L32)),IF(N(N32)=0,0,IF(N(M32)>0,M32*(1+N32/30),N32)))) | Y32: =IF(N(X32)=0,"",X32+ROW()/1000000000) | Z32: =IF(Y32="","",IF(COUNTIFS(Log!$D$6:$D$1505,D32,Log!$Y$6:$Y$1505,">"&Y32)=0,1,0)) | AA32: =IF(OR(B32="",D32=""),"",B32+ROW()/10000000) | AB32: =IF(AA32="","",IF(COUNTIFS(Log!$D$6:$D$1505,D32,Log!$AA$6:$AA$1505,">"&AA32)=0,1,0)) | AC32: =IF(S32="New best",AA32,"") | AD32: =ROW()
B33: 46217 | C33: Pull | D33: Lat pulldown | E33: 100 | F33: 11 | G33: 100 | H33: 11 | I33: 100 | J33: 10 | O33: =IF(D33="","",COUNT(F33,H33,J33,L33,N33)) | P33: =IF(D33="","",N(E33)*N(F33)+N(G33)*N(H33)+N(I33)*N(J33)+N(K33)*N(L33)+N(M33)*N(N33)) | Q33: =IF(N(X33)=0,"",IF(IF(N(F33)=0,0,IF(N(E33)>0,E33*(1+F33/30),F33))=X33,IF(N(E33)>0,E33&" x "&F33,F33&" reps"),IF(IF(N(H33)=0,0,IF(N(G33)>0,G33*(1+H33/30),H33))=X33,IF(N(G33)>0,G33&" x "&H33,H33&" reps"),IF(IF(N(J33)=0,0,IF(N(I33)>0,I33*(1+J33/30),J33))=X33,IF(N(I33)>0,I33&" x "&J33,J33&" reps"),IF(IF(N(L33)=0,0,IF(N(K33)>0,K33*(1+L33/30),L33))=X33,IF(N(K33)>0,K33&" x "&L33,L33&" reps"),IF(IF(N(N33)=0,0,IF(N(M33)>0,M33*(1+N33/30),N33))=X33,IF(N(M33)>0,M33&" x "&N33,N33&" reps"),"")))))) | R33: =IF(N(X33)=0,"",ROUND(X33,1)) | S33: =IF(N(X33)=0,"",IF(AND(COUNTIFS(Log!$D$6:$D$1505,D33,Log!$B$6:$B$1505,"<"&B33)>0,COUNTIFS(Log!$D$6:$D$1505,D33,Log!$B$6:$B$1505,"<"&B33,Log!$X$6:$X$1505,">="&X33)=0),"New best","")) | U33: =IF(D33="","",IFERROR(INDEX(Exercises!$C$6:$C$105,MATCH(D33,Exercises!$B$6:$B$105,0)),"Other")) | V33: =IF(B33="","",IF(COUNTIF($B$6:B33,B33)=1,1,0)) | W33: =IF(B33="","",B33-WEEKDAY(B33,3)) | X33: =IF(D33="","",MAX(IF(N(F33)=0,0,IF(N(E33)>0,E33*(1+F33/30),F33)),IF(N(H33)=0,0,IF(N(G33)>0,G33*(1+H33/30),H33)),IF(N(J33)=0,0,IF(N(I33)>0,I33*(1+J33/30),J33)),IF(N(L33)=0,0,IF(N(K33)>0,K33*(1+L33/30),L33)),IF(N(N33)=0,0,IF(N(M33)>0,M33*(1+N33/30),N33)))) | Y33: =IF(N(X33)=0,"",X33+ROW()/1000000000) | Z33: =IF(Y33="","",IF(COUNTIFS(Log!$D$6:$D$1505,D33,Log!$Y$6:$Y$1505,">"&Y33)=0,1,0)) | AA33: =IF(OR(B33="",D33=""),"",B33+ROW()/10000000) | AB33: =IF(AA33="","",IF(COUNTIFS(Log!$D$6:$D$1505,D33,Log!$AA$6:$AA$1505,">"&AA33)=0,1,0)) | AC33: =IF(S33="New best",AA33,"") | AD33: =ROW()
B34: 46217 | C34: Pull | D34: Biceps curl | E34: 25 | F34: 11 | G34: 25 | H34: 11 | I34: 25 | J34: 10 | O34: =IF(D34="","",COUNT(F34,H34,J34,L34,N34)) | P34: =IF(D34="","",N(E34)*N(F34)+N(G34)*N(H34)+N(I34)*N(J34)+N(K34)*N(L34)+N(M34)*N(N34)) | Q34: =IF(N(X34)=0,"",IF(IF(N(F34)=0,0,IF(N(E34)>0,E34*(1+F34/30),F34))=X34,IF(N(E34)>0,E34&" x "&F34,F34&" reps"),IF(IF(N(H34)=0,0,IF(N(G34)>0,G34*(1+H34/30),H34))=X34,IF(N(G34)>0,G34&" x "&H34,H34&" reps"),IF(IF(N(J34)=0,0,IF(N(I34)>0,I34*(1+J34/30),J34))=X34,IF(N(I34)>0,I34&" x "&J34,J34&" reps"),IF(IF(N(L34)=0,0,IF(N(K34)>0,K34*(1+L34/30),L34))=X34,IF(N(K34)>0,K34&" x "&L34,L34&" reps"),IF(IF(N(N34)=0,0,IF(N(M34)>0,M34*(1+N34/30),N34))=X34,IF(N(M34)>0,M34&" x "&N34,N34&" reps"),"")))))) | R34: =IF(N(X34)=0,"",ROUND(X34,1)) | S34: =IF(N(X34)=0,"",IF(AND(COUNTIFS(Log!$D$6:$D$1505,D34,Log!$B$6:$B$1505,"<"&B34)>0,COUNTIFS(Log!$D$6:$D$1505,D34,Log!$B$6:$B$1505,"<"&B34,Log!$X$6:$X$1505,">="&X34)=0),"New best","")) | U34: =IF(D34="","",IFERROR(INDEX(Exercises!$C$6:$C$105,MATCH(D34,Exercises!$B$6:$B$105,0)),"Other")) | V34: =IF(B34="","",IF(COUNTIF($B$6:B34,B34)=1,1,0)) | W34: =IF(B34="","",B34-WEEKDAY(B34,3)) | X34: =IF(D34="","",MAX(IF(N(F34)=0,0,IF(N(E34)>0,E34*(1+F34/30),F34)),IF(N(H34)=0,0,IF(N(G34)>0,G34*(1+H34/30),H34)),IF(N(J34)=0,0,IF(N(I34)>0,I34*(1+J34/30),J34)),IF(N(L34)=0,0,IF(N(K34)>0,K34*(1+L34/30),L34)),IF(N(N34)=0,0,IF(N(M34)>0,M34*(1+N34/30),N34)))) | Y34: =IF(N(X34)=0,"",X34+ROW()/1000000000) | Z34: =IF(Y34="","",IF(COUNTIFS(Log!$D$6:$D$1505,D34,Log!$Y$6:$Y$1505,">"&Y34)=0,1,0)) | AA34: =IF(OR(B34="",D34=""),"",B34+ROW()/10000000) | AB34: =IF(AA34="","",IF(COUNTIFS(Log!$D$6:$D$1505,D34,Log!$AA$6:$AA$1505,">"&AA34)=0,1,0)) | AC34: =IF(S34="New best",AA34,"") | AD34: =ROW()
