Workbook

Sheet Dashboard
M1: =Settings!$C$4 | P1: ='Class 1'!AD11
B2: Teaching week | P2: ='Class 1'!AD12
B3: Today's lessons, your classes and the students to watch. | P3: ='Class 1'!AD13
B4: Today | D4: Planned this week | E4: To mark | G4: Students | H4: Below pass | I4: Missing work | J4: Absent this week | P4: ='Class 1'!AD14
B5: =IF(WEEKDAY(TODAY(),2)>5,0,SUMPRODUCT((Timetable!$E$6:$I$15<>"")*(COLUMN(Timetable!$E$6:$I$15)-4=WEEKDAY(TODAY(),2)))) | D5: =COUNTIFS(Lessons!$B$6:$B$505,">="&Settings!$C$6,Lessons!$B$6:$B$505,"<="&(Settings!$C$6+4))&" of "&SUMPRODUCT(--(Timetable!$E$6:$I$15<>"")) | E5: =SUM('Class 1'!H54:AA54)+SUM('Class 2'!H54:AA54)+SUM('Class 3'!H54:AA54)+SUM('Class 4'!H54:AA54)+SUM('Class 5'!H54:AA54)+SUM('Class 6'!H54:AA54) | G5: =COUNTA('Class 1'!B11:B50)+COUNTA('Class 2'!B11:B50)+COUNTA('Class 3'!B11:B50)+COUNTA('Class 4'!B11:B50)+COUNTA('Class 5'!B11:B50)+COUNTA('Class 6'!B11:B50) | H5: =SUM('Class 1'!AE11:AE50)+SUM('Class 2'!AE11:AE50)+SUM('Class 3'!AE11:AE50)+SUM('Class 4'!AE11:AE50)+SUM('Class 5'!AE11:AE50)+SUM('Class 6'!AE11:AE50) | I5: =SUM('Class 1'!E11:E50)+SUM('Class 2'!E11:E50)+SUM('Class 3'!E11:E50)+SUM('Class 4'!E11:E50)+SUM('Class 5'!E11:E50)+SUM('Class 6'!E11:E50) | J5: =COUNTIFS(Absences!$B$6:$B$405,">="&Settings!$C$6,Absences!$B$6:$B$405,"<="&(Settings!$C$6+6),Absences!$E$6:$E$405,"Absent") | P5: ='Class 1'!AD15
P6: ='Class 1'!AD16
B7: Today | C7: Time | D7: Class | E7: Topic | G7: Class | H7: Students | I7: Average | J7: Below pass | P7: ='Class 1'!AD17
B8: 1 | C8: =IF(ISNUMBER(Timetable!C6),HOUR(Timetable!C6)&":"&RIGHT("0"&MINUTE(Timetable!C6),2),"") | D8: =IF(IF(ISNUMBER(N8),INDEX(Lessons!$I$6:$I$505,N8),IF(WEEKDAY(TODAY(),2)>5,"",IF(INDEX(Timetable!$E$6:$I$15,1,WEEKDAY(TODAY(),2))="","",INDEX(Timetable!$E$6:$I$15,1,WEEKDAY(TODAY(),2)))))="","",IF(ISNUMBER(N8),INDEX(Lessons!$I$6:$I$505,N8),IF(WEEKDAY(TODAY(),2)>5,"",IF(INDEX(Timetable!$E$6:$I$15,1,WEEKDAY(TODAY(),2))="","",INDEX(Timetable!$E$6:$I$15,1,WEEKDAY(TODAY(),2)))))) | E8: =IF(ISNUMBER(N8),IF(INDEX(Lessons!$E$6:$E$505,N8)="","",INDEX(Lessons!$E$6:$E$505,N8)),IF(IF(WEEKDAY(TODAY(),2)>5,"",IF(INDEX(Timetable!$E$6:$I$15,1,WEEKDAY(TODAY(),2))="","",INDEX(Timetable!$E$6:$I$15,1,WEEKDAY(TODAY(),2))))="","","Not planned yet")) | G8: =IF(Settings!$C$9="","",Settings!$C$9) | H8: =IF(G8="","",COUNTA('Class 1'!B11:B50)) | I8: =IF(G8="","",'Class 1'!C9) | J8: =IF(G8="","",SUM('Class 1'!AE11:AE50)) | N8: =IFERROR(MATCH(TODAY()*100+1,Lessons!$K$6:$K$505,0),"") | P8: ='Class 1'!AD18
B9: 2 | C9: =IF(ISNUMBER(Timetable!C7),HOUR(Timetable!C7)&":"&RIGHT("0"&MINUTE(Timetable!C7),2),"") | D9: =IF(IF(ISNUMBER(N9),INDEX(Lessons!$I$6:$I$505,N9),IF(WEEKDAY(TODAY(),2)>5,"",IF(INDEX(Timetable!$E$6:$I$15,2,WEEKDAY(TODAY(),2))="","",INDEX(Timetable!$E$6:$I$15,2,WEEKDAY(TODAY(),2)))))="","",IF(ISNUMBER(N9),INDEX(Lessons!$I$6:$I$505,N9),IF(WEEKDAY(TODAY(),2)>5,"",IF(INDEX(Timetable!$E$6:$I$15,2,WEEKDAY(TODAY(),2))="","",INDEX(Timetable!$E$6:$I$15,2,WEEKDAY(TODAY(),2)))))) | E9: =IF(ISNUMBER(N9),IF(INDEX(Lessons!$E$6:$E$505,N9)="","",INDEX(Lessons!$E$6:$E$505,N9)),IF(IF(WEEKDAY(TODAY(),2)>5,"",IF(INDEX(Timetable!$E$6:$I$15,2,WEEKDAY(TODAY(),2))="","",INDEX(Timetable!$E$6:$I$15,2,WEEKDAY(TODAY(),2))))="","","Not planned yet")) | G9: =IF(Settings!$C$10="","",Settings!$C$10) | H9: =IF(G9="","",COUNTA('Class 2'!B11:B50)) | I9: =IF(G9="","",'Class 2'!C9) | J9: =IF(G9="","",SUM('Class 2'!AE11:AE50)) | N9: =IFERROR(MATCH(TODAY()*100+2,Lessons!$K$6:$K$505,0),"") | P9: ='Class 1'!AD19
B10: 3 | C10: =IF(ISNUMBER(Timetable!C8),HOUR(Timetable!C8)&":"&RIGHT("0"&MINUTE(Timetable!C8),2),"") | D10: =IF(IF(ISNUMBER(N10),INDEX(Lessons!$I$6:$I$505,N10),IF(WEEKDAY(TODAY(),2)>5,"",IF(INDEX(Timetable!$E$6:$I$15,3,WEEKDAY(TODAY(),2))="","",INDEX(Timetable!$E$6:$I$15,3,WEEKDAY(TODAY(),2)))))="","",IF(ISNUMBER(N10),INDEX(Lessons!$I$6:$I$505,N10),IF(WEEKDAY(TODAY(),2)>5,"",IF(INDEX(Timetable!$E$6:$I$15,3,WEEKDAY(TODAY(),2))="","",INDEX(Timetable!$E$6:$I$15,3,WEEKDAY(TODAY(),2)))))) | E10: =IF(ISNUMBER(N10),IF(INDEX(Lessons!$E$6:$E$505,N10)="","",INDEX(Lessons!$E$6:$E$505,N10)),IF(IF(WEEKDAY(TODAY(),2)>5,"",IF(INDEX(Timetable!$E$6:$I$15,3,WEEKDAY(TODAY(),2))="","",INDEX(Timetable!$E$6:$I$15,3,WEEKDAY(TODAY(),2))))="","","Not planned yet")) | G10: =IF(Settings!$C$11="","",Settings!$C$11) | H10: =IF(G10="","",COUNTA('Class 3'!B11:B50)) | I10: =IF(G10="","",'Class 3'!C9) | J10: =IF(G10="","",SUM('Class 3'!AE11:AE50)) | N10: =IFERROR(MATCH(TODAY()*100+3,Lessons!$K$6:$K$505,0),"") | P10: ='Class 1'!AD20
B11: 4 | C11: =IF(ISNUMBER(Timetable!C9),HOUR(Timetable!C9)&":"&RIGHT("0"&MINUTE(Timetable!C9),2),"") | D11: =IF(IF(ISNUMBER(N11),INDEX(Lessons!$I$6:$I$505,N11),IF(WEEKDAY(TODAY(),2)>5,"",IF(INDEX(Timetable!$E$6:$I$15,4,WEEKDAY(TODAY(),2))="","",INDEX(Timetable!$E$6:$I$15,4,WEEKDAY(TODAY(),2)))))="","",IF(ISNUMBER(N11),INDEX(Lessons!$I$6:$I$505,N11),IF(WEEKDAY(TODAY(),2)>5,"",IF(INDEX(Timetable!$E$6:$I$15,4,WEEKDAY(TODAY(),2))="","",INDEX(Timetable!$E$6:$I$15,4,WEEKDAY(TODAY(),2)))))) | E11: =IF(ISNUMBER(N11),IF(INDEX(Lessons!$E$6:$E$505,N11)="","",INDEX(Lessons!$E$6:$E$505,N11)),IF(IF(WEEKDAY(TODAY(),2)>5,"",IF(INDEX(Timetable!$E$6:$I$15,4,WEEKDAY(TODAY(),2))="","",INDEX(Timetable!$E$6:$I$15,4,WEEKDAY(TODAY(),2))))="","","Not planned yet")) | G11: =IF(Settings!$C$12="","",Settings!$C$12) | H11: =IF(G11="","",COUNTA('Class 4'!B11:B50)) | I11: =IF(G11="","",'Class 4'!C9) | J11: =IF(G11="","",SUM('Class 4'!AE11:AE50)) | N11: =IFERROR(MATCH(TODAY()*100+4,Lessons!$K$6:$K$505,0),"") | P11: ='Class 1'!AD21
B12: 5 | C12: =IF(ISNUMBER(Timetable!C10),HOUR(Timetable!C10)&":"&RIGHT("0"&MINUTE(Timetable!C10),2),"") | D12: =IF(IF(ISNUMBER(N12),INDEX(Lessons!$I$6:$I$505,N12),IF(WEEKDAY(TODAY(),2)>5,"",IF(INDEX(Timetable!$E$6:$I$15,5,WEEKDAY(TODAY(),2))="","",INDEX(Timetable!$E$6:$I$15,5,WEEKDAY(TODAY(),2)))))="","",IF(ISNUMBER(N12),INDEX(Lessons!$I$6:$I$505,N12),IF(WEEKDAY(TODAY(),2)>5,"",IF(INDEX(Timetable!$E$6:$I$15,5,WEEKDAY(TODAY(),2))="","",INDEX(Timetable!$E$6:$I$15,5,WEEKDAY(TODAY(),2)))))) | E12: =IF(ISNUMBER(N12),IF(INDEX(Lessons!$E$6:$E$505,N12)="","",INDEX(Lessons!$E$6:$E$505,N12)),IF(IF(WEEKDAY(TODAY(),2)>5,"",IF(INDEX(Timetable!$E$6:$I$15,5,WEEKDAY(TODAY(),2))="","",INDEX(Timetable!$E$6:$I$15,5,WEEKDAY(TODAY(),2))))="","","Not planned yet")) | G12: =IF(Settings!$C$13="","",Settings!$C$13) | H12: =IF(G12="","",COUNTA('Class 5'!B11:B50)) | I12: =IF(G12="","",'Class 5'!C9) | J12: =IF(G12="","",SUM('Class 5'!AE11:AE50)) | N12: =IFERROR(MATCH(TODAY()*100+5,Lessons!$K$6:$K$505,0),"") | P12: ='Class 1'!AD22
B13: 6 | C13: =IF(ISNUMBER(Timetable!C11),HOUR(Timetable!C11)&":"&RIGHT("0"&MINUTE(Timetable!C11),2),"") | D13: =IF(IF(ISNUMBER(N13),INDEX(Lessons!$I$6:$I$505,N13),IF(WEEKDAY(TODAY(),2)>5,"",IF(INDEX(Timetable!$E$6:$I$15,6,WEEKDAY(TODAY(),2))="","",INDEX(Timetable!$E$6:$I$15,6,WEEKDAY(TODAY(),2)))))="","",IF(ISNUMBER(N13),INDEX(Lessons!$I$6:$I$505,N13),IF(WEEKDAY(TODAY(),2)>5,"",IF(INDEX(Timetable!$E$6:$I$15,6,WEEKDAY(TODAY(),2))="","",INDEX(Timetable!$E$6:$I$15,6,WEEKDAY(TODAY(),2)))))) | E13: =IF(ISNUMBER(N13),IF(INDEX(Lessons!$E$6:$E$505,N13)="","",INDEX(Lessons!$E$6:$E$505,N13)),IF(IF(WEEKDAY(TODAY(),2)>5,"",IF(INDEX(Timetable!$E$6:$I$15,6,WEEKDAY(TODAY(),2))="","",INDEX(Timetable!$E$6:$I$15,6,WEEKDAY(TODAY(),2))))="","","Not planned yet")) | G13: =IF(Settings!$C$14="","",Settings!$C$14) | H13: =IF(G13="","",COUNTA('Class 6'!B11:B50)) | I13: =IF(G13="","",'Class 6'!C9) | J13: =IF(G13="","",SUM('Class 6'!AE11:AE50)) | N13: =IFERROR(MATCH(TODAY()*100+6,Lessons!$K$6:$K$505,0),"") | P13: ='Class 1'!AD23
B14: 7 | C14: =IF(ISNUMBER(Timetable!C12),HOUR(Timetable!C12)&":"&RIGHT("0"&MINUTE(Timetable!C12),2),"") | D14: =IF(IF(ISNUMBER(N14),INDEX(Lessons!$I$6:$I$505,N14),IF(WEEKDAY(TODAY(),2)>5,"",IF(INDEX(Timetable!$E$6:$I$15,7,WEEKDAY(TODAY(),2))="","",INDEX(Timetable!$E$6:$I$15,7,WEEKDAY(TODAY(),2)))))="","",IF(ISNUMBER(N14),INDEX(Lessons!$I$6:$I$505,N14),IF(WEEKDAY(TODAY(),2)>5,"",IF(INDEX(Timetable!$E$6:$I$15,7,WEEKDAY(TODAY(),2))="","",INDEX(Timetable!$E$6:$I$15,7,WEEKDAY(TODAY(),2)))))) | E14: =IF(ISNUMBER(N14),IF(INDEX(Lessons!$E$6:$E$505,N14)="","",INDEX(Lessons!$E$6:$E$505,N14)),IF(IF(WEEKDAY(TODAY(),2)>5,"",IF(INDEX(Timetable!$E$6:$I$15,7,WEEKDAY(TODAY(),2))="","",INDEX(Timetable!$E$6:$I$15,7,WEEKDAY(TODAY(),2))))="","","Not planned yet")) | N14: =IFERROR(MATCH(TODAY()*100+7,Lessons!$K$6:$K$505,0),"") | P14: ='Class 1'!AD24
B15: 8 | C15: =IF(ISNUMBER(Timetable!C13),HOUR(Timetable!C13)&":"&RIGHT("0"&MINUTE(Timetable!C13),2),"") | D15: =IF(IF(ISNUMBER(N15),INDEX(Lessons!$I$6:$I$505,N15),IF(WEEKDAY(TODAY(),2)>5,"",IF(INDEX(Timetable!$E$6:$I$15,8,WEEKDAY(TODAY(),2))="","",INDEX(Timetable!$E$6:$I$15,8,WEEKDAY(TODAY(),2)))))="","",IF(ISNUMBER(N15),INDEX(Lessons!$I$6:$I$505,N15),IF(WEEKDAY(TODAY(),2)>5,"",IF(INDEX(Timetable!$E$6:$I$15,8,WEEKDAY(TODAY(),2))="","",INDEX(Timetable!$E$6:$I$15,8,WEEKDAY(TODAY(),2)))))) | E15: =IF(ISNUMBER(N15),IF(INDEX(Lessons!$E$6:$E$505,N15)="","",INDEX(Lessons!$E$6:$E$505,N15)),IF(IF(WEEKDAY(TODAY(),2)>5,"",IF(INDEX(Timetable!$E$6:$I$15,8,WEEKDAY(TODAY(),2))="","",INDEX(Timetable!$E$6:$I$15,8,WEEKDAY(TODAY(),2))))="","","Not planned yet")) | G15: Students to watch | H15: Class | I15: Average | J15: Absent | N15: =IFERROR(MATCH(TODAY()*100+8,Lessons!$K$6:$K$505,0),"") | P15: ='Class 1'!AD25
B16: 9 | C16: =IF(ISNUMBER(Timetable!C14),HOUR(Timetable!C14)&":"&RIGHT("0"&MINUTE(Timetable!C14),2),"") | D16: =IF(IF(ISNUMBER(N16),INDEX(Lessons!$I$6:$I$505,N16),IF(WEEKDAY(TODAY(),2)>5,"",IF(INDEX(Timetable!$E$6:$I$15,9,WEEKDAY(TODAY(),2))="","",INDEX(Timetable!$E$6:$I$15,9,WEEKDAY(TODAY(),2)))))="","",IF(ISNUMBER(N16),INDEX(Lessons!$I$6:$I$505,N16),IF(WEEKDAY(TODAY(),2)>5,"",IF(INDEX(Timetable!$E$6:$I$15,9,WEEKDAY(TODAY(),2))="","",INDEX(Timetable!$E$6:$I$15,9,WEEKDAY(TODAY(),2)))))) | E16: =IF(ISNUMBER(N16),IF(INDEX(Lessons!$E$6:$E$505,N16)="","",INDEX(Lessons!$E$6:$E$505,N16)),IF(IF(WEEKDAY(TODAY(),2)>5,"",IF(INDEX(Timetable!$E$6:$I$15,9,WEEKDAY(TODAY(),2))="","",INDEX(Timetable!$E$6:$I$15,9,WEEKDAY(TODAY(),2))))="","","Not planned yet")) | G16: =IF(O16="","",CHOOSE(INT(MOD(O16,1000)/100),INDEX('Class 1'!$B$1:$B$50,MOD(O16,100)+10),INDEX('Class 2'!$B$1:$B$50,MOD(O16,100)+10),INDEX('Class 3'!$B$1:$B$50,MOD(O16,100)+10),INDEX('Class 4'!$B$1:$B$50,MOD(O16,100)+10),INDEX('Class 5'!$B$1:$B$50,MOD(O16,100)+10),INDEX('Class 6'!$B$1:$B$50,MOD(O16,100)+10))) | H16: =IF(O16="","",IF(CHOOSE(INT(MOD(O16,1000)/100),Settings!$C$9,Settings!$C$10,Settings!$C$11,Settings!$C$12,Settings!$C$13,Settings!$C$14)="","",CHOOSE(INT(MOD(O16,1000)/100),Settings!$C$9,Settings!$C$10,Settings!$C$11,Settings!$C$12,Settings!$C$13,Settings!$C$14))) | I16: =IF(O16="","",CHOOSE(INT(MOD(O16,1000)/100),INDEX('Class 1'!$C$1:$C$50,MOD(O16,100)+10),INDEX('Class 2'!$C$1:$C$50,MOD(O16,100)+10),INDEX('Class 3'!$C$1:$C$50,MOD(O16,100)+10),INDEX('Class 4'!$C$1:$C$50,MOD(O16,100)+10),INDEX('Class 5'!$C$1:$C$50,MOD(O16,100)+10),INDEX('Class 6'!$C$1:$C$50,MOD(O16,100)+10))) | J16: =IF(O16="","",CHOOSE(INT(MOD(O16,1000)/100),INDEX('Class 1'!$F$1:$F$50,MOD(O16,100)+10),INDEX('Class 2'!$F$1:$F$50,MOD(O16,100)+10),INDEX('Class 3'!$F$1:$F$50,MOD(O16,100)+10),INDEX('Class 4'!$F$1:$F$50,MOD(O16,100)+10),INDEX('Class 5'!$F$1:$F$50,MOD(O16,100)+10),INDEX('Class 6'!$F$1:$F$50,MOD(O16,100)+10))) | N16: =IFERROR(MATCH(TODAY()*100+9,Lessons!$K$6:$K$505,0),"") | O16: =IFERROR(SMALL($P$1:$P$240,1),"") | P16: ='Class 1'!AD26
B17: 10 | C17: =IF(ISNUMBER(Timetable!C15),HOUR(Timetable!C15)&":"&RIGHT("0"&MINUTE(Timetable!C15),2),"") | D17: =IF(IF(ISNUMBER(N17),INDEX(Lessons!$I$6:$I$505,N17),IF(WEEKDAY(TODAY(),2)>5,"",IF(INDEX(Timetable!$E$6:$I$15,10,WEEKDAY(TODAY(),2))="","",INDEX(Timetable!$E$6:$I$15,10,WEEKDAY(TODAY(),2)))))="","",IF(ISNUMBER(N17),INDEX(Lessons!$I$6:$I$505,N17),IF(WEEKDAY(TODAY(),2)>5,"",IF(INDEX(Timetable!$E$6:$I$15,10,WEEKDAY(TODAY(),2))="","",INDEX(Timetable!$E$6:$I$15,10,WEEKDAY(TODAY(),2)))))) | E17: =IF(ISNUMBER(N17),IF(INDEX(Lessons!$E$6:$E$505,N17)="","",INDEX(Lessons!$E$6:$E$505,N17)),IF(IF(WEEKDAY(TODAY(),2)>5,"",IF(INDEX(Timetable!$E$6:$I$15,10,WEEKDAY(TODAY(),2))="","",INDEX(Timetable!$E$6:$I$15,10,WEEKDAY(TODAY(),2))))="","","Not planned yet")) | G17: =IF(O17="","",CHOOSE(INT(MOD(O17,1000)/100),INDEX('Class 1'!$B$1:$B$50,MOD(O17,100)+10),INDEX('Class 2'!$B$1:$B$50,MOD(O17,100)+10),INDEX('Class 3'!$B$1:$B$50,MOD(O17,100)+10),INDEX('Class 4'!$B$1:$B$50,MOD(O17,100)+10),INDEX('Class 5'!$B$1:$B$50,MOD(O17,100)+10),INDEX('Class 6'!$B$1:$B$50,MOD(O17,100)+10))) | H17: =IF(O17="","",IF(CHOOSE(INT(MOD(O17,1000)/100),Settings!$C$9,Settings!$C$10,Settings!$C$11,Settings!$C$12,Settings!$C$13,Settings!$C$14)="","",CHOOSE(INT(MOD(O17,1000)/100),Settings!$C$9,Settings!$C$10,Settings!$C$11,Settings!$C$12,Settings!$C$13,Settings!$C$14))) | I17: =IF(O17="","",CHOOSE(INT(MOD(O17,1000)/100),INDEX('Class 1'!$C$1:$C$50,MOD(O17,100)+10),INDEX('Class 2'!$C$1:$C$50,MOD(O17,100)+10),INDEX('Class 3'!$C$1:$C$50,MOD(O17,100)+10),INDEX('Class 4'!$C$1:$C$50,MOD(O17,100)+10),INDEX('Class 5'!$C$1:$C$50,MOD(O17,100)+10),INDEX('Class 6'!$C$1:$C$50,MOD(O17,100)+10))) | J17: =IF(O17="","",CHOOSE(INT(MOD(O17,1000)/100),INDEX('Class 1'!$F$1:$F$50,MOD(O17,100)+10),INDEX('Class 2'!$F$1:$F$50,MOD(O17,100)+10),INDEX('Class 3'!$F$1:$F$50,MOD(O17,100)+10),INDEX('Class 4'!$F$1:$F$50,MOD(O17,100)+10),INDEX('Class 5'!$F$1:$F$50,MOD(O17,100)+10),INDEX('Class 6'!$F$1:$F$50,MOD(O17,100)+10))) | N17: =IFERROR(MATCH(TODAY()*100+10,Lessons!$K$6:$K$505,0),"") | O17: =IFERROR(SMALL($P$1:$P$240,2),"") | P17: ='Class 1'!AD27
G18: =IF(O18="","",CHOOSE(INT(MOD(O18,1000)/100),INDEX('Class 1'!$B$1:$B$50,MOD(O18,100)+10),INDEX('Class 2'!$B$1:$B$50,MOD(O18,100)+10),INDEX('Class 3'!$B$1:$B$50,MOD(O18,100)+10),INDEX('Class 4'!$B$1:$B$50,MOD(O18,100)+10),INDEX('Class 5'!$B$1:$B$50,MOD(O18,100)+10),INDEX('Class 6'!$B$1:$B$50,MOD(O18,100)+10))) | H18: =IF(O18="","",IF(CHOOSE(INT(MOD(O18,1000)/100),Settings!$C$9,Settings!$C$10,Settings!$C$11,Settings!$C$12,Settings!$C$13,Settings!$C$14)="","",CHOOSE(INT(MOD(O18,1000)/100),Settings!$C$9,Settings!$C$10,Settings!$C$11,Settings!$C$12,Settings!$C$13,Settings!$C$14))) | I18: =IF(O18="","",CHOOSE(INT(MOD(O18,1000)/100),INDEX('Class 1'!$C$1:$C$50,MOD(O18,100)+10),INDEX('Class 2'!$C$1:$C$50,MOD(O18,100)+10),INDEX('Class 3'!$C$1:$C$50,MOD(O18,100)+10),INDEX('Class 4'!$C$1:$C$50,MOD(O18,100)+10),INDEX('Class 5'!$C$1:$C$50,MOD(O18,100)+10),INDEX('Class 6'!$C$1:$C$50,MOD(O18,100)+10))) | J18: =IF(O18="","",CHOOSE(INT(MOD(O18,1000)/100),INDEX('Class 1'!$F$1:$F$50,MOD(O18,100)+10),INDEX('Class 2'!$F$1:$F$50,MOD(O18,100)+10),INDEX('Class 3'!$F$1:$F$50,MOD(O18,100)+10),INDEX('Class 4'!$F$1:$F$50,MOD(O18,100)+10),INDEX('Class 5'!$F$1:$F$50,MOD(O18,100)+10),INDEX('Class 6'!$F$1:$F$50,MOD(O18,100)+10))) | O18: =IFERROR(SMALL($P$1:$P$240,3),"") | P18: ='Class 1'!AD28
G19: =IF(O19="","",CHOOSE(INT(MOD(O19,1000)/100),INDEX('Class 1'!$B$1:$B$50,MOD(O19,100)+10),INDEX('Class 2'!$B$1:$B$50,MOD(O19,100)+10),INDEX('Class 3'!$B$1:$B$50,MOD(O19,100)+10),INDEX('Class 4'!$B$1:$B$50,MOD(O19,100)+10),INDEX('Class 5'!$B$1:$B$50,MOD(O19,100)+10),INDEX('Class 6'!$B$1:$B$50,MOD(O19,100)+10))) | H19: =IF(O19="","",IF(CHOOSE(INT(MOD(O19,1000)/100),Settings!$C$9,Settings!$C$10,Settings!$C$11,Settings!$C$12,Settings!$C$13,Settings!$C$14)="","",CHOOSE(INT(MOD(O19,1000)/100),Settings!$C$9,Settings!$C$10,Settings!$C$11,Settings!$C$12,Settings!$C$13,Settings!$C$14))) | I19: =IF(O19="","",CHOOSE(INT(MOD(O19,1000)/100),INDEX('Class 1'!$C$1:$C$50,MOD(O19,100)+10),INDEX('Class 2'!$C$1:$C$50,MOD(O19,100)+10),INDEX('Class 3'!$C$1:$C$50,MOD(O19,100)+10),INDEX('Class 4'!$C$1:$C$50,MOD(O19,100)+10),INDEX('Class 5'!$C$1:$C$50,MOD(O19,100)+10),INDEX('Class 6'!$C$1:$C$50,MOD(O19,100)+10))) | J19: =IF(O19="","",CHOOSE(INT(MOD(O19,1000)/100),INDEX('Class 1'!$F$1:$F$50,MOD(O19,100)+10),INDEX('Class 2'!$F$1:$F$50,MOD(O19,100)+10),INDEX('Class 3'!$F$1:$F$50,MOD(O19,100)+10),INDEX('Class 4'!$F$1:$F$50,MOD(O19,100)+10),INDEX('Class 5'!$F$1:$F$50,MOD(O19,100)+10),INDEX('Class 6'!$F$1:$F$50,MOD(O19,100)+10))) | O19: =IFERROR(SMALL($P$1:$P$240,4),"") | P19: ='Class 1'!AD29
G20: =IF(O20="","",CHOOSE(INT(MOD(O20,1000)/100),INDEX('Class 1'!$B$1:$B$50,MOD(O20,100)+10),INDEX('Class 2'!$B$1:$B$50,MOD(O20,100)+10),INDEX('Class 3'!$B$1:$B$50,MOD(O20,100)+10),INDEX('Class 4'!$B$1:$B$50,MOD(O20,100)+10),INDEX('Class 5'!$B$1:$B$50,MOD(O20,100)+10),INDEX('Class 6'!$B$1:$B$50,MOD(O20,100)+10))) | H20: =IF(O20="","",IF(CHOOSE(INT(MOD(O20,1000)/100),Settings!$C$9,Settings!$C$10,Settings!$C$11,Settings!$C$12,Settings!$C$13,Settings!$C$14)="","",CHOOSE(INT(MOD(O20,1000)/100),Settings!$C$9,Settings!$C$10,Settings!$C$11,Settings!$C$12,Settings!$C$13,Settings!$C$14))) | I20: =IF(O20="","",CHOOSE(INT(MOD(O20,1000)/100),INDEX('Class 1'!$C$1:$C$50,MOD(O20,100)+10),INDEX('Class 2'!$C$1:$C$50,MOD(O20,100)+10),INDEX('Class 3'!$C$1:$C$50,MOD(O20,100)+10),INDEX('Class 4'!$C$1:$C$50,MOD(O20,100)+10),INDEX('Class 5'!$C$1:$C$50,MOD(O20,100)+10),INDEX('Class 6'!$C$1:$C$50,MOD(O20,100)+10))) | J20: =IF(O20="","",CHOOSE(INT(MOD(O20,1000)/100),INDEX('Class 1'!$F$1:$F$50,MOD(O20,100)+10),INDEX('Class 2'!$F$1:$F$50,MOD(O20,100)+10),INDEX('Class 3'!$F$1:$F$50,MOD(O20,100)+10),INDEX('Class 4'!$F$1:$F$50,MOD(O20,100)+10),INDEX('Class 5'!$F$1:$F$50,MOD(O20,100)+10),INDEX('Class 6'!$F$1:$F$50,MOD(O20,100)+10))) | O20: =IFERROR(SMALL($P$1:$P$240,5),"") | P20: ='Class 1'!AD30
G21: =IF(O21="","",CHOOSE(INT(MOD(O21,1000)/100),INDEX('Class 1'!$B$1:$B$50,MOD(O21,100)+10),INDEX('Class 2'!$B$1:$B$50,MOD(O21,100)+10),INDEX('Class 3'!$B$1:$B$50,MOD(O21,100)+10),INDEX('Class 4'!$B$1:$B$50,MOD(O21,100)+10),INDEX('Class 5'!$B$1:$B$50,MOD(O21,100)+10),INDEX('Class 6'!$B$1:$B$50,MOD(O21,100)+10))) | H21: =IF(O21="","",IF(CHOOSE(INT(MOD(O21,1000)/100),Settings!$C$9,Settings!$C$10,Settings!$C$11,Settings!$C$12,Settings!$C$13,Settings!$C$14)="","",CHOOSE(INT(MOD(O21,1000)/100),Settings!$C$9,Settings!$C$10,Settings!$C$11,Settings!$C$12,Settings!$C$13,Settings!$C$14))) | I21: =IF(O21="","",CHOOSE(INT(MOD(O21,1000)/100),INDEX('Class 1'!$C$1:$C$50,MOD(O21,100)+10),INDEX('Class 2'!$C$1:$C$50,MOD(O21,100)+10),INDEX('Class 3'!$C$1:$C$50,MOD(O21,100)+10),INDEX('Class 4'!$C$1:$C$50,MOD(O21,100)+10),INDEX('Class 5'!$C$1:$C$50,MOD(O21,100)+10),INDEX('Class 6'!$C$1:$C$50,MOD(O21,100)+10))) | J21: =IF(O21="","",CHOOSE(INT(MOD(O21,1000)/100),INDEX('Class 1'!$F$1:$F$50,MOD(O21,100)+10),INDEX('Class 2'!$F$1:$F$50,MOD(O21,100)+10),INDEX('Class 3'!$F$1:$F$50,MOD(O21,100)+10),INDEX('Class 4'!$F$1:$F$50,MOD(O21,100)+10),INDEX('Class 5'!$F$1:$F$50,MOD(O21,100)+10),INDEX('Class 6'!$F$1:$F$50,MOD(O21,100)+10))) | O21: =IFERROR(SMALL($P$1:$P$240,6),"") | P21: ='Class 1'!AD31
G22: =IF(O22="","",CHOOSE(INT(MOD(O22,1000)/100),INDEX('Class 1'!$B$1:$B$50,MOD(O22,100)+10),INDEX('Class 2'!$B$1:$B$50,MOD(O22,100)+10),INDEX('Class 3'!$B$1:$B$50,MOD(O22,100)+10),INDEX('Class 4'!$B$1:$B$50,MOD(O22,100)+10),INDEX('Class 5'!$B$1:$B$50,MOD(O22,100)+10),INDEX('Class 6'!$B$1:$B$50,MOD(O22,100)+10))) | H22: =IF(O22="","",IF(CHOOSE(INT(MOD(O22,1000)/100),Settings!$C$9,Settings!$C$10,Settings!$C$11,Settings!$C$12,Settings!$C$13,Settings!$C$14)="","",CHOOSE(INT(MOD(O22,1000)/100),Settings!$C$9,Settings!$C$10,Settings!$C$11,Settings!$C$12,Settings!$C$13,Settings!$C$14))) | I22: =IF(O22="","",CHOOSE(INT(MOD(O22,1000)/100),INDEX('Class 1'!$C$1:$C$50,MOD(O22,100)+10),INDEX('Class 2'!$C$1:$C$50,MOD(O22,100)+10),INDEX('Class 3'!$C$1:$C$50,MOD(O22,100)+10),INDEX('Class 4'!$C$1:$C$50,MOD(O22,100)+10),INDEX('Class 5'!$C$1:$C$50,MOD(O22,100)+10),INDEX('Class 6'!$C$1:$C$50,MOD(O22,100)+10))) | J22: =IF(O22="","",CHOOSE(INT(MOD(O22,1000)/100),INDEX('Class 1'!$F$1:$F$50,MOD(O22,100)+10),INDEX('Class 2'!$F$1:$F$50,MOD(O22,100)+10),INDEX('Class 3'!$F$1:$F$50,MOD(O22,100)+10),INDEX('Class 4'!$F$1:$F$50,MOD(O22,100)+10),INDEX('Class 5'!$F$1:$F$50,MOD(O22,100)+10),INDEX('Class 6'!$F$1:$F$50,MOD(O22,100)+10))) | O22: =IFERROR(SMALL($P$1:$P$240,7),"") | P22: ='Class 1'!AD32
G23: =IF(O23="","",CHOOSE(INT(MOD(O23,1000)/100),INDEX('Class 1'!$B$1:$B$50,MOD(O23,100)+10),INDEX('Class 2'!$B$1:$B$50,MOD(O23,100)+10),INDEX('Class 3'!$B$1:$B$50,MOD(O23,100)+10),INDEX('Class 4'!$B$1:$B$50,MOD(O23,100)+10),INDEX('Class 5'!$B$1:$B$50,MOD(O23,100)+10),INDEX('Class 6'!$B$1:$B$50,MOD(O23,100)+10))) | H23: =IF(O23="","",IF(CHOOSE(INT(MOD(O23,1000)/100),Settings!$C$9,Settings!$C$10,Settings!$C$11,Settings!$C$12,Settings!$C$13,Settings!$C$14)="","",CHOOSE(INT(MOD(O23,1000)/100),Settings!$C$9,Settings!$C$10,Settings!$C$11,Settings!$C$12,Settings!$C$13,Settings!$C$14))) | I23: =IF(O23="","",CHOOSE(INT(MOD(O23,1000)/100),INDEX('Class 1'!$C$1:$C$50,MOD(O23,100)+10),INDEX('Class 2'!$C$1:$C$50,MOD(O23,100)+10),INDEX('Class 3'!$C$1:$C$50,MOD(O23,100)+10),INDEX('Class 4'!$C$1:$C$50,MOD(O23,100)+10),INDEX('Class 5'!$C$1:$C$50,MOD(O23,100)+10),INDEX('Class 6'!$C$1:$C$50,MOD(O23,100)+10))) | J23: =IF(O23="","",CHOOSE(INT(MOD(O23,1000)/100),INDEX('Class 1'!$F$1:$F$50,MOD(O23,100)+10),INDEX('Class 2'!$F$1:$F$50,MOD(O23,100)+10),INDEX('Class 3'!$F$1:$F$50,MOD(O23,100)+10),INDEX('Class 4'!$F$1:$F$50,MOD(O23,100)+10),INDEX('Class 5'!$F$1:$F$50,MOD(O23,100)+10),INDEX('Class 6'!$F$1:$F$50,MOD(O23,100)+10))) | O23: =IFERROR(SMALL($P$1:$P$240,8),"") | P23: ='Class 1'!AD33
P24: ='Class 1'!AD34
P25: ='Class 1'!AD35
P26: ='Class 1'!AD36
P27: ='Class 1'!AD37
P28: ='Class 1'!AD38
P29: ='Class 1'!AD39
P30: ='Class 1'!AD40
P31: ='Class 1'!AD41
P32: ='Class 1'!AD42
P33: ='Class 1'!AD43
P34: ='Class 1'!AD44
P35: ='Class 1'!AD45
... P40: ='Class 1'!AD50
P41: ='Class 2'!AD11
P42: ='Class 2'!AD12
P43: ='Class 2'!AD13
P44: ='Class 2'!AD14
...

Sheet Week
B2: ="Week of "&DAY(Settings!$C$6)&" "&CHOOSE(MONTH(Settings!$C$6),"Jan","Feb","Mar","Apr","May","Jun","Jul","Aug","Sep","Oct","Nov","Dec")&" to "&DAY((Settings!$C$6+4))&" "&CHOOSE(MONTH((Settings!$C$6+4)),"Jan","Feb","Mar","Apr","May","Jun","Jul","Aug","Sep","Oct","Nov","Dec")
B3: The class and topic of each lesson. Shaded: a lesson on the timetable with no plan yet.
B5: Period | C5: Time | D5: ="Mon "&DAY(Settings!$C$6+0) | E5: ="Tue "&DAY(Settings!$C$6+1) | F5: ="Wed "&DAY(Settings!$C$6+2) | G5: ="Thu "&DAY(Settings!$C$6+3) | H5: ="Fri "&DAY(Settings!$C$6+4)
B6: 1 | C6: =IF(ISNUMBER(Timetable!C6),HOUR(Timetable!C6)&":"&RIGHT("0"&MINUTE(Timetable!C6),2),"") | D6: =IF(IF(ISNUMBER(M6),INDEX(Lessons!$I$6:$I$505,M6),IF(INDEX(Timetable!$E$6:$I$15,1,1)="","",INDEX(Timetable!$E$6:$I$15,1,1)))="","",IF(ISNUMBER(M6),INDEX(Lessons!$I$6:$I$505,M6),IF(INDEX(Timetable!$E$6:$I$15,1,1)="","",INDEX(Timetable!$E$6:$I$15,1,1)))&IF(IF(ISNUMBER(M6),INDEX(Lessons!$E$6:$E$505,M6),"")="","",CHAR(10)&IF(ISNUMBER(M6),INDEX(Lessons!$E$6:$E$505,M6),""))) | E6: =IF(IF(ISNUMBER(N6),INDEX(Lessons!$I$6:$I$505,N6),IF(INDEX(Timetable!$E$6:$I$15,1,2)="","",INDEX(Timetable!$E$6:$I$15,1,2)))="","",IF(ISNUMBER(N6),INDEX(Lessons!$I$6:$I$505,N6),IF(INDEX(Timetable!$E$6:$I$15,1,2)="","",INDEX(Timetable!$E$6:$I$15,1,2)))&IF(IF(ISNUMBER(N6),INDEX(Lessons!$E$6:$E$505,N6),"")="","",CHAR(10)&IF(ISNUMBER(N6),INDEX(Lessons!$E$6:$E$505,N6),""))) | F6: =IF(IF(ISNUMBER(O6),INDEX(Lessons!$I$6:$I$505,O6),IF(INDEX(Timetable!$E$6:$I$15,1,3)="","",INDEX(Timetable!$E$6:$I$15,1,3)))="","",IF(ISNUMBER(O6),INDEX(Lessons!$I$6:$I$505,O6),IF(INDEX(Timetable!$E$6:$I$15,1,3)="","",INDEX(Timetable!$E$6:$I$15,1,3)))&IF(IF(ISNUMBER(O6),INDEX(Lessons!$E$6:$E$505,O6),"")="","",CHAR(10)&IF(ISNUMBER(O6),INDEX(Lessons!$E$6:$E$505,O6),""))) | G6: =IF(IF(ISNUMBER(P6),INDEX(Lessons!$I$6:$I$505,P6),IF(INDEX(Timetable!$E$6:$I$15,1,4)="","",INDEX(Timetable!$E$6:$I$15,1,4)))="","",IF(ISNUMBER(P6),INDEX(Lessons!$I$6:$I$505,P6),IF(INDEX(Timetable!$E$6:$I$15,1,4)="","",INDEX(Timetable!$E$6:$I$15,1,4)))&IF(IF(ISNUMBER(P6),INDEX(Lessons!$E$6:$E$505,P6),"")="","",CHAR(10)&IF(ISNUMBER(P6),INDEX(Lessons!$E$6:$E$505,P6),""))) | H6: =IF(IF(ISNUMBER(Q6),INDEX(Lessons!$I$6:$I$505,Q6),IF(INDEX(Timetable!$E$6:$I$15,1,5)="","",INDEX(Timetable!$E$6:$I$15,1,5)))="","",IF(ISNUMBER(Q6),INDEX(Lessons!$I$6:$I$505,Q6),IF(INDEX(Timetable!$E$6:$I$15,1,5)="","",INDEX(Timetable!$E$6:$I$15,1,5)))&IF(IF(ISNUMBER(Q6),INDEX(Lessons!$E$6:$E$505,Q6),"")="","",CHAR(10)&IF(ISNUMBER(Q6),INDEX(Lessons!$E$6:$E$505,Q6),""))) | M6: =IFERROR(MATCH((Settings!$C$6+0)*100+1,Lessons!$K$6:$K$505,0),"") | N6: =IFERROR(MATCH((Settings!$C$6+1)*100+1,Lessons!$K$6:$K$505,0),"") | O6: =IFERROR(MATCH((Settings!$C$6+2)*100+1,Lessons!$K$6:$K$505,0),"") | P6: =IFERROR(MATCH((Settings!$C$6+3)*100+1,Lessons!$K$6:$K$505,0),"") | Q6: =IFERROR(MATCH((Settings!$C$6+4)*100+1,Lessons!$K$6:$K$505,0),"") | R6: =IF(AND(NOT(ISNUMBER(M6)),IF(INDEX(Timetable!$E$6:$I$15,1,1)="","",INDEX(Timetable!$E$6:$I$15,1,1))<>""),1,0) | S6: =IF(AND(NOT(ISNUMBER(N6)),IF(INDEX(Timetable!$E$6:$I$15,1,2)="","",INDEX(Timetable!$E$6:$I$15,1,2))<>""),1,0) | T6: =IF(AND(NOT(ISNUMBER(O6)),IF(INDEX(Timetable!$E$6:$I$15,1,3)="","",INDEX(Timetable!$E$6:$I$15,1,3))<>""),1,0) | U6: =IF(AND(NOT(ISNUMBER(P6)),IF(INDEX(Timetable!$E$6:$I$15,1,4)="","",INDEX(Timetable!$E$6:$I$15,1,4))<>""),1,0) | V6: =IF(AND(NOT(ISNUMBER(Q6)),IF(INDEX(Timetable!$E$6:$I$15,1,5)="","",INDEX(Timetable!$E$6:$I$15,1,5))<>""),1,0)
B7: 2 | C7: =IF(ISNUMBER(Timetable!C7),HOUR(Timetable!C7)&":"&RIGHT("0"&MINUTE(Timetable!C7),2),"") | D7: =IF(IF(ISNUMBER(M7),INDEX(Lessons!$I$6:$I$505,M7),IF(INDEX(Timetable!$E$6:$I$15,2,1)="","",INDEX(Timetable!$E$6:$I$15,2,1)))="","",IF(ISNUMBER(M7),INDEX(Lessons!$I$6:$I$505,M7),IF(INDEX(Timetable!$E$6:$I$15,2,1)="","",INDEX(Timetable!$E$6:$I$15,2,1)))&IF(IF(ISNUMBER(M7),INDEX(Lessons!$E$6:$E$505,M7),"")="","",CHAR(10)&IF(ISNUMBER(M7),INDEX(Lessons!$E$6:$E$505,M7),""))) | E7: =IF(IF(ISNUMBER(N7),INDEX(Lessons!$I$6:$I$505,N7),IF(INDEX(Timetable!$E$6:$I$15,2,2)="","",INDEX(Timetable!$E$6:$I$15,2,2)))="","",IF(ISNUMBER(N7),INDEX(Lessons!$I$6:$I$505,N7),IF(INDEX(Timetable!$E$6:$I$15,2,2)="","",INDEX(Timetable!$E$6:$I$15,2,2)))&IF(IF(ISNUMBER(N7),INDEX(Lessons!$E$6:$E$505,N7),"")="","",CHAR(10)&IF(ISNUMBER(N7),INDEX(Lessons!$E$6:$E$505,N7),""))) | F7: =IF(IF(ISNUMBER(O7),INDEX(Lessons!$I$6:$I$505,O7),IF(INDEX(Timetable!$E$6:$I$15,2,3)="","",INDEX(Timetable!$E$6:$I$15,2,3)))="","",IF(ISNUMBER(O7),INDEX(Lessons!$I$6:$I$505,O7),IF(INDEX(Timetable!$E$6:$I$15,2,3)="","",INDEX(Timetable!$E$6:$I$15,2,3)))&IF(IF(ISNUMBER(O7),INDEX(Lessons!$E$6:$E$505,O7),"")="","",CHAR(10)&IF(ISNUMBER(O7),INDEX(Lessons!$E$6:$E$505,O7),""))) | G7: =IF(IF(ISNUMBER(P7),INDEX(Lessons!$I$6:$I$505,P7),IF(INDEX(Timetable!$E$6:$I$15,2,4)="","",INDEX(Timetable!$E$6:$I$15,2,4)))="","",IF(ISNUMBER(P7),INDEX(Lessons!$I$6:$I$505,P7),IF(INDEX(Timetable!$E$6:$I$15,2,4)="","",INDEX(Timetable!$E$6:$I$15,2,4)))&IF(IF(ISNUMBER(P7),INDEX(Lessons!$E$6:$E$505,P7),"")="","",CHAR(10)&IF(ISNUMBER(P7),INDEX(Lessons!$E$6:$E$505,P7),""))) | H7: =IF(IF(ISNUMBER(Q7),INDEX(Lessons!$I$6:$I$505,Q7),IF(INDEX(Timetable!$E$6:$I$15,2,5)="","",INDEX(Timetable!$E$6:$I$15,2,5)))="","",IF(ISNUMBER(Q7),INDEX(Lessons!$I$6:$I$505,Q7),IF(INDEX(Timetable!$E$6:$I$15,2,5)="","",INDEX(Timetable!$E$6:$I$15,2,5)))&IF(IF(ISNUMBER(Q7),INDEX(Lessons!$E$6:$E$505,Q7),"")="","",CHAR(10)&IF(ISNUMBER(Q7),INDEX(Lessons!$E$6:$E$505,Q7),""))) | M7: =IFERROR(MATCH((Settings!$C$6+0)*100+2,Lessons!$K$6:$K$505,0),"") | N7: =IFERROR(MATCH((Settings!$C$6+1)*100+2,Lessons!$K$6:$K$505,0),"") | O7: =IFERROR(MATCH((Settings!$C$6+2)*100+2,Lessons!$K$6:$K$505,0),"") | P7: =IFERROR(MATCH((Settings!$C$6+3)*100+2,Lessons!$K$6:$K$505,0),"") | Q7: =IFERROR(MATCH((Settings!$C$6+4)*100+2,Lessons!$K$6:$K$505,0),"") | R7: =IF(AND(NOT(ISNUMBER(M7)),IF(INDEX(Timetable!$E$6:$I$15,2,1)="","",INDEX(Timetable!$E$6:$I$15,2,1))<>""),1,0) | S7: =IF(AND(NOT(ISNUMBER(N7)),IF(INDEX(Timetable!$E$6:$I$15,2,2)="","",INDEX(Timetable!$E$6:$I$15,2,2))<>""),1,0) | T7: =IF(AND(NOT(ISNUMBER(O7)),IF(INDEX(Timetable!$E$6:$I$15,2,3)="","",INDEX(Timetable!$E$6:$I$15,2,3))<>""),1,0) | U7: =IF(AND(NOT(ISNUMBER(P7)),IF(INDEX(Timetable!$E$6:$I$15,2,4)="","",INDEX(Timetable!$E$6:$I$15,2,4))<>""),1,0) | V7: =IF(AND(NOT(ISNUMBER(Q7)),IF(INDEX(Timetable!$E$6:$I$15,2,5)="","",INDEX(Timetable!$E$6:$I$15,2,5))<>""),1,0)
B8: 3 | C8: =IF(ISNUMBER(Timetable!C8),HOUR(Timetable!C8)&":"&RIGHT("0"&MINUTE(Timetable!C8),2),"") | D8: =IF(IF(ISNUMBER(M8),INDEX(Lessons!$I$6:$I$505,M8),IF(INDEX(Timetable!$E$6:$I$15,3,1)="","",INDEX(Timetable!$E$6:$I$15,3,1)))="","",IF(ISNUMBER(M8),INDEX(Lessons!$I$6:$I$505,M8),IF(INDEX(Timetable!$E$6:$I$15,3,1)="","",INDEX(Timetable!$E$6:$I$15,3,1)))&IF(IF(ISNUMBER(M8),INDEX(Lessons!$E$6:$E$505,M8),"")="","",CHAR(10)&IF(ISNUMBER(M8),INDEX(Lessons!$E$6:$E$505,M8),""))) | E8: =IF(IF(ISNUMBER(N8),INDEX(Lessons!$I$6:$I$505,N8),IF(INDEX(Timetable!$E$6:$I$15,3,2)="","",INDEX(Timetable!$E$6:$I$15,3,2)))="","",IF(ISNUMBER(N8),INDEX(Lessons!$I$6:$I$505,N8),IF(INDEX(Timetable!$E$6:$I$15,3,2)="","",INDEX(Timetable!$E$6:$I$15,3,2)))&IF(IF(ISNUMBER(N8),INDEX(Lessons!$E$6:$E$505,N8),"")="","",CHAR(10)&IF(ISNUMBER(N8),INDEX(Lessons!$E$6:$E$505,N8),""))) | F8: =IF(IF(ISNUMBER(O8),INDEX(Lessons!$I$6:$I$505,O8),IF(INDEX(Timetable!$E$6:$I$15,3,3)="","",INDEX(Timetable!$E$6:$I$15,3,3)))="","",IF(ISNUMBER(O8),INDEX(Lessons!$I$6:$I$505,O8),IF(INDEX(Timetable!$E$6:$I$15,3,3)="","",INDEX(Timetable!$E$6:$I$15,3,3)))&IF(IF(ISNUMBER(O8),INDEX(Lessons!$E$6:$E$505,O8),"")="","",CHAR(10)&IF(ISNUMBER(O8),INDEX(Lessons!$E$6:$E$505,O8),""))) | G8: =IF(IF(ISNUMBER(P8),INDEX(Lessons!$I$6:$I$505,P8),IF(INDEX(Timetable!$E$6:$I$15,3,4)="","",INDEX(Timetable!$E$6:$I$15,3,4)))="","",IF(ISNUMBER(P8),INDEX(Lessons!$I$6:$I$505,P8),IF(INDEX(Timetable!$E$6:$I$15,3,4)="","",INDEX(Timetable!$E$6:$I$15,3,4)))&IF(IF(ISNUMBER(P8),INDEX(Lessons!$E$6:$E$505,P8),"")="","",CHAR(10)&IF(ISNUMBER(P8),INDEX(Lessons!$E$6:$E$505,P8),""))) | H8: =IF(IF(ISNUMBER(Q8),INDEX(Lessons!$I$6:$I$505,Q8),IF(INDEX(Timetable!$E$6:$I$15,3,5)="","",INDEX(Timetable!$E$6:$I$15,3,5)))="","",IF(ISNUMBER(Q8),INDEX(Lessons!$I$6:$I$505,Q8),IF(INDEX(Timetable!$E$6:$I$15,3,5)="","",INDEX(Timetable!$E$6:$I$15,3,5)))&IF(IF(ISNUMBER(Q8),INDEX(Lessons!$E$6:$E$505,Q8),"")="","",CHAR(10)&IF(ISNUMBER(Q8),INDEX(Lessons!$E$6:$E$505,Q8),""))) | M8: =IFERROR(MATCH((Settings!$C$6+0)*100+3,Lessons!$K$6:$K$505,0),"") | N8: =IFERROR(MATCH((Settings!$C$6+1)*100+3,Lessons!$K$6:$K$505,0),"") | O8: =IFERROR(MATCH((Settings!$C$6+2)*100+3,Lessons!$K$6:$K$505,0),"") | P8: =IFERROR(MATCH((Settings!$C$6+3)*100+3,Lessons!$K$6:$K$505,0),"") | Q8: =IFERROR(MATCH((Settings!$C$6+4)*100+3,Lessons!$K$6:$K$505,0),"") | R8: =IF(AND(NOT(ISNUMBER(M8)),IF(INDEX(Timetable!$E$6:$I$15,3,1)="","",INDEX(Timetable!$E$6:$I$15,3,1))<>""),1,0) | S8: =IF(AND(NOT(ISNUMBER(N8)),IF(INDEX(Timetable!$E$6:$I$15,3,2)="","",INDEX(Timetable!$E$6:$I$15,3,2))<>""),1,0) | T8: =IF(AND(NOT(ISNUMBER(O8)),IF(INDEX(Timetable!$E$6:$I$15,3,3)="","",INDEX(Timetable!$E$6:$I$15,3,3))<>""),1,0) | U8: =IF(AND(NOT(ISNUMBER(P8)),IF(INDEX(Timetable!$E$6:$I$15,3,4)="","",INDEX(Timetable!$E$6:$I$15,3,4))<>""),1,0) | V8: =IF(AND(NOT(ISNUMBER(Q8)),IF(INDEX(Timetable!$E$6:$I$15,3,5)="","",INDEX(Timetable!$E$6:$I$15,3,5))<>""),1,0)
B9: 4 | C9: =IF(ISNUMBER(Timetable!C9),HOUR(Timetable!C9)&":"&RIGHT("0"&MINUTE(Timetable!C9),2),"") | D9: =IF(IF(ISNUMBER(M9),INDEX(Lessons!$I$6:$I$505,M9),IF(INDEX(Timetable!$E$6:$I$15,4,1)="","",INDEX(Timetable!$E$6:$I$15,4,1)))="","",IF(ISNUMBER(M9),INDEX(Lessons!$I$6:$I$505,M9),IF(INDEX(Timetable!$E$6:$I$15,4,1)="","",INDEX(Timetable!$E$6:$I$15,4,1)))&IF(IF(ISNUMBER(M9),INDEX(Lessons!$E$6:$E$505,M9),"")="","",CHAR(10)&IF(ISNUMBER(M9),INDEX(Lessons!$E$6:$E$505,M9),""))) | E9: =IF(IF(ISNUMBER(N9),INDEX(Lessons!$I$6:$I$505,N9),IF(INDEX(Timetable!$E$6:$I$15,4,2)="","",INDEX(Timetable!$E$6:$I$15,4,2)))="","",IF(ISNUMBER(N9),INDEX(Lessons!$I$6:$I$505,N9),IF(INDEX(Timetable!$E$6:$I$15,4,2)="","",INDEX(Timetable!$E$6:$I$15,4,2)))&IF(IF(ISNUMBER(N9),INDEX(Lessons!$E$6:$E$505,N9),"")="","",CHAR(10)&IF(ISNUMBER(N9),INDEX(Lessons!$E$6:$E$505,N9),""))) | F9: =IF(IF(ISNUMBER(O9),INDEX(Lessons!$I$6:$I$505,O9),IF(INDEX(Timetable!$E$6:$I$15,4,3)="","",INDEX(Timetable!$E$6:$I$15,4,3)))="","",IF(ISNUMBER(O9),INDEX(Lessons!$I$6:$I$505,O9),IF(INDEX(Timetable!$E$6:$I$15,4,3)="","",INDEX(Timetable!$E$6:$I$15,4,3)))&IF(IF(ISNUMBER(O9),INDEX(Lessons!$E$6:$E$505,O9),"")="","",CHAR(10)&IF(ISNUMBER(O9),INDEX(Lessons!$E$6:$E$505,O9),""))) | G9: =IF(IF(ISNUMBER(P9),INDEX(Lessons!$I$6:$I$505,P9),IF(INDEX(Timetable!$E$6:$I$15,4,4)="","",INDEX(Timetable!$E$6:$I$15,4,4)))="","",IF(ISNUMBER(P9),INDEX(Lessons!$I$6:$I$505,P9),IF(INDEX(Timetable!$E$6:$I$15,4,4)="","",INDEX(Timetable!$E$6:$I$15,4,4)))&IF(IF(ISNUMBER(P9),INDEX(Lessons!$E$6:$E$505,P9),"")="","",CHAR(10)&IF(ISNUMBER(P9),INDEX(Lessons!$E$6:$E$505,P9),""))) | H9: =IF(IF(ISNUMBER(Q9),INDEX(Lessons!$I$6:$I$505,Q9),IF(INDEX(Timetable!$E$6:$I$15,4,5)="","",INDEX(Timetable!$E$6:$I$15,4,5)))="","",IF(ISNUMBER(Q9),INDEX(Lessons!$I$6:$I$505,Q9),IF(INDEX(Timetable!$E$6:$I$15,4,5)="","",INDEX(Timetable!$E$6:$I$15,4,5)))&IF(IF(ISNUMBER(Q9),INDEX(Lessons!$E$6:$E$505,Q9),"")="","",CHAR(10)&IF(ISNUMBER(Q9),INDEX(Lessons!$E$6:$E$505,Q9),""))) | M9: =IFERROR(MATCH((Settings!$C$6+0)*100+4,Lessons!$K$6:$K$505,0),"") | N9: =IFERROR(MATCH((Settings!$C$6+1)*100+4,Lessons!$K$6:$K$505,0),"") | O9: =IFERROR(MATCH((Settings!$C$6+2)*100+4,Lessons!$K$6:$K$505,0),"") | P9: =IFERROR(MATCH((Settings!$C$6+3)*100+4,Lessons!$K$6:$K$505,0),"") | Q9: =IFERROR(MATCH((Settings!$C$6+4)*100+4,Lessons!$K$6:$K$505,0),"") | R9: =IF(AND(NOT(ISNUMBER(M9)),IF(INDEX(Timetable!$E$6:$I$15,4,1)="","",INDEX(Timetable!$E$6:$I$15,4,1))<>""),1,0) | S9: =IF(AND(NOT(ISNUMBER(N9)),IF(INDEX(Timetable!$E$6:$I$15,4,2)="","",INDEX(Timetable!$E$6:$I$15,4,2))<>""),1,0) | T9: =IF(AND(NOT(ISNUMBER(O9)),IF(INDEX(Timetable!$E$6:$I$15,4,3)="","",INDEX(Timetable!$E$6:$I$15,4,3))<>""),1,0) | U9: =IF(AND(NOT(ISNUMBER(P9)),IF(INDEX(Timetable!$E$6:$I$15,4,4)="","",INDEX(Timetable!$E$6:$I$15,4,4))<>""),1,0) | V9: =IF(AND(NOT(ISNUMBER(Q9)),IF(INDEX(Timetable!$E$6:$I$15,4,5)="","",INDEX(Timetable!$E$6:$I$15,4,5))<>""),1,0)
B10: 5 | C10: =IF(ISNUMBER(Timetable!C10),HOUR(Timetable!C10)&":"&RIGHT("0"&MINUTE(Timetable!C10),2),"") | D10: =IF(IF(ISNUMBER(M10),INDEX(Lessons!$I$6:$I$505,M10),IF(INDEX(Timetable!$E$6:$I$15,5,1)="","",INDEX(Timetable!$E$6:$I$15,5,1)))="","",IF(ISNUMBER(M10),INDEX(Lessons!$I$6:$I$505,M10),IF(INDEX(Timetable!$E$6:$I$15,5,1)="","",INDEX(Timetable!$E$6:$I$15,5,1)))&IF(IF(ISNUMBER(M10),INDEX(Lessons!$E$6:$E$505,M10),"")="","",CHAR(10)&IF(ISNUMBER(M10),INDEX(Lessons!$E$6:$E$505,M10),""))) | E10: =IF(IF(ISNUMBER(N10),INDEX(Lessons!$I$6:$I$505,N10),IF(INDEX(Timetable!$E$6:$I$15,5,2)="","",INDEX(Timetable!$E$6:$I$15,5,2)))="","",IF(ISNUMBER(N10),INDEX(Lessons!$I$6:$I$505,N10),IF(INDEX(Timetable!$E$6:$I$15,5,2)="","",INDEX(Timetable!$E$6:$I$15,5,2)))&IF(IF(ISNUMBER(N10),INDEX(Lessons!$E$6:$E$505,N10),"")="","",CHAR(10)&IF(ISNUMBER(N10),INDEX(Lessons!$E$6:$E$505,N10),""))) | F10: =IF(IF(ISNUMBER(O10),INDEX(Lessons!$I$6:$I$505,O10),IF(INDEX(Timetable!$E$6:$I$15,5,3)="","",INDEX(Timetable!$E$6:$I$15,5,3)))="","",IF(ISNUMBER(O10),INDEX(Lessons!$I$6:$I$505,O10),IF(INDEX(Timetable!$E$6:$I$15,5,3)="","",INDEX(Timetable!$E$6:$I$15,5,3)))&IF(IF(ISNUMBER(O10),INDEX(Lessons!$E$6:$E$505,O10),"")="","",CHAR(10)&IF(ISNUMBER(O10),INDEX(Lessons!$E$6:$E$505,O10),""))) | G10: =IF(IF(ISNUMBER(P10),INDEX(Lessons!$I$6:$I$505,P10),IF(INDEX(Timetable!$E$6:$I$15,5,4)="","",INDEX(Timetable!$E$6:$I$15,5,4)))="","",IF(ISNUMBER(P10),INDEX(Lessons!$I$6:$I$505,P10),IF(INDEX(Timetable!$E$6:$I$15,5,4)="","",INDEX(Timetable!$E$6:$I$15,5,4)))&IF(IF(ISNUMBER(P10),INDEX(Lessons!$E$6:$E$505,P10),"")="","",CHAR(10)&IF(ISNUMBER(P10),INDEX(Lessons!$E$6:$E$505,P10),""))) | H10: =IF(IF(ISNUMBER(Q10),INDEX(Lessons!$I$6:$I$505,Q10),IF(INDEX(Timetable!$E$6:$I$15,5,5)="","",INDEX(Timetable!$E$6:$I$15,5,5)))="","",IF(ISNUMBER(Q10),INDEX(Lessons!$I$6:$I$505,Q10),IF(INDEX(Timetable!$E$6:$I$15,5,5)="","",INDEX(Timetable!$E$6:$I$15,5,5)))&IF(IF(ISNUMBER(Q10),INDEX(Lessons!$E$6:$E$505,Q10),"")="","",CHAR(10)&IF(ISNUMBER(Q10),INDEX(Lessons!$E$6:$E$505,Q10),""))) | M10: =IFERROR(MATCH((Settings!$C$6+0)*100+5,Lessons!$K$6:$K$505,0),"") | N10: =IFERROR(MATCH((Settings!$C$6+1)*100+5,Lessons!$K$6:$K$505,0),"") | O10: =IFERROR(MATCH((Settings!$C$6+2)*100+5,Lessons!$K$6:$K$505,0),"") | P10: =IFERROR(MATCH((Settings!$C$6+3)*100+5,Lessons!$K$6:$K$505,0),"") | Q10: =IFERROR(MATCH((Settings!$C$6+4)*100+5,Lessons!$K$6:$K$505,0),"") | R10: =IF(AND(NOT(ISNUMBER(M10)),IF(INDEX(Timetable!$E$6:$I$15,5,1)="","",INDEX(Timetable!$E$6:$I$15,5,1))<>""),1,0) | S10: =IF(AND(NOT(ISNUMBER(N10)),IF(INDEX(Timetable!$E$6:$I$15,5,2)="","",INDEX(Timetable!$E$6:$I$15,5,2))<>""),1,0) | T10: =IF(AND(NOT(ISNUMBER(O10)),IF(INDEX(Timetable!$E$6:$I$15,5,3)="","",INDEX(Timetable!$E$6:$I$15,5,3))<>""),1,0) | U10: =IF(AND(NOT(ISNUMBER(P10)),IF(INDEX(Timetable!$E$6:$I$15,5,4)="","",INDEX(Timetable!$E$6:$I$15,5,4))<>""),1,0) | V10: =IF(AND(NOT(ISNUMBER(Q10)),IF(INDEX(Timetable!$E$6:$I$15,5,5)="","",INDEX(Timetable!$E$6:$I$15,5,5))<>""),1,0)
B11: 6 | C11: =IF(ISNUMBER(Timetable!C11),HOUR(Timetable!C11)&":"&RIGHT("0"&MINUTE(Timetable!C11),2),"") | D11: =IF(IF(ISNUMBER(M11),INDEX(Lessons!$I$6:$I$505,M11),IF(INDEX(Timetable!$E$6:$I$15,6,1)="","",INDEX(Timetable!$E$6:$I$15,6,1)))="","",IF(ISNUMBER(M11),INDEX(Lessons!$I$6:$I$505,M11),IF(INDEX(Timetable!$E$6:$I$15,6,1)="","",INDEX(Timetable!$E$6:$I$15,6,1)))&IF(IF(ISNUMBER(M11),INDEX(Lessons!$E$6:$E$505,M11),"")="","",CHAR(10)&IF(ISNUMBER(M11),INDEX(Lessons!$E$6:$E$505,M11),""))) | E11: =IF(IF(ISNUMBER(N11),INDEX(Lessons!$I$6:$I$505,N11),IF(INDEX(Timetable!$E$6:$I$15,6,2)="","",INDEX(Timetable!$E$6:$I$15,6,2)))="","",IF(ISNUMBER(N11),INDEX(Lessons!$I$6:$I$505,N11),IF(INDEX(Timetable!$E$6:$I$15,6,2)="","",INDEX(Timetable!$E$6:$I$15,6,2)))&IF(IF(ISNUMBER(N11),INDEX(Lessons!$E$6:$E$505,N11),"")="","",CHAR(10)&IF(ISNUMBER(N11),INDEX(Lessons!$E$6:$E$505,N11),""))) | F11: =IF(IF(ISNUMBER(O11),INDEX(Lessons!$I$6:$I$505,O11),IF(INDEX(Timetable!$E$6:$I$15,6,3)="","",INDEX(Timetable!$E$6:$I$15,6,3)))="","",IF(ISNUMBER(O11),INDEX(Lessons!$I$6:$I$505,O11),IF(INDEX(Timetable!$E$6:$I$15,6,3)="","",INDEX(Timetable!$E$6:$I$15,6,3)))&IF(IF(ISNUMBER(O11),INDEX(Lessons!$E$6:$E$505,O11),"")="","",CHAR(10)&IF(ISNUMBER(O11),INDEX(Lessons!$E$6:$E$505,O11),""))) | G11: =IF(IF(ISNUMBER(P11),INDEX(Lessons!$I$6:$I$505,P11),IF(INDEX(Timetable!$E$6:$I$15,6,4)="","",INDEX(Timetable!$E$6:$I$15,6,4)))="","",IF(ISNUMBER(P11),INDEX(Lessons!$I$6:$I$505,P11),IF(INDEX(Timetable!$E$6:$I$15,6,4)="","",INDEX(Timetable!$E$6:$I$15,6,4)))&IF(IF(ISNUMBER(P11),INDEX(Lessons!$E$6:$E$505,P11),"")="","",CHAR(10)&IF(ISNUMBER(P11),INDEX(Lessons!$E$6:$E$505,P11),""))) | H11: =IF(IF(ISNUMBER(Q11),INDEX(Lessons!$I$6:$I$505,Q11),IF(INDEX(Timetable!$E$6:$I$15,6,5)="","",INDEX(Timetable!$E$6:$I$15,6,5)))="","",IF(ISNUMBER(Q11),INDEX(Lessons!$I$6:$I$505,Q11),IF(INDEX(Timetable!$E$6:$I$15,6,5)="","",INDEX(Timetable!$E$6:$I$15,6,5)))&IF(IF(ISNUMBER(Q11),INDEX(Lessons!$E$6:$E$505,Q11),"")="","",CHAR(10)&IF(ISNUMBER(Q11),INDEX(Lessons!$E$6:$E$505,Q11),""))) | M11: =IFERROR(MATCH((Settings!$C$6+0)*100+6,Lessons!$K$6:$K$505,0),"") | N11: =IFERROR(MATCH((Settings!$C$6+1)*100+6,Lessons!$K$6:$K$505,0),"") | O11: =IFERROR(MATCH((Settings!$C$6+2)*100+6,Lessons!$K$6:$K$505,0),"") | P11: =IFERROR(MATCH((Settings!$C$6+3)*100+6,Lessons!$K$6:$K$505,0),"") | Q11: =IFERROR(MATCH((Settings!$C$6+4)*100+6,Lessons!$K$6:$K$505,0),"") | R11: =IF(AND(NOT(ISNUMBER(M11)),IF(INDEX(Timetable!$E$6:$I$15,6,1)="","",INDEX(Timetable!$E$6:$I$15,6,1))<>""),1,0) | S11: =IF(AND(NOT(ISNUMBER(N11)),IF(INDEX(Timetable!$E$6:$I$15,6,2)="","",INDEX(Timetable!$E$6:$I$15,6,2))<>""),1,0) | T11: =IF(AND(NOT(ISNUMBER(O11)),IF(INDEX(Timetable!$E$6:$I$15,6,3)="","",INDEX(Timetable!$E$6:$I$15,6,3))<>""),1,0) | U11: =IF(AND(NOT(ISNUMBER(P11)),IF(INDEX(Timetable!$E$6:$I$15,6,4)="","",INDEX(Timetable!$E$6:$I$15,6,4))<>""),1,0) | V11: =IF(AND(NOT(ISNUMBER(Q11)),IF(INDEX(Timetable!$E$6:$I$15,6,5)="","",INDEX(Timetable!$E$6:$I$15,6,5))<>""),1,0)
B12: 7 | C12: =IF(ISNUMBER(Timetable!C12),HOUR(Timetable!C12)&":"&RIGHT("0"&MINUTE(Timetable!C12),2),"") | D12: =IF(IF(ISNUMBER(M12),INDEX(Lessons!$I$6:$I$505,M12),IF(INDEX(Timetable!$E$6:$I$15,7,1)="","",INDEX(Timetable!$E$6:$I$15,7,1)))="","",IF(ISNUMBER(M12),INDEX(Lessons!$I$6:$I$505,M12),IF(INDEX(Timetable!$E$6:$I$15,7,1)="","",INDEX(Timetable!$E$6:$I$15,7,1)))&IF(IF(ISNUMBER(M12),INDEX(Lessons!$E$6:$E$505,M12),"")="","",CHAR(10)&IF(ISNUMBER(M12),INDEX(Lessons!$E$6:$E$505,M12),""))) | E12: =IF(IF(ISNUMBER(N12),INDEX(Lessons!$I$6:$I$505,N12),IF(INDEX(Timetable!$E$6:$I$15,7,2)="","",INDEX(Timetable!$E$6:$I$15,7,2)))="","",IF(ISNUMBER(N12),INDEX(Lessons!$I$6:$I$505,N12),IF(INDEX(Timetable!$E$6:$I$15,7,2)="","",INDEX(Timetable!$E$6:$I$15,7,2)))&IF(IF(ISNUMBER(N12),INDEX(Lessons!$E$6:$E$505,N12),"")="","",CHAR(10)&IF(ISNUMBER(N12),INDEX(Lessons!$E$6:$E$505,N12),""))) | F12: =IF(IF(ISNUMBER(O12),INDEX(Lessons!$I$6:$I$505,O12),IF(INDEX(Timetable!$E$6:$I$15,7,3)="","",INDEX(Timetable!$E$6:$I$15,7,3)))="","",IF(ISNUMBER(O12),INDEX(Lessons!$I$6:$I$505,O12),IF(INDEX(Timetable!$E$6:$I$15,7,3)="","",INDEX(Timetable!$E$6:$I$15,7,3)))&IF(IF(ISNUMBER(O12),INDEX(Lessons!$E$6:$E$505,O12),"")="","",CHAR(10)&IF(ISNUMBER(O12),INDEX(Lessons!$E$6:$E$505,O12),""))) | G12: =IF(IF(ISNUMBER(P12),INDEX(Lessons!$I$6:$I$505,P12),IF(INDEX(Timetable!$E$6:$I$15,7,4)="","",INDEX(Timetable!$E$6:$I$15,7,4)))="","",IF(ISNUMBER(P12),INDEX(Lessons!$I$6:$I$505,P12),IF(INDEX(Timetable!$E$6:$I$15,7,4)="","",INDEX(Timetable!$E$6:$I$15,7,4)))&IF(IF(ISNUMBER(P12),INDEX(Lessons!$E$6:$E$505,P12),"")="","",CHAR(10)&IF(ISNUMBER(P12),INDEX(Lessons!$E$6:$E$505,P12),""))) | H12: =IF(IF(ISNUMBER(Q12),INDEX(Lessons!$I$6:$I$505,Q12),IF(INDEX(Timetable!$E$6:$I$15,7,5)="","",INDEX(Timetable!$E$6:$I$15,7,5)))="","",IF(ISNUMBER(Q12),INDEX(Lessons!$I$6:$I$505,Q12),IF(INDEX(Timetable!$E$6:$I$15,7,5)="","",INDEX(Timetable!$E$6:$I$15,7,5)))&IF(IF(ISNUMBER(Q12),INDEX(Lessons!$E$6:$E$505,Q12),"")="","",CHAR(10)&IF(ISNUMBER(Q12),INDEX(Lessons!$E$6:$E$505,Q12),""))) | M12: =IFERROR(MATCH((Settings!$C$6+0)*100+7,Lessons!$K$6:$K$505,0),"") | N12: =IFERROR(MATCH((Settings!$C$6+1)*100+7,Lessons!$K$6:$K$505,0),"") | O12: =IFERROR(MATCH((Settings!$C$6+2)*100+7,Lessons!$K$6:$K$505,0),"") | P12: =IFERROR(MATCH((Settings!$C$6+3)*100+7,Lessons!$K$6:$K$505,0),"") | Q12: =IFERROR(MATCH((Settings!$C$6+4)*100+7,Lessons!$K$6:$K$505,0),"") | R12: =IF(AND(NOT(ISNUMBER(M12)),IF(INDEX(Timetable!$E$6:$I$15,7,1)="","",INDEX(Timetable!$E$6:$I$15,7,1))<>""),1,0) | S12: =IF(AND(NOT(ISNUMBER(N12)),IF(INDEX(Timetable!$E$6:$I$15,7,2)="","",INDEX(Timetable!$E$6:$I$15,7,2))<>""),1,0) | T12: =IF(AND(NOT(ISNUMBER(O12)),IF(INDEX(Timetable!$E$6:$I$15,7,3)="","",INDEX(Timetable!$E$6:$I$15,7,3))<>""),1,0) | U12: =IF(AND(NOT(ISNUMBER(P12)),IF(INDEX(Timetable!$E$6:$I$15,7,4)="","",INDEX(Timetable!$E$6:$I$15,7,4))<>""),1,0) | V12: =IF(AND(NOT(ISNUMBER(Q12)),IF(INDEX(Timetable!$E$6:$I$15,7,5)="","",INDEX(Timetable!$E$6:$I$15,7,5))<>""),1,0)
B13: 8 | C13: =IF(ISNUMBER(Timetable!C13),HOUR(Timetable!C13)&":"&RIGHT("0"&MINUTE(Timetable!C13),2),"") | D13: =IF(IF(ISNUMBER(M13),INDEX(Lessons!$I$6:$I$505,M13),IF(INDEX(Timetable!$E$6:$I$15,8,1)="","",INDEX(Timetable!$E$6:$I$15,8,1)))="","",IF(ISNUMBER(M13),INDEX(Lessons!$I$6:$I$505,M13),IF(INDEX(Timetable!$E$6:$I$15,8,1)="","",INDEX(Timetable!$E$6:$I$15,8,1)))&IF(IF(ISNUMBER(M13),INDEX(Lessons!$E$6:$E$505,M13),"")="","",CHAR(10)&IF(ISNUMBER(M13),INDEX(Lessons!$E$6:$E$505,M13),""))) | E13: =IF(IF(ISNUMBER(N13),INDEX(Lessons!$I$6:$I$505,N13),IF(INDEX(Timetable!$E$6:$I$15,8,2)="","",INDEX(Timetable!$E$6:$I$15,8,2)))="","",IF(ISNUMBER(N13),INDEX(Lessons!$I$6:$I$505,N13),IF(INDEX(Timetable!$E$6:$I$15,8,2)="","",INDEX(Timetable!$E$6:$I$15,8,2)))&IF(IF(ISNUMBER(N13),INDEX(Lessons!$E$6:$E$505,N13),"")="","",CHAR(10)&IF(ISNUMBER(N13),INDEX(Lessons!$E$6:$E$505,N13),""))) | F13: =IF(IF(ISNUMBER(O13),INDEX(Lessons!$I$6:$I$505,O13),IF(INDEX(Timetable!$E$6:$I$15,8,3)="","",INDEX(Timetable!$E$6:$I$15,8,3)))="","",IF(ISNUMBER(O13),INDEX(Lessons!$I$6:$I$505,O13),IF(INDEX(Timetable!$E$6:$I$15,8,3)="","",INDEX(Timetable!$E$6:$I$15,8,3)))&IF(IF(ISNUMBER(O13),INDEX(Lessons!$E$6:$E$505,O13),"")="","",CHAR(10)&IF(ISNUMBER(O13),INDEX(Lessons!$E$6:$E$505,O13),""))) | G13: =IF(IF(ISNUMBER(P13),INDEX(Lessons!$I$6:$I$505,P13),IF(INDEX(Timetable!$E$6:$I$15,8,4)="","",INDEX(Timetable!$E$6:$I$15,8,4)))="","",IF(ISNUMBER(P13),INDEX(Lessons!$I$6:$I$505,P13),IF(INDEX(Timetable!$E$6:$I$15,8,4)="","",INDEX(Timetable!$E$6:$I$15,8,4)))&IF(IF(ISNUMBER(P13),INDEX(Lessons!$E$6:$E$505,P13),"")="","",CHAR(10)&IF(ISNUMBER(P13),INDEX(Lessons!$E$6:$E$505,P13),""))) | H13: =IF(IF(ISNUMBER(Q13),INDEX(Lessons!$I$6:$I$505,Q13),IF(INDEX(Timetable!$E$6:$I$15,8,5)="","",INDEX(Timetable!$E$6:$I$15,8,5)))="","",IF(ISNUMBER(Q13),INDEX(Lessons!$I$6:$I$505,Q13),IF(INDEX(Timetable!$E$6:$I$15,8,5)="","",INDEX(Timetable!$E$6:$I$15,8,5)))&IF(IF(ISNUMBER(Q13),INDEX(Lessons!$E$6:$E$505,Q13),"")="","",CHAR(10)&IF(ISNUMBER(Q13),INDEX(Lessons!$E$6:$E$505,Q13),""))) | M13: =IFERROR(MATCH((Settings!$C$6+0)*100+8,Lessons!$K$6:$K$505,0),"") | N13: =IFERROR(MATCH((Settings!$C$6+1)*100+8,Lessons!$K$6:$K$505,0),"") | O13: =IFERROR(MATCH((Settings!$C$6+2)*100+8,Lessons!$K$6:$K$505,0),"") | P13: =IFERROR(MATCH((Settings!$C$6+3)*100+8,Lessons!$K$6:$K$505,0),"") | Q13: =IFERROR(MATCH((Settings!$C$6+4)*100+8,Lessons!$K$6:$K$505,0),"") | R13: =IF(AND(NOT(ISNUMBER(M13)),IF(INDEX(Timetable!$E$6:$I$15,8,1)="","",INDEX(Timetable!$E$6:$I$15,8,1))<>""),1,0) | S13: =IF(AND(NOT(ISNUMBER(N13)),IF(INDEX(Timetable!$E$6:$I$15,8,2)="","",INDEX(Timetable!$E$6:$I$15,8,2))<>""),1,0) | T13: =IF(AND(NOT(ISNUMBER(O13)),IF(INDEX(Timetable!$E$6:$I$15,8,3)="","",INDEX(Timetable!$E$6:$I$15,8,3))<>""),1,0) | U13: =IF(AND(NOT(ISNUMBER(P13)),IF(INDEX(Timetable!$E$6:$I$15,8,4)="","",INDEX(Timetable!$E$6:$I$15,8,4))<>""),1,0) | V13: =IF(AND(NOT(ISNUMBER(Q13)),IF(INDEX(Timetable!$E$6:$I$15,8,5)="","",INDEX(Timetable!$E$6:$I$15,8,5))<>""),1,0)
B14: 9 | C14: =IF(ISNUMBER(Timetable!C14),HOUR(Timetable!C14)&":"&RIGHT("0"&MINUTE(Timetable!C14),2),"") | D14: =IF(IF(ISNUMBER(M14),INDEX(Lessons!$I$6:$I$505,M14),IF(INDEX(Timetable!$E$6:$I$15,9,1)="","",INDEX(Timetable!$E$6:$I$15,9,1)))="","",IF(ISNUMBER(M14),INDEX(Lessons!$I$6:$I$505,M14),IF(INDEX(Timetable!$E$6:$I$15,9,1)="","",INDEX(Timetable!$E$6:$I$15,9,1)))&IF(IF(ISNUMBER(M14),INDEX(Lessons!$E$6:$E$505,M14),"")="","",CHAR(10)&IF(ISNUMBER(M14),INDEX(Lessons!$E$6:$E$505,M14),""))) | E14: =IF(IF(ISNUMBER(N14),INDEX(Lessons!$I$6:$I$505,N14),IF(INDEX(Timetable!$E$6:$I$15,9,2)="","",INDEX(Timetable!$E$6:$I$15,9,2)))="","",IF(ISNUMBER(N14),INDEX(Lessons!$I$6:$I$505,N14),IF(INDEX(Timetable!$E$6:$I$15,9,2)="","",INDEX(Timetable!$E$6:$I$15,9,2)))&IF(IF(ISNUMBER(N14),INDEX(Lessons!$E$6:$E$505,N14),"")="","",CHAR(10)&IF(ISNUMBER(N14),INDEX(Lessons!$E$6:$E$505,N14),""))) | F14: =IF(IF(ISNUMBER(O14),INDEX(Lessons!$I$6:$I$505,O14),IF(INDEX(Timetable!$E$6:$I$15,9,3)="","",INDEX(Timetable!$E$6:$I$15,9,3)))="","",IF(ISNUMBER(O14),INDEX(Lessons!$I$6:$I$505,O14),IF(INDEX(Timetable!$E$6:$I$15,9,3)="","",INDEX(Timetable!$E$6:$I$15,9,3)))&IF(IF(ISNUMBER(O14),INDEX(Lessons!$E$6:$E$505,O14),"")="","",CHAR(10)&IF(ISNUMBER(O14),INDEX(Lessons!$E$6:$E$505,O14),""))) | G14: =IF(IF(ISNUMBER(P14),INDEX(Lessons!$I$6:$I$505,P14),IF(INDEX(Timetable!$E$6:$I$15,9,4)="","",INDEX(Timetable!$E$6:$I$15,9,4)))="","",IF(ISNUMBER(P14),INDEX(Lessons!$I$6:$I$505,P14),IF(INDEX(Timetable!$E$6:$I$15,9,4)="","",INDEX(Timetable!$E$6:$I$15,9,4)))&IF(IF(ISNUMBER(P14),INDEX(Lessons!$E$6:$E$505,P14),"")="","",CHAR(10)&IF(ISNUMBER(P14),INDEX(Lessons!$E$6:$E$505,P14),""))) | H14: =IF(IF(ISNUMBER(Q14),INDEX(Lessons!$I$6:$I$505,Q14),IF(INDEX(Timetable!$E$6:$I$15,9,5)="","",INDEX(Timetable!$E$6:$I$15,9,5)))="","",IF(ISNUMBER(Q14),INDEX(Lessons!$I$6:$I$505,Q14),IF(INDEX(Timetable!$E$6:$I$15,9,5)="","",INDEX(Timetable!$E$6:$I$15,9,5)))&IF(IF(ISNUMBER(Q14),INDEX(Lessons!$E$6:$E$505,Q14),"")="","",CHAR(10)&IF(ISNUMBER(Q14),INDEX(Lessons!$E$6:$E$505,Q14),""))) | M14: =IFERROR(MATCH((Settings!$C$6+0)*100+9,Lessons!$K$6:$K$505,0),"") | N14: =IFERROR(MATCH((Settings!$C$6+1)*100+9,Lessons!$K$6:$K$505,0),"") | O14: =IFERROR(MATCH((Settings!$C$6+2)*100+9,Lessons!$K$6:$K$505,0),"") | P14: =IFERROR(MATCH((Settings!$C$6+3)*100+9,Lessons!$K$6:$K$505,0),"") | Q14: =IFERROR(MATCH((Settings!$C$6+4)*100+9,Lessons!$K$6:$K$505,0),"") | R14: =IF(AND(NOT(ISNUMBER(M14)),IF(INDEX(Timetable!$E$6:$I$15,9,1)="","",INDEX(Timetable!$E$6:$I$15,9,1))<>""),1,0) | S14: =IF(AND(NOT(ISNUMBER(N14)),IF(INDEX(Timetable!$E$6:$I$15,9,2)="","",INDEX(Timetable!$E$6:$I$15,9,2))<>""),1,0) | T14: =IF(AND(NOT(ISNUMBER(O14)),IF(INDEX(Timetable!$E$6:$I$15,9,3)="","",INDEX(Timetable!$E$6:$I$15,9,3))<>""),1,0) | U14: =IF(AND(NOT(ISNUMBER(P14)),IF(INDEX(Timetable!$E$6:$I$15,9,4)="","",INDEX(Timetable!$E$6:$I$15,9,4))<>""),1,0) | V14: =IF(AND(NOT(ISNUMBER(Q14)),IF(INDEX(Timetable!$E$6:$I$15,9,5)="","",INDEX(Timetable!$E$6:$I$15,9,5))<>""),1,0)
B15: 10 | C15: =IF(ISNUMBER(Timetable!C15),HOUR(Timetable!C15)&":"&RIGHT("0"&MINUTE(Timetable!C15),2),"") | D15: =IF(IF(ISNUMBER(M15),INDEX(Lessons!$I$6:$I$505,M15),IF(INDEX(Timetable!$E$6:$I$15,10,1)="","",INDEX(Timetable!$E$6:$I$15,10,1)))="","",IF(ISNUMBER(M15),INDEX(Lessons!$I$6:$I$505,M15),IF(INDEX(Timetable!$E$6:$I$15,10,1)="","",INDEX(Timetable!$E$6:$I$15,10,1)))&IF(IF(ISNUMBER(M15),INDEX(Lessons!$E$6:$E$505,M15),"")="","",CHAR(10)&IF(ISNUMBER(M15),INDEX(Lessons!$E$6:$E$505,M15),""))) | E15: =IF(IF(ISNUMBER(N15),INDEX(Lessons!$I$6:$I$505,N15),IF(INDEX(Timetable!$E$6:$I$15,10,2)="","",INDEX(Timetable!$E$6:$I$15,10,2)))="","",IF(ISNUMBER(N15),INDEX(Lessons!$I$6:$I$505,N15),IF(INDEX(Timetable!$E$6:$I$15,10,2)="","",INDEX(Timetable!$E$6:$I$15,10,2)))&IF(IF(ISNUMBER(N15),INDEX(Lessons!$E$6:$E$505,N15),"")="","",CHAR(10)&IF(ISNUMBER(N15),INDEX(Lessons!$E$6:$E$505,N15),""))) | F15: =IF(IF(ISNUMBER(O15),INDEX(Lessons!$I$6:$I$505,O15),IF(INDEX(Timetable!$E$6:$I$15,10,3)="","",INDEX(Timetable!$E$6:$I$15,10,3)))="","",IF(ISNUMBER(O15),INDEX(Lessons!$I$6:$I$505,O15),IF(INDEX(Timetable!$E$6:$I$15,10,3)="","",INDEX(Timetable!$E$6:$I$15,10,3)))&IF(IF(ISNUMBER(O15),INDEX(Lessons!$E$6:$E$505,O15),"")="","",CHAR(10)&IF(ISNUMBER(O15),INDEX(Lessons!$E$6:$E$505,O15),""))) | G15: =IF(IF(ISNUMBER(P15),INDEX(Lessons!$I$6:$I$505,P15),IF(INDEX(Timetable!$E$6:$I$15,10,4)="","",INDEX(Timetable!$E$6:$I$15,10,4)))="","",IF(ISNUMBER(P15),INDEX(Lessons!$I$6:$I$505,P15),IF(INDEX(Timetable!$E$6:$I$15,10,4)="","",INDEX(Timetable!$E$6:$I$15,10,4)))&IF(IF(ISNUMBER(P15),INDEX(Lessons!$E$6:$E$505,P15),"")="","",CHAR(10)&IF(ISNUMBER(P15),INDEX(Lessons!$E$6:$E$505,P15),""))) | H15: =IF(IF(ISNUMBER(Q15),INDEX(Lessons!$I$6:$I$505,Q15),IF(INDEX(Timetable!$E$6:$I$15,10,5)="","",INDEX(Timetable!$E$6:$I$15,10,5)))="","",IF(ISNUMBER(Q15),INDEX(Lessons!$I$6:$I$505,Q15),IF(INDEX(Timetable!$E$6:$I$15,10,5)="","",INDEX(Timetable!$E$6:$I$15,10,5)))&IF(IF(ISNUMBER(Q15),INDEX(Lessons!$E$6:$E$505,Q15),"")="","",CHAR(10)&IF(ISNUMBER(Q15),INDEX(Lessons!$E$6:$E$505,Q15),""))) | M15: =IFERROR(MATCH((Settings!$C$6+0)*100+10,Lessons!$K$6:$K$505,0),"") | N15: =IFERROR(MATCH((Settings!$C$6+1)*100+10,Lessons!$K$6:$K$505,0),"") | O15: =IFERROR(MATCH((Settings!$C$6+2)*100+10,Lessons!$K$6:$K$505,0),"") | P15: =IFERROR(MATCH((Settings!$C$6+3)*100+10,Lessons!$K$6:$K$505,0),"") | Q15: =IFERROR(MATCH((Settings!$C$6+4)*100+10,Lessons!$K$6:$K$505,0),"") | R15: =IF(AND(NOT(ISNUMBER(M15)),IF(INDEX(Timetable!$E$6:$I$15,10,1)="","",INDEX(Timetable!$E$6:$I$15,10,1))<>""),1,0) | S15: =IF(AND(NOT(ISNUMBER(N15)),IF(INDEX(Timetable!$E$6:$I$15,10,2)="","",INDEX(Timetable!$E$6:$I$15,10,2))<>""),1,0) | T15: =IF(AND(NOT(ISNUMBER(O15)),IF(INDEX(Timetable!$E$6:$I$15,10,3)="","",INDEX(Timetable!$E$6:$I$15,10,3))<>""),1,0) | U15: =IF(AND(NOT(ISNUMBER(P15)),IF(INDEX(Timetable!$E$6:$I$15,10,4)="","",INDEX(Timetable!$E$6:$I$15,10,4))<>""),1,0) | V15: =IF(AND(NOT(ISNUMBER(Q15)),IF(INDEX(Timetable!$E$6:$I$15,10,5)="","",INDEX(Timetable!$E$6:$I$15,10,5))<>""),1,0)
B17: Homework set this week
B18: Day | D18: Class | E18: Homework
B19: =IF(W19="","",CHOOSE(WEEKDAY(INDEX(Lessons!$B$1:$B$505,MOD(W19,1000)),2),"Mon","Tue","Wed","Thu","Fri","Sat","Sun")&" "&DAY(INDEX(Lessons!$B$1:$B$505,MOD(W19,1000)))) | D19: =IF(W19="","",INDEX(Lessons!$I$1:$I$505,MOD(W19,1000))) | E19: =IF(W19="","",INDEX(Lessons!$G$1:$G$505,MOD(W19,1000))) | W19: =IFERROR(SMALL(Lessons!$L$6:$L$505,1),"")
B20: =IF(W20="","",CHOOSE(WEEKDAY(INDEX(Lessons!$B$1:$B$505,MOD(W20,1000)),2),"Mon","Tue","Wed","Thu","Fri","Sat","Sun")&" "&DAY(INDEX(Lessons!$B$1:$B$505,MOD(W20,1000)))) | D20: =IF(W20="","",INDEX(Lessons!$I$1:$I$505,MOD(W20,1000))) | E20: =IF(W20="","",INDEX(Lessons!$G$1:$G$505,MOD(W20,1000))) | W20: =IFERROR(SMALL(Lessons!$L$6:$L$505,2),"")
B21: =IF(W21="","",CHOOSE(WEEKDAY(INDEX(Lessons!$B$1:$B$505,MOD(W21,1000)),2),"Mon","Tue","Wed","Thu","Fri","Sat","Sun")&" "&DAY(INDEX(Lessons!$B$1:$B$505,MOD(W21,1000)))) | D21: =IF(W21="","",INDEX(Lessons!$I$1:$I$505,MOD(W21,1000))) | E21: =IF(W21="","",INDEX(Lessons!$G$1:$G$505,MOD(W21,1000))) | W21: =IFERROR(SMALL(Lessons!$L$6:$L$505,3),"")
B22: =IF(W22="","",CHOOSE(WEEKDAY(INDEX(Lessons!$B$1:$B$505,MOD(W22,1000)),2),"Mon","Tue","Wed","Thu","Fri","Sat","Sun")&" "&DAY(INDEX(Lessons!$B$1:$B$505,MOD(W22,1000)))) | D22: =IF(W22="","",INDEX(Lessons!$I$1:$I$505,MOD(W22,1000))) | E22: =IF(W22="","",INDEX(Lessons!$G$1:$G$505,MOD(W22,1000))) | W22: =IFERROR(SMALL(Lessons!$L$6:$L$505,4),"")
B23: =IF(W23="","",CHOOSE(WEEKDAY(INDEX(Lessons!$B$1:$B$505,MOD(W23,1000)),2),"Mon","Tue","Wed","Thu","Fri","Sat","Sun")&" "&DAY(INDEX(Lessons!$B$1:$B$505,MOD(W23,1000)))) | D23: =IF(W23="","",INDEX(Lessons!$I$1:$I$505,MOD(W23,1000))) | E23: =IF(W23="","",INDEX(Lessons!$G$1:$G$505,MOD(W23,1000))) | W23: =IFERROR(SMALL(Lessons!$L$6:$L$505,5),"")
B24: =IF(W24="","",CHOOSE(WEEKDAY(INDEX(Lessons!$B$1:$B$505,MOD(W24,1000)),2),"Mon","Tue","Wed","Thu","Fri","Sat","Sun")&" "&DAY(INDEX(Lessons!$B$1:$B$505,MOD(W24,1000)))) | D24: =IF(W24="","",INDEX(Lessons!$I$1:$I$505,MOD(W24,1000))) | E24: =IF(W24="","",INDEX(Lessons!$G$1:$G$505,MOD(W24,1000))) | W24: =IFERROR(SMALL(Lessons!$L$6:$L$505,6),"")
B25: =IF(W25="","",CHOOSE(WEEKDAY(INDEX(Lessons!$B$1:$B$505,MOD(W25,1000)),2),"Mon","Tue","Wed","Thu","Fri","Sat","Sun")&" "&DAY(INDEX(Lessons!$B$1:$B$505,MOD(W25,1000)))) | D25: =IF(W25="","",INDEX(Lessons!$I$1:$I$505,MOD(W25,1000))) | E25: =IF(W25="","",INDEX(Lessons!$G$1:$G$505,MOD(W25,1000))) | W25: =IFERROR(SMALL(Lessons!$L$6:$L$505,7),"")
B26: =IF(W26="","",CHOOSE(WEEKDAY(INDEX(Lessons!$B$1:$B$505,MOD(W26,1000)),2),"Mon","Tue","Wed","Thu","Fri","Sat","Sun")&" "&DAY(INDEX(Lessons!$B$1:$B$505,MOD(W26,1000)))) | D26: =IF(W26="","",INDEX(Lessons!$I$1:$I$505,MOD(W26,1000))) | E26: =IF(W26="","",INDEX(Lessons!$G$1:$G$505,MOD(W26,1000))) | W26: =IFERROR(SMALL(Lessons!$L$6:$L$505,8),"")

Sheet Lessons
B2: Lessons
B3: Each lesson by date and period. Leave the class empty and it comes from the timetable.
B5: Date | C5: Period | D5: Class | E5: Topic | F5: Aims | G5: Homework | H5: Done | I5: Class taught
B6: 46286 | C6: 1 | E6: Lab safety | H6: x | I6: =IF(B6="","",IF(D6<>"",D6,IF(AND(ISNUMBER(B6),ISNUMBER(C6)),IF(OR(WEEKDAY(B6,2)>5,C6<1,C6>10),"",IF(INDEX(Timetable!$E$6:$I$15,C6,WEEKDAY(B6,2))="","",INDEX(Timetable!$E$6:$I$15,C6,WEEKDAY(B6,2)))),""))) | K6: =IF(AND(ISNUMBER(B6),ISNUMBER(C6)),B6*100+C6,"") | L6: =IF(OR(G6="",NOT(ISNUMBER(B6))),"",IF(AND(B6>=Settings!$C$6,B6<=Settings!$C$6+6),B6*1000+ROW(),""))
B7: 46286 | C7: 2 | E7: Using a microscope | F7: Name the parts and focus on a slide | H7: x | I7: =IF(B7="","",IF(D7<>"",D7,IF(AND(ISNUMBER(B7),ISNUMBER(C7)),IF(OR(WEEKDAY(B7,2)>5,C7<1,C7>10),"",IF(INDEX(Timetable!$E$6:$I$15,C7,WEEKDAY(B7,2))="","",INDEX(Timetable!$E$6:$I$15,C7,WEEKDAY(B7,2)))),""))) | K7: =IF(AND(ISNUMBER(B7),ISNUMBER(C7)),B7*100+C7,"") | L7: =IF(OR(G7="",NOT(ISNUMBER(B7))),"",IF(AND(B7>=Settings!$C$6,B7<=Settings!$C$6+6),B7*1000+ROW(),""))
B8: 46286 | C8: 4 | E8: Enzymes | F8: Explain the lock and key model | H8: x | I8: =IF(B8="","",IF(D8<>"",D8,IF(AND(ISNUMBER(B8),ISNUMBER(C8)),IF(OR(WEEKDAY(B8,2)>5,C8<1,C8>10),"",IF(INDEX(Timetable!$E$6:$I$15,C8,WEEKDAY(B8,2))="","",INDEX(Timetable!$E$6:$I$15,C8,WEEKDAY(B8,2)))),""))) | K8: =IF(AND(ISNUMBER(B8),ISNUMBER(C8)),B8*100+C8,"") | L8: =IF(OR(G8="",NOT(ISNUMBER(B8))),"",IF(AND(B8>=Settings!$C$6,B8<=Settings!$C$6+6),B8*1000+ROW(),""))
B9: 46286 | C9: 5 | E9: Atomic structure | H9: x | I9: =IF(B9="","",IF(D9<>"",D9,IF(AND(ISNUMBER(B9),ISNUMBER(C9)),IF(OR(WEEKDAY(B9,2)>5,C9<1,C9>10),"",IF(INDEX(Timetable!$E$6:$I$15,C9,WEEKDAY(B9,2))="","",INDEX(Timetable!$E$6:$I$15,C9,WEEKDAY(B9,2)))),""))) | K9: =IF(AND(ISNUMBER(B9),ISNUMBER(C9)),B9*100+C9,"") | L9: =IF(OR(G9="",NOT(ISNUMBER(B9))),"",IF(AND(B9>=Settings!$C$6,B9<=Settings!$C$6+6),B9*1000+ROW(),""))
B10: 46287 | C10: 2 | E10: Isotopes | H10: x | I10: =IF(B10="","",IF(D10<>"",D10,IF(AND(ISNUMBER(B10),ISNUMBER(C10)),IF(OR(WEEKDAY(B10,2)>5,C10<1,C10>10),"",IF(INDEX(Timetable!$E$6:$I$15,C10,WEEKDAY(B10,2))="","",INDEX(Timetable!$E$6:$I$15,C10,WEEKDAY(B10,2)))),""))) | K10: =IF(AND(ISNUMBER(B10),ISNUMBER(C10)),B10*100+C10,"") | L10: =IF(OR(G10="",NOT(ISNUMBER(B10))),"",IF(AND(B10>=Settings!$C$6,B10<=Settings!$C$6+6),B10*1000+ROW(),""))
B11: 46287 | C11: 3 | E11: Particle model | H11: x | I11: =IF(B11="","",IF(D11<>"",D11,IF(AND(ISNUMBER(B11),ISNUMBER(C11)),IF(OR(WEEKDAY(B11,2)>5,C11<1,C11>10),"",IF(INDEX(Timetable!$E$6:$I$15,C11,WEEKDAY(B11,2))="","",INDEX(Timetable!$E$6:$I$15,C11,WEEKDAY(B11,2)))),""))) | K11: =IF(AND(ISNUMBER(B11),ISNUMBER(C11)),B11*100+C11,"") | L11: =IF(OR(G11="",NOT(ISNUMBER(B11))),"",IF(AND(B11>=Settings!$C$6,B11<=Settings!$C$6+6),B11*1000+ROW(),""))
B12: 46287 | C12: 4 | E12: States of matter | H12: x | I12: =IF(B12="","",IF(D12<>"",D12,IF(AND(ISNUMBER(B12),ISNUMBER(C12)),IF(OR(WEEKDAY(B12,2)>5,C12<1,C12>10),"",IF(INDEX(Timetable!$E$6:$I$15,C12,WEEKDAY(B12,2))="","",INDEX(Timetable!$E$6:$I$15,C12,WEEKDAY(B12,2)))),""))) | K12: =IF(AND(ISNUMBER(B12),ISNUMBER(C12)),B12*100+C12,"") | L12: =IF(OR(G12="",NOT(ISNUMBER(B12))),"",IF(AND(B12>=Settings!$C$6,B12<=Settings!$C$6+6),B12*1000+ROW(),""))
B13: 46287 | C13: 6 | E13: Enzyme practical | H13: x | I13: =IF(B13="","",IF(D13<>"",D13,IF(AND(ISNUMBER(B13),ISNUMBER(C13)),IF(OR(WEEKDAY(B13,2)>5,C13<1,C13>10),"",IF(INDEX(Timetable!$E$6:$I$15,C13,WEEKDAY(B13,2))="","",INDEX(Timetable!$E$6:$I$15,C13,WEEKDAY(B13,2)))),""))) | K13: =IF(AND(ISNUMBER(B13),ISNUMBER(C13)),B13*100+C13,"") | L13: =IF(OR(G13="",NOT(ISNUMBER(B13))),"",IF(AND(B13>=Settings!$C$6,B13<=Settings!$C$6+6),B13*1000+ROW(),""))
B14: 46288 | C14: 1 | E14: Food tests | G14: Write up the results | H14: x | I14: =IF(B14="","",IF(D14<>"",D14,IF(AND(ISNUMBER(B14),ISNUMBER(C14)),IF(OR(WEEKDAY(B14,2)>5,C14<1,C14>10),"",IF(INDEX(Timetable!$E$6:$I$15,C14,WEEKDAY(B14,2))="","",INDEX(Timetable!$E$6:$I$15,C14,WEEKDAY(B14,2)))),""))) | K14: =IF(AND(ISNUMBER(B14),ISNUMBER(C14)),B14*100+C14,"") | L14: =IF(OR(G14="",NOT(ISNUMBER(B14))),"",IF(AND(B14>=Settings!$C$6,B14<=Settings!$C$6+6),B14*1000+ROW(),""))
B15: 46288 | C15: 3 | E15: Plant and animal cells | F15: Compare the two | G15: Cells worksheet | H15: x | I15: =IF(B15="","",IF(D15<>"",D15,IF(AND(ISNUMBER(B15),ISNUMBER(C15)),IF(OR(WEEKDAY(B15,2)>5,C15<1,C15>10),"",IF(INDEX(Timetable!$E$6:$I$15,C15,WEEKDAY(B15,2))="","",INDEX(Timetable!$E$6:$I$15,C15,WEEKDAY(B15,2)))),""))) | K15: =IF(AND(ISNUMBER(B15),ISNUMBER(C15)),B15*100+C15,"") | L15: =IF(OR(G15="",NOT(ISNUMBER(B15))),"",IF(AND(B15>=Settings!$C$6,B15<=Settings!$C$6+6),B15*1000+ROW(),""))
B16: 46288 | C16: 4 | E16: Specialised cells | H16: x | I16: =IF(B16="","",IF(D16<>"",D16,IF(AND(ISNUMBER(B16),ISNUMBER(C16)),IF(OR(WEEKDAY(B16,2)>5,C16<1,C16>10),"",IF(INDEX(Timetable!$E$6:$I$15,C16,WEEKDAY(B16,2))="","",INDEX(Timetable!$E$6:$I$15,C16,WEEKDAY(B16,2)))),""))) | K16: =IF(AND(ISNUMBER(B16),ISNUMBER(C16)),B16*100+C16,"") | L16: =IF(OR(G16="",NOT(ISNUMBER(B16))),"",IF(AND(B16>=Settings!$C$6,B16<=Settings!$C$6+6),B16*1000+ROW(),""))
