Workbook

Sheet Dashboard
AA1: =IF($C$4="",TODAY(),$C$4)
B2: =IF(Settings!$C$4="","Baby log",Settings!$C$4&"'s log")
B3: Pick a day, or leave it empty for today.
B4: Day | D4: =IF(OR(Dashboard!$AA$1="",Settings!$C$5=""),"",IF((Dashboard!$AA$1-Settings!$C$5)<0,"",INT((Dashboard!$AA$1-Settings!$C$5)/7)&IF(INT((Dashboard!$AA$1-Settings!$C$5)/7)=1," week"," weeks")&IF(MOD((Dashboard!$AA$1-Settings!$C$5),7)=0,""," "&MOD((Dashboard!$AA$1-Settings!$C$5),7)&IF(MOD((Dashboard!$AA$1-Settings!$C$5),7)=1," day"," days"))))
B6: Feeds | C6: Last feed | D6: Since then | E6: Sleep | F6: Wet | G6: Dirty | H6: Next appointment
B7: =COUNTIF(Feeds!$B$6:$B$3005,Dashboard!$AA$1) | C7: =IF(MAX(Feeds!$J$6:$J$3005)=0,"",MAX(Feeds!$J$6:$J$3005)) | D7: =IF(OR(MAX(Feeds!$J$6:$J$3005)=0,Dashboard!$AA$1<>TODAY()),"",INT((NOW()-MAX(Feeds!$J$6:$J$3005))*24)&" h "&IF(MOD(INT((NOW()-MAX(Feeds!$J$6:$J$3005))*1440),60)<10,"0","")&MOD(INT((NOW()-MAX(Feeds!$J$6:$J$3005))*1440),60)&" min") | E7: =SUMIFS(Sleep!$E$6:$E$2505,Sleep!$B$6:$B$2505,Dashboard!$AA$1) | F7: =COUNTIFS(Nappies!$B$6:$B$3005,Dashboard!$AA$1,Nappies!$D$6:$D$3005,"<>") | G7: =COUNTIFS(Nappies!$B$6:$B$3005,Dashboard!$AA$1,Nappies!$E$6:$E$3005,"<>") | H7: =IF(MIN(Appointments!$I$6:$I$105)=0,"None booked",INDEX(Appointments!$D$6:$D$105,MATCH(MIN(Appointments!$I$6:$I$105),Appointments!$I$6:$I$105,0))&", "&DAY(INT(MIN(Appointments!$I$6:$I$105)))&" "&CHOOSE(MONTH(INT(MIN(Appointments!$I$6:$I$105))),"Jan","Feb","Mar","Apr","May","Jun","Jul","Aug","Sep","Oct","Nov","Dec"))
B9: Day | C9: Feeds | D9: ="Bottle ("&Settings!$C$6&")" | E9: Breast (min) | F9: Sleep (h) | G9: Wet | H9: Dirty | J9: Growth | K9: Latest
B10: =(Dashboard!$AA$1-6) | C10: =COUNTIF(Feeds!$B$6:$B$3005,B10) | D10: =SUMIFS(Feeds!$F$6:$F$3005,Feeds!$B$6:$B$3005,B10,Feeds!$D$6:$D$3005,"Bottle") | E10: =SUMIFS(Feeds!$E$6:$E$3005,Feeds!$B$6:$B$3005,B10,Feeds!$D$6:$D$3005,"Breast*") | F10: =SUMIFS(Sleep!$E$6:$E$2505,Sleep!$B$6:$B$2505,B10) | G10: =COUNTIFS(Nappies!$B$6:$B$3005,B10,Nappies!$D$6:$D$3005,"<>") | H10: =COUNTIFS(Nappies!$B$6:$B$3005,B10,Nappies!$E$6:$E$3005,"<>") | J10: Weighed on | K10: =IF(COUNTIF(Growth!$J$6:$J$105,0)=0,"",IF(SUMIFS(Growth!$B$6:$B$105,Growth!$J$6:$J$105,0)=0,"",SUMIFS(Growth!$B$6:$B$105,Growth!$J$6:$J$105,0)))
B11: =(Dashboard!$AA$1-5) | C11: =COUNTIF(Feeds!$B$6:$B$3005,B11) | D11: =SUMIFS(Feeds!$F$6:$F$3005,Feeds!$B$6:$B$3005,B11,Feeds!$D$6:$D$3005,"Bottle") | E11: =SUMIFS(Feeds!$E$6:$E$3005,Feeds!$B$6:$B$3005,B11,Feeds!$D$6:$D$3005,"Breast*") | F11: =SUMIFS(Sleep!$E$6:$E$2505,Sleep!$B$6:$B$2505,B11) | G11: =COUNTIFS(Nappies!$B$6:$B$3005,B11,Nappies!$D$6:$D$3005,"<>") | H11: =COUNTIFS(Nappies!$B$6:$B$3005,B11,Nappies!$E$6:$E$3005,"<>") | J11: ="Weight ("&Settings!$C$7&")" | K11: =IF(COUNTIF(Growth!$J$6:$J$105,0)=0,"",IF(SUMIFS(Growth!$D$6:$D$105,Growth!$J$6:$J$105,0)=0,"",SUMIFS(Growth!$D$6:$D$105,Growth!$J$6:$J$105,0)))
B12: =(Dashboard!$AA$1-4) | C12: =COUNTIF(Feeds!$B$6:$B$3005,B12) | D12: =SUMIFS(Feeds!$F$6:$F$3005,Feeds!$B$6:$B$3005,B12,Feeds!$D$6:$D$3005,"Bottle") | E12: =SUMIFS(Feeds!$E$6:$E$3005,Feeds!$B$6:$B$3005,B12,Feeds!$D$6:$D$3005,"Breast*") | F12: =SUMIFS(Sleep!$E$6:$E$2505,Sleep!$B$6:$B$2505,B12) | G12: =COUNTIFS(Nappies!$B$6:$B$3005,B12,Nappies!$D$6:$D$3005,"<>") | H12: =COUNTIFS(Nappies!$B$6:$B$3005,B12,Nappies!$E$6:$E$3005,"<>") | J12: ="Length ("&Settings!$C$8&")" | K12: =IF(COUNTIF(Growth!$J$6:$J$105,0)=0,"",IF(SUMIFS(Growth!$E$6:$E$105,Growth!$J$6:$J$105,0)=0,"",SUMIFS(Growth!$E$6:$E$105,Growth!$J$6:$J$105,0)))
B13: =(Dashboard!$AA$1-3) | C13: =COUNTIF(Feeds!$B$6:$B$3005,B13) | D13: =SUMIFS(Feeds!$F$6:$F$3005,Feeds!$B$6:$B$3005,B13,Feeds!$D$6:$D$3005,"Bottle") | E13: =SUMIFS(Feeds!$E$6:$E$3005,Feeds!$B$6:$B$3005,B13,Feeds!$D$6:$D$3005,"Breast*") | F13: =SUMIFS(Sleep!$E$6:$E$2505,Sleep!$B$6:$B$2505,B13) | G13: =COUNTIFS(Nappies!$B$6:$B$3005,B13,Nappies!$D$6:$D$3005,"<>") | H13: =COUNTIFS(Nappies!$B$6:$B$3005,B13,Nappies!$E$6:$E$3005,"<>") | J13: ="Head ("&Settings!$C$8&")" | K13: =IF(COUNTIF(Growth!$J$6:$J$105,0)=0,"",IF(SUMIFS(Growth!$F$6:$F$105,Growth!$J$6:$J$105,0)=0,"",SUMIFS(Growth!$F$6:$F$105,Growth!$J$6:$J$105,0)))
B14: =(Dashboard!$AA$1-2) | C14: =COUNTIF(Feeds!$B$6:$B$3005,B14) | D14: =SUMIFS(Feeds!$F$6:$F$3005,Feeds!$B$6:$B$3005,B14,Feeds!$D$6:$D$3005,"Bottle") | E14: =SUMIFS(Feeds!$E$6:$E$3005,Feeds!$B$6:$B$3005,B14,Feeds!$D$6:$D$3005,"Breast*") | F14: =SUMIFS(Sleep!$E$6:$E$2505,Sleep!$B$6:$B$2505,B14) | G14: =COUNTIFS(Nappies!$B$6:$B$3005,B14,Nappies!$D$6:$D$3005,"<>") | H14: =COUNTIFS(Nappies!$B$6:$B$3005,B14,Nappies!$E$6:$E$3005,"<>") | J14: Age then | K14: =IF(OR(K10="",Settings!$C$5=""),"",IF((K10-Settings!$C$5)<0,"",INT((K10-Settings!$C$5)/7)&IF(INT((K10-Settings!$C$5)/7)=1," week"," weeks")&IF(MOD((K10-Settings!$C$5),7)=0,""," "&MOD((K10-Settings!$C$5),7)&IF(MOD((K10-Settings!$C$5),7)=1," day"," days"))))
B15: =(Dashboard!$AA$1-1) | C15: =COUNTIF(Feeds!$B$6:$B$3005,B15) | D15: =SUMIFS(Feeds!$F$6:$F$3005,Feeds!$B$6:$B$3005,B15,Feeds!$D$6:$D$3005,"Bottle") | E15: =SUMIFS(Feeds!$E$6:$E$3005,Feeds!$B$6:$B$3005,B15,Feeds!$D$6:$D$3005,"Breast*") | F15: =SUMIFS(Sleep!$E$6:$E$2505,Sleep!$B$6:$B$2505,B15) | G15: =COUNTIFS(Nappies!$B$6:$B$3005,B15,Nappies!$D$6:$D$3005,"<>") | H15: =COUNTIFS(Nappies!$B$6:$B$3005,B15,Nappies!$E$6:$E$3005,"<>") | J15: =COUNTIF(Milestones!$C$6:$C$45,"<>")&" milestones so far"
B16: =(Dashboard!$AA$1-0) | C16: =COUNTIF(Feeds!$B$6:$B$3005,B16) | D16: =SUMIFS(Feeds!$F$6:$F$3005,Feeds!$B$6:$B$3005,B16,Feeds!$D$6:$D$3005,"Bottle") | E16: =SUMIFS(Feeds!$E$6:$E$3005,Feeds!$B$6:$B$3005,B16,Feeds!$D$6:$D$3005,"Breast*") | F16: =SUMIFS(Sleep!$E$6:$E$2505,Sleep!$B$6:$B$2505,B16) | G16: =COUNTIFS(Nappies!$B$6:$B$3005,B16,Nappies!$D$6:$D$3005,"<>") | H16: =COUNTIFS(Nappies!$B$6:$B$3005,B16,Nappies!$E$6:$E$3005,"<>")
B17: Average | C17: =AVERAGE(C10:C16) | D17: =AVERAGE(D10:D16) | E17: =AVERAGE(E10:E16) | F17: =AVERAGE(F10:F16) | G17: =AVERAGE(G10:G16) | H17: =AVERAGE(H10:H16)

Sheet Feeds
B2: Feeds
B3: One line per feed: breast with the minutes, or bottle with the amount.
B5: Date | C5: Time | D5: Feed | E5: Minutes | F5: ="Amount ("&Settings!$C$6&")" | G5: Notes
B6: 46284 | C6: 0.024305556 | D6: Breast, right | E6: 20 | I6: =IF(OR(B6="",C6=""),"",B6+MOD(C6,1)) | J6: =IF(I6="","",IF(B6=Dashboard!$AA$1,I6,""))
B7: 46284 | C7: 0.16319444 | D7: Breast, right | E7: 10 | I7: =IF(OR(B7="",C7=""),"",B7+MOD(C7,1)) | J7: =IF(I7="","",IF(B7=Dashboard!$AA$1,I7,""))
B8: 46284 | C8: 0.28472222 | D8: Breast, right | E8: 18 | I8: =IF(OR(B8="",C8=""),"",B8+MOD(C8,1)) | J8: =IF(I8="","",IF(B8=Dashboard!$AA$1,I8,""))
B9: 46284 | C9: 0.41319444 | D9: Bottle | F9: 120 | I9: =IF(OR(B9="",C9=""),"",B9+MOD(C9,1)) | J9: =IF(I9="","",IF(B9=Dashboard!$AA$1,I9,""))
B10: 46284 | C10: 0.53472222 | D10: Breast, right | E10: 25 | I10: =IF(OR(B10="",C10=""),"",B10+MOD(C10,1)) | J10: =IF(I10="","",IF(B10=Dashboard!$AA$1,I10,""))
B11: 46284 | C11: 0.66666667 | D11: Breast, right | E11: 10 | I11: =IF(OR(B11="",C11=""),"",B11+MOD(C11,1)) | J11: =IF(I11="","",IF(B11=Dashboard!$AA$1,I11,""))
B12: 46284 | C12: 0.82291667 | D12: Breast, right | E12: 20 | I12: =IF(OR(B12="",C12=""),"",B12+MOD(C12,1)) | J12: =IF(I12="","",IF(B12=Dashboard!$AA$1,I12,""))
B13: 46284 | C13: 0.94097222 | D13: Bottle | F13: 130 | I13: =IF(OR(B13="",C13=""),"",B13+MOD(C13,1)) | J13: =IF(I13="","",IF(B13=Dashboard!$AA$1,I13,""))
B14: 46285 | C14: 0.010416667 | D14: Breast, left | E14: 25 | I14: =IF(OR(B14="",C14=""),"",B14+MOD(C14,1)) | J14: =IF(I14="","",IF(B14=Dashboard!$AA$1,I14,""))
B15: 46285 | C15: 0.14583333 | D15: Breast, left | E15: 20 | I15: =IF(OR(B15="",C15=""),"",B15+MOD(C15,1)) | J15: =IF(I15="","",IF(B15=Dashboard!$AA$1,I15,""))
B16: 46285 | C16: 0.28125 | D16: Breast, right | E16: 25 | I16: =IF(OR(B16="",C16=""),"",B16+MOD(C16,1)) | J16: =IF(I16="","",IF(B16=Dashboard!$AA$1,I16,""))
B17: 46285 | C17: 0.42013889 | D17: Bottle | F17: 150 | I17: =IF(OR(B17="",C17=""),"",B17+MOD(C17,1)) | J17: =IF(I17="","",IF(B17=Dashboard!$AA$1,I17,""))
B18: 46285 | C18: 0.54166667 | D18: Breast, both | E18: 25 | I18: =IF(OR(B18="",C18=""),"",B18+MOD(C18,1)) | J18: =IF(I18="","",IF(B18=Dashboard!$AA$1,I18,""))
B19: 46285 | C19: 0.66666667 | D19: Breast, both | E19: 25 | I19: =IF(OR(B19="",C19=""),"",B19+MOD(C19,1)) | J19: =IF(I19="","",IF(B19=Dashboard!$AA$1,I19,""))
B20: 46285 | C20: 0.82291667 | D20: Breast, both | E20: 25 | I20: =IF(OR(B20="",C20=""),"",B20+MOD(C20,1)) | J20: =IF(I20="","",IF(B20=Dashboard!$AA$1,I20,""))
B21: 46285 | C21: 0.94791667 | D21: Bottle | F21: 130 | I21: =IF(OR(B21="",C21=""),"",B21+MOD(C21,1)) | J21: =IF(I21="","",IF(B21=Dashboard!$AA$1,I21,""))
B22: 46286 | C22: 0.013888889 | D22: Breast, left | E22: 12 | I22: =IF(OR(B22="",C22=""),"",B22+MOD(C22,1)) | J22: =IF(I22="","",IF(B22=Dashboard!$AA$1,I22,""))
B23: 46286 | C23: 0.14236111 | D23: Breast, both | E23: 12 | I23: =IF(OR(B23="",C23=""),"",B23+MOD(C23,1)) | J23: =IF(I23="","",IF(B23=Dashboard!$AA$1,I23,""))
B24: 46286 | C24: 0.29861111 | D24: Breast, both | E24: 18 | I24: =IF(OR(B24="",C24=""),"",B24+MOD(C24,1)) | J24: =IF(I24="","",IF(B24=Dashboard!$AA$1,I24,""))
B25: 46286 | C25: 0.42708333 | D25: Bottle | F25: 130 | I25: =IF(OR(B25="",C25=""),"",B25+MOD(C25,1)) | J25: =IF(I25="","",IF(B25=Dashboard!$AA$1,I25,""))
B26: 46286 | C26: 0.53819444 | D26: Breast, both | E26: 12 | I26: =IF(OR(B26="",C26=""),"",B26+MOD(C26,1)) | J26: =IF(I26="","",IF(B26=Dashboard!$AA$1,I26,""))
B27: 46286 | C27: 0.69097222 | D27: Breast, left | E27: 10 | I27: =IF(OR(B27="",C27=""),"",B27+MOD(C27,1)) | J27: =IF(I27="","",IF(B27=Dashboard!$AA$1,I27,""))
B28: 46286 | C28: 0.80902778 | D28: Breast, both | E28: 20 | I28: =IF(OR(B28="",C28=""),"",B28+MOD(C28,1)) | J28: =IF(I28="","",IF(B28=Dashboard!$AA$1,I28,""))
B29: 46286 | C29: 0.93055556 | D29: Bottle | F29: 130 | I29: =IF(OR(B29="",C29=""),"",B29+MOD(C29,1)) | J29: =IF(I29="","",IF(B29=Dashboard!$AA$1,I29,""))
B30: 46287 | C30: 0.013888889 | D30: Breast, right | E30: 12 | I30: =IF(OR(B30="",C30=""),"",B30+MOD(C30,1)) | J30: =IF(I30="","",IF(B30=Dashboard!$AA$1,I30,""))
B31: 46287 | C31: 0.16319444 | D31: Breast, both | E31: 25 | I31: =IF(OR(B31="",C31=""),"",B31+MOD(C31,1)) | J31: =IF(I31="","",IF(B31=Dashboard!$AA$1,I31,""))
B32: 46287 | C32: 0.28125 | D32: Breast, left | E32: 10 | I32: =IF(OR(B32="",C32=""),"",B32+MOD(C32,1)) | J32: =IF(I32="","",IF(B32=Dashboard!$AA$1,I32,""))
B33: 46287 | C33: 0.43055556 | D33: Bottle | F33: 150 | I33: =IF(OR(B33="",C33=""),"",B33+MOD(C33,1)) | J33: =IF(I33="","",IF(B33=Dashboard!$AA$1,I33,""))
B34: 46287 | C34: 0.53472222 | D34: Breast, both | E34: 25 | I34: =IF(OR(B34="",C34=""),"",B34+MOD(C34,1)) | J34: =IF(I34="","",IF(B34=Dashboard!$AA$1,I34,""))
B35: 46287 | C35: 0.67708333 | D35: Breast, right | E35: 10 | I35: =IF(OR(B35="",C35=""),"",B35+MOD(C35,1)) | J35: =IF(I35="","",IF(B35=Dashboard!$AA$1,I35,""))
B36: 46287 | C36: 0.79513889 | D36: Breast, right | E36: 12 | I36: =IF(OR(B36="",C36=""),"",B36+MOD(C36,1)) | J36: =IF(I36="","",IF(B36=Dashboard!$AA$1,I36,""))
B37: 46287 | C37: 0.93402778 | D37: Bottle | F37: 120 | I37: =IF(OR(B37="",C37=""),"",B37+MOD(C37,1)) | J37: =IF(I37="","",IF(B37=Dashboard!$AA$1,I37,""))
B38: 46288 | C38: 0.010416667 | D38: Breast, left | E38: 12 | I38: =IF(OR(B38="",C38=""),"",B38+MOD(C38,1)) | J38: =IF(I38="","",IF(B38=Dashboard!$AA$1,I38,""))
B39: 46288 | C39: 0.13888889 | D39: Breast, right | E39: 15 | I39: =IF(OR(B39="",C39=""),"",B39+MOD(C39,1)) | J39: =IF(I39="","",IF(B39=Dashboard!$AA$1,I39,""))
B40: 46288 | C40: 0.29513889 | D40: Breast, right | E40: 25 | I40: =IF(OR(B40="",C40=""),"",B40+MOD(C40,1)) | J40: =IF(I40="","",IF(B40=Dashboard!$AA$1,I40,""))
B41: 46288 | C41: 0.39930556 | D41: Bottle | F41: 120 | I41: =IF(OR(B41="",C41=""),"",B41+MOD(C41,1)) | J41: =IF(I41="","",IF(B41=Dashboard!$AA$1,I41,""))
B42: 46288 | C42: 0.55208333 | D42: Breast, both | E42: 15 | I42: =IF(OR(B42="",C42=""),"",B42+MOD(C42,1)) | J42: =IF(I42="","",IF(B42=Dashboard!$AA$1,I42,""))
...

Sheet Sleep
B2: Sleep
B3: One line per sleep, from the time it started to the time it ended. A sleep past midnight counts on the day it started.
B5: Date | C5: Asleep | D5: Awake | E5: Hours | F5: Where | G5: Notes
B6: 46284 | C6: 0.038194444 | D6: 0.13194444 | E6: =IF(OR(C6="",D6=""),"",ROUND(MOD(D6-C6,1)*24,2)) | F6: Cot
B7: 46284 | C7: 0.17013889 | D7: 0.26736111 | E7: =IF(OR(C7="",D7=""),"",ROUND(MOD(D7-C7,1)*24,2)) | F7: Cot
B8: 46284 | C8: 0.38194444 | D8: 0.43055556 | E8: =IF(OR(C8="",D8=""),"",ROUND(MOD(D8-C8,1)*24,2)) | F8: Pram
B9: 46284 | C9: 0.50694444 | D9: 0.57638889 | E9: =IF(OR(C9="",D9=""),"",ROUND(MOD(D9-C9,1)*24,2)) | F9: Cot
B10: 46284 | C10: 0.67708333 | D10: 0.70486111 | E10: =IF(OR(C10="",D10=""),"",ROUND(MOD(D10-C10,1)*24,2)) | F10: Arms
B11: 46284 | C11: 0.80902778 | D11: 0.0069444444 | E11: =IF(OR(C11="",D11=""),"",ROUND(MOD(D11-C11,1)*24,2)) | F11: Cot
B12: 46285 | C12: 0.045138889 | D12: 0.13194444 | E12: =IF(OR(C12="",D12=""),"",ROUND(MOD(D12-C12,1)*24,2)) | F12: Cot
B13: 46285 | C13: 0.18055556 | D13: 0.27430556 | E13: =IF(OR(C13="",D13=""),"",ROUND(MOD(D13-C13,1)*24,2)) | F13: Cot
B14: 46285 | C14: 0.37152778 | D14: 0.42013889 | E14: =IF(OR(C14="",D14=""),"",ROUND(MOD(D14-C14,1)*24,2)) | F14: Pram
B15: 46285 | C15: 0.51388889 | D15: 0.57291667 | E15: =IF(OR(C15="",D15=""),"",ROUND(MOD(D15-C15,1)*24,2)) | F15: Cot
B16: 46285 | C16: 0.67013889 | D16: 0.70138889 | E16: =IF(OR(C16="",D16=""),"",ROUND(MOD(D16-C16,1)*24,2)) | F16: Arms
B17: 46285 | C17: 0.80208333 | D17: 0.97569444 | E17: =IF(OR(C17="",D17=""),"",ROUND(MOD(D17-C17,1)*24,2)) | F17: Cot
... B63: 46293 | C63: 0.50694444 | D63: 0.56944444 | E63: =IF(OR(C63="",D63=""),"",ROUND(MOD(D63-C63,1)*24,2)) | F63: Cot
E64: =IF(OR(C64="",D64=""),"",ROUND(MOD(D64-C64,1)*24,2))
E65: =IF(OR(C65="",D65=""),"",ROUND(MOD(D65-C65,1)*24,2))
E66: =IF(OR(C66="",D66=""),"",ROUND(MOD(D66-C66,1)*24,2))
E67: =IF(OR(C67="",D67=""),"",ROUND(MOD(D67-C67,1)*24,2))
E68: =IF(OR(C68="",D68=""),"",ROUND(MOD(D68-C68,1)*24,2))
E69: =IF(OR(C69="",D69=""),"",ROUND(MOD(D69-C69,1)*24,2))
E70: =IF(OR(C70="",D70=""),"",ROUND(MOD(D70-C70,1)*24,2))
E71: =IF(OR(C71="",D71=""),"",ROUND(MOD(D71-C71,1)*24,2))
E72: =IF(OR(C72="",D72=""),"",ROUND(MOD(D72-C72,1)*24,2))
E73: =IF(OR(C73="",D73=""),"",ROUND(MOD(D73-C73,1)*24,2))
E74: =IF(OR(C74="",D74=""),"",ROUND(MOD(D74-C74,1)*24,2))
E75: =IF(OR(C75="",D75=""),"",ROUND(MOD(D75-C75,1)*24,2))
... E2505: =IF(OR(C2505="",D2505=""),"",ROUND(MOD(D2505-C2505,1)*24,2))

Sheet Nappies
B2: Nappies
B3: One line per change. Put an x under Wet, Dirty or both.
B5: Date | C5: Time | D5: Wet | E5: Dirty | F5: Notes
B6: 46284 | C6: 0.055555556 | D6: x
B7: 46284 | C7: 0.1875 | D7: x
B8: 46284 | C8: 0.3125 | D8: x | E8: x
B9: 46284 | C9: 0.44444444 | D9: x
B10: 46284 | C10: 0.57638889 | D10: x
B11: 46284 | C11: 0.69791667 | D11: x | E11: x
B12: 46284 | C12: 0.84722222 | D12: x
B13: 46285 | C13: 0.052083333 | D13: x | E13: x
B14: 46285 | C14: 0.19097222 | D14: x
B15: 46285 | C15: 0.29861111 | D15: x | E15: x
B16: 46285 | C16: 0.42708333 | D16: x
B17: 46285 | C17: 0.56597222 | D17: x
B18: 46285 | C18: 0.70486111 | D18: x | E18: x
B19: 46285 | C19: 0.82638889 | D19: x
B20: 46286 | C20: 0.052083333 | D20: x
B21: 46286 | C21: 0.17361111 | D21: x
B22: 46286 | C22: 0.30902778 | D22: x | E22: x
B23: 46286 | C23: 0.44444444 | D23: x
B24: 46286 | C24: 0.56944444 | D24: x
B25: 46286 | C25: 0.71527778 | D25: x | E25: x
B26: 46286 | C26: 0.83333333 | D26: x
B27: 46287 | C27: 0.041666667 | D27: x
B28: 46287 | C28: 0.17708333 | D28: x
B29: 46287 | C29: 0.30208333 | D29: x | E29: x
B30: 46287 | C30: 0.43055556 | D30: x
B31: 46287 | C31: 0.57638889 | D31: x
B32: 46287 | C32: 0.71180556 | D32: x | E32: x
B33: 46287 | C33: 0.82638889 | D33: x
B34: 46288 | C34: 0.045138889 | D34: x
B35: 46288 | C35: 0.18055556 | D35: x
B36: 46288 | C36: 0.30208333 | D36: x | E36: x
B37: 46288 | C37: 0.45138889 | D37: x
B38: 46288 | C38: 0.56944444 | D38: x
B39: 46288 | C39: 0.70833333 | D39: x | E39: x
B40: 46288 | C40: 0.83680556 | D40: x
B41: 46289 | C41: 0.038194444 | D41: x
B42: 46289 | C42: 0.17013889 | D42: x
...

Sheet Growth
B2: Growth
B3: Each time the baby is weighed or measured. The age fills in from the birthday.
B5: Date | C5: Age | D5: ="Weight ("&Settings!$C$7&")" | E5: ="Length ("&Settings!$C$8&")" | F5: ="Head ("&Settings!$C$8&")" | G5: Notes
B6: 46178 | C6: =IF(OR(B6="",Settings!$C$5=""),"",IF((B6-Settings!$C$5)<0,"",INT((B6-Settings!$C$5)/7)&IF(INT((B6-Settings!$C$5)/7)=1," week"," weeks")&IF(MOD((B6-Settings!$C$5),7)=0,""," "&MOD((B6-Settings!$C$5),7)&IF(MOD((B6-Settings!$C$5),7)=1," day"," days")))) | D6: 3.4 | E6: 50 | F6: 34.5 | I6: =IF(B6="","",B6+ROW()/10000000) | J6: =IF(I6="","",COUNTIF(Growth!$I$6:$I$105,">"&I6))
B7: 46185 | C7: =IF(OR(B7="",Settings!$C$5=""),"",IF((B7-Settings!$C$5)<0,"",INT((B7-Settings!$C$5)/7)&IF(INT((B7-Settings!$C$5)/7)=1," week"," weeks")&IF(MOD((B7-Settings!$C$5),7)=0,""," "&MOD((B7-Settings!$C$5),7)&IF(MOD((B7-Settings!$C$5),7)=1," day"," days")))) | D7: 3.34 | E7: 50.7 | F7: 35 | I7: =IF(B7="","",B7+ROW()/10000000) | J7: =IF(I7="","",COUNTIF(Growth!$I$6:$I$105,">"&I7))
B8: 46192 | C8: =IF(OR(B8="",Settings!$C$5=""),"",IF((B8-Settings!$C$5)<0,"",INT((B8-Settings!$C$5)/7)&IF(INT((B8-Settings!$C$5)/7)=1," week"," weeks")&IF(MOD((B8-Settings!$C$5),7)=0,""," "&MOD((B8-Settings!$C$5),7)&IF(MOD((B8-Settings!$C$5),7)=1," day"," days")))) | D8: 3.58 | E8: 51.5 | F8: 35.4 | I8: =IF(B8="","",B8+ROW()/10000000) | J8: =IF(I8="","",COUNTIF(Growth!$I$6:$I$105,">"&I8))
B9: 46206 | C9: =IF(OR(B9="",Settings!$C$5=""),"",IF((B9-Settings!$C$5)<0,"",INT((B9-Settings!$C$5)/7)&IF(INT((B9-Settings!$C$5)/7)=1," week"," weeks")&IF(MOD((B9-Settings!$C$5),7)=0,""," "&MOD((B9-Settings!$C$5),7)&IF(MOD((B9-Settings!$C$5),7)=1," day"," days")))) | D9: 4.02 | E9: 52.9 | F9: 36.3 | I9: =IF(B9="","",B9+ROW()/10000000) | J9: =IF(I9="","",COUNTIF(Growth!$I$6:$I$105,">"&I9))
B10: 46220 | C10: =IF(OR(B10="",Settings!$C$5=""),"",IF((B10-Settings!$C$5)<0,"",INT((B10-Settings!$C$5)/7)&IF(INT((B10-Settings!$C$5)/7)=1," week"," weeks")&IF(MOD((B10-Settings!$C$5),7)=0,""," "&MOD((B10-Settings!$C$5),7)&IF(MOD((B10-Settings!$C$5),7)=1," day"," days")))) | D10: 4.5 | E10: 54.1 | F10: 37.2 | I10: =IF(B10="","",B10+ROW()/10000000) | J10: =IF(I10="","",COUNTIF(Growth!$I$6:$I$105,">"&I10))
B11: 46234 | C11: =IF(OR(B11="",Settings!$C$5=""),"",IF((B11-Settings!$C$5)<0,"",INT((B11-Settings!$C$5)/7)&IF(INT((B11-Settings!$C$5)/7)=1," week"," weeks")&IF(MOD((B11-Settings!$C$5),7)=0,""," "&MOD((B11-Settings!$C$5),7)&IF(MOD((B11-Settings!$C$5),7)=1," day"," days")))) | D11: 4.86 | E11: 55.6 | F11: 38.1 | I11: =IF(B11="","",B11+ROW()/10000000) | J11: =IF(I11="","",COUNTIF(Growth!$I$6:$I$105,">"&I11))
B12: 46248 | C12: =IF(OR(B12="",Settings!$C$5=""),"",IF((B12-Settings!$C$5)<0,"",INT((B12-Settings!$C$5)/7)&IF(INT((B12-Settings!$C$5)/7)=1," week"," weeks")&IF(MOD((B12-Settings!$C$5),7)=0,""," "&MOD((B12-Settings!$C$5),7)&IF(MOD((B12-Settings!$C$5),7)=1," day"," days")))) | D12: 5.15 | E12: 57.1 | F12: 39 | I12: =IF(B12="","",B12+ROW()/10000000) | J12: =IF(I12="","",COUNTIF(Growth!$I$6:$I$105,">"&I12))
B13: 46262 | C13: =IF(OR(B13="",Settings!$C$5=""),"",IF((B13-Settings!$C$5)<0,"",INT((B13-Settings!$C$5)/7)&IF(INT((B13-Settings!$C$5)/7)=1," week"," weeks")&IF(MOD((B13-Settings!$C$5),7)=0,""," "&MOD((B13-Settings!$C$5),7)&IF(MOD((B13-Settings!$C$5),7)=1," day"," days")))) | D13: 5.48 | E13: 58.8 | F13: 39.9 | I13: =IF(B13="","",B13+ROW()/10000000) | J13: =IF(I13="","",COUNTIF(Growth!$I$6:$I$105,">"&I13))
B14: 46276 | C14: =IF(OR(B14="",Settings!$C$5=""),"",IF((B14-Settings!$C$5)<0,"",INT((B14-Settings!$C$5)/7)&IF(INT((B14-Settings!$C$5)/7)=1," week"," weeks")&IF(MOD((B14-Settings!$C$5),7)=0,""," "&MOD((B14-Settings!$C$5),7)&IF(MOD((B14-Settings!$C$5),7)=1," day"," days")))) | D14: 5.78 | E14: 60.2 | F14: 40.8 | I14: =IF(B14="","",B14+ROW()/10000000) | J14: =IF(I14="","",COUNTIF(Growth!$I$6:$I$105,">"&I14))
B15: 46290 | C15: =IF(OR(B15="",Settings!$C$5=""),"",IF((B15-Settings!$C$5)<0,"",INT((B15-Settings!$C$5)/7)&IF(INT((B15-Settings!$C$5)/7)=1," week"," weeks")&IF(MOD((B15-Settings!$C$5),7)=0,""," "&MOD((B15-Settings!$C$5),7)&IF(MOD((B15-Settings!$C$5),7)=1," day"," days")))) | D15: 6.15 | E15: 61.6 | F15: 41.7 | I15: =IF(B15="","",B15+ROW()/10000000) | J15: =IF(I15="","",COUNTIF(Growth!$I$6:$I$105,">"&I15))
C16: =IF(OR(B16="",Settings!$C$5=""),"",IF((B16-Settings!$C$5)<0,"",INT((B16-Settings!$C$5)/7)&IF(INT((B16-Settings!$C$5)/7)=1," week"," weeks")&IF(MOD((B16-Settings!$C$5),7)=0,""," "&MOD((B16-Settings!$C$5),7)&IF(MOD((B16-Settings!$C$5),7)=1," day"," days")))) | I16: =IF(B16="","",B16+ROW()/10000000) | J16: =IF(I16="","",COUNTIF(Growth!$I$6:$I$105,">"&I16))
C17: =IF(OR(B17="",Settings!$C$5=""),"",IF((B17-Settings!$C$5)<0,"",INT((B17-Settings!$C$5)/7)&IF(INT((B17-Settings!$C$5)/7)=1," week"," weeks")&IF(MOD((B17-Settings!$C$5),7)=0,""," "&MOD((B17-Settings!$C$5),7)&IF(MOD((B17-Settings!$C$5),7)=1," day"," days")))) | I17: =IF(B17="","",B17+ROW()/10000000) | J17: =IF(I17="","",COUNTIF(Growth!$I$6:$I$105,">"&I17))
C18: =IF(OR(B18="",Settings!$C$5=""),"",IF((B18-Settings!$C$5)<0,"",INT((B18-Settings!$C$5)/7)&IF(INT((B18-Settings!$C$5)/7)=1," week"," weeks")&IF(MOD((B18-Settings!$C$5),7)=0,""," "&MOD((B18-Settings!$C$5),7)&IF(MOD((B18-Settings!$C$5),7)=1," day"," days")))) | I18: =IF(B18="","",B18+ROW()/10000000) | J18: =IF(I18="","",COUNTIF(Growth!$I$6:$I$105,">"&I18))
C19: =IF(OR(B19="",Settings!$C$5=""),"",IF((B19-Settings!$C$5)<0,"",INT((B19-Settings!$C$5)/7)&IF(INT((B19-Settings!$C$5)/7)=1," week"," weeks")&IF(MOD((B19-Settings!$C$5),7)=0,""," "&MOD((B19-Settings!$C$5),7)&IF(MOD((B19-Settings!$C$5),7)=1," day"," days")))) | I19: =IF(B19="","",B19+ROW()/10000000) | J19: =IF(I19="","",COUNTIF(Growth!$I$6:$I$105,">"&I19))
C20: =IF(OR(B20="",Settings!$C$5=""),"",IF((B20-Settings!$C$5)<0,"",INT((B20-Settings!$C$5)/7)&IF(INT((B20-Settings!$C$5)/7)=1," week"," weeks")&IF(MOD((B20-Settings!$C$5),7)=0,""," "&MOD((B20-Settings!$C$5),7)&IF(MOD((B20-Settings!$C$5),7)=1," day"," days")))) | I20: =IF(B20="","",B20+ROW()/10000000) | J20: =IF(I20="","",COUNTIF(Growth!$I$6:$I$105,">"&I20))
C21: =IF(OR(B21="",Settings!$C$5=""),"",IF((B21-Settings!$C$5)<0,"",INT((B21-Settings!$C$5)/7)&IF(INT((B21-Settings!$C$5)/7)=1," week"," weeks")&IF(MOD((B21-Settings!$C$5),7)=0,""," "&MOD((B21-Settings!$C$5),7)&IF(MOD((B21-Settings!$C$5),7)=1," day"," days")))) | I21: =IF(B21="","",B21+ROW()/10000000) | J21: =IF(I21="","",COUNTIF(Growth!$I$6:$I$105,">"&I21))
C22: =IF(OR(B22="",Settings!$C$5=""),"",IF((B22-Settings!$C$5)<0,"",INT((B22-Settings!$C$5)/7)&IF(INT((B22-Settings!$C$5)/7)=1," week"," weeks")&IF(MOD((B22-Settings!$C$5),7)=0,""," "&MOD((B22-Settings!$C$5),7)&IF(MOD((B22-Settings!$C$5),7)=1," day"," days")))) | I22: =IF(B22="","",B22+ROW()/10000000) | J22: =IF(I22="","",COUNTIF(Growth!$I$6:$I$105,">"&I22))
C23: =IF(OR(B23="",Settings!$C$5=""),"",IF((B23-Settings!$C$5)<0,"",INT((B23-Settings!$C$5)/7)&IF(INT((B23-Settings!$C$5)/7)=1," week"," weeks")&IF(MOD((B23-Settings!$C$5),7)=0,""," "&MOD((B23-Settings!$C$5),7)&IF(MOD((B23-Settings!$C$5),7)=1," day"," days")))) | I23: =IF(B23="","",B23+ROW()/10000000) | J23: =IF(I23="","",COUNTIF(Growth!$I$6:$I$105,">"&I23))
C24: =IF(OR(B24="",Settings!$C$5=""),"",IF((B24-Settings!$C$5)<0,"",INT((B24-Settings!$C$5)/7)&IF(INT((B24-Settings!$C$5)/7)=1," week"," weeks")&IF(MOD((B24-Settings!$C$5),7)=0,""," "&MOD((B24-Settings!$C$5),7)&IF(MOD((B24-Settings!$C$5),7)=1," day"," days")))) | I24: =IF(B24="","",B24+ROW()/10000000) | J24: =IF(I24="","",COUNTIF(Growth!$I$6:$I$105,">"&I24))
C25: =IF(OR(B25="",Settings!$C$5=""),"",IF((B25-Settings!$C$5)<0,"",INT((B25-Settings!$C$5)/7)&IF(INT((B25-Settings!$C$5)/7)=1," week"," weeks")&IF(MOD((B25-Settings!$C$5),7)=0,""," "&MOD((B25-Settings!$C$5),7)&IF(MOD((B25-Settings!$C$5),7)=1," day"," days")))) | I25: =IF(B25="","",B25+ROW()/10000000) | J25: =IF(I25="","",COUNTIF(Growth!$I$6:$I$105,">"&I25))
C26: =IF(OR(B26="",Settings!$C$5=""),"",IF((B26-Settings!$C$5)<0,"",INT((B26-Settings!$C$5)/7)&IF(INT((B26-Settings!$C$5)/7)=1," week"," weeks")&IF(MOD((B26-Settings!$C$5),7)=0,""," "&MOD((B26-Settings!$C$5),7)&IF(MOD((B26-Settings!$C$5),7)=1," day"," days")))) | I26: =IF(B26="","",B26+ROW()/10000000) | J26: =IF(I26="","",COUNTIF(Growth!$I$6:$I$105,">"&I26))
C27: =IF(OR(B27="",Settings!$C$5=""),"",IF((B27-Settings!$C$5)<0,"",INT((B27-Settings!$C$5)/7)&IF(INT((B27-Settings!$C$5)/7)=1," week"," weeks")&IF(MOD((B27-Settings!$C$5),7)=0,""," "&MOD((B27-Settings!$C$5),7)&IF(MOD((B27-Settings!$C$5),7)=1," day"," days")))) | I27: =IF(B27="","",B27+ROW()/10000000) | J27: =IF(I27="","",COUNTIF(Growth!$I$6:$I$105,">"&I27))
... C105: =IF(OR(B105="",Settings!$C$5=""),"",IF((B105-Settings!$C$5)<0,"",INT((B105-Settings!$C$5)/7)&IF(INT((B105-Settings!$C$5)/7)=1," week"," weeks")&IF(MOD((B105-Settings!$C$5),7)=0,""," "&MOD((B105-Settings!$C$5),7)&IF(MOD((B105-Settings!$C$5),7)=1," day"," days")))) | I105: =IF(B105="","",B105+ROW()/10000000) | J105: =IF(I105="","",COUNTIF(Growth!$I$6:$I$105,">"&I105))

Sheet Appointments
B2: Appointments
B3: Checks, vaccines and anything booked. Put an x under Done once it has happened.
B5: Date | C5: Time | D5: What | E5: Where | F5: Notes | G5: Done
B6: 46181 | C6: 0.41666667 | D6: Newborn check | E6: Home visit | F6: All fine | G6: x | I6: =IF(OR(B6="",G6<>"",B6<TODAY()),"",B6+MOD(N(C6),1)+ROW()/10000000)
B7: 46188 | C7: 0.60416667 | D7: Hearing test | E7: Clinic | G7: x | I7: =IF(OR(B7="",G7<>"",B7<TODAY()),"",B7+MOD(N(C7),1)+ROW()/10000000)
B8: 46227 | C8: 0.38541667 | D8: Six-week check | E8: Doctor | F8: Growing well | G8: x | I8: =IF(OR(B8="",G8<>"",B8<TODAY()),"",B8+MOD(N(C8),1)+ROW()/10000000)
B9: 46236 | C9: 0.45833333 | D9: Vaccines | E9: Doctor | F9: A bit sleepy after | G9: x | I9: =IF(OR(B9="",G9<>"",B9<TODAY()),"",B9+MOD(N(C9),1)+ROW()/10000000)
B10: 46264 | C10: 0.45833333 | D10: Vaccines | E10: Doctor | G10: x | I10: =IF(OR(B10="",G10<>"",B10<TODAY()),"",B10+MOD(N(C10),1)+ROW()/10000000)
B11: 46297 | C11: 0.4375 | D11: Vaccines | E11: Doctor | F11: Bring the red book | I11: =IF(OR(B11="",G11<>"",B11<TODAY()),"",B11+MOD(N(C11),1)+ROW()/10000000)
B12: 46305 | C12: 0.54166667 | D12: Weigh-in | E12: Baby clinic | I12: =IF(OR(B12="",G12<>"",B12<TODAY()),"",B12+MOD(N(C12),1)+ROW()/10000000)
I13: =IF(OR(B13="",G13<>"",B13<TODAY()),"",B13+MOD(N(C13),1)+ROW()/10000000)
I14: =IF(OR(B14="",G14<>"",B14<TODAY()),"",B14+MOD(N(C14),1)+ROW()/10000000)
I15: =IF(OR(B15="",G15<>"",B15<TODAY()),"",B15+MOD(N(C15),1)+ROW()/10000000)
I16: =IF(OR(B16="",G16<>"",B16<TODAY()),"",B16+MOD(N(C16),1)+ROW()/10000000)
I17: =IF(OR(B17="",G17<>"",B17<TODAY()),"",B17+MOD(N(C17),1)+ROW()/10000000)
I18: =IF(OR(B18="",G18<>"",B18<TODAY()),"",B18+MOD(N(C18),1)+ROW()/10000000)
I19: =IF(OR(B19="",G19<>"",B19<TODAY()),"",B19+MOD(N(C19),1)+ROW()/10000000)
I20: =IF(OR(B20="",G20<>"",B20<TODAY()),"",B20+MOD(N(C20),1)+ROW()/10000000)
I21: =IF(OR(B21="",G21<>"",B21<TODAY()),"",B21+MOD(N(C21),1)+ROW()/10000000)
I22: =IF(OR(B22="",G22<>"",B22<TODAY()),"",B22+MOD(N(C22),1)+ROW()/10000000)
I23: =IF(OR(B23="",G23<>"",B23<TODAY()),"",B23+MOD(N(C23),1)+ROW()/10000000)
I24: =IF(OR(B24="",G24<>"",B24<TODAY()),"",B24+MOD(N(C24),1)+ROW()/10000000)
... I105: =IF(OR(B105="",G105<>"",B105<TODAY()),"",B105+MOD(N(C105),1)+ROW()/10000000)

Sheet Milestones
B2: Milestones
B3: The firsts. Type the date when it happens and the age fills in. Every baby has its own pace.
B5: Milestone | C5: Date | D5: Age | E5: Notes
B6: First smile | C6: 46219 | D6: =IF(OR(C6="",Settings!$C$5=""),"",IF((C6-Settings!$C$5)<0,"",INT((C6-Settings!$C$5)/7)&IF(INT((C6-Settings!$C$5)/7)=1," week"," weeks")&IF(MOD((C6-Settings!$C$5),7)=0,""," "&MOD((C6-Settings!$C$5),7)&IF(MOD((C6-Settings!$C$5),7)=1," day"," days"))))
B7: Holds head up | C7: 46248 | D7: =IF(OR(C7="",Settings!$C$5=""),"",IF((C7-Settings!$C$5)<0,"",INT((C7-Settings!$C$5)/7)&IF(INT((C7-Settings!$C$5)/7)=1," week"," weeks")&IF(MOD((C7-Settings!$C$5),7)=0,""," "&MOD((C7-Settings!$C$5),7)&IF(MOD((C7-Settings!$C$5),7)=1," day"," days"))))
B8: Laughs | C8: 46277 | D8: =IF(OR(C8="",Settings!$C$5=""),"",IF((C8-Settings!$C$5)<0,"",INT((C8-Settings!$C$5)/7)&IF(INT((C8-Settings!$C$5)/7)=1," week"," weeks")&IF(MOD((C8-Settings!$C$5),7)=0,""," "&MOD((C8-Settings!$C$5),7)&IF(MOD((C8-Settings!$C$5),7)=1," day"," days"))))
B9: Rolls over | D9: =IF(OR(C9="",Settings!$C$5=""),"",IF((C9-Settings!$C$5)<0,"",INT((C9-Settings!$C$5)/7)&IF(INT((C9-Settings!$C$5)/7)=1," week"," weeks")&IF(MOD((C9-Settings!$C$5),7)=0,""," "&MOD((C9-Settings!$C$5),7)&IF(MOD((C9-Settings!$C$5),7)=1," day"," days"))))
B10: Reaches for toys | D10: =IF(OR(C10="",Settings!$C$5=""),"",IF((C10-Settings!$C$5)<0,"",INT((C10-Settings!$C$5)/7)&IF(INT((C10-Settings!$C$5)/7)=1," week"," weeks")&IF(MOD((C10-Settings!$C$5),7)=0,""," "&MOD((C10-Settings!$C$5),7)&IF(MOD((C10-Settings!$C$5),7)=1," day"," days"))))
B11: Sits without help | D11: =IF(OR(C11="",Settings!$C$5=""),"",IF((C11-Settings!$C$5)<0,"",INT((C11-Settings!$C$5)/7)&IF(INT((C11-Settings!$C$5)/7)=1," week"," weeks")&IF(MOD((C11-Settings!$C$5),7)=0,""," "&MOD((C11-Settings!$C$5),7)&IF(MOD((C11-Settings!$C$5),7)=1," day"," days"))))
B12: First tooth | D12: =IF(OR(C12="",Settings!$C$5=""),"",IF((C12-Settings!$C$5)<0,"",INT((C12-Settings!$C$5)/7)&IF(INT((C12-Settings!$C$5)/7)=1," week"," weeks")&IF(MOD((C12-Settings!$C$5),7)=0,""," "&MOD((C12-Settings!$C$5),7)&IF(MOD((C12-Settings!$C$5),7)=1," day"," days"))))
B13: Crawls | D13: =IF(OR(C13="",Settings!$C$5=""),"",IF((C13-Settings!$C$5)<0,"",INT((C13-Settings!$C$5)/7)&IF(INT((C13-Settings!$C$5)/7)=1," week"," weeks")&IF(MOD((C13-Settings!$C$5),7)=0,""," "&MOD((C13-Settings!$C$5),7)&IF(MOD((C13-Settings!$C$5),7)=1," day"," days"))))
B14: First word | D14: =IF(OR(C14="",Settings!$C$5=""),"",IF((C14-Settings!$C$5)<0,"",INT((C14-Settings!$C$5)/7)&IF(INT((C14-Settings!$C$5)/7)=1," week"," weeks")&IF(MOD((C14-Settings!$C$5),7)=0,""," "&MOD((C14-Settings!$C$5),7)&IF(MOD((C14-Settings!$C$5),7)=1," day"," days"))))
B15: Pulls up to stand | D15: =IF(OR(C15="",Settings!$C$5=""),"",IF((C15-Settings!$C$5)<0,"",INT((C15-Settings!$C$5)/7)&IF(INT((C15-Settings!$C$5)/7)=1," week"," weeks")&IF(MOD((C15-Settings!$C$5),7)=0,""," "&MOD((C15-Settings!$C$5),7)&IF(MOD((C15-Settings!$C$5),7)=1," day"," days"))))
B16: First steps | D16: =IF(OR(C16="",Settings!$C$5=""),"",IF((C16-Settings!$C$5)<0,"",INT((C16-Settings!$C$5)/7)&IF(INT((C16-Settings!$C$5)/7)=1," week"," weeks")&IF(MOD((C16-Settings!$C$5),7)=0,""," "&MOD((C16-Settings!$C$5),7)&IF(MOD((C16-Settings!$C$5),7)=1," day"," days"))))
D17: =IF(OR(C17="",Settings!$C$5=""),"",IF((C17-Settings!$C$5)<0,"",INT((C17-Settings!$C$5)/7)&IF(INT((C17-Settings!$C$5)/7)=1," week"," weeks")&IF(MOD((C17-Settings!$C$5),7)=0,""," "&MOD((C17-Settings!$C$5),7)&IF(MOD((C17-Settings!$C$5),7)=1," day"," days"))))
D18: =IF(OR(C18="",Settings!$C$5=""),"",IF((C18-Settings!$C$5)<0,"",INT((C18-Settings!$C$5)/7)&IF(INT((C18-Settings!$C$5)/7)=1," week"," weeks")&IF(MOD((C18-Settings!$C$5),7)=0,""," "&MOD((C18-Settings!$C$5),7)&IF(MOD((C18-Settings!$C$5),7)=1," day"," days"))))
D19: =IF(OR(C19="",Settings!$C$5=""),"",IF((C19-Settings!$C$5)<0,"",INT((C19-Settings!$C$5)/7)&IF(INT((C19-Settings!$C$5)/7)=1," week"," weeks")&IF(MOD((C19-Settings!$C$5),7)=0,""," "&MOD((C19-Settings!$C$5),7)&IF(MOD((C19-Settings!$C$5),7)=1," day"," days"))))
D20: =IF(OR(C20="",Settings!$C$5=""),"",IF((C20-Settings!$C$5)<0,"",INT((C20-Settings!$C$5)/7)&IF(INT((C20-Settings!$C$5)/7)=1," week"," weeks")&IF(MOD((C20-Settings!$C$5),7)=0,""," "&MOD((C20-Settings!$C$5),7)&IF(MOD((C20-Settings!$C$5),7)=1," day"," days"))))
D21: =IF(OR(C21="",Settings!$C$5=""),"",IF((C21-Settings!$C$5)<0,"",INT((C21-Settings!$C$5)/7)&IF(INT((C21-Settings!$C$5)/7)=1," week"," weeks")&IF(MOD((C21-Settings!$C$5),7)=0,""," "&MOD((C21-Settings!$C$5),7)&IF(MOD((C21-Settings!$C$5),7)=1," day"," days"))))
D22: =IF(OR(C22="",Settings!$C$5=""),"",IF((C22-Settings!$C$5)<0,"",INT((C22-Settings!$C$5)/7)&IF(INT((C22-Settings!$C$5)/7)=1," week"," weeks")&IF(MOD((C22-Settings!$C$5),7)=0,""," "&MOD((C22-Settings!$C$5),7)&IF(MOD((C22-Settings!$C$5),7)=1," day"," days"))))
D23: =IF(OR(C23="",Settings!$C$5=""),"",IF((C23-Settings!$C$5)<0,"",INT((C23-Settings!$C$5)/7)&IF(INT((C23-Settings!$C$5)/7)=1," week"," weeks")&IF(MOD((C23-Settings!$C$5),7)=0,""," "&MOD((C23-Settings!$C$5),7)&IF(MOD((C23-Settings!$C$5),7)=1," day"," days"))))
D24: =IF(OR(C24="",Settings!$C$5=""),"",IF((C24-Settings!$C$5)<0,"",INT((C24-Settings!$C$5)/7)&IF(INT((C24-Settings!$C$5)/7)=1," week"," weeks")&IF(MOD((C24-Settings!$C$5),7)=0,""," "&MOD((C24-Settings!$C$5),7)&IF(MOD((C24-Settings!$C$5),7)=1," day"," days"))))
D25: =IF(OR(C25="",Settings!$C$5=""),"",IF((C25-Settings!$C$5)<0,"",INT((C25-Settings!$C$5)/7)&IF(INT((C25-Settings!$C$5)/7)=1," week"," weeks")&IF(MOD((C25-Settings!$C$5),7)=0,""," "&MOD((C25-Settings!$C$5),7)&IF(MOD((C25-Settings!$C$5),7)=1," day"," days"))))
D26: =IF(OR(C26="",Settings!$C$5=""),"",IF((C26-Settings!$C$5)<0,"",INT((C26-Settings!$C$5)/7)&IF(INT((C26-Settings!$C$5)/7)=1," week"," weeks")&IF(MOD((C26-Settings!$C$5),7)=0,""," "&MOD((C26-Settings!$C$5),7)&IF(MOD((C26-Settings!$C$5),7)=1," day"," days"))))
D27: =IF(OR(C27="",Settings!$C$5=""),"",IF((C27-Settings!$C$5)<0,"",INT((C27-Settings!$C$5)/7)&IF(INT((C27-Settings!$C$5)/7)=1," week"," weeks")&IF(MOD((C27-Settings!$C$5),7)=0,""," "&MOD((C27-Settings!$C$5),7)&IF(MOD((C27-Settings!$C$5),7)=1," day"," days"))))
D28: =IF(OR(C28="",Settings!$C$5=""),"",IF((C28-Settings!$C$5)<0,"",INT((C28-Settings!$C$5)/7)&IF(INT((C28-Settings!$C$5)/7)=1," week"," weeks")&IF(MOD((C28-Settings!$C$5),7)=0,""," "&MOD((C28-Settings!$C$5),7)&IF(MOD((C28-Settings!$C$5),7)=1," day"," days"))))
... D45: =IF(OR(C45="",Settings!$C$5=""),"",IF((C45-Settings!$C$5)<0,"",INT((C45-Settings!$C$5)/7)&IF(INT((C45-Settings!$C$5)/7)=1," week"," weeks")&IF(MOD((C45-Settings!$C$5),7)=0,""," "&MOD((C45-Settings!$C$5),7)&IF(MOD((C45-Settings!$C$5),7)=1," day"," days"))))

Sheet Settings
B2: Settings
B3: The baby's name and birthday, and the units you use.
B4: Name | C4: Ella | E4: The ages on the other tabs count from the birthday.
B5: Birthday | C5: 46178
B6: Milk in | C6: ml
B7: Weight in | C7: kg
B8: Length in | C8: cm

Sheet Start Here
B2: Start here
B3: Type only in the yellow cells. Everything else is calculated.
B5: 1 | C5: Settings: the baby's name and birthday, and your units.
B7: 2 | C7: Feeds, Sleep and Nappies: one line each time, with the date and the time.
B9: 3 | C9: Growth: each time the baby is weighed or measured. The weight chart follows.
B11: 4 | C11: Appointments and Milestones: checks and vaccines as they are booked, and the firsts as they come.
B13: 5 | C13: Dashboard: the day you pick, or today, and the seven days before it.
C16: This is a log. It does not give medical advice: for any question about feeding, sleep or growth, ask your midwife, health visitor or doctor.
C18: The example baby and her days are made up. Delete them and start with yours.
C20: Works in Google Sheets and Microsoft Excel. The Google Sheets app makes it quick to add a feed at night.
