Workbook

Sheet Calculator
B2: Fee and profit calculator
B3: Type one sale in the yellow cells. Rates come from the Settings tab.
B4: ="Country: "&Settings!$C$4&" Currency: "&INDEX(Settings!$C$8:$C$15,MATCH(Settings!$C$4,Settings!$B$8:$B$15,0))
B6: The sale | C6: Amount | E6: Etsy fees | F6: Amount | G6: Share
B7: Item price | C7: 18 | E7: Listing fee | F7: =INDEX(Settings!$D$8:$D$15,MATCH(Settings!$C$4,Settings!$B$8:$B$15,0)) | G7: =IF((C7*(1-C9)+C8)=0,"",F7/(C7*(1-C9)+C8))
B8: Shipping you charge | C8: 4.5 | E8: Transaction fee | F8: =INDEX(Settings!$E$8:$E$15,MATCH(Settings!$C$4,Settings!$B$8:$B$15,0))*(C7*(1-C9)+C8) | G8: =IF((C7*(1-C9)+C8)=0,"",F8/(C7*(1-C9)+C8))
B9: Discount on the item | C9: 0 | E9: Payment processing | F9: =INDEX(Settings!$F$8:$F$15,MATCH(Settings!$C$4,Settings!$B$8:$B$15,0))*(C7*(1-C9)+C8)*(1+Settings!$C$26)+INDEX(Settings!$G$8:$G$15,MATCH(Settings!$C$4,Settings!$B$8:$B$15,0)) | G9: =IF((C7*(1-C9)+C8)=0,"",F9/(C7*(1-C9)+C8))
B10: Materials | C10: 3.2 | E10: Offsite Ads | F10: =IF(C14="Yes",MIN(Settings!$C$23*(C7*(1-C9)+C8),Settings!$C$24),0) | G10: =IF((C7*(1-C9)+C8)=0,"",F10/(C7*(1-C9)+C8))
B11: Packaging | C11: 0.8 | E11: Regulatory fee | F11: =INDEX(Settings!$H$8:$H$15,MATCH(Settings!$C$4,Settings!$B$8:$B$15,0))*(C7*(1-C9)+C8) | G11: =IF((C7*(1-C9)+C8)=0,"",F11/(C7*(1-C9)+C8))
B12: Shipping label you pay | C12: 4.1 | E12: Currency conversion | F12: =IF(Settings!$C$25="Yes",0.025,0)*(C7*(1-C9)+C8) | G12: =IF((C7*(1-C9)+C8)=0,"",F12/(C7*(1-C9)+C8))
B13: Minutes of work | C13: 12 | E13: VAT on fees | F13: =INDEX(Settings!$I$8:$I$15,MATCH(Settings!$C$4,Settings!$B$8:$B$15,0))*(F7+F8+F10+F11) | G13: =IF((C7*(1-C9)+C8)=0,"",F13/(C7*(1-C9)+C8))
B14: Sold through an Offsite Ad? | C14: No | E14: All Etsy fees | F14: =SUM(F7:F13) | G14: =IF((C7*(1-C9)+C8)=0,"",F14/(C7*(1-C9)+C8))
B17: What you keep | C17: Amount | E17: Verdict
B18: The buyer pays you | C18: =(C7*(1-C9)+C8) | E18: =IF(C18=0,"",IF(C21<0,"This sale loses money",IF(C22<Settings!$C$28,"Profit, but below your target of "&ROUND(Settings!$C$28*100,0)&"%","On target: "&ROUND(C22*100,0)&"% profit margin")))
B19: Minus Etsy fees | C19: =-F14
B20: Minus your costs | C20: =-(C10+C11+C12+C13/60*Settings!$C$27)
B21: Profit | C21: =C18+C19+C20 | E21: Price for your target margin
B22: Profit margin | C22: =IF(C18=0,"",C21/C18) | E22: =IF(1-(INDEX(Settings!$E$8:$E$15,MATCH(Settings!$C$4,Settings!$B$8:$B$15,0))+INDEX(Settings!$F$8:$F$15,MATCH(Settings!$C$4,Settings!$B$8:$B$15,0))*(1+Settings!$C$26)+IF(C14="Yes",Settings!$C$23,0)+INDEX(Settings!$H$8:$H$15,MATCH(Settings!$C$4,Settings!$B$8:$B$15,0))+IF(Settings!$C$25="Yes",0.025,0)+INDEX(Settings!$I$8:$I$15,MATCH(Settings!$C$4,Settings!$B$8:$B$15,0))*(INDEX(Settings!$E$8:$E$15,MATCH(Settings!$C$4,Settings!$B$8:$B$15,0))+IF(C14="Yes",Settings!$C$23,0)+INDEX(Settings!$H$8:$H$15,MATCH(Settings!$C$4,Settings!$B$8:$B$15,0))))-Settings!$C$28<=0,"Not reachable",MAX(0,((INDEX(Settings!$D$8:$D$15,MATCH(Settings!$C$4,Settings!$B$8:$B$15,0))*(1+INDEX(Settings!$I$8:$I$15,MATCH(Settings!$C$4,Settings!$B$8:$B$15,0)))+INDEX(Settings!$G$8:$G$15,MATCH(Settings!$C$4,Settings!$B$8:$B$15,0))+C10+C11+C12+C13/60*Settings!$C$27)/(1-(INDEX(Settings!$E$8:$E$15,MATCH(Settings!$C$4,Settings!$B$8:$B$15,0))+INDEX(Settings!$F$8:$F$15,MATCH(Settings!$C$4,Settings!$B$8:$B$15,0))*(1+Settings!$C$26)+IF(C14="Yes",Settings!$C$23,0)+INDEX(Settings!$H$8:$H$15,MATCH(Settings!$C$4,Settings!$B$8:$B$15,0))+IF(Settings!$C$25="Yes",0.025,0)+INDEX(Settings!$I$8:$I$15,MATCH(Settings!$C$4,Settings!$B$8:$B$15,0))*(INDEX(Settings!$E$8:$E$15,MATCH(Settings!$C$4,Settings!$B$8:$B$15,0))+IF(C14="Yes",Settings!$C$23,0)+INDEX(Settings!$H$8:$H$15,MATCH(Settings!$C$4,Settings!$B$8:$B$15,0))))-Settings!$C$28)-C8)/(1-C9)))
B23: ="Your time is counted at "&FIXED(Settings!$C$27,2)&" per hour (Settings)."
E24: Item price, with the same shipping and discount as above.

Sheet Products
B2: Your products
B3: One line per product. Fees, profit and a suggested price are calculated.
B4: ="Country: "&Settings!$C$4&". Your time at "&FIXED(Settings!$C$27,2)&" per hour. Target margin "&ROUND(Settings!$C$28*100,0)&"%."
B5: =COUNTIFS(B8:B207,"?*")&" products: "&COUNTIFS(O8:O207,"On target")&" on target, "&COUNTIFS(O8:O207,"Below target")&" below target, "&COUNTIFS(O8:O207,"Loss")&" at a loss."
B7: Product | C7: Price | D7: Shipping charged | E7: Materials | F7: Packaging | G7: Label you pay | H7: Minutes | I7: Share from Offsite Ads | J7: Buyer pays | K7: Etsy fees | L7: Your costs | M7: Profit | N7: Margin | O7: Status | P7: Price for target
B8: Soy candle, 200 g | C8: 18 | D8: 4.5 | E8: 3.2 | F8: 0.8 | G8: 4.1 | H8: 12 | I8: 0.1 | J8: =IF(B8="","",(N(C8)+N(D8))) | K8: =IF(B8="","",INDEX(Settings!$D$8:$D$15,MATCH(Settings!$C$4,Settings!$B$8:$B$15,0))+INDEX(Settings!$E$8:$E$15,MATCH(Settings!$C$4,Settings!$B$8:$B$15,0))*(N(C8)+N(D8))+INDEX(Settings!$F$8:$F$15,MATCH(Settings!$C$4,Settings!$B$8:$B$15,0))*(N(C8)+N(D8))*(1+Settings!$C$26)+INDEX(Settings!$G$8:$G$15,MATCH(Settings!$C$4,Settings!$B$8:$B$15,0))+N(I8)*MIN(Settings!$C$23*(N(C8)+N(D8)),Settings!$C$24)+INDEX(Settings!$H$8:$H$15,MATCH(Settings!$C$4,Settings!$B$8:$B$15,0))*(N(C8)+N(D8))+IF(Settings!$C$25="Yes",0.025,0)*(N(C8)+N(D8))+INDEX(Settings!$I$8:$I$15,MATCH(Settings!$C$4,Settings!$B$8:$B$15,0))*(INDEX(Settings!$D$8:$D$15,MATCH(Settings!$C$4,Settings!$B$8:$B$15,0))+INDEX(Settings!$E$8:$E$15,MATCH(Settings!$C$4,Settings!$B$8:$B$15,0))*(N(C8)+N(D8))+N(I8)*MIN(Settings!$C$23*(N(C8)+N(D8)),Settings!$C$24)+INDEX(Settings!$H$8:$H$15,MATCH(Settings!$C$4,Settings!$B$8:$B$15,0))*(N(C8)+N(D8)))) | L8: =IF(B8="","",N(E8)+N(F8)+N(G8)+N(H8)/60*Settings!$C$27) | M8: =IF(B8="","",J8-K8-L8) | N8: =IF(OR(B8="",N(J8)=0),"",M8/J8) | O8: =IF(B8="","",IF(M8<0,"Loss",IF(N8<Settings!$C$28,"Below target","On target"))) | P8: =IF(B8="","",IF(1-(INDEX(Settings!$E$8:$E$15,MATCH(Settings!$C$4,Settings!$B$8:$B$15,0))+INDEX(Settings!$F$8:$F$15,MATCH(Settings!$C$4,Settings!$B$8:$B$15,0))*(1+Settings!$C$26)+N(I8)*Settings!$C$23+INDEX(Settings!$H$8:$H$15,MATCH(Settings!$C$4,Settings!$B$8:$B$15,0))+IF(Settings!$C$25="Yes",0.025,0)+INDEX(Settings!$I$8:$I$15,MATCH(Settings!$C$4,Settings!$B$8:$B$15,0))*(INDEX(Settings!$E$8:$E$15,MATCH(Settings!$C$4,Settings!$B$8:$B$15,0))+N(I8)*Settings!$C$23+INDEX(Settings!$H$8:$H$15,MATCH(Settings!$C$4,Settings!$B$8:$B$15,0))))-Settings!$C$28<=0,"Not reachable",MAX(0,(INDEX(Settings!$D$8:$D$15,MATCH(Settings!$C$4,Settings!$B$8:$B$15,0))*(1+INDEX(Settings!$I$8:$I$15,MATCH(Settings!$C$4,Settings!$B$8:$B$15,0)))+INDEX(Settings!$G$8:$G$15,MATCH(Settings!$C$4,Settings!$B$8:$B$15,0))+L8)/(1-(INDEX(Settings!$E$8:$E$15,MATCH(Settings!$C$4,Settings!$B$8:$B$15,0))+INDEX(Settings!$F$8:$F$15,MATCH(Settings!$C$4,Settings!$B$8:$B$15,0))*(1+Settings!$C$26)+N(I8)*Settings!$C$23+INDEX(Settings!$H$8:$H$15,MATCH(Settings!$C$4,Settings!$B$8:$B$15,0))+IF(Settings!$C$25="Yes",0.025,0)+INDEX(Settings!$I$8:$I$15,MATCH(Settings!$C$4,Settings!$B$8:$B$15,0))*(INDEX(Settings!$E$8:$E$15,MATCH(Settings!$C$4,Settings!$B$8:$B$15,0))+N(I8)*Settings!$C$23+INDEX(Settings!$H$8:$H$15,MATCH(Settings!$C$4,Settings!$B$8:$B$15,0))))-Settings!$C$28)-N(D8))))
B9: Brass earrings | C9: 22 | D9: 3.5 | E9: 2.9 | F9: 0.5 | G9: 1.2 | H9: 20 | I9: 0.1 | J9: =IF(B9="","",(N(C9)+N(D9))) | K9: =IF(B9="","",INDEX(Settings!$D$8:$D$15,MATCH(Settings!$C$4,Settings!$B$8:$B$15,0))+INDEX(Settings!$E$8:$E$15,MATCH(Settings!$C$4,Settings!$B$8:$B$15,0))*(N(C9)+N(D9))+INDEX(Settings!$F$8:$F$15,MATCH(Settings!$C$4,Settings!$B$8:$B$15,0))*(N(C9)+N(D9))*(1+Settings!$C$26)+INDEX(Settings!$G$8:$G$15,MATCH(Settings!$C$4,Settings!$B$8:$B$15,0))+N(I9)*MIN(Settings!$C$23*(N(C9)+N(D9)),Settings!$C$24)+INDEX(Settings!$H$8:$H$15,MATCH(Settings!$C$4,Settings!$B$8:$B$15,0))*(N(C9)+N(D9))+IF(Settings!$C$25="Yes",0.025,0)*(N(C9)+N(D9))+INDEX(Settings!$I$8:$I$15,MATCH(Settings!$C$4,Settings!$B$8:$B$15,0))*(INDEX(Settings!$D$8:$D$15,MATCH(Settings!$C$4,Settings!$B$8:$B$15,0))+INDEX(Settings!$E$8:$E$15,MATCH(Settings!$C$4,Settings!$B$8:$B$15,0))*(N(C9)+N(D9))+N(I9)*MIN(Settings!$C$23*(N(C9)+N(D9)),Settings!$C$24)+INDEX(Settings!$H$8:$H$15,MATCH(Settings!$C$4,Settings!$B$8:$B$15,0))*(N(C9)+N(D9)))) | L9: =IF(B9="","",N(E9)+N(F9)+N(G9)+N(H9)/60*Settings!$C$27) | M9: =IF(B9="","",J9-K9-L9) | N9: =IF(OR(B9="",N(J9)=0),"",M9/J9) | O9: =IF(B9="","",IF(M9<0,"Loss",IF(N9<Settings!$C$28,"Below target","On target"))) | P9: =IF(B9="","",IF(1-(INDEX(Settings!$E$8:$E$15,MATCH(Settings!$C$4,Settings!$B$8:$B$15,0))+INDEX(Settings!$F$8:$F$15,MATCH(Settings!$C$4,Settings!$B$8:$B$15,0))*(1+Settings!$C$26)+N(I9)*Settings!$C$23+INDEX(Settings!$H$8:$H$15,MATCH(Settings!$C$4,Settings!$B$8:$B$15,0))+IF(Settings!$C$25="Yes",0.025,0)+INDEX(Settings!$I$8:$I$15,MATCH(Settings!$C$4,Settings!$B$8:$B$15,0))*(INDEX(Settings!$E$8:$E$15,MATCH(Settings!$C$4,Settings!$B$8:$B$15,0))+N(I9)*Settings!$C$23+INDEX(Settings!$H$8:$H$15,MATCH(Settings!$C$4,Settings!$B$8:$B$15,0))))-Settings!$C$28<=0,"Not reachable",MAX(0,(INDEX(Settings!$D$8:$D$15,MATCH(Settings!$C$4,Settings!$B$8:$B$15,0))*(1+INDEX(Settings!$I$8:$I$15,MATCH(Settings!$C$4,Settings!$B$8:$B$15,0)))+INDEX(Settings!$G$8:$G$15,MATCH(Settings!$C$4,Settings!$B$8:$B$15,0))+L9)/(1-(INDEX(Settings!$E$8:$E$15,MATCH(Settings!$C$4,Settings!$B$8:$B$15,0))+INDEX(Settings!$F$8:$F$15,MATCH(Settings!$C$4,Settings!$B$8:$B$15,0))*(1+Settings!$C$26)+N(I9)*Settings!$C$23+INDEX(Settings!$H$8:$H$15,MATCH(Settings!$C$4,Settings!$B$8:$B$15,0))+IF(Settings!$C$25="Yes",0.025,0)+INDEX(Settings!$I$8:$I$15,MATCH(Settings!$C$4,Settings!$B$8:$B$15,0))*(INDEX(Settings!$E$8:$E$15,MATCH(Settings!$C$4,Settings!$B$8:$B$15,0))+N(I9)*Settings!$C$23+INDEX(Settings!$H$8:$H$15,MATCH(Settings!$C$4,Settings!$B$8:$B$15,0))))-Settings!$C$28)-N(D9))))
B10: Art print, A4 | C10: 15 | D10: 3 | E10: 1.4 | F10: 0.9 | G10: 1.5 | H10: 5 | I10: 0 | J10: =IF(B10="","",(N(C10)+N(D10))) | K10: =IF(B10="","",INDEX(Settings!$D$8:$D$15,MATCH(Settings!$C$4,Settings!$B$8:$B$15,0))+INDEX(Settings!$E$8:$E$15,MATCH(Settings!$C$4,Settings!$B$8:$B$15,0))*(N(C10)+N(D10))+INDEX(Settings!$F$8:$F$15,MATCH(Settings!$C$4,Settings!$B$8:$B$15,0))*(N(C10)+N(D10))*(1+Settings!$C$26)+INDEX(Settings!$G$8:$G$15,MATCH(Settings!$C$4,Settings!$B$8:$B$15,0))+N(I10)*MIN(Settings!$C$23*(N(C10)+N(D10)),Settings!$C$24)+INDEX(Settings!$H$8:$H$15,MATCH(Settings!$C$4,Settings!$B$8:$B$15,0))*(N(C10)+N(D10))+IF(Settings!$C$25="Yes",0.025,0)*(N(C10)+N(D10))+INDEX(Settings!$I$8:$I$15,MATCH(Settings!$C$4,Settings!$B$8:$B$15,0))*(INDEX(Settings!$D$8:$D$15,MATCH(Settings!$C$4,Settings!$B$8:$B$15,0))+INDEX(Settings!$E$8:$E$15,MATCH(Settings!$C$4,Settings!$B$8:$B$15,0))*(N(C10)+N(D10))+N(I10)*MIN(Settings!$C$23*(N(C10)+N(D10)),Settings!$C$24)+INDEX(Settings!$H$8:$H$15,MATCH(Settings!$C$4,Settings!$B$8:$B$15,0))*(N(C10)+N(D10)))) | L10: =IF(B10="","",N(E10)+N(F10)+N(G10)+N(H10)/60*Settings!$C$27) | M10: =IF(B10="","",J10-K10-L10) | N10: =IF(OR(B10="",N(J10)=0),"",M10/J10) | O10: =IF(B10="","",IF(M10<0,"Loss",IF(N10<Settings!$C$28,"Below target","On target"))) | P10: =IF(B10="","",IF(1-(INDEX(Settings!$E$8:$E$15,MATCH(Settings!$C$4,Settings!$B$8:$B$15,0))+INDEX(Settings!$F$8:$F$15,MATCH(Settings!$C$4,Settings!$B$8:$B$15,0))*(1+Settings!$C$26)+N(I10)*Settings!$C$23+INDEX(Settings!$H$8:$H$15,MATCH(Settings!$C$4,Settings!$B$8:$B$15,0))+IF(Settings!$C$25="Yes",0.025,0)+INDEX(Settings!$I$8:$I$15,MATCH(Settings!$C$4,Settings!$B$8:$B$15,0))*(INDEX(Settings!$E$8:$E$15,MATCH(Settings!$C$4,Settings!$B$8:$B$15,0))+N(I10)*Settings!$C$23+INDEX(Settings!$H$8:$H$15,MATCH(Settings!$C$4,Settings!$B$8:$B$15,0))))-Settings!$C$28<=0,"Not reachable",MAX(0,(INDEX(Settings!$D$8:$D$15,MATCH(Settings!$C$4,Settings!$B$8:$B$15,0))*(1+INDEX(Settings!$I$8:$I$15,MATCH(Settings!$C$4,Settings!$B$8:$B$15,0)))+INDEX(Settings!$G$8:$G$15,MATCH(Settings!$C$4,Settings!$B$8:$B$15,0))+L10)/(1-(INDEX(Settings!$E$8:$E$15,MATCH(Settings!$C$4,Settings!$B$8:$B$15,0))+INDEX(Settings!$F$8:$F$15,MATCH(Settings!$C$4,Settings!$B$8:$B$15,0))*(1+Settings!$C$26)+N(I10)*Settings!$C$23+INDEX(Settings!$H$8:$H$15,MATCH(Settings!$C$4,Settings!$B$8:$B$15,0))+IF(Settings!$C$25="Yes",0.025,0)+INDEX(Settings!$I$8:$I$15,MATCH(Settings!$C$4,Settings!$B$8:$B$15,0))*(INDEX(Settings!$E$8:$E$15,MATCH(Settings!$C$4,Settings!$B$8:$B$15,0))+N(I10)*Settings!$C$23+INDEX(Settings!$H$8:$H$15,MATCH(Settings!$C$4,Settings!$B$8:$B$15,0))))-Settings!$C$28)-N(D10))))
B11: Knitted hat | C11: 38 | D11: 5 | E11: 9.5 | F11: 0.7 | G11: 4.6 | H11: 180 | I11: 0 | J11: =IF(B11="","",(N(C11)+N(D11))) | K11: =IF(B11="","",INDEX(Settings!$D$8:$D$15,MATCH(Settings!$C$4,Settings!$B$8:$B$15,0))+INDEX(Settings!$E$8:$E$15,MATCH(Settings!$C$4,Settings!$B$8:$B$15,0))*(N(C11)+N(D11))+INDEX(Settings!$F$8:$F$15,MATCH(Settings!$C$4,Settings!$B$8:$B$15,0))*(N(C11)+N(D11))*(1+Settings!$C$26)+INDEX(Settings!$G$8:$G$15,MATCH(Settings!$C$4,Settings!$B$8:$B$15,0))+N(I11)*MIN(Settings!$C$23*(N(C11)+N(D11)),Settings!$C$24)+INDEX(Settings!$H$8:$H$15,MATCH(Settings!$C$4,Settings!$B$8:$B$15,0))*(N(C11)+N(D11))+IF(Settings!$C$25="Yes",0.025,0)*(N(C11)+N(D11))+INDEX(Settings!$I$8:$I$15,MATCH(Settings!$C$4,Settings!$B$8:$B$15,0))*(INDEX(Settings!$D$8:$D$15,MATCH(Settings!$C$4,Settings!$B$8:$B$15,0))+INDEX(Settings!$E$8:$E$15,MATCH(Settings!$C$4,Settings!$B$8:$B$15,0))*(N(C11)+N(D11))+N(I11)*MIN(Settings!$C$23*(N(C11)+N(D11)),Settings!$C$24)+INDEX(Settings!$H$8:$H$15,MATCH(Settings!$C$4,Settings!$B$8:$B$15,0))*(N(C11)+N(D11)))) | L11: =IF(B11="","",N(E11)+N(F11)+N(G11)+N(H11)/60*Settings!$C$27) | M11: =IF(B11="","",J11-K11-L11) | N11: =IF(OR(B11="",N(J11)=0),"",M11/J11) | O11: =IF(B11="","",IF(M11<0,"Loss",IF(N11<Settings!$C$28,"Below target","On target"))) | P11: =IF(B11="","",IF(1-(INDEX(Settings!$E$8:$E$15,MATCH(Settings!$C$4,Settings!$B$8:$B$15,0))+INDEX(Settings!$F$8:$F$15,MATCH(Settings!$C$4,Settings!$B$8:$B$15,0))*(1+Settings!$C$26)+N(I11)*Settings!$C$23+INDEX(Settings!$H$8:$H$15,MATCH(Settings!$C$4,Settings!$B$8:$B$15,0))+IF(Settings!$C$25="Yes",0.025,0)+INDEX(Settings!$I$8:$I$15,MATCH(Settings!$C$4,Settings!$B$8:$B$15,0))*(INDEX(Settings!$E$8:$E$15,MATCH(Settings!$C$4,Settings!$B$8:$B$15,0))+N(I11)*Settings!$C$23+INDEX(Settings!$H$8:$H$15,MATCH(Settings!$C$4,Settings!$B$8:$B$15,0))))-Settings!$C$28<=0,"Not reachable",MAX(0,(INDEX(Settings!$D$8:$D$15,MATCH(Settings!$C$4,Settings!$B$8:$B$15,0))*(1+INDEX(Settings!$I$8:$I$15,MATCH(Settings!$C$4,Settings!$B$8:$B$15,0)))+INDEX(Settings!$G$8:$G$15,MATCH(Settings!$C$4,Settings!$B$8:$B$15,0))+L11)/(1-(INDEX(Settings!$E$8:$E$15,MATCH(Settings!$C$4,Settings!$B$8:$B$15,0))+INDEX(Settings!$F$8:$F$15,MATCH(Settings!$C$4,Settings!$B$8:$B$15,0))*(1+Settings!$C$26)+N(I11)*Settings!$C$23+INDEX(Settings!$H$8:$H$15,MATCH(Settings!$C$4,Settings!$B$8:$B$15,0))+IF(Settings!$C$25="Yes",0.025,0)+INDEX(Settings!$I$8:$I$15,MATCH(Settings!$C$4,Settings!$B$8:$B$15,0))*(INDEX(Settings!$E$8:$E$15,MATCH(Settings!$C$4,Settings!$B$8:$B$15,0))+N(I11)*Settings!$C$23+INDEX(Settings!$H$8:$H$15,MATCH(Settings!$C$4,Settings!$B$8:$B$15,0))))-Settings!$C$28)-N(D11))))
B12: Printable planner | C12: 6.5 | D12: 0 | E12: 0 | F12: 0 | G12: 0 | H12: 2 | I12: 0 | J12: =IF(B12="","",(N(C12)+N(D12))) | K12: =IF(B12="","",INDEX(Settings!$D$8:$D$15,MATCH(Settings!$C$4,Settings!$B$8:$B$15,0))+INDEX(Settings!$E$8:$E$15,MATCH(Settings!$C$4,Settings!$B$8:$B$15,0))*(N(C12)+N(D12))+INDEX(Settings!$F$8:$F$15,MATCH(Settings!$C$4,Settings!$B$8:$B$15,0))*(N(C12)+N(D12))*(1+Settings!$C$26)+INDEX(Settings!$G$8:$G$15,MATCH(Settings!$C$4,Settings!$B$8:$B$15,0))+N(I12)*MIN(Settings!$C$23*(N(C12)+N(D12)),Settings!$C$24)+INDEX(Settings!$H$8:$H$15,MATCH(Settings!$C$4,Settings!$B$8:$B$15,0))*(N(C12)+N(D12))+IF(Settings!$C$25="Yes",0.025,0)*(N(C12)+N(D12))+INDEX(Settings!$I$8:$I$15,MATCH(Settings!$C$4,Settings!$B$8:$B$15,0))*(INDEX(Settings!$D$8:$D$15,MATCH(Settings!$C$4,Settings!$B$8:$B$15,0))+INDEX(Settings!$E$8:$E$15,MATCH(Settings!$C$4,Settings!$B$8:$B$15,0))*(N(C12)+N(D12))+N(I12)*MIN(Settings!$C$23*(N(C12)+N(D12)),Settings!$C$24)+INDEX(Settings!$H$8:$H$15,MATCH(Settings!$C$4,Settings!$B$8:$B$15,0))*(N(C12)+N(D12)))) | L12: =IF(B12="","",N(E12)+N(F12)+N(G12)+N(H12)/60*Settings!$C$27) | M12: =IF(B12="","",J12-K12-L12) | N12: =IF(OR(B12="",N(J12)=0),"",M12/J12) | O12: =IF(B12="","",IF(M12<0,"Loss",IF(N12<Settings!$C$28,"Below target","On target"))) | P12: =IF(B12="","",IF(1-(INDEX(Settings!$E$8:$E$15,MATCH(Settings!$C$4,Settings!$B$8:$B$15,0))+INDEX(Settings!$F$8:$F$15,MATCH(Settings!$C$4,Settings!$B$8:$B$15,0))*(1+Settings!$C$26)+N(I12)*Settings!$C$23+INDEX(Settings!$H$8:$H$15,MATCH(Settings!$C$4,Settings!$B$8:$B$15,0))+IF(Settings!$C$25="Yes",0.025,0)+INDEX(Settings!$I$8:$I$15,MATCH(Settings!$C$4,Settings!$B$8:$B$15,0))*(INDEX(Settings!$E$8:$E$15,MATCH(Settings!$C$4,Settings!$B$8:$B$15,0))+N(I12)*Settings!$C$23+INDEX(Settings!$H$8:$H$15,MATCH(Settings!$C$4,Settings!$B$8:$B$15,0))))-Settings!$C$28<=0,"Not reachable",MAX(0,(INDEX(Settings!$D$8:$D$15,MATCH(Settings!$C$4,Settings!$B$8:$B$15,0))*(1+INDEX(Settings!$I$8:$I$15,MATCH(Settings!$C$4,Settings!$B$8:$B$15,0)))+INDEX(Settings!$G$8:$G$15,MATCH(Settings!$C$4,Settings!$B$8:$B$15,0))+L12)/(1-(INDEX(Settings!$E$8:$E$15,MATCH(Settings!$C$4,Settings!$B$8:$B$15,0))+INDEX(Settings!$F$8:$F$15,MATCH(Settings!$C$4,Settings!$B$8:$B$15,0))*(1+Settings!$C$26)+N(I12)*Settings!$C$23+INDEX(Settings!$H$8:$H$15,MATCH(Settings!$C$4,Settings!$B$8:$B$15,0))+IF(Settings!$C$25="Yes",0.025,0)+INDEX(Settings!$I$8:$I$15,MATCH(Settings!$C$4,Settings!$B$8:$B$15,0))*(INDEX(Settings!$E$8:$E$15,MATCH(Settings!$C$4,Settings!$B$8:$B$15,0))+N(I12)*Settings!$C$23+INDEX(Settings!$H$8:$H$15,MATCH(Settings!$C$4,Settings!$B$8:$B$15,0))))-Settings!$C$28)-N(D12))))
B13: Ceramic mug | C13: 28 | D13: 6 | E13: 5.5 | F13: 1.5 | G13: 7.8 | H13: 40 | I13: 0.1 | J13: =IF(B13="","",(N(C13)+N(D13))) | K13: =IF(B13="","",INDEX(Settings!$D$8:$D$15,MATCH(Settings!$C$4,Settings!$B$8:$B$15,0))+INDEX(Settings!$E$8:$E$15,MATCH(Settings!$C$4,Settings!$B$8:$B$15,0))*(N(C13)+N(D13))+INDEX(Settings!$F$8:$F$15,MATCH(Settings!$C$4,Settings!$B$8:$B$15,0))*(N(C13)+N(D13))*(1+Settings!$C$26)+INDEX(Settings!$G$8:$G$15,MATCH(Settings!$C$4,Settings!$B$8:$B$15,0))+N(I13)*MIN(Settings!$C$23*(N(C13)+N(D13)),Settings!$C$24)+INDEX(Settings!$H$8:$H$15,MATCH(Settings!$C$4,Settings!$B$8:$B$15,0))*(N(C13)+N(D13))+IF(Settings!$C$25="Yes",0.025,0)*(N(C13)+N(D13))+INDEX(Settings!$I$8:$I$15,MATCH(Settings!$C$4,Settings!$B$8:$B$15,0))*(INDEX(Settings!$D$8:$D$15,MATCH(Settings!$C$4,Settings!$B$8:$B$15,0))+INDEX(Settings!$E$8:$E$15,MATCH(Settings!$C$4,Settings!$B$8:$B$15,0))*(N(C13)+N(D13))+N(I13)*MIN(Settings!$C$23*(N(C13)+N(D13)),Settings!$C$24)+INDEX(Settings!$H$8:$H$15,MATCH(Settings!$C$4,Settings!$B$8:$B$15,0))*(N(C13)+N(D13)))) | L13: =IF(B13="","",N(E13)+N(F13)+N(G13)+N(H13)/60*Settings!$C$27) | M13: =IF(B13="","",J13-K13-L13) | N13: =IF(OR(B13="",N(J13)=0),"",M13/J13) | O13: =IF(B13="","",IF(M13<0,"Loss",IF(N13<Settings!$C$28,"Below target","On target"))) | P13: =IF(B13="","",IF(1-(INDEX(Settings!$E$8:$E$15,MATCH(Settings!$C$4,Settings!$B$8:$B$15,0))+INDEX(Settings!$F$8:$F$15,MATCH(Settings!$C$4,Settings!$B$8:$B$15,0))*(1+Settings!$C$26)+N(I13)*Settings!$C$23+INDEX(Settings!$H$8:$H$15,MATCH(Settings!$C$4,Settings!$B$8:$B$15,0))+IF(Settings!$C$25="Yes",0.025,0)+INDEX(Settings!$I$8:$I$15,MATCH(Settings!$C$4,Settings!$B$8:$B$15,0))*(INDEX(Settings!$E$8:$E$15,MATCH(Settings!$C$4,Settings!$B$8:$B$15,0))+N(I13)*Settings!$C$23+INDEX(Settings!$H$8:$H$15,MATCH(Settings!$C$4,Settings!$B$8:$B$15,0))))-Settings!$C$28<=0,"Not reachable",MAX(0,(INDEX(Settings!$D$8:$D$15,MATCH(Settings!$C$4,Settings!$B$8:$B$15,0))*(1+INDEX(Settings!$I$8:$I$15,MATCH(Settings!$C$4,Settings!$B$8:$B$15,0)))+INDEX(Settings!$G$8:$G$15,MATCH(Settings!$C$4,Settings!$B$8:$B$15,0))+L13)/(1-(INDEX(Settings!$E$8:$E$15,MATCH(Settings!$C$4,Settings!$B$8:$B$15,0))+INDEX(Settings!$F$8:$F$15,MATCH(Settings!$C$4,Settings!$B$8:$B$15,0))*(1+Settings!$C$26)+N(I13)*Settings!$C$23+INDEX(Settings!$H$8:$H$15,MATCH(Settings!$C$4,Settings!$B$8:$B$15,0))+IF(Settings!$C$25="Yes",0.025,0)+INDEX(Settings!$I$8:$I$15,MATCH(Settings!$C$4,Settings!$B$8:$B$15,0))*(INDEX(Settings!$E$8:$E$15,MATCH(Settings!$C$4,Settings!$B$8:$B$15,0))+N(I13)*Settings!$C$23+INDEX(Settings!$H$8:$H$15,MATCH(Settings!$C$4,Settings!$B$8:$B$15,0))))-Settings!$C$28)-N(D13))))
B14: Sticker sheet | C14: 4.5 | D14: 1.2 | E14: 0.6 | F14: 0.2 | G14: 0.7 | H14: 3 | I14: 0 | J14: =IF(B14="","",(N(C14)+N(D14))) | K14: =IF(B14="","",INDEX(Settings!$D$8:$D$15,MATCH(Settings!$C$4,Settings!$B$8:$B$15,0))+INDEX(Settings!$E$8:$E$15,MATCH(Settings!$C$4,Settings!$B$8:$B$15,0))*(N(C14)+N(D14))+INDEX(Settings!$F$8:$F$15,MATCH(Settings!$C$4,Settings!$B$8:$B$15,0))*(N(C14)+N(D14))*(1+Settings!$C$26)+INDEX(Settings!$G$8:$G$15,MATCH(Settings!$C$4,Settings!$B$8:$B$15,0))+N(I14)*MIN(Settings!$C$23*(N(C14)+N(D14)),Settings!$C$24)+INDEX(Settings!$H$8:$H$15,MATCH(Settings!$C$4,Settings!$B$8:$B$15,0))*(N(C14)+N(D14))+IF(Settings!$C$25="Yes",0.025,0)*(N(C14)+N(D14))+INDEX(Settings!$I$8:$I$15,MATCH(Settings!$C$4,Settings!$B$8:$B$15,0))*(INDEX(Settings!$D$8:$D$15,MATCH(Settings!$C$4,Settings!$B$8:$B$15,0))+INDEX(Settings!$E$8:$E$15,MATCH(Settings!$C$4,Settings!$B$8:$B$15,0))*(N(C14)+N(D14))+N(I14)*MIN(Settings!$C$23*(N(C14)+N(D14)),Settings!$C$24)+INDEX(Settings!$H$8:$H$15,MATCH(Settings!$C$4,Settings!$B$8:$B$15,0))*(N(C14)+N(D14)))) | L14: =IF(B14="","",N(E14)+N(F14)+N(G14)+N(H14)/60*Settings!$C$27) | M14: =IF(B14="","",J14-K14-L14) | N14: =IF(OR(B14="",N(J14)=0),"",M14/J14) | O14: =IF(B14="","",IF(M14<0,"Loss",IF(N14<Settings!$C$28,"Below target","On target"))) | P14: =IF(B14="","",IF(1-(INDEX(Settings!$E$8:$E$15,MATCH(Settings!$C$4,Settings!$B$8:$B$15,0))+INDEX(Settings!$F$8:$F$15,MATCH(Settings!$C$4,Settings!$B$8:$B$15,0))*(1+Settings!$C$26)+N(I14)*Settings!$C$23+INDEX(Settings!$H$8:$H$15,MATCH(Settings!$C$4,Settings!$B$8:$B$15,0))+IF(Settings!$C$25="Yes",0.025,0)+INDEX(Settings!$I$8:$I$15,MATCH(Settings!$C$4,Settings!$B$8:$B$15,0))*(INDEX(Settings!$E$8:$E$15,MATCH(Settings!$C$4,Settings!$B$8:$B$15,0))+N(I14)*Settings!$C$23+INDEX(Settings!$H$8:$H$15,MATCH(Settings!$C$4,Settings!$B$8:$B$15,0))))-Settings!$C$28<=0,"Not reachable",MAX(0,(INDEX(Settings!$D$8:$D$15,MATCH(Settings!$C$4,Settings!$B$8:$B$15,0))*(1+INDEX(Settings!$I$8:$I$15,MATCH(Settings!$C$4,Settings!$B$8:$B$15,0)))+INDEX(Settings!$G$8:$G$15,MATCH(Settings!$C$4,Settings!$B$8:$B$15,0))+L14)/(1-(INDEX(Settings!$E$8:$E$15,MATCH(Settings!$C$4,Settings!$B$8:$B$15,0))+INDEX(Settings!$F$8:$F$15,MATCH(Settings!$C$4,Settings!$B$8:$B$15,0))*(1+Settings!$C$26)+N(I14)*Settings!$C$23+INDEX(Settings!$H$8:$H$15,MATCH(Settings!$C$4,Settings!$B$8:$B$15,0))+IF(Settings!$C$25="Yes",0.025,0)+INDEX(Settings!$I$8:$I$15,MATCH(Settings!$C$4,Settings!$B$8:$B$15,0))*(INDEX(Settings!$E$8:$E$15,MATCH(Settings!$C$4,Settings!$B$8:$B$15,0))+N(I14)*Settings!$C$23+INDEX(Settings!$H$8:$H$15,MATCH(Settings!$C$4,Settings!$B$8:$B$15,0))))-Settings!$C$28)-N(D14))))
B15: Leather wallet | C15: 55 | D15: 5 | E15: 14 | F15: 1.2 | G15: 4.5 | H15: 75 | I15: 0.2 | J15: =IF(B15="","",(N(C15)+N(D15))) | K15: =IF(B15="","",INDEX(Settings!$D$8:$D$15,MATCH(Settings!$C$4,Settings!$B$8:$B$15,0))+INDEX(Settings!$E$8:$E$15,MATCH(Settings!$C$4,Settings!$B$8:$B$15,0))*(N(C15)+N(D15))+INDEX(Settings!$F$8:$F$15,MATCH(Settings!$C$4,Settings!$B$8:$B$15,0))*(N(C15)+N(D15))*(1+Settings!$C$26)+INDEX(Settings!$G$8:$G$15,MATCH(Settings!$C$4,Settings!$B$8:$B$15,0))+N(I15)*MIN(Settings!$C$23*(N(C15)+N(D15)),Settings!$C$24)+INDEX(Settings!$H$8:$H$15,MATCH(Settings!$C$4,Settings!$B$8:$B$15,0))*(N(C15)+N(D15))+IF(Settings!$C$25="Yes",0.025,0)*(N(C15)+N(D15))+INDEX(Settings!$I$8:$I$15,MATCH(Settings!$C$4,Settings!$B$8:$B$15,0))*(INDEX(Settings!$D$8:$D$15,MATCH(Settings!$C$4,Settings!$B$8:$B$15,0))+INDEX(Settings!$E$8:$E$15,MATCH(Settings!$C$4,Settings!$B$8:$B$15,0))*(N(C15)+N(D15))+N(I15)*MIN(Settings!$C$23*(N(C15)+N(D15)),Settings!$C$24)+INDEX(Settings!$H$8:$H$15,MATCH(Settings!$C$4,Settings!$B$8:$B$15,0))*(N(C15)+N(D15)))) | L15: =IF(B15="","",N(E15)+N(F15)+N(G15)+N(H15)/60*Settings!$C$27) | M15: =IF(B15="","",J15-K15-L15) | N15: =IF(OR(B15="",N(J15)=0),"",M15/J15) | O15: =IF(B15="","",IF(M15<0,"Loss",IF(N15<Settings!$C$28,"Below target","On target"))) | P15: =IF(B15="","",IF(1-(INDEX(Settings!$E$8:$E$15,MATCH(Settings!$C$4,Settings!$B$8:$B$15,0))+INDEX(Settings!$F$8:$F$15,MATCH(Settings!$C$4,Settings!$B$8:$B$15,0))*(1+Settings!$C$26)+N(I15)*Settings!$C$23+INDEX(Settings!$H$8:$H$15,MATCH(Settings!$C$4,Settings!$B$8:$B$15,0))+IF(Settings!$C$25="Yes",0.025,0)+INDEX(Settings!$I$8:$I$15,MATCH(Settings!$C$4,Settings!$B$8:$B$15,0))*(INDEX(Settings!$E$8:$E$15,MATCH(Settings!$C$4,Settings!$B$8:$B$15,0))+N(I15)*Settings!$C$23+INDEX(Settings!$H$8:$H$15,MATCH(Settings!$C$4,Settings!$B$8:$B$15,0))))-Settings!$C$28<=0,"Not reachable",MAX(0,(INDEX(Settings!$D$8:$D$15,MATCH(Settings!$C$4,Settings!$B$8:$B$15,0))*(1+INDEX(Settings!$I$8:$I$15,MATCH(Settings!$C$4,Settings!$B$8:$B$15,0)))+INDEX(Settings!$G$8:$G$15,MATCH(Settings!$C$4,Settings!$B$8:$B$15,0))+L15)/(1-(INDEX(Settings!$E$8:$E$15,MATCH(Settings!$C$4,Settings!$B$8:$B$15,0))+INDEX(Settings!$F$8:$F$15,MATCH(Settings!$C$4,Settings!$B$8:$B$15,0))*(1+Settings!$C$26)+N(I15)*Settings!$C$23+INDEX(Settings!$H$8:$H$15,MATCH(Settings!$C$4,Settings!$B$8:$B$15,0))+IF(Settings!$C$25="Yes",0.025,0)+INDEX(Settings!$I$8:$I$15,MATCH(Settings!$C$4,Settings!$B$8:$B$15,0))*(INDEX(Settings!$E$8:$E$15,MATCH(Settings!$C$4,Settings!$B$8:$B$15,0))+N(I15)*Settings!$C$23+INDEX(Settings!$H$8:$H$15,MATCH(Settings!$C$4,Settings!$B$8:$B$15,0))))-Settings!$C$28)-N(D15))))
J16: =IF(B16="","",(N(C16)+N(D16))) | K16: =IF(B16="","",INDEX(Settings!$D$8:$D$15,MATCH(Settings!$C$4,Settings!$B$8:$B$15,0))+INDEX(Settings!$E$8:$E$15,MATCH(Settings!$C$4,Settings!$B$8:$B$15,0))*(N(C16)+N(D16))+INDEX(Settings!$F$8:$F$15,MATCH(Settings!$C$4,Settings!$B$8:$B$15,0))*(N(C16)+N(D16))*(1+Settings!$C$26)+INDEX(Settings!$G$8:$G$15,MATCH(Settings!$C$4,Settings!$B$8:$B$15,0))+N(I16)*MIN(Settings!$C$23*(N(C16)+N(D16)),Settings!$C$24)+INDEX(Settings!$H$8:$H$15,MATCH(Settings!$C$4,Settings!$B$8:$B$15,0))*(N(C16)+N(D16))+IF(Settings!$C$25="Yes",0.025,0)*(N(C16)+N(D16))+INDEX(Settings!$I$8:$I$15,MATCH(Settings!$C$4,Settings!$B$8:$B$15,0))*(INDEX(Settings!$D$8:$D$15,MATCH(Settings!$C$4,Settings!$B$8:$B$15,0))+INDEX(Settings!$E$8:$E$15,MATCH(Settings!$C$4,Settings!$B$8:$B$15,0))*(N(C16)+N(D16))+N(I16)*MIN(Settings!$C$23*(N(C16)+N(D16)),Settings!$C$24)+INDEX(Settings!$H$8:$H$15,MATCH(Settings!$C$4,Settings!$B$8:$B$15,0))*(N(C16)+N(D16)))) | L16: =IF(B16="","",N(E16)+N(F16)+N(G16)+N(H16)/60*Settings!$C$27) | M16: =IF(B16="","",J16-K16-L16) | N16: =IF(OR(B16="",N(J16)=0),"",M16/J16) | O16: =IF(B16="","",IF(M16<0,"Loss",IF(N16<Settings!$C$28,"Below target","On target"))) | P16: =IF(B16="","",IF(1-(INDEX(Settings!$E$8:$E$15,MATCH(Settings!$C$4,Settings!$B$8:$B$15,0))+INDEX(Settings!$F$8:$F$15,MATCH(Settings!$C$4,Settings!$B$8:$B$15,0))*(1+Settings!$C$26)+N(I16)*Settings!$C$23+INDEX(Settings!$H$8:$H$15,MATCH(Settings!$C$4,Settings!$B$8:$B$15,0))+IF(Settings!$C$25="Yes",0.025,0)+INDEX(Settings!$I$8:$I$15,MATCH(Settings!$C$4,Settings!$B$8:$B$15,0))*(INDEX(Settings!$E$8:$E$15,MATCH(Settings!$C$4,Settings!$B$8:$B$15,0))+N(I16)*Settings!$C$23+INDEX(Settings!$H$8:$H$15,MATCH(Settings!$C$4,Settings!$B$8:$B$15,0))))-Settings!$C$28<=0,"Not reachable",MAX(0,(INDEX(Settings!$D$8:$D$15,MATCH(Settings!$C$4,Settings!$B$8:$B$15,0))*(1+INDEX(Settings!$I$8:$I$15,MATCH(Settings!$C$4,Settings!$B$8:$B$15,0)))+INDEX(Settings!$G$8:$G$15,MATCH(Settings!$C$4,Settings!$B$8:$B$15,0))+L16)/(1-(INDEX(Settings!$E$8:$E$15,MATCH(Settings!$C$4,Settings!$B$8:$B$15,0))+INDEX(Settings!$F$8:$F$15,MATCH(Settings!$C$4,Settings!$B$8:$B$15,0))*(1+Settings!$C$26)+N(I16)*Settings!$C$23+INDEX(Settings!$H$8:$H$15,MATCH(Settings!$C$4,Settings!$B$8:$B$15,0))+IF(Settings!$C$25="Yes",0.025,0)+INDEX(Settings!$I$8:$I$15,MATCH(Settings!$C$4,Settings!$B$8:$B$15,0))*(INDEX(Settings!$E$8:$E$15,MATCH(Settings!$C$4,Settings!$B$8:$B$15,0))+N(I16)*Settings!$C$23+INDEX(Settings!$H$8:$H$15,MATCH(Settings!$C$4,Settings!$B$8:$B$15,0))))-Settings!$C$28)-N(D16))))
J17: =IF(B17="","",(N(C17)+N(D17))) | K17: =IF(B17="","",INDEX(Settings!$D$8:$D$15,MATCH(Settings!$C$4,Settings!$B$8:$B$15,0))+INDEX(Settings!$E$8:$E$15,MATCH(Settings!$C$4,Settings!$B$8:$B$15,0))*(N(C17)+N(D17))+INDEX(Settings!$F$8:$F$15,MATCH(Settings!$C$4,Settings!$B$8:$B$15,0))*(N(C17)+N(D17))*(1+Settings!$C$26)+INDEX(Settings!$G$8:$G$15,MATCH(Settings!$C$4,Settings!$B$8:$B$15,0))+N(I17)*MIN(Settings!$C$23*(N(C17)+N(D17)),Settings!$C$24)+INDEX(Settings!$H$8:$H$15,MATCH(Settings!$C$4,Settings!$B$8:$B$15,0))*(N(C17)+N(D17))+IF(Settings!$C$25="Yes",0.025,0)*(N(C17)+N(D17))+INDEX(Settings!$I$8:$I$15,MATCH(Settings!$C$4,Settings!$B$8:$B$15,0))*(INDEX(Settings!$D$8:$D$15,MATCH(Settings!$C$4,Settings!$B$8:$B$15,0))+INDEX(Settings!$E$8:$E$15,MATCH(Settings!$C$4,Settings!$B$8:$B$15,0))*(N(C17)+N(D17))+N(I17)*MIN(Settings!$C$23*(N(C17)+N(D17)),Settings!$C$24)+INDEX(Settings!$H$8:$H$15,MATCH(Settings!$C$4,Settings!$B$8:$B$15,0))*(N(C17)+N(D17)))) | L17: =IF(B17="","",N(E17)+N(F17)+N(G17)+N(H17)/60*Settings!$C$27) | M17: =IF(B17="","",J17-K17-L17) | N17: =IF(OR(B17="",N(J17)=0),"",M17/J17) | O17: =IF(B17="","",IF(M17<0,"Loss",IF(N17<Settings!$C$28,"Below target","On target"))) | P17: =IF(B17="","",IF(1-(INDEX(Settings!$E$8:$E$15,MATCH(Settings!$C$4,Settings!$B$8:$B$15,0))+INDEX(Settings!$F$8:$F$15,MATCH(Settings!$C$4,Settings!$B$8:$B$15,0))*(1+Settings!$C$26)+N(I17)*Settings!$C$23+INDEX(Settings!$H$8:$H$15,MATCH(Settings!$C$4,Settings!$B$8:$B$15,0))+IF(Settings!$C$25="Yes",0.025,0)+INDEX(Settings!$I$8:$I$15,MATCH(Settings!$C$4,Settings!$B$8:$B$15,0))*(INDEX(Settings!$E$8:$E$15,MATCH(Settings!$C$4,Settings!$B$8:$B$15,0))+N(I17)*Settings!$C$23+INDEX(Settings!$H$8:$H$15,MATCH(Settings!$C$4,Settings!$B$8:$B$15,0))))-Settings!$C$28<=0,"Not reachable",MAX(0,(INDEX(Settings!$D$8:$D$15,MATCH(Settings!$C$4,Settings!$B$8:$B$15,0))*(1+INDEX(Settings!$I$8:$I$15,MATCH(Settings!$C$4,Settings!$B$8:$B$15,0)))+INDEX(Settings!$G$8:$G$15,MATCH(Settings!$C$4,Settings!$B$8:$B$15,0))+L17)/(1-(INDEX(Settings!$E$8:$E$15,MATCH(Settings!$C$4,Settings!$B$8:$B$15,0))+INDEX(Settings!$F$8:$F$15,MATCH(Settings!$C$4,Settings!$B$8:$B$15,0))*(1+Settings!$C$26)+N(I17)*Settings!$C$23+INDEX(Settings!$H$8:$H$15,MATCH(Settings!$C$4,Settings!$B$8:$B$15,0))+IF(Settings!$C$25="Yes",0.025,0)+INDEX(Settings!$I$8:$I$15,MATCH(Settings!$C$4,Settings!$B$8:$B$15,0))*(INDEX(Settings!$E$8:$E$15,MATCH(Settings!$C$4,Settings!$B$8:$B$15,0))+N(I17)*Settings!$C$23+INDEX(Settings!$H$8:$H$15,MATCH(Settings!$C$4,Settings!$B$8:$B$15,0))))-Settings!$C$28)-N(D17))))
J18: =IF(B18="","",(N(C18)+N(D18))) | K18: =IF(B18="","",INDEX(Settings!$D$8:$D$15,MATCH(Settings!$C$4,Settings!$B$8:$B$15,0))+INDEX(Settings!$E$8:$E$15,MATCH(Settings!$C$4,Settings!$B$8:$B$15,0))*(N(C18)+N(D18))+INDEX(Settings!$F$8:$F$15,MATCH(Settings!$C$4,Settings!$B$8:$B$15,0))*(N(C18)+N(D18))*(1+Settings!$C$26)+INDEX(Settings!$G$8:$G$15,MATCH(Settings!$C$4,Settings!$B$8:$B$15,0))+N(I18)*MIN(Settings!$C$23*(N(C18)+N(D18)),Settings!$C$24)+INDEX(Settings!$H$8:$H$15,MATCH(Settings!$C$4,Settings!$B$8:$B$15,0))*(N(C18)+N(D18))+IF(Settings!$C$25="Yes",0.025,0)*(N(C18)+N(D18))+INDEX(Settings!$I$8:$I$15,MATCH(Settings!$C$4,Settings!$B$8:$B$15,0))*(INDEX(Settings!$D$8:$D$15,MATCH(Settings!$C$4,Settings!$B$8:$B$15,0))+INDEX(Settings!$E$8:$E$15,MATCH(Settings!$C$4,Settings!$B$8:$B$15,0))*(N(C18)+N(D18))+N(I18)*MIN(Settings!$C$23*(N(C18)+N(D18)),Settings!$C$24)+INDEX(Settings!$H$8:$H$15,MATCH(Settings!$C$4,Settings!$B$8:$B$15,0))*(N(C18)+N(D18)))) | L18: =IF(B18="","",N(E18)+N(F18)+N(G18)+N(H18)/60*Settings!$C$27) | M18: =IF(B18="","",J18-K18-L18) | N18: =IF(OR(B18="",N(J18)=0),"",M18/J18) | O18: =IF(B18="","",IF(M18<0,"Loss",IF(N18<Settings!$C$28,"Below target","On target"))) | P18: =IF(B18="","",IF(1-(INDEX(Settings!$E$8:$E$15,MATCH(Settings!$C$4,Settings!$B$8:$B$15,0))+INDEX(Settings!$F$8:$F$15,MATCH(Settings!$C$4,Settings!$B$8:$B$15,0))*(1+Settings!$C$26)+N(I18)*Settings!$C$23+INDEX(Settings!$H$8:$H$15,MATCH(Settings!$C$4,Settings!$B$8:$B$15,0))+IF(Settings!$C$25="Yes",0.025,0)+INDEX(Settings!$I$8:$I$15,MATCH(Settings!$C$4,Settings!$B$8:$B$15,0))*(INDEX(Settings!$E$8:$E$15,MATCH(Settings!$C$4,Settings!$B$8:$B$15,0))+N(I18)*Settings!$C$23+INDEX(Settings!$H$8:$H$15,MATCH(Settings!$C$4,Settings!$B$8:$B$15,0))))-Settings!$C$28<=0,"Not reachable",MAX(0,(INDEX(Settings!$D$8:$D$15,MATCH(Settings!$C$4,Settings!$B$8:$B$15,0))*(1+INDEX(Settings!$I$8:$I$15,MATCH(Settings!$C$4,Settings!$B$8:$B$15,0)))+INDEX(Settings!$G$8:$G$15,MATCH(Settings!$C$4,Settings!$B$8:$B$15,0))+L18)/(1-(INDEX(Settings!$E$8:$E$15,MATCH(Settings!$C$4,Settings!$B$8:$B$15,0))+INDEX(Settings!$F$8:$F$15,MATCH(Settings!$C$4,Settings!$B$8:$B$15,0))*(1+Settings!$C$26)+N(I18)*Settings!$C$23+INDEX(Settings!$H$8:$H$15,MATCH(Settings!$C$4,Settings!$B$8:$B$15,0))+IF(Settings!$C$25="Yes",0.025,0)+INDEX(Settings!$I$8:$I$15,MATCH(Settings!$C$4,Settings!$B$8:$B$15,0))*(INDEX(Settings!$E$8:$E$15,MATCH(Settings!$C$4,Settings!$B$8:$B$15,0))+N(I18)*Settings!$C$23+INDEX(Settings!$H$8:$H$15,MATCH(Settings!$C$4,Settings!$B$8:$B$15,0))))-Settings!$C$28)-N(D18))))
J19: =IF(B19="","",(N(C19)+N(D19))) | K19: =IF(B19="","",INDEX(Settings!$D$8:$D$15,MATCH(Settings!$C$4,Settings!$B$8:$B$15,0))+INDEX(Settings!$E$8:$E$15,MATCH(Settings!$C$4,Settings!$B$8:$B$15,0))*(N(C19)+N(D19))+INDEX(Settings!$F$8:$F$15,MATCH(Settings!$C$4,Settings!$B$8:$B$15,0))*(N(C19)+N(D19))*(1+Settings!$C$26)+INDEX(Settings!$G$8:$G$15,MATCH(Settings!$C$4,Settings!$B$8:$B$15,0))+N(I19)*MIN(Settings!$C$23*(N(C19)+N(D19)),Settings!$C$24)+INDEX(Settings!$H$8:$H$15,MATCH(Settings!$C$4,Settings!$B$8:$B$15,0))*(N(C19)+N(D19))+IF(Settings!$C$25="Yes",0.025,0)*(N(C19)+N(D19))+INDEX(Settings!$I$8:$I$15,MATCH(Settings!$C$4,Settings!$B$8:$B$15,0))*(INDEX(Settings!$D$8:$D$15,MATCH(Settings!$C$4,Settings!$B$8:$B$15,0))+INDEX(Settings!$E$8:$E$15,MATCH(Settings!$C$4,Settings!$B$8:$B$15,0))*(N(C19)+N(D19))+N(I19)*MIN(Settings!$C$23*(N(C19)+N(D19)),Settings!$C$24)+INDEX(Settings!$H$8:$H$15,MATCH(Settings!$C$4,Settings!$B$8:$B$15,0))*(N(C19)+N(D19)))) | L19: =IF(B19="","",N(E19)+N(F19)+N(G19)+N(H19)/60*Settings!$C$27) | M19: =IF(B19="","",J19-K19-L19) | N19: =IF(OR(B19="",N(J19)=0),"",M19/J19) | O19: =IF(B19="","",IF(M19<0,"Loss",IF(N19<Settings!$C$28,"Below target","On target"))) | P19: =IF(B19="","",IF(1-(INDEX(Settings!$E$8:$E$15,MATCH(Settings!$C$4,Settings!$B$8:$B$15,0))+INDEX(Settings!$F$8:$F$15,MATCH(Settings!$C$4,Settings!$B$8:$B$15,0))*(1+Settings!$C$26)+N(I19)*Settings!$C$23+INDEX(Settings!$H$8:$H$15,MATCH(Settings!$C$4,Settings!$B$8:$B$15,0))+IF(Settings!$C$25="Yes",0.025,0)+INDEX(Settings!$I$8:$I$15,MATCH(Settings!$C$4,Settings!$B$8:$B$15,0))*(INDEX(Settings!$E$8:$E$15,MATCH(Settings!$C$4,Settings!$B$8:$B$15,0))+N(I19)*Settings!$C$23+INDEX(Settings!$H$8:$H$15,MATCH(Settings!$C$4,Settings!$B$8:$B$15,0))))-Settings!$C$28<=0,"Not reachable",MAX(0,(INDEX(Settings!$D$8:$D$15,MATCH(Settings!$C$4,Settings!$B$8:$B$15,0))*(1+INDEX(Settings!$I$8:$I$15,MATCH(Settings!$C$4,Settings!$B$8:$B$15,0)))+INDEX(Settings!$G$8:$G$15,MATCH(Settings!$C$4,Settings!$B$8:$B$15,0))+L19)/(1-(INDEX(Settings!$E$8:$E$15,MATCH(Settings!$C$4,Settings!$B$8:$B$15,0))+INDEX(Settings!$F$8:$F$15,MATCH(Settings!$C$4,Settings!$B$8:$B$15,0))*(1+Settings!$C$26)+N(I19)*Settings!$C$23+INDEX(Settings!$H$8:$H$15,MATCH(Settings!$C$4,Settings!$B$8:$B$15,0))+IF(Settings!$C$25="Yes",0.025,0)+INDEX(Settings!$I$8:$I$15,MATCH(Settings!$C$4,Settings!$B$8:$B$15,0))*(INDEX(Settings!$E$8:$E$15,MATCH(Settings!$C$4,Settings!$B$8:$B$15,0))+N(I19)*Settings!$C$23+INDEX(Settings!$H$8:$H$15,MATCH(Settings!$C$4,Settings!$B$8:$B$15,0))))-Settings!$C$28)-N(D19))))
J20: =IF(B20="","",(N(C20)+N(D20))) | K20: =IF(B20="","",INDEX(Settings!$D$8:$D$15,MATCH(Settings!$C$4,Settings!$B$8:$B$15,0))+INDEX(Settings!$E$8:$E$15,MATCH(Settings!$C$4,Settings!$B$8:$B$15,0))*(N(C20)+N(D20))+INDEX(Settings!$F$8:$F$15,MATCH(Settings!$C$4,Settings!$B$8:$B$15,0))*(N(C20)+N(D20))*(1+Settings!$C$26)+INDEX(Settings!$G$8:$G$15,MATCH(Settings!$C$4,Settings!$B$8:$B$15,0))+N(I20)*MIN(Settings!$C$23*(N(C20)+N(D20)),Settings!$C$24)+INDEX(Settings!$H$8:$H$15,MATCH(Settings!$C$4,Settings!$B$8:$B$15,0))*(N(C20)+N(D20))+IF(Settings!$C$25="Yes",0.025,0)*(N(C20)+N(D20))+INDEX(Settings!$I$8:$I$15,MATCH(Settings!$C$4,Settings!$B$8:$B$15,0))*(INDEX(Settings!$D$8:$D$15,MATCH(Settings!$C$4,Settings!$B$8:$B$15,0))+INDEX(Settings!$E$8:$E$15,MATCH(Settings!$C$4,Settings!$B$8:$B$15,0))*(N(C20)+N(D20))+N(I20)*MIN(Settings!$C$23*(N(C20)+N(D20)),Settings!$C$24)+INDEX(Settings!$H$8:$H$15,MATCH(Settings!$C$4,Settings!$B$8:$B$15,0))*(N(C20)+N(D20)))) | L20: =IF(B20="","",N(E20)+N(F20)+N(G20)+N(H20)/60*Settings!$C$27) | M20: =IF(B20="","",J20-K20-L20) | N20: =IF(OR(B20="",N(J20)=0),"",M20/J20) | O20: =IF(B20="","",IF(M20<0,"Loss",IF(N20<Settings!$C$28,"Below target","On target"))) | P20: =IF(B20="","",IF(1-(INDEX(Settings!$E$8:$E$15,MATCH(Settings!$C$4,Settings!$B$8:$B$15,0))+INDEX(Settings!$F$8:$F$15,MATCH(Settings!$C$4,Settings!$B$8:$B$15,0))*(1+Settings!$C$26)+N(I20)*Settings!$C$23+INDEX(Settings!$H$8:$H$15,MATCH(Settings!$C$4,Settings!$B$8:$B$15,0))+IF(Settings!$C$25="Yes",0.025,0)+INDEX(Settings!$I$8:$I$15,MATCH(Settings!$C$4,Settings!$B$8:$B$15,0))*(INDEX(Settings!$E$8:$E$15,MATCH(Settings!$C$4,Settings!$B$8:$B$15,0))+N(I20)*Settings!$C$23+INDEX(Settings!$H$8:$H$15,MATCH(Settings!$C$4,Settings!$B$8:$B$15,0))))-Settings!$C$28<=0,"Not reachable",MAX(0,(INDEX(Settings!$D$8:$D$15,MATCH(Settings!$C$4,Settings!$B$8:$B$15,0))*(1+INDEX(Settings!$I$8:$I$15,MATCH(Settings!$C$4,Settings!$B$8:$B$15,0)))+INDEX(Settings!$G$8:$G$15,MATCH(Settings!$C$4,Settings!$B$8:$B$15,0))+L20)/(1-(INDEX(Settings!$E$8:$E$15,MATCH(Settings!$C$4,Settings!$B$8:$B$15,0))+INDEX(Settings!$F$8:$F$15,MATCH(Settings!$C$4,Settings!$B$8:$B$15,0))*(1+Settings!$C$26)+N(I20)*Settings!$C$23+INDEX(Settings!$H$8:$H$15,MATCH(Settings!$C$4,Settings!$B$8:$B$15,0))+IF(Settings!$C$25="Yes",0.025,0)+INDEX(Settings!$I$8:$I$15,MATCH(Settings!$C$4,Settings!$B$8:$B$15,0))*(INDEX(Settings!$E$8:$E$15,MATCH(Settings!$C$4,Settings!$B$8:$B$15,0))+N(I20)*Settings!$C$23+INDEX(Settings!$H$8:$H$15,MATCH(Settings!$C$4,Settings!$B$8:$B$15,0))))-Settings!$C$28)-N(D20))))
J21: =IF(B21="","",(N(C21)+N(D21))) | K21: =IF(B21="","",INDEX(Settings!$D$8:$D$15,MATCH(Settings!$C$4,Settings!$B$8:$B$15,0))+INDEX(Settings!$E$8:$E$15,MATCH(Settings!$C$4,Settings!$B$8:$B$15,0))*(N(C21)+N(D21))+INDEX(Settings!$F$8:$F$15,MATCH(Settings!$C$4,Settings!$B$8:$B$15,0))*(N(C21)+N(D21))*(1+Settings!$C$26)+INDEX(Settings!$G$8:$G$15,MATCH(Settings!$C$4,Settings!$B$8:$B$15,0))+N(I21)*MIN(Settings!$C$23*(N(C21)+N(D21)),Settings!$C$24)+INDEX(Settings!$H$8:$H$15,MATCH(Settings!$C$4,Settings!$B$8:$B$15,0))*(N(C21)+N(D21))+IF(Settings!$C$25="Yes",0.025,0)*(N(C21)+N(D21))+INDEX(Settings!$I$8:$I$15,MATCH(Settings!$C$4,Settings!$B$8:$B$15,0))*(INDEX(Settings!$D$8:$D$15,MATCH(Settings!$C$4,Settings!$B$8:$B$15,0))+INDEX(Settings!$E$8:$E$15,MATCH(Settings!$C$4,Settings!$B$8:$B$15,0))*(N(C21)+N(D21))+N(I21)*MIN(Settings!$C$23*(N(C21)+N(D21)),Settings!$C$24)+INDEX(Settings!$H$8:$H$15,MATCH(Settings!$C$4,Settings!$B$8:$B$15,0))*(N(C21)+N(D21)))) | L21: =IF(B21="","",N(E21)+N(F21)+N(G21)+N(H21)/60*Settings!$C$27) | M21: =IF(B21="","",J21-K21-L21) | N21: =IF(OR(B21="",N(J21)=0),"",M21/J21) | O21: =IF(B21="","",IF(M21<0,"Loss",IF(N21<Settings!$C$28,"Below target","On target"))) | P21: =IF(B21="","",IF(1-(INDEX(Settings!$E$8:$E$15,MATCH(Settings!$C$4,Settings!$B$8:$B$15,0))+INDEX(Settings!$F$8:$F$15,MATCH(Settings!$C$4,Settings!$B$8:$B$15,0))*(1+Settings!$C$26)+N(I21)*Settings!$C$23+INDEX(Settings!$H$8:$H$15,MATCH(Settings!$C$4,Settings!$B$8:$B$15,0))+IF(Settings!$C$25="Yes",0.025,0)+INDEX(Settings!$I$8:$I$15,MATCH(Settings!$C$4,Settings!$B$8:$B$15,0))*(INDEX(Settings!$E$8:$E$15,MATCH(Settings!$C$4,Settings!$B$8:$B$15,0))+N(I21)*Settings!$C$23+INDEX(Settings!$H$8:$H$15,MATCH(Settings!$C$4,Settings!$B$8:$B$15,0))))-Settings!$C$28<=0,"Not reachable",MAX(0,(INDEX(Settings!$D$8:$D$15,MATCH(Settings!$C$4,Settings!$B$8:$B$15,0))*(1+INDEX(Settings!$I$8:$I$15,MATCH(Settings!$C$4,Settings!$B$8:$B$15,0)))+INDEX(Settings!$G$8:$G$15,MATCH(Settings!$C$4,Settings!$B$8:$B$15,0))+L21)/(1-(INDEX(Settings!$E$8:$E$15,MATCH(Settings!$C$4,Settings!$B$8:$B$15,0))+INDEX(Settings!$F$8:$F$15,MATCH(Settings!$C$4,Settings!$B$8:$B$15,0))*(1+Settings!$C$26)+N(I21)*Settings!$C$23+INDEX(Settings!$H$8:$H$15,MATCH(Settings!$C$4,Settings!$B$8:$B$15,0))+IF(Settings!$C$25="Yes",0.025,0)+INDEX(Settings!$I$8:$I$15,MATCH(Settings!$C$4,Settings!$B$8:$B$15,0))*(INDEX(Settings!$E$8:$E$15,MATCH(Settings!$C$4,Settings!$B$8:$B$15,0))+N(I21)*Settings!$C$23+INDEX(Settings!$H$8:$H$15,MATCH(Settings!$C$4,Settings!$B$8:$B$15,0))))-Settings!$C$28)-N(D21))))
J22: =IF(B22="","",(N(C22)+N(D22))) | K22: =IF(B22="","",INDEX(Settings!$D$8:$D$15,MATCH(Settings!$C$4,Settings!$B$8:$B$15,0))+INDEX(Settings!$E$8:$E$15,MATCH(Settings!$C$4,Settings!$B$8:$B$15,0))*(N(C22)+N(D22))+INDEX(Settings!$F$8:$F$15,MATCH(Settings!$C$4,Settings!$B$8:$B$15,0))*(N(C22)+N(D22))*(1+Settings!$C$26)+INDEX(Settings!$G$8:$G$15,MATCH(Settings!$C$4,Settings!$B$8:$B$15,0))+N(I22)*MIN(Settings!$C$23*(N(C22)+N(D22)),Settings!$C$24)+INDEX(Settings!$H$8:$H$15,MATCH(Settings!$C$4,Settings!$B$8:$B$15,0))*(N(C22)+N(D22))+IF(Settings!$C$25="Yes",0.025,0)*(N(C22)+N(D22))+INDEX(Settings!$I$8:$I$15,MATCH(Settings!$C$4,Settings!$B$8:$B$15,0))*(INDEX(Settings!$D$8:$D$15,MATCH(Settings!$C$4,Settings!$B$8:$B$15,0))+INDEX(Settings!$E$8:$E$15,MATCH(Settings!$C$4,Settings!$B$8:$B$15,0))*(N(C22)+N(D22))+N(I22)*MIN(Settings!$C$23*(N(C22)+N(D22)),Settings!$C$24)+INDEX(Settings!$H$8:$H$15,MATCH(Settings!$C$4,Settings!$B$8:$B$15,0))*(N(C22)+N(D22)))) | L22: =IF(B22="","",N(E22)+N(F22)+N(G22)+N(H22)/60*Settings!$C$27) | M22: =IF(B22="","",J22-K22-L22) | N22: =IF(OR(B22="",N(J22)=0),"",M22/J22) | O22: =IF(B22="","",IF(M22<0,"Loss",IF(N22<Settings!$C$28,"Below target","On target"))) | P22: =IF(B22="","",IF(1-(INDEX(Settings!$E$8:$E$15,MATCH(Settings!$C$4,Settings!$B$8:$B$15,0))+INDEX(Settings!$F$8:$F$15,MATCH(Settings!$C$4,Settings!$B$8:$B$15,0))*(1+Settings!$C$26)+N(I22)*Settings!$C$23+INDEX(Settings!$H$8:$H$15,MATCH(Settings!$C$4,Settings!$B$8:$B$15,0))+IF(Settings!$C$25="Yes",0.025,0)+INDEX(Settings!$I$8:$I$15,MATCH(Settings!$C$4,Settings!$B$8:$B$15,0))*(INDEX(Settings!$E$8:$E$15,MATCH(Settings!$C$4,Settings!$B$8:$B$15,0))+N(I22)*Settings!$C$23+INDEX(Settings!$H$8:$H$15,MATCH(Settings!$C$4,Settings!$B$8:$B$15,0))))-Settings!$C$28<=0,"Not reachable",MAX(0,(INDEX(Settings!$D$8:$D$15,MATCH(Settings!$C$4,Settings!$B$8:$B$15,0))*(1+INDEX(Settings!$I$8:$I$15,MATCH(Settings!$C$4,Settings!$B$8:$B$15,0)))+INDEX(Settings!$G$8:$G$15,MATCH(Settings!$C$4,Settings!$B$8:$B$15,0))+L22)/(1-(INDEX(Settings!$E$8:$E$15,MATCH(Settings!$C$4,Settings!$B$8:$B$15,0))+INDEX(Settings!$F$8:$F$15,MATCH(Settings!$C$4,Settings!$B$8:$B$15,0))*(1+Settings!$C$26)+N(I22)*Settings!$C$23+INDEX(Settings!$H$8:$H$15,MATCH(Settings!$C$4,Settings!$B$8:$B$15,0))+IF(Settings!$C$25="Yes",0.025,0)+INDEX(Settings!$I$8:$I$15,MATCH(Settings!$C$4,Settings!$B$8:$B$15,0))*(INDEX(Settings!$E$8:$E$15,MATCH(Settings!$C$4,Settings!$B$8:$B$15,0))+N(I22)*Settings!$C$23+INDEX(Settings!$H$8:$H$15,MATCH(Settings!$C$4,Settings!$B$8:$B$15,0))))-Settings!$C$28)-N(D22))))
J23: =IF(B23="","",(N(C23)+N(D23))) | K23: =IF(B23="","",INDEX(Settings!$D$8:$D$15,MATCH(Settings!$C$4,Settings!$B$8:$B$15,0))+INDEX(Settings!$E$8:$E$15,MATCH(Settings!$C$4,Settings!$B$8:$B$15,0))*(N(C23)+N(D23))+INDEX(Settings!$F$8:$F$15,MATCH(Settings!$C$4,Settings!$B$8:$B$15,0))*(N(C23)+N(D23))*(1+Settings!$C$26)+INDEX(Settings!$G$8:$G$15,MATCH(Settings!$C$4,Settings!$B$8:$B$15,0))+N(I23)*MIN(Settings!$C$23*(N(C23)+N(D23)),Settings!$C$24)+INDEX(Settings!$H$8:$H$15,MATCH(Settings!$C$4,Settings!$B$8:$B$15,0))*(N(C23)+N(D23))+IF(Settings!$C$25="Yes",0.025,0)*(N(C23)+N(D23))+INDEX(Settings!$I$8:$I$15,MATCH(Settings!$C$4,Settings!$B$8:$B$15,0))*(INDEX(Settings!$D$8:$D$15,MATCH(Settings!$C$4,Settings!$B$8:$B$15,0))+INDEX(Settings!$E$8:$E$15,MATCH(Settings!$C$4,Settings!$B$8:$B$15,0))*(N(C23)+N(D23))+N(I23)*MIN(Settings!$C$23*(N(C23)+N(D23)),Settings!$C$24)+INDEX(Settings!$H$8:$H$15,MATCH(Settings!$C$4,Settings!$B$8:$B$15,0))*(N(C23)+N(D23)))) | L23: =IF(B23="","",N(E23)+N(F23)+N(G23)+N(H23)/60*Settings!$C$27) | M23: =IF(B23="","",J23-K23-L23) | N23: =IF(OR(B23="",N(J23)=0),"",M23/J23) | O23: =IF(B23="","",IF(M23<0,"Loss",IF(N23<Settings!$C$28,"Below target","On target"))) | P23: =IF(B23="","",IF(1-(INDEX(Settings!$E$8:$E$15,MATCH(Settings!$C$4,Settings!$B$8:$B$15,0))+INDEX(Settings!$F$8:$F$15,MATCH(Settings!$C$4,Settings!$B$8:$B$15,0))*(1+Settings!$C$26)+N(I23)*Settings!$C$23+INDEX(Settings!$H$8:$H$15,MATCH(Settings!$C$4,Settings!$B$8:$B$15,0))+IF(Settings!$C$25="Yes",0.025,0)+INDEX(Settings!$I$8:$I$15,MATCH(Settings!$C$4,Settings!$B$8:$B$15,0))*(INDEX(Settings!$E$8:$E$15,MATCH(Settings!$C$4,Settings!$B$8:$B$15,0))+N(I23)*Settings!$C$23+INDEX(Settings!$H$8:$H$15,MATCH(Settings!$C$4,Settings!$B$8:$B$15,0))))-Settings!$C$28<=0,"Not reachable",MAX(0,(INDEX(Settings!$D$8:$D$15,MATCH(Settings!$C$4,Settings!$B$8:$B$15,0))*(1+INDEX(Settings!$I$8:$I$15,MATCH(Settings!$C$4,Settings!$B$8:$B$15,0)))+INDEX(Settings!$G$8:$G$15,MATCH(Settings!$C$4,Settings!$B$8:$B$15,0))+L23)/(1-(INDEX(Settings!$E$8:$E$15,MATCH(Settings!$C$4,Settings!$B$8:$B$15,0))+INDEX(Settings!$F$8:$F$15,MATCH(Settings!$C$4,Settings!$B$8:$B$15,0))*(1+Settings!$C$26)+N(I23)*Settings!$C$23+INDEX(Settings!$H$8:$H$15,MATCH(Settings!$C$4,Settings!$B$8:$B$15,0))+IF(Settings!$C$25="Yes",0.025,0)+INDEX(Settings!$I$8:$I$15,MATCH(Settings!$C$4,Settings!$B$8:$B$15,0))*(INDEX(Settings!$E$8:$E$15,MATCH(Settings!$C$4,Settings!$B$8:$B$15,0))+N(I23)*Settings!$C$23+INDEX(Settings!$H$8:$H$15,MATCH(Settings!$C$4,Settings!$B$8:$B$15,0))))-Settings!$C$28)-N(D23))))
J24: =IF(B24="","",(N(C24)+N(D24))) | K24: =IF(B24="","",INDEX(Settings!$D$8:$D$15,MATCH(Settings!$C$4,Settings!$B$8:$B$15,0))+INDEX(Settings!$E$8:$E$15,MATCH(Settings!$C$4,Settings!$B$8:$B$15,0))*(N(C24)+N(D24))+INDEX(Settings!$F$8:$F$15,MATCH(Settings!$C$4,Settings!$B$8:$B$15,0))*(N(C24)+N(D24))*(1+Settings!$C$26)+INDEX(Settings!$G$8:$G$15,MATCH(Settings!$C$4,Settings!$B$8:$B$15,0))+N(I24)*MIN(Settings!$C$23*(N(C24)+N(D24)),Settings!$C$24)+INDEX(Settings!$H$8:$H$15,MATCH(Settings!$C$4,Settings!$B$8:$B$15,0))*(N(C24)+N(D24))+IF(Settings!$C$25="Yes",0.025,0)*(N(C24)+N(D24))+INDEX(Settings!$I$8:$I$15,MATCH(Settings!$C$4,Settings!$B$8:$B$15,0))*(INDEX(Settings!$D$8:$D$15,MATCH(Settings!$C$4,Settings!$B$8:$B$15,0))+INDEX(Settings!$E$8:$E$15,MATCH(Settings!$C$4,Settings!$B$8:$B$15,0))*(N(C24)+N(D24))+N(I24)*MIN(Settings!$C$23*(N(C24)+N(D24)),Settings!$C$24)+INDEX(Settings!$H$8:$H$15,MATCH(Settings!$C$4,Settings!$B$8:$B$15,0))*(N(C24)+N(D24)))) | L24: =IF(B24="","",N(E24)+N(F24)+N(G24)+N(H24)/60*Settings!$C$27) | M24: =IF(B24="","",J24-K24-L24) | N24: =IF(OR(B24="",N(J24)=0),"",M24/J24) | O24: =IF(B24="","",IF(M24<0,"Loss",IF(N24<Settings!$C$28,"Below target","On target"))) | P24: =IF(B24="","",IF(1-(INDEX(Settings!$E$8:$E$15,MATCH(Settings!$C$4,Settings!$B$8:$B$15,0))+INDEX(Settings!$F$8:$F$15,MATCH(Settings!$C$4,Settings!$B$8:$B$15,0))*(1+Settings!$C$26)+N(I24)*Settings!$C$23+INDEX(Settings!$H$8:$H$15,MATCH(Settings!$C$4,Settings!$B$8:$B$15,0))+IF(Settings!$C$25="Yes",0.025,0)+INDEX(Settings!$I$8:$I$15,MATCH(Settings!$C$4,Settings!$B$8:$B$15,0))*(INDEX(Settings!$E$8:$E$15,MATCH(Settings!$C$4,Settings!$B$8:$B$15,0))+N(I24)*Settings!$C$23+INDEX(Settings!$H$8:$H$15,MATCH(Settings!$C$4,Settings!$B$8:$B$15,0))))-Settings!$C$28<=0,"Not reachable",MAX(0,(INDEX(Settings!$D$8:$D$15,MATCH(Settings!$C$4,Settings!$B$8:$B$15,0))*(1+INDEX(Settings!$I$8:$I$15,MATCH(Settings!$C$4,Settings!$B$8:$B$15,0)))+INDEX(Settings!$G$8:$G$15,MATCH(Settings!$C$4,Settings!$B$8:$B$15,0))+L24)/(1-(INDEX(Settings!$E$8:$E$15,MATCH(Settings!$C$4,Settings!$B$8:$B$15,0))+INDEX(Settings!$F$8:$F$15,MATCH(Settings!$C$4,Settings!$B$8:$B$15,0))*(1+Settings!$C$26)+N(I24)*Settings!$C$23+INDEX(Settings!$H$8:$H$15,MATCH(Settings!$C$4,Settings!$B$8:$B$15,0))+IF(Settings!$C$25="Yes",0.025,0)+INDEX(Settings!$I$8:$I$15,MATCH(Settings!$C$4,Settings!$B$8:$B$15,0))*(INDEX(Settings!$E$8:$E$15,MATCH(Settings!$C$4,Settings!$B$8:$B$15,0))+N(I24)*Settings!$C$23+INDEX(Settings!$H$8:$H$15,MATCH(Settings!$C$4,Settings!$B$8:$B$15,0))))-Settings!$C$28)-N(D24))))
J25: =IF(B25="","",(N(C25)+N(D25))) | K25: =IF(B25="","",INDEX(Settings!$D$8:$D$15,MATCH(Settings!$C$4,Settings!$B$8:$B$15,0))+INDEX(Settings!$E$8:$E$15,MATCH(Settings!$C$4,Settings!$B$8:$B$15,0))*(N(C25)+N(D25))+INDEX(Settings!$F$8:$F$15,MATCH(Settings!$C$4,Settings!$B$8:$B$15,0))*(N(C25)+N(D25))*(1+Settings!$C$26)+INDEX(Settings!$G$8:$G$15,MATCH(Settings!$C$4,Settings!$B$8:$B$15,0))+N(I25)*MIN(Settings!$C$23*(N(C25)+N(D25)),Settings!$C$24)+INDEX(Settings!$H$8:$H$15,MATCH(Settings!$C$4,Settings!$B$8:$B$15,0))*(N(C25)+N(D25))+IF(Settings!$C$25="Yes",0.025,0)*(N(C25)+N(D25))+INDEX(Settings!$I$8:$I$15,MATCH(Settings!$C$4,Settings!$B$8:$B$15,0))*(INDEX(Settings!$D$8:$D$15,MATCH(Settings!$C$4,Settings!$B$8:$B$15,0))+INDEX(Settings!$E$8:$E$15,MATCH(Settings!$C$4,Settings!$B$8:$B$15,0))*(N(C25)+N(D25))+N(I25)*MIN(Settings!$C$23*(N(C25)+N(D25)),Settings!$C$24)+INDEX(Settings!$H$8:$H$15,MATCH(Settings!$C$4,Settings!$B$8:$B$15,0))*(N(C25)+N(D25)))) | L25: =IF(B25="","",N(E25)+N(F25)+N(G25)+N(H25)/60*Settings!$C$27) | M25: =IF(B25="","",J25-K25-L25) | N25: =IF(OR(B25="",N(J25)=0),"",M25/J25) | O25: =IF(B25="","",IF(M25<0,"Loss",IF(N25<Settings!$C$28,"Below target","On target"))) | P25: =IF(B25="","",IF(1-(INDEX(Settings!$E$8:$E$15,MATCH(Settings!$C$4,Settings!$B$8:$B$15,0))+INDEX(Settings!$F$8:$F$15,MATCH(Settings!$C$4,Settings!$B$8:$B$15,0))*(1+Settings!$C$26)+N(I25)*Settings!$C$23+INDEX(Settings!$H$8:$H$15,MATCH(Settings!$C$4,Settings!$B$8:$B$15,0))+IF(Settings!$C$25="Yes",0.025,0)+INDEX(Settings!$I$8:$I$15,MATCH(Settings!$C$4,Settings!$B$8:$B$15,0))*(INDEX(Settings!$E$8:$E$15,MATCH(Settings!$C$4,Settings!$B$8:$B$15,0))+N(I25)*Settings!$C$23+INDEX(Settings!$H$8:$H$15,MATCH(Settings!$C$4,Settings!$B$8:$B$15,0))))-Settings!$C$28<=0,"Not reachable",MAX(0,(INDEX(Settings!$D$8:$D$15,MATCH(Settings!$C$4,Settings!$B$8:$B$15,0))*(1+INDEX(Settings!$I$8:$I$15,MATCH(Settings!$C$4,Settings!$B$8:$B$15,0)))+INDEX(Settings!$G$8:$G$15,MATCH(Settings!$C$4,Settings!$B$8:$B$15,0))+L25)/(1-(INDEX(Settings!$E$8:$E$15,MATCH(Settings!$C$4,Settings!$B$8:$B$15,0))+INDEX(Settings!$F$8:$F$15,MATCH(Settings!$C$4,Settings!$B$8:$B$15,0))*(1+Settings!$C$26)+N(I25)*Settings!$C$23+INDEX(Settings!$H$8:$H$15,MATCH(Settings!$C$4,Settings!$B$8:$B$15,0))+IF(Settings!$C$25="Yes",0.025,0)+INDEX(Settings!$I$8:$I$15,MATCH(Settings!$C$4,Settings!$B$8:$B$15,0))*(INDEX(Settings!$E$8:$E$15,MATCH(Settings!$C$4,Settings!$B$8:$B$15,0))+N(I25)*Settings!$C$23+INDEX(Settings!$H$8:$H$15,MATCH(Settings!$C$4,Settings!$B$8:$B$15,0))))-Settings!$C$28)-N(D25))))
J26: =IF(B26="","",(N(C26)+N(D26))) | K26: =IF(B26="","",INDEX(Settings!$D$8:$D$15,MATCH(Settings!$C$4,Settings!$B$8:$B$15,0))+INDEX(Settings!$E$8:$E$15,MATCH(Settings!$C$4,Settings!$B$8:$B$15,0))*(N(C26)+N(D26))+INDEX(Settings!$F$8:$F$15,MATCH(Settings!$C$4,Settings!$B$8:$B$15,0))*(N(C26)+N(D26))*(1+Settings!$C$26)+INDEX(Settings!$G$8:$G$15,MATCH(Settings!$C$4,Settings!$B$8:$B$15,0))+N(I26)*MIN(Settings!$C$23*(N(C26)+N(D26)),Settings!$C$24)+INDEX(Settings!$H$8:$H$15,MATCH(Settings!$C$4,Settings!$B$8:$B$15,0))*(N(C26)+N(D26))+IF(Settings!$C$25="Yes",0.025,0)*(N(C26)+N(D26))+INDEX(Settings!$I$8:$I$15,MATCH(Settings!$C$4,Settings!$B$8:$B$15,0))*(INDEX(Settings!$D$8:$D$15,MATCH(Settings!$C$4,Settings!$B$8:$B$15,0))+INDEX(Settings!$E$8:$E$15,MATCH(Settings!$C$4,Settings!$B$8:$B$15,0))*(N(C26)+N(D26))+N(I26)*MIN(Settings!$C$23*(N(C26)+N(D26)),Settings!$C$24)+INDEX(Settings!$H$8:$H$15,MATCH(Settings!$C$4,Settings!$B$8:$B$15,0))*(N(C26)+N(D26)))) | L26: =IF(B26="","",N(E26)+N(F26)+N(G26)+N(H26)/60*Settings!$C$27) | M26: =IF(B26="","",J26-K26-L26) | N26: =IF(OR(B26="",N(J26)=0),"",M26/J26) | O26: =IF(B26="","",IF(M26<0,"Loss",IF(N26<Settings!$C$28,"Below target","On target"))) | P26: =IF(B26="","",IF(1-(INDEX(Settings!$E$8:$E$15,MATCH(Settings!$C$4,Settings!$B$8:$B$15,0))+INDEX(Settings!$F$8:$F$15,MATCH(Settings!$C$4,Settings!$B$8:$B$15,0))*(1+Settings!$C$26)+N(I26)*Settings!$C$23+INDEX(Settings!$H$8:$H$15,MATCH(Settings!$C$4,Settings!$B$8:$B$15,0))+IF(Settings!$C$25="Yes",0.025,0)+INDEX(Settings!$I$8:$I$15,MATCH(Settings!$C$4,Settings!$B$8:$B$15,0))*(INDEX(Settings!$E$8:$E$15,MATCH(Settings!$C$4,Settings!$B$8:$B$15,0))+N(I26)*Settings!$C$23+INDEX(Settings!$H$8:$H$15,MATCH(Settings!$C$4,Settings!$B$8:$B$15,0))))-Settings!$C$28<=0,"Not reachable",MAX(0,(INDEX(Settings!$D$8:$D$15,MATCH(Settings!$C$4,Settings!$B$8:$B$15,0))*(1+INDEX(Settings!$I$8:$I$15,MATCH(Settings!$C$4,Settings!$B$8:$B$15,0)))+INDEX(Settings!$G$8:$G$15,MATCH(Settings!$C$4,Settings!$B$8:$B$15,0))+L26)/(1-(INDEX(Settings!$E$8:$E$15,MATCH(Settings!$C$4,Settings!$B$8:$B$15,0))+INDEX(Settings!$F$8:$F$15,MATCH(Settings!$C$4,Settings!$B$8:$B$15,0))*(1+Settings!$C$26)+N(I26)*Settings!$C$23+INDEX(Settings!$H$8:$H$15,MATCH(Settings!$C$4,Settings!$B$8:$B$15,0))+IF(Settings!$C$25="Yes",0.025,0)+INDEX(Settings!$I$8:$I$15,MATCH(Settings!$C$4,Settings!$B$8:$B$15,0))*(INDEX(Settings!$E$8:$E$15,MATCH(Settings!$C$4,Settings!$B$8:$B$15,0))+N(I26)*Settings!$C$23+INDEX(Settings!$H$8:$H$15,MATCH(Settings!$C$4,Settings!$B$8:$B$15,0))))-Settings!$C$28)-N(D26))))
J27: =IF(B27="","",(N(C27)+N(D27))) | K27: =IF(B27="","",INDEX(Settings!$D$8:$D$15,MATCH(Settings!$C$4,Settings!$B$8:$B$15,0))+INDEX(Settings!$E$8:$E$15,MATCH(Settings!$C$4,Settings!$B$8:$B$15,0))*(N(C27)+N(D27))+INDEX(Settings!$F$8:$F$15,MATCH(Settings!$C$4,Settings!$B$8:$B$15,0))*(N(C27)+N(D27))*(1+Settings!$C$26)+INDEX(Settings!$G$8:$G$15,MATCH(Settings!$C$4,Settings!$B$8:$B$15,0))+N(I27)*MIN(Settings!$C$23*(N(C27)+N(D27)),Settings!$C$24)+INDEX(Settings!$H$8:$H$15,MATCH(Settings!$C$4,Settings!$B$8:$B$15,0))*(N(C27)+N(D27))+IF(Settings!$C$25="Yes",0.025,0)*(N(C27)+N(D27))+INDEX(Settings!$I$8:$I$15,MATCH(Settings!$C$4,Settings!$B$8:$B$15,0))*(INDEX(Settings!$D$8:$D$15,MATCH(Settings!$C$4,Settings!$B$8:$B$15,0))+INDEX(Settings!$E$8:$E$15,MATCH(Settings!$C$4,Settings!$B$8:$B$15,0))*(N(C27)+N(D27))+N(I27)*MIN(Settings!$C$23*(N(C27)+N(D27)),Settings!$C$24)+INDEX(Settings!$H$8:$H$15,MATCH(Settings!$C$4,Settings!$B$8:$B$15,0))*(N(C27)+N(D27)))) | L27: =IF(B27="","",N(E27)+N(F27)+N(G27)+N(H27)/60*Settings!$C$27) | M27: =IF(B27="","",J27-K27-L27) | N27: =IF(OR(B27="",N(J27)=0),"",M27/J27) | O27: =IF(B27="","",IF(M27<0,"Loss",IF(N27<Settings!$C$28,"Below target","On target"))) | P27: =IF(B27="","",IF(1-(INDEX(Settings!$E$8:$E$15,MATCH(Settings!$C$4,Settings!$B$8:$B$15,0))+INDEX(Settings!$F$8:$F$15,MATCH(Settings!$C$4,Settings!$B$8:$B$15,0))*(1+Settings!$C$26)+N(I27)*Settings!$C$23+INDEX(Settings!$H$8:$H$15,MATCH(Settings!$C$4,Settings!$B$8:$B$15,0))+IF(Settings!$C$25="Yes",0.025,0)+INDEX(Settings!$I$8:$I$15,MATCH(Settings!$C$4,Settings!$B$8:$B$15,0))*(INDEX(Settings!$E$8:$E$15,MATCH(Settings!$C$4,Settings!$B$8:$B$15,0))+N(I27)*Settings!$C$23+INDEX(Settings!$H$8:$H$15,MATCH(Settings!$C$4,Settings!$B$8:$B$15,0))))-Settings!$C$28<=0,"Not reachable",MAX(0,(INDEX(Settings!$D$8:$D$15,MATCH(Settings!$C$4,Settings!$B$8:$B$15,0))*(1+INDEX(Settings!$I$8:$I$15,MATCH(Settings!$C$4,Settings!$B$8:$B$15,0)))+INDEX(Settings!$G$8:$G$15,MATCH(Settings!$C$4,Settings!$B$8:$B$15,0))+L27)/(1-(INDEX(Settings!$E$8:$E$15,MATCH(Settings!$C$4,Settings!$B$8:$B$15,0))+INDEX(Settings!$F$8:$F$15,MATCH(Settings!$C$4,Settings!$B$8:$B$15,0))*(1+Settings!$C$26)+N(I27)*Settings!$C$23+INDEX(Settings!$H$8:$H$15,MATCH(Settings!$C$4,Settings!$B$8:$B$15,0))+IF(Settings!$C$25="Yes",0.025,0)+INDEX(Settings!$I$8:$I$15,MATCH(Settings!$C$4,Settings!$B$8:$B$15,0))*(INDEX(Settings!$E$8:$E$15,MATCH(Settings!$C$4,Settings!$B$8:$B$15,0))+N(I27)*Settings!$C$23+INDEX(Settings!$H$8:$H$15,MATCH(Settings!$C$4,Settings!$B$8:$B$15,0))))-Settings!$C$28)-N(D27))))
... J207: =IF(B207="","",(N(C207)+N(D207))) | K207: =IF(B207="","",INDEX(Settings!$D$8:$D$15,MATCH(Settings!$C$4,Settings!$B$8:$B$15,0))+INDEX(Settings!$E$8:$E$15,MATCH(Settings!$C$4,Settings!$B$8:$B$15,0))*(N(C207)+N(D207))+INDEX(Settings!$F$8:$F$15,MATCH(Settings!$C$4,Settings!$B$8:$B$15,0))*(N(C207)+N(D207))*(1+Settings!$C$26)+INDEX(Settings!$G$8:$G$15,MATCH(Settings!$C$4,Settings!$B$8:$B$15,0))+N(I207)*MIN(Settings!$C$23*(N(C207)+N(D207)),Settings!$C$24)+INDEX(Settings!$H$8:$H$15,MATCH(Settings!$C$4,Settings!$B$8:$B$15,0))*(N(C207)+N(D207))+IF(Settings!$C$25="Yes",0.025,0)*(N(C207)+N(D207))+INDEX(Settings!$I$8:$I$15,MATCH(Settings!$C$4,Settings!$B$8:$B$15,0))*(INDEX(Settings!$D$8:$D$15,MATCH(Settings!$C$4,Settings!$B$8:$B$15,0))+INDEX(Settings!$E$8:$E$15,MATCH(Settings!$C$4,Settings!$B$8:$B$15,0))*(N(C207)+N(D207))+N(I207)*MIN(Settings!$C$23*(N(C207)+N(D207)),Settings!$C$24)+INDEX(Settings!$H$8:$H$15,MATCH(Settings!$C$4,Settings!$B$8:$B$15,0))*(N(C207)+N(D207)))) | L207: =IF(B207="","",N(E207)+N(F207)+N(G207)+N(H207)/60*Settings!$C$27) | M207: =IF(B207="","",J207-K207-L207) | N207: =IF(OR(B207="",N(J207)=0),"",M207/J207) | O207: =IF(B207="","",IF(M207<0,"Loss",IF(N207<Settings!$C$28,"Below target","On target"))) | P207: =IF(B207="","",IF(1-(INDEX(Settings!$E$8:$E$15,MATCH(Settings!$C$4,Settings!$B$8:$B$15,0))+INDEX(Settings!$F$8:$F$15,MATCH(Settings!$C$4,Settings!$B$8:$B$15,0))*(1+Settings!$C$26)+N(I207)*Settings!$C$23+INDEX(Settings!$H$8:$H$15,MATCH(Settings!$C$4,Settings!$B$8:$B$15,0))+IF(Settings!$C$25="Yes",0.025,0)+INDEX(Settings!$I$8:$I$15,MATCH(Settings!$C$4,Settings!$B$8:$B$15,0))*(INDEX(Settings!$E$8:$E$15,MATCH(Settings!$C$4,Settings!$B$8:$B$15,0))+N(I207)*Settings!$C$23+INDEX(Settings!$H$8:$H$15,MATCH(Settings!$C$4,Settings!$B$8:$B$15,0))))-Settings!$C$28<=0,"Not reachable",MAX(0,(INDEX(Settings!$D$8:$D$15,MATCH(Settings!$C$4,Settings!$B$8:$B$15,0))*(1+INDEX(Settings!$I$8:$I$15,MATCH(Settings!$C$4,Settings!$B$8:$B$15,0)))+INDEX(Settings!$G$8:$G$15,MATCH(Settings!$C$4,Settings!$B$8:$B$15,0))+L207)/(1-(INDEX(Settings!$E$8:$E$15,MATCH(Settings!$C$4,Settings!$B$8:$B$15,0))+INDEX(Settings!$F$8:$F$15,MATCH(Settings!$C$4,Settings!$B$8:$B$15,0))*(1+Settings!$C$26)+N(I207)*Settings!$C$23+INDEX(Settings!$H$8:$H$15,MATCH(Settings!$C$4,Settings!$B$8:$B$15,0))+IF(Settings!$C$25="Yes",0.025,0)+INDEX(Settings!$I$8:$I$15,MATCH(Settings!$C$4,Settings!$B$8:$B$15,0))*(INDEX(Settings!$E$8:$E$15,MATCH(Settings!$C$4,Settings!$B$8:$B$15,0))+N(I207)*Settings!$C$23+INDEX(Settings!$H$8:$H$15,MATCH(Settings!$C$4,Settings!$B$8:$B$15,0))))-Settings!$C$28)-N(D207))))

Sheet Settings
B2: Settings
B3: Pick your country. Every calculation uses the rates on its line.
B4: Your country | C4: United States
B7: Country | C7: Currency | D7: Listing fee | E7: Transaction fee | F7: Payment processing | G7: Processing fixed part | H7: Regulatory fee | I7: VAT on Etsy fees
B8: United States | C8: USD | D8: 0.2 | E8: 0.065 | F8: 0.03 | G8: 0.25 | H8: 0 | I8: 0
B9: United Kingdom | C9: GBP | D9: 0.16 | E9: 0.065 | F9: 0.04 | G9: 0.2 | H9: 0.0032 | I9: 0.2
B10: France | C10: EUR | D10: 0.18 | E10: 0.065 | F10: 0.04 | G10: 0.3 | H10: 0.0047 | I10: 0.2
B11: Germany | C11: EUR | D11: 0.18 | E11: 0.065 | F11: 0.04 | G11: 0.3 | H11: 0 | I11: 0.19
B12: Italy | C12: EUR | D12: 0.18 | E12: 0.065 | F12: 0.04 | G12: 0.3 | H12: 0.0032 | I12: 0.22
B13: Spain | C13: EUR | D13: 0.18 | E13: 0.065 | F13: 0.04 | G13: 0.3 | H13: 0.0072 | I13: 0.21
B14: Canada | C14: CAD | D14: 0.27 | E14: 0.065 | F14: 0.03 | G14: 0.25 | H14: 0 | I14: 0
B15: Australia | C15: AUD | D15: 0.3 | E15: 0.065 | F15: 0.03 | G15: 0.25 | H15: 0 | I15: 0.1
B17: Etsy changes its fees from time to time. These rates are a starting point: check the current ones at
B18: etsy.com/legal/fees and change any number in this table. Every calculation follows.
