Workbook

Sheet Dashboard
B2: Client dashboard
B3: This month, what is coming up, and who needs a message.
B5: Paid this month | D5: Done this month | E5: Booked ahead | F5: No-shows | G5: Owed to you | I5: Clients | J5: Visits this year | K5: Paid this year
B6: =SUMIFS(Appointments!$I$6:$I$2005,Appointments!$B$6:$B$2005,">="&DATE(YEAR(TODAY()),MONTH(TODAY()),1),Appointments!$B$6:$B$2005,"<="&EOMONTH(TODAY(),0))+SUMIFS(Packages!$F$6:$F$305,Packages!$B$6:$B$305,">="&DATE(YEAR(TODAY()),MONTH(TODAY()),1),Packages!$B$6:$B$305,"<="&EOMONTH(TODAY(),0)) | D6: =COUNTIFS(Appointments!$F$6:$F$2005,"Done",Appointments!$B$6:$B$2005,">="&DATE(YEAR(TODAY()),MONTH(TODAY()),1),Appointments!$B$6:$B$2005,"<="&EOMONTH(TODAY(),0)) | E6: =COUNTIFS(Appointments!$F$6:$F$2005,"Booked",Appointments!$B$6:$B$2005,">="&TODAY()) | F6: =COUNTIFS(Appointments!$F$6:$F$2005,"No-show",Appointments!$B$6:$B$2005,">="&DATE(YEAR(TODAY()),MONTH(TODAY()),1),Appointments!$B$6:$B$2005,"<="&EOMONTH(TODAY(),0)) | G6: =SUM(Appointments!$K$6:$K$2005) | I6: =COUNTIF(Clients!$B$6:$B$305,"?*") | J6: =COUNTIFS(Appointments!$F$6:$F$2005,"Done",Appointments!$B$6:$B$2005,">="&DATE(YEAR(TODAY()),1,1)) | K6: =SUMIFS(Appointments!$I$6:$I$2005,Appointments!$B$6:$B$2005,">="&DATE(YEAR(TODAY()),1,1))+SUMIFS(Packages!$F$6:$F$305,Packages!$B$6:$B$305,">="&DATE(YEAR(TODAY()),1,1))
B8: Coming up
B9: Date | C9: Time | D9: Client | E9: Service | I9: Needs attention
B10: =IF(O10="","",INT(O10)) | C10: =IF(O10="","",INDEX(Appointments!$C$6:$C$2005,MATCH(O10,Appointments!$M$6:$M$2005,0))) | D10: =IF(O10="","",INDEX(Appointments!$D$6:$D$2005,MATCH(O10,Appointments!$M$6:$M$2005,0))) | E10: =IF(O10="","",INDEX(Appointments!$E$6:$E$2005,MATCH(O10,Appointments!$M$6:$M$2005,0))) | I10: =IF(COUNTIFS(Appointments!$F$6:$F$2005,"Booked",Appointments!$B$6:$B$2005,"<"&TODAY())=0,"Every past appointment has its status",IF(COUNTIFS(Appointments!$F$6:$F$2005,"Booked",Appointments!$B$6:$B$2005,"<"&TODAY())=1,"1 past appointment is",COUNTIFS(Appointments!$F$6:$F$2005,"Booked",Appointments!$B$6:$B$2005,"<"&TODAY())&" past appointments are")&" still marked Booked") | O10: =IFERROR(SMALL(Appointments!$M$6:$M$2005,COUNTIF(Appointments!$M$6:$M$2005,"<"&NOW())+1),"")
B11: =IF(O11="","",INT(O11)) | C11: =IF(O11="","",INDEX(Appointments!$C$6:$C$2005,MATCH(O11,Appointments!$M$6:$M$2005,0))) | D11: =IF(O11="","",INDEX(Appointments!$D$6:$D$2005,MATCH(O11,Appointments!$M$6:$M$2005,0))) | E11: =IF(O11="","",INDEX(Appointments!$E$6:$E$2005,MATCH(O11,Appointments!$M$6:$M$2005,0))) | I11: =IF(COUNTIFS(Clients!$L$6:$L$305,">0")=0,"Nobody owes you money",IF(COUNTIFS(Clients!$L$6:$L$305,">0")=1,"1 client owes you ",COUNTIFS(Clients!$L$6:$L$305,">0")&" clients owe you ")&FIXED(SUM(Clients!$L$6:$L$305),2)) | O11: =IFERROR(SMALL(Appointments!$M$6:$M$2005,COUNTIF(Appointments!$M$6:$M$2005,"<"&NOW())+2),"")
B12: =IF(O12="","",INT(O12)) | C12: =IF(O12="","",INDEX(Appointments!$C$6:$C$2005,MATCH(O12,Appointments!$M$6:$M$2005,0))) | D12: =IF(O12="","",INDEX(Appointments!$D$6:$D$2005,MATCH(O12,Appointments!$M$6:$M$2005,0))) | E12: =IF(O12="","",INDEX(Appointments!$E$6:$E$2005,MATCH(O12,Appointments!$M$6:$M$2005,0))) | I12: =IF(COUNTIFS(Clients!$M$6:$M$305,"<=1")=0,"No package is running out",IF(COUNTIFS(Clients!$M$6:$M$305,"<=1")=1,"1 client has",COUNTIFS(Clients!$M$6:$M$305,"<=1")&" clients have")&" 1 package session left or none") | O12: =IFERROR(SMALL(Appointments!$M$6:$M$2005,COUNTIF(Appointments!$M$6:$M$2005,"<"&NOW())+3),"")
B13: =IF(O13="","",INT(O13)) | C13: =IF(O13="","",INDEX(Appointments!$C$6:$C$2005,MATCH(O13,Appointments!$M$6:$M$2005,0))) | D13: =IF(O13="","",INDEX(Appointments!$D$6:$D$2005,MATCH(O13,Appointments!$M$6:$M$2005,0))) | E13: =IF(O13="","",INDEX(Appointments!$E$6:$E$2005,MATCH(O13,Appointments!$M$6:$M$2005,0))) | I13: =IF(COUNTIFS(Clients!$N$6:$N$305,"Not seen*")=0,"Every regular client has been back lately",IF(COUNTIFS(Clients!$N$6:$N$305,"Not seen*")=1,"1 client has not",COUNTIFS(Clients!$N$6:$N$305,"Not seen*")&" clients have not")&" been back in "&Services!$I$7&" days") | O13: =IFERROR(SMALL(Appointments!$M$6:$M$2005,COUNTIF(Appointments!$M$6:$M$2005,"<"&NOW())+4),"")
B14: =IF(O14="","",INT(O14)) | C14: =IF(O14="","",INDEX(Appointments!$C$6:$C$2005,MATCH(O14,Appointments!$M$6:$M$2005,0))) | D14: =IF(O14="","",INDEX(Appointments!$D$6:$D$2005,MATCH(O14,Appointments!$M$6:$M$2005,0))) | E14: =IF(O14="","",INDEX(Appointments!$E$6:$E$2005,MATCH(O14,Appointments!$M$6:$M$2005,0))) | I14: =IF(COUNTIFS(Clients!$O$6:$O$305,MONTH(TODAY()))=0,"No birthdays this month",IF(COUNTIFS(Clients!$O$6:$O$305,MONTH(TODAY()))=1,"1 client has a birthday",COUNTIFS(Clients!$O$6:$O$305,MONTH(TODAY()))&" clients have a birthday")&" this month") | O14: =IFERROR(SMALL(Appointments!$M$6:$M$2005,COUNTIF(Appointments!$M$6:$M$2005,"<"&NOW())+5),"")
B15: =IF(O15="","",INT(O15)) | C15: =IF(O15="","",INDEX(Appointments!$C$6:$C$2005,MATCH(O15,Appointments!$M$6:$M$2005,0))) | D15: =IF(O15="","",INDEX(Appointments!$D$6:$D$2005,MATCH(O15,Appointments!$M$6:$M$2005,0))) | E15: =IF(O15="","",INDEX(Appointments!$E$6:$E$2005,MATCH(O15,Appointments!$M$6:$M$2005,0))) | O15: =IFERROR(SMALL(Appointments!$M$6:$M$2005,COUNTIF(Appointments!$M$6:$M$2005,"<"&NOW())+6),"")
B16: =IF(O16="","",INT(O16)) | C16: =IF(O16="","",INDEX(Appointments!$C$6:$C$2005,MATCH(O16,Appointments!$M$6:$M$2005,0))) | D16: =IF(O16="","",INDEX(Appointments!$D$6:$D$2005,MATCH(O16,Appointments!$M$6:$M$2005,0))) | E16: =IF(O16="","",INDEX(Appointments!$E$6:$E$2005,MATCH(O16,Appointments!$M$6:$M$2005,0))) | O16: =IFERROR(SMALL(Appointments!$M$6:$M$2005,COUNTIF(Appointments!$M$6:$M$2005,"<"&NOW())+7),"")
B17: =IF(O17="","",INT(O17)) | C17: =IF(O17="","",INDEX(Appointments!$C$6:$C$2005,MATCH(O17,Appointments!$M$6:$M$2005,0))) | D17: =IF(O17="","",INDEX(Appointments!$D$6:$D$2005,MATCH(O17,Appointments!$M$6:$M$2005,0))) | E17: =IF(O17="","",INDEX(Appointments!$E$6:$E$2005,MATCH(O17,Appointments!$M$6:$M$2005,0))) | O17: =IFERROR(SMALL(Appointments!$M$6:$M$2005,COUNTIF(Appointments!$M$6:$M$2005,"<"&NOW())+8),"")
B18: =IF(O18="","",INT(O18)) | C18: =IF(O18="","",INDEX(Appointments!$C$6:$C$2005,MATCH(O18,Appointments!$M$6:$M$2005,0))) | D18: =IF(O18="","",INDEX(Appointments!$D$6:$D$2005,MATCH(O18,Appointments!$M$6:$M$2005,0))) | E18: =IF(O18="","",INDEX(Appointments!$E$6:$E$2005,MATCH(O18,Appointments!$M$6:$M$2005,0))) | O18: =IFERROR(SMALL(Appointments!$M$6:$M$2005,COUNTIF(Appointments!$M$6:$M$2005,"<"&NOW())+9),"")
B19: =IF(O19="","",INT(O19)) | C19: =IF(O19="","",INDEX(Appointments!$C$6:$C$2005,MATCH(O19,Appointments!$M$6:$M$2005,0))) | D19: =IF(O19="","",INDEX(Appointments!$D$6:$D$2005,MATCH(O19,Appointments!$M$6:$M$2005,0))) | E19: =IF(O19="","",INDEX(Appointments!$E$6:$E$2005,MATCH(O19,Appointments!$M$6:$M$2005,0))) | O19: =IFERROR(SMALL(Appointments!$M$6:$M$2005,COUNTIF(Appointments!$M$6:$M$2005,"<"&NOW())+10),"")
B22: Year | C22: 2026
B24: Month | C24: Done | D24: No-shows | E24: Appointments paid | F24: Packages sold | G24: Total
B25: Jan | C25: =COUNTIFS(Appointments!$F$6:$F$2005,"Done",Appointments!$B$6:$B$2005,">="&DATE($C$22,1,1),Appointments!$B$6:$B$2005,"<="&EOMONTH(DATE($C$22,1,1),0)) | D25: =COUNTIFS(Appointments!$F$6:$F$2005,"No-show",Appointments!$B$6:$B$2005,">="&DATE($C$22,1,1),Appointments!$B$6:$B$2005,"<="&EOMONTH(DATE($C$22,1,1),0)) | E25: =SUMIFS(Appointments!$I$6:$I$2005,Appointments!$B$6:$B$2005,">="&DATE($C$22,1,1),Appointments!$B$6:$B$2005,"<="&EOMONTH(DATE($C$22,1,1),0)) | F25: =SUMIFS(Packages!$F$6:$F$305,Packages!$B$6:$B$305,">="&DATE($C$22,1,1),Packages!$B$6:$B$305,"<="&EOMONTH(DATE($C$22,1,1),0)) | G25: =E25+F25
B26: Feb | C26: =COUNTIFS(Appointments!$F$6:$F$2005,"Done",Appointments!$B$6:$B$2005,">="&DATE($C$22,2,1),Appointments!$B$6:$B$2005,"<="&EOMONTH(DATE($C$22,2,1),0)) | D26: =COUNTIFS(Appointments!$F$6:$F$2005,"No-show",Appointments!$B$6:$B$2005,">="&DATE($C$22,2,1),Appointments!$B$6:$B$2005,"<="&EOMONTH(DATE($C$22,2,1),0)) | E26: =SUMIFS(Appointments!$I$6:$I$2005,Appointments!$B$6:$B$2005,">="&DATE($C$22,2,1),Appointments!$B$6:$B$2005,"<="&EOMONTH(DATE($C$22,2,1),0)) | F26: =SUMIFS(Packages!$F$6:$F$305,Packages!$B$6:$B$305,">="&DATE($C$22,2,1),Packages!$B$6:$B$305,"<="&EOMONTH(DATE($C$22,2,1),0)) | G26: =E26+F26
B27: Mar | C27: =COUNTIFS(Appointments!$F$6:$F$2005,"Done",Appointments!$B$6:$B$2005,">="&DATE($C$22,3,1),Appointments!$B$6:$B$2005,"<="&EOMONTH(DATE($C$22,3,1),0)) | D27: =COUNTIFS(Appointments!$F$6:$F$2005,"No-show",Appointments!$B$6:$B$2005,">="&DATE($C$22,3,1),Appointments!$B$6:$B$2005,"<="&EOMONTH(DATE($C$22,3,1),0)) | E27: =SUMIFS(Appointments!$I$6:$I$2005,Appointments!$B$6:$B$2005,">="&DATE($C$22,3,1),Appointments!$B$6:$B$2005,"<="&EOMONTH(DATE($C$22,3,1),0)) | F27: =SUMIFS(Packages!$F$6:$F$305,Packages!$B$6:$B$305,">="&DATE($C$22,3,1),Packages!$B$6:$B$305,"<="&EOMONTH(DATE($C$22,3,1),0)) | G27: =E27+F27
B28: Apr | C28: =COUNTIFS(Appointments!$F$6:$F$2005,"Done",Appointments!$B$6:$B$2005,">="&DATE($C$22,4,1),Appointments!$B$6:$B$2005,"<="&EOMONTH(DATE($C$22,4,1),0)) | D28: =COUNTIFS(Appointments!$F$6:$F$2005,"No-show",Appointments!$B$6:$B$2005,">="&DATE($C$22,4,1),Appointments!$B$6:$B$2005,"<="&EOMONTH(DATE($C$22,4,1),0)) | E28: =SUMIFS(Appointments!$I$6:$I$2005,Appointments!$B$6:$B$2005,">="&DATE($C$22,4,1),Appointments!$B$6:$B$2005,"<="&EOMONTH(DATE($C$22,4,1),0)) | F28: =SUMIFS(Packages!$F$6:$F$305,Packages!$B$6:$B$305,">="&DATE($C$22,4,1),Packages!$B$6:$B$305,"<="&EOMONTH(DATE($C$22,4,1),0)) | G28: =E28+F28
B29: May | C29: =COUNTIFS(Appointments!$F$6:$F$2005,"Done",Appointments!$B$6:$B$2005,">="&DATE($C$22,5,1),Appointments!$B$6:$B$2005,"<="&EOMONTH(DATE($C$22,5,1),0)) | D29: =COUNTIFS(Appointments!$F$6:$F$2005,"No-show",Appointments!$B$6:$B$2005,">="&DATE($C$22,5,1),Appointments!$B$6:$B$2005,"<="&EOMONTH(DATE($C$22,5,1),0)) | E29: =SUMIFS(Appointments!$I$6:$I$2005,Appointments!$B$6:$B$2005,">="&DATE($C$22,5,1),Appointments!$B$6:$B$2005,"<="&EOMONTH(DATE($C$22,5,1),0)) | F29: =SUMIFS(Packages!$F$6:$F$305,Packages!$B$6:$B$305,">="&DATE($C$22,5,1),Packages!$B$6:$B$305,"<="&EOMONTH(DATE($C$22,5,1),0)) | G29: =E29+F29
B30: Jun | C30: =COUNTIFS(Appointments!$F$6:$F$2005,"Done",Appointments!$B$6:$B$2005,">="&DATE($C$22,6,1),Appointments!$B$6:$B$2005,"<="&EOMONTH(DATE($C$22,6,1),0)) | D30: =COUNTIFS(Appointments!$F$6:$F$2005,"No-show",Appointments!$B$6:$B$2005,">="&DATE($C$22,6,1),Appointments!$B$6:$B$2005,"<="&EOMONTH(DATE($C$22,6,1),0)) | E30: =SUMIFS(Appointments!$I$6:$I$2005,Appointments!$B$6:$B$2005,">="&DATE($C$22,6,1),Appointments!$B$6:$B$2005,"<="&EOMONTH(DATE($C$22,6,1),0)) | F30: =SUMIFS(Packages!$F$6:$F$305,Packages!$B$6:$B$305,">="&DATE($C$22,6,1),Packages!$B$6:$B$305,"<="&EOMONTH(DATE($C$22,6,1),0)) | G30: =E30+F30
B31: Jul | C31: =COUNTIFS(Appointments!$F$6:$F$2005,"Done",Appointments!$B$6:$B$2005,">="&DATE($C$22,7,1),Appointments!$B$6:$B$2005,"<="&EOMONTH(DATE($C$22,7,1),0)) | D31: =COUNTIFS(Appointments!$F$6:$F$2005,"No-show",Appointments!$B$6:$B$2005,">="&DATE($C$22,7,1),Appointments!$B$6:$B$2005,"<="&EOMONTH(DATE($C$22,7,1),0)) | E31: =SUMIFS(Appointments!$I$6:$I$2005,Appointments!$B$6:$B$2005,">="&DATE($C$22,7,1),Appointments!$B$6:$B$2005,"<="&EOMONTH(DATE($C$22,7,1),0)) | F31: =SUMIFS(Packages!$F$6:$F$305,Packages!$B$6:$B$305,">="&DATE($C$22,7,1),Packages!$B$6:$B$305,"<="&EOMONTH(DATE($C$22,7,1),0)) | G31: =E31+F31
B32: Aug | C32: =COUNTIFS(Appointments!$F$6:$F$2005,"Done",Appointments!$B$6:$B$2005,">="&DATE($C$22,8,1),Appointments!$B$6:$B$2005,"<="&EOMONTH(DATE($C$22,8,1),0)) | D32: =COUNTIFS(Appointments!$F$6:$F$2005,"No-show",Appointments!$B$6:$B$2005,">="&DATE($C$22,8,1),Appointments!$B$6:$B$2005,"<="&EOMONTH(DATE($C$22,8,1),0)) | E32: =SUMIFS(Appointments!$I$6:$I$2005,Appointments!$B$6:$B$2005,">="&DATE($C$22,8,1),Appointments!$B$6:$B$2005,"<="&EOMONTH(DATE($C$22,8,1),0)) | F32: =SUMIFS(Packages!$F$6:$F$305,Packages!$B$6:$B$305,">="&DATE($C$22,8,1),Packages!$B$6:$B$305,"<="&EOMONTH(DATE($C$22,8,1),0)) | G32: =E32+F32
B33: Sep | C33: =COUNTIFS(Appointments!$F$6:$F$2005,"Done",Appointments!$B$6:$B$2005,">="&DATE($C$22,9,1),Appointments!$B$6:$B$2005,"<="&EOMONTH(DATE($C$22,9,1),0)) | D33: =COUNTIFS(Appointments!$F$6:$F$2005,"No-show",Appointments!$B$6:$B$2005,">="&DATE($C$22,9,1),Appointments!$B$6:$B$2005,"<="&EOMONTH(DATE($C$22,9,1),0)) | E33: =SUMIFS(Appointments!$I$6:$I$2005,Appointments!$B$6:$B$2005,">="&DATE($C$22,9,1),Appointments!$B$6:$B$2005,"<="&EOMONTH(DATE($C$22,9,1),0)) | F33: =SUMIFS(Packages!$F$6:$F$305,Packages!$B$6:$B$305,">="&DATE($C$22,9,1),Packages!$B$6:$B$305,"<="&EOMONTH(DATE($C$22,9,1),0)) | G33: =E33+F33
B34: Oct | C34: =COUNTIFS(Appointments!$F$6:$F$2005,"Done",Appointments!$B$6:$B$2005,">="&DATE($C$22,10,1),Appointments!$B$6:$B$2005,"<="&EOMONTH(DATE($C$22,10,1),0)) | D34: =COUNTIFS(Appointments!$F$6:$F$2005,"No-show",Appointments!$B$6:$B$2005,">="&DATE($C$22,10,1),Appointments!$B$6:$B$2005,"<="&EOMONTH(DATE($C$22,10,1),0)) | E34: =SUMIFS(Appointments!$I$6:$I$2005,Appointments!$B$6:$B$2005,">="&DATE($C$22,10,1),Appointments!$B$6:$B$2005,"<="&EOMONTH(DATE($C$22,10,1),0)) | F34: =SUMIFS(Packages!$F$6:$F$305,Packages!$B$6:$B$305,">="&DATE($C$22,10,1),Packages!$B$6:$B$305,"<="&EOMONTH(DATE($C$22,10,1),0)) | G34: =E34+F34
B35: Nov | C35: =COUNTIFS(Appointments!$F$6:$F$2005,"Done",Appointments!$B$6:$B$2005,">="&DATE($C$22,11,1),Appointments!$B$6:$B$2005,"<="&EOMONTH(DATE($C$22,11,1),0)) | D35: =COUNTIFS(Appointments!$F$6:$F$2005,"No-show",Appointments!$B$6:$B$2005,">="&DATE($C$22,11,1),Appointments!$B$6:$B$2005,"<="&EOMONTH(DATE($C$22,11,1),0)) | E35: =SUMIFS(Appointments!$I$6:$I$2005,Appointments!$B$6:$B$2005,">="&DATE($C$22,11,1),Appointments!$B$6:$B$2005,"<="&EOMONTH(DATE($C$22,11,1),0)) | F35: =SUMIFS(Packages!$F$6:$F$305,Packages!$B$6:$B$305,">="&DATE($C$22,11,1),Packages!$B$6:$B$305,"<="&EOMONTH(DATE($C$22,11,1),0)) | G35: =E35+F35
B36: Dec | C36: =COUNTIFS(Appointments!$F$6:$F$2005,"Done",Appointments!$B$6:$B$2005,">="&DATE($C$22,12,1),Appointments!$B$6:$B$2005,"<="&EOMONTH(DATE($C$22,12,1),0)) | D36: =COUNTIFS(Appointments!$F$6:$F$2005,"No-show",Appointments!$B$6:$B$2005,">="&DATE($C$22,12,1),Appointments!$B$6:$B$2005,"<="&EOMONTH(DATE($C$22,12,1),0)) | E36: =SUMIFS(Appointments!$I$6:$I$2005,Appointments!$B$6:$B$2005,">="&DATE($C$22,12,1),Appointments!$B$6:$B$2005,"<="&EOMONTH(DATE($C$22,12,1),0)) | F36: =SUMIFS(Packages!$F$6:$F$305,Packages!$B$6:$B$305,">="&DATE($C$22,12,1),Packages!$B$6:$B$305,"<="&EOMONTH(DATE($C$22,12,1),0)) | G36: =E36+F36
B37: Year | C37: =SUM(C25:C36) | D37: =SUM(D25:D36) | E37: =SUM(E25:E36) | F37: =SUM(F25:F36) | G37: =SUM(G25:G36)

Sheet Appointments
B2: Appointments
B3: One line per appointment. Change the status to Done after the visit and type what was paid.
B5: Date | C5: Time | D5: Client | E5: Service | F5: Status | G5: Price | H5: Discount | I5: Paid | J5: Paid with | K5: Still to pay | L5: Note
B6: 46028 | C6: 0.375 | D6: Anna Rossi | E6: Colour | F6: Done | G6: =IF(E6="","",MAX(0,IFERROR(INDEX(Services!$C$6:$C$35,MATCH(E6,Services!$B$6:$B$35,0)),0)-N(H6))) | I6: 95 | J6: App | K6: =IF(OR(B6="",F6<>"Done",J6="Package"),"",IF(N(G6)-N(I6)>0,N(G6)-N(I6),"")) | M6: =IF(OR(B6="",D6="",F6="Cancelled"),"",B6+N(C6)+ROW()/10000000) | N6: =IF(AND(F6="Done",M6<>""),IF(COUNTIFS(Appointments!$D$6:$D$2005,D6,Appointments!$F$6:$F$2005,"Done",Appointments!$M$6:$M$2005,">"&M6)=0,1,0),0) | O6: =IF(AND(F6="Booked",M6<>"",N(B6)>=TODAY()),IF(COUNTIFS(Appointments!$D$6:$D$2005,D6,Appointments!$F$6:$F$2005,"Booked",Appointments!$B$6:$B$2005,">="&TODAY(),Appointments!$M$6:$M$2005,"<"&M6)=0,1,0),0)
B7: 46028 | C7: 0.46527778 | D7: Finn Cook | E7: Men's haircut | F7: Done | G7: =IF(E7="","",MAX(0,IFERROR(INDEX(Services!$C$6:$C$35,MATCH(E7,Services!$B$6:$B$35,0)),0)-N(H7))) | I7: 30 | J7: Card | K7: =IF(OR(B7="",F7<>"Done",J7="Package"),"",IF(N(G7)-N(I7)>0,N(G7)-N(I7),"")) | M7: =IF(OR(B7="",D7="",F7="Cancelled"),"",B7+N(C7)+ROW()/10000000) | N7: =IF(AND(F7="Done",M7<>""),IF(COUNTIFS(Appointments!$D$6:$D$2005,D7,Appointments!$F$6:$F$2005,"Done",Appointments!$M$6:$M$2005,">"&M7)=0,1,0),0) | O7: =IF(AND(F7="Booked",M7<>"",N(B7)>=TODAY()),IF(COUNTIFS(Appointments!$D$6:$D$2005,D7,Appointments!$F$6:$F$2005,"Booked",Appointments!$B$6:$B$2005,">="&TODAY(),Appointments!$M$6:$M$2005,"<"&M7)=0,1,0),0)
B8: 46029 | C8: 0.375 | D8: Ava Reed | E8: Highlights | F8: Done | G8: =IF(E8="","",MAX(0,IFERROR(INDEX(Services!$C$6:$C$35,MATCH(E8,Services!$B$6:$B$35,0)),0)-N(H8))) | I8: 140 | J8: Cash | K8: =IF(OR(B8="",F8<>"Done",J8="Package"),"",IF(N(G8)-N(I8)>0,N(G8)-N(I8),"")) | M8: =IF(OR(B8="",D8="",F8="Cancelled"),"",B8+N(C8)+ROW()/10000000) | N8: =IF(AND(F8="Done",M8<>""),IF(COUNTIFS(Appointments!$D$6:$D$2005,D8,Appointments!$F$6:$F$2005,"Done",Appointments!$M$6:$M$2005,">"&M8)=0,1,0),0) | O8: =IF(AND(F8="Booked",M8<>"",N(B8)>=TODAY()),IF(COUNTIFS(Appointments!$D$6:$D$2005,D8,Appointments!$F$6:$F$2005,"Booked",Appointments!$B$6:$B$2005,">="&TODAY(),Appointments!$M$6:$M$2005,"<"&M8)=0,1,0),0)
B9: 46029 | C9: 0.48611111 | D9: Eli James | E9: Men's haircut | F9: Done | G9: =IF(E9="","",MAX(0,IFERROR(INDEX(Services!$C$6:$C$35,MATCH(E9,Services!$B$6:$B$35,0)),0)-N(H9))) | I9: 30 | J9: Card | K9: =IF(OR(B9="",F9<>"Done",J9="Package"),"",IF(N(G9)-N(I9)>0,N(G9)-N(I9),"")) | M9: =IF(OR(B9="",D9="",F9="Cancelled"),"",B9+N(C9)+ROW()/10000000) | N9: =IF(AND(F9="Done",M9<>""),IF(COUNTIFS(Appointments!$D$6:$D$2005,D9,Appointments!$F$6:$F$2005,"Done",Appointments!$M$6:$M$2005,">"&M9)=0,1,0),0) | O9: =IF(AND(F9="Booked",M9<>"",N(B9)>=TODAY()),IF(COUNTIFS(Appointments!$D$6:$D$2005,D9,Appointments!$F$6:$F$2005,"Booked",Appointments!$B$6:$B$2005,">="&TODAY(),Appointments!$M$6:$M$2005,"<"&M9)=0,1,0),0)
B10: 46029 | C10: 0.51388889 | D10: Kara Adams | E10: Women's haircut | F10: No-show | G10: =IF(E10="","",MAX(0,IFERROR(INDEX(Services!$C$6:$C$35,MATCH(E10,Services!$B$6:$B$35,0)),0)-N(H10))) | K10: =IF(OR(B10="",F10<>"Done",J10="Package"),"",IF(N(G10)-N(I10)>0,N(G10)-N(I10),"")) | M10: =IF(OR(B10="",D10="",F10="Cancelled"),"",B10+N(C10)+ROW()/10000000) | N10: =IF(AND(F10="Done",M10<>""),IF(COUNTIFS(Appointments!$D$6:$D$2005,D10,Appointments!$F$6:$F$2005,"Done",Appointments!$M$6:$M$2005,">"&M10)=0,1,0),0) | O10: =IF(AND(F10="Booked",M10<>"",N(B10)>=TODAY()),IF(COUNTIFS(Appointments!$D$6:$D$2005,D10,Appointments!$F$6:$F$2005,"Booked",Appointments!$B$6:$B$2005,">="&TODAY(),Appointments!$M$6:$M$2005,"<"&M10)=0,1,0),0)
B11: 46030 | C11: 0.375 | D11: Julia Hughes | E11: Women's haircut | F11: Done | G11: =IF(E11="","",MAX(0,IFERROR(INDEX(Services!$C$6:$C$35,MATCH(E11,Services!$B$6:$B$35,0)),0)-N(H11))) | H11: 10 | I11: 45 | J11: Card | K11: =IF(OR(B11="",F11<>"Done",J11="Package"),"",IF(N(G11)-N(I11)>0,N(G11)-N(I11),"")) | L11: Friends and family | M11: =IF(OR(B11="",D11="",F11="Cancelled"),"",B11+N(C11)+ROW()/10000000) | N11: =IF(AND(F11="Done",M11<>""),IF(COUNTIFS(Appointments!$D$6:$D$2005,D11,Appointments!$F$6:$F$2005,"Done",Appointments!$M$6:$M$2005,">"&M11)=0,1,0),0) | O11: =IF(AND(F11="Booked",M11<>"",N(B11)>=TODAY()),IF(COUNTIFS(Appointments!$D$6:$D$2005,D11,Appointments!$F$6:$F$2005,"Booked",Appointments!$B$6:$B$2005,">="&TODAY(),Appointments!$M$6:$M$2005,"<"&M11)=0,1,0),0)
B12: 46030 | C12: 0.42361111 | D12: Owen Walsh | E12: Men's haircut | F12: Done | G12: =IF(E12="","",MAX(0,IFERROR(INDEX(Services!$C$6:$C$35,MATCH(E12,Services!$B$6:$B$35,0)),0)-N(H12))) | I12: 30 | J12: Card | K12: =IF(OR(B12="",F12<>"Done",J12="Package"),"",IF(N(G12)-N(I12)>0,N(G12)-N(I12),"")) | M12: =IF(OR(B12="",D12="",F12="Cancelled"),"",B12+N(C12)+ROW()/10000000) | N12: =IF(AND(F12="Done",M12<>""),IF(COUNTIFS(Appointments!$D$6:$D$2005,D12,Appointments!$F$6:$F$2005,"Done",Appointments!$M$6:$M$2005,">"&M12)=0,1,0),0) | O12: =IF(AND(F12="Booked",M12<>"",N(B12)>=TODAY()),IF(COUNTIFS(Appointments!$D$6:$D$2005,D12,Appointments!$F$6:$F$2005,"Booked",Appointments!$B$6:$B$2005,">="&TODAY(),Appointments!$M$6:$M$2005,"<"&M12)=0,1,0),0)
B13: 46030 | C13: 0.45138889 | D13: Sara Stone | E13: Blow dry | F13: Done | G13: =IF(E13="","",MAX(0,IFERROR(INDEX(Services!$C$6:$C$35,MATCH(E13,Services!$B$6:$B$35,0)),0)-N(H13))) | I13: 35 | J13: Card | K13: =IF(OR(B13="",F13<>"Done",J13="Package"),"",IF(N(G13)-N(I13)>0,N(G13)-N(I13),"")) | M13: =IF(OR(B13="",D13="",F13="Cancelled"),"",B13+N(C13)+ROW()/10000000) | N13: =IF(AND(F13="Done",M13<>""),IF(COUNTIFS(Appointments!$D$6:$D$2005,D13,Appointments!$F$6:$F$2005,"Done",Appointments!$M$6:$M$2005,">"&M13)=0,1,0),0) | O13: =IF(AND(F13="Booked",M13<>"",N(B13)>=TODAY()),IF(COUNTIFS(Appointments!$D$6:$D$2005,D13,Appointments!$F$6:$F$2005,"Booked",Appointments!$B$6:$B$2005,">="&TODAY(),Appointments!$M$6:$M$2005,"<"&M13)=0,1,0),0)
B14: 46030 | C14: 0.48958333 | D14: Sophie Ellis | E14: Treatment | F14: Done | G14: =IF(E14="","",MAX(0,IFERROR(INDEX(Services!$C$6:$C$35,MATCH(E14,Services!$B$6:$B$35,0)),0)-N(H14))) | I14: 30 | J14: Card | K14: =IF(OR(B14="",F14<>"Done",J14="Package"),"",IF(N(G14)-N(I14)>0,N(G14)-N(I14),"")) | M14: =IF(OR(B14="",D14="",F14="Cancelled"),"",B14+N(C14)+ROW()/10000000) | N14: =IF(AND(F14="Done",M14<>""),IF(COUNTIFS(Appointments!$D$6:$D$2005,D14,Appointments!$F$6:$F$2005,"Done",Appointments!$M$6:$M$2005,">"&M14)=0,1,0),0) | O14: =IF(AND(F14="Booked",M14<>"",N(B14)>=TODAY()),IF(COUNTIFS(Appointments!$D$6:$D$2005,D14,Appointments!$F$6:$F$2005,"Booked",Appointments!$B$6:$B$2005,">="&TODAY(),Appointments!$M$6:$M$2005,"<"&M14)=0,1,0),0)
B15: 46030 | C15: 0.51736111 | D15: Zoe Turner | E15: Women's haircut | F15: Done | G15: =IF(E15="","",MAX(0,IFERROR(INDEX(Services!$C$6:$C$35,MATCH(E15,Services!$B$6:$B$35,0)),0)-N(H15))) | I15: 55 | J15: Cash | K15: =IF(OR(B15="",F15<>"Done",J15="Package"),"",IF(N(G15)-N(I15)>0,N(G15)-N(I15),"")) | M15: =IF(OR(B15="",D15="",F15="Cancelled"),"",B15+N(C15)+ROW()/10000000) | N15: =IF(AND(F15="Done",M15<>""),IF(COUNTIFS(Appointments!$D$6:$D$2005,D15,Appointments!$F$6:$F$2005,"Done",Appointments!$M$6:$M$2005,">"&M15)=0,1,0),0) | O15: =IF(AND(F15="Booked",M15<>"",N(B15)>=TODAY()),IF(COUNTIFS(Appointments!$D$6:$D$2005,D15,Appointments!$F$6:$F$2005,"Booked",Appointments!$B$6:$B$2005,">="&TODAY(),Appointments!$M$6:$M$2005,"<"&M15)=0,1,0),0)
B16: 46031 | C16: 0.375 | D16: Ella James | E16: Treatment | F16: No-show | G16: =IF(E16="","",MAX(0,IFERROR(INDEX(Services!$C$6:$C$35,MATCH(E16,Services!$B$6:$B$35,0)),0)-N(H16))) | K16: =IF(OR(B16="",F16<>"Done",J16="Package"),"",IF(N(G16)-N(I16)>0,N(G16)-N(I16),"")) | M16: =IF(OR(B16="",D16="",F16="Cancelled"),"",B16+N(C16)+ROW()/10000000) | N16: =IF(AND(F16="Done",M16<>""),IF(COUNTIFS(Appointments!$D$6:$D$2005,D16,Appointments!$F$6:$F$2005,"Done",Appointments!$M$6:$M$2005,">"&M16)=0,1,0),0) | O16: =IF(AND(F16="Booked",M16<>"",N(B16)>=TODAY()),IF(COUNTIFS(Appointments!$D$6:$D$2005,D16,Appointments!$F$6:$F$2005,"Booked",Appointments!$B$6:$B$2005,">="&TODAY(),Appointments!$M$6:$M$2005,"<"&M16)=0,1,0),0)
B17: 46031 | C17: 0.40277778 | D17: Hannah Ellis | E17: Colour | F17: Done | G17: =IF(E17="","",MAX(0,IFERROR(INDEX(Services!$C$6:$C$35,MATCH(E17,Services!$B$6:$B$35,0)),0)-N(H17))) | I17: 95 | J17: Card | K17: =IF(OR(B17="",F17<>"Done",J17="Package"),"",IF(N(G17)-N(I17)>0,N(G17)-N(I17),"")) | M17: =IF(OR(B17="",D17="",F17="Cancelled"),"",B17+N(C17)+ROW()/10000000) | N17: =IF(AND(F17="Done",M17<>""),IF(COUNTIFS(Appointments!$D$6:$D$2005,D17,Appointments!$F$6:$F$2005,"Done",Appointments!$M$6:$M$2005,">"&M17)=0,1,0),0) | O17: =IF(AND(F17="Booked",M17<>"",N(B17)>=TODAY()),IF(COUNTIFS(Appointments!$D$6:$D$2005,D17,Appointments!$F$6:$F$2005,"Booked",Appointments!$B$6:$B$2005,">="&TODAY(),Appointments!$M$6:$M$2005,"<"&M17)=0,1,0),0)
B18: 46031 | C18: 0.49305556 | D18: Hannah Kelly | E18: Women's haircut | F18: No-show | G18: =IF(E18="","",MAX(0,IFERROR(INDEX(Services!$C$6:$C$35,MATCH(E18,Services!$B$6:$B$35,0)),0)-N(H18))) | K18: =IF(OR(B18="",F18<>"Done",J18="Package"),"",IF(N(G18)-N(I18)>0,N(G18)-N(I18),"")) | M18: =IF(OR(B18="",D18="",F18="Cancelled"),"",B18+N(C18)+ROW()/10000000) | N18: =IF(AND(F18="Done",M18<>""),IF(COUNTIFS(Appointments!$D$6:$D$2005,D18,Appointments!$F$6:$F$2005,"Done",Appointments!$M$6:$M$2005,">"&M18)=0,1,0),0) | O18: =IF(AND(F18="Booked",M18<>"",N(B18)>=TODAY()),IF(COUNTIFS(Appointments!$D$6:$D$2005,D18,Appointments!$F$6:$F$2005,"Booked",Appointments!$B$6:$B$2005,">="&TODAY(),Appointments!$M$6:$M$2005,"<"&M18)=0,1,0),0)
B19: 46031 | C19: 0.54166667 | D19: Harry Adams | E19: Men's haircut | F19: Done | G19: =IF(E19="","",MAX(0,IFERROR(INDEX(Services!$C$6:$C$35,MATCH(E19,Services!$B$6:$B$35,0)),0)-N(H19))) | I19: 30 | J19: Cash | K19: =IF(OR(B19="",F19<>"Done",J19="Package"),"",IF(N(G19)-N(I19)>0,N(G19)-N(I19),"")) | M19: =IF(OR(B19="",D19="",F19="Cancelled"),"",B19+N(C19)+ROW()/10000000) | N19: =IF(AND(F19="Done",M19<>""),IF(COUNTIFS(Appointments!$D$6:$D$2005,D19,Appointments!$F$6:$F$2005,"Done",Appointments!$M$6:$M$2005,">"&M19)=0,1,0),0) | O19: =IF(AND(F19="Booked",M19<>"",N(B19)>=TODAY()),IF(COUNTIFS(Appointments!$D$6:$D$2005,D19,Appointments!$F$6:$F$2005,"Booked",Appointments!$B$6:$B$2005,">="&TODAY(),Appointments!$M$6:$M$2005,"<"&M19)=0,1,0),0)
B20: 46031 | C20: 0.56944444 | D20: Isla Brown | E20: Women's haircut | F20: Done | G20: =IF(E20="","",MAX(0,IFERROR(INDEX(Services!$C$6:$C$35,MATCH(E20,Services!$B$6:$B$35,0)),0)-N(H20))) | I20: 55 | J20: Card | K20: =IF(OR(B20="",F20<>"Done",J20="Package"),"",IF(N(G20)-N(I20)>0,N(G20)-N(I20),"")) | M20: =IF(OR(B20="",D20="",F20="Cancelled"),"",B20+N(C20)+ROW()/10000000) | N20: =IF(AND(F20="Done",M20<>""),IF(COUNTIFS(Appointments!$D$6:$D$2005,D20,Appointments!$F$6:$F$2005,"Done",Appointments!$M$6:$M$2005,">"&M20)=0,1,0),0) | O20: =IF(AND(F20="Booked",M20<>"",N(B20)>=TODAY()),IF(COUNTIFS(Appointments!$D$6:$D$2005,D20,Appointments!$F$6:$F$2005,"Booked",Appointments!$B$6:$B$2005,">="&TODAY(),Appointments!$M$6:$M$2005,"<"&M20)=0,1,0),0)
B21: 46031 | C21: 0.61805556 | D21: Nina Ellis | E21: Women's haircut | F21: Done | G21: =IF(E21="","",MAX(0,IFERROR(INDEX(Services!$C$6:$C$35,MATCH(E21,Services!$B$6:$B$35,0)),0)-N(H21))) | I21: 55 | J21: Cash | K21: =IF(OR(B21="",F21<>"Done",J21="Package"),"",IF(N(G21)-N(I21)>0,N(G21)-N(I21),"")) | M21: =IF(OR(B21="",D21="",F21="Cancelled"),"",B21+N(C21)+ROW()/10000000) | N21: =IF(AND(F21="Done",M21<>""),IF(COUNTIFS(Appointments!$D$6:$D$2005,D21,Appointments!$F$6:$F$2005,"Done",Appointments!$M$6:$M$2005,">"&M21)=0,1,0),0) | O21: =IF(AND(F21="Booked",M21<>"",N(B21)>=TODAY()),IF(COUNTIFS(Appointments!$D$6:$D$2005,D21,Appointments!$F$6:$F$2005,"Booked",Appointments!$B$6:$B$2005,">="&TODAY(),Appointments!$M$6:$M$2005,"<"&M21)=0,1,0),0)
B22: 46031 | C22: 0.66666667 | D22: Ruby Webb | E22: Women's haircut | F22: No-show | G22: =IF(E22="","",MAX(0,IFERROR(INDEX(Services!$C$6:$C$35,MATCH(E22,Services!$B$6:$B$35,0)),0)-N(H22))) | K22: =IF(OR(B22="",F22<>"Done",J22="Package"),"",IF(N(G22)-N(I22)>0,N(G22)-N(I22),"")) | M22: =IF(OR(B22="",D22="",F22="Cancelled"),"",B22+N(C22)+ROW()/10000000) | N22: =IF(AND(F22="Done",M22<>""),IF(COUNTIFS(Appointments!$D$6:$D$2005,D22,Appointments!$F$6:$F$2005,"Done",Appointments!$M$6:$M$2005,">"&M22)=0,1,0),0) | O22: =IF(AND(F22="Booked",M22<>"",N(B22)>=TODAY()),IF(COUNTIFS(Appointments!$D$6:$D$2005,D22,Appointments!$F$6:$F$2005,"Booked",Appointments!$B$6:$B$2005,">="&TODAY(),Appointments!$M$6:$M$2005,"<"&M22)=0,1,0),0)
B23: 46032 | C23: 0.375 | D23: Chris Cox | E23: Men's haircut | F23: Done | G23: =IF(E23="","",MAX(0,IFERROR(INDEX(Services!$C$6:$C$35,MATCH(E23,Services!$B$6:$B$35,0)),0)-N(H23))) | I23: 30 | J23: Card | K23: =IF(OR(B23="",F23<>"Done",J23="Package"),"",IF(N(G23)-N(I23)>0,N(G23)-N(I23),"")) | M23: =IF(OR(B23="",D23="",F23="Cancelled"),"",B23+N(C23)+ROW()/10000000) | N23: =IF(AND(F23="Done",M23<>""),IF(COUNTIFS(Appointments!$D$6:$D$2005,D23,Appointments!$F$6:$F$2005,"Done",Appointments!$M$6:$M$2005,">"&M23)=0,1,0),0) | O23: =IF(AND(F23="Booked",M23<>"",N(B23)>=TODAY()),IF(COUNTIFS(Appointments!$D$6:$D$2005,D23,Appointments!$F$6:$F$2005,"Booked",Appointments!$B$6:$B$2005,">="&TODAY(),Appointments!$M$6:$M$2005,"<"&M23)=0,1,0),0)
B24: 46032 | C24: 0.40277778 | D24: Chris Ellis | E24: Men's haircut | F24: Done | G24: =IF(E24="","",MAX(0,IFERROR(INDEX(Services!$C$6:$C$35,MATCH(E24,Services!$B$6:$B$35,0)),0)-N(H24))) | I24: 30 | J24: Cash | K24: =IF(OR(B24="",F24<>"Done",J24="Package"),"",IF(N(G24)-N(I24)>0,N(G24)-N(I24),"")) | M24: =IF(OR(B24="",D24="",F24="Cancelled"),"",B24+N(C24)+ROW()/10000000) | N24: =IF(AND(F24="Done",M24<>""),IF(COUNTIFS(Appointments!$D$6:$D$2005,D24,Appointments!$F$6:$F$2005,"Done",Appointments!$M$6:$M$2005,">"&M24)=0,1,0),0) | O24: =IF(AND(F24="Booked",M24<>"",N(B24)>=TODAY()),IF(COUNTIFS(Appointments!$D$6:$D$2005,D24,Appointments!$F$6:$F$2005,"Booked",Appointments!$B$6:$B$2005,">="&TODAY(),Appointments!$M$6:$M$2005,"<"&M24)=0,1,0),0)
B25: 46032 | C25: 0.43055556 | D25: Holly Shaw | E25: Women's haircut | F25: Done | G25: =IF(E25="","",MAX(0,IFERROR(INDEX(Services!$C$6:$C$35,MATCH(E25,Services!$B$6:$B$35,0)),0)-N(H25))) | I25: 55 | J25: Cash | K25: =IF(OR(B25="",F25<>"Done",J25="Package"),"",IF(N(G25)-N(I25)>0,N(G25)-N(I25),"")) | M25: =IF(OR(B25="",D25="",F25="Cancelled"),"",B25+N(C25)+ROW()/10000000) | N25: =IF(AND(F25="Done",M25<>""),IF(COUNTIFS(Appointments!$D$6:$D$2005,D25,Appointments!$F$6:$F$2005,"Done",Appointments!$M$6:$M$2005,">"&M25)=0,1,0),0) | O25: =IF(AND(F25="Booked",M25<>"",N(B25)>=TODAY()),IF(COUNTIFS(Appointments!$D$6:$D$2005,D25,Appointments!$F$6:$F$2005,"Booked",Appointments!$B$6:$B$2005,">="&TODAY(),Appointments!$M$6:$M$2005,"<"&M25)=0,1,0),0)
B26: 46032 | C26: 0.47916667 | D26: Lily Lewis | E26: Blow dry | F26: Done | G26: =IF(E26="","",MAX(0,IFERROR(INDEX(Services!$C$6:$C$35,MATCH(E26,Services!$B$6:$B$35,0)),0)-N(H26))) | I26: 35 | J26: Card | K26: =IF(OR(B26="",F26<>"Done",J26="Package"),"",IF(N(G26)-N(I26)>0,N(G26)-N(I26),"")) | M26: =IF(OR(B26="",D26="",F26="Cancelled"),"",B26+N(C26)+ROW()/10000000) | N26: =IF(AND(F26="Done",M26<>""),IF(COUNTIFS(Appointments!$D$6:$D$2005,D26,Appointments!$F$6:$F$2005,"Done",Appointments!$M$6:$M$2005,">"&M26)=0,1,0),0) | O26: =IF(AND(F26="Booked",M26<>"",N(B26)>=TODAY()),IF(COUNTIFS(Appointments!$D$6:$D$2005,D26,Appointments!$F$6:$F$2005,"Booked",Appointments!$B$6:$B$2005,">="&TODAY(),Appointments!$M$6:$M$2005,"<"&M26)=0,1,0),0)
B27: 46032 | C27: 0.51736111 | D27: Nina Baker | E27: Women's haircut | F27: Done | G27: =IF(E27="","",MAX(0,IFERROR(INDEX(Services!$C$6:$C$35,MATCH(E27,Services!$B$6:$B$35,0)),0)-N(H27))) | I27: 55 | J27: Card | K27: =IF(OR(B27="",F27<>"Done",J27="Package"),"",IF(N(G27)-N(I27)>0,N(G27)-N(I27),"")) | M27: =IF(OR(B27="",D27="",F27="Cancelled"),"",B27+N(C27)+ROW()/10000000) | N27: =IF(AND(F27="Done",M27<>""),IF(COUNTIFS(Appointments!$D$6:$D$2005,D27,Appointments!$F$6:$F$2005,"Done",Appointments!$M$6:$M$2005,">"&M27)=0,1,0),0) | O27: =IF(AND(F27="Booked",M27<>"",N(B27)>=TODAY()),IF(COUNTIFS(Appointments!$D$6:$D$2005,D27,Appointments!$F$6:$F$2005,"Booked",Appointments!$B$6:$B$2005,">="&TODAY(),Appointments!$M$6:$M$2005,"<"&M27)=0,1,0),0)
B28: 46032 | C28: 0.56597222 | D28: Nina Young | E28: Women's haircut | F28: Done | G28: =IF(E28="","",MAX(0,IFERROR(INDEX(Services!$C$6:$C$35,MATCH(E28,Services!$B$6:$B$35,0)),0)-N(H28))) | I28: 55 | J28: Card | K28: =IF(OR(B28="",F28<>"Done",J28="Package"),"",IF(N(G28)-N(I28)>0,N(G28)-N(I28),"")) | M28: =IF(OR(B28="",D28="",F28="Cancelled"),"",B28+N(C28)+ROW()/10000000) | N28: =IF(AND(F28="Done",M28<>""),IF(COUNTIFS(Appointments!$D$6:$D$2005,D28,Appointments!$F$6:$F$2005,"Done",Appointments!$M$6:$M$2005,">"&M28)=0,1,0),0) | O28: =IF(AND(F28="Booked",M28<>"",N(B28)>=TODAY()),IF(COUNTIFS(Appointments!$D$6:$D$2005,D28,Appointments!$F$6:$F$2005,"Booked",Appointments!$B$6:$B$2005,">="&TODAY(),Appointments!$M$6:$M$2005,"<"&M28)=0,1,0),0)
B29: 46032 | C29: 0.61458333 | D29: Tom Ellis | E29: Men's haircut | F29: Done | G29: =IF(E29="","",MAX(0,IFERROR(INDEX(Services!$C$6:$C$35,MATCH(E29,Services!$B$6:$B$35,0)),0)-N(H29))) | I29: 30 | J29: Transfer | K29: =IF(OR(B29="",F29<>"Done",J29="Package"),"",IF(N(G29)-N(I29)>0,N(G29)-N(I29),"")) | M29: =IF(OR(B29="",D29="",F29="Cancelled"),"",B29+N(C29)+ROW()/10000000) | N29: =IF(AND(F29="Done",M29<>""),IF(COUNTIFS(Appointments!$D$6:$D$2005,D29,Appointments!$F$6:$F$2005,"Done",Appointments!$M$6:$M$2005,">"&M29)=0,1,0),0) | O29: =IF(AND(F29="Booked",M29<>"",N(B29)>=TODAY()),IF(COUNTIFS(Appointments!$D$6:$D$2005,D29,Appointments!$F$6:$F$2005,"Booked",Appointments!$B$6:$B$2005,">="&TODAY(),Appointments!$M$6:$M$2005,"<"&M29)=0,1,0),0)
B30: 46035 | C30: 0.375 | D30: Finn Price | E30: Men's haircut | F30: Done | G30: =IF(E30="","",MAX(0,IFERROR(INDEX(Services!$C$6:$C$35,MATCH(E30,Services!$B$6:$B$35,0)),0)-N(H30))) | H30: 10 | I30: 20 | J30: Transfer | K30: =IF(OR(B30="",F30<>"Done",J30="Package"),"",IF(N(G30)-N(I30)>0,N(G30)-N(I30),"")) | L30: Friends and family | M30: =IF(OR(B30="",D30="",F30="Cancelled"),"",B30+N(C30)+ROW()/10000000) | N30: =IF(AND(F30="Done",M30<>""),IF(COUNTIFS(Appointments!$D$6:$D$2005,D30,Appointments!$F$6:$F$2005,"Done",Appointments!$M$6:$M$2005,">"&M30)=0,1,0),0) | O30: =IF(AND(F30="Booked",M30<>"",N(B30)>=TODAY()),IF(COUNTIFS(Appointments!$D$6:$D$2005,D30,Appointments!$F$6:$F$2005,"Booked",Appointments!$B$6:$B$2005,">="&TODAY(),Appointments!$M$6:$M$2005,"<"&M30)=0,1,0),0)
B31: 46035 | C31: 0.40277778 | D31: Harry Cox | E31: Men's haircut | F31: Done | G31: =IF(E31="","",MAX(0,IFERROR(INDEX(Services!$C$6:$C$35,MATCH(E31,Services!$B$6:$B$35,0)),0)-N(H31))) | I31: 30 | J31: Cash | K31: =IF(OR(B31="",F31<>"Done",J31="Package"),"",IF(N(G31)-N(I31)>0,N(G31)-N(I31),"")) | M31: =IF(OR(B31="",D31="",F31="Cancelled"),"",B31+N(C31)+ROW()/10000000) | N31: =IF(AND(F31="Done",M31<>""),IF(COUNTIFS(Appointments!$D$6:$D$2005,D31,Appointments!$F$6:$F$2005,"Done",Appointments!$M$6:$M$2005,">"&M31)=0,1,0),0) | O31: =IF(AND(F31="Booked",M31<>"",N(B31)>=TODAY()),IF(COUNTIFS(Appointments!$D$6:$D$2005,D31,Appointments!$F$6:$F$2005,"Booked",Appointments!$B$6:$B$2005,">="&TODAY(),Appointments!$M$6:$M$2005,"<"&M31)=0,1,0),0)
B32: 46035 | C32: 0.43055556 | D32: Kyle Hughes | E32: Men's haircut | F32: Done | G32: =IF(E32="","",MAX(0,IFERROR(INDEX(Services!$C$6:$C$35,MATCH(E32,Services!$B$6:$B$35,0)),0)-N(H32))) | I32: 30 | J32: Cash | K32: =IF(OR(B32="",F32<>"Done",J32="Package"),"",IF(N(G32)-N(I32)>0,N(G32)-N(I32),"")) | M32: =IF(OR(B32="",D32="",F32="Cancelled"),"",B32+N(C32)+ROW()/10000000) | N32: =IF(AND(F32="Done",M32<>""),IF(COUNTIFS(Appointments!$D$6:$D$2005,D32,Appointments!$F$6:$F$2005,"Done",Appointments!$M$6:$M$2005,">"&M32)=0,1,0),0) | O32: =IF(AND(F32="Booked",M32<>"",N(B32)>=TODAY()),IF(COUNTIFS(Appointments!$D$6:$D$2005,D32,Appointments!$F$6:$F$2005,"Booked",Appointments!$B$6:$B$2005,">="&TODAY(),Appointments!$M$6:$M$2005,"<"&M32)=0,1,0),0)
B33: 46035 | C33: 0.45833333 | D33: Luke Hall | E33: Men's haircut | F33: Done | G33: =IF(E33="","",MAX(0,IFERROR(INDEX(Services!$C$6:$C$35,MATCH(E33,Services!$B$6:$B$35,0)),0)-N(H33))) | I33: 30 | J33: Card | K33: =IF(OR(B33="",F33<>"Done",J33="Package"),"",IF(N(G33)-N(I33)>0,N(G33)-N(I33),"")) | M33: =IF(OR(B33="",D33="",F33="Cancelled"),"",B33+N(C33)+ROW()/10000000) | N33: =IF(AND(F33="Done",M33<>""),IF(COUNTIFS(Appointments!$D$6:$D$2005,D33,Appointments!$F$6:$F$2005,"Done",Appointments!$M$6:$M$2005,">"&M33)=0,1,0),0) | O33: =IF(AND(F33="Booked",M33<>"",N(B33)>=TODAY()),IF(COUNTIFS(Appointments!$D$6:$D$2005,D33,Appointments!$F$6:$F$2005,"Booked",Appointments!$B$6:$B$2005,">="&TODAY(),Appointments!$M$6:$M$2005,"<"&M33)=0,1,0),0)
B34: 46035 | C34: 0.48611111 | D34: Owen Morgan | E34: Men's haircut | F34: Done | G34: =IF(E34="","",MAX(0,IFERROR(INDEX(Services!$C$6:$C$35,MATCH(E34,Services!$B$6:$B$35,0)),0)-N(H34))) | I34: 30 | J34: Card | K34: =IF(OR(B34="",F34<>"Done",J34="Package"),"",IF(N(G34)-N(I34)>0,N(G34)-N(I34),"")) | M34: =IF(OR(B34="",D34="",F34="Cancelled"),"",B34+N(C34)+ROW()/10000000) | N34: =IF(AND(F34="Done",M34<>""),IF(COUNTIFS(Appointments!$D$6:$D$2005,D34,Appointments!$F$6:$F$2005,"Done",Appointments!$M$6:$M$2005,">"&M34)=0,1,0),0) | O34: =IF(AND(F34="Booked",M34<>"",N(B34)>=TODAY()),IF(COUNTIFS(Appointments!$D$6:$D$2005,D34,Appointments!$F$6:$F$2005,"Booked",Appointments!$B$6:$B$2005,">="&TODAY(),Appointments!$M$6:$M$2005,"<"&M34)=0,1,0),0)
B35: 46035 | C35: 0.51388889 | D35: Pete Young | E35: Men's haircut | F35: Cancelled | G35: =IF(E35="","",MAX(0,IFERROR(INDEX(Services!$C$6:$C$35,MATCH(E35,Services!$B$6:$B$35,0)),0)-N(H35))) | K35: =IF(OR(B35="",F35<>"Done",J35="Package"),"",IF(N(G35)-N(I35)>0,N(G35)-N(I35),"")) | M35: =IF(OR(B35="",D35="",F35="Cancelled"),"",B35+N(C35)+ROW()/10000000) | N35: =IF(AND(F35="Done",M35<>""),IF(COUNTIFS(Appointments!$D$6:$D$2005,D35,Appointments!$F$6:$F$2005,"Done",Appointments!$M$6:$M$2005,">"&M35)=0,1,0),0) | O35: =IF(AND(F35="Booked",M35<>"",N(B35)>=TODAY()),IF(COUNTIFS(Appointments!$D$6:$D$2005,D35,Appointments!$F$6:$F$2005,"Booked",Appointments!$B$6:$B$2005,">="&TODAY(),Appointments!$M$6:$M$2005,"<"&M35)=0,1,0),0)
B36: 46035 | C36: 0.54166667 | D36: Uma Nair | E36: Women's haircut | F36: Cancelled | G36: =IF(E36="","",MAX(0,IFERROR(INDEX(Services!$C$6:$C$35,MATCH(E36,Services!$B$6:$B$35,0)),0)-N(H36))) | K36: =IF(OR(B36="",F36<>"Done",J36="Package"),"",IF(N(G36)-N(I36)>0,N(G36)-N(I36),"")) | M36: =IF(OR(B36="",D36="",F36="Cancelled"),"",B36+N(C36)+ROW()/10000000) | N36: =IF(AND(F36="Done",M36<>""),IF(COUNTIFS(Appointments!$D$6:$D$2005,D36,Appointments!$F$6:$F$2005,"Done",Appointments!$M$6:$M$2005,">"&M36)=0,1,0),0) | O36: =IF(AND(F36="Booked",M36<>"",N(B36)>=TODAY()),IF(COUNTIFS(Appointments!$D$6:$D$2005,D36,Appointments!$F$6:$F$2005,"Booked",Appointments!$B$6:$B$2005,">="&TODAY(),Appointments!$M$6:$M$2005,"<"&M36)=0,1,0),0)
B37: 46036 | C37: 0.375 | D37: Ben Carter | E37: Men's haircut | F37: Done | G37: =IF(E37="","",MAX(0,IFERROR(INDEX(Services!$C$6:$C$35,MATCH(E37,Services!$B$6:$B$35,0)),0)-N(H37))) | I37: 30 | J37: Card | K37: =IF(OR(B37="",F37<>"Done",J37="Package"),"",IF(N(G37)-N(I37)>0,N(G37)-N(I37),"")) | M37: =IF(OR(B37="",D37="",F37="Cancelled"),"",B37+N(C37)+ROW()/10000000) | N37: =IF(AND(F37="Done",M37<>""),IF(COUNTIFS(Appointments!$D$6:$D$2005,D37,Appointments!$F$6:$F$2005,"Done",Appointments!$M$6:$M$2005,">"&M37)=0,1,0),0) | O37: =IF(AND(F37="Booked",M37<>"",N(B37)>=TODAY()),IF(COUNTIFS(Appointments!$D$6:$D$2005,D37,Appointments!$F$6:$F$2005,"Booked",Appointments!$B$6:$B$2005,">="&TODAY(),Appointments!$M$6:$M$2005,"<"&M37)=0,1,0),0)
B38: 46036 | C38: 0.40277778 | D38: Dina Baker | E38: Women's haircut | F38: Done | G38: =IF(E38="","",MAX(0,IFERROR(INDEX(Services!$C$6:$C$35,MATCH(E38,Services!$B$6:$B$35,0)),0)-N(H38))) | I38: 55 | J38: Card | K38: =IF(OR(B38="",F38<>"Done",J38="Package"),"",IF(N(G38)-N(I38)>0,N(G38)-N(I38),"")) | M38: =IF(OR(B38="",D38="",F38="Cancelled"),"",B38+N(C38)+ROW()/10000000) | N38: =IF(AND(F38="Done",M38<>""),IF(COUNTIFS(Appointments!$D$6:$D$2005,D38,Appointments!$F$6:$F$2005,"Done",Appointments!$M$6:$M$2005,">"&M38)=0,1,0),0) | O38: =IF(AND(F38="Booked",M38<>"",N(B38)>=TODAY()),IF(COUNTIFS(Appointments!$D$6:$D$2005,D38,Appointments!$F$6:$F$2005,"Booked",Appointments!$B$6:$B$2005,">="&TODAY(),Appointments!$M$6:$M$2005,"<"&M38)=0,1,0),0)
B39: 46036 | C39: 0.45138889 | D39: Eli Hughes | E39: Men's haircut | F39: Done | G39: =IF(E39="","",MAX(0,IFERROR(INDEX(Services!$C$6:$C$35,MATCH(E39,Services!$B$6:$B$35,0)),0)-N(H39))) | I39: 30 | J39: Card | K39: =IF(OR(B39="",F39<>"Done",J39="Package"),"",IF(N(G39)-N(I39)>0,N(G39)-N(I39),"")) | M39: =IF(OR(B39="",D39="",F39="Cancelled"),"",B39+N(C39)+ROW()/10000000) | N39: =IF(AND(F39="Done",M39<>""),IF(COUNTIFS(Appointments!$D$6:$D$2005,D39,Appointments!$F$6:$F$2005,"Done",Appointments!$M$6:$M$2005,">"&M39)=0,1,0),0) | O39: =IF(AND(F39="Booked",M39<>"",N(B39)>=TODAY()),IF(COUNTIFS(Appointments!$D$6:$D$2005,D39,Appointments!$F$6:$F$2005,"Booked",Appointments!$B$6:$B$2005,">="&TODAY(),Appointments!$M$6:$M$2005,"<"&M39)=0,1,0),0)
B40: 46036 | C40: 0.47916667 | D40: Jade Hill | E40: Women's haircut | F40: Done | G40: =IF(E40="","",MAX(0,IFERROR(INDEX(Services!$C$6:$C$35,MATCH(E40,Services!$B$6:$B$35,0)),0)-N(H40))) | I40: 55 | J40: Cash | K40: =IF(OR(B40="",F40<>"Done",J40="Package"),"",IF(N(G40)-N(I40)>0,N(G40)-N(I40),"")) | M40: =IF(OR(B40="",D40="",F40="Cancelled"),"",B40+N(C40)+ROW()/10000000) | N40: =IF(AND(F40="Done",M40<>""),IF(COUNTIFS(Appointments!$D$6:$D$2005,D40,Appointments!$F$6:$F$2005,"Done",Appointments!$M$6:$M$2005,">"&M40)=0,1,0),0) | O40: =IF(AND(F40="Booked",M40<>"",N(B40)>=TODAY()),IF(COUNTIFS(Appointments!$D$6:$D$2005,D40,Appointments!$F$6:$F$2005,"Booked",Appointments!$B$6:$B$2005,">="&TODAY(),Appointments!$M$6:$M$2005,"<"&M40)=0,1,0),0)
B41: 46036 | C41: 0.52777778 | D41: Jon Reid | E41: Men's haircut | F41: Done | G41: =IF(E41="","",MAX(0,IFERROR(INDEX(Services!$C$6:$C$35,MATCH(E41,Services!$B$6:$B$35,0)),0)-N(H41))) | I41: 30 | J41: Cash | K41: =IF(OR(B41="",F41<>"Done",J41="Package"),"",IF(N(G41)-N(I41)>0,N(G41)-N(I41),"")) | M41: =IF(OR(B41="",D41="",F41="Cancelled"),"",B41+N(C41)+ROW()/10000000) | N41: =IF(AND(F41="Done",M41<>""),IF(COUNTIFS(Appointments!$D$6:$D$2005,D41,Appointments!$F$6:$F$2005,"Done",Appointments!$M$6:$M$2005,">"&M41)=0,1,0),0) | O41: =IF(AND(F41="Booked",M41<>"",N(B41)>=TODAY()),IF(COUNTIFS(Appointments!$D$6:$D$2005,D41,Appointments!$F$6:$F$2005,"Booked",Appointments!$B$6:$B$2005,">="&TODAY(),Appointments!$M$6:$M$2005,"<"&M41)=0,1,0),0)
B42: 46036 | C42: 0.55555556 | D42: Sam Clarke | E42: Men's haircut | F42: Done | G42: =IF(E42="","",MAX(0,IFERROR(INDEX(Services!$C$6:$C$35,MATCH(E42,Services!$B$6:$B$35,0)),0)-N(H42))) | I42: 30 | J42: Card | K42: =IF(OR(B42="",F42<>"Done",J42="Package"),"",IF(N(G42)-N(I42)>0,N(G42)-N(I42),"")) | M42: =IF(OR(B42="",D42="",F42="Cancelled"),"",B42+N(C42)+ROW()/10000000) | N42: =IF(AND(F42="Done",M42<>""),IF(COUNTIFS(Appointments!$D$6:$D$2005,D42,Appointments!$F$6:$F$2005,"Done",Appointments!$M$6:$M$2005,">"&M42)=0,1,0),0) | O42: =IF(AND(F42="Booked",M42<>"",N(B42)>=TODAY()),IF(COUNTIFS(Appointments!$D$6:$D$2005,D42,Appointments!$F$6:$F$2005,"Booked",Appointments!$B$6:$B$2005,">="&TODAY(),Appointments!$M$6:$M$2005,"<"&M42)=0,1,0),0)
...

Sheet Clients
B2: Clients
B3: One line per client. Visits, payments and package sessions come from the other tabs.
B5: Client | C5: Phone | D5: Email | E5: Birthday | F5: Client since | G5: Notes | H5: Visits | I5: Last visit | J5: Next booking | K5: Paid in total | L5: Owes | M5: Sessions left | N5: Follow up
B6: Anna Rossi | C6: 555 0101 | D6: anna.r@example.com | E6: 32400 | F6: 45353 | G6: Likes it shorter at the back | H6: =IF(B6="","",COUNTIFS(Appointments!$D$6:$D$2005,B6,Appointments!$F$6:$F$2005,"Done")) | I6: =IF(OR(B6="",N(H6)=0),"",INT(SUMIFS(Appointments!$M$6:$M$2005,Appointments!$D$6:$D$2005,B6,Appointments!$N$6:$N$2005,1))) | J6: =IF(B6="","",IF(SUMIFS(Appointments!$M$6:$M$2005,Appointments!$D$6:$D$2005,B6,Appointments!$O$6:$O$2005,1)=0,"",INT(SUMIFS(Appointments!$M$6:$M$2005,Appointments!$D$6:$D$2005,B6,Appointments!$O$6:$O$2005,1)))) | K6: =IF(B6="","",SUMIFS(Appointments!$I$6:$I$2005,Appointments!$D$6:$D$2005,B6)+SUMIFS(Packages!$F$6:$F$305,Packages!$C$6:$C$305,B6)) | L6: =IF(B6="","",IF(SUMIFS(Appointments!$K$6:$K$2005,Appointments!$D$6:$D$2005,B6)=0,"",SUMIFS(Appointments!$K$6:$K$2005,Appointments!$D$6:$D$2005,B6))) | M6: =IF(OR(B6="",SUMIFS(Packages!$E$6:$E$305,Packages!$C$6:$C$305,B6)=0),"",SUMIFS(Packages!$E$6:$E$305,Packages!$C$6:$C$305,B6)-COUNTIFS(Appointments!$D$6:$D$2005,B6,Appointments!$J$6:$J$2005,"Package",Appointments!$F$6:$F$2005,"Done")+IF(Services!$I$6="Yes",COUNTIFS(Appointments!$D$6:$D$2005,B6,Appointments!$J$6:$J$2005,"Package",Appointments!$F$6:$F$2005,"No-show"),0)) | N6: =IF(OR(B6="",I6=""),"",IF(AND(J6="",TODAY()-I6>=N(Services!$I$7)),"Not seen for "&(TODAY()-I6)&" days","")) | O6: =IF(N(E6)=0,"",MONTH(E6))
B7: Ben Carter | C7: 555 0102 | F7: 45250 | H7: =IF(B7="","",COUNTIFS(Appointments!$D$6:$D$2005,B7,Appointments!$F$6:$F$2005,"Done")) | I7: =IF(OR(B7="",N(H7)=0),"",INT(SUMIFS(Appointments!$M$6:$M$2005,Appointments!$D$6:$D$2005,B7,Appointments!$N$6:$N$2005,1))) | J7: =IF(B7="","",IF(SUMIFS(Appointments!$M$6:$M$2005,Appointments!$D$6:$D$2005,B7,Appointments!$O$6:$O$2005,1)=0,"",INT(SUMIFS(Appointments!$M$6:$M$2005,Appointments!$D$6:$D$2005,B7,Appointments!$O$6:$O$2005,1)))) | K7: =IF(B7="","",SUMIFS(Appointments!$I$6:$I$2005,Appointments!$D$6:$D$2005,B7)+SUMIFS(Packages!$F$6:$F$305,Packages!$C$6:$C$305,B7)) | L7: =IF(B7="","",IF(SUMIFS(Appointments!$K$6:$K$2005,Appointments!$D$6:$D$2005,B7)=0,"",SUMIFS(Appointments!$K$6:$K$2005,Appointments!$D$6:$D$2005,B7))) | M7: =IF(OR(B7="",SUMIFS(Packages!$E$6:$E$305,Packages!$C$6:$C$305,B7)=0),"",SUMIFS(Packages!$E$6:$E$305,Packages!$C$6:$C$305,B7)-COUNTIFS(Appointments!$D$6:$D$2005,B7,Appointments!$J$6:$J$2005,"Package",Appointments!$F$6:$F$2005,"Done")+IF(Services!$I$6="Yes",COUNTIFS(Appointments!$D$6:$D$2005,B7,Appointments!$J$6:$J$2005,"Package",Appointments!$F$6:$F$2005,"No-show"),0)) | N7: =IF(OR(B7="",I7=""),"",IF(AND(J7="",TODAY()-I7>=N(Services!$I$7)),"Not seen for "&(TODAY()-I7)&" days","")) | O7: =IF(N(E7)=0,"",MONTH(E7))
B8: Chloe Martin | C8: 555 0103 | D8: chloe.m@example.com | E8: 33637 | F8: 44723 | G8: Blow dry card since September | H8: =IF(B8="","",COUNTIFS(Appointments!$D$6:$D$2005,B8,Appointments!$F$6:$F$2005,"Done")) | I8: =IF(OR(B8="",N(H8)=0),"",INT(SUMIFS(Appointments!$M$6:$M$2005,Appointments!$D$6:$D$2005,B8,Appointments!$N$6:$N$2005,1))) | J8: =IF(B8="","",IF(SUMIFS(Appointments!$M$6:$M$2005,Appointments!$D$6:$D$2005,B8,Appointments!$O$6:$O$2005,1)=0,"",INT(SUMIFS(Appointments!$M$6:$M$2005,Appointments!$D$6:$D$2005,B8,Appointments!$O$6:$O$2005,1)))) | K8: =IF(B8="","",SUMIFS(Appointments!$I$6:$I$2005,Appointments!$D$6:$D$2005,B8)+SUMIFS(Packages!$F$6:$F$305,Packages!$C$6:$C$305,B8)) | L8: =IF(B8="","",IF(SUMIFS(Appointments!$K$6:$K$2005,Appointments!$D$6:$D$2005,B8)=0,"",SUMIFS(Appointments!$K$6:$K$2005,Appointments!$D$6:$D$2005,B8))) | M8: =IF(OR(B8="",SUMIFS(Packages!$E$6:$E$305,Packages!$C$6:$C$305,B8)=0),"",SUMIFS(Packages!$E$6:$E$305,Packages!$C$6:$C$305,B8)-COUNTIFS(Appointments!$D$6:$D$2005,B8,Appointments!$J$6:$J$2005,"Package",Appointments!$F$6:$F$2005,"Done")+IF(Services!$I$6="Yes",COUNTIFS(Appointments!$D$6:$D$2005,B8,Appointments!$J$6:$J$2005,"Package",Appointments!$F$6:$F$2005,"No-show"),0)) | N8: =IF(OR(B8="",I8=""),"",IF(AND(J8="",TODAY()-I8>=N(Services!$I$7)),"Not seen for "&(TODAY()-I8)&" days","")) | O8: =IF(N(E8)=0,"",MONTH(E8))
B9: Daniel Kim | C9: 555 0104 | E9: 33208 | F9: 45306 | H9: =IF(B9="","",COUNTIFS(Appointments!$D$6:$D$2005,B9,Appointments!$F$6:$F$2005,"Done")) | I9: =IF(OR(B9="",N(H9)=0),"",INT(SUMIFS(Appointments!$M$6:$M$2005,Appointments!$D$6:$D$2005,B9,Appointments!$N$6:$N$2005,1))) | J9: =IF(B9="","",IF(SUMIFS(Appointments!$M$6:$M$2005,Appointments!$D$6:$D$2005,B9,Appointments!$O$6:$O$2005,1)=0,"",INT(SUMIFS(Appointments!$M$6:$M$2005,Appointments!$D$6:$D$2005,B9,Appointments!$O$6:$O$2005,1)))) | K9: =IF(B9="","",SUMIFS(Appointments!$I$6:$I$2005,Appointments!$D$6:$D$2005,B9)+SUMIFS(Packages!$F$6:$F$305,Packages!$C$6:$C$305,B9)) | L9: =IF(B9="","",IF(SUMIFS(Appointments!$K$6:$K$2005,Appointments!$D$6:$D$2005,B9)=0,"",SUMIFS(Appointments!$K$6:$K$2005,Appointments!$D$6:$D$2005,B9))) | M9: =IF(OR(B9="",SUMIFS(Packages!$E$6:$E$305,Packages!$C$6:$C$305,B9)=0),"",SUMIFS(Packages!$E$6:$E$305,Packages!$C$6:$C$305,B9)-COUNTIFS(Appointments!$D$6:$D$2005,B9,Appointments!$J$6:$J$2005,"Package",Appointments!$F$6:$F$2005,"Done")+IF(Services!$I$6="Yes",COUNTIFS(Appointments!$D$6:$D$2005,B9,Appointments!$J$6:$J$2005,"Package",Appointments!$F$6:$F$2005,"No-show"),0)) | N9: =IF(OR(B9="",I9=""),"",IF(AND(J9="",TODAY()-I9>=N(Services!$I$7)),"Not seen for "&(TODAY()-I9)&" days","")) | O9: =IF(N(E9)=0,"",MONTH(E9))
B10: Emma Johnson | C10: 555 0105 | D10: emma.j@example.com | E10: 34811 | F10: 45051 | G10: Blow dry card | H10: =IF(B10="","",COUNTIFS(Appointments!$D$6:$D$2005,B10,Appointments!$F$6:$F$2005,"Done")) | I10: =IF(OR(B10="",N(H10)=0),"",INT(SUMIFS(Appointments!$M$6:$M$2005,Appointments!$D$6:$D$2005,B10,Appointments!$N$6:$N$2005,1))) | J10: =IF(B10="","",IF(SUMIFS(Appointments!$M$6:$M$2005,Appointments!$D$6:$D$2005,B10,Appointments!$O$6:$O$2005,1)=0,"",INT(SUMIFS(Appointments!$M$6:$M$2005,Appointments!$D$6:$D$2005,B10,Appointments!$O$6:$O$2005,1)))) | K10: =IF(B10="","",SUMIFS(Appointments!$I$6:$I$2005,Appointments!$D$6:$D$2005,B10)+SUMIFS(Packages!$F$6:$F$305,Packages!$C$6:$C$305,B10)) | L10: =IF(B10="","",IF(SUMIFS(Appointments!$K$6:$K$2005,Appointments!$D$6:$D$2005,B10)=0,"",SUMIFS(Appointments!$K$6:$K$2005,Appointments!$D$6:$D$2005,B10))) | M10: =IF(OR(B10="",SUMIFS(Packages!$E$6:$E$305,Packages!$C$6:$C$305,B10)=0),"",SUMIFS(Packages!$E$6:$E$305,Packages!$C$6:$C$305,B10)-COUNTIFS(Appointments!$D$6:$D$2005,B10,Appointments!$J$6:$J$2005,"Package",Appointments!$F$6:$F$2005,"Done")+IF(Services!$I$6="Yes",COUNTIFS(Appointments!$D$6:$D$2005,B10,Appointments!$J$6:$J$2005,"Package",Appointments!$F$6:$F$2005,"No-show"),0)) | N10: =IF(OR(B10="",I10=""),"",IF(AND(J10="",TODAY()-I10>=N(Services!$I$7)),"Not seen for "&(TODAY()-I10)&" days","")) | O10: =IF(N(E10)=0,"",MONTH(E10))
B11: Farah Ali | C11: 555 0106 | E11: 31237 | F11: 44469 | G11: Patch test before colour | H11: =IF(B11="","",COUNTIFS(Appointments!$D$6:$D$2005,B11,Appointments!$F$6:$F$2005,"Done")) | I11: =IF(OR(B11="",N(H11)=0),"",INT(SUMIFS(Appointments!$M$6:$M$2005,Appointments!$D$6:$D$2005,B11,Appointments!$N$6:$N$2005,1))) | J11: =IF(B11="","",IF(SUMIFS(Appointments!$M$6:$M$2005,Appointments!$D$6:$D$2005,B11,Appointments!$O$6:$O$2005,1)=0,"",INT(SUMIFS(Appointments!$M$6:$M$2005,Appointments!$D$6:$D$2005,B11,Appointments!$O$6:$O$2005,1)))) | K11: =IF(B11="","",SUMIFS(Appointments!$I$6:$I$2005,Appointments!$D$6:$D$2005,B11)+SUMIFS(Packages!$F$6:$F$305,Packages!$C$6:$C$305,B11)) | L11: =IF(B11="","",IF(SUMIFS(Appointments!$K$6:$K$2005,Appointments!$D$6:$D$2005,B11)=0,"",SUMIFS(Appointments!$K$6:$K$2005,Appointments!$D$6:$D$2005,B11))) | M11: =IF(OR(B11="",SUMIFS(Packages!$E$6:$E$305,Packages!$C$6:$C$305,B11)=0),"",SUMIFS(Packages!$E$6:$E$305,Packages!$C$6:$C$305,B11)-COUNTIFS(Appointments!$D$6:$D$2005,B11,Appointments!$J$6:$J$2005,"Package",Appointments!$F$6:$F$2005,"Done")+IF(Services!$I$6="Yes",COUNTIFS(Appointments!$D$6:$D$2005,B11,Appointments!$J$6:$J$2005,"Package",Appointments!$F$6:$F$2005,"No-show"),0)) | N11: =IF(OR(B11="",I11=""),"",IF(AND(J11="",TODAY()-I11>=N(Services!$I$7)),"Not seen for "&(TODAY()-I11)&" days","")) | O11: =IF(N(E11)=0,"",MONTH(E11))
B12: Grace Lee | C12: 555 0107 | D12: grace.l@example.com | F12: 45512 | H12: =IF(B12="","",COUNTIFS(Appointments!$D$6:$D$2005,B12,Appointments!$F$6:$F$2005,"Done")) | I12: =IF(OR(B12="",N(H12)=0),"",INT(SUMIFS(Appointments!$M$6:$M$2005,Appointments!$D$6:$D$2005,B12,Appointments!$N$6:$N$2005,1))) | J12: =IF(B12="","",IF(SUMIFS(Appointments!$M$6:$M$2005,Appointments!$D$6:$D$2005,B12,Appointments!$O$6:$O$2005,1)=0,"",INT(SUMIFS(Appointments!$M$6:$M$2005,Appointments!$D$6:$D$2005,B12,Appointments!$O$6:$O$2005,1)))) | K12: =IF(B12="","",SUMIFS(Appointments!$I$6:$I$2005,Appointments!$D$6:$D$2005,B12)+SUMIFS(Packages!$F$6:$F$305,Packages!$C$6:$C$305,B12)) | L12: =IF(B12="","",IF(SUMIFS(Appointments!$K$6:$K$2005,Appointments!$D$6:$D$2005,B12)=0,"",SUMIFS(Appointments!$K$6:$K$2005,Appointments!$D$6:$D$2005,B12))) | M12: =IF(OR(B12="",SUMIFS(Packages!$E$6:$E$305,Packages!$C$6:$C$305,B12)=0),"",SUMIFS(Packages!$E$6:$E$305,Packages!$C$6:$C$305,B12)-COUNTIFS(Appointments!$D$6:$D$2005,B12,Appointments!$J$6:$J$2005,"Package",Appointments!$F$6:$F$2005,"Done")+IF(Services!$I$6="Yes",COUNTIFS(Appointments!$D$6:$D$2005,B12,Appointments!$J$6:$J$2005,"Package",Appointments!$F$6:$F$2005,"No-show"),0)) | N12: =IF(OR(B12="",I12=""),"",IF(AND(J12="",TODAY()-I12>=N(Services!$I$7)),"Not seen for "&(TODAY()-I12)&" days","")) | O12: =IF(N(E12)=0,"",MONTH(E12))
B13: Hugo Silva | C13: 555 0108 | E13: 31853 | F13: 44958 | H13: =IF(B13="","",COUNTIFS(Appointments!$D$6:$D$2005,B13,Appointments!$F$6:$F$2005,"Done")) | I13: =IF(OR(B13="",N(H13)=0),"",INT(SUMIFS(Appointments!$M$6:$M$2005,Appointments!$D$6:$D$2005,B13,Appointments!$N$6:$N$2005,1))) | J13: =IF(B13="","",IF(SUMIFS(Appointments!$M$6:$M$2005,Appointments!$D$6:$D$2005,B13,Appointments!$O$6:$O$2005,1)=0,"",INT(SUMIFS(Appointments!$M$6:$M$2005,Appointments!$D$6:$D$2005,B13,Appointments!$O$6:$O$2005,1)))) | K13: =IF(B13="","",SUMIFS(Appointments!$I$6:$I$2005,Appointments!$D$6:$D$2005,B13)+SUMIFS(Packages!$F$6:$F$305,Packages!$C$6:$C$305,B13)) | L13: =IF(B13="","",IF(SUMIFS(Appointments!$K$6:$K$2005,Appointments!$D$6:$D$2005,B13)=0,"",SUMIFS(Appointments!$K$6:$K$2005,Appointments!$D$6:$D$2005,B13))) | M13: =IF(OR(B13="",SUMIFS(Packages!$E$6:$E$305,Packages!$C$6:$C$305,B13)=0),"",SUMIFS(Packages!$E$6:$E$305,Packages!$C$6:$C$305,B13)-COUNTIFS(Appointments!$D$6:$D$2005,B13,Appointments!$J$6:$J$2005,"Package",Appointments!$F$6:$F$2005,"Done")+IF(Services!$I$6="Yes",COUNTIFS(Appointments!$D$6:$D$2005,B13,Appointments!$J$6:$J$2005,"Package",Appointments!$F$6:$F$2005,"No-show"),0)) | N13: =IF(OR(B13="",I13=""),"",IF(AND(J13="",TODAY()-I13>=N(Services!$I$7)),"Not seen for "&(TODAY()-I13)&" days","")) | O13: =IF(N(E13)=0,"",MONTH(E13))
B14: Isla Brown | C14: 555 0109 | F14: 44838 | G14: Sensitive scalp | H14: =IF(B14="","",COUNTIFS(Appointments!$D$6:$D$2005,B14,Appointments!$F$6:$F$2005,"Done")) | I14: =IF(OR(B14="",N(H14)=0),"",INT(SUMIFS(Appointments!$M$6:$M$2005,Appointments!$D$6:$D$2005,B14,Appointments!$N$6:$N$2005,1))) | J14: =IF(B14="","",IF(SUMIFS(Appointments!$M$6:$M$2005,Appointments!$D$6:$D$2005,B14,Appointments!$O$6:$O$2005,1)=0,"",INT(SUMIFS(Appointments!$M$6:$M$2005,Appointments!$D$6:$D$2005,B14,Appointments!$O$6:$O$2005,1)))) | K14: =IF(B14="","",SUMIFS(Appointments!$I$6:$I$2005,Appointments!$D$6:$D$2005,B14)+SUMIFS(Packages!$F$6:$F$305,Packages!$C$6:$C$305,B14)) | L14: =IF(B14="","",IF(SUMIFS(Appointments!$K$6:$K$2005,Appointments!$D$6:$D$2005,B14)=0,"",SUMIFS(Appointments!$K$6:$K$2005,Appointments!$D$6:$D$2005,B14))) | M14: =IF(OR(B14="",SUMIFS(Packages!$E$6:$E$305,Packages!$C$6:$C$305,B14)=0),"",SUMIFS(Packages!$E$6:$E$305,Packages!$C$6:$C$305,B14)-COUNTIFS(Appointments!$D$6:$D$2005,B14,Appointments!$J$6:$J$2005,"Package",Appointments!$F$6:$F$2005,"Done")+IF(Services!$I$6="Yes",COUNTIFS(Appointments!$D$6:$D$2005,B14,Appointments!$J$6:$J$2005,"Package",Appointments!$F$6:$F$2005,"No-show"),0)) | N14: =IF(OR(B14="",I14=""),"",IF(AND(J14="",TODAY()-I14>=N(Services!$I$7)),"Not seen for "&(TODAY()-I14)&" days","")) | O14: =IF(N(E14)=0,"",MONTH(E14))
B15: Jack Wilson | C15: 555 0110 | F15: 45433 | H15: =IF(B15="","",COUNTIFS(Appointments!$D$6:$D$2005,B15,Appointments!$F$6:$F$2005,"Done")) | I15: =IF(OR(B15="",N(H15)=0),"",INT(SUMIFS(Appointments!$M$6:$M$2005,Appointments!$D$6:$D$2005,B15,Appointments!$N$6:$N$2005,1))) | J15: =IF(B15="","",IF(SUMIFS(Appointments!$M$6:$M$2005,Appointments!$D$6:$D$2005,B15,Appointments!$O$6:$O$2005,1)=0,"",INT(SUMIFS(Appointments!$M$6:$M$2005,Appointments!$D$6:$D$2005,B15,Appointments!$O$6:$O$2005,1)))) | K15: =IF(B15="","",SUMIFS(Appointments!$I$6:$I$2005,Appointments!$D$6:$D$2005,B15)+SUMIFS(Packages!$F$6:$F$305,Packages!$C$6:$C$305,B15)) | L15: =IF(B15="","",IF(SUMIFS(Appointments!$K$6:$K$2005,Appointments!$D$6:$D$2005,B15)=0,"",SUMIFS(Appointments!$K$6:$K$2005,Appointments!$D$6:$D$2005,B15))) | M15: =IF(OR(B15="",SUMIFS(Packages!$E$6:$E$305,Packages!$C$6:$C$305,B15)=0),"",SUMIFS(Packages!$E$6:$E$305,Packages!$C$6:$C$305,B15)-COUNTIFS(Appointments!$D$6:$D$2005,B15,Appointments!$J$6:$J$2005,"Package",Appointments!$F$6:$F$2005,"Done")+IF(Services!$I$6="Yes",COUNTIFS(Appointments!$D$6:$D$2005,B15,Appointments!$J$6:$J$2005,"Package",Appointments!$F$6:$F$2005,"No-show"),0)) | N15: =IF(OR(B15="",I15=""),"",IF(AND(J15="",TODAY()-I15>=N(Services!$I$7)),"Not seen for "&(TODAY()-I15)&" days","")) | O15: =IF(N(E15)=0,"",MONTH(E15))
B16: Katie Moore | C16: 555 0111 | D16: katie.m@example.com | E16: 34281 | F16: 45114 | H16: =IF(B16="","",COUNTIFS(Appointments!$D$6:$D$2005,B16,Appointments!$F$6:$F$2005,"Done")) | I16: =IF(OR(B16="",N(H16)=0),"",INT(SUMIFS(Appointments!$M$6:$M$2005,Appointments!$D$6:$D$2005,B16,Appointments!$N$6:$N$2005,1))) | J16: =IF(B16="","",IF(SUMIFS(Appointments!$M$6:$M$2005,Appointments!$D$6:$D$2005,B16,Appointments!$O$6:$O$2005,1)=0,"",INT(SUMIFS(Appointments!$M$6:$M$2005,Appointments!$D$6:$D$2005,B16,Appointments!$O$6:$O$2005,1)))) | K16: =IF(B16="","",SUMIFS(Appointments!$I$6:$I$2005,Appointments!$D$6:$D$2005,B16)+SUMIFS(Packages!$F$6:$F$305,Packages!$C$6:$C$305,B16)) | L16: =IF(B16="","",IF(SUMIFS(Appointments!$K$6:$K$2005,Appointments!$D$6:$D$2005,B16)=0,"",SUMIFS(Appointments!$K$6:$K$2005,Appointments!$D$6:$D$2005,B16))) | M16: =IF(OR(B16="",SUMIFS(Packages!$E$6:$E$305,Packages!$C$6:$C$305,B16)=0),"",SUMIFS(Packages!$E$6:$E$305,Packages!$C$6:$C$305,B16)-COUNTIFS(Appointments!$D$6:$D$2005,B16,Appointments!$J$6:$J$2005,"Package",Appointments!$F$6:$F$2005,"Done")+IF(Services!$I$6="Yes",COUNTIFS(Appointments!$D$6:$D$2005,B16,Appointments!$J$6:$J$2005,"Package",Appointments!$F$6:$F$2005,"No-show"),0)) | N16: =IF(OR(B16="",I16=""),"",IF(AND(J16="",TODAY()-I16>=N(Services!$I$7)),"Not seen for "&(TODAY()-I16)&" days","")) | O16: =IF(N(E16)=0,"",MONTH(E16))
B17: Liam Evans | C17: 555 0112 | F17: 45667 | H17: =IF(B17="","",COUNTIFS(Appointments!$D$6:$D$2005,B17,Appointments!$F$6:$F$2005,"Done")) | I17: =IF(OR(B17="",N(H17)=0),"",INT(SUMIFS(Appointments!$M$6:$M$2005,Appointments!$D$6:$D$2005,B17,Appointments!$N$6:$N$2005,1))) | J17: =IF(B17="","",IF(SUMIFS(Appointments!$M$6:$M$2005,Appointments!$D$6:$D$2005,B17,Appointments!$O$6:$O$2005,1)=0,"",INT(SUMIFS(Appointments!$M$6:$M$2005,Appointments!$D$6:$D$2005,B17,Appointments!$O$6:$O$2005,1)))) | K17: =IF(B17="","",SUMIFS(Appointments!$I$6:$I$2005,Appointments!$D$6:$D$2005,B17)+SUMIFS(Packages!$F$6:$F$305,Packages!$C$6:$C$305,B17)) | L17: =IF(B17="","",IF(SUMIFS(Appointments!$K$6:$K$2005,Appointments!$D$6:$D$2005,B17)=0,"",SUMIFS(Appointments!$K$6:$K$2005,Appointments!$D$6:$D$2005,B17))) | M17: =IF(OR(B17="",SUMIFS(Packages!$E$6:$E$305,Packages!$C$6:$C$305,B17)=0),"",SUMIFS(Packages!$E$6:$E$305,Packages!$C$6:$C$305,B17)-COUNTIFS(Appointments!$D$6:$D$2005,B17,Appointments!$J$6:$J$2005,"Package",Appointments!$F$6:$F$2005,"Done")+IF(Services!$I$6="Yes",COUNTIFS(Appointments!$D$6:$D$2005,B17,Appointments!$J$6:$J$2005,"Package",Appointments!$F$6:$F$2005,"No-show"),0)) | N17: =IF(OR(B17="",I17=""),"",IF(AND(J17="",TODAY()-I17>=N(Services!$I$7)),"Not seen for "&(TODAY()-I17)&" days","")) | O17: =IF(N(E17)=0,"",MONTH(E17))
B18: Maya Patel | C18: 555 0113 | D18: maya.p@example.com | E18: 33414 | F18: 45336 | G18: Treatment card | H18: =IF(B18="","",COUNTIFS(Appointments!$D$6:$D$2005,B18,Appointments!$F$6:$F$2005,"Done")) | I18: =IF(OR(B18="",N(H18)=0),"",INT(SUMIFS(Appointments!$M$6:$M$2005,Appointments!$D$6:$D$2005,B18,Appointments!$N$6:$N$2005,1))) | J18: =IF(B18="","",IF(SUMIFS(Appointments!$M$6:$M$2005,Appointments!$D$6:$D$2005,B18,Appointments!$O$6:$O$2005,1)=0,"",INT(SUMIFS(Appointments!$M$6:$M$2005,Appointments!$D$6:$D$2005,B18,Appointments!$O$6:$O$2005,1)))) | K18: =IF(B18="","",SUMIFS(Appointments!$I$6:$I$2005,Appointments!$D$6:$D$2005,B18)+SUMIFS(Packages!$F$6:$F$305,Packages!$C$6:$C$305,B18)) | L18: =IF(B18="","",IF(SUMIFS(Appointments!$K$6:$K$2005,Appointments!$D$6:$D$2005,B18)=0,"",SUMIFS(Appointments!$K$6:$K$2005,Appointments!$D$6:$D$2005,B18))) | M18: =IF(OR(B18="",SUMIFS(Packages!$E$6:$E$305,Packages!$C$6:$C$305,B18)=0),"",SUMIFS(Packages!$E$6:$E$305,Packages!$C$6:$C$305,B18)-COUNTIFS(Appointments!$D$6:$D$2005,B18,Appointments!$J$6:$J$2005,"Package",Appointments!$F$6:$F$2005,"Done")+IF(Services!$I$6="Yes",COUNTIFS(Appointments!$D$6:$D$2005,B18,Appointments!$J$6:$J$2005,"Package",Appointments!$F$6:$F$2005,"No-show"),0)) | N18: =IF(OR(B18="",I18=""),"",IF(AND(J18="",TODAY()-I18>=N(Services!$I$7)),"Not seen for "&(TODAY()-I18)&" days","")) | O18: =IF(N(E18)=0,"",MONTH(E18))
