Workbook

Sheet Dashboard
B2: =IF(Settings!$C$4="","Home inventory",Settings!$C$4)
B3: ="What your things are worth, room by room, and the proof still to find."
B4: Worth in all | C4: Items | D4: Contents cover | E4: No receipt | G4: Cover less the list | H4: No photo | I4: Renews in (days)
B5: =SUM(Items!$T$6:$T$1005) | C5: =SUM(Items!$S$6:$S$1005) | D5: =IF(N(Settings!$C$6)=0,"",N(Settings!$C$6)) | E5: =SUM(Items!$W$6:$W$1005) | G5: =IF(N(Settings!$C$6)=0,"",N(Settings!$C$6)-B5) | H5: =SUM(Items!$X$6:$X$1005) | I5: =IF(NOT(ISNUMBER(Settings!$C$9)),"",INT(Settings!$C$9)-TODAY())
B7: Room | C7: Items | D7: Worth | E7: Share | G7: Most valuable | H7: Room | I7: Worth
B8: =IF(INDEX(Rooms!$B$6:$B$35,1)="","",INDEX(Rooms!$B$6:$B$35,1)) | C8: =IF(B8="","",INDEX(Rooms!$D$6:$D$35,1)) | D8: =IF(B8="","",INDEX(Rooms!$E$6:$E$35,1)) | E8: =IF(OR(B8="",N($B$5)=0),"",D8/$B$5) | G8: =IF(L8="","",INDEX(Items!$C$1:$C$1005,10000-MOD(L8,10000))) | H8: =IF(L8="","",INDEX(Items!$B$1:$B$1005,10000-MOD(L8,10000))) | I8: =IF(L8="","",INDEX(Items!$N$1:$N$1005,10000-MOD(L8,10000))) | L8: =IFERROR(LARGE(Items!$U$6:$U$1005,1),"")
B9: =IF(INDEX(Rooms!$B$6:$B$35,2)="","",INDEX(Rooms!$B$6:$B$35,2)) | C9: =IF(B9="","",INDEX(Rooms!$D$6:$D$35,2)) | D9: =IF(B9="","",INDEX(Rooms!$E$6:$E$35,2)) | E9: =IF(OR(B9="",N($B$5)=0),"",D9/$B$5) | G9: =IF(L9="","",INDEX(Items!$C$1:$C$1005,10000-MOD(L9,10000))) | H9: =IF(L9="","",INDEX(Items!$B$1:$B$1005,10000-MOD(L9,10000))) | I9: =IF(L9="","",INDEX(Items!$N$1:$N$1005,10000-MOD(L9,10000))) | L9: =IFERROR(LARGE(Items!$U$6:$U$1005,2),"")
B10: =IF(INDEX(Rooms!$B$6:$B$35,3)="","",INDEX(Rooms!$B$6:$B$35,3)) | C10: =IF(B10="","",INDEX(Rooms!$D$6:$D$35,3)) | D10: =IF(B10="","",INDEX(Rooms!$E$6:$E$35,3)) | E10: =IF(OR(B10="",N($B$5)=0),"",D10/$B$5) | G10: =IF(L10="","",INDEX(Items!$C$1:$C$1005,10000-MOD(L10,10000))) | H10: =IF(L10="","",INDEX(Items!$B$1:$B$1005,10000-MOD(L10,10000))) | I10: =IF(L10="","",INDEX(Items!$N$1:$N$1005,10000-MOD(L10,10000))) | L10: =IFERROR(LARGE(Items!$U$6:$U$1005,3),"")
B11: =IF(INDEX(Rooms!$B$6:$B$35,4)="","",INDEX(Rooms!$B$6:$B$35,4)) | C11: =IF(B11="","",INDEX(Rooms!$D$6:$D$35,4)) | D11: =IF(B11="","",INDEX(Rooms!$E$6:$E$35,4)) | E11: =IF(OR(B11="",N($B$5)=0),"",D11/$B$5) | G11: =IF(L11="","",INDEX(Items!$C$1:$C$1005,10000-MOD(L11,10000))) | H11: =IF(L11="","",INDEX(Items!$B$1:$B$1005,10000-MOD(L11,10000))) | I11: =IF(L11="","",INDEX(Items!$N$1:$N$1005,10000-MOD(L11,10000))) | L11: =IFERROR(LARGE(Items!$U$6:$U$1005,4),"")
B12: =IF(INDEX(Rooms!$B$6:$B$35,5)="","",INDEX(Rooms!$B$6:$B$35,5)) | C12: =IF(B12="","",INDEX(Rooms!$D$6:$D$35,5)) | D12: =IF(B12="","",INDEX(Rooms!$E$6:$E$35,5)) | E12: =IF(OR(B12="",N($B$5)=0),"",D12/$B$5) | G12: =IF(L12="","",INDEX(Items!$C$1:$C$1005,10000-MOD(L12,10000))) | H12: =IF(L12="","",INDEX(Items!$B$1:$B$1005,10000-MOD(L12,10000))) | I12: =IF(L12="","",INDEX(Items!$N$1:$N$1005,10000-MOD(L12,10000))) | L12: =IFERROR(LARGE(Items!$U$6:$U$1005,5),"")
B13: =IF(INDEX(Rooms!$B$6:$B$35,6)="","",INDEX(Rooms!$B$6:$B$35,6)) | C13: =IF(B13="","",INDEX(Rooms!$D$6:$D$35,6)) | D13: =IF(B13="","",INDEX(Rooms!$E$6:$E$35,6)) | E13: =IF(OR(B13="",N($B$5)=0),"",D13/$B$5) | G13: =IF(L13="","",INDEX(Items!$C$1:$C$1005,10000-MOD(L13,10000))) | H13: =IF(L13="","",INDEX(Items!$B$1:$B$1005,10000-MOD(L13,10000))) | I13: =IF(L13="","",INDEX(Items!$N$1:$N$1005,10000-MOD(L13,10000))) | L13: =IFERROR(LARGE(Items!$U$6:$U$1005,6),"")
B14: =IF(INDEX(Rooms!$B$6:$B$35,7)="","",INDEX(Rooms!$B$6:$B$35,7)) | C14: =IF(B14="","",INDEX(Rooms!$D$6:$D$35,7)) | D14: =IF(B14="","",INDEX(Rooms!$E$6:$E$35,7)) | E14: =IF(OR(B14="",N($B$5)=0),"",D14/$B$5) | G14: =IF(L14="","",INDEX(Items!$C$1:$C$1005,10000-MOD(L14,10000))) | H14: =IF(L14="","",INDEX(Items!$B$1:$B$1005,10000-MOD(L14,10000))) | I14: =IF(L14="","",INDEX(Items!$N$1:$N$1005,10000-MOD(L14,10000))) | L14: =IFERROR(LARGE(Items!$U$6:$U$1005,7),"")
B15: =IF(INDEX(Rooms!$B$6:$B$35,8)="","",INDEX(Rooms!$B$6:$B$35,8)) | C15: =IF(B15="","",INDEX(Rooms!$D$6:$D$35,8)) | D15: =IF(B15="","",INDEX(Rooms!$E$6:$E$35,8)) | E15: =IF(OR(B15="",N($B$5)=0),"",D15/$B$5) | G15: =IF(L15="","",INDEX(Items!$C$1:$C$1005,10000-MOD(L15,10000))) | H15: =IF(L15="","",INDEX(Items!$B$1:$B$1005,10000-MOD(L15,10000))) | I15: =IF(L15="","",INDEX(Items!$N$1:$N$1005,10000-MOD(L15,10000))) | L15: =IFERROR(LARGE(Items!$U$6:$U$1005,8),"")
B16: =IF(INDEX(Rooms!$B$6:$B$35,9)="","",INDEX(Rooms!$B$6:$B$35,9)) | C16: =IF(B16="","",INDEX(Rooms!$D$6:$D$35,9)) | D16: =IF(B16="","",INDEX(Rooms!$E$6:$E$35,9)) | E16: =IF(OR(B16="",N($B$5)=0),"",D16/$B$5) | G16: =IF(L16="","",INDEX(Items!$C$1:$C$1005,10000-MOD(L16,10000))) | H16: =IF(L16="","",INDEX(Items!$B$1:$B$1005,10000-MOD(L16,10000))) | I16: =IF(L16="","",INDEX(Items!$N$1:$N$1005,10000-MOD(L16,10000))) | L16: =IFERROR(LARGE(Items!$U$6:$U$1005,9),"")
B17: =IF(INDEX(Rooms!$B$6:$B$35,10)="","",INDEX(Rooms!$B$6:$B$35,10)) | C17: =IF(B17="","",INDEX(Rooms!$D$6:$D$35,10)) | D17: =IF(B17="","",INDEX(Rooms!$E$6:$E$35,10)) | E17: =IF(OR(B17="",N($B$5)=0),"",D17/$B$5) | G17: =IF(L17="","",INDEX(Items!$C$1:$C$1005,10000-MOD(L17,10000))) | H17: =IF(L17="","",INDEX(Items!$B$1:$B$1005,10000-MOD(L17,10000))) | I17: =IF(L17="","",INDEX(Items!$N$1:$N$1005,10000-MOD(L17,10000))) | L17: =IFERROR(LARGE(Items!$U$6:$U$1005,10),"")
B19: Category | C19: Items | D19: Worth | G19: Proof to find first | H19: Missing | I19: Worth
B20: =IF(Settings!$B$14="","",Settings!$B$14) | C20: =IF(B20="","",SUMIFS(Items!$S$6:$S$1005,Items!$D$6:$D$1005,B20)) | D20: =IF(B20="","",SUMIFS(Items!$T$6:$T$1005,Items!$D$6:$D$1005,B20)) | G20: =IF(M20="","",INDEX(Items!$C$1:$C$1005,10000-MOD(M20,10000))) | H20: =IF(M20="","",INDEX(Items!$Q$1:$Q$1005,10000-MOD(M20,10000))) | I20: =IF(M20="","",INDEX(Items!$N$1:$N$1005,10000-MOD(M20,10000))) | M20: =IFERROR(LARGE(Items!$Y$6:$Y$1005,1),"")
B21: =IF(Settings!$B$15="","",Settings!$B$15) | C21: =IF(B21="","",SUMIFS(Items!$S$6:$S$1005,Items!$D$6:$D$1005,B21)) | D21: =IF(B21="","",SUMIFS(Items!$T$6:$T$1005,Items!$D$6:$D$1005,B21)) | G21: =IF(M21="","",INDEX(Items!$C$1:$C$1005,10000-MOD(M21,10000))) | H21: =IF(M21="","",INDEX(Items!$Q$1:$Q$1005,10000-MOD(M21,10000))) | I21: =IF(M21="","",INDEX(Items!$N$1:$N$1005,10000-MOD(M21,10000))) | M21: =IFERROR(LARGE(Items!$Y$6:$Y$1005,2),"")
B22: =IF(Settings!$B$16="","",Settings!$B$16) | C22: =IF(B22="","",SUMIFS(Items!$S$6:$S$1005,Items!$D$6:$D$1005,B22)) | D22: =IF(B22="","",SUMIFS(Items!$T$6:$T$1005,Items!$D$6:$D$1005,B22)) | G22: =IF(M22="","",INDEX(Items!$C$1:$C$1005,10000-MOD(M22,10000))) | H22: =IF(M22="","",INDEX(Items!$Q$1:$Q$1005,10000-MOD(M22,10000))) | I22: =IF(M22="","",INDEX(Items!$N$1:$N$1005,10000-MOD(M22,10000))) | M22: =IFERROR(LARGE(Items!$Y$6:$Y$1005,3),"")
B23: =IF(Settings!$B$17="","",Settings!$B$17) | C23: =IF(B23="","",SUMIFS(Items!$S$6:$S$1005,Items!$D$6:$D$1005,B23)) | D23: =IF(B23="","",SUMIFS(Items!$T$6:$T$1005,Items!$D$6:$D$1005,B23)) | G23: =IF(M23="","",INDEX(Items!$C$1:$C$1005,10000-MOD(M23,10000))) | H23: =IF(M23="","",INDEX(Items!$Q$1:$Q$1005,10000-MOD(M23,10000))) | I23: =IF(M23="","",INDEX(Items!$N$1:$N$1005,10000-MOD(M23,10000))) | M23: =IFERROR(LARGE(Items!$Y$6:$Y$1005,4),"")
B24: =IF(Settings!$B$18="","",Settings!$B$18) | C24: =IF(B24="","",SUMIFS(Items!$S$6:$S$1005,Items!$D$6:$D$1005,B24)) | D24: =IF(B24="","",SUMIFS(Items!$T$6:$T$1005,Items!$D$6:$D$1005,B24)) | G24: =IF(M24="","",INDEX(Items!$C$1:$C$1005,10000-MOD(M24,10000))) | H24: =IF(M24="","",INDEX(Items!$Q$1:$Q$1005,10000-MOD(M24,10000))) | I24: =IF(M24="","",INDEX(Items!$N$1:$N$1005,10000-MOD(M24,10000))) | M24: =IFERROR(LARGE(Items!$Y$6:$Y$1005,5),"")
B25: =IF(Settings!$B$19="","",Settings!$B$19) | C25: =IF(B25="","",SUMIFS(Items!$S$6:$S$1005,Items!$D$6:$D$1005,B25)) | D25: =IF(B25="","",SUMIFS(Items!$T$6:$T$1005,Items!$D$6:$D$1005,B25)) | G25: =IF(M25="","",INDEX(Items!$C$1:$C$1005,10000-MOD(M25,10000))) | H25: =IF(M25="","",INDEX(Items!$Q$1:$Q$1005,10000-MOD(M25,10000))) | I25: =IF(M25="","",INDEX(Items!$N$1:$N$1005,10000-MOD(M25,10000))) | M25: =IFERROR(LARGE(Items!$Y$6:$Y$1005,6),"")
B26: =IF(Settings!$B$20="","",Settings!$B$20) | C26: =IF(B26="","",SUMIFS(Items!$S$6:$S$1005,Items!$D$6:$D$1005,B26)) | D26: =IF(B26="","",SUMIFS(Items!$T$6:$T$1005,Items!$D$6:$D$1005,B26)) | G26: =IF(M26="","",INDEX(Items!$C$1:$C$1005,10000-MOD(M26,10000))) | H26: =IF(M26="","",INDEX(Items!$Q$1:$Q$1005,10000-MOD(M26,10000))) | I26: =IF(M26="","",INDEX(Items!$N$1:$N$1005,10000-MOD(M26,10000))) | M26: =IFERROR(LARGE(Items!$Y$6:$Y$1005,7),"")
B27: =IF(Settings!$B$21="","",Settings!$B$21) | C27: =IF(B27="","",SUMIFS(Items!$S$6:$S$1005,Items!$D$6:$D$1005,B27)) | D27: =IF(B27="","",SUMIFS(Items!$T$6:$T$1005,Items!$D$6:$D$1005,B27)) | G27: =IF(M27="","",INDEX(Items!$C$1:$C$1005,10000-MOD(M27,10000))) | H27: =IF(M27="","",INDEX(Items!$Q$1:$Q$1005,10000-MOD(M27,10000))) | I27: =IF(M27="","",INDEX(Items!$N$1:$N$1005,10000-MOD(M27,10000))) | M27: =IFERROR(LARGE(Items!$Y$6:$Y$1005,8),"")
B28: =IF(Settings!$B$22="","",Settings!$B$22) | C28: =IF(B28="","",SUMIFS(Items!$S$6:$S$1005,Items!$D$6:$D$1005,B28)) | D28: =IF(B28="","",SUMIFS(Items!$T$6:$T$1005,Items!$D$6:$D$1005,B28))
B29: =IF(Settings!$B$23="","",Settings!$B$23) | C29: =IF(B29="","",SUMIFS(Items!$S$6:$S$1005,Items!$D$6:$D$1005,B29)) | D29: =IF(B29="","",SUMIFS(Items!$T$6:$T$1005,Items!$D$6:$D$1005,B29)) | G29: =IF(COUNT(Items!$Y$6:$Y$1005)>8,"And "&(COUNT(Items!$Y$6:$Y$1005)-8)&" more with something missing","")
B30: =IF(Settings!$B$24="","",Settings!$B$24) | C30: =IF(B30="","",SUMIFS(Items!$S$6:$S$1005,Items!$D$6:$D$1005,B30)) | D30: =IF(B30="","",SUMIFS(Items!$T$6:$T$1005,Items!$D$6:$D$1005,B30))
B31: =IF(Settings!$B$25="","",Settings!$B$25) | C31: =IF(B31="","",SUMIFS(Items!$S$6:$S$1005,Items!$D$6:$D$1005,B31)) | D31: =IF(B31="","",SUMIFS(Items!$T$6:$T$1005,Items!$D$6:$D$1005,B31))
B33: =IF(Settings!$C$7="","",Settings!$C$7)&IF(Settings!$C$8="",""," Policy "&Settings!$C$8)

Sheet Items
B2: Items
B3: Everything worth listing, room by room. The photo column is where you keep the picture: a file name or a link.
B5: Room | C5: Item | D5: Category | E5: Brand and model | F5: Serial number | G5: Bought | H5: Paid | I5: Worth now | J5: Receipt | K5: Photo | L5: Warranty until | M5: Note | N5: Value | O5: Age | P5: Warranty | Q5: Missing | R5: Check
B6: Living room | C6: 55 inch TV | D6: Electronics | E6: Model KX-55 | F6: SN46490500 | G6: 45981 | H6: 899 | I6: 750 | J6: File | K6: IMG_7843.jpg | L6: 46711 | N6: =IF(C6="","",IF(ISNUMBER(I6),I6,IF(ISNUMBER(H6),H6,""))) | O6: =IF(OR(C6="",NOT(ISNUMBER(G6))),"",(TODAY()-INT(G6))/365.25) | P6: =IF(OR(C6="",NOT(ISNUMBER(L6))),"",IF(L6<TODAY(),"Ended",IF(L6-TODAY()<=N(Settings!$C$10),"Ends soon","Covered"))) | Q6: =IF(C6="","",MID(IF(N6="",", value","")&IF(OR(J6="",J6="No"),", receipt","")&IF(K6="",", photo",""),3,100)) | R6: =IF(AND(B6="",C6=""),"",IF(C6="","Needs the item",IF(B6="","Needs a room",IF(COUNTIF(Rooms!$B$6:$B$35,B6)=0,"Not on Rooms",IF(AND(H6<>"",NOT(ISNUMBER(H6))),"Paid not a number",IF(AND(I6<>"",NOT(ISNUMBER(I6))),"Worth not a number",IF(AND(G6<>"",NOT(ISNUMBER(G6))),"Bought is not a date",IF(AND(L6<>"",NOT(ISNUMBER(L6))),"Warranty is not a date","")))))))) | S6: =IF(AND(C6<>"",R6=""),1,0) | T6: =IF(S6=1,N(N6),0) | U6: =IF(AND(S6=1,T6>0),ROUND(T6*100,0)*10000+10000-ROW(),"") | V6: =IF(AND(S6=1,OR(Report!$C$5="",B6=Report!$C$5)),MATCH(B6,Rooms!$B$6:$B$35,0)*10000+ROW(),"") | W6: =IF(AND(S6=1,OR(J6="",J6="No")),1,0) | X6: =IF(AND(S6=1,K6=""),1,0) | Y6: =IF(AND(S6=1,Q6<>""),ROUND(T6*100,0)*10000+10000-ROW(),"")
B7: Living room | C7: Sofa, three seats | D7: Furniture | E7: Linen, grey | G7: 45018 | H7: 1250 | I7: 900 | J7: Paper | K7: IMG_8995.jpg | N7: =IF(C7="","",IF(ISNUMBER(I7),I7,IF(ISNUMBER(H7),H7,""))) | O7: =IF(OR(C7="",NOT(ISNUMBER(G7))),"",(TODAY()-INT(G7))/365.25) | P7: =IF(OR(C7="",NOT(ISNUMBER(L7))),"",IF(L7<TODAY(),"Ended",IF(L7-TODAY()<=N(Settings!$C$10),"Ends soon","Covered"))) | Q7: =IF(C7="","",MID(IF(N7="",", value","")&IF(OR(J7="",J7="No"),", receipt","")&IF(K7="",", photo",""),3,100)) | R7: =IF(AND(B7="",C7=""),"",IF(C7="","Needs the item",IF(B7="","Needs a room",IF(COUNTIF(Rooms!$B$6:$B$35,B7)=0,"Not on Rooms",IF(AND(H7<>"",NOT(ISNUMBER(H7))),"Paid not a number",IF(AND(I7<>"",NOT(ISNUMBER(I7))),"Worth not a number",IF(AND(G7<>"",NOT(ISNUMBER(G7))),"Bought is not a date",IF(AND(L7<>"",NOT(ISNUMBER(L7))),"Warranty is not a date","")))))))) | S7: =IF(AND(C7<>"",R7=""),1,0) | T7: =IF(S7=1,N(N7),0) | U7: =IF(AND(S7=1,T7>0),ROUND(T7*100,0)*10000+10000-ROW(),"") | V7: =IF(AND(S7=1,OR(Report!$C$5="",B7=Report!$C$5)),MATCH(B7,Rooms!$B$6:$B$35,0)*10000+ROW(),"") | W7: =IF(AND(S7=1,OR(J7="",J7="No")),1,0) | X7: =IF(AND(S7=1,K7=""),1,0) | Y7: =IF(AND(S7=1,Q7<>""),ROUND(T7*100,0)*10000+10000-ROW(),"")
B8: Living room | C8: Sound bar | D8: Electronics | E8: SB-300 | F8: SN44582623 | G8: 45627 | H8: 329 | I8: 250 | J8: File | K8: IMG_2341.jpg | L8: 45992 | N8: =IF(C8="","",IF(ISNUMBER(I8),I8,IF(ISNUMBER(H8),H8,""))) | O8: =IF(OR(C8="",NOT(ISNUMBER(G8))),"",(TODAY()-INT(G8))/365.25) | P8: =IF(OR(C8="",NOT(ISNUMBER(L8))),"",IF(L8<TODAY(),"Ended",IF(L8-TODAY()<=N(Settings!$C$10),"Ends soon","Covered"))) | Q8: =IF(C8="","",MID(IF(N8="",", value","")&IF(OR(J8="",J8="No"),", receipt","")&IF(K8="",", photo",""),3,100)) | R8: =IF(AND(B8="",C8=""),"",IF(C8="","Needs the item",IF(B8="","Needs a room",IF(COUNTIF(Rooms!$B$6:$B$35,B8)=0,"Not on Rooms",IF(AND(H8<>"",NOT(ISNUMBER(H8))),"Paid not a number",IF(AND(I8<>"",NOT(ISNUMBER(I8))),"Worth not a number",IF(AND(G8<>"",NOT(ISNUMBER(G8))),"Bought is not a date",IF(AND(L8<>"",NOT(ISNUMBER(L8))),"Warranty is not a date","")))))))) | S8: =IF(AND(C8<>"",R8=""),1,0) | T8: =IF(S8=1,N(N8),0) | U8: =IF(AND(S8=1,T8>0),ROUND(T8*100,0)*10000+10000-ROW(),"") | V8: =IF(AND(S8=1,OR(Report!$C$5="",B8=Report!$C$5)),MATCH(B8,Rooms!$B$6:$B$35,0)*10000+ROW(),"") | W8: =IF(AND(S8=1,OR(J8="",J8="No")),1,0) | X8: =IF(AND(S8=1,K8=""),1,0) | Y8: =IF(AND(S8=1,Q8<>""),ROUND(T8*100,0)*10000+10000-ROW(),"")
B9: Living room | C9: Game console | D9: Electronics | E9: GC-5 with two pads | F9: SN50693756 | G9: 46011 | H9: 549 | I9: 450 | J9: File | K9: IMG_6549.jpg | L9: 46376 | N9: =IF(C9="","",IF(ISNUMBER(I9),I9,IF(ISNUMBER(H9),H9,""))) | O9: =IF(OR(C9="",NOT(ISNUMBER(G9))),"",(TODAY()-INT(G9))/365.25) | P9: =IF(OR(C9="",NOT(ISNUMBER(L9))),"",IF(L9<TODAY(),"Ended",IF(L9-TODAY()<=N(Settings!$C$10),"Ends soon","Covered"))) | Q9: =IF(C9="","",MID(IF(N9="",", value","")&IF(OR(J9="",J9="No"),", receipt","")&IF(K9="",", photo",""),3,100)) | R9: =IF(AND(B9="",C9=""),"",IF(C9="","Needs the item",IF(B9="","Needs a room",IF(COUNTIF(Rooms!$B$6:$B$35,B9)=0,"Not on Rooms",IF(AND(H9<>"",NOT(ISNUMBER(H9))),"Paid not a number",IF(AND(I9<>"",NOT(ISNUMBER(I9))),"Worth not a number",IF(AND(G9<>"",NOT(ISNUMBER(G9))),"Bought is not a date",IF(AND(L9<>"",NOT(ISNUMBER(L9))),"Warranty is not a date","")))))))) | S9: =IF(AND(C9<>"",R9=""),1,0) | T9: =IF(S9=1,N(N9),0) | U9: =IF(AND(S9=1,T9>0),ROUND(T9*100,0)*10000+10000-ROW(),"") | V9: =IF(AND(S9=1,OR(Report!$C$5="",B9=Report!$C$5)),MATCH(B9,Rooms!$B$6:$B$35,0)*10000+ROW(),"") | W9: =IF(AND(S9=1,OR(J9="",J9="No")),1,0) | X9: =IF(AND(S9=1,K9=""),1,0) | Y9: =IF(AND(S9=1,Q9<>""),ROUND(T9*100,0)*10000+10000-ROW(),"")
B10: Living room | C10: Rug | D10: Art and decor | E10: Wool, 2 x 3 m | G10: 44722 | H10: 480 | I10: 300 | J10: No | K10: IMG_1353.jpg | N10: =IF(C10="","",IF(ISNUMBER(I10),I10,IF(ISNUMBER(H10),H10,""))) | O10: =IF(OR(C10="",NOT(ISNUMBER(G10))),"",(TODAY()-INT(G10))/365.25) | P10: =IF(OR(C10="",NOT(ISNUMBER(L10))),"",IF(L10<TODAY(),"Ended",IF(L10-TODAY()<=N(Settings!$C$10),"Ends soon","Covered"))) | Q10: =IF(C10="","",MID(IF(N10="",", value","")&IF(OR(J10="",J10="No"),", receipt","")&IF(K10="",", photo",""),3,100)) | R10: =IF(AND(B10="",C10=""),"",IF(C10="","Needs the item",IF(B10="","Needs a room",IF(COUNTIF(Rooms!$B$6:$B$35,B10)=0,"Not on Rooms",IF(AND(H10<>"",NOT(ISNUMBER(H10))),"Paid not a number",IF(AND(I10<>"",NOT(ISNUMBER(I10))),"Worth not a number",IF(AND(G10<>"",NOT(ISNUMBER(G10))),"Bought is not a date",IF(AND(L10<>"",NOT(ISNUMBER(L10))),"Warranty is not a date","")))))))) | S10: =IF(AND(C10<>"",R10=""),1,0) | T10: =IF(S10=1,N(N10),0) | U10: =IF(AND(S10=1,T10>0),ROUND(T10*100,0)*10000+10000-ROW(),"") | V10: =IF(AND(S10=1,OR(Report!$C$5="",B10=Report!$C$5)),MATCH(B10,Rooms!$B$6:$B$35,0)*10000+ROW(),"") | W10: =IF(AND(S10=1,OR(J10="",J10="No")),1,0) | X10: =IF(AND(S10=1,K10=""),1,0) | Y10: =IF(AND(S10=1,Q10<>""),ROUND(T10*100,0)*10000+10000-ROW(),"")
B11: Living room | C11: Painting of the harbour | D11: Art and decor | E11: Oil on canvas | G11: 44058 | H11: 900 | I11: 900 | J11: Paper | K11: IMG_2185.jpg | N11: =IF(C11="","",IF(ISNUMBER(I11),I11,IF(ISNUMBER(H11),H11,""))) | O11: =IF(OR(C11="",NOT(ISNUMBER(G11))),"",(TODAY()-INT(G11))/365.25) | P11: =IF(OR(C11="",NOT(ISNUMBER(L11))),"",IF(L11<TODAY(),"Ended",IF(L11-TODAY()<=N(Settings!$C$10),"Ends soon","Covered"))) | Q11: =IF(C11="","",MID(IF(N11="",", value","")&IF(OR(J11="",J11="No"),", receipt","")&IF(K11="",", photo",""),3,100)) | R11: =IF(AND(B11="",C11=""),"",IF(C11="","Needs the item",IF(B11="","Needs a room",IF(COUNTIF(Rooms!$B$6:$B$35,B11)=0,"Not on Rooms",IF(AND(H11<>"",NOT(ISNUMBER(H11))),"Paid not a number",IF(AND(I11<>"",NOT(ISNUMBER(I11))),"Worth not a number",IF(AND(G11<>"",NOT(ISNUMBER(G11))),"Bought is not a date",IF(AND(L11<>"",NOT(ISNUMBER(L11))),"Warranty is not a date","")))))))) | S11: =IF(AND(C11<>"",R11=""),1,0) | T11: =IF(S11=1,N(N11),0) | U11: =IF(AND(S11=1,T11>0),ROUND(T11*100,0)*10000+10000-ROW(),"") | V11: =IF(AND(S11=1,OR(Report!$C$5="",B11=Report!$C$5)),MATCH(B11,Rooms!$B$6:$B$35,0)*10000+ROW(),"") | W11: =IF(AND(S11=1,OR(J11="",J11="No")),1,0) | X11: =IF(AND(S11=1,K11=""),1,0) | Y11: =IF(AND(S11=1,Q11<>""),ROUND(T11*100,0)*10000+10000-ROW(),"")
B12: Living room | C12: Bookcase | D12: Furniture | E12: Oak, 5 shelves | G12: 44230 | H12: 380 | I12: 250 | J12: No | N12: =IF(C12="","",IF(ISNUMBER(I12),I12,IF(ISNUMBER(H12),H12,""))) | O12: =IF(OR(C12="",NOT(ISNUMBER(G12))),"",(TODAY()-INT(G12))/365.25) | P12: =IF(OR(C12="",NOT(ISNUMBER(L12))),"",IF(L12<TODAY(),"Ended",IF(L12-TODAY()<=N(Settings!$C$10),"Ends soon","Covered"))) | Q12: =IF(C12="","",MID(IF(N12="",", value","")&IF(OR(J12="",J12="No"),", receipt","")&IF(K12="",", photo",""),3,100)) | R12: =IF(AND(B12="",C12=""),"",IF(C12="","Needs the item",IF(B12="","Needs a room",IF(COUNTIF(Rooms!$B$6:$B$35,B12)=0,"Not on Rooms",IF(AND(H12<>"",NOT(ISNUMBER(H12))),"Paid not a number",IF(AND(I12<>"",NOT(ISNUMBER(I12))),"Worth not a number",IF(AND(G12<>"",NOT(ISNUMBER(G12))),"Bought is not a date",IF(AND(L12<>"",NOT(ISNUMBER(L12))),"Warranty is not a date","")))))))) | S12: =IF(AND(C12<>"",R12=""),1,0) | T12: =IF(S12=1,N(N12),0) | U12: =IF(AND(S12=1,T12>0),ROUND(T12*100,0)*10000+10000-ROW(),"") | V12: =IF(AND(S12=1,OR(Report!$C$5="",B12=Report!$C$5)),MATCH(B12,Rooms!$B$6:$B$35,0)*10000+ROW(),"") | W12: =IF(AND(S12=1,OR(J12="",J12="No")),1,0) | X12: =IF(AND(S12=1,K12=""),1,0) | Y12: =IF(AND(S12=1,Q12<>""),ROUND(T12*100,0)*10000+10000-ROW(),"")
B13: Kitchen | C13: Fridge freezer | D13: Appliances | E13: FF-360 | F13: SN74995729 | G13: 45363 | H13: 1099 | I13: 850 | J13: File | K13: IMG_1180.jpg | L13: 47189 | N13: =IF(C13="","",IF(ISNUMBER(I13),I13,IF(ISNUMBER(H13),H13,""))) | O13: =IF(OR(C13="",NOT(ISNUMBER(G13))),"",(TODAY()-INT(G13))/365.25) | P13: =IF(OR(C13="",NOT(ISNUMBER(L13))),"",IF(L13<TODAY(),"Ended",IF(L13-TODAY()<=N(Settings!$C$10),"Ends soon","Covered"))) | Q13: =IF(C13="","",MID(IF(N13="",", value","")&IF(OR(J13="",J13="No"),", receipt","")&IF(K13="",", photo",""),3,100)) | R13: =IF(AND(B13="",C13=""),"",IF(C13="","Needs the item",IF(B13="","Needs a room",IF(COUNTIF(Rooms!$B$6:$B$35,B13)=0,"Not on Rooms",IF(AND(H13<>"",NOT(ISNUMBER(H13))),"Paid not a number",IF(AND(I13<>"",NOT(ISNUMBER(I13))),"Worth not a number",IF(AND(G13<>"",NOT(ISNUMBER(G13))),"Bought is not a date",IF(AND(L13<>"",NOT(ISNUMBER(L13))),"Warranty is not a date","")))))))) | S13: =IF(AND(C13<>"",R13=""),1,0) | T13: =IF(S13=1,N(N13),0) | U13: =IF(AND(S13=1,T13>0),ROUND(T13*100,0)*10000+10000-ROW(),"") | V13: =IF(AND(S13=1,OR(Report!$C$5="",B13=Report!$C$5)),MATCH(B13,Rooms!$B$6:$B$35,0)*10000+ROW(),"") | W13: =IF(AND(S13=1,OR(J13="",J13="No")),1,0) | X13: =IF(AND(S13=1,K13=""),1,0) | Y13: =IF(AND(S13=1,Q13<>""),ROUND(T13*100,0)*10000+10000-ROW(),"")
B14: Kitchen | C14: Dishwasher | D14: Appliances | E14: DW-45 | F14: SN25413319 | G14: 45170 | H14: 549 | I14: 380 | J14: File | K14: IMG_5650.jpg | L14: 45901 | N14: =IF(C14="","",IF(ISNUMBER(I14),I14,IF(ISNUMBER(H14),H14,""))) | O14: =IF(OR(C14="",NOT(ISNUMBER(G14))),"",(TODAY()-INT(G14))/365.25) | P14: =IF(OR(C14="",NOT(ISNUMBER(L14))),"",IF(L14<TODAY(),"Ended",IF(L14-TODAY()<=N(Settings!$C$10),"Ends soon","Covered"))) | Q14: =IF(C14="","",MID(IF(N14="",", value","")&IF(OR(J14="",J14="No"),", receipt","")&IF(K14="",", photo",""),3,100)) | R14: =IF(AND(B14="",C14=""),"",IF(C14="","Needs the item",IF(B14="","Needs a room",IF(COUNTIF(Rooms!$B$6:$B$35,B14)=0,"Not on Rooms",IF(AND(H14<>"",NOT(ISNUMBER(H14))),"Paid not a number",IF(AND(I14<>"",NOT(ISNUMBER(I14))),"Worth not a number",IF(AND(G14<>"",NOT(ISNUMBER(G14))),"Bought is not a date",IF(AND(L14<>"",NOT(ISNUMBER(L14))),"Warranty is not a date","")))))))) | S14: =IF(AND(C14<>"",R14=""),1,0) | T14: =IF(S14=1,N(N14),0) | U14: =IF(AND(S14=1,T14>0),ROUND(T14*100,0)*10000+10000-ROW(),"") | V14: =IF(AND(S14=1,OR(Report!$C$5="",B14=Report!$C$5)),MATCH(B14,Rooms!$B$6:$B$35,0)*10000+ROW(),"") | W14: =IF(AND(S14=1,OR(J14="",J14="No")),1,0) | X14: =IF(AND(S14=1,K14=""),1,0) | Y14: =IF(AND(S14=1,Q14<>""),ROUND(T14*100,0)*10000+10000-ROW(),"")
B15: Kitchen | C15: Coffee machine | D15: Appliances | E15: Espresso EM-2 | F15: SN25798280 | G15: 46030 | H15: 429 | I15: 400 | J15: File | K15: IMG_6096.jpg | L15: 46760 | N15: =IF(C15="","",IF(ISNUMBER(I15),I15,IF(ISNUMBER(H15),H15,""))) | O15: =IF(OR(C15="",NOT(ISNUMBER(G15))),"",(TODAY()-INT(G15))/365.25) | P15: =IF(OR(C15="",NOT(ISNUMBER(L15))),"",IF(L15<TODAY(),"Ended",IF(L15-TODAY()<=N(Settings!$C$10),"Ends soon","Covered"))) | Q15: =IF(C15="","",MID(IF(N15="",", value","")&IF(OR(J15="",J15="No"),", receipt","")&IF(K15="",", photo",""),3,100)) | R15: =IF(AND(B15="",C15=""),"",IF(C15="","Needs the item",IF(B15="","Needs a room",IF(COUNTIF(Rooms!$B$6:$B$35,B15)=0,"Not on Rooms",IF(AND(H15<>"",NOT(ISNUMBER(H15))),"Paid not a number",IF(AND(I15<>"",NOT(ISNUMBER(I15))),"Worth not a number",IF(AND(G15<>"",NOT(ISNUMBER(G15))),"Bought is not a date",IF(AND(L15<>"",NOT(ISNUMBER(L15))),"Warranty is not a date","")))))))) | S15: =IF(AND(C15<>"",R15=""),1,0) | T15: =IF(S15=1,N(N15),0) | U15: =IF(AND(S15=1,T15>0),ROUND(T15*100,0)*10000+10000-ROW(),"") | V15: =IF(AND(S15=1,OR(Report!$C$5="",B15=Report!$C$5)),MATCH(B15,Rooms!$B$6:$B$35,0)*10000+ROW(),"") | W15: =IF(AND(S15=1,OR(J15="",J15="No")),1,0) | X15: =IF(AND(S15=1,K15=""),1,0) | Y15: =IF(AND(S15=1,Q15<>""),ROUND(T15*100,0)*10000+10000-ROW(),"")
B16: Kitchen | C16: Stand mixer | D16: Kitchenware | E16: SM-5, red | G16: 45651 | H16: 399 | I16: 300 | J16: No | K16: IMG_1585.jpg | N16: =IF(C16="","",IF(ISNUMBER(I16),I16,IF(ISNUMBER(H16),H16,""))) | O16: =IF(OR(C16="",NOT(ISNUMBER(G16))),"",(TODAY()-INT(G16))/365.25) | P16: =IF(OR(C16="",NOT(ISNUMBER(L16))),"",IF(L16<TODAY(),"Ended",IF(L16-TODAY()<=N(Settings!$C$10),"Ends soon","Covered"))) | Q16: =IF(C16="","",MID(IF(N16="",", value","")&IF(OR(J16="",J16="No"),", receipt","")&IF(K16="",", photo",""),3,100)) | R16: =IF(AND(B16="",C16=""),"",IF(C16="","Needs the item",IF(B16="","Needs a room",IF(COUNTIF(Rooms!$B$6:$B$35,B16)=0,"Not on Rooms",IF(AND(H16<>"",NOT(ISNUMBER(H16))),"Paid not a number",IF(AND(I16<>"",NOT(ISNUMBER(I16))),"Worth not a number",IF(AND(G16<>"",NOT(ISNUMBER(G16))),"Bought is not a date",IF(AND(L16<>"",NOT(ISNUMBER(L16))),"Warranty is not a date","")))))))) | S16: =IF(AND(C16<>"",R16=""),1,0) | T16: =IF(S16=1,N(N16),0) | U16: =IF(AND(S16=1,T16>0),ROUND(T16*100,0)*10000+10000-ROW(),"") | V16: =IF(AND(S16=1,OR(Report!$C$5="",B16=Report!$C$5)),MATCH(B16,Rooms!$B$6:$B$35,0)*10000+ROW(),"") | W16: =IF(AND(S16=1,OR(J16="",J16="No")),1,0) | X16: =IF(AND(S16=1,K16=""),1,0) | Y16: =IF(AND(S16=1,Q16<>""),ROUND(T16*100,0)*10000+10000-ROW(),"")
B17: Kitchen | C17: Knife set | D17: Kitchenware | E17: 8 knives and block | G17: 45845 | H17: 229 | I17: 200 | J17: Paper | N17: =IF(C17="","",IF(ISNUMBER(I17),I17,IF(ISNUMBER(H17),H17,""))) | O17: =IF(OR(C17="",NOT(ISNUMBER(G17))),"",(TODAY()-INT(G17))/365.25) | P17: =IF(OR(C17="",NOT(ISNUMBER(L17))),"",IF(L17<TODAY(),"Ended",IF(L17-TODAY()<=N(Settings!$C$10),"Ends soon","Covered"))) | Q17: =IF(C17="","",MID(IF(N17="",", value","")&IF(OR(J17="",J17="No"),", receipt","")&IF(K17="",", photo",""),3,100)) | R17: =IF(AND(B17="",C17=""),"",IF(C17="","Needs the item",IF(B17="","Needs a room",IF(COUNTIF(Rooms!$B$6:$B$35,B17)=0,"Not on Rooms",IF(AND(H17<>"",NOT(ISNUMBER(H17))),"Paid not a number",IF(AND(I17<>"",NOT(ISNUMBER(I17))),"Worth not a number",IF(AND(G17<>"",NOT(ISNUMBER(G17))),"Bought is not a date",IF(AND(L17<>"",NOT(ISNUMBER(L17))),"Warranty is not a date","")))))))) | S17: =IF(AND(C17<>"",R17=""),1,0) | T17: =IF(S17=1,N(N17),0) | U17: =IF(AND(S17=1,T17>0),ROUND(T17*100,0)*10000+10000-ROW(),"") | V17: =IF(AND(S17=1,OR(Report!$C$5="",B17=Report!$C$5)),MATCH(B17,Rooms!$B$6:$B$35,0)*10000+ROW(),"") | W17: =IF(AND(S17=1,OR(J17="",J17="No")),1,0) | X17: =IF(AND(S17=1,K17=""),1,0) | Y17: =IF(AND(S17=1,Q17<>""),ROUND(T17*100,0)*10000+10000-ROW(),"")
B18: Kitchen | C18: Pots and pans | D18: Kitchenware | E18: 10 pieces | G18: 44895 | H18: 350 | I18: 200 | J18: No | N18: =IF(C18="","",IF(ISNUMBER(I18),I18,IF(ISNUMBER(H18),H18,""))) | O18: =IF(OR(C18="",NOT(ISNUMBER(G18))),"",(TODAY()-INT(G18))/365.25) | P18: =IF(OR(C18="",NOT(ISNUMBER(L18))),"",IF(L18<TODAY(),"Ended",IF(L18-TODAY()<=N(Settings!$C$10),"Ends soon","Covered"))) | Q18: =IF(C18="","",MID(IF(N18="",", value","")&IF(OR(J18="",J18="No"),", receipt","")&IF(K18="",", photo",""),3,100)) | R18: =IF(AND(B18="",C18=""),"",IF(C18="","Needs the item",IF(B18="","Needs a room",IF(COUNTIF(Rooms!$B$6:$B$35,B18)=0,"Not on Rooms",IF(AND(H18<>"",NOT(ISNUMBER(H18))),"Paid not a number",IF(AND(I18<>"",NOT(ISNUMBER(I18))),"Worth not a number",IF(AND(G18<>"",NOT(ISNUMBER(G18))),"Bought is not a date",IF(AND(L18<>"",NOT(ISNUMBER(L18))),"Warranty is not a date","")))))))) | S18: =IF(AND(C18<>"",R18=""),1,0) | T18: =IF(S18=1,N(N18),0) | U18: =IF(AND(S18=1,T18>0),ROUND(T18*100,0)*10000+10000-ROW(),"") | V18: =IF(AND(S18=1,OR(Report!$C$5="",B18=Report!$C$5)),MATCH(B18,Rooms!$B$6:$B$35,0)*10000+ROW(),"") | W18: =IF(AND(S18=1,OR(J18="",J18="No")),1,0) | X18: =IF(AND(S18=1,K18=""),1,0) | Y18: =IF(AND(S18=1,Q18<>""),ROUND(T18*100,0)*10000+10000-ROW(),"")
B19: Main bedroom | C19: Bed and mattress | D19: Furniture | E19: King size | G19: 45432 | H19: 1600 | I19: 1300 | J19: File | K19: IMG_2091.jpg | L19: 49084 | N19: =IF(C19="","",IF(ISNUMBER(I19),I19,IF(ISNUMBER(H19),H19,""))) | O19: =IF(OR(C19="",NOT(ISNUMBER(G19))),"",(TODAY()-INT(G19))/365.25) | P19: =IF(OR(C19="",NOT(ISNUMBER(L19))),"",IF(L19<TODAY(),"Ended",IF(L19-TODAY()<=N(Settings!$C$10),"Ends soon","Covered"))) | Q19: =IF(C19="","",MID(IF(N19="",", value","")&IF(OR(J19="",J19="No"),", receipt","")&IF(K19="",", photo",""),3,100)) | R19: =IF(AND(B19="",C19=""),"",IF(C19="","Needs the item",IF(B19="","Needs a room",IF(COUNTIF(Rooms!$B$6:$B$35,B19)=0,"Not on Rooms",IF(AND(H19<>"",NOT(ISNUMBER(H19))),"Paid not a number",IF(AND(I19<>"",NOT(ISNUMBER(I19))),"Worth not a number",IF(AND(G19<>"",NOT(ISNUMBER(G19))),"Bought is not a date",IF(AND(L19<>"",NOT(ISNUMBER(L19))),"Warranty is not a date","")))))))) | S19: =IF(AND(C19<>"",R19=""),1,0) | T19: =IF(S19=1,N(N19),0) | U19: =IF(AND(S19=1,T19>0),ROUND(T19*100,0)*10000+10000-ROW(),"") | V19: =IF(AND(S19=1,OR(Report!$C$5="",B19=Report!$C$5)),MATCH(B19,Rooms!$B$6:$B$35,0)*10000+ROW(),"") | W19: =IF(AND(S19=1,OR(J19="",J19="No")),1,0) | X19: =IF(AND(S19=1,K19=""),1,0) | Y19: =IF(AND(S19=1,Q19<>""),ROUND(T19*100,0)*10000+10000-ROW(),"")
B20: Main bedroom | C20: Wardrobe | D20: Furniture | E20: Two doors, white | G20: 44208 | H20: 520 | I20: 350 | J20: No | K20: IMG_3212.jpg | N20: =IF(C20="","",IF(ISNUMBER(I20),I20,IF(ISNUMBER(H20),H20,""))) | O20: =IF(OR(C20="",NOT(ISNUMBER(G20))),"",(TODAY()-INT(G20))/365.25) | P20: =IF(OR(C20="",NOT(ISNUMBER(L20))),"",IF(L20<TODAY(),"Ended",IF(L20-TODAY()<=N(Settings!$C$10),"Ends soon","Covered"))) | Q20: =IF(C20="","",MID(IF(N20="",", value","")&IF(OR(J20="",J20="No"),", receipt","")&IF(K20="",", photo",""),3,100)) | R20: =IF(AND(B20="",C20=""),"",IF(C20="","Needs the item",IF(B20="","Needs a room",IF(COUNTIF(Rooms!$B$6:$B$35,B20)=0,"Not on Rooms",IF(AND(H20<>"",NOT(ISNUMBER(H20))),"Paid not a number",IF(AND(I20<>"",NOT(ISNUMBER(I20))),"Worth not a number",IF(AND(G20<>"",NOT(ISNUMBER(G20))),"Bought is not a date",IF(AND(L20<>"",NOT(ISNUMBER(L20))),"Warranty is not a date","")))))))) | S20: =IF(AND(C20<>"",R20=""),1,0) | T20: =IF(S20=1,N(N20),0) | U20: =IF(AND(S20=1,T20>0),ROUND(T20*100,0)*10000+10000-ROW(),"") | V20: =IF(AND(S20=1,OR(Report!$C$5="",B20=Report!$C$5)),MATCH(B20,Rooms!$B$6:$B$35,0)*10000+ROW(),"") | W20: =IF(AND(S20=1,OR(J20="",J20="No")),1,0) | X20: =IF(AND(S20=1,K20=""),1,0) | Y20: =IF(AND(S20=1,Q20<>""),ROUND(T20*100,0)*10000+10000-ROW(),"")
B21: Main bedroom | C21: Engagement ring | D21: Jewelry and watches | E21: Gold, one diamond | G21: 43510 | H21: 2400 | I21: 3100 | J21: Paper | K21: IMG_5449.jpg | N21: =IF(C21="","",IF(ISNUMBER(I21),I21,IF(ISNUMBER(H21),H21,""))) | O21: =IF(OR(C21="",NOT(ISNUMBER(G21))),"",(TODAY()-INT(G21))/365.25) | P21: =IF(OR(C21="",NOT(ISNUMBER(L21))),"",IF(L21<TODAY(),"Ended",IF(L21-TODAY()<=N(Settings!$C$10),"Ends soon","Covered"))) | Q21: =IF(C21="","",MID(IF(N21="",", value","")&IF(OR(J21="",J21="No"),", receipt","")&IF(K21="",", photo",""),3,100)) | R21: =IF(AND(B21="",C21=""),"",IF(C21="","Needs the item",IF(B21="","Needs a room",IF(COUNTIF(Rooms!$B$6:$B$35,B21)=0,"Not on Rooms",IF(AND(H21<>"",NOT(ISNUMBER(H21))),"Paid not a number",IF(AND(I21<>"",NOT(ISNUMBER(I21))),"Worth not a number",IF(AND(G21<>"",NOT(ISNUMBER(G21))),"Bought is not a date",IF(AND(L21<>"",NOT(ISNUMBER(L21))),"Warranty is not a date","")))))))) | S21: =IF(AND(C21<>"",R21=""),1,0) | T21: =IF(S21=1,N(N21),0) | U21: =IF(AND(S21=1,T21>0),ROUND(T21*100,0)*10000+10000-ROW(),"") | V21: =IF(AND(S21=1,OR(Report!$C$5="",B21=Report!$C$5)),MATCH(B21,Rooms!$B$6:$B$35,0)*10000+ROW(),"") | W21: =IF(AND(S21=1,OR(J21="",J21="No")),1,0) | X21: =IF(AND(S21=1,K21=""),1,0) | Y21: =IF(AND(S21=1,Q21<>""),ROUND(T21*100,0)*10000+10000-ROW(),"")
B22: Main bedroom | C22: Watch | D22: Jewelry and watches | E22: Steel, automatic | G22: 45284 | H22: 780 | I22: 700 | J22: Paper | K22: IMG_3525.jpg | L22: 46015 | N22: =IF(C22="","",IF(ISNUMBER(I22),I22,IF(ISNUMBER(H22),H22,""))) | O22: =IF(OR(C22="",NOT(ISNUMBER(G22))),"",(TODAY()-INT(G22))/365.25) | P22: =IF(OR(C22="",NOT(ISNUMBER(L22))),"",IF(L22<TODAY(),"Ended",IF(L22-TODAY()<=N(Settings!$C$10),"Ends soon","Covered"))) | Q22: =IF(C22="","",MID(IF(N22="",", value","")&IF(OR(J22="",J22="No"),", receipt","")&IF(K22="",", photo",""),3,100)) | R22: =IF(AND(B22="",C22=""),"",IF(C22="","Needs the item",IF(B22="","Needs a room",IF(COUNTIF(Rooms!$B$6:$B$35,B22)=0,"Not on Rooms",IF(AND(H22<>"",NOT(ISNUMBER(H22))),"Paid not a number",IF(AND(I22<>"",NOT(ISNUMBER(I22))),"Worth not a number",IF(AND(G22<>"",NOT(ISNUMBER(G22))),"Bought is not a date",IF(AND(L22<>"",NOT(ISNUMBER(L22))),"Warranty is not a date","")))))))) | S22: =IF(AND(C22<>"",R22=""),1,0) | T22: =IF(S22=1,N(N22),0) | U22: =IF(AND(S22=1,T22>0),ROUND(T22*100,0)*10000+10000-ROW(),"") | V22: =IF(AND(S22=1,OR(Report!$C$5="",B22=Report!$C$5)),MATCH(B22,Rooms!$B$6:$B$35,0)*10000+ROW(),"") | W22: =IF(AND(S22=1,OR(J22="",J22="No")),1,0) | X22: =IF(AND(S22=1,K22=""),1,0) | Y22: =IF(AND(S22=1,Q22<>""),ROUND(T22*100,0)*10000+10000-ROW(),"")
B23: Main bedroom | C23: Winter coats | D23: Clothing | E23: Two coats | G23: 45963 | H23: 460 | I23: 350 | J23: No | N23: =IF(C23="","",IF(ISNUMBER(I23),I23,IF(ISNUMBER(H23),H23,""))) | O23: =IF(OR(C23="",NOT(ISNUMBER(G23))),"",(TODAY()-INT(G23))/365.25) | P23: =IF(OR(C23="",NOT(ISNUMBER(L23))),"",IF(L23<TODAY(),"Ended",IF(L23-TODAY()<=N(Settings!$C$10),"Ends soon","Covered"))) | Q23: =IF(C23="","",MID(IF(N23="",", value","")&IF(OR(J23="",J23="No"),", receipt","")&IF(K23="",", photo",""),3,100)) | R23: =IF(AND(B23="",C23=""),"",IF(C23="","Needs the item",IF(B23="","Needs a room",IF(COUNTIF(Rooms!$B$6:$B$35,B23)=0,"Not on Rooms",IF(AND(H23<>"",NOT(ISNUMBER(H23))),"Paid not a number",IF(AND(I23<>"",NOT(ISNUMBER(I23))),"Worth not a number",IF(AND(G23<>"",NOT(ISNUMBER(G23))),"Bought is not a date",IF(AND(L23<>"",NOT(ISNUMBER(L23))),"Warranty is not a date","")))))))) | S23: =IF(AND(C23<>"",R23=""),1,0) | T23: =IF(S23=1,N(N23),0) | U23: =IF(AND(S23=1,T23>0),ROUND(T23*100,0)*10000+10000-ROW(),"") | V23: =IF(AND(S23=1,OR(Report!$C$5="",B23=Report!$C$5)),MATCH(B23,Rooms!$B$6:$B$35,0)*10000+ROW(),"") | W23: =IF(AND(S23=1,OR(J23="",J23="No")),1,0) | X23: =IF(AND(S23=1,K23=""),1,0) | Y23: =IF(AND(S23=1,Q23<>""),ROUND(T23*100,0)*10000+10000-ROW(),"")
B24: Main bedroom | C24: Clothes and shoes | D24: Clothing | E24: Everyday | I24: 2500 | J24: No | N24: =IF(C24="","",IF(ISNUMBER(I24),I24,IF(ISNUMBER(H24),H24,""))) | O24: =IF(OR(C24="",NOT(ISNUMBER(G24))),"",(TODAY()-INT(G24))/365.25) | P24: =IF(OR(C24="",NOT(ISNUMBER(L24))),"",IF(L24<TODAY(),"Ended",IF(L24-TODAY()<=N(Settings!$C$10),"Ends soon","Covered"))) | Q24: =IF(C24="","",MID(IF(N24="",", value","")&IF(OR(J24="",J24="No"),", receipt","")&IF(K24="",", photo",""),3,100)) | R24: =IF(AND(B24="",C24=""),"",IF(C24="","Needs the item",IF(B24="","Needs a room",IF(COUNTIF(Rooms!$B$6:$B$35,B24)=0,"Not on Rooms",IF(AND(H24<>"",NOT(ISNUMBER(H24))),"Paid not a number",IF(AND(I24<>"",NOT(ISNUMBER(I24))),"Worth not a number",IF(AND(G24<>"",NOT(ISNUMBER(G24))),"Bought is not a date",IF(AND(L24<>"",NOT(ISNUMBER(L24))),"Warranty is not a date","")))))))) | S24: =IF(AND(C24<>"",R24=""),1,0) | T24: =IF(S24=1,N(N24),0) | U24: =IF(AND(S24=1,T24>0),ROUND(T24*100,0)*10000+10000-ROW(),"") | V24: =IF(AND(S24=1,OR(Report!$C$5="",B24=Report!$C$5)),MATCH(B24,Rooms!$B$6:$B$35,0)*10000+ROW(),"") | W24: =IF(AND(S24=1,OR(J24="",J24="No")),1,0) | X24: =IF(AND(S24=1,K24=""),1,0) | Y24: =IF(AND(S24=1,Q24<>""),ROUND(T24*100,0)*10000+10000-ROW(),"")
B25: Home office | C25: Laptop | D25: Electronics | E25: Pro 14, 16 GB | F25: SN38321322 | G25: 46073 | H25: 1499 | I25: 1350 | J25: File | K25: IMG_8018.jpg | L25: 46438 | N25: =IF(C25="","",IF(ISNUMBER(I25),I25,IF(ISNUMBER(H25),H25,""))) | O25: =IF(OR(C25="",NOT(ISNUMBER(G25))),"",(TODAY()-INT(G25))/365.25) | P25: =IF(OR(C25="",NOT(ISNUMBER(L25))),"",IF(L25<TODAY(),"Ended",IF(L25-TODAY()<=N(Settings!$C$10),"Ends soon","Covered"))) | Q25: =IF(C25="","",MID(IF(N25="",", value","")&IF(OR(J25="",J25="No"),", receipt","")&IF(K25="",", photo",""),3,100)) | R25: =IF(AND(B25="",C25=""),"",IF(C25="","Needs the item",IF(B25="","Needs a room",IF(COUNTIF(Rooms!$B$6:$B$35,B25)=0,"Not on Rooms",IF(AND(H25<>"",NOT(ISNUMBER(H25))),"Paid not a number",IF(AND(I25<>"",NOT(ISNUMBER(I25))),"Worth not a number",IF(AND(G25<>"",NOT(ISNUMBER(G25))),"Bought is not a date",IF(AND(L25<>"",NOT(ISNUMBER(L25))),"Warranty is not a date","")))))))) | S25: =IF(AND(C25<>"",R25=""),1,0) | T25: =IF(S25=1,N(N25),0) | U25: =IF(AND(S25=1,T25>0),ROUND(T25*100,0)*10000+10000-ROW(),"") | V25: =IF(AND(S25=1,OR(Report!$C$5="",B25=Report!$C$5)),MATCH(B25,Rooms!$B$6:$B$35,0)*10000+ROW(),"") | W25: =IF(AND(S25=1,OR(J25="",J25="No")),1,0) | X25: =IF(AND(S25=1,K25=""),1,0) | Y25: =IF(AND(S25=1,Q25<>""),ROUND(T25*100,0)*10000+10000-ROW(),"")
B26: Home office | C26: Monitor | D26: Electronics | E26: 27 inch, 4K | F26: SN20059796 | G26: 45719 | H26: 379 | I26: 320 | J26: File | K26: IMG_7686.jpg | L26: 46815 | N26: =IF(C26="","",IF(ISNUMBER(I26),I26,IF(ISNUMBER(H26),H26,""))) | O26: =IF(OR(C26="",NOT(ISNUMBER(G26))),"",(TODAY()-INT(G26))/365.25) | P26: =IF(OR(C26="",NOT(ISNUMBER(L26))),"",IF(L26<TODAY(),"Ended",IF(L26-TODAY()<=N(Settings!$C$10),"Ends soon","Covered"))) | Q26: =IF(C26="","",MID(IF(N26="",", value","")&IF(OR(J26="",J26="No"),", receipt","")&IF(K26="",", photo",""),3,100)) | R26: =IF(AND(B26="",C26=""),"",IF(C26="","Needs the item",IF(B26="","Needs a room",IF(COUNTIF(Rooms!$B$6:$B$35,B26)=0,"Not on Rooms",IF(AND(H26<>"",NOT(ISNUMBER(H26))),"Paid not a number",IF(AND(I26<>"",NOT(ISNUMBER(I26))),"Worth not a number",IF(AND(G26<>"",NOT(ISNUMBER(G26))),"Bought is not a date",IF(AND(L26<>"",NOT(ISNUMBER(L26))),"Warranty is not a date","")))))))) | S26: =IF(AND(C26<>"",R26=""),1,0) | T26: =IF(S26=1,N(N26),0) | U26: =IF(AND(S26=1,T26>0),ROUND(T26*100,0)*10000+10000-ROW(),"") | V26: =IF(AND(S26=1,OR(Report!$C$5="",B26=Report!$C$5)),MATCH(B26,Rooms!$B$6:$B$35,0)*10000+ROW(),"") | W26: =IF(AND(S26=1,OR(J26="",J26="No")),1,0) | X26: =IF(AND(S26=1,K26=""),1,0) | Y26: =IF(AND(S26=1,Q26<>""),ROUND(T26*100,0)*10000+10000-ROW(),"")
B27: Home office | C27: Desk chair | D27: Furniture | E27: Mesh, adjustable | G27: 45544 | H27: 449 | I27: 350 | J27: File | K27: IMG_3339.jpg | L27: 47370 | N27: =IF(C27="","",IF(ISNUMBER(I27),I27,IF(ISNUMBER(H27),H27,""))) | O27: =IF(OR(C27="",NOT(ISNUMBER(G27))),"",(TODAY()-INT(G27))/365.25) | P27: =IF(OR(C27="",NOT(ISNUMBER(L27))),"",IF(L27<TODAY(),"Ended",IF(L27-TODAY()<=N(Settings!$C$10),"Ends soon","Covered"))) | Q27: =IF(C27="","",MID(IF(N27="",", value","")&IF(OR(J27="",J27="No"),", receipt","")&IF(K27="",", photo",""),3,100)) | R27: =IF(AND(B27="",C27=""),"",IF(C27="","Needs the item",IF(B27="","Needs a room",IF(COUNTIF(Rooms!$B$6:$B$35,B27)=0,"Not on Rooms",IF(AND(H27<>"",NOT(ISNUMBER(H27))),"Paid not a number",IF(AND(I27<>"",NOT(ISNUMBER(I27))),"Worth not a number",IF(AND(G27<>"",NOT(ISNUMBER(G27))),"Bought is not a date",IF(AND(L27<>"",NOT(ISNUMBER(L27))),"Warranty is not a date","")))))))) | S27: =IF(AND(C27<>"",R27=""),1,0) | T27: =IF(S27=1,N(N27),0) | U27: =IF(AND(S27=1,T27>0),ROUND(T27*100,0)*10000+10000-ROW(),"") | V27: =IF(AND(S27=1,OR(Report!$C$5="",B27=Report!$C$5)),MATCH(B27,Rooms!$B$6:$B$35,0)*10000+ROW(),"") | W27: =IF(AND(S27=1,OR(J27="",J27="No")),1,0) | X27: =IF(AND(S27=1,K27=""),1,0) | Y27: =IF(AND(S27=1,Q27<>""),ROUND(T27*100,0)*10000+10000-ROW(),"")
B28: Home office | C28: Printer | D28: Electronics | E28: Colour laser | F28: SN17676393 | G28: 45083 | H28: 299 | I28: 150 | J28: No | K28: IMG_1527.jpg | L28: 45449 | N28: =IF(C28="","",IF(ISNUMBER(I28),I28,IF(ISNUMBER(H28),H28,""))) | O28: =IF(OR(C28="",NOT(ISNUMBER(G28))),"",(TODAY()-INT(G28))/365.25) | P28: =IF(OR(C28="",NOT(ISNUMBER(L28))),"",IF(L28<TODAY(),"Ended",IF(L28-TODAY()<=N(Settings!$C$10),"Ends soon","Covered"))) | Q28: =IF(C28="","",MID(IF(N28="",", value","")&IF(OR(J28="",J28="No"),", receipt","")&IF(K28="",", photo",""),3,100)) | R28: =IF(AND(B28="",C28=""),"",IF(C28="","Needs the item",IF(B28="","Needs a room",IF(COUNTIF(Rooms!$B$6:$B$35,B28)=0,"Not on Rooms",IF(AND(H28<>"",NOT(ISNUMBER(H28))),"Paid not a number",IF(AND(I28<>"",NOT(ISNUMBER(I28))),"Worth not a number",IF(AND(G28<>"",NOT(ISNUMBER(G28))),"Bought is not a date",IF(AND(L28<>"",NOT(ISNUMBER(L28))),"Warranty is not a date","")))))))) | S28: =IF(AND(C28<>"",R28=""),1,0) | T28: =IF(S28=1,N(N28),0) | U28: =IF(AND(S28=1,T28>0),ROUND(T28*100,0)*10000+10000-ROW(),"") | V28: =IF(AND(S28=1,OR(Report!$C$5="",B28=Report!$C$5)),MATCH(B28,Rooms!$B$6:$B$35,0)*10000+ROW(),"") | W28: =IF(AND(S28=1,OR(J28="",J28="No")),1,0) | X28: =IF(AND(S28=1,K28=""),1,0) | Y28: =IF(AND(S28=1,Q28<>""),ROUND(T28*100,0)*10000+10000-ROW(),"")
B29: Home office | C29: Camera | D29: Electronics | E29: Mirrorless with 2 lenses | F29: SN33113795 | G29: 45474 | H29: 1250 | I29: 950 | J29: File | L29: 46204 | N29: =IF(C29="","",IF(ISNUMBER(I29),I29,IF(ISNUMBER(H29),H29,""))) | O29: =IF(OR(C29="",NOT(ISNUMBER(G29))),"",(TODAY()-INT(G29))/365.25) | P29: =IF(OR(C29="",NOT(ISNUMBER(L29))),"",IF(L29<TODAY(),"Ended",IF(L29-TODAY()<=N(Settings!$C$10),"Ends soon","Covered"))) | Q29: =IF(C29="","",MID(IF(N29="",", value","")&IF(OR(J29="",J29="No"),", receipt","")&IF(K29="",", photo",""),3,100)) | R29: =IF(AND(B29="",C29=""),"",IF(C29="","Needs the item",IF(B29="","Needs a room",IF(COUNTIF(Rooms!$B$6:$B$35,B29)=0,"Not on Rooms",IF(AND(H29<>"",NOT(ISNUMBER(H29))),"Paid not a number",IF(AND(I29<>"",NOT(ISNUMBER(I29))),"Worth not a number",IF(AND(G29<>"",NOT(ISNUMBER(G29))),"Bought is not a date",IF(AND(L29<>"",NOT(ISNUMBER(L29))),"Warranty is not a date","")))))))) | S29: =IF(AND(C29<>"",R29=""),1,0) | T29: =IF(S29=1,N(N29),0) | U29: =IF(AND(S29=1,T29>0),ROUND(T29*100,0)*10000+10000-ROW(),"") | V29: =IF(AND(S29=1,OR(Report!$C$5="",B29=Report!$C$5)),MATCH(B29,Rooms!$B$6:$B$35,0)*10000+ROW(),"") | W29: =IF(AND(S29=1,OR(J29="",J29="No")),1,0) | X29: =IF(AND(S29=1,K29=""),1,0) | Y29: =IF(AND(S29=1,Q29<>""),ROUND(T29*100,0)*10000+10000-ROW(),"")
B30: Home office | C30: Acoustic guitar | D30: Music | E30: Dreadnought | G30: 44185 | H30: 650 | I30: 600 | J30: No | K30: IMG_6253.jpg | N30: =IF(C30="","",IF(ISNUMBER(I30),I30,IF(ISNUMBER(H30),H30,""))) | O30: =IF(OR(C30="",NOT(ISNUMBER(G30))),"",(TODAY()-INT(G30))/365.25) | P30: =IF(OR(C30="",NOT(ISNUMBER(L30))),"",IF(L30<TODAY(),"Ended",IF(L30-TODAY()<=N(Settings!$C$10),"Ends soon","Covered"))) | Q30: =IF(C30="","",MID(IF(N30="",", value","")&IF(OR(J30="",J30="No"),", receipt","")&IF(K30="",", photo",""),3,100)) | R30: =IF(AND(B30="",C30=""),"",IF(C30="","Needs the item",IF(B30="","Needs a room",IF(COUNTIF(Rooms!$B$6:$B$35,B30)=0,"Not on Rooms",IF(AND(H30<>"",NOT(ISNUMBER(H30))),"Paid not a number",IF(AND(I30<>"",NOT(ISNUMBER(I30))),"Worth not a number",IF(AND(G30<>"",NOT(ISNUMBER(G30))),"Bought is not a date",IF(AND(L30<>"",NOT(ISNUMBER(L30))),"Warranty is not a date","")))))))) | S30: =IF(AND(C30<>"",R30=""),1,0) | T30: =IF(S30=1,N(N30),0) | U30: =IF(AND(S30=1,T30>0),ROUND(T30*100,0)*10000+10000-ROW(),"") | V30: =IF(AND(S30=1,OR(Report!$C$5="",B30=Report!$C$5)),MATCH(B30,Rooms!$B$6:$B$35,0)*10000+ROW(),"") | W30: =IF(AND(S30=1,OR(J30="",J30="No")),1,0) | X30: =IF(AND(S30=1,K30=""),1,0) | Y30: =IF(AND(S30=1,Q30<>""),ROUND(T30*100,0)*10000+10000-ROW(),"")
B31: Kids room | C31: Bunk bed | D31: Furniture | E31: Pine, with drawers | G31: 45522 | H31: 690 | I31: 500 | J31: File | K31: IMG_5126.jpg | L31: 46252 | N31: =IF(C31="","",IF(ISNUMBER(I31),I31,IF(ISNUMBER(H31),H31,""))) | O31: =IF(OR(C31="",NOT(ISNUMBER(G31))),"",(TODAY()-INT(G31))/365.25) | P31: =IF(OR(C31="",NOT(ISNUMBER(L31))),"",IF(L31<TODAY(),"Ended",IF(L31-TODAY()<=N(Settings!$C$10),"Ends soon","Covered"))) | Q31: =IF(C31="","",MID(IF(N31="",", value","")&IF(OR(J31="",J31="No"),", receipt","")&IF(K31="",", photo",""),3,100)) | R31: =IF(AND(B31="",C31=""),"",IF(C31="","Needs the item",IF(B31="","Needs a room",IF(COUNTIF(Rooms!$B$6:$B$35,B31)=0,"Not on Rooms",IF(AND(H31<>"",NOT(ISNUMBER(H31))),"Paid not a number",IF(AND(I31<>"",NOT(ISNUMBER(I31))),"Worth not a number",IF(AND(G31<>"",NOT(ISNUMBER(G31))),"Bought is not a date",IF(AND(L31<>"",NOT(ISNUMBER(L31))),"Warranty is not a date","")))))))) | S31: =IF(AND(C31<>"",R31=""),1,0) | T31: =IF(S31=1,N(N31),0) | U31: =IF(AND(S31=1,T31>0),ROUND(T31*100,0)*10000+10000-ROW(),"") | V31: =IF(AND(S31=1,OR(Report!$C$5="",B31=Report!$C$5)),MATCH(B31,Rooms!$B$6:$B$35,0)*10000+ROW(),"") | W31: =IF(AND(S31=1,OR(J31="",J31="No")),1,0) | X31: =IF(AND(S31=1,K31=""),1,0) | Y31: =IF(AND(S31=1,Q31<>""),ROUND(T31*100,0)*10000+10000-ROW(),"")
B32: Kids room | C32: Tablet | D32: Electronics | E32: 10 inch, 64 GB | F32: SN57853790 | G32: 46016 | H32: 349 | I32: 280 | J32: File | K32: IMG_6243.jpg | L32: 46381 | N32: =IF(C32="","",IF(ISNUMBER(I32),I32,IF(ISNUMBER(H32),H32,""))) | O32: =IF(OR(C32="",NOT(ISNUMBER(G32))),"",(TODAY()-INT(G32))/365.25) | P32: =IF(OR(C32="",NOT(ISNUMBER(L32))),"",IF(L32<TODAY(),"Ended",IF(L32-TODAY()<=N(Settings!$C$10),"Ends soon","Covered"))) | Q32: =IF(C32="","",MID(IF(N32="",", value","")&IF(OR(J32="",J32="No"),", receipt","")&IF(K32="",", photo",""),3,100)) | R32: =IF(AND(B32="",C32=""),"",IF(C32="","Needs the item",IF(B32="","Needs a room",IF(COUNTIF(Rooms!$B$6:$B$35,B32)=0,"Not on Rooms",IF(AND(H32<>"",NOT(ISNUMBER(H32))),"Paid not a number",IF(AND(I32<>"",NOT(ISNUMBER(I32))),"Worth not a number",IF(AND(G32<>"",NOT(ISNUMBER(G32))),"Bought is not a date",IF(AND(L32<>"",NOT(ISNUMBER(L32))),"Warranty is not a date","")))))))) | S32: =IF(AND(C32<>"",R32=""),1,0) | T32: =IF(S32=1,N(N32),0) | U32: =IF(AND(S32=1,T32>0),ROUND(T32*100,0)*10000+10000-ROW(),"") | V32: =IF(AND(S32=1,OR(Report!$C$5="",B32=Report!$C$5)),MATCH(B32,Rooms!$B$6:$B$35,0)*10000+ROW(),"") | W32: =IF(AND(S32=1,OR(J32="",J32="No")),1,0) | X32: =IF(AND(S32=1,K32=""),1,0) | Y32: =IF(AND(S32=1,Q32<>""),ROUND(T32*100,0)*10000+10000-ROW(),"")
B33: Kids room | C33: Toys and games | D33: Toys | E33: Lego, board games | I33: 800 | J33: No | K33: IMG_2536.jpg | N33: =IF(C33="","",IF(ISNUMBER(I33),I33,IF(ISNUMBER(H33),H33,""))) | O33: =IF(OR(C33="",NOT(ISNUMBER(G33))),"",(TODAY()-INT(G33))/365.25) | P33: =IF(OR(C33="",NOT(ISNUMBER(L33))),"",IF(L33<TODAY(),"Ended",IF(L33-TODAY()<=N(Settings!$C$10),"Ends soon","Covered"))) | Q33: =IF(C33="","",MID(IF(N33="",", value","")&IF(OR(J33="",J33="No"),", receipt","")&IF(K33="",", photo",""),3,100)) | R33: =IF(AND(B33="",C33=""),"",IF(C33="","Needs the item",IF(B33="","Needs a room",IF(COUNTIF(Rooms!$B$6:$B$35,B33)=0,"Not on Rooms",IF(AND(H33<>"",NOT(ISNUMBER(H33))),"Paid not a number",IF(AND(I33<>"",NOT(ISNUMBER(I33))),"Worth not a number",IF(AND(G33<>"",NOT(ISNUMBER(G33))),"Bought is not a date",IF(AND(L33<>"",NOT(ISNUMBER(L33))),"Warranty is not a date","")))))))) | S33: =IF(AND(C33<>"",R33=""),1,0) | T33: =IF(S33=1,N(N33),0) | U33: =IF(AND(S33=1,T33>0),ROUND(T33*100,0)*10000+10000-ROW(),"") | V33: =IF(AND(S33=1,OR(Report!$C$5="",B33=Report!$C$5)),MATCH(B33,Rooms!$B$6:$B$35,0)*10000+ROW(),"") | W33: =IF(AND(S33=1,OR(J33="",J33="No")),1,0) | X33: =IF(AND(S33=1,K33=""),1,0) | Y33: =IF(AND(S33=1,Q33<>""),ROUND(T33*100,0)*10000+10000-ROW(),"")
B34: Kids room | C34: Keyboard piano | D34: Music | E34: 61 keys | G34: 46016 | H34: 229 | I34: 180 | J34: File | L34: 46381 | N34: =IF(C34="","",IF(ISNUMBER(I34),I34,IF(ISNUMBER(H34),H34,""))) | O34: =IF(OR(C34="",NOT(ISNUMBER(G34))),"",(TODAY()-INT(G34))/365.25) | P34: =IF(OR(C34="",NOT(ISNUMBER(L34))),"",IF(L34<TODAY(),"Ended",IF(L34-TODAY()<=N(Settings!$C$10),"Ends soon","Covered"))) | Q34: =IF(C34="","",MID(IF(N34="",", value","")&IF(OR(J34="",J34="No"),", receipt","")&IF(K34="",", photo",""),3,100)) | R34: =IF(AND(B34="",C34=""),"",IF(C34="","Needs the item",IF(B34="","Needs a room",IF(COUNTIF(Rooms!$B$6:$B$35,B34)=0,"Not on Rooms",IF(AND(H34<>"",NOT(ISNUMBER(H34))),"Paid not a number",IF(AND(I34<>"",NOT(ISNUMBER(I34))),"Worth not a number",IF(AND(G34<>"",NOT(ISNUMBER(G34))),"Bought is not a date",IF(AND(L34<>"",NOT(ISNUMBER(L34))),"Warranty is not a date","")))))))) | S34: =IF(AND(C34<>"",R34=""),1,0) | T34: =IF(S34=1,N(N34),0) | U34: =IF(AND(S34=1,T34>0),ROUND(T34*100,0)*10000+10000-ROW(),"") | V34: =IF(AND(S34=1,OR(Report!$C$5="",B34=Report!$C$5)),MATCH(B34,Rooms!$B$6:$B$35,0)*10000+ROW(),"") | W34: =IF(AND(S34=1,OR(J34="",J34="No")),1,0) | X34: =IF(AND(S34=1,K34=""),1,0) | Y34: =IF(AND(S34=1,Q34<>""),ROUND(T34*100,0)*10000+10000-ROW(),"")
B35: Bathroom | C35: Hair dryer and straightener | D35: Appliances | E35: Two items | F35: SN65216647 | G35: 45782 | H35: 180 | I35: 140 | J35: No | N35: =IF(C35="","",IF(ISNUMBER(I35),I35,IF(ISNUMBER(H35),H35,""))) | O35: =IF(OR(C35="",NOT(ISNUMBER(G35))),"",(TODAY()-INT(G35))/365.25) | P35: =IF(OR(C35="",NOT(ISNUMBER(L35))),"",IF(L35<TODAY(),"Ended",IF(L35-TODAY()<=N(Settings!$C$10),"Ends soon","Covered"))) | Q35: =IF(C35="","",MID(IF(N35="",", value","")&IF(OR(J35="",J35="No"),", receipt","")&IF(K35="",", photo",""),3,100)) | R35: =IF(AND(B35="",C35=""),"",IF(C35="","Needs the item",IF(B35="","Needs a room",IF(COUNTIF(Rooms!$B$6:$B$35,B35)=0,"Not on Rooms",IF(AND(H35<>"",NOT(ISNUMBER(H35))),"Paid not a number",IF(AND(I35<>"",NOT(ISNUMBER(I35))),"Worth not a number",IF(AND(G35<>"",NOT(ISNUMBER(G35))),"Bought is not a date",IF(AND(L35<>"",NOT(ISNUMBER(L35))),"Warranty is not a date","")))))))) | S35: =IF(AND(C35<>"",R35=""),1,0) | T35: =IF(S35=1,N(N35),0) | U35: =IF(AND(S35=1,T35>0),ROUND(T35*100,0)*10000+10000-ROW(),"") | V35: =IF(AND(S35=1,OR(Report!$C$5="",B35=Report!$C$5)),MATCH(B35,Rooms!$B$6:$B$35,0)*10000+ROW(),"") | W35: =IF(AND(S35=1,OR(J35="",J35="No")),1,0) | X35: =IF(AND(S35=1,K35=""),1,0) | Y35: =IF(AND(S35=1,Q35<>""),ROUND(T35*100,0)*10000+10000-ROW(),"")
B36: Bathroom | C36: Electric toothbrushes | D36: Appliances | E36: Two, with chargers | F36: SN22056547 | G36: 46084 | H36: 160 | I36: 150 | J36: File | K36: IMG_1347.jpg | L36: 46815 | N36: =IF(C36="","",IF(ISNUMBER(I36),I36,IF(ISNUMBER(H36),H36,""))) | O36: =IF(OR(C36="",NOT(ISNUMBER(G36))),"",(TODAY()-INT(G36))/365.25) | P36: =IF(OR(C36="",NOT(ISNUMBER(L36))),"",IF(L36<TODAY(),"Ended",IF(L36-TODAY()<=N(Settings!$C$10),"Ends soon","Covered"))) | Q36: =IF(C36="","",MID(IF(N36="",", value","")&IF(OR(J36="",J36="No"),", receipt","")&IF(K36="",", photo",""),3,100)) | R36: =IF(AND(B36="",C36=""),"",IF(C36="","Needs the item",IF(B36="","Needs a room",IF(COUNTIF(Rooms!$B$6:$B$35,B36)=0,"Not on Rooms",IF(AND(H36<>"",NOT(ISNUMBER(H36))),"Paid not a number",IF(AND(I36<>"",NOT(ISNUMBER(I36))),"Worth not a number",IF(AND(G36<>"",NOT(ISNUMBER(G36))),"Bought is not a date",IF(AND(L36<>"",NOT(ISNUMBER(L36))),"Warranty is not a date","")))))))) | S36: =IF(AND(C36<>"",R36=""),1,0) | T36: =IF(S36=1,N(N36),0) | U36: =IF(AND(S36=1,T36>0),ROUND(T36*100,0)*10000+10000-ROW(),"") | V36: =IF(AND(S36=1,OR(Report!$C$5="",B36=Report!$C$5)),MATCH(B36,Rooms!$B$6:$B$35,0)*10000+ROW(),"") | W36: =IF(AND(S36=1,OR(J36="",J36="No")),1,0) | X36: =IF(AND(S36=1,K36=""),1,0) | Y36: =IF(AND(S36=1,Q36<>""),ROUND(T36*100,0)*10000+10000-ROW(),"")
B37: Hallway | C37: Mirror | D37: Art and decor | E37: Round, brass frame | G37: 45209 | H37: 220 | I37: 180 | J37: No | K37: IMG_6382.jpg | N37: =IF(C37="","",IF(ISNUMBER(I37),I37,IF(ISNUMBER(H37),H37,""))) | O37: =IF(OR(C37="",NOT(ISNUMBER(G37))),"",(TODAY()-INT(G37))/365.25) | P37: =IF(OR(C37="",NOT(ISNUMBER(L37))),"",IF(L37<TODAY(),"Ended",IF(L37-TODAY()<=N(Settings!$C$10),"Ends soon","Covered"))) | Q37: =IF(C37="","",MID(IF(N37="",", value","")&IF(OR(J37="",J37="No"),", receipt","")&IF(K37="",", photo",""),3,100)) | R37: =IF(AND(B37="",C37=""),"",IF(C37="","Needs the item",IF(B37="","Needs a room",IF(COUNTIF(Rooms!$B$6:$B$35,B37)=0,"Not on Rooms",IF(AND(H37<>"",NOT(ISNUMBER(H37))),"Paid not a number",IF(AND(I37<>"",NOT(ISNUMBER(I37))),"Worth not a number",IF(AND(G37<>"",NOT(ISNUMBER(G37))),"Bought is not a date",IF(AND(L37<>"",NOT(ISNUMBER(L37))),"Warranty is not a date","")))))))) | S37: =IF(AND(C37<>"",R37=""),1,0) | T37: =IF(S37=1,N(N37),0) | U37: =IF(AND(S37=1,T37>0),ROUND(T37*100,0)*10000+10000-ROW(),"") | V37: =IF(AND(S37=1,OR(Report!$C$5="",B37=Report!$C$5)),MATCH(B37,Rooms!$B$6:$B$35,0)*10000+ROW(),"") | W37: =IF(AND(S37=1,OR(J37="",J37="No")),1,0) | X37: =IF(AND(S37=1,K37=""),1,0) | Y37: =IF(AND(S37=1,Q37<>""),ROUND(T37*100,0)*10000+10000-ROW(),"")
B38: Hallway | C38: Coats and boots | D38: Clothing | E38: Family | I38: 900 | J38: No | N38: =IF(C38="","",IF(ISNUMBER(I38),I38,IF(ISNUMBER(H38),H38,""))) | O38: =IF(OR(C38="",NOT(ISNUMBER(G38))),"",(TODAY()-INT(G38))/365.25) | P38: =IF(OR(C38="",NOT(ISNUMBER(L38))),"",IF(L38<TODAY(),"Ended",IF(L38-TODAY()<=N(Settings!$C$10),"Ends soon","Covered"))) | Q38: =IF(C38="","",MID(IF(N38="",", value","")&IF(OR(J38="",J38="No"),", receipt","")&IF(K38="",", photo",""),3,100)) | R38: =IF(AND(B38="",C38=""),"",IF(C38="","Needs the item",IF(B38="","Needs a room",IF(COUNTIF(Rooms!$B$6:$B$35,B38)=0,"Not on Rooms",IF(AND(H38<>"",NOT(ISNUMBER(H38))),"Paid not a number",IF(AND(I38<>"",NOT(ISNUMBER(I38))),"Worth not a number",IF(AND(G38<>"",NOT(ISNUMBER(G38))),"Bought is not a date",IF(AND(L38<>"",NOT(ISNUMBER(L38))),"Warranty is not a date","")))))))) | S38: =IF(AND(C38<>"",R38=""),1,0) | T38: =IF(S38=1,N(N38),0) | U38: =IF(AND(S38=1,T38>0),ROUND(T38*100,0)*10000+10000-ROW(),"") | V38: =IF(AND(S38=1,OR(Report!$C$5="",B38=Report!$C$5)),MATCH(B38,Rooms!$B$6:$B$35,0)*10000+ROW(),"") | W38: =IF(AND(S38=1,OR(J38="",J38="No")),1,0) | X38: =IF(AND(S38=1,K38=""),1,0) | Y38: =IF(AND(S38=1,Q38<>""),ROUND(T38*100,0)*10000+10000-ROW(),"")
B39: Garage | C39: Road bike | D39: Sports | E39: Carbon, size 56 | F39: SN52545585 | G39: 45407 | H39: 2100 | I39: 1700 | J39: Paper | K39: IMG_7336.jpg | L39: 46137 | N39: =IF(C39="","",IF(ISNUMBER(I39),I39,IF(ISNUMBER(H39),H39,""))) | O39: =IF(OR(C39="",NOT(ISNUMBER(G39))),"",(TODAY()-INT(G39))/365.25) | P39: =IF(OR(C39="",NOT(ISNUMBER(L39))),"",IF(L39<TODAY(),"Ended",IF(L39-TODAY()<=N(Settings!$C$10),"Ends soon","Covered"))) | Q39: =IF(C39="","",MID(IF(N39="",", value","")&IF(OR(J39="",J39="No"),", receipt","")&IF(K39="",", photo",""),3,100)) | R39: =IF(AND(B39="",C39=""),"",IF(C39="","Needs the item",IF(B39="","Needs a room",IF(COUNTIF(Rooms!$B$6:$B$35,B39)=0,"Not on Rooms",IF(AND(H39<>"",NOT(ISNUMBER(H39))),"Paid not a number",IF(AND(I39<>"",NOT(ISNUMBER(I39))),"Worth not a number",IF(AND(G39<>"",NOT(ISNUMBER(G39))),"Bought is not a date",IF(AND(L39<>"",NOT(ISNUMBER(L39))),"Warranty is not a date","")))))))) | S39: =IF(AND(C39<>"",R39=""),1,0) | T39: =IF(S39=1,N(N39),0) | U39: =IF(AND(S39=1,T39>0),ROUND(T39*100,0)*10000+10000-ROW(),"") | V39: =IF(AND(S39=1,OR(Report!$C$5="",B39=Report!$C$5)),MATCH(B39,Rooms!$B$6:$B$35,0)*10000+ROW(),"") | W39: =IF(AND(S39=1,OR(J39="",J39="No")),1,0) | X39: =IF(AND(S39=1,K39=""),1,0) | Y39: =IF(AND(S39=1,Q39<>""),ROUND(T39*100,0)*10000+10000-ROW(),"")
B40: Garage | C40: Kids bikes | D40: Sports | E40: Two bikes | F40: SN81221428 | G40: 45809 | H40: 520 | I40: 400 | J40: File | K40: IMG_9796.jpg | L40: 46174 | N40: =IF(C40="","",IF(ISNUMBER(I40),I40,IF(ISNUMBER(H40),H40,""))) | O40: =IF(OR(C40="",NOT(ISNUMBER(G40))),"",(TODAY()-INT(G40))/365.25) | P40: =IF(OR(C40="",NOT(ISNUMBER(L40))),"",IF(L40<TODAY(),"Ended",IF(L40-TODAY()<=N(Settings!$C$10),"Ends soon","Covered"))) | Q40: =IF(C40="","",MID(IF(N40="",", value","")&IF(OR(J40="",J40="No"),", receipt","")&IF(K40="",", photo",""),3,100)) | R40: =IF(AND(B40="",C40=""),"",IF(C40="","Needs the item",IF(B40="","Needs a room",IF(COUNTIF(Rooms!$B$6:$B$35,B40)=0,"Not on Rooms",IF(AND(H40<>"",NOT(ISNUMBER(H40))),"Paid not a number",IF(AND(I40<>"",NOT(ISNUMBER(I40))),"Worth not a number",IF(AND(G40<>"",NOT(ISNUMBER(G40))),"Bought is not a date",IF(AND(L40<>"",NOT(ISNUMBER(L40))),"Warranty is not a date","")))))))) | S40: =IF(AND(C40<>"",R40=""),1,0) | T40: =IF(S40=1,N(N40),0) | U40: =IF(AND(S40=1,T40>0),ROUND(T40*100,0)*10000+10000-ROW(),"") | V40: =IF(AND(S40=1,OR(Report!$C$5="",B40=Report!$C$5)),MATCH(B40,Rooms!$B$6:$B$35,0)*10000+ROW(),"") | W40: =IF(AND(S40=1,OR(J40="",J40="No")),1,0) | X40: =IF(AND(S40=1,K40=""),1,0) | Y40: =IF(AND(S40=1,Q40<>""),ROUND(T40*100,0)*10000+10000-ROW(),"")
B41: Garage | C41: Cordless drill set | D41: Tools | E41: 18 V with 2 batteries | F41: SN94834301 | G41: 45698 | H41: 259 | I41: 220 | J41: File | K41: IMG_5166.jpg | L41: 46793 | N41: =IF(C41="","",IF(ISNUMBER(I41),I41,IF(ISNUMBER(H41),H41,""))) | O41: =IF(OR(C41="",NOT(ISNUMBER(G41))),"",(TODAY()-INT(G41))/365.25) | P41: =IF(OR(C41="",NOT(ISNUMBER(L41))),"",IF(L41<TODAY(),"Ended",IF(L41-TODAY()<=N(Settings!$C$10),"Ends soon","Covered"))) | Q41: =IF(C41="","",MID(IF(N41="",", value","")&IF(OR(J41="",J41="No"),", receipt","")&IF(K41="",", photo",""),3,100)) | R41: =IF(AND(B41="",C41=""),"",IF(C41="","Needs the item",IF(B41="","Needs a room",IF(COUNTIF(Rooms!$B$6:$B$35,B41)=0,"Not on Rooms",IF(AND(H41<>"",NOT(ISNUMBER(H41))),"Paid not a number",IF(AND(I41<>"",NOT(ISNUMBER(I41))),"Worth not a number",IF(AND(G41<>"",NOT(ISNUMBER(G41))),"Bought is not a date",IF(AND(L41<>"",NOT(ISNUMBER(L41))),"Warranty is not a date","")))))))) | S41: =IF(AND(C41<>"",R41=""),1,0) | T41: =IF(S41=1,N(N41),0) | U41: =IF(AND(S41=1,T41>0),ROUND(T41*100,0)*10000+10000-ROW(),"") | V41: =IF(AND(S41=1,OR(Report!$C$5="",B41=Report!$C$5)),MATCH(B41,Rooms!$B$6:$B$35,0)*10000+ROW(),"") | W41: =IF(AND(S41=1,OR(J41="",J41="No")),1,0) | X41: =IF(AND(S41=1,K41=""),1,0) | Y41: =IF(AND(S41=1,Q41<>""),ROUND(T41*100,0)*10000+10000-ROW(),"")
B42: Garage | C42: Lawn mower | D42: Tools | E42: Battery, 40 cm | F42: SN89612357 | G42: 45413 | H42: 399 | I42: 300 | J42: No | K42: IMG_1980.jpg | L42: 46143 | N42: =IF(C42="","",IF(ISNUMBER(I42),I42,IF(ISNUMBER(H42),H42,""))) | O42: =IF(OR(C42="",NOT(ISNUMBER(G42))),"",(TODAY()-INT(G42))/365.25) | P42: =IF(OR(C42="",NOT(ISNUMBER(L42))),"",IF(L42<TODAY(),"Ended",IF(L42-TODAY()<=N(Settings!$C$10),"Ends soon","Covered"))) | Q42: =IF(C42="","",MID(IF(N42="",", value","")&IF(OR(J42="",J42="No"),", receipt","")&IF(K42="",", photo",""),3,100)) | R42: =IF(AND(B42="",C42=""),"",IF(C42="","Needs the item",IF(B42="","Needs a room",IF(COUNTIF(Rooms!$B$6:$B$35,B42)=0,"Not on Rooms",IF(AND(H42<>"",NOT(ISNUMBER(H42))),"Paid not a number",IF(AND(I42<>"",NOT(ISNUMBER(I42))),"Worth not a number",IF(AND(G42<>"",NOT(ISNUMBER(G42))),"Bought is not a date",IF(AND(L42<>"",NOT(ISNUMBER(L42))),"Warranty is not a date","")))))))) | S42: =IF(AND(C42<>"",R42=""),1,0) | T42: =IF(S42=1,N(N42),0) | U42: =IF(AND(S42=1,T42>0),ROUND(T42*100,0)*10000+10000-ROW(),"") | V42: =IF(AND(S42=1,OR(Report!$C$5="",B42=Report!$C$5)),MATCH(B42,Rooms!$B$6:$B$35,0)*10000+ROW(),"") | W42: =IF(AND(S42=1,OR(J42="",J42="No")),1,0) | X42: =IF(AND(S42=1,K42=""),1,0) | Y42: =IF(AND(S42=1,Q42<>""),ROUND(T42*100,0)*10000+10000-ROW(),"")
...

Sheet Rooms
B2: Rooms
B3: Each room or place once, in the order you walk through your home.
B5: Room | C5: Note | D5: Items | E5: Worth | F5: No receipt | G5: No photo
B6: Living room | D6: =IF(B6="","",SUMIFS(Items!$S$6:$S$1005,Items!$B$6:$B$1005,B6)) | E6: =IF(B6="","",SUMIFS(Items!$T$6:$T$1005,Items!$B$6:$B$1005,B6)) | F6: =IF(B6="","",SUMIFS(Items!$W$6:$W$1005,Items!$B$6:$B$1005,B6)) | G6: =IF(B6="","",SUMIFS(Items!$X$6:$X$1005,Items!$B$6:$B$1005,B6))
B7: Kitchen | D7: =IF(B7="","",SUMIFS(Items!$S$6:$S$1005,Items!$B$6:$B$1005,B7)) | E7: =IF(B7="","",SUMIFS(Items!$T$6:$T$1005,Items!$B$6:$B$1005,B7)) | F7: =IF(B7="","",SUMIFS(Items!$W$6:$W$1005,Items!$B$6:$B$1005,B7)) | G7: =IF(B7="","",SUMIFS(Items!$X$6:$X$1005,Items!$B$6:$B$1005,B7))
B8: Main bedroom | D8: =IF(B8="","",SUMIFS(Items!$S$6:$S$1005,Items!$B$6:$B$1005,B8)) | E8: =IF(B8="","",SUMIFS(Items!$T$6:$T$1005,Items!$B$6:$B$1005,B8)) | F8: =IF(B8="","",SUMIFS(Items!$W$6:$W$1005,Items!$B$6:$B$1005,B8)) | G8: =IF(B8="","",SUMIFS(Items!$X$6:$X$1005,Items!$B$6:$B$1005,B8))
B9: Home office | D9: =IF(B9="","",SUMIFS(Items!$S$6:$S$1005,Items!$B$6:$B$1005,B9)) | E9: =IF(B9="","",SUMIFS(Items!$T$6:$T$1005,Items!$B$6:$B$1005,B9)) | F9: =IF(B9="","",SUMIFS(Items!$W$6:$W$1005,Items!$B$6:$B$1005,B9)) | G9: =IF(B9="","",SUMIFS(Items!$X$6:$X$1005,Items!$B$6:$B$1005,B9))
B10: Kids room | D10: =IF(B10="","",SUMIFS(Items!$S$6:$S$1005,Items!$B$6:$B$1005,B10)) | E10: =IF(B10="","",SUMIFS(Items!$T$6:$T$1005,Items!$B$6:$B$1005,B10)) | F10: =IF(B10="","",SUMIFS(Items!$W$6:$W$1005,Items!$B$6:$B$1005,B10)) | G10: =IF(B10="","",SUMIFS(Items!$X$6:$X$1005,Items!$B$6:$B$1005,B10))
B11: Bathroom | D11: =IF(B11="","",SUMIFS(Items!$S$6:$S$1005,Items!$B$6:$B$1005,B11)) | E11: =IF(B11="","",SUMIFS(Items!$T$6:$T$1005,Items!$B$6:$B$1005,B11)) | F11: =IF(B11="","",SUMIFS(Items!$W$6:$W$1005,Items!$B$6:$B$1005,B11)) | G11: =IF(B11="","",SUMIFS(Items!$X$6:$X$1005,Items!$B$6:$B$1005,B11))
