Workbook

Sheet Dashboard
B2: Chores and pocket money
B3: ="The week of "&DAY(Settings!$C$6)&" "&CHOOSE(MONTH(Settings!$C$6),"Jan","Feb","Mar","Apr","May","Jun","Jul","Aug","Sep","Oct","Nov","Dec")&" to "&DAY((Settings!$C$6+6))&" "&CHOOSE(MONTH((Settings!$C$6+6)),"Jan","Feb","Mar","Apr","May","Jun","Jul","Aug","Sep","Oct","Nov","Dec")&", and the jars so far"&IF(Settings!$C$4="",".",", in "&Settings!$C$4&".")
B4: Done this week | C4: Points | D4: To pay this week | E4: In the jars | G4: Save jars | H4: Spend jars | I4: Give jars | J4: Goals reached
B5: =SUM('This week'!$L$6:$L$45)&" of "&SUM(Chores!$N$6:$N$45) | C5: =SUM('This week'!$M$6:$M$45) | D5: =SUM(E9:E14) | E5: =SUM(Kids!$K$6:$K$11)+SUM(Kids!$L$6:$L$11)+SUM(Kids!$M$6:$M$11) | G5: =SUM(Kids!$K$6:$K$11) | H5: =SUM(Kids!$L$6:$L$11) | I5: =SUM(Kids!$M$6:$M$11) | J5: =COUNTIF(Kids!$O$6:$O$11,"Reached")&" of "&COUNT(Kids!$J$6:$J$11)
B8: This week | C8: Done | D8: Points | E8: Earned | G8: Jars | H8: Save | I8: Spend | J8: Give
B9: =IF(Kids!$B$6="","",Kids!$B$6) | C9: =IF(B9="","",SUMIFS('This week'!$L$6:$L$45,'This week'!$B$6:$B$45,B9)) | D9: =IF(B9="","",SUMIFS('This week'!$M$6:$M$45,'This week'!$B$6:$B$45,B9)) | E9: =IF(B9="","",N(Kids!$D$6)+N(Kids!$E$6)*D9) | G9: =IF(Kids!$B$6="","",Kids!$B$6) | H9: =IF(G9="","",Kids!$K$6) | I9: =IF(G9="","",Kids!$L$6) | J9: =IF(G9="","",Kids!$M$6)
B10: =IF(Kids!$B$7="","",Kids!$B$7) | C10: =IF(B10="","",SUMIFS('This week'!$L$6:$L$45,'This week'!$B$6:$B$45,B10)) | D10: =IF(B10="","",SUMIFS('This week'!$M$6:$M$45,'This week'!$B$6:$B$45,B10)) | E10: =IF(B10="","",N(Kids!$D$7)+N(Kids!$E$7)*D10) | G10: =IF(Kids!$B$7="","",Kids!$B$7) | H10: =IF(G10="","",Kids!$K$7) | I10: =IF(G10="","",Kids!$L$7) | J10: =IF(G10="","",Kids!$M$7)
B11: =IF(Kids!$B$8="","",Kids!$B$8) | C11: =IF(B11="","",SUMIFS('This week'!$L$6:$L$45,'This week'!$B$6:$B$45,B11)) | D11: =IF(B11="","",SUMIFS('This week'!$M$6:$M$45,'This week'!$B$6:$B$45,B11)) | E11: =IF(B11="","",N(Kids!$D$8)+N(Kids!$E$8)*D11) | G11: =IF(Kids!$B$8="","",Kids!$B$8) | H11: =IF(G11="","",Kids!$K$8) | I11: =IF(G11="","",Kids!$L$8) | J11: =IF(G11="","",Kids!$M$8)
B12: =IF(Kids!$B$9="","",Kids!$B$9) | C12: =IF(B12="","",SUMIFS('This week'!$L$6:$L$45,'This week'!$B$6:$B$45,B12)) | D12: =IF(B12="","",SUMIFS('This week'!$M$6:$M$45,'This week'!$B$6:$B$45,B12)) | E12: =IF(B12="","",N(Kids!$D$9)+N(Kids!$E$9)*D12) | G12: =IF(Kids!$B$9="","",Kids!$B$9) | H12: =IF(G12="","",Kids!$K$9) | I12: =IF(G12="","",Kids!$L$9) | J12: =IF(G12="","",Kids!$M$9)
B13: =IF(Kids!$B$10="","",Kids!$B$10) | C13: =IF(B13="","",SUMIFS('This week'!$L$6:$L$45,'This week'!$B$6:$B$45,B13)) | D13: =IF(B13="","",SUMIFS('This week'!$M$6:$M$45,'This week'!$B$6:$B$45,B13)) | E13: =IF(B13="","",N(Kids!$D$10)+N(Kids!$E$10)*D13) | G13: =IF(Kids!$B$10="","",Kids!$B$10) | H13: =IF(G13="","",Kids!$K$10) | I13: =IF(G13="","",Kids!$L$10) | J13: =IF(G13="","",Kids!$M$10)
B14: =IF(Kids!$B$11="","",Kids!$B$11) | C14: =IF(B14="","",SUMIFS('This week'!$L$6:$L$45,'This week'!$B$6:$B$45,B14)) | D14: =IF(B14="","",SUMIFS('This week'!$M$6:$M$45,'This week'!$B$6:$B$45,B14)) | E14: =IF(B14="","",N(Kids!$D$11)+N(Kids!$E$11)*D14) | G14: =IF(Kids!$B$11="","",Kids!$B$11) | H14: =IF(G14="","",Kids!$K$11) | I14: =IF(G14="","",Kids!$L$11) | J14: =IF(G14="","",Kids!$M$11)
B17: Goals | C17: For | D17: Saved | E17: Weeks to go
B18: =IF(OR(Kids!$B$6="",Kids!$I$6=""),"",Kids!$B$6) | C18: =IF(B18="","",Kids!$I$6) | D18: =IF(B18="","",FIXED(Kids!$K$6,2)&IF(N(Kids!$J$6)=0,""," of "&FIXED(Kids!$J$6,2))) | E18: =IF(B18="","",Kids!$O$6)
B19: =IF(OR(Kids!$B$7="",Kids!$I$7=""),"",Kids!$B$7) | C19: =IF(B19="","",Kids!$I$7) | D19: =IF(B19="","",FIXED(Kids!$K$7,2)&IF(N(Kids!$J$7)=0,""," of "&FIXED(Kids!$J$7,2))) | E19: =IF(B19="","",Kids!$O$7)
B20: =IF(OR(Kids!$B$8="",Kids!$I$8=""),"",Kids!$B$8) | C20: =IF(B20="","",Kids!$I$8) | D20: =IF(B20="","",FIXED(Kids!$K$8,2)&IF(N(Kids!$J$8)=0,""," of "&FIXED(Kids!$J$8,2))) | E20: =IF(B20="","",Kids!$O$8)
B21: =IF(OR(Kids!$B$9="",Kids!$I$9=""),"",Kids!$B$9) | C21: =IF(B21="","",Kids!$I$9) | D21: =IF(B21="","",FIXED(Kids!$K$9,2)&IF(N(Kids!$J$9)=0,""," of "&FIXED(Kids!$J$9,2))) | E21: =IF(B21="","",Kids!$O$9)
B22: =IF(OR(Kids!$B$10="",Kids!$I$10=""),"",Kids!$B$10) | C22: =IF(B22="","",Kids!$I$10) | D22: =IF(B22="","",FIXED(Kids!$K$10,2)&IF(N(Kids!$J$10)=0,""," of "&FIXED(Kids!$J$10,2))) | E22: =IF(B22="","",Kids!$O$10)
B23: =IF(OR(Kids!$B$11="",Kids!$I$11=""),"",Kids!$B$11) | C23: =IF(B23="","",Kids!$I$11) | D23: =IF(B23="","",FIXED(Kids!$K$11,2)&IF(N(Kids!$J$11)=0,""," of "&FIXED(Kids!$J$11,2))) | E23: =IF(B23="","",Kids!$O$11)

Sheet This week
B2: ="Chores for the week of "&DAY(Settings!$C$6)&" "&CHOOSE(MONTH(Settings!$C$6),"Jan","Feb","Mar","Apr","May","Jun","Jul","Aug","Sep","Oct","Nov","Dec")&" to "&DAY((Settings!$C$6+6))&" "&CHOOSE(MONTH((Settings!$C$6+6)),"Jan","Feb","Mar","Apr","May","Jun","Jul","Aug","Sep","Oct","Nov","Dec")
B3: An x in the box when it is done. Shaded boxes are the days it is expected. To print, use Fridge chart.
B5: Child | C5: Chore | D5: Points | E5: ="Mon "&DAY(Settings!$C$6+0) | F5: ="Tue "&DAY(Settings!$C$6+1) | G5: ="Wed "&DAY(Settings!$C$6+2) | H5: ="Thu "&DAY(Settings!$C$6+3) | I5: ="Fri "&DAY(Settings!$C$6+4) | J5: ="Sat "&DAY(Settings!$C$6+5) | K5: ="Sun "&DAY(Settings!$C$6+6) | L5: Done | M5: Earned
B6: =IF(Chores!B6="","",IF(Chores!C6="","",Chores!C6)) | C6: =IF(Chores!B6="","",Chores!B6) | D6: =IF(Chores!B6="","",N(Chores!D6)) | E6: x | F6: x | G6: x | H6: x | I6: x | J6: x | K6: x | L6: =IF(C6="","",COUNTA(E6:K6)) | M6: =IF(C6="","",L6*D6)
B7: =IF(Chores!B7="","",IF(Chores!C7="","",Chores!C7)) | C7: =IF(Chores!B7="","",Chores!B7) | D7: =IF(Chores!B7="","",N(Chores!D7)) | E7: x | F7: x | G7: x | I7: x | L7: =IF(C7="","",COUNTA(E7:K7)) | M7: =IF(C7="","",L7*D7)
B8: =IF(Chores!B8="","",IF(Chores!C8="","",Chores!C8)) | C8: =IF(Chores!B8="","",Chores!B8) | D8: =IF(Chores!B8="","",N(Chores!D8)) | E8: x | F8: x | G8: x | H8: x | I8: x | J8: x | K8: x | L8: =IF(C8="","",COUNTA(E8:K8)) | M8: =IF(C8="","",L8*D8)
B9: =IF(Chores!B9="","",IF(Chores!C9="","",Chores!C9)) | C9: =IF(Chores!B9="","",Chores!B9) | D9: =IF(Chores!B9="","",N(Chores!D9)) | J9: x | L9: =IF(C9="","",COUNTA(E9:K9)) | M9: =IF(C9="","",L9*D9)
B10: =IF(Chores!B10="","",IF(Chores!C10="","",Chores!C10)) | C10: =IF(Chores!B10="","",Chores!B10) | D10: =IF(Chores!B10="","",N(Chores!D10)) | E10: x | G10: x | L10: =IF(C10="","",COUNTA(E10:K10)) | M10: =IF(C10="","",L10*D10)
B11: =IF(Chores!B11="","",IF(Chores!C11="","",Chores!C11)) | C11: =IF(Chores!B11="","",Chores!B11) | D11: =IF(Chores!B11="","",N(Chores!D11)) | E11: x | F11: x | G11: x | H11: x | I11: x | J11: x | K11: x | L11: =IF(C11="","",COUNTA(E11:K11)) | M11: =IF(C11="","",L11*D11)
B12: =IF(Chores!B12="","",IF(Chores!C12="","",Chores!C12)) | C12: =IF(Chores!B12="","",Chores!B12) | D12: =IF(Chores!B12="","",N(Chores!D12)) | E12: x | F12: x | H12: x | I12: x | J12: x | K12: x | L12: =IF(C12="","",COUNTA(E12:K12)) | M12: =IF(C12="","",L12*D12)
B13: =IF(Chores!B13="","",IF(Chores!C13="","",Chores!C13)) | C13: =IF(Chores!B13="","",Chores!B13) | D13: =IF(Chores!B13="","",N(Chores!D13)) | J13: x | L13: =IF(C13="","",COUNTA(E13:K13)) | M13: =IF(C13="","",L13*D13)
B14: =IF(Chores!B14="","",IF(Chores!C14="","",Chores!C14)) | C14: =IF(Chores!B14="","",Chores!B14) | D14: =IF(Chores!B14="","",N(Chores!D14)) | E14: x | G14: x | L14: =IF(C14="","",COUNTA(E14:K14)) | M14: =IF(C14="","",L14*D14)
B15: =IF(Chores!B15="","",IF(Chores!C15="","",Chores!C15)) | C15: =IF(Chores!B15="","",Chores!B15) | D15: =IF(Chores!B15="","",N(Chores!D15)) | E15: x | F15: x | G15: x | H15: x | I15: x | J15: x | K15: x | L15: =IF(C15="","",COUNTA(E15:K15)) | M15: =IF(C15="","",L15*D15)
B16: =IF(Chores!B16="","",IF(Chores!C16="","",Chores!C16)) | C16: =IF(Chores!B16="","",Chores!B16) | D16: =IF(Chores!B16="","",N(Chores!D16)) | E16: x | F16: x | G16: x | H16: x | I16: x | L16: =IF(C16="","",COUNTA(E16:K16)) | M16: =IF(C16="","",L16*D16)
B17: =IF(Chores!B17="","",IF(Chores!C17="","",Chores!C17)) | C17: =IF(Chores!B17="","",Chores!B17) | D17: =IF(Chores!B17="","",N(Chores!D17)) | H17: x | J17: x | L17: =IF(C17="","",COUNTA(E17:K17)) | M17: =IF(C17="","",L17*D17)
B18: =IF(Chores!B18="","",IF(Chores!C18="","",Chores!C18)) | C18: =IF(Chores!B18="","",Chores!B18) | D18: =IF(Chores!B18="","",N(Chores!D18)) | E18: x | F18: x | H18: x | L18: =IF(C18="","",COUNTA(E18:K18)) | M18: =IF(C18="","",L18*D18)
B19: =IF(Chores!B19="","",IF(Chores!C19="","",Chores!C19)) | C19: =IF(Chores!B19="","",Chores!B19) | D19: =IF(Chores!B19="","",N(Chores!D19)) | K19: x | L19: =IF(C19="","",COUNTA(E19:K19)) | M19: =IF(C19="","",L19*D19)
B20: =IF(Chores!B20="","",IF(Chores!C20="","",Chores!C20)) | C20: =IF(Chores!B20="","",Chores!B20) | D20: =IF(Chores!B20="","",N(Chores!D20)) | L20: =IF(C20="","",COUNTA(E20:K20)) | M20: =IF(C20="","",L20*D20)
B21: =IF(Chores!B21="","",IF(Chores!C21="","",Chores!C21)) | C21: =IF(Chores!B21="","",Chores!B21) | D21: =IF(Chores!B21="","",N(Chores!D21)) | L21: =IF(C21="","",COUNTA(E21:K21)) | M21: =IF(C21="","",L21*D21)
B22: =IF(Chores!B22="","",IF(Chores!C22="","",Chores!C22)) | C22: =IF(Chores!B22="","",Chores!B22) | D22: =IF(Chores!B22="","",N(Chores!D22)) | L22: =IF(C22="","",COUNTA(E22:K22)) | M22: =IF(C22="","",L22*D22)
B23: =IF(Chores!B23="","",IF(Chores!C23="","",Chores!C23)) | C23: =IF(Chores!B23="","",Chores!B23) | D23: =IF(Chores!B23="","",N(Chores!D23)) | L23: =IF(C23="","",COUNTA(E23:K23)) | M23: =IF(C23="","",L23*D23)
B24: =IF(Chores!B24="","",IF(Chores!C24="","",Chores!C24)) | C24: =IF(Chores!B24="","",Chores!B24) | D24: =IF(Chores!B24="","",N(Chores!D24)) | L24: =IF(C24="","",COUNTA(E24:K24)) | M24: =IF(C24="","",L24*D24)
B25: =IF(Chores!B25="","",IF(Chores!C25="","",Chores!C25)) | C25: =IF(Chores!B25="","",Chores!B25) | D25: =IF(Chores!B25="","",N(Chores!D25)) | L25: =IF(C25="","",COUNTA(E25:K25)) | M25: =IF(C25="","",L25*D25)
B26: =IF(Chores!B26="","",IF(Chores!C26="","",Chores!C26)) | C26: =IF(Chores!B26="","",Chores!B26) | D26: =IF(Chores!B26="","",N(Chores!D26)) | L26: =IF(C26="","",COUNTA(E26:K26)) | M26: =IF(C26="","",L26*D26)
B27: =IF(Chores!B27="","",IF(Chores!C27="","",Chores!C27)) | C27: =IF(Chores!B27="","",Chores!B27) | D27: =IF(Chores!B27="","",N(Chores!D27)) | L27: =IF(C27="","",COUNTA(E27:K27)) | M27: =IF(C27="","",L27*D27)
B28: =IF(Chores!B28="","",IF(Chores!C28="","",Chores!C28)) | C28: =IF(Chores!B28="","",Chores!B28) | D28: =IF(Chores!B28="","",N(Chores!D28)) | L28: =IF(C28="","",COUNTA(E28:K28)) | M28: =IF(C28="","",L28*D28)
B29: =IF(Chores!B29="","",IF(Chores!C29="","",Chores!C29)) | C29: =IF(Chores!B29="","",Chores!B29) | D29: =IF(Chores!B29="","",N(Chores!D29)) | L29: =IF(C29="","",COUNTA(E29:K29)) | M29: =IF(C29="","",L29*D29)
B30: =IF(Chores!B30="","",IF(Chores!C30="","",Chores!C30)) | C30: =IF(Chores!B30="","",Chores!B30) | D30: =IF(Chores!B30="","",N(Chores!D30)) | L30: =IF(C30="","",COUNTA(E30:K30)) | M30: =IF(C30="","",L30*D30)
B31: =IF(Chores!B31="","",IF(Chores!C31="","",Chores!C31)) | C31: =IF(Chores!B31="","",Chores!B31) | D31: =IF(Chores!B31="","",N(Chores!D31)) | L31: =IF(C31="","",COUNTA(E31:K31)) | M31: =IF(C31="","",L31*D31)
... B45: =IF(Chores!B45="","",IF(Chores!C45="","",Chores!C45)) | C45: =IF(Chores!B45="","",Chores!B45) | D45: =IF(Chores!B45="","",N(Chores!D45)) | L45: =IF(C45="","",COUNTA(E45:K45)) | M45: =IF(C45="","",L45*D45)

Sheet Fridge chart
B2: Mia | D2: ="Chores for the week of "&DAY(Settings!$C$6)&" "&CHOOSE(MONTH(Settings!$C$6),"Jan","Feb","Mar","Apr","May","Jun","Jul","Aug","Sep","Oct","Nov","Dec")&" to "&DAY((Settings!$C$6+6))&" "&CHOOSE(MONTH((Settings!$C$6+6)),"Jan","Feb","Mar","Apr","May","Jun","Jul","Aug","Sep","Oct","Nov","Dec")
B3: An x in the box when it is done. The shaded boxes are the days to do it.
B5: Chore | C5: Points | D5: ="Mon "&DAY(Settings!$C$6+0) | E5: ="Tue "&DAY(Settings!$C$6+1) | F5: ="Wed "&DAY(Settings!$C$6+2) | G5: ="Thu "&DAY(Settings!$C$6+3) | H5: ="Fri "&DAY(Settings!$C$6+4) | I5: ="Sat "&DAY(Settings!$C$6+5) | J5: ="Sun "&DAY(Settings!$C$6+6) | K5: Done
B6: =IF($N6="","",INDEX(Chores!$B$1:$B$45,$N6)) | C6: =IF($N6="","",N(INDEX(Chores!$D$1:$D$45,$N6))) | D6: =IF($N6="","",IF(INDEX('This week'!$E$1:$E$45,$N6)="","",INDEX('This week'!$E$1:$E$45,$N6))) | E6: =IF($N6="","",IF(INDEX('This week'!$F$1:$F$45,$N6)="","",INDEX('This week'!$F$1:$F$45,$N6))) | F6: =IF($N6="","",IF(INDEX('This week'!$G$1:$G$45,$N6)="","",INDEX('This week'!$G$1:$G$45,$N6))) | G6: =IF($N6="","",IF(INDEX('This week'!$H$1:$H$45,$N6)="","",INDEX('This week'!$H$1:$H$45,$N6))) | H6: =IF($N6="","",IF(INDEX('This week'!$I$1:$I$45,$N6)="","",INDEX('This week'!$I$1:$I$45,$N6))) | I6: =IF($N6="","",IF(INDEX('This week'!$J$1:$J$45,$N6)="","",INDEX('This week'!$J$1:$J$45,$N6))) | J6: =IF($N6="","",IF(INDEX('This week'!$K$1:$K$45,$N6)="","",INDEX('This week'!$K$1:$K$45,$N6))) | K6: =IF($N6="","",INDEX('This week'!$L$1:$L$45,$N6)) | N6: =IFERROR(SMALL(Chores!$O$6:$O$45,1),"") | P6: =IF($N6="",0,IF(INDEX(Chores!$E$1:$E$45,$N6)="",0,1)) | Q6: =IF($N6="",0,IF(INDEX(Chores!$F$1:$F$45,$N6)="",0,1)) | R6: =IF($N6="",0,IF(INDEX(Chores!$G$1:$G$45,$N6)="",0,1)) | S6: =IF($N6="",0,IF(INDEX(Chores!$H$1:$H$45,$N6)="",0,1)) | T6: =IF($N6="",0,IF(INDEX(Chores!$I$1:$I$45,$N6)="",0,1)) | U6: =IF($N6="",0,IF(INDEX(Chores!$J$1:$J$45,$N6)="",0,1)) | V6: =IF($N6="",0,IF(INDEX(Chores!$K$1:$K$45,$N6)="",0,1))
B7: =IF($N7="","",INDEX(Chores!$B$1:$B$45,$N7)) | C7: =IF($N7="","",N(INDEX(Chores!$D$1:$D$45,$N7))) | D7: =IF($N7="","",IF(INDEX('This week'!$E$1:$E$45,$N7)="","",INDEX('This week'!$E$1:$E$45,$N7))) | E7: =IF($N7="","",IF(INDEX('This week'!$F$1:$F$45,$N7)="","",INDEX('This week'!$F$1:$F$45,$N7))) | F7: =IF($N7="","",IF(INDEX('This week'!$G$1:$G$45,$N7)="","",INDEX('This week'!$G$1:$G$45,$N7))) | G7: =IF($N7="","",IF(INDEX('This week'!$H$1:$H$45,$N7)="","",INDEX('This week'!$H$1:$H$45,$N7))) | H7: =IF($N7="","",IF(INDEX('This week'!$I$1:$I$45,$N7)="","",INDEX('This week'!$I$1:$I$45,$N7))) | I7: =IF($N7="","",IF(INDEX('This week'!$J$1:$J$45,$N7)="","",INDEX('This week'!$J$1:$J$45,$N7))) | J7: =IF($N7="","",IF(INDEX('This week'!$K$1:$K$45,$N7)="","",INDEX('This week'!$K$1:$K$45,$N7))) | K7: =IF($N7="","",INDEX('This week'!$L$1:$L$45,$N7)) | N7: =IFERROR(SMALL(Chores!$O$6:$O$45,2),"") | P7: =IF($N7="",0,IF(INDEX(Chores!$E$1:$E$45,$N7)="",0,1)) | Q7: =IF($N7="",0,IF(INDEX(Chores!$F$1:$F$45,$N7)="",0,1)) | R7: =IF($N7="",0,IF(INDEX(Chores!$G$1:$G$45,$N7)="",0,1)) | S7: =IF($N7="",0,IF(INDEX(Chores!$H$1:$H$45,$N7)="",0,1)) | T7: =IF($N7="",0,IF(INDEX(Chores!$I$1:$I$45,$N7)="",0,1)) | U7: =IF($N7="",0,IF(INDEX(Chores!$J$1:$J$45,$N7)="",0,1)) | V7: =IF($N7="",0,IF(INDEX(Chores!$K$1:$K$45,$N7)="",0,1))
B8: =IF($N8="","",INDEX(Chores!$B$1:$B$45,$N8)) | C8: =IF($N8="","",N(INDEX(Chores!$D$1:$D$45,$N8))) | D8: =IF($N8="","",IF(INDEX('This week'!$E$1:$E$45,$N8)="","",INDEX('This week'!$E$1:$E$45,$N8))) | E8: =IF($N8="","",IF(INDEX('This week'!$F$1:$F$45,$N8)="","",INDEX('This week'!$F$1:$F$45,$N8))) | F8: =IF($N8="","",IF(INDEX('This week'!$G$1:$G$45,$N8)="","",INDEX('This week'!$G$1:$G$45,$N8))) | G8: =IF($N8="","",IF(INDEX('This week'!$H$1:$H$45,$N8)="","",INDEX('This week'!$H$1:$H$45,$N8))) | H8: =IF($N8="","",IF(INDEX('This week'!$I$1:$I$45,$N8)="","",INDEX('This week'!$I$1:$I$45,$N8))) | I8: =IF($N8="","",IF(INDEX('This week'!$J$1:$J$45,$N8)="","",INDEX('This week'!$J$1:$J$45,$N8))) | J8: =IF($N8="","",IF(INDEX('This week'!$K$1:$K$45,$N8)="","",INDEX('This week'!$K$1:$K$45,$N8))) | K8: =IF($N8="","",INDEX('This week'!$L$1:$L$45,$N8)) | N8: =IFERROR(SMALL(Chores!$O$6:$O$45,3),"") | P8: =IF($N8="",0,IF(INDEX(Chores!$E$1:$E$45,$N8)="",0,1)) | Q8: =IF($N8="",0,IF(INDEX(Chores!$F$1:$F$45,$N8)="",0,1)) | R8: =IF($N8="",0,IF(INDEX(Chores!$G$1:$G$45,$N8)="",0,1)) | S8: =IF($N8="",0,IF(INDEX(Chores!$H$1:$H$45,$N8)="",0,1)) | T8: =IF($N8="",0,IF(INDEX(Chores!$I$1:$I$45,$N8)="",0,1)) | U8: =IF($N8="",0,IF(INDEX(Chores!$J$1:$J$45,$N8)="",0,1)) | V8: =IF($N8="",0,IF(INDEX(Chores!$K$1:$K$45,$N8)="",0,1))
B9: =IF($N9="","",INDEX(Chores!$B$1:$B$45,$N9)) | C9: =IF($N9="","",N(INDEX(Chores!$D$1:$D$45,$N9))) | D9: =IF($N9="","",IF(INDEX('This week'!$E$1:$E$45,$N9)="","",INDEX('This week'!$E$1:$E$45,$N9))) | E9: =IF($N9="","",IF(INDEX('This week'!$F$1:$F$45,$N9)="","",INDEX('This week'!$F$1:$F$45,$N9))) | F9: =IF($N9="","",IF(INDEX('This week'!$G$1:$G$45,$N9)="","",INDEX('This week'!$G$1:$G$45,$N9))) | G9: =IF($N9="","",IF(INDEX('This week'!$H$1:$H$45,$N9)="","",INDEX('This week'!$H$1:$H$45,$N9))) | H9: =IF($N9="","",IF(INDEX('This week'!$I$1:$I$45,$N9)="","",INDEX('This week'!$I$1:$I$45,$N9))) | I9: =IF($N9="","",IF(INDEX('This week'!$J$1:$J$45,$N9)="","",INDEX('This week'!$J$1:$J$45,$N9))) | J9: =IF($N9="","",IF(INDEX('This week'!$K$1:$K$45,$N9)="","",INDEX('This week'!$K$1:$K$45,$N9))) | K9: =IF($N9="","",INDEX('This week'!$L$1:$L$45,$N9)) | N9: =IFERROR(SMALL(Chores!$O$6:$O$45,4),"") | P9: =IF($N9="",0,IF(INDEX(Chores!$E$1:$E$45,$N9)="",0,1)) | Q9: =IF($N9="",0,IF(INDEX(Chores!$F$1:$F$45,$N9)="",0,1)) | R9: =IF($N9="",0,IF(INDEX(Chores!$G$1:$G$45,$N9)="",0,1)) | S9: =IF($N9="",0,IF(INDEX(Chores!$H$1:$H$45,$N9)="",0,1)) | T9: =IF($N9="",0,IF(INDEX(Chores!$I$1:$I$45,$N9)="",0,1)) | U9: =IF($N9="",0,IF(INDEX(Chores!$J$1:$J$45,$N9)="",0,1)) | V9: =IF($N9="",0,IF(INDEX(Chores!$K$1:$K$45,$N9)="",0,1))
B10: =IF($N10="","",INDEX(Chores!$B$1:$B$45,$N10)) | C10: =IF($N10="","",N(INDEX(Chores!$D$1:$D$45,$N10))) | D10: =IF($N10="","",IF(INDEX('This week'!$E$1:$E$45,$N10)="","",INDEX('This week'!$E$1:$E$45,$N10))) | E10: =IF($N10="","",IF(INDEX('This week'!$F$1:$F$45,$N10)="","",INDEX('This week'!$F$1:$F$45,$N10))) | F10: =IF($N10="","",IF(INDEX('This week'!$G$1:$G$45,$N10)="","",INDEX('This week'!$G$1:$G$45,$N10))) | G10: =IF($N10="","",IF(INDEX('This week'!$H$1:$H$45,$N10)="","",INDEX('This week'!$H$1:$H$45,$N10))) | H10: =IF($N10="","",IF(INDEX('This week'!$I$1:$I$45,$N10)="","",INDEX('This week'!$I$1:$I$45,$N10))) | I10: =IF($N10="","",IF(INDEX('This week'!$J$1:$J$45,$N10)="","",INDEX('This week'!$J$1:$J$45,$N10))) | J10: =IF($N10="","",IF(INDEX('This week'!$K$1:$K$45,$N10)="","",INDEX('This week'!$K$1:$K$45,$N10))) | K10: =IF($N10="","",INDEX('This week'!$L$1:$L$45,$N10)) | N10: =IFERROR(SMALL(Chores!$O$6:$O$45,5),"") | P10: =IF($N10="",0,IF(INDEX(Chores!$E$1:$E$45,$N10)="",0,1)) | Q10: =IF($N10="",0,IF(INDEX(Chores!$F$1:$F$45,$N10)="",0,1)) | R10: =IF($N10="",0,IF(INDEX(Chores!$G$1:$G$45,$N10)="",0,1)) | S10: =IF($N10="",0,IF(INDEX(Chores!$H$1:$H$45,$N10)="",0,1)) | T10: =IF($N10="",0,IF(INDEX(Chores!$I$1:$I$45,$N10)="",0,1)) | U10: =IF($N10="",0,IF(INDEX(Chores!$J$1:$J$45,$N10)="",0,1)) | V10: =IF($N10="",0,IF(INDEX(Chores!$K$1:$K$45,$N10)="",0,1))
B11: =IF($N11="","",INDEX(Chores!$B$1:$B$45,$N11)) | C11: =IF($N11="","",N(INDEX(Chores!$D$1:$D$45,$N11))) | D11: =IF($N11="","",IF(INDEX('This week'!$E$1:$E$45,$N11)="","",INDEX('This week'!$E$1:$E$45,$N11))) | E11: =IF($N11="","",IF(INDEX('This week'!$F$1:$F$45,$N11)="","",INDEX('This week'!$F$1:$F$45,$N11))) | F11: =IF($N11="","",IF(INDEX('This week'!$G$1:$G$45,$N11)="","",INDEX('This week'!$G$1:$G$45,$N11))) | G11: =IF($N11="","",IF(INDEX('This week'!$H$1:$H$45,$N11)="","",INDEX('This week'!$H$1:$H$45,$N11))) | H11: =IF($N11="","",IF(INDEX('This week'!$I$1:$I$45,$N11)="","",INDEX('This week'!$I$1:$I$45,$N11))) | I11: =IF($N11="","",IF(INDEX('This week'!$J$1:$J$45,$N11)="","",INDEX('This week'!$J$1:$J$45,$N11))) | J11: =IF($N11="","",IF(INDEX('This week'!$K$1:$K$45,$N11)="","",INDEX('This week'!$K$1:$K$45,$N11))) | K11: =IF($N11="","",INDEX('This week'!$L$1:$L$45,$N11)) | N11: =IFERROR(SMALL(Chores!$O$6:$O$45,6),"") | P11: =IF($N11="",0,IF(INDEX(Chores!$E$1:$E$45,$N11)="",0,1)) | Q11: =IF($N11="",0,IF(INDEX(Chores!$F$1:$F$45,$N11)="",0,1)) | R11: =IF($N11="",0,IF(INDEX(Chores!$G$1:$G$45,$N11)="",0,1)) | S11: =IF($N11="",0,IF(INDEX(Chores!$H$1:$H$45,$N11)="",0,1)) | T11: =IF($N11="",0,IF(INDEX(Chores!$I$1:$I$45,$N11)="",0,1)) | U11: =IF($N11="",0,IF(INDEX(Chores!$J$1:$J$45,$N11)="",0,1)) | V11: =IF($N11="",0,IF(INDEX(Chores!$K$1:$K$45,$N11)="",0,1))
B12: =IF($N12="","",INDEX(Chores!$B$1:$B$45,$N12)) | C12: =IF($N12="","",N(INDEX(Chores!$D$1:$D$45,$N12))) | D12: =IF($N12="","",IF(INDEX('This week'!$E$1:$E$45,$N12)="","",INDEX('This week'!$E$1:$E$45,$N12))) | E12: =IF($N12="","",IF(INDEX('This week'!$F$1:$F$45,$N12)="","",INDEX('This week'!$F$1:$F$45,$N12))) | F12: =IF($N12="","",IF(INDEX('This week'!$G$1:$G$45,$N12)="","",INDEX('This week'!$G$1:$G$45,$N12))) | G12: =IF($N12="","",IF(INDEX('This week'!$H$1:$H$45,$N12)="","",INDEX('This week'!$H$1:$H$45,$N12))) | H12: =IF($N12="","",IF(INDEX('This week'!$I$1:$I$45,$N12)="","",INDEX('This week'!$I$1:$I$45,$N12))) | I12: =IF($N12="","",IF(INDEX('This week'!$J$1:$J$45,$N12)="","",INDEX('This week'!$J$1:$J$45,$N12))) | J12: =IF($N12="","",IF(INDEX('This week'!$K$1:$K$45,$N12)="","",INDEX('This week'!$K$1:$K$45,$N12))) | K12: =IF($N12="","",INDEX('This week'!$L$1:$L$45,$N12)) | N12: =IFERROR(SMALL(Chores!$O$6:$O$45,7),"") | P12: =IF($N12="",0,IF(INDEX(Chores!$E$1:$E$45,$N12)="",0,1)) | Q12: =IF($N12="",0,IF(INDEX(Chores!$F$1:$F$45,$N12)="",0,1)) | R12: =IF($N12="",0,IF(INDEX(Chores!$G$1:$G$45,$N12)="",0,1)) | S12: =IF($N12="",0,IF(INDEX(Chores!$H$1:$H$45,$N12)="",0,1)) | T12: =IF($N12="",0,IF(INDEX(Chores!$I$1:$I$45,$N12)="",0,1)) | U12: =IF($N12="",0,IF(INDEX(Chores!$J$1:$J$45,$N12)="",0,1)) | V12: =IF($N12="",0,IF(INDEX(Chores!$K$1:$K$45,$N12)="",0,1))
B13: =IF($N13="","",INDEX(Chores!$B$1:$B$45,$N13)) | C13: =IF($N13="","",N(INDEX(Chores!$D$1:$D$45,$N13))) | D13: =IF($N13="","",IF(INDEX('This week'!$E$1:$E$45,$N13)="","",INDEX('This week'!$E$1:$E$45,$N13))) | E13: =IF($N13="","",IF(INDEX('This week'!$F$1:$F$45,$N13)="","",INDEX('This week'!$F$1:$F$45,$N13))) | F13: =IF($N13="","",IF(INDEX('This week'!$G$1:$G$45,$N13)="","",INDEX('This week'!$G$1:$G$45,$N13))) | G13: =IF($N13="","",IF(INDEX('This week'!$H$1:$H$45,$N13)="","",INDEX('This week'!$H$1:$H$45,$N13))) | H13: =IF($N13="","",IF(INDEX('This week'!$I$1:$I$45,$N13)="","",INDEX('This week'!$I$1:$I$45,$N13))) | I13: =IF($N13="","",IF(INDEX('This week'!$J$1:$J$45,$N13)="","",INDEX('This week'!$J$1:$J$45,$N13))) | J13: =IF($N13="","",IF(INDEX('This week'!$K$1:$K$45,$N13)="","",INDEX('This week'!$K$1:$K$45,$N13))) | K13: =IF($N13="","",INDEX('This week'!$L$1:$L$45,$N13)) | N13: =IFERROR(SMALL(Chores!$O$6:$O$45,8),"") | P13: =IF($N13="",0,IF(INDEX(Chores!$E$1:$E$45,$N13)="",0,1)) | Q13: =IF($N13="",0,IF(INDEX(Chores!$F$1:$F$45,$N13)="",0,1)) | R13: =IF($N13="",0,IF(INDEX(Chores!$G$1:$G$45,$N13)="",0,1)) | S13: =IF($N13="",0,IF(INDEX(Chores!$H$1:$H$45,$N13)="",0,1)) | T13: =IF($N13="",0,IF(INDEX(Chores!$I$1:$I$45,$N13)="",0,1)) | U13: =IF($N13="",0,IF(INDEX(Chores!$J$1:$J$45,$N13)="",0,1)) | V13: =IF($N13="",0,IF(INDEX(Chores!$K$1:$K$45,$N13)="",0,1))
B14: =IF($N14="","",INDEX(Chores!$B$1:$B$45,$N14)) | C14: =IF($N14="","",N(INDEX(Chores!$D$1:$D$45,$N14))) | D14: =IF($N14="","",IF(INDEX('This week'!$E$1:$E$45,$N14)="","",INDEX('This week'!$E$1:$E$45,$N14))) | E14: =IF($N14="","",IF(INDEX('This week'!$F$1:$F$45,$N14)="","",INDEX('This week'!$F$1:$F$45,$N14))) | F14: =IF($N14="","",IF(INDEX('This week'!$G$1:$G$45,$N14)="","",INDEX('This week'!$G$1:$G$45,$N14))) | G14: =IF($N14="","",IF(INDEX('This week'!$H$1:$H$45,$N14)="","",INDEX('This week'!$H$1:$H$45,$N14))) | H14: =IF($N14="","",IF(INDEX('This week'!$I$1:$I$45,$N14)="","",INDEX('This week'!$I$1:$I$45,$N14))) | I14: =IF($N14="","",IF(INDEX('This week'!$J$1:$J$45,$N14)="","",INDEX('This week'!$J$1:$J$45,$N14))) | J14: =IF($N14="","",IF(INDEX('This week'!$K$1:$K$45,$N14)="","",INDEX('This week'!$K$1:$K$45,$N14))) | K14: =IF($N14="","",INDEX('This week'!$L$1:$L$45,$N14)) | N14: =IFERROR(SMALL(Chores!$O$6:$O$45,9),"") | P14: =IF($N14="",0,IF(INDEX(Chores!$E$1:$E$45,$N14)="",0,1)) | Q14: =IF($N14="",0,IF(INDEX(Chores!$F$1:$F$45,$N14)="",0,1)) | R14: =IF($N14="",0,IF(INDEX(Chores!$G$1:$G$45,$N14)="",0,1)) | S14: =IF($N14="",0,IF(INDEX(Chores!$H$1:$H$45,$N14)="",0,1)) | T14: =IF($N14="",0,IF(INDEX(Chores!$I$1:$I$45,$N14)="",0,1)) | U14: =IF($N14="",0,IF(INDEX(Chores!$J$1:$J$45,$N14)="",0,1)) | V14: =IF($N14="",0,IF(INDEX(Chores!$K$1:$K$45,$N14)="",0,1))
B15: =IF($N15="","",INDEX(Chores!$B$1:$B$45,$N15)) | C15: =IF($N15="","",N(INDEX(Chores!$D$1:$D$45,$N15))) | D15: =IF($N15="","",IF(INDEX('This week'!$E$1:$E$45,$N15)="","",INDEX('This week'!$E$1:$E$45,$N15))) | E15: =IF($N15="","",IF(INDEX('This week'!$F$1:$F$45,$N15)="","",INDEX('This week'!$F$1:$F$45,$N15))) | F15: =IF($N15="","",IF(INDEX('This week'!$G$1:$G$45,$N15)="","",INDEX('This week'!$G$1:$G$45,$N15))) | G15: =IF($N15="","",IF(INDEX('This week'!$H$1:$H$45,$N15)="","",INDEX('This week'!$H$1:$H$45,$N15))) | H15: =IF($N15="","",IF(INDEX('This week'!$I$1:$I$45,$N15)="","",INDEX('This week'!$I$1:$I$45,$N15))) | I15: =IF($N15="","",IF(INDEX('This week'!$J$1:$J$45,$N15)="","",INDEX('This week'!$J$1:$J$45,$N15))) | J15: =IF($N15="","",IF(INDEX('This week'!$K$1:$K$45,$N15)="","",INDEX('This week'!$K$1:$K$45,$N15))) | K15: =IF($N15="","",INDEX('This week'!$L$1:$L$45,$N15)) | N15: =IFERROR(SMALL(Chores!$O$6:$O$45,10),"") | P15: =IF($N15="",0,IF(INDEX(Chores!$E$1:$E$45,$N15)="",0,1)) | Q15: =IF($N15="",0,IF(INDEX(Chores!$F$1:$F$45,$N15)="",0,1)) | R15: =IF($N15="",0,IF(INDEX(Chores!$G$1:$G$45,$N15)="",0,1)) | S15: =IF($N15="",0,IF(INDEX(Chores!$H$1:$H$45,$N15)="",0,1)) | T15: =IF($N15="",0,IF(INDEX(Chores!$I$1:$I$45,$N15)="",0,1)) | U15: =IF($N15="",0,IF(INDEX(Chores!$J$1:$J$45,$N15)="",0,1)) | V15: =IF($N15="",0,IF(INDEX(Chores!$K$1:$K$45,$N15)="",0,1))
B16: =IF($N16="","",INDEX(Chores!$B$1:$B$45,$N16)) | C16: =IF($N16="","",N(INDEX(Chores!$D$1:$D$45,$N16))) | D16: =IF($N16="","",IF(INDEX('This week'!$E$1:$E$45,$N16)="","",INDEX('This week'!$E$1:$E$45,$N16))) | E16: =IF($N16="","",IF(INDEX('This week'!$F$1:$F$45,$N16)="","",INDEX('This week'!$F$1:$F$45,$N16))) | F16: =IF($N16="","",IF(INDEX('This week'!$G$1:$G$45,$N16)="","",INDEX('This week'!$G$1:$G$45,$N16))) | G16: =IF($N16="","",IF(INDEX('This week'!$H$1:$H$45,$N16)="","",INDEX('This week'!$H$1:$H$45,$N16))) | H16: =IF($N16="","",IF(INDEX('This week'!$I$1:$I$45,$N16)="","",INDEX('This week'!$I$1:$I$45,$N16))) | I16: =IF($N16="","",IF(INDEX('This week'!$J$1:$J$45,$N16)="","",INDEX('This week'!$J$1:$J$45,$N16))) | J16: =IF($N16="","",IF(INDEX('This week'!$K$1:$K$45,$N16)="","",INDEX('This week'!$K$1:$K$45,$N16))) | K16: =IF($N16="","",INDEX('This week'!$L$1:$L$45,$N16)) | N16: =IFERROR(SMALL(Chores!$O$6:$O$45,11),"") | P16: =IF($N16="",0,IF(INDEX(Chores!$E$1:$E$45,$N16)="",0,1)) | Q16: =IF($N16="",0,IF(INDEX(Chores!$F$1:$F$45,$N16)="",0,1)) | R16: =IF($N16="",0,IF(INDEX(Chores!$G$1:$G$45,$N16)="",0,1)) | S16: =IF($N16="",0,IF(INDEX(Chores!$H$1:$H$45,$N16)="",0,1)) | T16: =IF($N16="",0,IF(INDEX(Chores!$I$1:$I$45,$N16)="",0,1)) | U16: =IF($N16="",0,IF(INDEX(Chores!$J$1:$J$45,$N16)="",0,1)) | V16: =IF($N16="",0,IF(INDEX(Chores!$K$1:$K$45,$N16)="",0,1))
B17: =IF($N17="","",INDEX(Chores!$B$1:$B$45,$N17)) | C17: =IF($N17="","",N(INDEX(Chores!$D$1:$D$45,$N17))) | D17: =IF($N17="","",IF(INDEX('This week'!$E$1:$E$45,$N17)="","",INDEX('This week'!$E$1:$E$45,$N17))) | E17: =IF($N17="","",IF(INDEX('This week'!$F$1:$F$45,$N17)="","",INDEX('This week'!$F$1:$F$45,$N17))) | F17: =IF($N17="","",IF(INDEX('This week'!$G$1:$G$45,$N17)="","",INDEX('This week'!$G$1:$G$45,$N17))) | G17: =IF($N17="","",IF(INDEX('This week'!$H$1:$H$45,$N17)="","",INDEX('This week'!$H$1:$H$45,$N17))) | H17: =IF($N17="","",IF(INDEX('This week'!$I$1:$I$45,$N17)="","",INDEX('This week'!$I$1:$I$45,$N17))) | I17: =IF($N17="","",IF(INDEX('This week'!$J$1:$J$45,$N17)="","",INDEX('This week'!$J$1:$J$45,$N17))) | J17: =IF($N17="","",IF(INDEX('This week'!$K$1:$K$45,$N17)="","",INDEX('This week'!$K$1:$K$45,$N17))) | K17: =IF($N17="","",INDEX('This week'!$L$1:$L$45,$N17)) | N17: =IFERROR(SMALL(Chores!$O$6:$O$45,12),"") | P17: =IF($N17="",0,IF(INDEX(Chores!$E$1:$E$45,$N17)="",0,1)) | Q17: =IF($N17="",0,IF(INDEX(Chores!$F$1:$F$45,$N17)="",0,1)) | R17: =IF($N17="",0,IF(INDEX(Chores!$G$1:$G$45,$N17)="",0,1)) | S17: =IF($N17="",0,IF(INDEX(Chores!$H$1:$H$45,$N17)="",0,1)) | T17: =IF($N17="",0,IF(INDEX(Chores!$I$1:$I$45,$N17)="",0,1)) | U17: =IF($N17="",0,IF(INDEX(Chores!$J$1:$J$45,$N17)="",0,1)) | V17: =IF($N17="",0,IF(INDEX(Chores!$K$1:$K$45,$N17)="",0,1))
B18: =IF(COUNT(Chores!$O$6:$O$45)>12,"And "&(COUNT(Chores!$O$6:$O$45)-12)&" more on This week","")
B19: Points this week | C19: =IF($B$2="","",SUMIFS('This week'!$M$6:$M$45,'This week'!$B$6:$B$45,$B$2))
B20: ="Pocket money this week"&IF(Settings!$C$4="",""," ("&Settings!$C$4&")") | C20: =IF($B$2="","",IFERROR(N(INDEX(Kids!$D$6:$D$11,MATCH($B$2,Kids!$B$6:$B$11,0))),0)+IFERROR(N(INDEX(Kids!$E$6:$E$11,MATCH($B$2,Kids!$B$6:$B$11,0))),0)*N(C19))

Sheet Chores
B2: Chores
B3: Each chore once per child, with its points and an x on the days it is expected.
B5: Chore | C5: Child | D5: Points | E5: Mon | F5: Tue | G5: Wed | H5: Thu | I5: Fri | J5: Sat | K5: Sun | L5: Notes | M5: A week
B6: Make bed | C6: Mia | D6: 1 | E6: x | F6: x | G6: x | H6: x | I6: x | J6: x | K6: x | M6: =IF(B6="","",N(D6)*COUNTA(E6:K6)) | N6: =IF(B6="","",COUNTA(E6:K6)) | O6: =IF(OR(B6="",C6=""),"",IF(C6='Fridge chart'!$B$2,ROW(),""))
B7: Feed the cat | C7: Mia | D7: 2 | E7: x | F7: x | G7: x | H7: x | I7: x | L7: Before school | M7: =IF(B7="","",N(D7)*COUNTA(E7:K7)) | N7: =IF(B7="","",COUNTA(E7:K7)) | O7: =IF(OR(B7="",C7=""),"",IF(C7='Fridge chart'!$B$2,ROW(),""))
B8: Set the table | C8: Mia | D8: 1 | E8: x | F8: x | G8: x | H8: x | I8: x | J8: x | K8: x | M8: =IF(B8="","",N(D8)*COUNTA(E8:K8)) | N8: =IF(B8="","",COUNTA(E8:K8)) | O8: =IF(OR(B8="",C8=""),"",IF(C8='Fridge chart'!$B$2,ROW(),""))
B9: Tidy room | C9: Mia | D9: 3 | J9: x | M9: =IF(B9="","",N(D9)*COUNTA(E9:K9)) | N9: =IF(B9="","",COUNTA(E9:K9)) | O9: =IF(OR(B9="",C9=""),"",IF(C9='Fridge chart'!$B$2,ROW(),""))
B10: Water the plants | C10: Mia | D10: 2 | G10: x | K10: x | M10: =IF(B10="","",N(D10)*COUNTA(E10:K10)) | N10: =IF(B10="","",COUNTA(E10:K10)) | O10: =IF(OR(B10="",C10=""),"",IF(C10='Fridge chart'!$B$2,ROW(),""))
B11: Make bed | C11: Leo | D11: 1 | E11: x | F11: x | G11: x | H11: x | I11: x | J11: x | K11: x | M11: =IF(B11="","",N(D11)*COUNTA(E11:K11)) | N11: =IF(B11="","",COUNTA(E11:K11)) | O11: =IF(OR(B11="",C11=""),"",IF(C11='Fridge chart'!$B$2,ROW(),""))
B12: Put toys away | C12: Leo | D12: 1 | E12: x | F12: x | G12: x | H12: x | I12: x | J12: x | K12: x | L12: Before bath | M12: =IF(B12="","",N(D12)*COUNTA(E12:K12)) | N12: =IF(B12="","",COUNTA(E12:K12)) | O12: =IF(OR(B12="",C12=""),"",IF(C12='Fridge chart'!$B$2,ROW(),""))
B13: Help with laundry | C13: Leo | D13: 2 | J13: x | M13: =IF(B13="","",N(D13)*COUNTA(E13:K13)) | N13: =IF(B13="","",COUNTA(E13:K13)) | O13: =IF(OR(B13="",C13=""),"",IF(C13='Fridge chart'!$B$2,ROW(),""))
B14: Feed the fish | C14: Leo | D14: 1 | E14: x | G14: x | I14: x | L14: A pinch only | M14: =IF(B14="","",N(D14)*COUNTA(E14:K14)) | N14: =IF(B14="","",COUNTA(E14:K14)) | O14: =IF(OR(B14="",C14=""),"",IF(C14='Fridge chart'!$B$2,ROW(),""))
B15: Make bed | C15: Ava | D15: 1 | E15: x | F15: x | G15: x | H15: x | I15: x | J15: x | K15: x | M15: =IF(B15="","",N(D15)*COUNTA(E15:K15)) | N15: =IF(B15="","",COUNTA(E15:K15)) | O15: =IF(OR(B15="",C15=""),"",IF(C15='Fridge chart'!$B$2,ROW(),""))
B16: Empty the dishwasher | C16: Ava | D16: 2 | E16: x | F16: x | G16: x | H16: x | I16: x | M16: =IF(B16="","",N(D16)*COUNTA(E16:K16)) | N16: =IF(B16="","",COUNTA(E16:K16)) | O16: =IF(OR(B16="",C16=""),"",IF(C16='Fridge chart'!$B$2,ROW(),""))
B17: Walk the dog | C17: Ava | D17: 3 | F17: x | H17: x | J17: x | M17: =IF(B17="","",N(D17)*COUNTA(E17:K17)) | N17: =IF(B17="","",COUNTA(E17:K17)) | O17: =IF(OR(B17="",C17=""),"",IF(C17='Fridge chart'!$B$2,ROW(),""))
B18: Homework before screens | C18: Ava | D18: 2 | E18: x | F18: x | G18: x | H18: x | M18: =IF(B18="","",N(D18)*COUNTA(E18:K18)) | N18: =IF(B18="","",COUNTA(E18:K18)) | O18: =IF(OR(B18="",C18=""),"",IF(C18='Fridge chart'!$B$2,ROW(),""))
B19: Vacuum the stairs | C19: Ava | D19: 4 | K19: x | M19: =IF(B19="","",N(D19)*COUNTA(E19:K19)) | N19: =IF(B19="","",COUNTA(E19:K19)) | O19: =IF(OR(B19="",C19=""),"",IF(C19='Fridge chart'!$B$2,ROW(),""))
M20: =IF(B20="","",N(D20)*COUNTA(E20:K20)) | N20: =IF(B20="","",COUNTA(E20:K20)) | O20: =IF(OR(B20="",C20=""),"",IF(C20='Fridge chart'!$B$2,ROW(),""))
M21: =IF(B21="","",N(D21)*COUNTA(E21:K21)) | N21: =IF(B21="","",COUNTA(E21:K21)) | O21: =IF(OR(B21="",C21=""),"",IF(C21='Fridge chart'!$B$2,ROW(),""))
M22: =IF(B22="","",N(D22)*COUNTA(E22:K22)) | N22: =IF(B22="","",COUNTA(E22:K22)) | O22: =IF(OR(B22="",C22=""),"",IF(C22='Fridge chart'!$B$2,ROW(),""))
M23: =IF(B23="","",N(D23)*COUNTA(E23:K23)) | N23: =IF(B23="","",COUNTA(E23:K23)) | O23: =IF(OR(B23="",C23=""),"",IF(C23='Fridge chart'!$B$2,ROW(),""))
M24: =IF(B24="","",N(D24)*COUNTA(E24:K24)) | N24: =IF(B24="","",COUNTA(E24:K24)) | O24: =IF(OR(B24="",C24=""),"",IF(C24='Fridge chart'!$B$2,ROW(),""))
M25: =IF(B25="","",N(D25)*COUNTA(E25:K25)) | N25: =IF(B25="","",COUNTA(E25:K25)) | O25: =IF(OR(B25="",C25=""),"",IF(C25='Fridge chart'!$B$2,ROW(),""))
M26: =IF(B26="","",N(D26)*COUNTA(E26:K26)) | N26: =IF(B26="","",COUNTA(E26:K26)) | O26: =IF(OR(B26="",C26=""),"",IF(C26='Fridge chart'!$B$2,ROW(),""))
M27: =IF(B27="","",N(D27)*COUNTA(E27:K27)) | N27: =IF(B27="","",COUNTA(E27:K27)) | O27: =IF(OR(B27="",C27=""),"",IF(C27='Fridge chart'!$B$2,ROW(),""))
M28: =IF(B28="","",N(D28)*COUNTA(E28:K28)) | N28: =IF(B28="","",COUNTA(E28:K28)) | O28: =IF(OR(B28="",C28=""),"",IF(C28='Fridge chart'!$B$2,ROW(),""))
M29: =IF(B29="","",N(D29)*COUNTA(E29:K29)) | N29: =IF(B29="","",COUNTA(E29:K29)) | O29: =IF(OR(B29="",C29=""),"",IF(C29='Fridge chart'!$B$2,ROW(),""))
M30: =IF(B30="","",N(D30)*COUNTA(E30:K30)) | N30: =IF(B30="","",COUNTA(E30:K30)) | O30: =IF(OR(B30="",C30=""),"",IF(C30='Fridge chart'!$B$2,ROW(),""))
M31: =IF(B31="","",N(D31)*COUNTA(E31:K31)) | N31: =IF(B31="","",COUNTA(E31:K31)) | O31: =IF(OR(B31="",C31=""),"",IF(C31='Fridge chart'!$B$2,ROW(),""))
... M45: =IF(B45="","",N(D45)*COUNTA(E45:K45)) | N45: =IF(B45="","",COUNTA(E45:K45)) | O45: =IF(OR(B45="",C45=""),"",IF(C45='Fridge chart'!$B$2,ROW(),""))

Sheet Money
B2: Money
B3: Money in and out for each child. Split shares it by the child's jars; or name one jar.
B5: Date | C5: Child | D5: What | E5: In | F5: Out | G5: Jar
B6: 46257 | C6: Mia | D6: Pocket money | E6: 7.5 | G6: Split | H6: =IF(C6="",0,IF(OR(G6="",G6="Split"),(N(E6)-N(F6))*IFERROR(N(INDEX(Kids!$F$6:$F$11,MATCH(C6,Kids!$B$6:$B$11,0))),0),IF(G6="Save",(N(E6)-N(F6)),0))) | I6: =IF(C6="",0,(N(E6)-N(F6))-H6-J6) | J6: =IF(C6="",0,IF(OR(G6="",G6="Split"),(N(E6)-N(F6))*IFERROR(N(INDEX(Kids!$G$6:$G$11,MATCH(C6,Kids!$B$6:$B$11,0))),0),IF(G6="Give",(N(E6)-N(F6)),0))) | K6: =IF(C6="",0,IF(OR(G6="",G6="Split"),N(E6)*IFERROR(N(INDEX(Kids!$F$6:$F$11,MATCH(C6,Kids!$B$6:$B$11,0))),0),IF(G6="Save",N(E6),0)))
B7: 46257 | C7: Leo | D7: Pocket money | E7: 4.7 | G7: Split | H7: =IF(C7="",0,IF(OR(G7="",G7="Split"),(N(E7)-N(F7))*IFERROR(N(INDEX(Kids!$F$6:$F$11,MATCH(C7,Kids!$B$6:$B$11,0))),0),IF(G7="Save",(N(E7)-N(F7)),0))) | I7: =IF(C7="",0,(N(E7)-N(F7))-H7-J7) | J7: =IF(C7="",0,IF(OR(G7="",G7="Split"),(N(E7)-N(F7))*IFERROR(N(INDEX(Kids!$G$6:$G$11,MATCH(C7,Kids!$B$6:$B$11,0))),0),IF(G7="Give",(N(E7)-N(F7)),0))) | K7: =IF(C7="",0,IF(OR(G7="",G7="Split"),N(E7)*IFERROR(N(INDEX(Kids!$F$6:$F$11,MATCH(C7,Kids!$B$6:$B$11,0))),0),IF(G7="Save",N(E7),0)))
B8: 46257 | C8: Ava | D8: Pocket money | E8: 10.2 | G8: Split | H8: =IF(C8="",0,IF(OR(G8="",G8="Split"),(N(E8)-N(F8))*IFERROR(N(INDEX(Kids!$F$6:$F$11,MATCH(C8,Kids!$B$6:$B$11,0))),0),IF(G8="Save",(N(E8)-N(F8)),0))) | I8: =IF(C8="",0,(N(E8)-N(F8))-H8-J8) | J8: =IF(C8="",0,IF(OR(G8="",G8="Split"),(N(E8)-N(F8))*IFERROR(N(INDEX(Kids!$G$6:$G$11,MATCH(C8,Kids!$B$6:$B$11,0))),0),IF(G8="Give",(N(E8)-N(F8)),0))) | K8: =IF(C8="",0,IF(OR(G8="",G8="Split"),N(E8)*IFERROR(N(INDEX(Kids!$F$6:$F$11,MATCH(C8,Kids!$B$6:$B$11,0))),0),IF(G8="Save",N(E8),0)))
B9: 46263 | C9: Leo | D9: Birthday money from Grandma | E9: 20 | G9: Save | H9: =IF(C9="",0,IF(OR(G9="",G9="Split"),(N(E9)-N(F9))*IFERROR(N(INDEX(Kids!$F$6:$F$11,MATCH(C9,Kids!$B$6:$B$11,0))),0),IF(G9="Save",(N(E9)-N(F9)),0))) | I9: =IF(C9="",0,(N(E9)-N(F9))-H9-J9) | J9: =IF(C9="",0,IF(OR(G9="",G9="Split"),(N(E9)-N(F9))*IFERROR(N(INDEX(Kids!$G$6:$G$11,MATCH(C9,Kids!$B$6:$B$11,0))),0),IF(G9="Give",(N(E9)-N(F9)),0))) | K9: =IF(C9="",0,IF(OR(G9="",G9="Split"),N(E9)*IFERROR(N(INDEX(Kids!$F$6:$F$11,MATCH(C9,Kids!$B$6:$B$11,0))),0),IF(G9="Save",N(E9),0)))
B10: 46264 | C10: Mia | D10: Pocket money | E10: 7 | G10: Split | H10: =IF(C10="",0,IF(OR(G10="",G10="Split"),(N(E10)-N(F10))*IFERROR(N(INDEX(Kids!$F$6:$F$11,MATCH(C10,Kids!$B$6:$B$11,0))),0),IF(G10="Save",(N(E10)-N(F10)),0))) | I10: =IF(C10="",0,(N(E10)-N(F10))-H10-J10) | J10: =IF(C10="",0,IF(OR(G10="",G10="Split"),(N(E10)-N(F10))*IFERROR(N(INDEX(Kids!$G$6:$G$11,MATCH(C10,Kids!$B$6:$B$11,0))),0),IF(G10="Give",(N(E10)-N(F10)),0))) | K10: =IF(C10="",0,IF(OR(G10="",G10="Split"),N(E10)*IFERROR(N(INDEX(Kids!$F$6:$F$11,MATCH(C10,Kids!$B$6:$B$11,0))),0),IF(G10="Save",N(E10),0)))
B11: 46264 | C11: Leo | D11: Pocket money | E11: 4.5 | G11: Split | H11: =IF(C11="",0,IF(OR(G11="",G11="Split"),(N(E11)-N(F11))*IFERROR(N(INDEX(Kids!$F$6:$F$11,MATCH(C11,Kids!$B$6:$B$11,0))),0),IF(G11="Save",(N(E11)-N(F11)),0))) | I11: =IF(C11="",0,(N(E11)-N(F11))-H11-J11) | J11: =IF(C11="",0,IF(OR(G11="",G11="Split"),(N(E11)-N(F11))*IFERROR(N(INDEX(Kids!$G$6:$G$11,MATCH(C11,Kids!$B$6:$B$11,0))),0),IF(G11="Give",(N(E11)-N(F11)),0))) | K11: =IF(C11="",0,IF(OR(G11="",G11="Split"),N(E11)*IFERROR(N(INDEX(Kids!$F$6:$F$11,MATCH(C11,Kids!$B$6:$B$11,0))),0),IF(G11="Save",N(E11),0)))
B12: 46264 | C12: Ava | D12: Pocket money | E12: 10.5 | G12: Split | H12: =IF(C12="",0,IF(OR(G12="",G12="Split"),(N(E12)-N(F12))*IFERROR(N(INDEX(Kids!$F$6:$F$11,MATCH(C12,Kids!$B$6:$B$11,0))),0),IF(G12="Save",(N(E12)-N(F12)),0))) | I12: =IF(C12="",0,(N(E12)-N(F12))-H12-J12) | J12: =IF(C12="",0,IF(OR(G12="",G12="Split"),(N(E12)-N(F12))*IFERROR(N(INDEX(Kids!$G$6:$G$11,MATCH(C12,Kids!$B$6:$B$11,0))),0),IF(G12="Give",(N(E12)-N(F12)),0))) | K12: =IF(C12="",0,IF(OR(G12="",G12="Split"),N(E12)*IFERROR(N(INDEX(Kids!$F$6:$F$11,MATCH(C12,Kids!$B$6:$B$11,0))),0),IF(G12="Save",N(E12),0)))
B13: 46267 | C13: Mia | D13: Comic | F13: 4.5 | G13: Spend | H13: =IF(C13="",0,IF(OR(G13="",G13="Split"),(N(E13)-N(F13))*IFERROR(N(INDEX(Kids!$F$6:$F$11,MATCH(C13,Kids!$B$6:$B$11,0))),0),IF(G13="Save",(N(E13)-N(F13)),0))) | I13: =IF(C13="",0,(N(E13)-N(F13))-H13-J13) | J13: =IF(C13="",0,IF(OR(G13="",G13="Split"),(N(E13)-N(F13))*IFERROR(N(INDEX(Kids!$G$6:$G$11,MATCH(C13,Kids!$B$6:$B$11,0))),0),IF(G13="Give",(N(E13)-N(F13)),0))) | K13: =IF(C13="",0,IF(OR(G13="",G13="Split"),N(E13)*IFERROR(N(INDEX(Kids!$F$6:$F$11,MATCH(C13,Kids!$B$6:$B$11,0))),0),IF(G13="Save",N(E13),0)))
B14: 46271 | C14: Mia | D14: Pocket money | E14: 7.25 | G14: Split | H14: =IF(C14="",0,IF(OR(G14="",G14="Split"),(N(E14)-N(F14))*IFERROR(N(INDEX(Kids!$F$6:$F$11,MATCH(C14,Kids!$B$6:$B$11,0))),0),IF(G14="Save",(N(E14)-N(F14)),0))) | I14: =IF(C14="",0,(N(E14)-N(F14))-H14-J14) | J14: =IF(C14="",0,IF(OR(G14="",G14="Split"),(N(E14)-N(F14))*IFERROR(N(INDEX(Kids!$G$6:$G$11,MATCH(C14,Kids!$B$6:$B$11,0))),0),IF(G14="Give",(N(E14)-N(F14)),0))) | K14: =IF(C14="",0,IF(OR(G14="",G14="Split"),N(E14)*IFERROR(N(INDEX(Kids!$F$6:$F$11,MATCH(C14,Kids!$B$6:$B$11,0))),0),IF(G14="Save",N(E14),0)))
B15: 46271 | C15: Leo | D15: Pocket money | E15: 4.7 | G15: Split | H15: =IF(C15="",0,IF(OR(G15="",G15="Split"),(N(E15)-N(F15))*IFERROR(N(INDEX(Kids!$F$6:$F$11,MATCH(C15,Kids!$B$6:$B$11,0))),0),IF(G15="Save",(N(E15)-N(F15)),0))) | I15: =IF(C15="",0,(N(E15)-N(F15))-H15-J15) | J15: =IF(C15="",0,IF(OR(G15="",G15="Split"),(N(E15)-N(F15))*IFERROR(N(INDEX(Kids!$G$6:$G$11,MATCH(C15,Kids!$B$6:$B$11,0))),0),IF(G15="Give",(N(E15)-N(F15)),0))) | K15: =IF(C15="",0,IF(OR(G15="",G15="Split"),N(E15)*IFERROR(N(INDEX(Kids!$F$6:$F$11,MATCH(C15,Kids!$B$6:$B$11,0))),0),IF(G15="Save",N(E15),0)))
B16: 46271 | C16: Ava | D16: Pocket money | E16: 10.8 | G16: Split | H16: =IF(C16="",0,IF(OR(G16="",G16="Split"),(N(E16)-N(F16))*IFERROR(N(INDEX(Kids!$F$6:$F$11,MATCH(C16,Kids!$B$6:$B$11,0))),0),IF(G16="Save",(N(E16)-N(F16)),0))) | I16: =IF(C16="",0,(N(E16)-N(F16))-H16-J16) | J16: =IF(C16="",0,IF(OR(G16="",G16="Split"),(N(E16)-N(F16))*IFERROR(N(INDEX(Kids!$G$6:$G$11,MATCH(C16,Kids!$B$6:$B$11,0))),0),IF(G16="Give",(N(E16)-N(F16)),0))) | K16: =IF(C16="",0,IF(OR(G16="",G16="Split"),N(E16)*IFERROR(N(INDEX(Kids!$F$6:$F$11,MATCH(C16,Kids!$B$6:$B$11,0))),0),IF(G16="Save",N(E16),0)))
B17: 46274 | C17: Ava | D17: Cinema with friends | F17: 8 | G17: Spend | H17: =IF(C17="",0,IF(OR(G17="",G17="Split"),(N(E17)-N(F17))*IFERROR(N(INDEX(Kids!$F$6:$F$11,MATCH(C17,Kids!$B$6:$B$11,0))),0),IF(G17="Save",(N(E17)-N(F17)),0))) | I17: =IF(C17="",0,(N(E17)-N(F17))-H17-J17) | J17: =IF(C17="",0,IF(OR(G17="",G17="Split"),(N(E17)-N(F17))*IFERROR(N(INDEX(Kids!$G$6:$G$11,MATCH(C17,Kids!$B$6:$B$11,0))),0),IF(G17="Give",(N(E17)-N(F17)),0))) | K17: =IF(C17="",0,IF(OR(G17="",G17="Split"),N(E17)*IFERROR(N(INDEX(Kids!$F$6:$F$11,MATCH(C17,Kids!$B$6:$B$11,0))),0),IF(G17="Save",N(E17),0)))
B18: 46277 | C18: Leo | D18: Sweets | F18: 1.2 | G18: Spend | H18: =IF(C18="",0,IF(OR(G18="",G18="Split"),(N(E18)-N(F18))*IFERROR(N(INDEX(Kids!$F$6:$F$11,MATCH(C18,Kids!$B$6:$B$11,0))),0),IF(G18="Save",(N(E18)-N(F18)),0))) | I18: =IF(C18="",0,(N(E18)-N(F18))-H18-J18) | J18: =IF(C18="",0,IF(OR(G18="",G18="Split"),(N(E18)-N(F18))*IFERROR(N(INDEX(Kids!$G$6:$G$11,MATCH(C18,Kids!$B$6:$B$11,0))),0),IF(G18="Give",(N(E18)-N(F18)),0))) | K18: =IF(C18="",0,IF(OR(G18="",G18="Split"),N(E18)*IFERROR(N(INDEX(Kids!$F$6:$F$11,MATCH(C18,Kids!$B$6:$B$11,0))),0),IF(G18="Save",N(E18),0)))
B19: 46278 | C19: Mia | D19: Pocket money | E19: 7.5 | G19: Split | H19: =IF(C19="",0,IF(OR(G19="",G19="Split"),(N(E19)-N(F19))*IFERROR(N(INDEX(Kids!$F$6:$F$11,MATCH(C19,Kids!$B$6:$B$11,0))),0),IF(G19="Save",(N(E19)-N(F19)),0))) | I19: =IF(C19="",0,(N(E19)-N(F19))-H19-J19) | J19: =IF(C19="",0,IF(OR(G19="",G19="Split"),(N(E19)-N(F19))*IFERROR(N(INDEX(Kids!$G$6:$G$11,MATCH(C19,Kids!$B$6:$B$11,0))),0),IF(G19="Give",(N(E19)-N(F19)),0))) | K19: =IF(C19="",0,IF(OR(G19="",G19="Split"),N(E19)*IFERROR(N(INDEX(Kids!$F$6:$F$11,MATCH(C19,Kids!$B$6:$B$11,0))),0),IF(G19="Save",N(E19),0)))
B20: 46278 | C20: Leo | D20: Pocket money | E20: 4.5 | G20: Split | H20: =IF(C20="",0,IF(OR(G20="",G20="Split"),(N(E20)-N(F20))*IFERROR(N(INDEX(Kids!$F$6:$F$11,MATCH(C20,Kids!$B$6:$B$11,0))),0),IF(G20="Save",(N(E20)-N(F20)),0))) | I20: =IF(C20="",0,(N(E20)-N(F20))-H20-J20) | J20: =IF(C20="",0,IF(OR(G20="",G20="Split"),(N(E20)-N(F20))*IFERROR(N(INDEX(Kids!$G$6:$G$11,MATCH(C20,Kids!$B$6:$B$11,0))),0),IF(G20="Give",(N(E20)-N(F20)),0))) | K20: =IF(C20="",0,IF(OR(G20="",G20="Split"),N(E20)*IFERROR(N(INDEX(Kids!$F$6:$F$11,MATCH(C20,Kids!$B$6:$B$11,0))),0),IF(G20="Save",N(E20),0)))
B21: 46278 | C21: Ava | D21: Pocket money | E21: 9.9 | G21: Split | H21: =IF(C21="",0,IF(OR(G21="",G21="Split"),(N(E21)-N(F21))*IFERROR(N(INDEX(Kids!$F$6:$F$11,MATCH(C21,Kids!$B$6:$B$11,0))),0),IF(G21="Save",(N(E21)-N(F21)),0))) | I21: =IF(C21="",0,(N(E21)-N(F21))-H21-J21) | J21: =IF(C21="",0,IF(OR(G21="",G21="Split"),(N(E21)-N(F21))*IFERROR(N(INDEX(Kids!$G$6:$G$11,MATCH(C21,Kids!$B$6:$B$11,0))),0),IF(G21="Give",(N(E21)-N(F21)),0))) | K21: =IF(C21="",0,IF(OR(G21="",G21="Split"),N(E21)*IFERROR(N(INDEX(Kids!$F$6:$F$11,MATCH(C21,Kids!$B$6:$B$11,0))),0),IF(G21="Save",N(E21),0)))
B22: 46281 | C22: Mia | D22: Animal shelter | F22: 3 | G22: Give | H22: =IF(C22="",0,IF(OR(G22="",G22="Split"),(N(E22)-N(F22))*IFERROR(N(INDEX(Kids!$F$6:$F$11,MATCH(C22,Kids!$B$6:$B$11,0))),0),IF(G22="Save",(N(E22)-N(F22)),0))) | I22: =IF(C22="",0,(N(E22)-N(F22))-H22-J22) | J22: =IF(C22="",0,IF(OR(G22="",G22="Split"),(N(E22)-N(F22))*IFERROR(N(INDEX(Kids!$G$6:$G$11,MATCH(C22,Kids!$B$6:$B$11,0))),0),IF(G22="Give",(N(E22)-N(F22)),0))) | K22: =IF(C22="",0,IF(OR(G22="",G22="Split"),N(E22)*IFERROR(N(INDEX(Kids!$F$6:$F$11,MATCH(C22,Kids!$B$6:$B$11,0))),0),IF(G22="Save",N(E22),0)))
B23: 46284 | C23: Ava | D23: Sold old books | E23: 6 | G23: Split | H23: =IF(C23="",0,IF(OR(G23="",G23="Split"),(N(E23)-N(F23))*IFERROR(N(INDEX(Kids!$F$6:$F$11,MATCH(C23,Kids!$B$6:$B$11,0))),0),IF(G23="Save",(N(E23)-N(F23)),0))) | I23: =IF(C23="",0,(N(E23)-N(F23))-H23-J23) | J23: =IF(C23="",0,IF(OR(G23="",G23="Split"),(N(E23)-N(F23))*IFERROR(N(INDEX(Kids!$G$6:$G$11,MATCH(C23,Kids!$B$6:$B$11,0))),0),IF(G23="Give",(N(E23)-N(F23)),0))) | K23: =IF(C23="",0,IF(OR(G23="",G23="Split"),N(E23)*IFERROR(N(INDEX(Kids!$F$6:$F$11,MATCH(C23,Kids!$B$6:$B$11,0))),0),IF(G23="Save",N(E23),0)))
B24: 46285 | C24: Mia | D24: Pocket money | E24: 7 | G24: Split | H24: =IF(C24="",0,IF(OR(G24="",G24="Split"),(N(E24)-N(F24))*IFERROR(N(INDEX(Kids!$F$6:$F$11,MATCH(C24,Kids!$B$6:$B$11,0))),0),IF(G24="Save",(N(E24)-N(F24)),0))) | I24: =IF(C24="",0,(N(E24)-N(F24))-H24-J24) | J24: =IF(C24="",0,IF(OR(G24="",G24="Split"),(N(E24)-N(F24))*IFERROR(N(INDEX(Kids!$G$6:$G$11,MATCH(C24,Kids!$B$6:$B$11,0))),0),IF(G24="Give",(N(E24)-N(F24)),0))) | K24: =IF(C24="",0,IF(OR(G24="",G24="Split"),N(E24)*IFERROR(N(INDEX(Kids!$F$6:$F$11,MATCH(C24,Kids!$B$6:$B$11,0))),0),IF(G24="Save",N(E24),0)))
B25: 46285 | C25: Leo | D25: Pocket money | E25: 4.7 | G25: Split | H25: =IF(C25="",0,IF(OR(G25="",G25="Split"),(N(E25)-N(F25))*IFERROR(N(INDEX(Kids!$F$6:$F$11,MATCH(C25,Kids!$B$6:$B$11,0))),0),IF(G25="Save",(N(E25)-N(F25)),0))) | I25: =IF(C25="",0,(N(E25)-N(F25))-H25-J25) | J25: =IF(C25="",0,IF(OR(G25="",G25="Split"),(N(E25)-N(F25))*IFERROR(N(INDEX(Kids!$G$6:$G$11,MATCH(C25,Kids!$B$6:$B$11,0))),0),IF(G25="Give",(N(E25)-N(F25)),0))) | K25: =IF(C25="",0,IF(OR(G25="",G25="Split"),N(E25)*IFERROR(N(INDEX(Kids!$F$6:$F$11,MATCH(C25,Kids!$B$6:$B$11,0))),0),IF(G25="Save",N(E25),0)))
B26: 46285 | C26: Ava | D26: Pocket money | E26: 10.2 | G26: Split | H26: =IF(C26="",0,IF(OR(G26="",G26="Split"),(N(E26)-N(F26))*IFERROR(N(INDEX(Kids!$F$6:$F$11,MATCH(C26,Kids!$B$6:$B$11,0))),0),IF(G26="Save",(N(E26)-N(F26)),0))) | I26: =IF(C26="",0,(N(E26)-N(F26))-H26-J26) | J26: =IF(C26="",0,IF(OR(G26="",G26="Split"),(N(E26)-N(F26))*IFERROR(N(INDEX(Kids!$G$6:$G$11,MATCH(C26,Kids!$B$6:$B$11,0))),0),IF(G26="Give",(N(E26)-N(F26)),0))) | K26: =IF(C26="",0,IF(OR(G26="",G26="Split"),N(E26)*IFERROR(N(INDEX(Kids!$F$6:$F$11,MATCH(C26,Kids!$B$6:$B$11,0))),0),IF(G26="Save",N(E26),0)))
B27: 46288 | C27: Ava | D27: School charity day | F27: 4 | G27: Give | H27: =IF(C27="",0,IF(OR(G27="",G27="Split"),(N(E27)-N(F27))*IFERROR(N(INDEX(Kids!$F$6:$F$11,MATCH(C27,Kids!$B$6:$B$11,0))),0),IF(G27="Save",(N(E27)-N(F27)),0))) | I27: =IF(C27="",0,(N(E27)-N(F27))-H27-J27) | J27: =IF(C27="",0,IF(OR(G27="",G27="Split"),(N(E27)-N(F27))*IFERROR(N(INDEX(Kids!$G$6:$G$11,MATCH(C27,Kids!$B$6:$B$11,0))),0),IF(G27="Give",(N(E27)-N(F27)),0))) | K27: =IF(C27="",0,IF(OR(G27="",G27="Split"),N(E27)*IFERROR(N(INDEX(Kids!$F$6:$F$11,MATCH(C27,Kids!$B$6:$B$11,0))),0),IF(G27="Save",N(E27),0)))
B28: 46290 | C28: Leo | D28: Stickers | F28: 2.5 | G28: Spend | H28: =IF(C28="",0,IF(OR(G28="",G28="Split"),(N(E28)-N(F28))*IFERROR(N(INDEX(Kids!$F$6:$F$11,MATCH(C28,Kids!$B$6:$B$11,0))),0),IF(G28="Save",(N(E28)-N(F28)),0))) | I28: =IF(C28="",0,(N(E28)-N(F28))-H28-J28) | J28: =IF(C28="",0,IF(OR(G28="",G28="Split"),(N(E28)-N(F28))*IFERROR(N(INDEX(Kids!$G$6:$G$11,MATCH(C28,Kids!$B$6:$B$11,0))),0),IF(G28="Give",(N(E28)-N(F28)),0))) | K28: =IF(C28="",0,IF(OR(G28="",G28="Split"),N(E28)*IFERROR(N(INDEX(Kids!$F$6:$F$11,MATCH(C28,Kids!$B$6:$B$11,0))),0),IF(G28="Save",N(E28),0)))
B29: 46292 | C29: Mia | D29: Pocket money | E29: 7.25 | G29: Split | H29: =IF(C29="",0,IF(OR(G29="",G29="Split"),(N(E29)-N(F29))*IFERROR(N(INDEX(Kids!$F$6:$F$11,MATCH(C29,Kids!$B$6:$B$11,0))),0),IF(G29="Save",(N(E29)-N(F29)),0))) | I29: =IF(C29="",0,(N(E29)-N(F29))-H29-J29) | J29: =IF(C29="",0,IF(OR(G29="",G29="Split"),(N(E29)-N(F29))*IFERROR(N(INDEX(Kids!$G$6:$G$11,MATCH(C29,Kids!$B$6:$B$11,0))),0),IF(G29="Give",(N(E29)-N(F29)),0))) | K29: =IF(C29="",0,IF(OR(G29="",G29="Split"),N(E29)*IFERROR(N(INDEX(Kids!$F$6:$F$11,MATCH(C29,Kids!$B$6:$B$11,0))),0),IF(G29="Save",N(E29),0)))
B30: 46292 | C30: Leo | D30: Pocket money | E30: 4.5 | G30: Split | H30: =IF(C30="",0,IF(OR(G30="",G30="Split"),(N(E30)-N(F30))*IFERROR(N(INDEX(Kids!$F$6:$F$11,MATCH(C30,Kids!$B$6:$B$11,0))),0),IF(G30="Save",(N(E30)-N(F30)),0))) | I30: =IF(C30="",0,(N(E30)-N(F30))-H30-J30) | J30: =IF(C30="",0,IF(OR(G30="",G30="Split"),(N(E30)-N(F30))*IFERROR(N(INDEX(Kids!$G$6:$G$11,MATCH(C30,Kids!$B$6:$B$11,0))),0),IF(G30="Give",(N(E30)-N(F30)),0))) | K30: =IF(C30="",0,IF(OR(G30="",G30="Split"),N(E30)*IFERROR(N(INDEX(Kids!$F$6:$F$11,MATCH(C30,Kids!$B$6:$B$11,0))),0),IF(G30="Save",N(E30),0)))
B31: 46292 | C31: Ava | D31: Pocket money | E31: 10.5 | G31: Split | H31: =IF(C31="",0,IF(OR(G31="",G31="Split"),(N(E31)-N(F31))*IFERROR(N(INDEX(Kids!$F$6:$F$11,MATCH(C31,Kids!$B$6:$B$11,0))),0),IF(G31="Save",(N(E31)-N(F31)),0))) | I31: =IF(C31="",0,(N(E31)-N(F31))-H31-J31) | J31: =IF(C31="",0,IF(OR(G31="",G31="Split"),(N(E31)-N(F31))*IFERROR(N(INDEX(Kids!$G$6:$G$11,MATCH(C31,Kids!$B$6:$B$11,0))),0),IF(G31="Give",(N(E31)-N(F31)),0))) | K31: =IF(C31="",0,IF(OR(G31="",G31="Split"),N(E31)*IFERROR(N(INDEX(Kids!$F$6:$F$11,MATCH(C31,Kids!$B$6:$B$11,0))),0),IF(G31="Save",N(E31),0)))
H32: =IF(C32="",0,IF(OR(G32="",G32="Split"),(N(E32)-N(F32))*IFERROR(N(INDEX(Kids!$F$6:$F$11,MATCH(C32,Kids!$B$6:$B$11,0))),0),IF(G32="Save",(N(E32)-N(F32)),0))) | I32: =IF(C32="",0,(N(E32)-N(F32))-H32-J32) | J32: =IF(C32="",0,IF(OR(G32="",G32="Split"),(N(E32)-N(F32))*IFERROR(N(INDEX(Kids!$G$6:$G$11,MATCH(C32,Kids!$B$6:$B$11,0))),0),IF(G32="Give",(N(E32)-N(F32)),0))) | K32: =IF(C32="",0,IF(OR(G32="",G32="Split"),N(E32)*IFERROR(N(INDEX(Kids!$F$6:$F$11,MATCH(C32,Kids!$B$6:$B$11,0))),0),IF(G32="Save",N(E32),0)))
H33: =IF(C33="",0,IF(OR(G33="",G33="Split"),(N(E33)-N(F33))*IFERROR(N(INDEX(Kids!$F$6:$F$11,MATCH(C33,Kids!$B$6:$B$11,0))),0),IF(G33="Save",(N(E33)-N(F33)),0))) | I33: =IF(C33="",0,(N(E33)-N(F33))-H33-J33) | J33: =IF(C33="",0,IF(OR(G33="",G33="Split"),(N(E33)-N(F33))*IFERROR(N(INDEX(Kids!$G$6:$G$11,MATCH(C33,Kids!$B$6:$B$11,0))),0),IF(G33="Give",(N(E33)-N(F33)),0))) | K33: =IF(C33="",0,IF(OR(G33="",G33="Split"),N(E33)*IFERROR(N(INDEX(Kids!$F$6:$F$11,MATCH(C33,Kids!$B$6:$B$11,0))),0),IF(G33="Save",N(E33),0)))
H34: =IF(C34="",0,IF(OR(G34="",G34="Split"),(N(E34)-N(F34))*IFERROR(N(INDEX(Kids!$F$6:$F$11,MATCH(C34,Kids!$B$6:$B$11,0))),0),IF(G34="Save",(N(E34)-N(F34)),0))) | I34: =IF(C34="",0,(N(E34)-N(F34))-H34-J34) | J34: =IF(C34="",0,IF(OR(G34="",G34="Split"),(N(E34)-N(F34))*IFERROR(N(INDEX(Kids!$G$6:$G$11,MATCH(C34,Kids!$B$6:$B$11,0))),0),IF(G34="Give",(N(E34)-N(F34)),0))) | K34: =IF(C34="",0,IF(OR(G34="",G34="Split"),N(E34)*IFERROR(N(INDEX(Kids!$F$6:$F$11,MATCH(C34,Kids!$B$6:$B$11,0))),0),IF(G34="Save",N(E34),0)))
H35: =IF(C35="",0,IF(OR(G35="",G35="Split"),(N(E35)-N(F35))*IFERROR(N(INDEX(Kids!$F$6:$F$11,MATCH(C35,Kids!$B$6:$B$11,0))),0),IF(G35="Save",(N(E35)-N(F35)),0))) | I35: =IF(C35="",0,(N(E35)-N(F35))-H35-J35) | J35: =IF(C35="",0,IF(OR(G35="",G35="Split"),(N(E35)-N(F35))*IFERROR(N(INDEX(Kids!$G$6:$G$11,MATCH(C35,Kids!$B$6:$B$11,0))),0),IF(G35="Give",(N(E35)-N(F35)),0))) | K35: =IF(C35="",0,IF(OR(G35="",G35="Split"),N(E35)*IFERROR(N(INDEX(Kids!$F$6:$F$11,MATCH(C35,Kids!$B$6:$B$11,0))),0),IF(G35="Save",N(E35),0)))
H36: =IF(C36="",0,IF(OR(G36="",G36="Split"),(N(E36)-N(F36))*IFERROR(N(INDEX(Kids!$F$6:$F$11,MATCH(C36,Kids!$B$6:$B$11,0))),0),IF(G36="Save",(N(E36)-N(F36)),0))) | I36: =IF(C36="",0,(N(E36)-N(F36))-H36-J36) | J36: =IF(C36="",0,IF(OR(G36="",G36="Split"),(N(E36)-N(F36))*IFERROR(N(INDEX(Kids!$G$6:$G$11,MATCH(C36,Kids!$B$6:$B$11,0))),0),IF(G36="Give",(N(E36)-N(F36)),0))) | K36: =IF(C36="",0,IF(OR(G36="",G36="Split"),N(E36)*IFERROR(N(INDEX(Kids!$F$6:$F$11,MATCH(C36,Kids!$B$6:$B$11,0))),0),IF(G36="Save",N(E36),0)))
H37: =IF(C37="",0,IF(OR(G37="",G37="Split"),(N(E37)-N(F37))*IFERROR(N(INDEX(Kids!$F$6:$F$11,MATCH(C37,Kids!$B$6:$B$11,0))),0),IF(G37="Save",(N(E37)-N(F37)),0))) | I37: =IF(C37="",0,(N(E37)-N(F37))-H37-J37) | J37: =IF(C37="",0,IF(OR(G37="",G37="Split"),(N(E37)-N(F37))*IFERROR(N(INDEX(Kids!$G$6:$G$11,MATCH(C37,Kids!$B$6:$B$11,0))),0),IF(G37="Give",(N(E37)-N(F37)),0))) | K37: =IF(C37="",0,IF(OR(G37="",G37="Split"),N(E37)*IFERROR(N(INDEX(Kids!$F$6:$F$11,MATCH(C37,Kids!$B$6:$B$11,0))),0),IF(G37="Save",N(E37),0)))
H38: =IF(C38="",0,IF(OR(G38="",G38="Split"),(N(E38)-N(F38))*IFERROR(N(INDEX(Kids!$F$6:$F$11,MATCH(C38,Kids!$B$6:$B$11,0))),0),IF(G38="Save",(N(E38)-N(F38)),0))) | I38: =IF(C38="",0,(N(E38)-N(F38))-H38-J38) | J38: =IF(C38="",0,IF(OR(G38="",G38="Split"),(N(E38)-N(F38))*IFERROR(N(INDEX(Kids!$G$6:$G$11,MATCH(C38,Kids!$B$6:$B$11,0))),0),IF(G38="Give",(N(E38)-N(F38)),0))) | K38: =IF(C38="",0,IF(OR(G38="",G38="Split"),N(E38)*IFERROR(N(INDEX(Kids!$F$6:$F$11,MATCH(C38,Kids!$B$6:$B$11,0))),0),IF(G38="Save",N(E38),0)))
H39: =IF(C39="",0,IF(OR(G39="",G39="Split"),(N(E39)-N(F39))*IFERROR(N(INDEX(Kids!$F$6:$F$11,MATCH(C39,Kids!$B$6:$B$11,0))),0),IF(G39="Save",(N(E39)-N(F39)),0))) | I39: =IF(C39="",0,(N(E39)-N(F39))-H39-J39) | J39: =IF(C39="",0,IF(OR(G39="",G39="Split"),(N(E39)-N(F39))*IFERROR(N(INDEX(Kids!$G$6:$G$11,MATCH(C39,Kids!$B$6:$B$11,0))),0),IF(G39="Give",(N(E39)-N(F39)),0))) | K39: =IF(C39="",0,IF(OR(G39="",G39="Split"),N(E39)*IFERROR(N(INDEX(Kids!$F$6:$F$11,MATCH(C39,Kids!$B$6:$B$11,0))),0),IF(G39="Save",N(E39),0)))
H40: =IF(C40="",0,IF(OR(G40="",G40="Split"),(N(E40)-N(F40))*IFERROR(N(INDEX(Kids!$F$6:$F$11,MATCH(C40,Kids!$B$6:$B$11,0))),0),IF(G40="Save",(N(E40)-N(F40)),0))) | I40: =IF(C40="",0,(N(E40)-N(F40))-H40-J40) | J40: =IF(C40="",0,IF(OR(G40="",G40="Split"),(N(E40)-N(F40))*IFERROR(N(INDEX(Kids!$G$6:$G$11,MATCH(C40,Kids!$B$6:$B$11,0))),0),IF(G40="Give",(N(E40)-N(F40)),0))) | K40: =IF(C40="",0,IF(OR(G40="",G40="Split"),N(E40)*IFERROR(N(INDEX(Kids!$F$6:$F$11,MATCH(C40,Kids!$B$6:$B$11,0))),0),IF(G40="Save",N(E40),0)))
H41: =IF(C41="",0,IF(OR(G41="",G41="Split"),(N(E41)-N(F41))*IFERROR(N(INDEX(Kids!$F$6:$F$11,MATCH(C41,Kids!$B$6:$B$11,0))),0),IF(G41="Save",(N(E41)-N(F41)),0))) | I41: =IF(C41="",0,(N(E41)-N(F41))-H41-J41) | J41: =IF(C41="",0,IF(OR(G41="",G41="Split"),(N(E41)-N(F41))*IFERROR(N(INDEX(Kids!$G$6:$G$11,MATCH(C41,Kids!$B$6:$B$11,0))),0),IF(G41="Give",(N(E41)-N(F41)),0))) | K41: =IF(C41="",0,IF(OR(G41="",G41="Split"),N(E41)*IFERROR(N(INDEX(Kids!$F$6:$F$11,MATCH(C41,Kids!$B$6:$B$11,0))),0),IF(G41="Save",N(E41),0)))
H42: =IF(C42="",0,IF(OR(G42="",G42="Split"),(N(E42)-N(F42))*IFERROR(N(INDEX(Kids!$F$6:$F$11,MATCH(C42,Kids!$B$6:$B$11,0))),0),IF(G42="Save",(N(E42)-N(F42)),0))) | I42: =IF(C42="",0,(N(E42)-N(F42))-H42-J42) | J42: =IF(C42="",0,IF(OR(G42="",G42="Split"),(N(E42)-N(F42))*IFERROR(N(INDEX(Kids!$G$6:$G$11,MATCH(C42,Kids!$B$6:$B$11,0))),0),IF(G42="Give",(N(E42)-N(F42)),0))) | K42: =IF(C42="",0,IF(OR(G42="",G42="Split"),N(E42)*IFERROR(N(INDEX(Kids!$F$6:$F$11,MATCH(C42,Kids!$B$6:$B$11,0))),0),IF(G42="Save",N(E42),0)))
...

Sheet Kids
B2: Kids
B3: Each child's pocket money: a base amount a week and so much a point, split into three jars.
B5: Name | C5: Age | D5: Base a week | E5: Per point | F5: Save | G5: Give | H5: Spend | I5: Goal | J5: Goal price | K5: Save jar | L5: Spend jar | M5: Give jar | N5: Goal saved | O5: Weeks to go
B6: Mia | C6: 9 | D6: 2 | E6: 0.25 | F6: 0.4 | G6: 0.1 | H6: =IF(B6="","",1-N(F6)-N(G6)) | I6: Art kit | J6: 30 | K6: =IF(B6="","",SUMIFS(Money!$H$6:$H$505,Money!$C$6:$C$505,B6)) | L6: =IF(B6="","",SUMIFS(Money!$I$6:$I$505,Money!$C$6:$C$505,B6)) | M6: =IF(B6="","",SUMIFS(Money!$J$6:$J$505,Money!$C$6:$C$505,B6)) | N6: =IF(OR(B6="",N(J6)=0),"",REPT("█",MIN(12,MAX(0,ROUND((K6/J6)*12,0))))&REPT("░",12-MIN(12,MAX(0,ROUND((K6/J6)*12,0))))) | O6: =IF(OR(B6="",N(J6)=0),"",IF(K6>=J6,"Reached",IF(N(Q6)<=0,"",ROUNDUP(ROUND((J6-K6)/Q6,6),0)))) | Q6: =IF(B6="","",SUMIFS(Money!$K$6:$K$505,Money!$C$6:$C$505,B6,Money!$B$6:$B$505,">"&(TODAY()-28))/4)
B7: Leo | C7: 7 | D7: 1.5 | E7: 0.2 | F7: 0.3 | G7: 0.1 | H7: =IF(B7="","",1-N(F7)-N(G7)) | I7: Building set | J7: 45 | K7: =IF(B7="","",SUMIFS(Money!$H$6:$H$505,Money!$C$6:$C$505,B7)) | L7: =IF(B7="","",SUMIFS(Money!$I$6:$I$505,Money!$C$6:$C$505,B7)) | M7: =IF(B7="","",SUMIFS(Money!$J$6:$J$505,Money!$C$6:$C$505,B7)) | N7: =IF(OR(B7="",N(J7)=0),"",REPT("█",MIN(12,MAX(0,ROUND((K7/J7)*12,0))))&REPT("░",12-MIN(12,MAX(0,ROUND((K7/J7)*12,0))))) | O7: =IF(OR(B7="",N(J7)=0),"",IF(K7>=J7,"Reached",IF(N(Q7)<=0,"",ROUNDUP(ROUND((J7-K7)/Q7,6),0)))) | Q7: =IF(B7="","",SUMIFS(Money!$K$6:$K$505,Money!$C$6:$C$505,B7,Money!$B$6:$B$505,">"&(TODAY()-28))/4)
B8: Ava | C8: 12 | D8: 3 | E8: 0.3 | F8: 0.5 | G8: 0.1 | H8: =IF(B8="","",1-N(F8)-N(G8)) | I8: Headphones | J8: 60 | K8: =IF(B8="","",SUMIFS(Money!$H$6:$H$505,Money!$C$6:$C$505,B8)) | L8: =IF(B8="","",SUMIFS(Money!$I$6:$I$505,Money!$C$6:$C$505,B8)) | M8: =IF(B8="","",SUMIFS(Money!$J$6:$J$505,Money!$C$6:$C$505,B8)) | N8: =IF(OR(B8="",N(J8)=0),"",REPT("█",MIN(12,MAX(0,ROUND((K8/J8)*12,0))))&REPT("░",12-MIN(12,MAX(0,ROUND((K8/J8)*12,0))))) | O8: =IF(OR(B8="",N(J8)=0),"",IF(K8>=J8,"Reached",IF(N(Q8)<=0,"",ROUNDUP(ROUND((J8-K8)/Q8,6),0)))) | Q8: =IF(B8="","",SUMIFS(Money!$K$6:$K$505,Money!$C$6:$C$505,B8,Money!$B$6:$B$505,">"&(TODAY()-28))/4)
H9: =IF(B9="","",1-N(F9)-N(G9)) | K9: =IF(B9="","",SUMIFS(Money!$H$6:$H$505,Money!$C$6:$C$505,B9)) | L9: =IF(B9="","",SUMIFS(Money!$I$6:$I$505,Money!$C$6:$C$505,B9)) | M9: =IF(B9="","",SUMIFS(Money!$J$6:$J$505,Money!$C$6:$C$505,B9)) | N9: =IF(OR(B9="",N(J9)=0),"",REPT("█",MIN(12,MAX(0,ROUND((K9/J9)*12,0))))&REPT("░",12-MIN(12,MAX(0,ROUND((K9/J9)*12,0))))) | O9: =IF(OR(B9="",N(J9)=0),"",IF(K9>=J9,"Reached",IF(N(Q9)<=0,"",ROUNDUP(ROUND((J9-K9)/Q9,6),0)))) | Q9: =IF(B9="","",SUMIFS(Money!$K$6:$K$505,Money!$C$6:$C$505,B9,Money!$B$6:$B$505,">"&(TODAY()-28))/4)
H10: =IF(B10="","",1-N(F10)-N(G10)) | K10: =IF(B10="","",SUMIFS(Money!$H$6:$H$505,Money!$C$6:$C$505,B10)) | L10: =IF(B10="","",SUMIFS(Money!$I$6:$I$505,Money!$C$6:$C$505,B10)) | M10: =IF(B10="","",SUMIFS(Money!$J$6:$J$505,Money!$C$6:$C$505,B10)) | N10: =IF(OR(B10="",N(J10)=0),"",REPT("█",MIN(12,MAX(0,ROUND((K10/J10)*12,0))))&REPT("░",12-MIN(12,MAX(0,ROUND((K10/J10)*12,0))))) | O10: =IF(OR(B10="",N(J10)=0),"",IF(K10>=J10,"Reached",IF(N(Q10)<=0,"",ROUNDUP(ROUND((J10-K10)/Q10,6),0)))) | Q10: =IF(B10="","",SUMIFS(Money!$K$6:$K$505,Money!$C$6:$C$505,B10,Money!$B$6:$B$505,">"&(TODAY()-28))/4)
H11: =IF(B11="","",1-N(F11)-N(G11)) | K11: =IF(B11="","",SUMIFS(Money!$H$6:$H$505,Money!$C$6:$C$505,B11)) | L11: =IF(B11="","",SUMIFS(Money!$I$6:$I$505,Money!$C$6:$C$505,B11)) | M11: =IF(B11="","",SUMIFS(Money!$J$6:$J$505,Money!$C$6:$C$505,B11)) | N11: =IF(OR(B11="",N(J11)=0),"",REPT("█",MIN(12,MAX(0,ROUND((K11/J11)*12,0))))&REPT("░",12-MIN(12,MAX(0,ROUND((K11/J11)*12,0))))) | O11: =IF(OR(B11="",N(J11)=0),"",IF(K11>=J11,"Reached",IF(N(Q11)<=0,"",ROUNDUP(ROUND((J11-K11)/Q11,6),0)))) | Q11: =IF(B11="","",SUMIFS(Money!$K$6:$K$505,Money!$C$6:$C$505,B11,Money!$B$6:$B$505,">"&(TODAY()-28))/4)

Sheet Settings
B2: Settings
B3: The currency and the week the chart shows.
B4: Currency | C4: USD | E4: Amounts have no currency sign, so any currency works.
B5: Show another week | E5: Leave it empty for the week we are in. Type any day to see and print its week.
B6: The week starts on | C6: =IF(C5="",TODAY(),C5)-WEEKDAY(IF(C5="",TODAY(),C5),3) | E6: The Monday of that week.

Sheet Start Here
B2: Start here
B3: Type only in the yellow cells, and tick the boxes on This week.
B5: 1 | C5: Kids: each child with a base amount a week, so much a point, and the shares to save and to give.
B7: 2 | C7: Chores: each chore for each child, its points and an x on the days it is expected.
B9: 3 | C9: This week: an x in the box when a chore is done.
B11: 4 | C11: Fridge chart: pick a child in the yellow box and print the chart. It shows the ticks made so far.
B13: 5 | C13: Pay day: the Dashboard shows what each child earned. Add it on Money as Pocket money, jar Split.
