Workbook

Sheet Dashboard
B2: Hours and invoices
B3: The work on the left, the money on the right.
B4: Hours this week | C4: Hours this month | D4: Worth this month | E4: Worth this year | G4: To invoice | H4: Waiting | I4: Overdue | J4: Paid this year
B5: =SUMIFS(Timesheet!$M$6:$M$2005,Timesheet!$B$6:$B$2005,">="&TODAY()-WEEKDAY(TODAY(),3),Timesheet!$B$6:$B$2005,"<="&TODAY()-WEEKDAY(TODAY(),3)+6) | C5: =SUMIFS(Timesheet!$M$6:$M$2005,Timesheet!$B$6:$B$2005,">="&DATE(YEAR(TODAY()),MONTH(TODAY()),1),Timesheet!$B$6:$B$2005,"<="&EOMONTH(TODAY(),0)) | D5: =SUMIFS(Timesheet!$O$6:$O$2005,Timesheet!$B$6:$B$2005,">="&DATE(YEAR(TODAY()),MONTH(TODAY()),1),Timesheet!$B$6:$B$2005,"<="&EOMONTH(TODAY(),0)) | E5: =SUMIFS(Timesheet!$O$6:$O$2005,Timesheet!$B$6:$B$2005,">="&DATE(YEAR(TODAY()),1,1),Timesheet!$B$6:$B$2005,"<="&DATE(YEAR(TODAY()),12,31)) | G5: =SUMIFS(Timesheet!$O$6:$O$2005,Timesheet!$Q$6:$Q$2005,"To invoice")+SUMIFS(Timesheet!$O$6:$O$2005,Timesheet!$Q$6:$Q$2005,"Draft") | H5: =SUMIFS(Invoices!$J$6:$J$305,Invoices!$M$6:$M$305,"Waiting") | I5: =SUMIFS(Invoices!$J$6:$J$305,Invoices!$M$6:$M$305,"Overdue*") | J5: =SUMIFS(Invoices!$J$6:$J$305,Invoices!$L$6:$L$305,">="&DATE(YEAR(TODAY()),1,1),Invoices!$L$6:$L$305,"<="&DATE(YEAR(TODAY()),12,31))
B8: This week | C8: Hours | D8: Billable | E8: Worth | G8: Client | H8: Hours this month | I8: To invoice | J8: Not paid
B9: ="Monday "&DAY((TODAY()-WEEKDAY(TODAY(),3)+0))&" "&CHOOSE(MONTH((TODAY()-WEEKDAY(TODAY(),3)+0)),"Jan","Feb","Mar","Apr","May","Jun","Jul","Aug","Sep","Oct","Nov","Dec") | C9: =SUMIFS(Timesheet!$M$6:$M$2005,Timesheet!$B$6:$B$2005,(TODAY()-WEEKDAY(TODAY(),3)+0)) | D9: =SUMIFS(Timesheet!$U$6:$U$2005,Timesheet!$B$6:$B$2005,(TODAY()-WEEKDAY(TODAY(),3)+0)) | E9: =SUMIFS(Timesheet!$O$6:$O$2005,Timesheet!$B$6:$B$2005,(TODAY()-WEEKDAY(TODAY(),3)+0)) | G9: =IF(O9="","No work this month yet",INDEX(Clients!$B$6:$B$45,O9-5)) | H9: =IF(O9="","",SUMIFS(Timesheet!$M$6:$M$2005,Timesheet!$C$6:$C$2005,G9,Timesheet!$B$6:$B$2005,">="&DATE(YEAR(TODAY()),MONTH(TODAY()),1),Timesheet!$B$6:$B$2005,"<="&EOMONTH(TODAY(),0))) | I9: =IF(O9="","",SUMIFS(Timesheet!$O$6:$O$2005,Timesheet!$C$6:$C$2005,G9,Timesheet!$Q$6:$Q$2005,"To invoice")+SUMIFS(Timesheet!$O$6:$O$2005,Timesheet!$C$6:$C$2005,G9,Timesheet!$Q$6:$Q$2005,"Draft")) | J9: =IF(O9="","",SUMIFS(Invoices!$J$6:$J$305,Invoices!$C$6:$C$305,G9,Invoices!$M$6:$M$305,"Waiting")+SUMIFS(Invoices!$J$6:$J$305,Invoices!$C$6:$C$305,G9,Invoices!$M$6:$M$305,"Overdue*")) | O9: =IFERROR(SMALL(Clients!$J$6:$J$45,1),"")
B10: ="Tuesday "&DAY((TODAY()-WEEKDAY(TODAY(),3)+1))&" "&CHOOSE(MONTH((TODAY()-WEEKDAY(TODAY(),3)+1)),"Jan","Feb","Mar","Apr","May","Jun","Jul","Aug","Sep","Oct","Nov","Dec") | C10: =SUMIFS(Timesheet!$M$6:$M$2005,Timesheet!$B$6:$B$2005,(TODAY()-WEEKDAY(TODAY(),3)+1)) | D10: =SUMIFS(Timesheet!$U$6:$U$2005,Timesheet!$B$6:$B$2005,(TODAY()-WEEKDAY(TODAY(),3)+1)) | E10: =SUMIFS(Timesheet!$O$6:$O$2005,Timesheet!$B$6:$B$2005,(TODAY()-WEEKDAY(TODAY(),3)+1)) | G10: =IF(O10="","",INDEX(Clients!$B$6:$B$45,O10-5)) | H10: =IF(O10="","",SUMIFS(Timesheet!$M$6:$M$2005,Timesheet!$C$6:$C$2005,G10,Timesheet!$B$6:$B$2005,">="&DATE(YEAR(TODAY()),MONTH(TODAY()),1),Timesheet!$B$6:$B$2005,"<="&EOMONTH(TODAY(),0))) | I10: =IF(O10="","",SUMIFS(Timesheet!$O$6:$O$2005,Timesheet!$C$6:$C$2005,G10,Timesheet!$Q$6:$Q$2005,"To invoice")+SUMIFS(Timesheet!$O$6:$O$2005,Timesheet!$C$6:$C$2005,G10,Timesheet!$Q$6:$Q$2005,"Draft")) | J10: =IF(O10="","",SUMIFS(Invoices!$J$6:$J$305,Invoices!$C$6:$C$305,G10,Invoices!$M$6:$M$305,"Waiting")+SUMIFS(Invoices!$J$6:$J$305,Invoices!$C$6:$C$305,G10,Invoices!$M$6:$M$305,"Overdue*")) | O10: =IFERROR(SMALL(Clients!$J$6:$J$45,2),"")
B11: ="Wednesday "&DAY((TODAY()-WEEKDAY(TODAY(),3)+2))&" "&CHOOSE(MONTH((TODAY()-WEEKDAY(TODAY(),3)+2)),"Jan","Feb","Mar","Apr","May","Jun","Jul","Aug","Sep","Oct","Nov","Dec") | C11: =SUMIFS(Timesheet!$M$6:$M$2005,Timesheet!$B$6:$B$2005,(TODAY()-WEEKDAY(TODAY(),3)+2)) | D11: =SUMIFS(Timesheet!$U$6:$U$2005,Timesheet!$B$6:$B$2005,(TODAY()-WEEKDAY(TODAY(),3)+2)) | E11: =SUMIFS(Timesheet!$O$6:$O$2005,Timesheet!$B$6:$B$2005,(TODAY()-WEEKDAY(TODAY(),3)+2)) | G11: =IF(O11="","",INDEX(Clients!$B$6:$B$45,O11-5)) | H11: =IF(O11="","",SUMIFS(Timesheet!$M$6:$M$2005,Timesheet!$C$6:$C$2005,G11,Timesheet!$B$6:$B$2005,">="&DATE(YEAR(TODAY()),MONTH(TODAY()),1),Timesheet!$B$6:$B$2005,"<="&EOMONTH(TODAY(),0))) | I11: =IF(O11="","",SUMIFS(Timesheet!$O$6:$O$2005,Timesheet!$C$6:$C$2005,G11,Timesheet!$Q$6:$Q$2005,"To invoice")+SUMIFS(Timesheet!$O$6:$O$2005,Timesheet!$C$6:$C$2005,G11,Timesheet!$Q$6:$Q$2005,"Draft")) | J11: =IF(O11="","",SUMIFS(Invoices!$J$6:$J$305,Invoices!$C$6:$C$305,G11,Invoices!$M$6:$M$305,"Waiting")+SUMIFS(Invoices!$J$6:$J$305,Invoices!$C$6:$C$305,G11,Invoices!$M$6:$M$305,"Overdue*")) | O11: =IFERROR(SMALL(Clients!$J$6:$J$45,3),"")
B12: ="Thursday "&DAY((TODAY()-WEEKDAY(TODAY(),3)+3))&" "&CHOOSE(MONTH((TODAY()-WEEKDAY(TODAY(),3)+3)),"Jan","Feb","Mar","Apr","May","Jun","Jul","Aug","Sep","Oct","Nov","Dec") | C12: =SUMIFS(Timesheet!$M$6:$M$2005,Timesheet!$B$6:$B$2005,(TODAY()-WEEKDAY(TODAY(),3)+3)) | D12: =SUMIFS(Timesheet!$U$6:$U$2005,Timesheet!$B$6:$B$2005,(TODAY()-WEEKDAY(TODAY(),3)+3)) | E12: =SUMIFS(Timesheet!$O$6:$O$2005,Timesheet!$B$6:$B$2005,(TODAY()-WEEKDAY(TODAY(),3)+3)) | G12: =IF(O12="","",INDEX(Clients!$B$6:$B$45,O12-5)) | H12: =IF(O12="","",SUMIFS(Timesheet!$M$6:$M$2005,Timesheet!$C$6:$C$2005,G12,Timesheet!$B$6:$B$2005,">="&DATE(YEAR(TODAY()),MONTH(TODAY()),1),Timesheet!$B$6:$B$2005,"<="&EOMONTH(TODAY(),0))) | I12: =IF(O12="","",SUMIFS(Timesheet!$O$6:$O$2005,Timesheet!$C$6:$C$2005,G12,Timesheet!$Q$6:$Q$2005,"To invoice")+SUMIFS(Timesheet!$O$6:$O$2005,Timesheet!$C$6:$C$2005,G12,Timesheet!$Q$6:$Q$2005,"Draft")) | J12: =IF(O12="","",SUMIFS(Invoices!$J$6:$J$305,Invoices!$C$6:$C$305,G12,Invoices!$M$6:$M$305,"Waiting")+SUMIFS(Invoices!$J$6:$J$305,Invoices!$C$6:$C$305,G12,Invoices!$M$6:$M$305,"Overdue*")) | O12: =IFERROR(SMALL(Clients!$J$6:$J$45,4),"")
B13: ="Friday "&DAY((TODAY()-WEEKDAY(TODAY(),3)+4))&" "&CHOOSE(MONTH((TODAY()-WEEKDAY(TODAY(),3)+4)),"Jan","Feb","Mar","Apr","May","Jun","Jul","Aug","Sep","Oct","Nov","Dec") | C13: =SUMIFS(Timesheet!$M$6:$M$2005,Timesheet!$B$6:$B$2005,(TODAY()-WEEKDAY(TODAY(),3)+4)) | D13: =SUMIFS(Timesheet!$U$6:$U$2005,Timesheet!$B$6:$B$2005,(TODAY()-WEEKDAY(TODAY(),3)+4)) | E13: =SUMIFS(Timesheet!$O$6:$O$2005,Timesheet!$B$6:$B$2005,(TODAY()-WEEKDAY(TODAY(),3)+4)) | G13: =IF(O13="","",INDEX(Clients!$B$6:$B$45,O13-5)) | H13: =IF(O13="","",SUMIFS(Timesheet!$M$6:$M$2005,Timesheet!$C$6:$C$2005,G13,Timesheet!$B$6:$B$2005,">="&DATE(YEAR(TODAY()),MONTH(TODAY()),1),Timesheet!$B$6:$B$2005,"<="&EOMONTH(TODAY(),0))) | I13: =IF(O13="","",SUMIFS(Timesheet!$O$6:$O$2005,Timesheet!$C$6:$C$2005,G13,Timesheet!$Q$6:$Q$2005,"To invoice")+SUMIFS(Timesheet!$O$6:$O$2005,Timesheet!$C$6:$C$2005,G13,Timesheet!$Q$6:$Q$2005,"Draft")) | J13: =IF(O13="","",SUMIFS(Invoices!$J$6:$J$305,Invoices!$C$6:$C$305,G13,Invoices!$M$6:$M$305,"Waiting")+SUMIFS(Invoices!$J$6:$J$305,Invoices!$C$6:$C$305,G13,Invoices!$M$6:$M$305,"Overdue*")) | O13: =IFERROR(SMALL(Clients!$J$6:$J$45,5),"")
B14: ="Saturday "&DAY((TODAY()-WEEKDAY(TODAY(),3)+5))&" "&CHOOSE(MONTH((TODAY()-WEEKDAY(TODAY(),3)+5)),"Jan","Feb","Mar","Apr","May","Jun","Jul","Aug","Sep","Oct","Nov","Dec") | C14: =SUMIFS(Timesheet!$M$6:$M$2005,Timesheet!$B$6:$B$2005,(TODAY()-WEEKDAY(TODAY(),3)+5)) | D14: =SUMIFS(Timesheet!$U$6:$U$2005,Timesheet!$B$6:$B$2005,(TODAY()-WEEKDAY(TODAY(),3)+5)) | E14: =SUMIFS(Timesheet!$O$6:$O$2005,Timesheet!$B$6:$B$2005,(TODAY()-WEEKDAY(TODAY(),3)+5)) | G14: =IF(O14="","",INDEX(Clients!$B$6:$B$45,O14-5)) | H14: =IF(O14="","",SUMIFS(Timesheet!$M$6:$M$2005,Timesheet!$C$6:$C$2005,G14,Timesheet!$B$6:$B$2005,">="&DATE(YEAR(TODAY()),MONTH(TODAY()),1),Timesheet!$B$6:$B$2005,"<="&EOMONTH(TODAY(),0))) | I14: =IF(O14="","",SUMIFS(Timesheet!$O$6:$O$2005,Timesheet!$C$6:$C$2005,G14,Timesheet!$Q$6:$Q$2005,"To invoice")+SUMIFS(Timesheet!$O$6:$O$2005,Timesheet!$C$6:$C$2005,G14,Timesheet!$Q$6:$Q$2005,"Draft")) | J14: =IF(O14="","",SUMIFS(Invoices!$J$6:$J$305,Invoices!$C$6:$C$305,G14,Invoices!$M$6:$M$305,"Waiting")+SUMIFS(Invoices!$J$6:$J$305,Invoices!$C$6:$C$305,G14,Invoices!$M$6:$M$305,"Overdue*")) | O14: =IFERROR(SMALL(Clients!$J$6:$J$45,6),"")
B15: ="Sunday "&DAY((TODAY()-WEEKDAY(TODAY(),3)+6))&" "&CHOOSE(MONTH((TODAY()-WEEKDAY(TODAY(),3)+6)),"Jan","Feb","Mar","Apr","May","Jun","Jul","Aug","Sep","Oct","Nov","Dec") | C15: =SUMIFS(Timesheet!$M$6:$M$2005,Timesheet!$B$6:$B$2005,(TODAY()-WEEKDAY(TODAY(),3)+6)) | D15: =SUMIFS(Timesheet!$U$6:$U$2005,Timesheet!$B$6:$B$2005,(TODAY()-WEEKDAY(TODAY(),3)+6)) | E15: =SUMIFS(Timesheet!$O$6:$O$2005,Timesheet!$B$6:$B$2005,(TODAY()-WEEKDAY(TODAY(),3)+6)) | G15: =IF(O15="","",INDEX(Clients!$B$6:$B$45,O15-5)) | H15: =IF(O15="","",SUMIFS(Timesheet!$M$6:$M$2005,Timesheet!$C$6:$C$2005,G15,Timesheet!$B$6:$B$2005,">="&DATE(YEAR(TODAY()),MONTH(TODAY()),1),Timesheet!$B$6:$B$2005,"<="&EOMONTH(TODAY(),0))) | I15: =IF(O15="","",SUMIFS(Timesheet!$O$6:$O$2005,Timesheet!$C$6:$C$2005,G15,Timesheet!$Q$6:$Q$2005,"To invoice")+SUMIFS(Timesheet!$O$6:$O$2005,Timesheet!$C$6:$C$2005,G15,Timesheet!$Q$6:$Q$2005,"Draft")) | J15: =IF(O15="","",SUMIFS(Invoices!$J$6:$J$305,Invoices!$C$6:$C$305,G15,Invoices!$M$6:$M$305,"Waiting")+SUMIFS(Invoices!$J$6:$J$305,Invoices!$C$6:$C$305,G15,Invoices!$M$6:$M$305,"Overdue*")) | O15: =IFERROR(SMALL(Clients!$J$6:$J$45,7),"")
G16: =IF(O16="","",INDEX(Clients!$B$6:$B$45,O16-5)) | H16: =IF(O16="","",SUMIFS(Timesheet!$M$6:$M$2005,Timesheet!$C$6:$C$2005,G16,Timesheet!$B$6:$B$2005,">="&DATE(YEAR(TODAY()),MONTH(TODAY()),1),Timesheet!$B$6:$B$2005,"<="&EOMONTH(TODAY(),0))) | I16: =IF(O16="","",SUMIFS(Timesheet!$O$6:$O$2005,Timesheet!$C$6:$C$2005,G16,Timesheet!$Q$6:$Q$2005,"To invoice")+SUMIFS(Timesheet!$O$6:$O$2005,Timesheet!$C$6:$C$2005,G16,Timesheet!$Q$6:$Q$2005,"Draft")) | J16: =IF(O16="","",SUMIFS(Invoices!$J$6:$J$305,Invoices!$C$6:$C$305,G16,Invoices!$M$6:$M$305,"Waiting")+SUMIFS(Invoices!$J$6:$J$305,Invoices!$C$6:$C$305,G16,Invoices!$M$6:$M$305,"Overdue*")) | O16: =IFERROR(SMALL(Clients!$J$6:$J$45,8),"")
B19: Month | C19: Hours | D19: Worth | E19: Paid in | G19: Not paid yet | H19: Client | I19: Total | J19: Status
B20: =CHOOSE(MONTH(DATE(YEAR(TODAY()),MONTH(TODAY())-5,1)),"Jan","Feb","Mar","Apr","May","Jun","Jul","Aug","Sep","Oct","Nov","Dec")&" "&YEAR(DATE(YEAR(TODAY()),MONTH(TODAY())-5,1)) | C20: =SUMIFS(Timesheet!$M$6:$M$2005,Timesheet!$B$6:$B$2005,">="&DATE(YEAR(TODAY()),MONTH(TODAY())-5,1),Timesheet!$B$6:$B$2005,"<="&EOMONTH(DATE(YEAR(TODAY()),MONTH(TODAY())-5,1),0)) | D20: =SUMIFS(Timesheet!$O$6:$O$2005,Timesheet!$B$6:$B$2005,">="&DATE(YEAR(TODAY()),MONTH(TODAY())-5,1),Timesheet!$B$6:$B$2005,"<="&EOMONTH(DATE(YEAR(TODAY()),MONTH(TODAY())-5,1),0)) | E20: =SUMIFS(Invoices!$J$6:$J$305,Invoices!$L$6:$L$305,">="&DATE(YEAR(TODAY()),MONTH(TODAY())-5,1),Invoices!$L$6:$L$305,"<="&EOMONTH(DATE(YEAR(TODAY()),MONTH(TODAY())-5,1),0)) | G20: =IF(P20="","Every invoice is paid",INDEX(Invoices!$B$6:$B$305,MATCH(P20,Invoices!$P$6:$P$305,0))) | H20: =IF(P20="","",INDEX(Invoices!$C$6:$C$305,MATCH(P20,Invoices!$P$6:$P$305,0))) | I20: =IF(P20="","",INDEX(Invoices!$J$6:$J$305,MATCH(P20,Invoices!$P$6:$P$305,0))) | J20: =IF(P20="","",IF(INDEX(Invoices!$M$6:$M$305,MATCH(P20,Invoices!$P$6:$P$305,0))="Waiting","Due "&DAY(INT(P20))&" "&CHOOSE(MONTH(INT(P20)),"Jan","Feb","Mar","Apr","May","Jun","Jul","Aug","Sep","Oct","Nov","Dec"),INDEX(Invoices!$M$6:$M$305,MATCH(P20,Invoices!$P$6:$P$305,0)))) | P20: =IFERROR(SMALL(Invoices!$P$6:$P$305,1),"")
B21: =CHOOSE(MONTH(DATE(YEAR(TODAY()),MONTH(TODAY())-4,1)),"Jan","Feb","Mar","Apr","May","Jun","Jul","Aug","Sep","Oct","Nov","Dec")&" "&YEAR(DATE(YEAR(TODAY()),MONTH(TODAY())-4,1)) | C21: =SUMIFS(Timesheet!$M$6:$M$2005,Timesheet!$B$6:$B$2005,">="&DATE(YEAR(TODAY()),MONTH(TODAY())-4,1),Timesheet!$B$6:$B$2005,"<="&EOMONTH(DATE(YEAR(TODAY()),MONTH(TODAY())-4,1),0)) | D21: =SUMIFS(Timesheet!$O$6:$O$2005,Timesheet!$B$6:$B$2005,">="&DATE(YEAR(TODAY()),MONTH(TODAY())-4,1),Timesheet!$B$6:$B$2005,"<="&EOMONTH(DATE(YEAR(TODAY()),MONTH(TODAY())-4,1),0)) | E21: =SUMIFS(Invoices!$J$6:$J$305,Invoices!$L$6:$L$305,">="&DATE(YEAR(TODAY()),MONTH(TODAY())-4,1),Invoices!$L$6:$L$305,"<="&EOMONTH(DATE(YEAR(TODAY()),MONTH(TODAY())-4,1),0)) | G21: =IF(P21="","",INDEX(Invoices!$B$6:$B$305,MATCH(P21,Invoices!$P$6:$P$305,0))) | H21: =IF(P21="","",INDEX(Invoices!$C$6:$C$305,MATCH(P21,Invoices!$P$6:$P$305,0))) | I21: =IF(P21="","",INDEX(Invoices!$J$6:$J$305,MATCH(P21,Invoices!$P$6:$P$305,0))) | J21: =IF(P21="","",IF(INDEX(Invoices!$M$6:$M$305,MATCH(P21,Invoices!$P$6:$P$305,0))="Waiting","Due "&DAY(INT(P21))&" "&CHOOSE(MONTH(INT(P21)),"Jan","Feb","Mar","Apr","May","Jun","Jul","Aug","Sep","Oct","Nov","Dec"),INDEX(Invoices!$M$6:$M$305,MATCH(P21,Invoices!$P$6:$P$305,0)))) | P21: =IFERROR(SMALL(Invoices!$P$6:$P$305,2),"")
B22: =CHOOSE(MONTH(DATE(YEAR(TODAY()),MONTH(TODAY())-3,1)),"Jan","Feb","Mar","Apr","May","Jun","Jul","Aug","Sep","Oct","Nov","Dec")&" "&YEAR(DATE(YEAR(TODAY()),MONTH(TODAY())-3,1)) | C22: =SUMIFS(Timesheet!$M$6:$M$2005,Timesheet!$B$6:$B$2005,">="&DATE(YEAR(TODAY()),MONTH(TODAY())-3,1),Timesheet!$B$6:$B$2005,"<="&EOMONTH(DATE(YEAR(TODAY()),MONTH(TODAY())-3,1),0)) | D22: =SUMIFS(Timesheet!$O$6:$O$2005,Timesheet!$B$6:$B$2005,">="&DATE(YEAR(TODAY()),MONTH(TODAY())-3,1),Timesheet!$B$6:$B$2005,"<="&EOMONTH(DATE(YEAR(TODAY()),MONTH(TODAY())-3,1),0)) | E22: =SUMIFS(Invoices!$J$6:$J$305,Invoices!$L$6:$L$305,">="&DATE(YEAR(TODAY()),MONTH(TODAY())-3,1),Invoices!$L$6:$L$305,"<="&EOMONTH(DATE(YEAR(TODAY()),MONTH(TODAY())-3,1),0)) | G22: =IF(P22="","",INDEX(Invoices!$B$6:$B$305,MATCH(P22,Invoices!$P$6:$P$305,0))) | H22: =IF(P22="","",INDEX(Invoices!$C$6:$C$305,MATCH(P22,Invoices!$P$6:$P$305,0))) | I22: =IF(P22="","",INDEX(Invoices!$J$6:$J$305,MATCH(P22,Invoices!$P$6:$P$305,0))) | J22: =IF(P22="","",IF(INDEX(Invoices!$M$6:$M$305,MATCH(P22,Invoices!$P$6:$P$305,0))="Waiting","Due "&DAY(INT(P22))&" "&CHOOSE(MONTH(INT(P22)),"Jan","Feb","Mar","Apr","May","Jun","Jul","Aug","Sep","Oct","Nov","Dec"),INDEX(Invoices!$M$6:$M$305,MATCH(P22,Invoices!$P$6:$P$305,0)))) | P22: =IFERROR(SMALL(Invoices!$P$6:$P$305,3),"")
B23: =CHOOSE(MONTH(DATE(YEAR(TODAY()),MONTH(TODAY())-2,1)),"Jan","Feb","Mar","Apr","May","Jun","Jul","Aug","Sep","Oct","Nov","Dec")&" "&YEAR(DATE(YEAR(TODAY()),MONTH(TODAY())-2,1)) | C23: =SUMIFS(Timesheet!$M$6:$M$2005,Timesheet!$B$6:$B$2005,">="&DATE(YEAR(TODAY()),MONTH(TODAY())-2,1),Timesheet!$B$6:$B$2005,"<="&EOMONTH(DATE(YEAR(TODAY()),MONTH(TODAY())-2,1),0)) | D23: =SUMIFS(Timesheet!$O$6:$O$2005,Timesheet!$B$6:$B$2005,">="&DATE(YEAR(TODAY()),MONTH(TODAY())-2,1),Timesheet!$B$6:$B$2005,"<="&EOMONTH(DATE(YEAR(TODAY()),MONTH(TODAY())-2,1),0)) | E23: =SUMIFS(Invoices!$J$6:$J$305,Invoices!$L$6:$L$305,">="&DATE(YEAR(TODAY()),MONTH(TODAY())-2,1),Invoices!$L$6:$L$305,"<="&EOMONTH(DATE(YEAR(TODAY()),MONTH(TODAY())-2,1),0)) | G23: =IF(P23="","",INDEX(Invoices!$B$6:$B$305,MATCH(P23,Invoices!$P$6:$P$305,0))) | H23: =IF(P23="","",INDEX(Invoices!$C$6:$C$305,MATCH(P23,Invoices!$P$6:$P$305,0))) | I23: =IF(P23="","",INDEX(Invoices!$J$6:$J$305,MATCH(P23,Invoices!$P$6:$P$305,0))) | J23: =IF(P23="","",IF(INDEX(Invoices!$M$6:$M$305,MATCH(P23,Invoices!$P$6:$P$305,0))="Waiting","Due "&DAY(INT(P23))&" "&CHOOSE(MONTH(INT(P23)),"Jan","Feb","Mar","Apr","May","Jun","Jul","Aug","Sep","Oct","Nov","Dec"),INDEX(Invoices!$M$6:$M$305,MATCH(P23,Invoices!$P$6:$P$305,0)))) | P23: =IFERROR(SMALL(Invoices!$P$6:$P$305,4),"")
B24: =CHOOSE(MONTH(DATE(YEAR(TODAY()),MONTH(TODAY())-1,1)),"Jan","Feb","Mar","Apr","May","Jun","Jul","Aug","Sep","Oct","Nov","Dec")&" "&YEAR(DATE(YEAR(TODAY()),MONTH(TODAY())-1,1)) | C24: =SUMIFS(Timesheet!$M$6:$M$2005,Timesheet!$B$6:$B$2005,">="&DATE(YEAR(TODAY()),MONTH(TODAY())-1,1),Timesheet!$B$6:$B$2005,"<="&EOMONTH(DATE(YEAR(TODAY()),MONTH(TODAY())-1,1),0)) | D24: =SUMIFS(Timesheet!$O$6:$O$2005,Timesheet!$B$6:$B$2005,">="&DATE(YEAR(TODAY()),MONTH(TODAY())-1,1),Timesheet!$B$6:$B$2005,"<="&EOMONTH(DATE(YEAR(TODAY()),MONTH(TODAY())-1,1),0)) | E24: =SUMIFS(Invoices!$J$6:$J$305,Invoices!$L$6:$L$305,">="&DATE(YEAR(TODAY()),MONTH(TODAY())-1,1),Invoices!$L$6:$L$305,"<="&EOMONTH(DATE(YEAR(TODAY()),MONTH(TODAY())-1,1),0)) | G24: =IF(P24="","",INDEX(Invoices!$B$6:$B$305,MATCH(P24,Invoices!$P$6:$P$305,0))) | H24: =IF(P24="","",INDEX(Invoices!$C$6:$C$305,MATCH(P24,Invoices!$P$6:$P$305,0))) | I24: =IF(P24="","",INDEX(Invoices!$J$6:$J$305,MATCH(P24,Invoices!$P$6:$P$305,0))) | J24: =IF(P24="","",IF(INDEX(Invoices!$M$6:$M$305,MATCH(P24,Invoices!$P$6:$P$305,0))="Waiting","Due "&DAY(INT(P24))&" "&CHOOSE(MONTH(INT(P24)),"Jan","Feb","Mar","Apr","May","Jun","Jul","Aug","Sep","Oct","Nov","Dec"),INDEX(Invoices!$M$6:$M$305,MATCH(P24,Invoices!$P$6:$P$305,0)))) | P24: =IFERROR(SMALL(Invoices!$P$6:$P$305,5),"")
B25: =CHOOSE(MONTH(DATE(YEAR(TODAY()),MONTH(TODAY())-0,1)),"Jan","Feb","Mar","Apr","May","Jun","Jul","Aug","Sep","Oct","Nov","Dec")&" "&YEAR(DATE(YEAR(TODAY()),MONTH(TODAY())-0,1)) | C25: =SUMIFS(Timesheet!$M$6:$M$2005,Timesheet!$B$6:$B$2005,">="&DATE(YEAR(TODAY()),MONTH(TODAY())-0,1),Timesheet!$B$6:$B$2005,"<="&EOMONTH(DATE(YEAR(TODAY()),MONTH(TODAY())-0,1),0)) | D25: =SUMIFS(Timesheet!$O$6:$O$2005,Timesheet!$B$6:$B$2005,">="&DATE(YEAR(TODAY()),MONTH(TODAY())-0,1),Timesheet!$B$6:$B$2005,"<="&EOMONTH(DATE(YEAR(TODAY()),MONTH(TODAY())-0,1),0)) | E25: =SUMIFS(Invoices!$J$6:$J$305,Invoices!$L$6:$L$305,">="&DATE(YEAR(TODAY()),MONTH(TODAY())-0,1),Invoices!$L$6:$L$305,"<="&EOMONTH(DATE(YEAR(TODAY()),MONTH(TODAY())-0,1),0)) | G25: =IF(P25="","",INDEX(Invoices!$B$6:$B$305,MATCH(P25,Invoices!$P$6:$P$305,0))) | H25: =IF(P25="","",INDEX(Invoices!$C$6:$C$305,MATCH(P25,Invoices!$P$6:$P$305,0))) | I25: =IF(P25="","",INDEX(Invoices!$J$6:$J$305,MATCH(P25,Invoices!$P$6:$P$305,0))) | J25: =IF(P25="","",IF(INDEX(Invoices!$M$6:$M$305,MATCH(P25,Invoices!$P$6:$P$305,0))="Waiting","Due "&DAY(INT(P25))&" "&CHOOSE(MONTH(INT(P25)),"Jan","Feb","Mar","Apr","May","Jun","Jul","Aug","Sep","Oct","Nov","Dec"),INDEX(Invoices!$M$6:$M$305,MATCH(P25,Invoices!$P$6:$P$305,0)))) | P25: =IFERROR(SMALL(Invoices!$P$6:$P$305,6),"")
G26: =IF(P26="","",INDEX(Invoices!$B$6:$B$305,MATCH(P26,Invoices!$P$6:$P$305,0))) | H26: =IF(P26="","",INDEX(Invoices!$C$6:$C$305,MATCH(P26,Invoices!$P$6:$P$305,0))) | I26: =IF(P26="","",INDEX(Invoices!$J$6:$J$305,MATCH(P26,Invoices!$P$6:$P$305,0))) | J26: =IF(P26="","",IF(INDEX(Invoices!$M$6:$M$305,MATCH(P26,Invoices!$P$6:$P$305,0))="Waiting","Due "&DAY(INT(P26))&" "&CHOOSE(MONTH(INT(P26)),"Jan","Feb","Mar","Apr","May","Jun","Jul","Aug","Sep","Oct","Nov","Dec"),INDEX(Invoices!$M$6:$M$305,MATCH(P26,Invoices!$P$6:$P$305,0)))) | P26: =IFERROR(SMALL(Invoices!$P$6:$P$305,7),"")
G27: =IF(P27="","",INDEX(Invoices!$B$6:$B$305,MATCH(P27,Invoices!$P$6:$P$305,0))) | H27: =IF(P27="","",INDEX(Invoices!$C$6:$C$305,MATCH(P27,Invoices!$P$6:$P$305,0))) | I27: =IF(P27="","",INDEX(Invoices!$J$6:$J$305,MATCH(P27,Invoices!$P$6:$P$305,0))) | J27: =IF(P27="","",IF(INDEX(Invoices!$M$6:$M$305,MATCH(P27,Invoices!$P$6:$P$305,0))="Waiting","Due "&DAY(INT(P27))&" "&CHOOSE(MONTH(INT(P27)),"Jan","Feb","Mar","Apr","May","Jun","Jul","Aug","Sep","Oct","Nov","Dec"),INDEX(Invoices!$M$6:$M$305,MATCH(P27,Invoices!$P$6:$P$305,0)))) | P27: =IFERROR(SMALL(Invoices!$P$6:$P$305,8),"")

Sheet Timesheet
B2: Timesheet
B3: One line per piece of work: start and end times, or the hours typed in. Each line goes on the invoice for its client and dates by itself.
B5: Date | C5: Client | D5: Project | E5: What | F5: Start | G5: End | H5: Break (min) | I5: Hours typed | J5: Not billable | K5: Own rate | L5: Put on invoice | M5: Hours | N5: Rate | O5: Amount | P5: Invoice | Q5: Status
B6: 46113 | C6: Harbour Books | D6: Spring catalogue | E6: Cover design | F6: 0.39583333 | G6: 0.55208333 | H6: 15 | M6: =IF(B6="","",IF(AND(F6<>"",G6<>""),MAX(0,ROUND(MOD(G6-F6,1)*24-N(H6)/60,2)),N(I6))) | N6: =IF(B6="","",IF(K6<>"",K6,IF(N(IFERROR(INDEX(Projects!$D$6:$D$65,MATCH(D6,Projects!$B$6:$B$65,0)),""))>0,IFERROR(INDEX(Projects!$D$6:$D$65,MATCH(D6,Projects!$B$6:$B$65,0)),""),IFERROR(INDEX(Clients!$G$6:$G$45,MATCH(C6,Clients!$B$6:$B$45,0)),0)))) | O6: =IF(B6="","",IF(J6<>"",0,ROUND(M6*N6,2))) | P6: =IF(OR(B6="",J6<>""),"",IF(L6<>"",L6,IF(COUNTIFS(Invoices!$C$6:$C$305,C6,Invoices!$E$6:$E$305,"<="&B6,Invoices!$F$6:$F$305,">="&B6)=1,INDEX(Invoices!$B$6:$B$305,SUMIFS(Invoices!$O$6:$O$305,Invoices!$C$6:$C$305,C6,Invoices!$E$6:$E$305,"<="&B6,Invoices!$F$6:$F$305,">="&B6)),IF(COUNTIFS(Invoices!$C$6:$C$305,C6,Invoices!$E$6:$E$305,"<="&B6,Invoices!$F$6:$F$305,">="&B6)>1,"Two invoices","")))) | Q6: =IF(B6="","",IF(J6<>"","Not billable",IF(P6="","To invoice",IF(P6="Two invoices","Check dates",IF(ISNA(MATCH(P6,Invoices!$B$6:$B$305,0)),"Check number",IF(INDEX(Invoices!$M$6:$M$305,MATCH(P6,Invoices!$B$6:$B$305,0))="Paid","Paid",IF(INDEX(Invoices!$M$6:$M$305,MATCH(P6,Invoices!$B$6:$B$305,0))="Draft","Draft","Invoiced"))))))) | R6: =IF(AND(B6<>"",P6<>"",P6=Invoice!$G$4),B6+MOD(N(F6),1)+ROW()/10000000,"") | S6: =IF(R6="","",IF(D6="","Other work",D6)&IF(AND(K6<>"",E6<>""),", "&E6,"")) | T6: =IF(R6="","",R6) | U6: =IF(B6="","",IF(J6<>"",0,M6))
B7: 46114 | C7: Harbour Books | D7: Spring catalogue | E7: Cover design | I7: 2.5 | M7: =IF(B7="","",IF(AND(F7<>"",G7<>""),MAX(0,ROUND(MOD(G7-F7,1)*24-N(H7)/60,2)),N(I7))) | N7: =IF(B7="","",IF(K7<>"",K7,IF(N(IFERROR(INDEX(Projects!$D$6:$D$65,MATCH(D7,Projects!$B$6:$B$65,0)),""))>0,IFERROR(INDEX(Projects!$D$6:$D$65,MATCH(D7,Projects!$B$6:$B$65,0)),""),IFERROR(INDEX(Clients!$G$6:$G$45,MATCH(C7,Clients!$B$6:$B$45,0)),0)))) | O7: =IF(B7="","",IF(J7<>"",0,ROUND(M7*N7,2))) | P7: =IF(OR(B7="",J7<>""),"",IF(L7<>"",L7,IF(COUNTIFS(Invoices!$C$6:$C$305,C7,Invoices!$E$6:$E$305,"<="&B7,Invoices!$F$6:$F$305,">="&B7)=1,INDEX(Invoices!$B$6:$B$305,SUMIFS(Invoices!$O$6:$O$305,Invoices!$C$6:$C$305,C7,Invoices!$E$6:$E$305,"<="&B7,Invoices!$F$6:$F$305,">="&B7)),IF(COUNTIFS(Invoices!$C$6:$C$305,C7,Invoices!$E$6:$E$305,"<="&B7,Invoices!$F$6:$F$305,">="&B7)>1,"Two invoices","")))) | Q7: =IF(B7="","",IF(J7<>"","Not billable",IF(P7="","To invoice",IF(P7="Two invoices","Check dates",IF(ISNA(MATCH(P7,Invoices!$B$6:$B$305,0)),"Check number",IF(INDEX(Invoices!$M$6:$M$305,MATCH(P7,Invoices!$B$6:$B$305,0))="Paid","Paid",IF(INDEX(Invoices!$M$6:$M$305,MATCH(P7,Invoices!$B$6:$B$305,0))="Draft","Draft","Invoiced"))))))) | R7: =IF(AND(B7<>"",P7<>"",P7=Invoice!$G$4),B7+MOD(N(F7),1)+ROW()/10000000,"") | S7: =IF(R7="","",IF(D7="","Other work",D7)&IF(AND(K7<>"",E7<>""),", "&E7,"")) | T7: =IF(R7="","",IF(COUNTIFS(R$6:R6,">0",S$6:S6,S7,N$6:N6,N7)=0,R7,"")) | U7: =IF(B7="","",IF(J7<>"",0,M7))
B8: 46115 | C8: Greenleaf Studio | D8: Monthly social posts | E8: Captions and scheduling | F8: 0.375 | G8: 0.51041667 | H8: 15 | M8: =IF(B8="","",IF(AND(F8<>"",G8<>""),MAX(0,ROUND(MOD(G8-F8,1)*24-N(H8)/60,2)),N(I8))) | N8: =IF(B8="","",IF(K8<>"",K8,IF(N(IFERROR(INDEX(Projects!$D$6:$D$65,MATCH(D8,Projects!$B$6:$B$65,0)),""))>0,IFERROR(INDEX(Projects!$D$6:$D$65,MATCH(D8,Projects!$B$6:$B$65,0)),""),IFERROR(INDEX(Clients!$G$6:$G$45,MATCH(C8,Clients!$B$6:$B$45,0)),0)))) | O8: =IF(B8="","",IF(J8<>"",0,ROUND(M8*N8,2))) | P8: =IF(OR(B8="",J8<>""),"",IF(L8<>"",L8,IF(COUNTIFS(Invoices!$C$6:$C$305,C8,Invoices!$E$6:$E$305,"<="&B8,Invoices!$F$6:$F$305,">="&B8)=1,INDEX(Invoices!$B$6:$B$305,SUMIFS(Invoices!$O$6:$O$305,Invoices!$C$6:$C$305,C8,Invoices!$E$6:$E$305,"<="&B8,Invoices!$F$6:$F$305,">="&B8)),IF(COUNTIFS(Invoices!$C$6:$C$305,C8,Invoices!$E$6:$E$305,"<="&B8,Invoices!$F$6:$F$305,">="&B8)>1,"Two invoices","")))) | Q8: =IF(B8="","",IF(J8<>"","Not billable",IF(P8="","To invoice",IF(P8="Two invoices","Check dates",IF(ISNA(MATCH(P8,Invoices!$B$6:$B$305,0)),"Check number",IF(INDEX(Invoices!$M$6:$M$305,MATCH(P8,Invoices!$B$6:$B$305,0))="Paid","Paid",IF(INDEX(Invoices!$M$6:$M$305,MATCH(P8,Invoices!$B$6:$B$305,0))="Draft","Draft","Invoiced"))))))) | R8: =IF(AND(B8<>"",P8<>"",P8=Invoice!$G$4),B8+MOD(N(F8),1)+ROW()/10000000,"") | S8: =IF(R8="","",IF(D8="","Other work",D8)&IF(AND(K8<>"",E8<>""),", "&E8,"")) | T8: =IF(R8="","",IF(COUNTIFS(R$6:R7,">0",S$6:S7,S8,N$6:N7,N8)=0,R8,"")) | U8: =IF(B8="","",IF(J8<>"",0,M8))
B9: 46115 | C9: Harbour Books | D9: Spring catalogue | E9: Product pages | F9: 0.52083333 | G9: 0.625 | M9: =IF(B9="","",IF(AND(F9<>"",G9<>""),MAX(0,ROUND(MOD(G9-F9,1)*24-N(H9)/60,2)),N(I9))) | N9: =IF(B9="","",IF(K9<>"",K9,IF(N(IFERROR(INDEX(Projects!$D$6:$D$65,MATCH(D9,Projects!$B$6:$B$65,0)),""))>0,IFERROR(INDEX(Projects!$D$6:$D$65,MATCH(D9,Projects!$B$6:$B$65,0)),""),IFERROR(INDEX(Clients!$G$6:$G$45,MATCH(C9,Clients!$B$6:$B$45,0)),0)))) | O9: =IF(B9="","",IF(J9<>"",0,ROUND(M9*N9,2))) | P9: =IF(OR(B9="",J9<>""),"",IF(L9<>"",L9,IF(COUNTIFS(Invoices!$C$6:$C$305,C9,Invoices!$E$6:$E$305,"<="&B9,Invoices!$F$6:$F$305,">="&B9)=1,INDEX(Invoices!$B$6:$B$305,SUMIFS(Invoices!$O$6:$O$305,Invoices!$C$6:$C$305,C9,Invoices!$E$6:$E$305,"<="&B9,Invoices!$F$6:$F$305,">="&B9)),IF(COUNTIFS(Invoices!$C$6:$C$305,C9,Invoices!$E$6:$E$305,"<="&B9,Invoices!$F$6:$F$305,">="&B9)>1,"Two invoices","")))) | Q9: =IF(B9="","",IF(J9<>"","Not billable",IF(P9="","To invoice",IF(P9="Two invoices","Check dates",IF(ISNA(MATCH(P9,Invoices!$B$6:$B$305,0)),"Check number",IF(INDEX(Invoices!$M$6:$M$305,MATCH(P9,Invoices!$B$6:$B$305,0))="Paid","Paid",IF(INDEX(Invoices!$M$6:$M$305,MATCH(P9,Invoices!$B$6:$B$305,0))="Draft","Draft","Invoiced"))))))) | R9: =IF(AND(B9<>"",P9<>"",P9=Invoice!$G$4),B9+MOD(N(F9),1)+ROW()/10000000,"") | S9: =IF(R9="","",IF(D9="","Other work",D9)&IF(AND(K9<>"",E9<>""),", "&E9,"")) | T9: =IF(R9="","",IF(COUNTIFS(R$6:R8,">0",S$6:S8,S9,N$6:N8,N9)=0,R9,"")) | U9: =IF(B9="","",IF(J9<>"",0,M9))
B10: 46115 | C10: Harbour Books | D10: Spring catalogue | E10: Catalogue layout | F10: 0.63541667 | G10: 0.76041667 | M10: =IF(B10="","",IF(AND(F10<>"",G10<>""),MAX(0,ROUND(MOD(G10-F10,1)*24-N(H10)/60,2)),N(I10))) | N10: =IF(B10="","",IF(K10<>"",K10,IF(N(IFERROR(INDEX(Projects!$D$6:$D$65,MATCH(D10,Projects!$B$6:$B$65,0)),""))>0,IFERROR(INDEX(Projects!$D$6:$D$65,MATCH(D10,Projects!$B$6:$B$65,0)),""),IFERROR(INDEX(Clients!$G$6:$G$45,MATCH(C10,Clients!$B$6:$B$45,0)),0)))) | O10: =IF(B10="","",IF(J10<>"",0,ROUND(M10*N10,2))) | P10: =IF(OR(B10="",J10<>""),"",IF(L10<>"",L10,IF(COUNTIFS(Invoices!$C$6:$C$305,C10,Invoices!$E$6:$E$305,"<="&B10,Invoices!$F$6:$F$305,">="&B10)=1,INDEX(Invoices!$B$6:$B$305,SUMIFS(Invoices!$O$6:$O$305,Invoices!$C$6:$C$305,C10,Invoices!$E$6:$E$305,"<="&B10,Invoices!$F$6:$F$305,">="&B10)),IF(COUNTIFS(Invoices!$C$6:$C$305,C10,Invoices!$E$6:$E$305,"<="&B10,Invoices!$F$6:$F$305,">="&B10)>1,"Two invoices","")))) | Q10: =IF(B10="","",IF(J10<>"","Not billable",IF(P10="","To invoice",IF(P10="Two invoices","Check dates",IF(ISNA(MATCH(P10,Invoices!$B$6:$B$305,0)),"Check number",IF(INDEX(Invoices!$M$6:$M$305,MATCH(P10,Invoices!$B$6:$B$305,0))="Paid","Paid",IF(INDEX(Invoices!$M$6:$M$305,MATCH(P10,Invoices!$B$6:$B$305,0))="Draft","Draft","Invoiced"))))))) | R10: =IF(AND(B10<>"",P10<>"",P10=Invoice!$G$4),B10+MOD(N(F10),1)+ROW()/10000000,"") | S10: =IF(R10="","",IF(D10="","Other work",D10)&IF(AND(K10<>"",E10<>""),", "&E10,"")) | T10: =IF(R10="","",IF(COUNTIFS(R$6:R9,">0",S$6:S9,S10,N$6:N9,N10)=0,R10,"")) | U10: =IF(B10="","",IF(J10<>"",0,M10))
B11: 46118 | C11: Harbour Books | D11: Spring catalogue | E11: Cover design | F11: 0.39583333 | G11: 0.4375 | M11: =IF(B11="","",IF(AND(F11<>"",G11<>""),MAX(0,ROUND(MOD(G11-F11,1)*24-N(H11)/60,2)),N(I11))) | N11: =IF(B11="","",IF(K11<>"",K11,IF(N(IFERROR(INDEX(Projects!$D$6:$D$65,MATCH(D11,Projects!$B$6:$B$65,0)),""))>0,IFERROR(INDEX(Projects!$D$6:$D$65,MATCH(D11,Projects!$B$6:$B$65,0)),""),IFERROR(INDEX(Clients!$G$6:$G$45,MATCH(C11,Clients!$B$6:$B$45,0)),0)))) | O11: =IF(B11="","",IF(J11<>"",0,ROUND(M11*N11,2))) | P11: =IF(OR(B11="",J11<>""),"",IF(L11<>"",L11,IF(COUNTIFS(Invoices!$C$6:$C$305,C11,Invoices!$E$6:$E$305,"<="&B11,Invoices!$F$6:$F$305,">="&B11)=1,INDEX(Invoices!$B$6:$B$305,SUMIFS(Invoices!$O$6:$O$305,Invoices!$C$6:$C$305,C11,Invoices!$E$6:$E$305,"<="&B11,Invoices!$F$6:$F$305,">="&B11)),IF(COUNTIFS(Invoices!$C$6:$C$305,C11,Invoices!$E$6:$E$305,"<="&B11,Invoices!$F$6:$F$305,">="&B11)>1,"Two invoices","")))) | Q11: =IF(B11="","",IF(J11<>"","Not billable",IF(P11="","To invoice",IF(P11="Two invoices","Check dates",IF(ISNA(MATCH(P11,Invoices!$B$6:$B$305,0)),"Check number",IF(INDEX(Invoices!$M$6:$M$305,MATCH(P11,Invoices!$B$6:$B$305,0))="Paid","Paid",IF(INDEX(Invoices!$M$6:$M$305,MATCH(P11,Invoices!$B$6:$B$305,0))="Draft","Draft","Invoiced"))))))) | R11: =IF(AND(B11<>"",P11<>"",P11=Invoice!$G$4),B11+MOD(N(F11),1)+ROW()/10000000,"") | S11: =IF(R11="","",IF(D11="","Other work",D11)&IF(AND(K11<>"",E11<>""),", "&E11,"")) | T11: =IF(R11="","",IF(COUNTIFS(R$6:R10,">0",S$6:S10,S11,N$6:N10,N11)=0,R11,"")) | U11: =IF(B11="","",IF(J11<>"",0,M11))
B12: 46118 | C12: Harbour Books | D12: Spring catalogue | E12: Proof corrections | F12: 0.46875 | G12: 0.51041667 | M12: =IF(B12="","",IF(AND(F12<>"",G12<>""),MAX(0,ROUND(MOD(G12-F12,1)*24-N(H12)/60,2)),N(I12))) | N12: =IF(B12="","",IF(K12<>"",K12,IF(N(IFERROR(INDEX(Projects!$D$6:$D$65,MATCH(D12,Projects!$B$6:$B$65,0)),""))>0,IFERROR(INDEX(Projects!$D$6:$D$65,MATCH(D12,Projects!$B$6:$B$65,0)),""),IFERROR(INDEX(Clients!$G$6:$G$45,MATCH(C12,Clients!$B$6:$B$45,0)),0)))) | O12: =IF(B12="","",IF(J12<>"",0,ROUND(M12*N12,2))) | P12: =IF(OR(B12="",J12<>""),"",IF(L12<>"",L12,IF(COUNTIFS(Invoices!$C$6:$C$305,C12,Invoices!$E$6:$E$305,"<="&B12,Invoices!$F$6:$F$305,">="&B12)=1,INDEX(Invoices!$B$6:$B$305,SUMIFS(Invoices!$O$6:$O$305,Invoices!$C$6:$C$305,C12,Invoices!$E$6:$E$305,"<="&B12,Invoices!$F$6:$F$305,">="&B12)),IF(COUNTIFS(Invoices!$C$6:$C$305,C12,Invoices!$E$6:$E$305,"<="&B12,Invoices!$F$6:$F$305,">="&B12)>1,"Two invoices","")))) | Q12: =IF(B12="","",IF(J12<>"","Not billable",IF(P12="","To invoice",IF(P12="Two invoices","Check dates",IF(ISNA(MATCH(P12,Invoices!$B$6:$B$305,0)),"Check number",IF(INDEX(Invoices!$M$6:$M$305,MATCH(P12,Invoices!$B$6:$B$305,0))="Paid","Paid",IF(INDEX(Invoices!$M$6:$M$305,MATCH(P12,Invoices!$B$6:$B$305,0))="Draft","Draft","Invoiced"))))))) | R12: =IF(AND(B12<>"",P12<>"",P12=Invoice!$G$4),B12+MOD(N(F12),1)+ROW()/10000000,"") | S12: =IF(R12="","",IF(D12="","Other work",D12)&IF(AND(K12<>"",E12<>""),", "&E12,"")) | T12: =IF(R12="","",IF(COUNTIFS(R$6:R11,">0",S$6:S11,S12,N$6:N11,N12)=0,R12,"")) | U12: =IF(B12="","",IF(J12<>"",0,M12))
B13: 46119 | C13: Harbour Books | D13: Spring catalogue | E13: Proof corrections | F13: 0.375 | G13: 0.45833333 | M13: =IF(B13="","",IF(AND(F13<>"",G13<>""),MAX(0,ROUND(MOD(G13-F13,1)*24-N(H13)/60,2)),N(I13))) | N13: =IF(B13="","",IF(K13<>"",K13,IF(N(IFERROR(INDEX(Projects!$D$6:$D$65,MATCH(D13,Projects!$B$6:$B$65,0)),""))>0,IFERROR(INDEX(Projects!$D$6:$D$65,MATCH(D13,Projects!$B$6:$B$65,0)),""),IFERROR(INDEX(Clients!$G$6:$G$45,MATCH(C13,Clients!$B$6:$B$45,0)),0)))) | O13: =IF(B13="","",IF(J13<>"",0,ROUND(M13*N13,2))) | P13: =IF(OR(B13="",J13<>""),"",IF(L13<>"",L13,IF(COUNTIFS(Invoices!$C$6:$C$305,C13,Invoices!$E$6:$E$305,"<="&B13,Invoices!$F$6:$F$305,">="&B13)=1,INDEX(Invoices!$B$6:$B$305,SUMIFS(Invoices!$O$6:$O$305,Invoices!$C$6:$C$305,C13,Invoices!$E$6:$E$305,"<="&B13,Invoices!$F$6:$F$305,">="&B13)),IF(COUNTIFS(Invoices!$C$6:$C$305,C13,Invoices!$E$6:$E$305,"<="&B13,Invoices!$F$6:$F$305,">="&B13)>1,"Two invoices","")))) | Q13: =IF(B13="","",IF(J13<>"","Not billable",IF(P13="","To invoice",IF(P13="Two invoices","Check dates",IF(ISNA(MATCH(P13,Invoices!$B$6:$B$305,0)),"Check number",IF(INDEX(Invoices!$M$6:$M$305,MATCH(P13,Invoices!$B$6:$B$305,0))="Paid","Paid",IF(INDEX(Invoices!$M$6:$M$305,MATCH(P13,Invoices!$B$6:$B$305,0))="Draft","Draft","Invoiced"))))))) | R13: =IF(AND(B13<>"",P13<>"",P13=Invoice!$G$4),B13+MOD(N(F13),1)+ROW()/10000000,"") | S13: =IF(R13="","",IF(D13="","Other work",D13)&IF(AND(K13<>"",E13<>""),", "&E13,"")) | T13: =IF(R13="","",IF(COUNTIFS(R$6:R12,">0",S$6:S12,S13,N$6:N12,N13)=0,R13,"")) | U13: =IF(B13="","",IF(J13<>"",0,M13))
B14: 46119 | C14: Harbour Books | D14: Spring catalogue | E14: Catalogue layout | F14: 0.48958333 | G14: 0.53125 | M14: =IF(B14="","",IF(AND(F14<>"",G14<>""),MAX(0,ROUND(MOD(G14-F14,1)*24-N(H14)/60,2)),N(I14))) | N14: =IF(B14="","",IF(K14<>"",K14,IF(N(IFERROR(INDEX(Projects!$D$6:$D$65,MATCH(D14,Projects!$B$6:$B$65,0)),""))>0,IFERROR(INDEX(Projects!$D$6:$D$65,MATCH(D14,Projects!$B$6:$B$65,0)),""),IFERROR(INDEX(Clients!$G$6:$G$45,MATCH(C14,Clients!$B$6:$B$45,0)),0)))) | O14: =IF(B14="","",IF(J14<>"",0,ROUND(M14*N14,2))) | P14: =IF(OR(B14="",J14<>""),"",IF(L14<>"",L14,IF(COUNTIFS(Invoices!$C$6:$C$305,C14,Invoices!$E$6:$E$305,"<="&B14,Invoices!$F$6:$F$305,">="&B14)=1,INDEX(Invoices!$B$6:$B$305,SUMIFS(Invoices!$O$6:$O$305,Invoices!$C$6:$C$305,C14,Invoices!$E$6:$E$305,"<="&B14,Invoices!$F$6:$F$305,">="&B14)),IF(COUNTIFS(Invoices!$C$6:$C$305,C14,Invoices!$E$6:$E$305,"<="&B14,Invoices!$F$6:$F$305,">="&B14)>1,"Two invoices","")))) | Q14: =IF(B14="","",IF(J14<>"","Not billable",IF(P14="","To invoice",IF(P14="Two invoices","Check dates",IF(ISNA(MATCH(P14,Invoices!$B$6:$B$305,0)),"Check number",IF(INDEX(Invoices!$M$6:$M$305,MATCH(P14,Invoices!$B$6:$B$305,0))="Paid","Paid",IF(INDEX(Invoices!$M$6:$M$305,MATCH(P14,Invoices!$B$6:$B$305,0))="Draft","Draft","Invoiced"))))))) | R14: =IF(AND(B14<>"",P14<>"",P14=Invoice!$G$4),B14+MOD(N(F14),1)+ROW()/10000000,"") | S14: =IF(R14="","",IF(D14="","Other work",D14)&IF(AND(K14<>"",E14<>""),", "&E14,"")) | T14: =IF(R14="","",IF(COUNTIFS(R$6:R13,">0",S$6:S13,S14,N$6:N13,N14)=0,R14,"")) | U14: =IF(B14="","",IF(J14<>"",0,M14))
B15: 46120 | C15: Harbour Books | D15: Spring catalogue | E15: Product pages | F15: 0.39583333 | G15: 0.47916667 | M15: =IF(B15="","",IF(AND(F15<>"",G15<>""),MAX(0,ROUND(MOD(G15-F15,1)*24-N(H15)/60,2)),N(I15))) | N15: =IF(B15="","",IF(K15<>"",K15,IF(N(IFERROR(INDEX(Projects!$D$6:$D$65,MATCH(D15,Projects!$B$6:$B$65,0)),""))>0,IFERROR(INDEX(Projects!$D$6:$D$65,MATCH(D15,Projects!$B$6:$B$65,0)),""),IFERROR(INDEX(Clients!$G$6:$G$45,MATCH(C15,Clients!$B$6:$B$45,0)),0)))) | O15: =IF(B15="","",IF(J15<>"",0,ROUND(M15*N15,2))) | P15: =IF(OR(B15="",J15<>""),"",IF(L15<>"",L15,IF(COUNTIFS(Invoices!$C$6:$C$305,C15,Invoices!$E$6:$E$305,"<="&B15,Invoices!$F$6:$F$305,">="&B15)=1,INDEX(Invoices!$B$6:$B$305,SUMIFS(Invoices!$O$6:$O$305,Invoices!$C$6:$C$305,C15,Invoices!$E$6:$E$305,"<="&B15,Invoices!$F$6:$F$305,">="&B15)),IF(COUNTIFS(Invoices!$C$6:$C$305,C15,Invoices!$E$6:$E$305,"<="&B15,Invoices!$F$6:$F$305,">="&B15)>1,"Two invoices","")))) | Q15: =IF(B15="","",IF(J15<>"","Not billable",IF(P15="","To invoice",IF(P15="Two invoices","Check dates",IF(ISNA(MATCH(P15,Invoices!$B$6:$B$305,0)),"Check number",IF(INDEX(Invoices!$M$6:$M$305,MATCH(P15,Invoices!$B$6:$B$305,0))="Paid","Paid",IF(INDEX(Invoices!$M$6:$M$305,MATCH(P15,Invoices!$B$6:$B$305,0))="Draft","Draft","Invoiced"))))))) | R15: =IF(AND(B15<>"",P15<>"",P15=Invoice!$G$4),B15+MOD(N(F15),1)+ROW()/10000000,"") | S15: =IF(R15="","",IF(D15="","Other work",D15)&IF(AND(K15<>"",E15<>""),", "&E15,"")) | T15: =IF(R15="","",IF(COUNTIFS(R$6:R14,">0",S$6:S14,S15,N$6:N14,N15)=0,R15,"")) | U15: =IF(B15="","",IF(J15<>"",0,M15))
B16: 46120 | C16: Harbour Books | D16: Spring catalogue | E16: Cover design | F16: 0.5 | G16: 0.64583333 | M16: =IF(B16="","",IF(AND(F16<>"",G16<>""),MAX(0,ROUND(MOD(G16-F16,1)*24-N(H16)/60,2)),N(I16))) | N16: =IF(B16="","",IF(K16<>"",K16,IF(N(IFERROR(INDEX(Projects!$D$6:$D$65,MATCH(D16,Projects!$B$6:$B$65,0)),""))>0,IFERROR(INDEX(Projects!$D$6:$D$65,MATCH(D16,Projects!$B$6:$B$65,0)),""),IFERROR(INDEX(Clients!$G$6:$G$45,MATCH(C16,Clients!$B$6:$B$45,0)),0)))) | O16: =IF(B16="","",IF(J16<>"",0,ROUND(M16*N16,2))) | P16: =IF(OR(B16="",J16<>""),"",IF(L16<>"",L16,IF(COUNTIFS(Invoices!$C$6:$C$305,C16,Invoices!$E$6:$E$305,"<="&B16,Invoices!$F$6:$F$305,">="&B16)=1,INDEX(Invoices!$B$6:$B$305,SUMIFS(Invoices!$O$6:$O$305,Invoices!$C$6:$C$305,C16,Invoices!$E$6:$E$305,"<="&B16,Invoices!$F$6:$F$305,">="&B16)),IF(COUNTIFS(Invoices!$C$6:$C$305,C16,Invoices!$E$6:$E$305,"<="&B16,Invoices!$F$6:$F$305,">="&B16)>1,"Two invoices","")))) | Q16: =IF(B16="","",IF(J16<>"","Not billable",IF(P16="","To invoice",IF(P16="Two invoices","Check dates",IF(ISNA(MATCH(P16,Invoices!$B$6:$B$305,0)),"Check number",IF(INDEX(Invoices!$M$6:$M$305,MATCH(P16,Invoices!$B$6:$B$305,0))="Paid","Paid",IF(INDEX(Invoices!$M$6:$M$305,MATCH(P16,Invoices!$B$6:$B$305,0))="Draft","Draft","Invoiced"))))))) | R16: =IF(AND(B16<>"",P16<>"",P16=Invoice!$G$4),B16+MOD(N(F16),1)+ROW()/10000000,"") | S16: =IF(R16="","",IF(D16="","Other work",D16)&IF(AND(K16<>"",E16<>""),", "&E16,"")) | T16: =IF(R16="","",IF(COUNTIFS(R$6:R15,">0",S$6:S15,S16,N$6:N15,N16)=0,R16,"")) | U16: =IF(B16="","",IF(J16<>"",0,M16))
B17: 46120 | C17: Greenleaf Studio | D17: Monthly social posts | E17: Captions and scheduling | F17: 0.66666667 | G17: 0.75 | M17: =IF(B17="","",IF(AND(F17<>"",G17<>""),MAX(0,ROUND(MOD(G17-F17,1)*24-N(H17)/60,2)),N(I17))) | N17: =IF(B17="","",IF(K17<>"",K17,IF(N(IFERROR(INDEX(Projects!$D$6:$D$65,MATCH(D17,Projects!$B$6:$B$65,0)),""))>0,IFERROR(INDEX(Projects!$D$6:$D$65,MATCH(D17,Projects!$B$6:$B$65,0)),""),IFERROR(INDEX(Clients!$G$6:$G$45,MATCH(C17,Clients!$B$6:$B$45,0)),0)))) | O17: =IF(B17="","",IF(J17<>"",0,ROUND(M17*N17,2))) | P17: =IF(OR(B17="",J17<>""),"",IF(L17<>"",L17,IF(COUNTIFS(Invoices!$C$6:$C$305,C17,Invoices!$E$6:$E$305,"<="&B17,Invoices!$F$6:$F$305,">="&B17)=1,INDEX(Invoices!$B$6:$B$305,SUMIFS(Invoices!$O$6:$O$305,Invoices!$C$6:$C$305,C17,Invoices!$E$6:$E$305,"<="&B17,Invoices!$F$6:$F$305,">="&B17)),IF(COUNTIFS(Invoices!$C$6:$C$305,C17,Invoices!$E$6:$E$305,"<="&B17,Invoices!$F$6:$F$305,">="&B17)>1,"Two invoices","")))) | Q17: =IF(B17="","",IF(J17<>"","Not billable",IF(P17="","To invoice",IF(P17="Two invoices","Check dates",IF(ISNA(MATCH(P17,Invoices!$B$6:$B$305,0)),"Check number",IF(INDEX(Invoices!$M$6:$M$305,MATCH(P17,Invoices!$B$6:$B$305,0))="Paid","Paid",IF(INDEX(Invoices!$M$6:$M$305,MATCH(P17,Invoices!$B$6:$B$305,0))="Draft","Draft","Invoiced"))))))) | R17: =IF(AND(B17<>"",P17<>"",P17=Invoice!$G$4),B17+MOD(N(F17),1)+ROW()/10000000,"") | S17: =IF(R17="","",IF(D17="","Other work",D17)&IF(AND(K17<>"",E17<>""),", "&E17,"")) | T17: =IF(R17="","",IF(COUNTIFS(R$6:R16,">0",S$6:S16,S17,N$6:N16,N17)=0,R17,"")) | U17: =IF(B17="","",IF(J17<>"",0,M17))
B18: 46121 | C18: Greenleaf Studio | D18: Monthly social posts | E18: Captions and scheduling | I18: 2.5 | M18: =IF(B18="","",IF(AND(F18<>"",G18<>""),MAX(0,ROUND(MOD(G18-F18,1)*24-N(H18)/60,2)),N(I18))) | N18: =IF(B18="","",IF(K18<>"",K18,IF(N(IFERROR(INDEX(Projects!$D$6:$D$65,MATCH(D18,Projects!$B$6:$B$65,0)),""))>0,IFERROR(INDEX(Projects!$D$6:$D$65,MATCH(D18,Projects!$B$6:$B$65,0)),""),IFERROR(INDEX(Clients!$G$6:$G$45,MATCH(C18,Clients!$B$6:$B$45,0)),0)))) | O18: =IF(B18="","",IF(J18<>"",0,ROUND(M18*N18,2))) | P18: =IF(OR(B18="",J18<>""),"",IF(L18<>"",L18,IF(COUNTIFS(Invoices!$C$6:$C$305,C18,Invoices!$E$6:$E$305,"<="&B18,Invoices!$F$6:$F$305,">="&B18)=1,INDEX(Invoices!$B$6:$B$305,SUMIFS(Invoices!$O$6:$O$305,Invoices!$C$6:$C$305,C18,Invoices!$E$6:$E$305,"<="&B18,Invoices!$F$6:$F$305,">="&B18)),IF(COUNTIFS(Invoices!$C$6:$C$305,C18,Invoices!$E$6:$E$305,"<="&B18,Invoices!$F$6:$F$305,">="&B18)>1,"Two invoices","")))) | Q18: =IF(B18="","",IF(J18<>"","Not billable",IF(P18="","To invoice",IF(P18="Two invoices","Check dates",IF(ISNA(MATCH(P18,Invoices!$B$6:$B$305,0)),"Check number",IF(INDEX(Invoices!$M$6:$M$305,MATCH(P18,Invoices!$B$6:$B$305,0))="Paid","Paid",IF(INDEX(Invoices!$M$6:$M$305,MATCH(P18,Invoices!$B$6:$B$305,0))="Draft","Draft","Invoiced"))))))) | R18: =IF(AND(B18<>"",P18<>"",P18=Invoice!$G$4),B18+MOD(N(F18),1)+ROW()/10000000,"") | S18: =IF(R18="","",IF(D18="","Other work",D18)&IF(AND(K18<>"",E18<>""),", "&E18,"")) | T18: =IF(R18="","",IF(COUNTIFS(R$6:R17,">0",S$6:S17,S18,N$6:N17,N18)=0,R18,"")) | U18: =IF(B18="","",IF(J18<>"",0,M18))
B19: 46121 | C19: Harbour Books | D19: Spring catalogue | E19: Proof corrections | F19: 0.39583333 | G19: 0.54166667 | M19: =IF(B19="","",IF(AND(F19<>"",G19<>""),MAX(0,ROUND(MOD(G19-F19,1)*24-N(H19)/60,2)),N(I19))) | N19: =IF(B19="","",IF(K19<>"",K19,IF(N(IFERROR(INDEX(Projects!$D$6:$D$65,MATCH(D19,Projects!$B$6:$B$65,0)),""))>0,IFERROR(INDEX(Projects!$D$6:$D$65,MATCH(D19,Projects!$B$6:$B$65,0)),""),IFERROR(INDEX(Clients!$G$6:$G$45,MATCH(C19,Clients!$B$6:$B$45,0)),0)))) | O19: =IF(B19="","",IF(J19<>"",0,ROUND(M19*N19,2))) | P19: =IF(OR(B19="",J19<>""),"",IF(L19<>"",L19,IF(COUNTIFS(Invoices!$C$6:$C$305,C19,Invoices!$E$6:$E$305,"<="&B19,Invoices!$F$6:$F$305,">="&B19)=1,INDEX(Invoices!$B$6:$B$305,SUMIFS(Invoices!$O$6:$O$305,Invoices!$C$6:$C$305,C19,Invoices!$E$6:$E$305,"<="&B19,Invoices!$F$6:$F$305,">="&B19)),IF(COUNTIFS(Invoices!$C$6:$C$305,C19,Invoices!$E$6:$E$305,"<="&B19,Invoices!$F$6:$F$305,">="&B19)>1,"Two invoices","")))) | Q19: =IF(B19="","",IF(J19<>"","Not billable",IF(P19="","To invoice",IF(P19="Two invoices","Check dates",IF(ISNA(MATCH(P19,Invoices!$B$6:$B$305,0)),"Check number",IF(INDEX(Invoices!$M$6:$M$305,MATCH(P19,Invoices!$B$6:$B$305,0))="Paid","Paid",IF(INDEX(Invoices!$M$6:$M$305,MATCH(P19,Invoices!$B$6:$B$305,0))="Draft","Draft","Invoiced"))))))) | R19: =IF(AND(B19<>"",P19<>"",P19=Invoice!$G$4),B19+MOD(N(F19),1)+ROW()/10000000,"") | S19: =IF(R19="","",IF(D19="","Other work",D19)&IF(AND(K19<>"",E19<>""),", "&E19,"")) | T19: =IF(R19="","",IF(COUNTIFS(R$6:R18,">0",S$6:S18,S19,N$6:N18,N19)=0,R19,"")) | U19: =IF(B19="","",IF(J19<>"",0,M19))
B20: 46121 | C20: Harbour Books | D20: Spring catalogue | E20: Product pages | F20: 0.5625 | G20: 0.70833333 | M20: =IF(B20="","",IF(AND(F20<>"",G20<>""),MAX(0,ROUND(MOD(G20-F20,1)*24-N(H20)/60,2)),N(I20))) | N20: =IF(B20="","",IF(K20<>"",K20,IF(N(IFERROR(INDEX(Projects!$D$6:$D$65,MATCH(D20,Projects!$B$6:$B$65,0)),""))>0,IFERROR(INDEX(Projects!$D$6:$D$65,MATCH(D20,Projects!$B$6:$B$65,0)),""),IFERROR(INDEX(Clients!$G$6:$G$45,MATCH(C20,Clients!$B$6:$B$45,0)),0)))) | O20: =IF(B20="","",IF(J20<>"",0,ROUND(M20*N20,2))) | P20: =IF(OR(B20="",J20<>""),"",IF(L20<>"",L20,IF(COUNTIFS(Invoices!$C$6:$C$305,C20,Invoices!$E$6:$E$305,"<="&B20,Invoices!$F$6:$F$305,">="&B20)=1,INDEX(Invoices!$B$6:$B$305,SUMIFS(Invoices!$O$6:$O$305,Invoices!$C$6:$C$305,C20,Invoices!$E$6:$E$305,"<="&B20,Invoices!$F$6:$F$305,">="&B20)),IF(COUNTIFS(Invoices!$C$6:$C$305,C20,Invoices!$E$6:$E$305,"<="&B20,Invoices!$F$6:$F$305,">="&B20)>1,"Two invoices","")))) | Q20: =IF(B20="","",IF(J20<>"","Not billable",IF(P20="","To invoice",IF(P20="Two invoices","Check dates",IF(ISNA(MATCH(P20,Invoices!$B$6:$B$305,0)),"Check number",IF(INDEX(Invoices!$M$6:$M$305,MATCH(P20,Invoices!$B$6:$B$305,0))="Paid","Paid",IF(INDEX(Invoices!$M$6:$M$305,MATCH(P20,Invoices!$B$6:$B$305,0))="Draft","Draft","Invoiced"))))))) | R20: =IF(AND(B20<>"",P20<>"",P20=Invoice!$G$4),B20+MOD(N(F20),1)+ROW()/10000000,"") | S20: =IF(R20="","",IF(D20="","Other work",D20)&IF(AND(K20<>"",E20<>""),", "&E20,"")) | T20: =IF(R20="","",IF(COUNTIFS(R$6:R19,">0",S$6:S19,S20,N$6:N19,N20)=0,R20,"")) | U20: =IF(B20="","",IF(J20<>"",0,M20))
B21: 46122 | C21: Greenleaf Studio | D21: Monthly social posts | E21: Post designs | I21: 3 | M21: =IF(B21="","",IF(AND(F21<>"",G21<>""),MAX(0,ROUND(MOD(G21-F21,1)*24-N(H21)/60,2)),N(I21))) | N21: =IF(B21="","",IF(K21<>"",K21,IF(N(IFERROR(INDEX(Projects!$D$6:$D$65,MATCH(D21,Projects!$B$6:$B$65,0)),""))>0,IFERROR(INDEX(Projects!$D$6:$D$65,MATCH(D21,Projects!$B$6:$B$65,0)),""),IFERROR(INDEX(Clients!$G$6:$G$45,MATCH(C21,Clients!$B$6:$B$45,0)),0)))) | O21: =IF(B21="","",IF(J21<>"",0,ROUND(M21*N21,2))) | P21: =IF(OR(B21="",J21<>""),"",IF(L21<>"",L21,IF(COUNTIFS(Invoices!$C$6:$C$305,C21,Invoices!$E$6:$E$305,"<="&B21,Invoices!$F$6:$F$305,">="&B21)=1,INDEX(Invoices!$B$6:$B$305,SUMIFS(Invoices!$O$6:$O$305,Invoices!$C$6:$C$305,C21,Invoices!$E$6:$E$305,"<="&B21,Invoices!$F$6:$F$305,">="&B21)),IF(COUNTIFS(Invoices!$C$6:$C$305,C21,Invoices!$E$6:$E$305,"<="&B21,Invoices!$F$6:$F$305,">="&B21)>1,"Two invoices","")))) | Q21: =IF(B21="","",IF(J21<>"","Not billable",IF(P21="","To invoice",IF(P21="Two invoices","Check dates",IF(ISNA(MATCH(P21,Invoices!$B$6:$B$305,0)),"Check number",IF(INDEX(Invoices!$M$6:$M$305,MATCH(P21,Invoices!$B$6:$B$305,0))="Paid","Paid",IF(INDEX(Invoices!$M$6:$M$305,MATCH(P21,Invoices!$B$6:$B$305,0))="Draft","Draft","Invoiced"))))))) | R21: =IF(AND(B21<>"",P21<>"",P21=Invoice!$G$4),B21+MOD(N(F21),1)+ROW()/10000000,"") | S21: =IF(R21="","",IF(D21="","Other work",D21)&IF(AND(K21<>"",E21<>""),", "&E21,"")) | T21: =IF(R21="","",IF(COUNTIFS(R$6:R20,">0",S$6:S20,S21,N$6:N20,N21)=0,R21,"")) | U21: =IF(B21="","",IF(J21<>"",0,M21))
B22: 46125 | C22: Harbour Books | D22: Spring catalogue | E22: Cover design | I22: 3.5 | M22: =IF(B22="","",IF(AND(F22<>"",G22<>""),MAX(0,ROUND(MOD(G22-F22,1)*24-N(H22)/60,2)),N(I22))) | N22: =IF(B22="","",IF(K22<>"",K22,IF(N(IFERROR(INDEX(Projects!$D$6:$D$65,MATCH(D22,Projects!$B$6:$B$65,0)),""))>0,IFERROR(INDEX(Projects!$D$6:$D$65,MATCH(D22,Projects!$B$6:$B$65,0)),""),IFERROR(INDEX(Clients!$G$6:$G$45,MATCH(C22,Clients!$B$6:$B$45,0)),0)))) | O22: =IF(B22="","",IF(J22<>"",0,ROUND(M22*N22,2))) | P22: =IF(OR(B22="",J22<>""),"",IF(L22<>"",L22,IF(COUNTIFS(Invoices!$C$6:$C$305,C22,Invoices!$E$6:$E$305,"<="&B22,Invoices!$F$6:$F$305,">="&B22)=1,INDEX(Invoices!$B$6:$B$305,SUMIFS(Invoices!$O$6:$O$305,Invoices!$C$6:$C$305,C22,Invoices!$E$6:$E$305,"<="&B22,Invoices!$F$6:$F$305,">="&B22)),IF(COUNTIFS(Invoices!$C$6:$C$305,C22,Invoices!$E$6:$E$305,"<="&B22,Invoices!$F$6:$F$305,">="&B22)>1,"Two invoices","")))) | Q22: =IF(B22="","",IF(J22<>"","Not billable",IF(P22="","To invoice",IF(P22="Two invoices","Check dates",IF(ISNA(MATCH(P22,Invoices!$B$6:$B$305,0)),"Check number",IF(INDEX(Invoices!$M$6:$M$305,MATCH(P22,Invoices!$B$6:$B$305,0))="Paid","Paid",IF(INDEX(Invoices!$M$6:$M$305,MATCH(P22,Invoices!$B$6:$B$305,0))="Draft","Draft","Invoiced"))))))) | R22: =IF(AND(B22<>"",P22<>"",P22=Invoice!$G$4),B22+MOD(N(F22),1)+ROW()/10000000,"") | S22: =IF(R22="","",IF(D22="","Other work",D22)&IF(AND(K22<>"",E22<>""),", "&E22,"")) | T22: =IF(R22="","",IF(COUNTIFS(R$6:R21,">0",S$6:S21,S22,N$6:N21,N22)=0,R22,"")) | U22: =IF(B22="","",IF(J22<>"",0,M22))
B23: 46125 | C23: Greenleaf Studio | D23: Monthly social posts | E23: Post designs | F23: 0.39583333 | G23: 0.5 | M23: =IF(B23="","",IF(AND(F23<>"",G23<>""),MAX(0,ROUND(MOD(G23-F23,1)*24-N(H23)/60,2)),N(I23))) | N23: =IF(B23="","",IF(K23<>"",K23,IF(N(IFERROR(INDEX(Projects!$D$6:$D$65,MATCH(D23,Projects!$B$6:$B$65,0)),""))>0,IFERROR(INDEX(Projects!$D$6:$D$65,MATCH(D23,Projects!$B$6:$B$65,0)),""),IFERROR(INDEX(Clients!$G$6:$G$45,MATCH(C23,Clients!$B$6:$B$45,0)),0)))) | O23: =IF(B23="","",IF(J23<>"",0,ROUND(M23*N23,2))) | P23: =IF(OR(B23="",J23<>""),"",IF(L23<>"",L23,IF(COUNTIFS(Invoices!$C$6:$C$305,C23,Invoices!$E$6:$E$305,"<="&B23,Invoices!$F$6:$F$305,">="&B23)=1,INDEX(Invoices!$B$6:$B$305,SUMIFS(Invoices!$O$6:$O$305,Invoices!$C$6:$C$305,C23,Invoices!$E$6:$E$305,"<="&B23,Invoices!$F$6:$F$305,">="&B23)),IF(COUNTIFS(Invoices!$C$6:$C$305,C23,Invoices!$E$6:$E$305,"<="&B23,Invoices!$F$6:$F$305,">="&B23)>1,"Two invoices","")))) | Q23: =IF(B23="","",IF(J23<>"","Not billable",IF(P23="","To invoice",IF(P23="Two invoices","Check dates",IF(ISNA(MATCH(P23,Invoices!$B$6:$B$305,0)),"Check number",IF(INDEX(Invoices!$M$6:$M$305,MATCH(P23,Invoices!$B$6:$B$305,0))="Paid","Paid",IF(INDEX(Invoices!$M$6:$M$305,MATCH(P23,Invoices!$B$6:$B$305,0))="Draft","Draft","Invoiced"))))))) | R23: =IF(AND(B23<>"",P23<>"",P23=Invoice!$G$4),B23+MOD(N(F23),1)+ROW()/10000000,"") | S23: =IF(R23="","",IF(D23="","Other work",D23)&IF(AND(K23<>"",E23<>""),", "&E23,"")) | T23: =IF(R23="","",IF(COUNTIFS(R$6:R22,">0",S$6:S22,S23,N$6:N22,N23)=0,R23,"")) | U23: =IF(B23="","",IF(J23<>"",0,M23))
B24: 46126 | C24: Harbour Books | D24: Spring catalogue | E24: Catalogue layout | I24: 2 | M24: =IF(B24="","",IF(AND(F24<>"",G24<>""),MAX(0,ROUND(MOD(G24-F24,1)*24-N(H24)/60,2)),N(I24))) | N24: =IF(B24="","",IF(K24<>"",K24,IF(N(IFERROR(INDEX(Projects!$D$6:$D$65,MATCH(D24,Projects!$B$6:$B$65,0)),""))>0,IFERROR(INDEX(Projects!$D$6:$D$65,MATCH(D24,Projects!$B$6:$B$65,0)),""),IFERROR(INDEX(Clients!$G$6:$G$45,MATCH(C24,Clients!$B$6:$B$45,0)),0)))) | O24: =IF(B24="","",IF(J24<>"",0,ROUND(M24*N24,2))) | P24: =IF(OR(B24="",J24<>""),"",IF(L24<>"",L24,IF(COUNTIFS(Invoices!$C$6:$C$305,C24,Invoices!$E$6:$E$305,"<="&B24,Invoices!$F$6:$F$305,">="&B24)=1,INDEX(Invoices!$B$6:$B$305,SUMIFS(Invoices!$O$6:$O$305,Invoices!$C$6:$C$305,C24,Invoices!$E$6:$E$305,"<="&B24,Invoices!$F$6:$F$305,">="&B24)),IF(COUNTIFS(Invoices!$C$6:$C$305,C24,Invoices!$E$6:$E$305,"<="&B24,Invoices!$F$6:$F$305,">="&B24)>1,"Two invoices","")))) | Q24: =IF(B24="","",IF(J24<>"","Not billable",IF(P24="","To invoice",IF(P24="Two invoices","Check dates",IF(ISNA(MATCH(P24,Invoices!$B$6:$B$305,0)),"Check number",IF(INDEX(Invoices!$M$6:$M$305,MATCH(P24,Invoices!$B$6:$B$305,0))="Paid","Paid",IF(INDEX(Invoices!$M$6:$M$305,MATCH(P24,Invoices!$B$6:$B$305,0))="Draft","Draft","Invoiced"))))))) | R24: =IF(AND(B24<>"",P24<>"",P24=Invoice!$G$4),B24+MOD(N(F24),1)+ROW()/10000000,"") | S24: =IF(R24="","",IF(D24="","Other work",D24)&IF(AND(K24<>"",E24<>""),", "&E24,"")) | T24: =IF(R24="","",IF(COUNTIFS(R$6:R23,">0",S$6:S23,S24,N$6:N23,N24)=0,R24,"")) | U24: =IF(B24="","",IF(J24<>"",0,M24))
B25: 46126 | C25: Harbour Books | D25: Spring catalogue | E25: Proof corrections | F25: 0.375 | G25: 0.41666667 | M25: =IF(B25="","",IF(AND(F25<>"",G25<>""),MAX(0,ROUND(MOD(G25-F25,1)*24-N(H25)/60,2)),N(I25))) | N25: =IF(B25="","",IF(K25<>"",K25,IF(N(IFERROR(INDEX(Projects!$D$6:$D$65,MATCH(D25,Projects!$B$6:$B$65,0)),""))>0,IFERROR(INDEX(Projects!$D$6:$D$65,MATCH(D25,Projects!$B$6:$B$65,0)),""),IFERROR(INDEX(Clients!$G$6:$G$45,MATCH(C25,Clients!$B$6:$B$45,0)),0)))) | O25: =IF(B25="","",IF(J25<>"",0,ROUND(M25*N25,2))) | P25: =IF(OR(B25="",J25<>""),"",IF(L25<>"",L25,IF(COUNTIFS(Invoices!$C$6:$C$305,C25,Invoices!$E$6:$E$305,"<="&B25,Invoices!$F$6:$F$305,">="&B25)=1,INDEX(Invoices!$B$6:$B$305,SUMIFS(Invoices!$O$6:$O$305,Invoices!$C$6:$C$305,C25,Invoices!$E$6:$E$305,"<="&B25,Invoices!$F$6:$F$305,">="&B25)),IF(COUNTIFS(Invoices!$C$6:$C$305,C25,Invoices!$E$6:$E$305,"<="&B25,Invoices!$F$6:$F$305,">="&B25)>1,"Two invoices","")))) | Q25: =IF(B25="","",IF(J25<>"","Not billable",IF(P25="","To invoice",IF(P25="Two invoices","Check dates",IF(ISNA(MATCH(P25,Invoices!$B$6:$B$305,0)),"Check number",IF(INDEX(Invoices!$M$6:$M$305,MATCH(P25,Invoices!$B$6:$B$305,0))="Paid","Paid",IF(INDEX(Invoices!$M$6:$M$305,MATCH(P25,Invoices!$B$6:$B$305,0))="Draft","Draft","Invoiced"))))))) | R25: =IF(AND(B25<>"",P25<>"",P25=Invoice!$G$4),B25+MOD(N(F25),1)+ROW()/10000000,"") | S25: =IF(R25="","",IF(D25="","Other work",D25)&IF(AND(K25<>"",E25<>""),", "&E25,"")) | T25: =IF(R25="","",IF(COUNTIFS(R$6:R24,">0",S$6:S24,S25,N$6:N24,N25)=0,R25,"")) | U25: =IF(B25="","",IF(J25<>"",0,M25))
B26: 46127 | C26: Greenleaf Studio | D26: Monthly social posts | E26: Post designs | F26: 0.39583333 | G26: 0.47916667 | M26: =IF(B26="","",IF(AND(F26<>"",G26<>""),MAX(0,ROUND(MOD(G26-F26,1)*24-N(H26)/60,2)),N(I26))) | N26: =IF(B26="","",IF(K26<>"",K26,IF(N(IFERROR(INDEX(Projects!$D$6:$D$65,MATCH(D26,Projects!$B$6:$B$65,0)),""))>0,IFERROR(INDEX(Projects!$D$6:$D$65,MATCH(D26,Projects!$B$6:$B$65,0)),""),IFERROR(INDEX(Clients!$G$6:$G$45,MATCH(C26,Clients!$B$6:$B$45,0)),0)))) | O26: =IF(B26="","",IF(J26<>"",0,ROUND(M26*N26,2))) | P26: =IF(OR(B26="",J26<>""),"",IF(L26<>"",L26,IF(COUNTIFS(Invoices!$C$6:$C$305,C26,Invoices!$E$6:$E$305,"<="&B26,Invoices!$F$6:$F$305,">="&B26)=1,INDEX(Invoices!$B$6:$B$305,SUMIFS(Invoices!$O$6:$O$305,Invoices!$C$6:$C$305,C26,Invoices!$E$6:$E$305,"<="&B26,Invoices!$F$6:$F$305,">="&B26)),IF(COUNTIFS(Invoices!$C$6:$C$305,C26,Invoices!$E$6:$E$305,"<="&B26,Invoices!$F$6:$F$305,">="&B26)>1,"Two invoices","")))) | Q26: =IF(B26="","",IF(J26<>"","Not billable",IF(P26="","To invoice",IF(P26="Two invoices","Check dates",IF(ISNA(MATCH(P26,Invoices!$B$6:$B$305,0)),"Check number",IF(INDEX(Invoices!$M$6:$M$305,MATCH(P26,Invoices!$B$6:$B$305,0))="Paid","Paid",IF(INDEX(Invoices!$M$6:$M$305,MATCH(P26,Invoices!$B$6:$B$305,0))="Draft","Draft","Invoiced"))))))) | R26: =IF(AND(B26<>"",P26<>"",P26=Invoice!$G$4),B26+MOD(N(F26),1)+ROW()/10000000,"") | S26: =IF(R26="","",IF(D26="","Other work",D26)&IF(AND(K26<>"",E26<>""),", "&E26,"")) | T26: =IF(R26="","",IF(COUNTIFS(R$6:R25,">0",S$6:S25,S26,N$6:N25,N26)=0,R26,"")) | U26: =IF(B26="","",IF(J26<>"",0,M26))
B27: 46128 | C27: Harbour Books | D27: Spring catalogue | E27: Catalogue layout | I27: 2 | M27: =IF(B27="","",IF(AND(F27<>"",G27<>""),MAX(0,ROUND(MOD(G27-F27,1)*24-N(H27)/60,2)),N(I27))) | N27: =IF(B27="","",IF(K27<>"",K27,IF(N(IFERROR(INDEX(Projects!$D$6:$D$65,MATCH(D27,Projects!$B$6:$B$65,0)),""))>0,IFERROR(INDEX(Projects!$D$6:$D$65,MATCH(D27,Projects!$B$6:$B$65,0)),""),IFERROR(INDEX(Clients!$G$6:$G$45,MATCH(C27,Clients!$B$6:$B$45,0)),0)))) | O27: =IF(B27="","",IF(J27<>"",0,ROUND(M27*N27,2))) | P27: =IF(OR(B27="",J27<>""),"",IF(L27<>"",L27,IF(COUNTIFS(Invoices!$C$6:$C$305,C27,Invoices!$E$6:$E$305,"<="&B27,Invoices!$F$6:$F$305,">="&B27)=1,INDEX(Invoices!$B$6:$B$305,SUMIFS(Invoices!$O$6:$O$305,Invoices!$C$6:$C$305,C27,Invoices!$E$6:$E$305,"<="&B27,Invoices!$F$6:$F$305,">="&B27)),IF(COUNTIFS(Invoices!$C$6:$C$305,C27,Invoices!$E$6:$E$305,"<="&B27,Invoices!$F$6:$F$305,">="&B27)>1,"Two invoices","")))) | Q27: =IF(B27="","",IF(J27<>"","Not billable",IF(P27="","To invoice",IF(P27="Two invoices","Check dates",IF(ISNA(MATCH(P27,Invoices!$B$6:$B$305,0)),"Check number",IF(INDEX(Invoices!$M$6:$M$305,MATCH(P27,Invoices!$B$6:$B$305,0))="Paid","Paid",IF(INDEX(Invoices!$M$6:$M$305,MATCH(P27,Invoices!$B$6:$B$305,0))="Draft","Draft","Invoiced"))))))) | R27: =IF(AND(B27<>"",P27<>"",P27=Invoice!$G$4),B27+MOD(N(F27),1)+ROW()/10000000,"") | S27: =IF(R27="","",IF(D27="","Other work",D27)&IF(AND(K27<>"",E27<>""),", "&E27,"")) | T27: =IF(R27="","",IF(COUNTIFS(R$6:R26,">0",S$6:S26,S27,N$6:N26,N27)=0,R27,"")) | U27: =IF(B27="","",IF(J27<>"",0,M27))
B28: 46128 | C28: Harbour Books | D28: Spring catalogue | E28: Proof corrections | F28: 0.375 | G28: 0.53125 | H28: 15 | M28: =IF(B28="","",IF(AND(F28<>"",G28<>""),MAX(0,ROUND(MOD(G28-F28,1)*24-N(H28)/60,2)),N(I28))) | N28: =IF(B28="","",IF(K28<>"",K28,IF(N(IFERROR(INDEX(Projects!$D$6:$D$65,MATCH(D28,Projects!$B$6:$B$65,0)),""))>0,IFERROR(INDEX(Projects!$D$6:$D$65,MATCH(D28,Projects!$B$6:$B$65,0)),""),IFERROR(INDEX(Clients!$G$6:$G$45,MATCH(C28,Clients!$B$6:$B$45,0)),0)))) | O28: =IF(B28="","",IF(J28<>"",0,ROUND(M28*N28,2))) | P28: =IF(OR(B28="",J28<>""),"",IF(L28<>"",L28,IF(COUNTIFS(Invoices!$C$6:$C$305,C28,Invoices!$E$6:$E$305,"<="&B28,Invoices!$F$6:$F$305,">="&B28)=1,INDEX(Invoices!$B$6:$B$305,SUMIFS(Invoices!$O$6:$O$305,Invoices!$C$6:$C$305,C28,Invoices!$E$6:$E$305,"<="&B28,Invoices!$F$6:$F$305,">="&B28)),IF(COUNTIFS(Invoices!$C$6:$C$305,C28,Invoices!$E$6:$E$305,"<="&B28,Invoices!$F$6:$F$305,">="&B28)>1,"Two invoices","")))) | Q28: =IF(B28="","",IF(J28<>"","Not billable",IF(P28="","To invoice",IF(P28="Two invoices","Check dates",IF(ISNA(MATCH(P28,Invoices!$B$6:$B$305,0)),"Check number",IF(INDEX(Invoices!$M$6:$M$305,MATCH(P28,Invoices!$B$6:$B$305,0))="Paid","Paid",IF(INDEX(Invoices!$M$6:$M$305,MATCH(P28,Invoices!$B$6:$B$305,0))="Draft","Draft","Invoiced"))))))) | R28: =IF(AND(B28<>"",P28<>"",P28=Invoice!$G$4),B28+MOD(N(F28),1)+ROW()/10000000,"") | S28: =IF(R28="","",IF(D28="","Other work",D28)&IF(AND(K28<>"",E28<>""),", "&E28,"")) | T28: =IF(R28="","",IF(COUNTIFS(R$6:R27,">0",S$6:S27,S28,N$6:N27,N28)=0,R28,"")) | U28: =IF(B28="","",IF(J28<>"",0,M28))
B29: 46129 | C29: Harbour Books | D29: Spring catalogue | E29: Cover design | I29: 1 | M29: =IF(B29="","",IF(AND(F29<>"",G29<>""),MAX(0,ROUND(MOD(G29-F29,1)*24-N(H29)/60,2)),N(I29))) | N29: =IF(B29="","",IF(K29<>"",K29,IF(N(IFERROR(INDEX(Projects!$D$6:$D$65,MATCH(D29,Projects!$B$6:$B$65,0)),""))>0,IFERROR(INDEX(Projects!$D$6:$D$65,MATCH(D29,Projects!$B$6:$B$65,0)),""),IFERROR(INDEX(Clients!$G$6:$G$45,MATCH(C29,Clients!$B$6:$B$45,0)),0)))) | O29: =IF(B29="","",IF(J29<>"",0,ROUND(M29*N29,2))) | P29: =IF(OR(B29="",J29<>""),"",IF(L29<>"",L29,IF(COUNTIFS(Invoices!$C$6:$C$305,C29,Invoices!$E$6:$E$305,"<="&B29,Invoices!$F$6:$F$305,">="&B29)=1,INDEX(Invoices!$B$6:$B$305,SUMIFS(Invoices!$O$6:$O$305,Invoices!$C$6:$C$305,C29,Invoices!$E$6:$E$305,"<="&B29,Invoices!$F$6:$F$305,">="&B29)),IF(COUNTIFS(Invoices!$C$6:$C$305,C29,Invoices!$E$6:$E$305,"<="&B29,Invoices!$F$6:$F$305,">="&B29)>1,"Two invoices","")))) | Q29: =IF(B29="","",IF(J29<>"","Not billable",IF(P29="","To invoice",IF(P29="Two invoices","Check dates",IF(ISNA(MATCH(P29,Invoices!$B$6:$B$305,0)),"Check number",IF(INDEX(Invoices!$M$6:$M$305,MATCH(P29,Invoices!$B$6:$B$305,0))="Paid","Paid",IF(INDEX(Invoices!$M$6:$M$305,MATCH(P29,Invoices!$B$6:$B$305,0))="Draft","Draft","Invoiced"))))))) | R29: =IF(AND(B29<>"",P29<>"",P29=Invoice!$G$4),B29+MOD(N(F29),1)+ROW()/10000000,"") | S29: =IF(R29="","",IF(D29="","Other work",D29)&IF(AND(K29<>"",E29<>""),", "&E29,"")) | T29: =IF(R29="","",IF(COUNTIFS(R$6:R28,">0",S$6:S28,S29,N$6:N28,N29)=0,R29,"")) | U29: =IF(B29="","",IF(J29<>"",0,M29))
B30: 46132 | C30: Greenleaf Studio | D30: Monthly social posts | E30: Monthly report | I30: 3 | M30: =IF(B30="","",IF(AND(F30<>"",G30<>""),MAX(0,ROUND(MOD(G30-F30,1)*24-N(H30)/60,2)),N(I30))) | N30: =IF(B30="","",IF(K30<>"",K30,IF(N(IFERROR(INDEX(Projects!$D$6:$D$65,MATCH(D30,Projects!$B$6:$B$65,0)),""))>0,IFERROR(INDEX(Projects!$D$6:$D$65,MATCH(D30,Projects!$B$6:$B$65,0)),""),IFERROR(INDEX(Clients!$G$6:$G$45,MATCH(C30,Clients!$B$6:$B$45,0)),0)))) | O30: =IF(B30="","",IF(J30<>"",0,ROUND(M30*N30,2))) | P30: =IF(OR(B30="",J30<>""),"",IF(L30<>"",L30,IF(COUNTIFS(Invoices!$C$6:$C$305,C30,Invoices!$E$6:$E$305,"<="&B30,Invoices!$F$6:$F$305,">="&B30)=1,INDEX(Invoices!$B$6:$B$305,SUMIFS(Invoices!$O$6:$O$305,Invoices!$C$6:$C$305,C30,Invoices!$E$6:$E$305,"<="&B30,Invoices!$F$6:$F$305,">="&B30)),IF(COUNTIFS(Invoices!$C$6:$C$305,C30,Invoices!$E$6:$E$305,"<="&B30,Invoices!$F$6:$F$305,">="&B30)>1,"Two invoices","")))) | Q30: =IF(B30="","",IF(J30<>"","Not billable",IF(P30="","To invoice",IF(P30="Two invoices","Check dates",IF(ISNA(MATCH(P30,Invoices!$B$6:$B$305,0)),"Check number",IF(INDEX(Invoices!$M$6:$M$305,MATCH(P30,Invoices!$B$6:$B$305,0))="Paid","Paid",IF(INDEX(Invoices!$M$6:$M$305,MATCH(P30,Invoices!$B$6:$B$305,0))="Draft","Draft","Invoiced"))))))) | R30: =IF(AND(B30<>"",P30<>"",P30=Invoice!$G$4),B30+MOD(N(F30),1)+ROW()/10000000,"") | S30: =IF(R30="","",IF(D30="","Other work",D30)&IF(AND(K30<>"",E30<>""),", "&E30,"")) | T30: =IF(R30="","",IF(COUNTIFS(R$6:R29,">0",S$6:S29,S30,N$6:N29,N30)=0,R30,"")) | U30: =IF(B30="","",IF(J30<>"",0,M30))
