Workbook

Sheet Dashboard
N1: =IF($C$4<YEAR(TODAY()),12,IF($C$4>YEAR(TODAY()),0,MONTH(TODAY())))
B2: Rental dashboard | N2: =IF($N$1=0,0,DATE($C$4,$N$1+1,1)-DATE($C$4,1,1))
B3: Pick a year and a property. Nights are counted in the month they fall in.
B4: Year | C4: 2026 | D4: Property | E4: All properties
B6: Revenue | C6: Expenses | D6: Profit | E6: Nights booked | F6: Occupancy to date | G6: Nightly rate
B7: =IF(Dashboard!$E$4="All properties",SUM(Bookings!$AF$6:$AF$505),SUMIFS(Bookings!$AF$6:$AF$505,Bookings!$B$6:$B$505,$E$4)) | C7: =IF(Dashboard!$E$4="All properties",SUMIFS(Expenses!$E$6:$E$505,Expenses!$B$6:$B$505,">="&DATE($C$4,1,1),Expenses!$B$6:$B$505,"<="&DATE($C$4,12,31)),SUMIFS(Expenses!$E$6:$E$505,Expenses!$B$6:$B$505,">="&DATE($C$4,1,1),Expenses!$B$6:$B$505,"<="&DATE($C$4,12,31),Expenses!$C$6:$C$505,$E$4)) | D7: =B7-C7 | E7: =IF(Dashboard!$E$4="All properties",SUM(Bookings!$AE$6:$AE$505),SUMIFS(Bookings!$AE$6:$AE$505,Bookings!$B$6:$B$505,$E$4)) | F7: =IF(OR($N$2=0,IF(Dashboard!$E$4="All properties",COUNTA(Settings!$B$6:$B$11),1)=0),"",IF(Dashboard!$E$4="All properties",SUM(Bookings!$AH$6:$AH$505),SUMIFS(Bookings!$AH$6:$AH$505,Bookings!$B$6:$B$505,$E$4))/(IF(Dashboard!$E$4="All properties",COUNTA(Settings!$B$6:$B$11),1)*$N$2)) | G7: =IF(E7=0,"",IF(Dashboard!$E$4="All properties",SUM(Bookings!$AG$6:$AG$505),SUMIFS(Bookings!$AG$6:$AG$505,Bookings!$B$6:$B$505,$E$4))/E7)
B9: Month | C9: Nights | D9: Occupancy | E9: Revenue | F9: Expenses | G9: Profit | I9: Heads-up
B10: Jan | C10: =IF(Dashboard!$E$4="All properties",SUM(Bookings!$S$6:$S$505),SUMIFS(Bookings!$S$6:$S$505,Bookings!$B$6:$B$505,$E$4)) | D10: =IF($N10=0,"",C10/$N10) | E10: =IF(Dashboard!$E$4="All properties",SUMPRODUCT(Bookings!$S$6:$S$505,Bookings!$Q$6:$Q$505),SUMPRODUCT(Bookings!$S$6:$S$505,Bookings!$Q$6:$Q$505,--(Bookings!$B$6:$B$505=$E$4))) | F10: =IF(Dashboard!$E$4="All properties",SUMIFS(Expenses!$E$6:$E$505,Expenses!$B$6:$B$505,">="&DATE($C$4,1,1),Expenses!$B$6:$B$505,"<="&EOMONTH(DATE($C$4,1,1),0)),SUMIFS(Expenses!$E$6:$E$505,Expenses!$B$6:$B$505,">="&DATE($C$4,1,1),Expenses!$B$6:$B$505,"<="&EOMONTH(DATE($C$4,1,1),0),Expenses!$C$6:$C$505,$E$4)) | G10: =E10-F10 | I10: =IF(COUNTIFS(Bookings!$E$6:$E$505,">="&TODAY(),Bookings!$E$6:$E$505,"<="&TODAY()+7)=0,"No check-ins in the next 7 days",IF(COUNTIFS(Bookings!$E$6:$E$505,">="&TODAY(),Bookings!$E$6:$E$505,"<="&TODAY()+7)=1,"1 check-in",COUNTIFS(Bookings!$E$6:$E$505,">="&TODAY(),Bookings!$E$6:$E$505,"<="&TODAY()+7)&" check-ins")&" in the next 7 days") | N10: =DAY(EOMONTH(DATE($C$4,1,1),0))*IF(Dashboard!$E$4="All properties",COUNTA(Settings!$B$6:$B$11),1)
B11: Feb | C11: =IF(Dashboard!$E$4="All properties",SUM(Bookings!$T$6:$T$505),SUMIFS(Bookings!$T$6:$T$505,Bookings!$B$6:$B$505,$E$4)) | D11: =IF($N11=0,"",C11/$N11) | E11: =IF(Dashboard!$E$4="All properties",SUMPRODUCT(Bookings!$T$6:$T$505,Bookings!$Q$6:$Q$505),SUMPRODUCT(Bookings!$T$6:$T$505,Bookings!$Q$6:$Q$505,--(Bookings!$B$6:$B$505=$E$4))) | F11: =IF(Dashboard!$E$4="All properties",SUMIFS(Expenses!$E$6:$E$505,Expenses!$B$6:$B$505,">="&DATE($C$4,2,1),Expenses!$B$6:$B$505,"<="&EOMONTH(DATE($C$4,2,1),0)),SUMIFS(Expenses!$E$6:$E$505,Expenses!$B$6:$B$505,">="&DATE($C$4,2,1),Expenses!$B$6:$B$505,"<="&EOMONTH(DATE($C$4,2,1),0),Expenses!$C$6:$C$505,$E$4)) | G11: =E11-F11 | I11: =IF(COUNTIFS(Bookings!$N$6:$N$505,"Staying now")=0,"Nobody is staying right now",IF(COUNTIFS(Bookings!$N$6:$N$505,"Staying now")=1,"1 booking is",COUNTIFS(Bookings!$N$6:$N$505,"Staying now")&" bookings are")&" staying right now") | N11: =DAY(EOMONTH(DATE($C$4,2,1),0))*IF(Dashboard!$E$4="All properties",COUNTA(Settings!$B$6:$B$11),1)
B12: Mar | C12: =IF(Dashboard!$E$4="All properties",SUM(Bookings!$U$6:$U$505),SUMIFS(Bookings!$U$6:$U$505,Bookings!$B$6:$B$505,$E$4)) | D12: =IF($N12=0,"",C12/$N12) | E12: =IF(Dashboard!$E$4="All properties",SUMPRODUCT(Bookings!$U$6:$U$505,Bookings!$Q$6:$Q$505),SUMPRODUCT(Bookings!$U$6:$U$505,Bookings!$Q$6:$Q$505,--(Bookings!$B$6:$B$505=$E$4))) | F12: =IF(Dashboard!$E$4="All properties",SUMIFS(Expenses!$E$6:$E$505,Expenses!$B$6:$B$505,">="&DATE($C$4,3,1),Expenses!$B$6:$B$505,"<="&EOMONTH(DATE($C$4,3,1),0)),SUMIFS(Expenses!$E$6:$E$505,Expenses!$B$6:$B$505,">="&DATE($C$4,3,1),Expenses!$B$6:$B$505,"<="&EOMONTH(DATE($C$4,3,1),0),Expenses!$C$6:$C$505,$E$4)) | G12: =E12-F12 | I12: =IF(COUNTIFS(Bookings!$N$6:$N$505,"Payout not received")=0,"All payouts received",IF(COUNTIFS(Bookings!$N$6:$N$505,"Payout not received")=1,"1 payout",COUNTIFS(Bookings!$N$6:$N$505,"Payout not received")&" payouts")&" not received yet: "&FIXED(SUMIFS(Bookings!$L$6:$L$505,Bookings!$N$6:$N$505,"Payout not received"),2)) | N12: =DAY(EOMONTH(DATE($C$4,3,1),0))*IF(Dashboard!$E$4="All properties",COUNTA(Settings!$B$6:$B$11),1)
B13: Apr | C13: =IF(Dashboard!$E$4="All properties",SUM(Bookings!$V$6:$V$505),SUMIFS(Bookings!$V$6:$V$505,Bookings!$B$6:$B$505,$E$4)) | D13: =IF($N13=0,"",C13/$N13) | E13: =IF(Dashboard!$E$4="All properties",SUMPRODUCT(Bookings!$V$6:$V$505,Bookings!$Q$6:$Q$505),SUMPRODUCT(Bookings!$V$6:$V$505,Bookings!$Q$6:$Q$505,--(Bookings!$B$6:$B$505=$E$4))) | F13: =IF(Dashboard!$E$4="All properties",SUMIFS(Expenses!$E$6:$E$505,Expenses!$B$6:$B$505,">="&DATE($C$4,4,1),Expenses!$B$6:$B$505,"<="&EOMONTH(DATE($C$4,4,1),0)),SUMIFS(Expenses!$E$6:$E$505,Expenses!$B$6:$B$505,">="&DATE($C$4,4,1),Expenses!$B$6:$B$505,"<="&EOMONTH(DATE($C$4,4,1),0),Expenses!$C$6:$C$505,$E$4)) | G13: =E13-F13 | I13: =IF(MAX(E10:E21)<=0,"No revenue yet this year","Best month so far: "&INDEX(B10:B21,MATCH(MAX(E10:E21),E10:E21,0))) | N13: =DAY(EOMONTH(DATE($C$4,4,1),0))*IF(Dashboard!$E$4="All properties",COUNTA(Settings!$B$6:$B$11),1)
B14: May | C14: =IF(Dashboard!$E$4="All properties",SUM(Bookings!$W$6:$W$505),SUMIFS(Bookings!$W$6:$W$505,Bookings!$B$6:$B$505,$E$4)) | D14: =IF($N14=0,"",C14/$N14) | E14: =IF(Dashboard!$E$4="All properties",SUMPRODUCT(Bookings!$W$6:$W$505,Bookings!$Q$6:$Q$505),SUMPRODUCT(Bookings!$W$6:$W$505,Bookings!$Q$6:$Q$505,--(Bookings!$B$6:$B$505=$E$4))) | F14: =IF(Dashboard!$E$4="All properties",SUMIFS(Expenses!$E$6:$E$505,Expenses!$B$6:$B$505,">="&DATE($C$4,5,1),Expenses!$B$6:$B$505,"<="&EOMONTH(DATE($C$4,5,1),0)),SUMIFS(Expenses!$E$6:$E$505,Expenses!$B$6:$B$505,">="&DATE($C$4,5,1),Expenses!$B$6:$B$505,"<="&EOMONTH(DATE($C$4,5,1),0),Expenses!$C$6:$C$505,$E$4)) | G14: =E14-F14 | N14: =DAY(EOMONTH(DATE($C$4,5,1),0))*IF(Dashboard!$E$4="All properties",COUNTA(Settings!$B$6:$B$11),1)
B15: Jun | C15: =IF(Dashboard!$E$4="All properties",SUM(Bookings!$X$6:$X$505),SUMIFS(Bookings!$X$6:$X$505,Bookings!$B$6:$B$505,$E$4)) | D15: =IF($N15=0,"",C15/$N15) | E15: =IF(Dashboard!$E$4="All properties",SUMPRODUCT(Bookings!$X$6:$X$505,Bookings!$Q$6:$Q$505),SUMPRODUCT(Bookings!$X$6:$X$505,Bookings!$Q$6:$Q$505,--(Bookings!$B$6:$B$505=$E$4))) | F15: =IF(Dashboard!$E$4="All properties",SUMIFS(Expenses!$E$6:$E$505,Expenses!$B$6:$B$505,">="&DATE($C$4,6,1),Expenses!$B$6:$B$505,"<="&EOMONTH(DATE($C$4,6,1),0)),SUMIFS(Expenses!$E$6:$E$505,Expenses!$B$6:$B$505,">="&DATE($C$4,6,1),Expenses!$B$6:$B$505,"<="&EOMONTH(DATE($C$4,6,1),0),Expenses!$C$6:$C$505,$E$4)) | G15: =E15-F15 | I15: Next check-ins | J15: Property | K15: Guest | N15: =DAY(EOMONTH(DATE($C$4,6,1),0))*IF(Dashboard!$E$4="All properties",COUNTA(Settings!$B$6:$B$11),1)
B16: Jul | C16: =IF(Dashboard!$E$4="All properties",SUM(Bookings!$Y$6:$Y$505),SUMIFS(Bookings!$Y$6:$Y$505,Bookings!$B$6:$B$505,$E$4)) | D16: =IF($N16=0,"",C16/$N16) | E16: =IF(Dashboard!$E$4="All properties",SUMPRODUCT(Bookings!$Y$6:$Y$505,Bookings!$Q$6:$Q$505),SUMPRODUCT(Bookings!$Y$6:$Y$505,Bookings!$Q$6:$Q$505,--(Bookings!$B$6:$B$505=$E$4))) | F16: =IF(Dashboard!$E$4="All properties",SUMIFS(Expenses!$E$6:$E$505,Expenses!$B$6:$B$505,">="&DATE($C$4,7,1),Expenses!$B$6:$B$505,"<="&EOMONTH(DATE($C$4,7,1),0)),SUMIFS(Expenses!$E$6:$E$505,Expenses!$B$6:$B$505,">="&DATE($C$4,7,1),Expenses!$B$6:$B$505,"<="&EOMONTH(DATE($C$4,7,1),0),Expenses!$C$6:$C$505,$E$4)) | G16: =E16-F16 | I16: =IF($M16="","",INT($M16)) | J16: =IF($M16="","",INDEX(Bookings!$B$6:$B$505,MATCH($M16,Bookings!$AI$6:$AI$505,0))) | K16: =IF($M16="","",INDEX(Bookings!$C$6:$C$505,MATCH($M16,Bookings!$AI$6:$AI$505,0))) | M16: =IFERROR(SMALL(Bookings!$AI$6:$AI$505,1),"") | N16: =DAY(EOMONTH(DATE($C$4,7,1),0))*IF(Dashboard!$E$4="All properties",COUNTA(Settings!$B$6:$B$11),1)
B17: Aug | C17: =IF(Dashboard!$E$4="All properties",SUM(Bookings!$Z$6:$Z$505),SUMIFS(Bookings!$Z$6:$Z$505,Bookings!$B$6:$B$505,$E$4)) | D17: =IF($N17=0,"",C17/$N17) | E17: =IF(Dashboard!$E$4="All properties",SUMPRODUCT(Bookings!$Z$6:$Z$505,Bookings!$Q$6:$Q$505),SUMPRODUCT(Bookings!$Z$6:$Z$505,Bookings!$Q$6:$Q$505,--(Bookings!$B$6:$B$505=$E$4))) | F17: =IF(Dashboard!$E$4="All properties",SUMIFS(Expenses!$E$6:$E$505,Expenses!$B$6:$B$505,">="&DATE($C$4,8,1),Expenses!$B$6:$B$505,"<="&EOMONTH(DATE($C$4,8,1),0)),SUMIFS(Expenses!$E$6:$E$505,Expenses!$B$6:$B$505,">="&DATE($C$4,8,1),Expenses!$B$6:$B$505,"<="&EOMONTH(DATE($C$4,8,1),0),Expenses!$C$6:$C$505,$E$4)) | G17: =E17-F17 | I17: =IF($M17="","",INT($M17)) | J17: =IF($M17="","",INDEX(Bookings!$B$6:$B$505,MATCH($M17,Bookings!$AI$6:$AI$505,0))) | K17: =IF($M17="","",INDEX(Bookings!$C$6:$C$505,MATCH($M17,Bookings!$AI$6:$AI$505,0))) | M17: =IFERROR(SMALL(Bookings!$AI$6:$AI$505,2),"") | N17: =DAY(EOMONTH(DATE($C$4,8,1),0))*IF(Dashboard!$E$4="All properties",COUNTA(Settings!$B$6:$B$11),1)
B18: Sep | C18: =IF(Dashboard!$E$4="All properties",SUM(Bookings!$AA$6:$AA$505),SUMIFS(Bookings!$AA$6:$AA$505,Bookings!$B$6:$B$505,$E$4)) | D18: =IF($N18=0,"",C18/$N18) | E18: =IF(Dashboard!$E$4="All properties",SUMPRODUCT(Bookings!$AA$6:$AA$505,Bookings!$Q$6:$Q$505),SUMPRODUCT(Bookings!$AA$6:$AA$505,Bookings!$Q$6:$Q$505,--(Bookings!$B$6:$B$505=$E$4))) | F18: =IF(Dashboard!$E$4="All properties",SUMIFS(Expenses!$E$6:$E$505,Expenses!$B$6:$B$505,">="&DATE($C$4,9,1),Expenses!$B$6:$B$505,"<="&EOMONTH(DATE($C$4,9,1),0)),SUMIFS(Expenses!$E$6:$E$505,Expenses!$B$6:$B$505,">="&DATE($C$4,9,1),Expenses!$B$6:$B$505,"<="&EOMONTH(DATE($C$4,9,1),0),Expenses!$C$6:$C$505,$E$4)) | G18: =E18-F18 | I18: =IF($M18="","",INT($M18)) | J18: =IF($M18="","",INDEX(Bookings!$B$6:$B$505,MATCH($M18,Bookings!$AI$6:$AI$505,0))) | K18: =IF($M18="","",INDEX(Bookings!$C$6:$C$505,MATCH($M18,Bookings!$AI$6:$AI$505,0))) | M18: =IFERROR(SMALL(Bookings!$AI$6:$AI$505,3),"") | N18: =DAY(EOMONTH(DATE($C$4,9,1),0))*IF(Dashboard!$E$4="All properties",COUNTA(Settings!$B$6:$B$11),1)
B19: Oct | C19: =IF(Dashboard!$E$4="All properties",SUM(Bookings!$AB$6:$AB$505),SUMIFS(Bookings!$AB$6:$AB$505,Bookings!$B$6:$B$505,$E$4)) | D19: =IF($N19=0,"",C19/$N19) | E19: =IF(Dashboard!$E$4="All properties",SUMPRODUCT(Bookings!$AB$6:$AB$505,Bookings!$Q$6:$Q$505),SUMPRODUCT(Bookings!$AB$6:$AB$505,Bookings!$Q$6:$Q$505,--(Bookings!$B$6:$B$505=$E$4))) | F19: =IF(Dashboard!$E$4="All properties",SUMIFS(Expenses!$E$6:$E$505,Expenses!$B$6:$B$505,">="&DATE($C$4,10,1),Expenses!$B$6:$B$505,"<="&EOMONTH(DATE($C$4,10,1),0)),SUMIFS(Expenses!$E$6:$E$505,Expenses!$B$6:$B$505,">="&DATE($C$4,10,1),Expenses!$B$6:$B$505,"<="&EOMONTH(DATE($C$4,10,1),0),Expenses!$C$6:$C$505,$E$4)) | G19: =E19-F19 | I19: =IF($M19="","",INT($M19)) | J19: =IF($M19="","",INDEX(Bookings!$B$6:$B$505,MATCH($M19,Bookings!$AI$6:$AI$505,0))) | K19: =IF($M19="","",INDEX(Bookings!$C$6:$C$505,MATCH($M19,Bookings!$AI$6:$AI$505,0))) | M19: =IFERROR(SMALL(Bookings!$AI$6:$AI$505,4),"") | N19: =DAY(EOMONTH(DATE($C$4,10,1),0))*IF(Dashboard!$E$4="All properties",COUNTA(Settings!$B$6:$B$11),1)
B20: Nov | C20: =IF(Dashboard!$E$4="All properties",SUM(Bookings!$AC$6:$AC$505),SUMIFS(Bookings!$AC$6:$AC$505,Bookings!$B$6:$B$505,$E$4)) | D20: =IF($N20=0,"",C20/$N20) | E20: =IF(Dashboard!$E$4="All properties",SUMPRODUCT(Bookings!$AC$6:$AC$505,Bookings!$Q$6:$Q$505),SUMPRODUCT(Bookings!$AC$6:$AC$505,Bookings!$Q$6:$Q$505,--(Bookings!$B$6:$B$505=$E$4))) | F20: =IF(Dashboard!$E$4="All properties",SUMIFS(Expenses!$E$6:$E$505,Expenses!$B$6:$B$505,">="&DATE($C$4,11,1),Expenses!$B$6:$B$505,"<="&EOMONTH(DATE($C$4,11,1),0)),SUMIFS(Expenses!$E$6:$E$505,Expenses!$B$6:$B$505,">="&DATE($C$4,11,1),Expenses!$B$6:$B$505,"<="&EOMONTH(DATE($C$4,11,1),0),Expenses!$C$6:$C$505,$E$4)) | G20: =E20-F20 | I20: =IF($M20="","",INT($M20)) | J20: =IF($M20="","",INDEX(Bookings!$B$6:$B$505,MATCH($M20,Bookings!$AI$6:$AI$505,0))) | K20: =IF($M20="","",INDEX(Bookings!$C$6:$C$505,MATCH($M20,Bookings!$AI$6:$AI$505,0))) | M20: =IFERROR(SMALL(Bookings!$AI$6:$AI$505,5),"") | N20: =DAY(EOMONTH(DATE($C$4,11,1),0))*IF(Dashboard!$E$4="All properties",COUNTA(Settings!$B$6:$B$11),1)
B21: Dec | C21: =IF(Dashboard!$E$4="All properties",SUM(Bookings!$AD$6:$AD$505),SUMIFS(Bookings!$AD$6:$AD$505,Bookings!$B$6:$B$505,$E$4)) | D21: =IF($N21=0,"",C21/$N21) | E21: =IF(Dashboard!$E$4="All properties",SUMPRODUCT(Bookings!$AD$6:$AD$505,Bookings!$Q$6:$Q$505),SUMPRODUCT(Bookings!$AD$6:$AD$505,Bookings!$Q$6:$Q$505,--(Bookings!$B$6:$B$505=$E$4))) | F21: =IF(Dashboard!$E$4="All properties",SUMIFS(Expenses!$E$6:$E$505,Expenses!$B$6:$B$505,">="&DATE($C$4,12,1),Expenses!$B$6:$B$505,"<="&EOMONTH(DATE($C$4,12,1),0)),SUMIFS(Expenses!$E$6:$E$505,Expenses!$B$6:$B$505,">="&DATE($C$4,12,1),Expenses!$B$6:$B$505,"<="&EOMONTH(DATE($C$4,12,1),0),Expenses!$C$6:$C$505,$E$4)) | G21: =E21-F21 | N21: =DAY(EOMONTH(DATE($C$4,12,1),0))*IF(Dashboard!$E$4="All properties",COUNTA(Settings!$B$6:$B$11),1)
B22: Year | C22: =SUM(C10:C21) | D22: =IF(SUM(N10:N21)=0,"",C22/SUM(N10:N21)) | E22: =SUM(E10:E21) | F22: =SUM(F10:F21) | G22: =SUM(G10:G21)
B24: Property | C24: Nights | D24: Occupancy | E24: Revenue | F24: Expenses | G24: Profit
B25: =IF(Settings!B6="","",Settings!B6) | C25: =IF(B25="","",SUMIFS(Bookings!$AE$6:$AE$505,Bookings!$B$6:$B$505,B25)) | D25: =IF(OR(B25="",$N$2=0),"",SUMIFS(Bookings!$AH$6:$AH$505,Bookings!$B$6:$B$505,B25)/$N$2) | E25: =IF(B25="","",SUMIFS(Bookings!$AF$6:$AF$505,Bookings!$B$6:$B$505,B25)) | F25: =IF(B25="","",SUMIFS(Expenses!$E$6:$E$505,Expenses!$C$6:$C$505,B25,Expenses!$B$6:$B$505,">="&DATE($C$4,1,1),Expenses!$B$6:$B$505,"<="&DATE($C$4,12,31))) | G25: =IF(B25="","",E25-F25) | I25: Next check-outs | J25: Property | K25: Same-day arrival
B26: =IF(Settings!B7="","",Settings!B7) | C26: =IF(B26="","",SUMIFS(Bookings!$AE$6:$AE$505,Bookings!$B$6:$B$505,B26)) | D26: =IF(OR(B26="",$N$2=0),"",SUMIFS(Bookings!$AH$6:$AH$505,Bookings!$B$6:$B$505,B26)/$N$2) | E26: =IF(B26="","",SUMIFS(Bookings!$AF$6:$AF$505,Bookings!$B$6:$B$505,B26)) | F26: =IF(B26="","",SUMIFS(Expenses!$E$6:$E$505,Expenses!$C$6:$C$505,B26,Expenses!$B$6:$B$505,">="&DATE($C$4,1,1),Expenses!$B$6:$B$505,"<="&DATE($C$4,12,31))) | G26: =IF(B26="","",E26-F26) | I26: =IF($M26="","",INT($M26)) | J26: =IF($M26="","",INDEX(Bookings!$B$6:$B$505,MATCH($M26,Bookings!$AJ$6:$AJ$505,0))) | K26: =IF($M26="","",IF(COUNTIFS(Bookings!$B$6:$B$505,J26,Bookings!$E$6:$E$505,I26)>0,"Yes","No")) | M26: =IFERROR(SMALL(Bookings!$AJ$6:$AJ$505,1),"")
B27: =IF(Settings!B8="","",Settings!B8) | C27: =IF(B27="","",SUMIFS(Bookings!$AE$6:$AE$505,Bookings!$B$6:$B$505,B27)) | D27: =IF(OR(B27="",$N$2=0),"",SUMIFS(Bookings!$AH$6:$AH$505,Bookings!$B$6:$B$505,B27)/$N$2) | E27: =IF(B27="","",SUMIFS(Bookings!$AF$6:$AF$505,Bookings!$B$6:$B$505,B27)) | F27: =IF(B27="","",SUMIFS(Expenses!$E$6:$E$505,Expenses!$C$6:$C$505,B27,Expenses!$B$6:$B$505,">="&DATE($C$4,1,1),Expenses!$B$6:$B$505,"<="&DATE($C$4,12,31))) | G27: =IF(B27="","",E27-F27) | I27: =IF($M27="","",INT($M27)) | J27: =IF($M27="","",INDEX(Bookings!$B$6:$B$505,MATCH($M27,Bookings!$AJ$6:$AJ$505,0))) | K27: =IF($M27="","",IF(COUNTIFS(Bookings!$B$6:$B$505,J27,Bookings!$E$6:$E$505,I27)>0,"Yes","No")) | M27: =IFERROR(SMALL(Bookings!$AJ$6:$AJ$505,2),"")
B28: =IF(Settings!B9="","",Settings!B9) | C28: =IF(B28="","",SUMIFS(Bookings!$AE$6:$AE$505,Bookings!$B$6:$B$505,B28)) | D28: =IF(OR(B28="",$N$2=0),"",SUMIFS(Bookings!$AH$6:$AH$505,Bookings!$B$6:$B$505,B28)/$N$2) | E28: =IF(B28="","",SUMIFS(Bookings!$AF$6:$AF$505,Bookings!$B$6:$B$505,B28)) | F28: =IF(B28="","",SUMIFS(Expenses!$E$6:$E$505,Expenses!$C$6:$C$505,B28,Expenses!$B$6:$B$505,">="&DATE($C$4,1,1),Expenses!$B$6:$B$505,"<="&DATE($C$4,12,31))) | G28: =IF(B28="","",E28-F28) | I28: =IF($M28="","",INT($M28)) | J28: =IF($M28="","",INDEX(Bookings!$B$6:$B$505,MATCH($M28,Bookings!$AJ$6:$AJ$505,0))) | K28: =IF($M28="","",IF(COUNTIFS(Bookings!$B$6:$B$505,J28,Bookings!$E$6:$E$505,I28)>0,"Yes","No")) | M28: =IFERROR(SMALL(Bookings!$AJ$6:$AJ$505,3),"")
B29: =IF(Settings!B10="","",Settings!B10) | C29: =IF(B29="","",SUMIFS(Bookings!$AE$6:$AE$505,Bookings!$B$6:$B$505,B29)) | D29: =IF(OR(B29="",$N$2=0),"",SUMIFS(Bookings!$AH$6:$AH$505,Bookings!$B$6:$B$505,B29)/$N$2) | E29: =IF(B29="","",SUMIFS(Bookings!$AF$6:$AF$505,Bookings!$B$6:$B$505,B29)) | F29: =IF(B29="","",SUMIFS(Expenses!$E$6:$E$505,Expenses!$C$6:$C$505,B29,Expenses!$B$6:$B$505,">="&DATE($C$4,1,1),Expenses!$B$6:$B$505,"<="&DATE($C$4,12,31))) | G29: =IF(B29="","",E29-F29) | I29: =IF($M29="","",INT($M29)) | J29: =IF($M29="","",INDEX(Bookings!$B$6:$B$505,MATCH($M29,Bookings!$AJ$6:$AJ$505,0))) | K29: =IF($M29="","",IF(COUNTIFS(Bookings!$B$6:$B$505,J29,Bookings!$E$6:$E$505,I29)>0,"Yes","No")) | M29: =IFERROR(SMALL(Bookings!$AJ$6:$AJ$505,4),"")
B30: =IF(Settings!B11="","",Settings!B11) | C30: =IF(B30="","",SUMIFS(Bookings!$AE$6:$AE$505,Bookings!$B$6:$B$505,B30)) | D30: =IF(OR(B30="",$N$2=0),"",SUMIFS(Bookings!$AH$6:$AH$505,Bookings!$B$6:$B$505,B30)/$N$2) | E30: =IF(B30="","",SUMIFS(Bookings!$AF$6:$AF$505,Bookings!$B$6:$B$505,B30)) | F30: =IF(B30="","",SUMIFS(Expenses!$E$6:$E$505,Expenses!$C$6:$C$505,B30,Expenses!$B$6:$B$505,">="&DATE($C$4,1,1),Expenses!$B$6:$B$505,"<="&DATE($C$4,12,31))) | G30: =IF(B30="","",E30-F30) | I30: =IF($M30="","",INT($M30)) | J30: =IF($M30="","",INDEX(Bookings!$B$6:$B$505,MATCH($M30,Bookings!$AJ$6:$AJ$505,0))) | K30: =IF($M30="","",IF(COUNTIFS(Bookings!$B$6:$B$505,J30,Bookings!$E$6:$E$505,I30)>0,"Yes","No")) | M30: =IFERROR(SMALL(Bookings!$AJ$6:$AJ$505,5),"")
B31: Shared costs | F31: =SUMIFS(Expenses!$E$6:$E$505,Expenses!$C$6:$C$505,"Shared",Expenses!$B$6:$B$505,">="&DATE($C$4,1,1),Expenses!$B$6:$B$505,"<="&DATE($C$4,12,31)) | G31: =-F31
B32: Occupancy here counts the months up to today. Shared costs belong to no single property.

Sheet Settings
B2: Settings
B3: Your properties and expense categories. The lists in the other tabs follow them.
B5: Properties (up to 6)
B6: Beach apartment | D6: Rename a property here and its bookings and expenses need the same new name. | F6: All properties | G6: Shared
B7: Mountain cabin | F7: =IF(B6="","",B6) | G7: =IF(B6="","",B6)
F8: =IF(B7="","",B7) | G8: =IF(B7="","",B7)
F9: =IF(B8="","",B8) | G9: =IF(B8="","",B8)
F10: =IF(B9="","",B9) | G10: =IF(B9="","",B9)
F11: =IF(B10="","",B10) | G11: =IF(B10="","",B10)
F12: =IF(B11="","",B11) | G12: =IF(B11="","",B11)
B14: Expense categories
B15: Cleaning
B16: Supplies
B17: Utilities
B18: Repairs
B19: Furnishing
B20: Insurance
B21: Taxes and fees
B22: Marketing
B23: Mortgage or rent
B24: Other

Sheet Bookings
B2: Bookings
B3: One line per stay, from any platform. Nights, payout and status are calculated.
B5: Property | C5: Guest | D5: Platform | E5: Check-in | F5: Check-out | G5: Nights | H5: Guests | I5: Booking total | J5: Cleaning fee | K5: Platform fee | L5: Payout | M5: Paid out? | N5: Status | O5: Note
B6: Mountain cabin | C6: Chloe A. | D6: Airbnb | E6: 46024 | F6: 46029 | G6: =IF(OR(E6="",F6=""),"",F6-E6) | H6: 4 | I6: 700 | J6: 80 | K6: 23.4 | L6: =IF(E6="","",N(I6)+N(J6)-N(K6)) | M6: Yes | N6: =IF(E6="","",IF(TODAY()<E6,"Upcoming",IF(TODAY()<F6,"Staying now",IF(M6="Yes","Checked out","Payout not received")))) | Q6: =IF(N(G6)>0,L6/G6,0) | R6: =IF(N(G6)>0,N(I6)/G6,0) | S6: =IF(OR($E6="",$F6=""),0,MAX(0,MIN($F6,DATE(Dashboard!$C$4,2,1))-MAX($E6,DATE(Dashboard!$C$4,1,1)))) | T6: =IF(OR($E6="",$F6=""),0,MAX(0,MIN($F6,DATE(Dashboard!$C$4,3,1))-MAX($E6,DATE(Dashboard!$C$4,2,1)))) | U6: =IF(OR($E6="",$F6=""),0,MAX(0,MIN($F6,DATE(Dashboard!$C$4,4,1))-MAX($E6,DATE(Dashboard!$C$4,3,1)))) | V6: =IF(OR($E6="",$F6=""),0,MAX(0,MIN($F6,DATE(Dashboard!$C$4,5,1))-MAX($E6,DATE(Dashboard!$C$4,4,1)))) | W6: =IF(OR($E6="",$F6=""),0,MAX(0,MIN($F6,DATE(Dashboard!$C$4,6,1))-MAX($E6,DATE(Dashboard!$C$4,5,1)))) | X6: =IF(OR($E6="",$F6=""),0,MAX(0,MIN($F6,DATE(Dashboard!$C$4,7,1))-MAX($E6,DATE(Dashboard!$C$4,6,1)))) | Y6: =IF(OR($E6="",$F6=""),0,MAX(0,MIN($F6,DATE(Dashboard!$C$4,8,1))-MAX($E6,DATE(Dashboard!$C$4,7,1)))) | Z6: =IF(OR($E6="",$F6=""),0,MAX(0,MIN($F6,DATE(Dashboard!$C$4,9,1))-MAX($E6,DATE(Dashboard!$C$4,8,1)))) | AA6: =IF(OR($E6="",$F6=""),0,MAX(0,MIN($F6,DATE(Dashboard!$C$4,10,1))-MAX($E6,DATE(Dashboard!$C$4,9,1)))) | AB6: =IF(OR($E6="",$F6=""),0,MAX(0,MIN($F6,DATE(Dashboard!$C$4,11,1))-MAX($E6,DATE(Dashboard!$C$4,10,1)))) | AC6: =IF(OR($E6="",$F6=""),0,MAX(0,MIN($F6,DATE(Dashboard!$C$4,12,1))-MAX($E6,DATE(Dashboard!$C$4,11,1)))) | AD6: =IF(OR($E6="",$F6=""),0,MAX(0,MIN($F6,DATE(Dashboard!$C$4,13,1))-MAX($E6,DATE(Dashboard!$C$4,12,1)))) | AE6: =SUM(S6:AD6) | AF6: =Q6*AE6 | AG6: =R6*AE6 | AH6: =SUMPRODUCT(S6:AD6,--(COLUMN(S6:AD6)-COLUMN(S6)+1<=Dashboard!$N$1)) | AI6: =IF(OR(E6="",E6<TODAY()),"",E6+ROW()/100000) | AJ6: =IF(OR(F6="",F6<TODAY()),"",F6+ROW()/100000)
B7: Mountain cabin | C7: Nora C. | D7: Booking.com | E7: 46029 | F7: 46033 | G7: =IF(OR(E7="",F7=""),"",F7-E7) | H7: 2 | I7: 560 | J7: 80 | K7: 96 | L7: =IF(E7="","",N(I7)+N(J7)-N(K7)) | M7: Yes | N7: =IF(E7="","",IF(TODAY()<E7,"Upcoming",IF(TODAY()<F7,"Staying now",IF(M7="Yes","Checked out","Payout not received")))) | Q7: =IF(N(G7)>0,L7/G7,0) | R7: =IF(N(G7)>0,N(I7)/G7,0) | S7: =IF(OR($E7="",$F7=""),0,MAX(0,MIN($F7,DATE(Dashboard!$C$4,2,1))-MAX($E7,DATE(Dashboard!$C$4,1,1)))) | T7: =IF(OR($E7="",$F7=""),0,MAX(0,MIN($F7,DATE(Dashboard!$C$4,3,1))-MAX($E7,DATE(Dashboard!$C$4,2,1)))) | U7: =IF(OR($E7="",$F7=""),0,MAX(0,MIN($F7,DATE(Dashboard!$C$4,4,1))-MAX($E7,DATE(Dashboard!$C$4,3,1)))) | V7: =IF(OR($E7="",$F7=""),0,MAX(0,MIN($F7,DATE(Dashboard!$C$4,5,1))-MAX($E7,DATE(Dashboard!$C$4,4,1)))) | W7: =IF(OR($E7="",$F7=""),0,MAX(0,MIN($F7,DATE(Dashboard!$C$4,6,1))-MAX($E7,DATE(Dashboard!$C$4,5,1)))) | X7: =IF(OR($E7="",$F7=""),0,MAX(0,MIN($F7,DATE(Dashboard!$C$4,7,1))-MAX($E7,DATE(Dashboard!$C$4,6,1)))) | Y7: =IF(OR($E7="",$F7=""),0,MAX(0,MIN($F7,DATE(Dashboard!$C$4,8,1))-MAX($E7,DATE(Dashboard!$C$4,7,1)))) | Z7: =IF(OR($E7="",$F7=""),0,MAX(0,MIN($F7,DATE(Dashboard!$C$4,9,1))-MAX($E7,DATE(Dashboard!$C$4,8,1)))) | AA7: =IF(OR($E7="",$F7=""),0,MAX(0,MIN($F7,DATE(Dashboard!$C$4,10,1))-MAX($E7,DATE(Dashboard!$C$4,9,1)))) | AB7: =IF(OR($E7="",$F7=""),0,MAX(0,MIN($F7,DATE(Dashboard!$C$4,11,1))-MAX($E7,DATE(Dashboard!$C$4,10,1)))) | AC7: =IF(OR($E7="",$F7=""),0,MAX(0,MIN($F7,DATE(Dashboard!$C$4,12,1))-MAX($E7,DATE(Dashboard!$C$4,11,1)))) | AD7: =IF(OR($E7="",$F7=""),0,MAX(0,MIN($F7,DATE(Dashboard!$C$4,13,1))-MAX($E7,DATE(Dashboard!$C$4,12,1)))) | AE7: =SUM(S7:AD7) | AF7: =Q7*AE7 | AG7: =R7*AE7 | AH7: =SUMPRODUCT(S7:AD7,--(COLUMN(S7:AD7)-COLUMN(S7)+1<=Dashboard!$N$1)) | AI7: =IF(OR(E7="",E7<TODAY()),"",E7+ROW()/100000) | AJ7: =IF(OR(F7="",F7<TODAY()),"",F7+ROW()/100000)
B8: Beach apartment | C8: Ruby J. | D8: Airbnb | E8: 46033 | F8: 46039 | G8: =IF(OR(E8="",F8=""),"",F8-E8) | H8: 2 | I8: 570 | J8: 60 | K8: 18.9 | L8: =IF(E8="","",N(I8)+N(J8)-N(K8)) | M8: Yes | N8: =IF(E8="","",IF(TODAY()<E8,"Upcoming",IF(TODAY()<F8,"Staying now",IF(M8="Yes","Checked out","Payout not received")))) | Q8: =IF(N(G8)>0,L8/G8,0) | R8: =IF(N(G8)>0,N(I8)/G8,0) | S8: =IF(OR($E8="",$F8=""),0,MAX(0,MIN($F8,DATE(Dashboard!$C$4,2,1))-MAX($E8,DATE(Dashboard!$C$4,1,1)))) | T8: =IF(OR($E8="",$F8=""),0,MAX(0,MIN($F8,DATE(Dashboard!$C$4,3,1))-MAX($E8,DATE(Dashboard!$C$4,2,1)))) | U8: =IF(OR($E8="",$F8=""),0,MAX(0,MIN($F8,DATE(Dashboard!$C$4,4,1))-MAX($E8,DATE(Dashboard!$C$4,3,1)))) | V8: =IF(OR($E8="",$F8=""),0,MAX(0,MIN($F8,DATE(Dashboard!$C$4,5,1))-MAX($E8,DATE(Dashboard!$C$4,4,1)))) | W8: =IF(OR($E8="",$F8=""),0,MAX(0,MIN($F8,DATE(Dashboard!$C$4,6,1))-MAX($E8,DATE(Dashboard!$C$4,5,1)))) | X8: =IF(OR($E8="",$F8=""),0,MAX(0,MIN($F8,DATE(Dashboard!$C$4,7,1))-MAX($E8,DATE(Dashboard!$C$4,6,1)))) | Y8: =IF(OR($E8="",$F8=""),0,MAX(0,MIN($F8,DATE(Dashboard!$C$4,8,1))-MAX($E8,DATE(Dashboard!$C$4,7,1)))) | Z8: =IF(OR($E8="",$F8=""),0,MAX(0,MIN($F8,DATE(Dashboard!$C$4,9,1))-MAX($E8,DATE(Dashboard!$C$4,8,1)))) | AA8: =IF(OR($E8="",$F8=""),0,MAX(0,MIN($F8,DATE(Dashboard!$C$4,10,1))-MAX($E8,DATE(Dashboard!$C$4,9,1)))) | AB8: =IF(OR($E8="",$F8=""),0,MAX(0,MIN($F8,DATE(Dashboard!$C$4,11,1))-MAX($E8,DATE(Dashboard!$C$4,10,1)))) | AC8: =IF(OR($E8="",$F8=""),0,MAX(0,MIN($F8,DATE(Dashboard!$C$4,12,1))-MAX($E8,DATE(Dashboard!$C$4,11,1)))) | AD8: =IF(OR($E8="",$F8=""),0,MAX(0,MIN($F8,DATE(Dashboard!$C$4,13,1))-MAX($E8,DATE(Dashboard!$C$4,12,1)))) | AE8: =SUM(S8:AD8) | AF8: =Q8*AE8 | AG8: =R8*AE8 | AH8: =SUMPRODUCT(S8:AD8,--(COLUMN(S8:AD8)-COLUMN(S8)+1<=Dashboard!$N$1)) | AI8: =IF(OR(E8="",E8<TODAY()),"",E8+ROW()/100000) | AJ8: =IF(OR(F8="",F8<TODAY()),"",F8+ROW()/100000)
B9: Mountain cabin | C9: Ethan S. | D9: Vrbo | E9: 46036 | F9: 46038 | G9: =IF(OR(E9="",F9=""),"",F9-E9) | H9: 3 | I9: 280 | J9: 80 | K9: 18 | L9: =IF(E9="","",N(I9)+N(J9)-N(K9)) | M9: Yes | N9: =IF(E9="","",IF(TODAY()<E9,"Upcoming",IF(TODAY()<F9,"Staying now",IF(M9="Yes","Checked out","Payout not received")))) | Q9: =IF(N(G9)>0,L9/G9,0) | R9: =IF(N(G9)>0,N(I9)/G9,0) | S9: =IF(OR($E9="",$F9=""),0,MAX(0,MIN($F9,DATE(Dashboard!$C$4,2,1))-MAX($E9,DATE(Dashboard!$C$4,1,1)))) | T9: =IF(OR($E9="",$F9=""),0,MAX(0,MIN($F9,DATE(Dashboard!$C$4,3,1))-MAX($E9,DATE(Dashboard!$C$4,2,1)))) | U9: =IF(OR($E9="",$F9=""),0,MAX(0,MIN($F9,DATE(Dashboard!$C$4,4,1))-MAX($E9,DATE(Dashboard!$C$4,3,1)))) | V9: =IF(OR($E9="",$F9=""),0,MAX(0,MIN($F9,DATE(Dashboard!$C$4,5,1))-MAX($E9,DATE(Dashboard!$C$4,4,1)))) | W9: =IF(OR($E9="",$F9=""),0,MAX(0,MIN($F9,DATE(Dashboard!$C$4,6,1))-MAX($E9,DATE(Dashboard!$C$4,5,1)))) | X9: =IF(OR($E9="",$F9=""),0,MAX(0,MIN($F9,DATE(Dashboard!$C$4,7,1))-MAX($E9,DATE(Dashboard!$C$4,6,1)))) | Y9: =IF(OR($E9="",$F9=""),0,MAX(0,MIN($F9,DATE(Dashboard!$C$4,8,1))-MAX($E9,DATE(Dashboard!$C$4,7,1)))) | Z9: =IF(OR($E9="",$F9=""),0,MAX(0,MIN($F9,DATE(Dashboard!$C$4,9,1))-MAX($E9,DATE(Dashboard!$C$4,8,1)))) | AA9: =IF(OR($E9="",$F9=""),0,MAX(0,MIN($F9,DATE(Dashboard!$C$4,10,1))-MAX($E9,DATE(Dashboard!$C$4,9,1)))) | AB9: =IF(OR($E9="",$F9=""),0,MAX(0,MIN($F9,DATE(Dashboard!$C$4,11,1))-MAX($E9,DATE(Dashboard!$C$4,10,1)))) | AC9: =IF(OR($E9="",$F9=""),0,MAX(0,MIN($F9,DATE(Dashboard!$C$4,12,1))-MAX($E9,DATE(Dashboard!$C$4,11,1)))) | AD9: =IF(OR($E9="",$F9=""),0,MAX(0,MIN($F9,DATE(Dashboard!$C$4,13,1))-MAX($E9,DATE(Dashboard!$C$4,12,1)))) | AE9: =SUM(S9:AD9) | AF9: =Q9*AE9 | AG9: =R9*AE9 | AH9: =SUMPRODUCT(S9:AD9,--(COLUMN(S9:AD9)-COLUMN(S9)+1<=Dashboard!$N$1)) | AI9: =IF(OR(E9="",E9<TODAY()),"",E9+ROW()/100000) | AJ9: =IF(OR(F9="",F9<TODAY()),"",F9+ROW()/100000)
B10: Mountain cabin | C10: Owen E. | D10: Direct | E10: 46038 | F10: 46045 | G10: =IF(OR(E10="",F10=""),"",F10-E10) | H10: 5 | I10: 980 | J10: 80 | K10: 0 | L10: =IF(E10="","",N(I10)+N(J10)-N(K10)) | M10: Yes | N10: =IF(E10="","",IF(TODAY()<E10,"Upcoming",IF(TODAY()<F10,"Staying now",IF(M10="Yes","Checked out","Payout not received")))) | Q10: =IF(N(G10)>0,L10/G10,0) | R10: =IF(N(G10)>0,N(I10)/G10,0) | S10: =IF(OR($E10="",$F10=""),0,MAX(0,MIN($F10,DATE(Dashboard!$C$4,2,1))-MAX($E10,DATE(Dashboard!$C$4,1,1)))) | T10: =IF(OR($E10="",$F10=""),0,MAX(0,MIN($F10,DATE(Dashboard!$C$4,3,1))-MAX($E10,DATE(Dashboard!$C$4,2,1)))) | U10: =IF(OR($E10="",$F10=""),0,MAX(0,MIN($F10,DATE(Dashboard!$C$4,4,1))-MAX($E10,DATE(Dashboard!$C$4,3,1)))) | V10: =IF(OR($E10="",$F10=""),0,MAX(0,MIN($F10,DATE(Dashboard!$C$4,5,1))-MAX($E10,DATE(Dashboard!$C$4,4,1)))) | W10: =IF(OR($E10="",$F10=""),0,MAX(0,MIN($F10,DATE(Dashboard!$C$4,6,1))-MAX($E10,DATE(Dashboard!$C$4,5,1)))) | X10: =IF(OR($E10="",$F10=""),0,MAX(0,MIN($F10,DATE(Dashboard!$C$4,7,1))-MAX($E10,DATE(Dashboard!$C$4,6,1)))) | Y10: =IF(OR($E10="",$F10=""),0,MAX(0,MIN($F10,DATE(Dashboard!$C$4,8,1))-MAX($E10,DATE(Dashboard!$C$4,7,1)))) | Z10: =IF(OR($E10="",$F10=""),0,MAX(0,MIN($F10,DATE(Dashboard!$C$4,9,1))-MAX($E10,DATE(Dashboard!$C$4,8,1)))) | AA10: =IF(OR($E10="",$F10=""),0,MAX(0,MIN($F10,DATE(Dashboard!$C$4,10,1))-MAX($E10,DATE(Dashboard!$C$4,9,1)))) | AB10: =IF(OR($E10="",$F10=""),0,MAX(0,MIN($F10,DATE(Dashboard!$C$4,11,1))-MAX($E10,DATE(Dashboard!$C$4,10,1)))) | AC10: =IF(OR($E10="",$F10=""),0,MAX(0,MIN($F10,DATE(Dashboard!$C$4,12,1))-MAX($E10,DATE(Dashboard!$C$4,11,1)))) | AD10: =IF(OR($E10="",$F10=""),0,MAX(0,MIN($F10,DATE(Dashboard!$C$4,13,1))-MAX($E10,DATE(Dashboard!$C$4,12,1)))) | AE10: =SUM(S10:AD10) | AF10: =Q10*AE10 | AG10: =R10*AE10 | AH10: =SUMPRODUCT(S10:AD10,--(COLUMN(S10:AD10)-COLUMN(S10)+1<=Dashboard!$N$1)) | AI10: =IF(OR(E10="",E10<TODAY()),"",E10+ROW()/100000) | AJ10: =IF(OR(F10="",F10<TODAY()),"",F10+ROW()/100000)
B11: Mountain cabin | C11: Olivia L. | D11: Airbnb | E11: 46045 | F11: 46048 | G11: =IF(OR(E11="",F11=""),"",F11-E11) | H11: 3 | I11: 420 | J11: 80 | K11: 15 | L11: =IF(E11="","",N(I11)+N(J11)-N(K11)) | M11: Yes | N11: =IF(E11="","",IF(TODAY()<E11,"Upcoming",IF(TODAY()<F11,"Staying now",IF(M11="Yes","Checked out","Payout not received")))) | Q11: =IF(N(G11)>0,L11/G11,0) | R11: =IF(N(G11)>0,N(I11)/G11,0) | S11: =IF(OR($E11="",$F11=""),0,MAX(0,MIN($F11,DATE(Dashboard!$C$4,2,1))-MAX($E11,DATE(Dashboard!$C$4,1,1)))) | T11: =IF(OR($E11="",$F11=""),0,MAX(0,MIN($F11,DATE(Dashboard!$C$4,3,1))-MAX($E11,DATE(Dashboard!$C$4,2,1)))) | U11: =IF(OR($E11="",$F11=""),0,MAX(0,MIN($F11,DATE(Dashboard!$C$4,4,1))-MAX($E11,DATE(Dashboard!$C$4,3,1)))) | V11: =IF(OR($E11="",$F11=""),0,MAX(0,MIN($F11,DATE(Dashboard!$C$4,5,1))-MAX($E11,DATE(Dashboard!$C$4,4,1)))) | W11: =IF(OR($E11="",$F11=""),0,MAX(0,MIN($F11,DATE(Dashboard!$C$4,6,1))-MAX($E11,DATE(Dashboard!$C$4,5,1)))) | X11: =IF(OR($E11="",$F11=""),0,MAX(0,MIN($F11,DATE(Dashboard!$C$4,7,1))-MAX($E11,DATE(Dashboard!$C$4,6,1)))) | Y11: =IF(OR($E11="",$F11=""),0,MAX(0,MIN($F11,DATE(Dashboard!$C$4,8,1))-MAX($E11,DATE(Dashboard!$C$4,7,1)))) | Z11: =IF(OR($E11="",$F11=""),0,MAX(0,MIN($F11,DATE(Dashboard!$C$4,9,1))-MAX($E11,DATE(Dashboard!$C$4,8,1)))) | AA11: =IF(OR($E11="",$F11=""),0,MAX(0,MIN($F11,DATE(Dashboard!$C$4,10,1))-MAX($E11,DATE(Dashboard!$C$4,9,1)))) | AB11: =IF(OR($E11="",$F11=""),0,MAX(0,MIN($F11,DATE(Dashboard!$C$4,11,1))-MAX($E11,DATE(Dashboard!$C$4,10,1)))) | AC11: =IF(OR($E11="",$F11=""),0,MAX(0,MIN($F11,DATE(Dashboard!$C$4,12,1))-MAX($E11,DATE(Dashboard!$C$4,11,1)))) | AD11: =IF(OR($E11="",$F11=""),0,MAX(0,MIN($F11,DATE(Dashboard!$C$4,13,1))-MAX($E11,DATE(Dashboard!$C$4,12,1)))) | AE11: =SUM(S11:AD11) | AF11: =Q11*AE11 | AG11: =R11*AE11 | AH11: =SUMPRODUCT(S11:AD11,--(COLUMN(S11:AD11)-COLUMN(S11)+1<=Dashboard!$N$1)) | AI11: =IF(OR(E11="",E11<TODAY()),"",E11+ROW()/100000) | AJ11: =IF(OR(F11="",F11<TODAY()),"",F11+ROW()/100000)
B12: Beach apartment | C12: Hugo H. | D12: Booking.com | E12: 46048 | F12: 46053 | G12: =IF(OR(E12="",F12=""),"",F12-E12) | H12: 3 | I12: 475 | J12: 60 | K12: 80.25 | L12: =IF(E12="","",N(I12)+N(J12)-N(K12)) | M12: Yes | N12: =IF(E12="","",IF(TODAY()<E12,"Upcoming",IF(TODAY()<F12,"Staying now",IF(M12="Yes","Checked out","Payout not received")))) | Q12: =IF(N(G12)>0,L12/G12,0) | R12: =IF(N(G12)>0,N(I12)/G12,0) | S12: =IF(OR($E12="",$F12=""),0,MAX(0,MIN($F12,DATE(Dashboard!$C$4,2,1))-MAX($E12,DATE(Dashboard!$C$4,1,1)))) | T12: =IF(OR($E12="",$F12=""),0,MAX(0,MIN($F12,DATE(Dashboard!$C$4,3,1))-MAX($E12,DATE(Dashboard!$C$4,2,1)))) | U12: =IF(OR($E12="",$F12=""),0,MAX(0,MIN($F12,DATE(Dashboard!$C$4,4,1))-MAX($E12,DATE(Dashboard!$C$4,3,1)))) | V12: =IF(OR($E12="",$F12=""),0,MAX(0,MIN($F12,DATE(Dashboard!$C$4,5,1))-MAX($E12,DATE(Dashboard!$C$4,4,1)))) | W12: =IF(OR($E12="",$F12=""),0,MAX(0,MIN($F12,DATE(Dashboard!$C$4,6,1))-MAX($E12,DATE(Dashboard!$C$4,5,1)))) | X12: =IF(OR($E12="",$F12=""),0,MAX(0,MIN($F12,DATE(Dashboard!$C$4,7,1))-MAX($E12,DATE(Dashboard!$C$4,6,1)))) | Y12: =IF(OR($E12="",$F12=""),0,MAX(0,MIN($F12,DATE(Dashboard!$C$4,8,1))-MAX($E12,DATE(Dashboard!$C$4,7,1)))) | Z12: =IF(OR($E12="",$F12=""),0,MAX(0,MIN($F12,DATE(Dashboard!$C$4,9,1))-MAX($E12,DATE(Dashboard!$C$4,8,1)))) | AA12: =IF(OR($E12="",$F12=""),0,MAX(0,MIN($F12,DATE(Dashboard!$C$4,10,1))-MAX($E12,DATE(Dashboard!$C$4,9,1)))) | AB12: =IF(OR($E12="",$F12=""),0,MAX(0,MIN($F12,DATE(Dashboard!$C$4,11,1))-MAX($E12,DATE(Dashboard!$C$4,10,1)))) | AC12: =IF(OR($E12="",$F12=""),0,MAX(0,MIN($F12,DATE(Dashboard!$C$4,12,1))-MAX($E12,DATE(Dashboard!$C$4,11,1)))) | AD12: =IF(OR($E12="",$F12=""),0,MAX(0,MIN($F12,DATE(Dashboard!$C$4,13,1))-MAX($E12,DATE(Dashboard!$C$4,12,1)))) | AE12: =SUM(S12:AD12) | AF12: =Q12*AE12 | AG12: =R12*AE12 | AH12: =SUMPRODUCT(S12:AD12,--(COLUMN(S12:AD12)-COLUMN(S12)+1<=Dashboard!$N$1)) | AI12: =IF(OR(E12="",E12<TODAY()),"",E12+ROW()/100000) | AJ12: =IF(OR(F12="",F12<TODAY()),"",F12+ROW()/100000)
B13: Mountain cabin | C13: Max H. | D13: Vrbo | E13: 46049 | F13: 46051 | G13: =IF(OR(E13="",F13=""),"",F13-E13) | H13: 5 | I13: 280 | J13: 80 | K13: 18 | L13: =IF(E13="","",N(I13)+N(J13)-N(K13)) | M13: Yes | N13: =IF(E13="","",IF(TODAY()<E13,"Upcoming",IF(TODAY()<F13,"Staying now",IF(M13="Yes","Checked out","Payout not received")))) | Q13: =IF(N(G13)>0,L13/G13,0) | R13: =IF(N(G13)>0,N(I13)/G13,0) | S13: =IF(OR($E13="",$F13=""),0,MAX(0,MIN($F13,DATE(Dashboard!$C$4,2,1))-MAX($E13,DATE(Dashboard!$C$4,1,1)))) | T13: =IF(OR($E13="",$F13=""),0,MAX(0,MIN($F13,DATE(Dashboard!$C$4,3,1))-MAX($E13,DATE(Dashboard!$C$4,2,1)))) | U13: =IF(OR($E13="",$F13=""),0,MAX(0,MIN($F13,DATE(Dashboard!$C$4,4,1))-MAX($E13,DATE(Dashboard!$C$4,3,1)))) | V13: =IF(OR($E13="",$F13=""),0,MAX(0,MIN($F13,DATE(Dashboard!$C$4,5,1))-MAX($E13,DATE(Dashboard!$C$4,4,1)))) | W13: =IF(OR($E13="",$F13=""),0,MAX(0,MIN($F13,DATE(Dashboard!$C$4,6,1))-MAX($E13,DATE(Dashboard!$C$4,5,1)))) | X13: =IF(OR($E13="",$F13=""),0,MAX(0,MIN($F13,DATE(Dashboard!$C$4,7,1))-MAX($E13,DATE(Dashboard!$C$4,6,1)))) | Y13: =IF(OR($E13="",$F13=""),0,MAX(0,MIN($F13,DATE(Dashboard!$C$4,8,1))-MAX($E13,DATE(Dashboard!$C$4,7,1)))) | Z13: =IF(OR($E13="",$F13=""),0,MAX(0,MIN($F13,DATE(Dashboard!$C$4,9,1))-MAX($E13,DATE(Dashboard!$C$4,8,1)))) | AA13: =IF(OR($E13="",$F13=""),0,MAX(0,MIN($F13,DATE(Dashboard!$C$4,10,1))-MAX($E13,DATE(Dashboard!$C$4,9,1)))) | AB13: =IF(OR($E13="",$F13=""),0,MAX(0,MIN($F13,DATE(Dashboard!$C$4,11,1))-MAX($E13,DATE(Dashboard!$C$4,10,1)))) | AC13: =IF(OR($E13="",$F13=""),0,MAX(0,MIN($F13,DATE(Dashboard!$C$4,12,1))-MAX($E13,DATE(Dashboard!$C$4,11,1)))) | AD13: =IF(OR($E13="",$F13=""),0,MAX(0,MIN($F13,DATE(Dashboard!$C$4,13,1))-MAX($E13,DATE(Dashboard!$C$4,12,1)))) | AE13: =SUM(S13:AD13) | AF13: =Q13*AE13 | AG13: =R13*AE13 | AH13: =SUMPRODUCT(S13:AD13,--(COLUMN(S13:AD13)-COLUMN(S13)+1<=Dashboard!$N$1)) | AI13: =IF(OR(E13="",E13<TODAY()),"",E13+ROW()/100000) | AJ13: =IF(OR(F13="",F13<TODAY()),"",F13+ROW()/100000)
B14: Mountain cabin | C14: Sam C. | D14: Booking.com | E14: 46054 | F14: 46059 | G14: =IF(OR(E14="",F14=""),"",F14-E14) | H14: 5 | I14: 700 | J14: 80 | K14: 117 | L14: =IF(E14="","",N(I14)+N(J14)-N(K14)) | M14: Yes | N14: =IF(E14="","",IF(TODAY()<E14,"Upcoming",IF(TODAY()<F14,"Staying now",IF(M14="Yes","Checked out","Payout not received")))) | Q14: =IF(N(G14)>0,L14/G14,0) | R14: =IF(N(G14)>0,N(I14)/G14,0) | S14: =IF(OR($E14="",$F14=""),0,MAX(0,MIN($F14,DATE(Dashboard!$C$4,2,1))-MAX($E14,DATE(Dashboard!$C$4,1,1)))) | T14: =IF(OR($E14="",$F14=""),0,MAX(0,MIN($F14,DATE(Dashboard!$C$4,3,1))-MAX($E14,DATE(Dashboard!$C$4,2,1)))) | U14: =IF(OR($E14="",$F14=""),0,MAX(0,MIN($F14,DATE(Dashboard!$C$4,4,1))-MAX($E14,DATE(Dashboard!$C$4,3,1)))) | V14: =IF(OR($E14="",$F14=""),0,MAX(0,MIN($F14,DATE(Dashboard!$C$4,5,1))-MAX($E14,DATE(Dashboard!$C$4,4,1)))) | W14: =IF(OR($E14="",$F14=""),0,MAX(0,MIN($F14,DATE(Dashboard!$C$4,6,1))-MAX($E14,DATE(Dashboard!$C$4,5,1)))) | X14: =IF(OR($E14="",$F14=""),0,MAX(0,MIN($F14,DATE(Dashboard!$C$4,7,1))-MAX($E14,DATE(Dashboard!$C$4,6,1)))) | Y14: =IF(OR($E14="",$F14=""),0,MAX(0,MIN($F14,DATE(Dashboard!$C$4,8,1))-MAX($E14,DATE(Dashboard!$C$4,7,1)))) | Z14: =IF(OR($E14="",$F14=""),0,MAX(0,MIN($F14,DATE(Dashboard!$C$4,9,1))-MAX($E14,DATE(Dashboard!$C$4,8,1)))) | AA14: =IF(OR($E14="",$F14=""),0,MAX(0,MIN($F14,DATE(Dashboard!$C$4,10,1))-MAX($E14,DATE(Dashboard!$C$4,9,1)))) | AB14: =IF(OR($E14="",$F14=""),0,MAX(0,MIN($F14,DATE(Dashboard!$C$4,11,1))-MAX($E14,DATE(Dashboard!$C$4,10,1)))) | AC14: =IF(OR($E14="",$F14=""),0,MAX(0,MIN($F14,DATE(Dashboard!$C$4,12,1))-MAX($E14,DATE(Dashboard!$C$4,11,1)))) | AD14: =IF(OR($E14="",$F14=""),0,MAX(0,MIN($F14,DATE(Dashboard!$C$4,13,1))-MAX($E14,DATE(Dashboard!$C$4,12,1)))) | AE14: =SUM(S14:AD14) | AF14: =Q14*AE14 | AG14: =R14*AE14 | AH14: =SUMPRODUCT(S14:AD14,--(COLUMN(S14:AD14)-COLUMN(S14)+1<=Dashboard!$N$1)) | AI14: =IF(OR(E14="",E14<TODAY()),"",E14+ROW()/100000) | AJ14: =IF(OR(F14="",F14<TODAY()),"",F14+ROW()/100000)
B15: Mountain cabin | C15: Noah B. | D15: Airbnb | E15: 46062 | F15: 46067 | G15: =IF(OR(E15="",F15=""),"",F15-E15) | H15: 4 | I15: 700 | J15: 80 | K15: 23.4 | L15: =IF(E15="","",N(I15)+N(J15)-N(K15)) | M15: Yes | N15: =IF(E15="","",IF(TODAY()<E15,"Upcoming",IF(TODAY()<F15,"Staying now",IF(M15="Yes","Checked out","Payout not received")))) | Q15: =IF(N(G15)>0,L15/G15,0) | R15: =IF(N(G15)>0,N(I15)/G15,0) | S15: =IF(OR($E15="",$F15=""),0,MAX(0,MIN($F15,DATE(Dashboard!$C$4,2,1))-MAX($E15,DATE(Dashboard!$C$4,1,1)))) | T15: =IF(OR($E15="",$F15=""),0,MAX(0,MIN($F15,DATE(Dashboard!$C$4,3,1))-MAX($E15,DATE(Dashboard!$C$4,2,1)))) | U15: =IF(OR($E15="",$F15=""),0,MAX(0,MIN($F15,DATE(Dashboard!$C$4,4,1))-MAX($E15,DATE(Dashboard!$C$4,3,1)))) | V15: =IF(OR($E15="",$F15=""),0,MAX(0,MIN($F15,DATE(Dashboard!$C$4,5,1))-MAX($E15,DATE(Dashboard!$C$4,4,1)))) | W15: =IF(OR($E15="",$F15=""),0,MAX(0,MIN($F15,DATE(Dashboard!$C$4,6,1))-MAX($E15,DATE(Dashboard!$C$4,5,1)))) | X15: =IF(OR($E15="",$F15=""),0,MAX(0,MIN($F15,DATE(Dashboard!$C$4,7,1))-MAX($E15,DATE(Dashboard!$C$4,6,1)))) | Y15: =IF(OR($E15="",$F15=""),0,MAX(0,MIN($F15,DATE(Dashboard!$C$4,8,1))-MAX($E15,DATE(Dashboard!$C$4,7,1)))) | Z15: =IF(OR($E15="",$F15=""),0,MAX(0,MIN($F15,DATE(Dashboard!$C$4,9,1))-MAX($E15,DATE(Dashboard!$C$4,8,1)))) | AA15: =IF(OR($E15="",$F15=""),0,MAX(0,MIN($F15,DATE(Dashboard!$C$4,10,1))-MAX($E15,DATE(Dashboard!$C$4,9,1)))) | AB15: =IF(OR($E15="",$F15=""),0,MAX(0,MIN($F15,DATE(Dashboard!$C$4,11,1))-MAX($E15,DATE(Dashboard!$C$4,10,1)))) | AC15: =IF(OR($E15="",$F15=""),0,MAX(0,MIN($F15,DATE(Dashboard!$C$4,12,1))-MAX($E15,DATE(Dashboard!$C$4,11,1)))) | AD15: =IF(OR($E15="",$F15=""),0,MAX(0,MIN($F15,DATE(Dashboard!$C$4,13,1))-MAX($E15,DATE(Dashboard!$C$4,12,1)))) | AE15: =SUM(S15:AD15) | AF15: =Q15*AE15 | AG15: =R15*AE15 | AH15: =SUMPRODUCT(S15:AD15,--(COLUMN(S15:AD15)-COLUMN(S15)+1<=Dashboard!$N$1)) | AI15: =IF(OR(E15="",E15<TODAY()),"",E15+ROW()/100000) | AJ15: =IF(OR(F15="",F15<TODAY()),"",F15+ROW()/100000)
B16: Beach apartment | C16: Nora K. | D16: Airbnb | E16: 46063 | F16: 46069 | G16: =IF(OR(E16="",F16=""),"",F16-E16) | H16: 5 | I16: 570 | J16: 60 | K16: 18.9 | L16: =IF(E16="","",N(I16)+N(J16)-N(K16)) | M16: Yes | N16: =IF(E16="","",IF(TODAY()<E16,"Upcoming",IF(TODAY()<F16,"Staying now",IF(M16="Yes","Checked out","Payout not received")))) | Q16: =IF(N(G16)>0,L16/G16,0) | R16: =IF(N(G16)>0,N(I16)/G16,0) | S16: =IF(OR($E16="",$F16=""),0,MAX(0,MIN($F16,DATE(Dashboard!$C$4,2,1))-MAX($E16,DATE(Dashboard!$C$4,1,1)))) | T16: =IF(OR($E16="",$F16=""),0,MAX(0,MIN($F16,DATE(Dashboard!$C$4,3,1))-MAX($E16,DATE(Dashboard!$C$4,2,1)))) | U16: =IF(OR($E16="",$F16=""),0,MAX(0,MIN($F16,DATE(Dashboard!$C$4,4,1))-MAX($E16,DATE(Dashboard!$C$4,3,1)))) | V16: =IF(OR($E16="",$F16=""),0,MAX(0,MIN($F16,DATE(Dashboard!$C$4,5,1))-MAX($E16,DATE(Dashboard!$C$4,4,1)))) | W16: =IF(OR($E16="",$F16=""),0,MAX(0,MIN($F16,DATE(Dashboard!$C$4,6,1))-MAX($E16,DATE(Dashboard!$C$4,5,1)))) | X16: =IF(OR($E16="",$F16=""),0,MAX(0,MIN($F16,DATE(Dashboard!$C$4,7,1))-MAX($E16,DATE(Dashboard!$C$4,6,1)))) | Y16: =IF(OR($E16="",$F16=""),0,MAX(0,MIN($F16,DATE(Dashboard!$C$4,8,1))-MAX($E16,DATE(Dashboard!$C$4,7,1)))) | Z16: =IF(OR($E16="",$F16=""),0,MAX(0,MIN($F16,DATE(Dashboard!$C$4,9,1))-MAX($E16,DATE(Dashboard!$C$4,8,1)))) | AA16: =IF(OR($E16="",$F16=""),0,MAX(0,MIN($F16,DATE(Dashboard!$C$4,10,1))-MAX($E16,DATE(Dashboard!$C$4,9,1)))) | AB16: =IF(OR($E16="",$F16=""),0,MAX(0,MIN($F16,DATE(Dashboard!$C$4,11,1))-MAX($E16,DATE(Dashboard!$C$4,10,1)))) | AC16: =IF(OR($E16="",$F16=""),0,MAX(0,MIN($F16,DATE(Dashboard!$C$4,12,1))-MAX($E16,DATE(Dashboard!$C$4,11,1)))) | AD16: =IF(OR($E16="",$F16=""),0,MAX(0,MIN($F16,DATE(Dashboard!$C$4,13,1))-MAX($E16,DATE(Dashboard!$C$4,12,1)))) | AE16: =SUM(S16:AD16) | AF16: =Q16*AE16 | AG16: =R16*AE16 | AH16: =SUMPRODUCT(S16:AD16,--(COLUMN(S16:AD16)-COLUMN(S16)+1<=Dashboard!$N$1)) | AI16: =IF(OR(E16="",E16<TODAY()),"",E16+ROW()/100000) | AJ16: =IF(OR(F16="",F16<TODAY()),"",F16+ROW()/100000)
B17: Mountain cabin | C17: Sam T. | D17: Booking.com | E17: 46067 | F17: 46073 | G17: =IF(OR(E17="",F17=""),"",F17-E17) | H17: 4 | I17: 840 | J17: 80 | K17: 138 | L17: =IF(E17="","",N(I17)+N(J17)-N(K17)) | M17: Yes | N17: =IF(E17="","",IF(TODAY()<E17,"Upcoming",IF(TODAY()<F17,"Staying now",IF(M17="Yes","Checked out","Payout not received")))) | Q17: =IF(N(G17)>0,L17/G17,0) | R17: =IF(N(G17)>0,N(I17)/G17,0) | S17: =IF(OR($E17="",$F17=""),0,MAX(0,MIN($F17,DATE(Dashboard!$C$4,2,1))-MAX($E17,DATE(Dashboard!$C$4,1,1)))) | T17: =IF(OR($E17="",$F17=""),0,MAX(0,MIN($F17,DATE(Dashboard!$C$4,3,1))-MAX($E17,DATE(Dashboard!$C$4,2,1)))) | U17: =IF(OR($E17="",$F17=""),0,MAX(0,MIN($F17,DATE(Dashboard!$C$4,4,1))-MAX($E17,DATE(Dashboard!$C$4,3,1)))) | V17: =IF(OR($E17="",$F17=""),0,MAX(0,MIN($F17,DATE(Dashboard!$C$4,5,1))-MAX($E17,DATE(Dashboard!$C$4,4,1)))) | W17: =IF(OR($E17="",$F17=""),0,MAX(0,MIN($F17,DATE(Dashboard!$C$4,6,1))-MAX($E17,DATE(Dashboard!$C$4,5,1)))) | X17: =IF(OR($E17="",$F17=""),0,MAX(0,MIN($F17,DATE(Dashboard!$C$4,7,1))-MAX($E17,DATE(Dashboard!$C$4,6,1)))) | Y17: =IF(OR($E17="",$F17=""),0,MAX(0,MIN($F17,DATE(Dashboard!$C$4,8,1))-MAX($E17,DATE(Dashboard!$C$4,7,1)))) | Z17: =IF(OR($E17="",$F17=""),0,MAX(0,MIN($F17,DATE(Dashboard!$C$4,9,1))-MAX($E17,DATE(Dashboard!$C$4,8,1)))) | AA17: =IF(OR($E17="",$F17=""),0,MAX(0,MIN($F17,DATE(Dashboard!$C$4,10,1))-MAX($E17,DATE(Dashboard!$C$4,9,1)))) | AB17: =IF(OR($E17="",$F17=""),0,MAX(0,MIN($F17,DATE(Dashboard!$C$4,11,1))-MAX($E17,DATE(Dashboard!$C$4,10,1)))) | AC17: =IF(OR($E17="",$F17=""),0,MAX(0,MIN($F17,DATE(Dashboard!$C$4,12,1))-MAX($E17,DATE(Dashboard!$C$4,11,1)))) | AD17: =IF(OR($E17="",$F17=""),0,MAX(0,MIN($F17,DATE(Dashboard!$C$4,13,1))-MAX($E17,DATE(Dashboard!$C$4,12,1)))) | AE17: =SUM(S17:AD17) | AF17: =Q17*AE17 | AG17: =R17*AE17 | AH17: =SUMPRODUCT(S17:AD17,--(COLUMN(S17:AD17)-COLUMN(S17)+1<=Dashboard!$N$1)) | AI17: =IF(OR(E17="",E17<TODAY()),"",E17+ROW()/100000) | AJ17: =IF(OR(F17="",F17<TODAY()),"",F17+ROW()/100000)
... B66: Mountain cabin | C66: Adam K. | D66: Airbnb | E66: 46287 | F66: 46292 | G66: =IF(OR(E66="",F66=""),"",F66-E66) | H66: 5 | I66: 550 | J66: 80 | K66: 18.9 | L66: =IF(E66="","",N(I66)+N(J66)-N(K66)) | M66: No | N66: =IF(E66="","",IF(TODAY()<E66,"Upcoming",IF(TODAY()<F66,"Staying now",IF(M66="Yes","Checked out","Payout not received")))) | Q66: =IF(N(G66)>0,L66/G66,0) | R66: =IF(N(G66)>0,N(I66)/G66,0) | S66: =IF(OR($E66="",$F66=""),0,MAX(0,MIN($F66,DATE(Dashboard!$C$4,2,1))-MAX($E66,DATE(Dashboard!$C$4,1,1)))) | T66: =IF(OR($E66="",$F66=""),0,MAX(0,MIN($F66,DATE(Dashboard!$C$4,3,1))-MAX($E66,DATE(Dashboard!$C$4,2,1)))) | U66: =IF(OR($E66="",$F66=""),0,MAX(0,MIN($F66,DATE(Dashboard!$C$4,4,1))-MAX($E66,DATE(Dashboard!$C$4,3,1)))) | V66: =IF(OR($E66="",$F66=""),0,MAX(0,MIN($F66,DATE(Dashboard!$C$4,5,1))-MAX($E66,DATE(Dashboard!$C$4,4,1)))) | W66: =IF(OR($E66="",$F66=""),0,MAX(0,MIN($F66,DATE(Dashboard!$C$4,6,1))-MAX($E66,DATE(Dashboard!$C$4,5,1)))) | X66: =IF(OR($E66="",$F66=""),0,MAX(0,MIN($F66,DATE(Dashboard!$C$4,7,1))-MAX($E66,DATE(Dashboard!$C$4,6,1)))) | Y66: =IF(OR($E66="",$F66=""),0,MAX(0,MIN($F66,DATE(Dashboard!$C$4,8,1))-MAX($E66,DATE(Dashboard!$C$4,7,1)))) | Z66: =IF(OR($E66="",$F66=""),0,MAX(0,MIN($F66,DATE(Dashboard!$C$4,9,1))-MAX($E66,DATE(Dashboard!$C$4,8,1)))) | AA66: =IF(OR($E66="",$F66=""),0,MAX(0,MIN($F66,DATE(Dashboard!$C$4,10,1))-MAX($E66,DATE(Dashboard!$C$4,9,1)))) | AB66: =IF(OR($E66="",$F66=""),0,MAX(0,MIN($F66,DATE(Dashboard!$C$4,11,1))-MAX($E66,DATE(Dashboard!$C$4,10,1)))) | AC66: =IF(OR($E66="",$F66=""),0,MAX(0,MIN($F66,DATE(Dashboard!$C$4,12,1))-MAX($E66,DATE(Dashboard!$C$4,11,1)))) | AD66: =IF(OR($E66="",$F66=""),0,MAX(0,MIN($F66,DATE(Dashboard!$C$4,13,1))-MAX($E66,DATE(Dashboard!$C$4,12,1)))) | AE66: =SUM(S66:AD66) | AF66: =Q66*AE66 | AG66: =R66*AE66 | AH66: =SUMPRODUCT(S66:AD66,--(COLUMN(S66:AD66)-COLUMN(S66)+1<=Dashboard!$N$1)) | AI66: =IF(OR(E66="",E66<TODAY()),"",E66+ROW()/100000) | AJ66: =IF(OR(F66="",F66<TODAY()),"",F66+ROW()/100000)
B67: Beach apartment | C67: Ava C. | D67: Direct | E67: 46291 | F67: 46296 | G67: =IF(OR(E67="",F67=""),"",F67-E67) | H67: 5 | I67: 625 | J67: 60 | K67: 0 | L67: =IF(E67="","",N(I67)+N(J67)-N(K67)) | N67: =IF(E67="","",IF(TODAY()<E67,"Upcoming",IF(TODAY()<F67,"Staying now",IF(M67="Yes","Checked out","Payout not received")))) | Q67: =IF(N(G67)>0,L67/G67,0) | R67: =IF(N(G67)>0,N(I67)/G67,0) | S67: =IF(OR($E67="",$F67=""),0,MAX(0,MIN($F67,DATE(Dashboard!$C$4,2,1))-MAX($E67,DATE(Dashboard!$C$4,1,1)))) | T67: =IF(OR($E67="",$F67=""),0,MAX(0,MIN($F67,DATE(Dashboard!$C$4,3,1))-MAX($E67,DATE(Dashboard!$C$4,2,1)))) | U67: =IF(OR($E67="",$F67=""),0,MAX(0,MIN($F67,DATE(Dashboard!$C$4,4,1))-MAX($E67,DATE(Dashboard!$C$4,3,1)))) | V67: =IF(OR($E67="",$F67=""),0,MAX(0,MIN($F67,DATE(Dashboard!$C$4,5,1))-MAX($E67,DATE(Dashboard!$C$4,4,1)))) | W67: =IF(OR($E67="",$F67=""),0,MAX(0,MIN($F67,DATE(Dashboard!$C$4,6,1))-MAX($E67,DATE(Dashboard!$C$4,5,1)))) | X67: =IF(OR($E67="",$F67=""),0,MAX(0,MIN($F67,DATE(Dashboard!$C$4,7,1))-MAX($E67,DATE(Dashboard!$C$4,6,1)))) | Y67: =IF(OR($E67="",$F67=""),0,MAX(0,MIN($F67,DATE(Dashboard!$C$4,8,1))-MAX($E67,DATE(Dashboard!$C$4,7,1)))) | Z67: =IF(OR($E67="",$F67=""),0,MAX(0,MIN($F67,DATE(Dashboard!$C$4,9,1))-MAX($E67,DATE(Dashboard!$C$4,8,1)))) | AA67: =IF(OR($E67="",$F67=""),0,MAX(0,MIN($F67,DATE(Dashboard!$C$4,10,1))-MAX($E67,DATE(Dashboard!$C$4,9,1)))) | AB67: =IF(OR($E67="",$F67=""),0,MAX(0,MIN($F67,DATE(Dashboard!$C$4,11,1))-MAX($E67,DATE(Dashboard!$C$4,10,1)))) | AC67: =IF(OR($E67="",$F67=""),0,MAX(0,MIN($F67,DATE(Dashboard!$C$4,12,1))-MAX($E67,DATE(Dashboard!$C$4,11,1)))) | AD67: =IF(OR($E67="",$F67=""),0,MAX(0,MIN($F67,DATE(Dashboard!$C$4,13,1))-MAX($E67,DATE(Dashboard!$C$4,12,1)))) | AE67: =SUM(S67:AD67) | AF67: =Q67*AE67 | AG67: =R67*AE67 | AH67: =SUMPRODUCT(S67:AD67,--(COLUMN(S67:AD67)-COLUMN(S67)+1<=Dashboard!$N$1)) | AI67: =IF(OR(E67="",E67<TODAY()),"",E67+ROW()/100000) | AJ67: =IF(OR(F67="",F67<TODAY()),"",F67+ROW()/100000)
B68: Mountain cabin | C68: Leo M. | D68: Booking.com | E68: 46295 | F68: 46299 | G68: =IF(OR(E68="",F68=""),"",F68-E68) | H68: 3 | I68: 440 | J68: 80 | K68: 78 | L68: =IF(E68="","",N(I68)+N(J68)-N(K68)) | N68: =IF(E68="","",IF(TODAY()<E68,"Upcoming",IF(TODAY()<F68,"Staying now",IF(M68="Yes","Checked out","Payout not received")))) | Q68: =IF(N(G68)>0,L68/G68,0) | R68: =IF(N(G68)>0,N(I68)/G68,0) | S68: =IF(OR($E68="",$F68=""),0,MAX(0,MIN($F68,DATE(Dashboard!$C$4,2,1))-MAX($E68,DATE(Dashboard!$C$4,1,1)))) | T68: =IF(OR($E68="",$F68=""),0,MAX(0,MIN($F68,DATE(Dashboard!$C$4,3,1))-MAX($E68,DATE(Dashboard!$C$4,2,1)))) | U68: =IF(OR($E68="",$F68=""),0,MAX(0,MIN($F68,DATE(Dashboard!$C$4,4,1))-MAX($E68,DATE(Dashboard!$C$4,3,1)))) | V68: =IF(OR($E68="",$F68=""),0,MAX(0,MIN($F68,DATE(Dashboard!$C$4,5,1))-MAX($E68,DATE(Dashboard!$C$4,4,1)))) | W68: =IF(OR($E68="",$F68=""),0,MAX(0,MIN($F68,DATE(Dashboard!$C$4,6,1))-MAX($E68,DATE(Dashboard!$C$4,5,1)))) | X68: =IF(OR($E68="",$F68=""),0,MAX(0,MIN($F68,DATE(Dashboard!$C$4,7,1))-MAX($E68,DATE(Dashboard!$C$4,6,1)))) | Y68: =IF(OR($E68="",$F68=""),0,MAX(0,MIN($F68,DATE(Dashboard!$C$4,8,1))-MAX($E68,DATE(Dashboard!$C$4,7,1)))) | Z68: =IF(OR($E68="",$F68=""),0,MAX(0,MIN($F68,DATE(Dashboard!$C$4,9,1))-MAX($E68,DATE(Dashboard!$C$4,8,1)))) | AA68: =IF(OR($E68="",$F68=""),0,MAX(0,MIN($F68,DATE(Dashboard!$C$4,10,1))-MAX($E68,DATE(Dashboard!$C$4,9,1)))) | AB68: =IF(OR($E68="",$F68=""),0,MAX(0,MIN($F68,DATE(Dashboard!$C$4,11,1))-MAX($E68,DATE(Dashboard!$C$4,10,1)))) | AC68: =IF(OR($E68="",$F68=""),0,MAX(0,MIN($F68,DATE(Dashboard!$C$4,12,1))-MAX($E68,DATE(Dashboard!$C$4,11,1)))) | AD68: =IF(OR($E68="",$F68=""),0,MAX(0,MIN($F68,DATE(Dashboard!$C$4,13,1))-MAX($E68,DATE(Dashboard!$C$4,12,1)))) | AE68: =SUM(S68:AD68) | AF68: =Q68*AE68 | AG68: =R68*AE68 | AH68: =SUMPRODUCT(S68:AD68,--(COLUMN(S68:AD68)-COLUMN(S68)+1<=Dashboard!$N$1)) | AI68: =IF(OR(E68="",E68<TODAY()),"",E68+ROW()/100000) | AJ68: =IF(OR(F68="",F68<TODAY()),"",F68+ROW()/100000)
B69: Beach apartment | C69: Zoe W. | D69: Airbnb | E69: 46298 | F69: 46302 | G69: =IF(OR(E69="",F69=""),"",F69-E69) | H69: 5 | I69: 380 | J69: 60 | K69: 13.2 | L69: =IF(E69="","",N(I69)+N(J69)-N(K69)) | N69: =IF(E69="","",IF(TODAY()<E69,"Upcoming",IF(TODAY()<F69,"Staying now",IF(M69="Yes","Checked out","Payout not received")))) | Q69: =IF(N(G69)>0,L69/G69,0) | R69: =IF(N(G69)>0,N(I69)/G69,0) | S69: =IF(OR($E69="",$F69=""),0,MAX(0,MIN($F69,DATE(Dashboard!$C$4,2,1))-MAX($E69,DATE(Dashboard!$C$4,1,1)))) | T69: =IF(OR($E69="",$F69=""),0,MAX(0,MIN($F69,DATE(Dashboard!$C$4,3,1))-MAX($E69,DATE(Dashboard!$C$4,2,1)))) | U69: =IF(OR($E69="",$F69=""),0,MAX(0,MIN($F69,DATE(Dashboard!$C$4,4,1))-MAX($E69,DATE(Dashboard!$C$4,3,1)))) | V69: =IF(OR($E69="",$F69=""),0,MAX(0,MIN($F69,DATE(Dashboard!$C$4,5,1))-MAX($E69,DATE(Dashboard!$C$4,4,1)))) | W69: =IF(OR($E69="",$F69=""),0,MAX(0,MIN($F69,DATE(Dashboard!$C$4,6,1))-MAX($E69,DATE(Dashboard!$C$4,5,1)))) | X69: =IF(OR($E69="",$F69=""),0,MAX(0,MIN($F69,DATE(Dashboard!$C$4,7,1))-MAX($E69,DATE(Dashboard!$C$4,6,1)))) | Y69: =IF(OR($E69="",$F69=""),0,MAX(0,MIN($F69,DATE(Dashboard!$C$4,8,1))-MAX($E69,DATE(Dashboard!$C$4,7,1)))) | Z69: =IF(OR($E69="",$F69=""),0,MAX(0,MIN($F69,DATE(Dashboard!$C$4,9,1))-MAX($E69,DATE(Dashboard!$C$4,8,1)))) | AA69: =IF(OR($E69="",$F69=""),0,MAX(0,MIN($F69,DATE(Dashboard!$C$4,10,1))-MAX($E69,DATE(Dashboard!$C$4,9,1)))) | AB69: =IF(OR($E69="",$F69=""),0,MAX(0,MIN($F69,DATE(Dashboard!$C$4,11,1))-MAX($E69,DATE(Dashboard!$C$4,10,1)))) | AC69: =IF(OR($E69="",$F69=""),0,MAX(0,MIN($F69,DATE(Dashboard!$C$4,12,1))-MAX($E69,DATE(Dashboard!$C$4,11,1)))) | AD69: =IF(OR($E69="",$F69=""),0,MAX(0,MIN($F69,DATE(Dashboard!$C$4,13,1))-MAX($E69,DATE(Dashboard!$C$4,12,1)))) | AE69: =SUM(S69:AD69) | AF69: =Q69*AE69 | AG69: =R69*AE69 | AH69: =SUMPRODUCT(S69:AD69,--(COLUMN(S69:AD69)-COLUMN(S69)+1<=Dashboard!$N$1)) | AI69: =IF(OR(E69="",E69<TODAY()),"",E69+ROW()/100000) | AJ69: =IF(OR(F69="",F69<TODAY()),"",F69+ROW()/100000)
B70: Beach apartment | C70: Owen C. | D70: Direct | E70: 46302 | F70: 46306 | G70: =IF(OR(E70="",F70=""),"",F70-E70) | H70: 3 | I70: 380 | J70: 60 | K70: 0 | L70: =IF(E70="","",N(I70)+N(J70)-N(K70)) | N70: =IF(E70="","",IF(TODAY()<E70,"Upcoming",IF(TODAY()<F70,"Staying now",IF(M70="Yes","Checked out","Payout not received")))) | Q70: =IF(N(G70)>0,L70/G70,0) | R70: =IF(N(G70)>0,N(I70)/G70,0) | S70: =IF(OR($E70="",$F70=""),0,MAX(0,MIN($F70,DATE(Dashboard!$C$4,2,1))-MAX($E70,DATE(Dashboard!$C$4,1,1)))) | T70: =IF(OR($E70="",$F70=""),0,MAX(0,MIN($F70,DATE(Dashboard!$C$4,3,1))-MAX($E70,DATE(Dashboard!$C$4,2,1)))) | U70: =IF(OR($E70="",$F70=""),0,MAX(0,MIN($F70,DATE(Dashboard!$C$4,4,1))-MAX($E70,DATE(Dashboard!$C$4,3,1)))) | V70: =IF(OR($E70="",$F70=""),0,MAX(0,MIN($F70,DATE(Dashboard!$C$4,5,1))-MAX($E70,DATE(Dashboard!$C$4,4,1)))) | W70: =IF(OR($E70="",$F70=""),0,MAX(0,MIN($F70,DATE(Dashboard!$C$4,6,1))-MAX($E70,DATE(Dashboard!$C$4,5,1)))) | X70: =IF(OR($E70="",$F70=""),0,MAX(0,MIN($F70,DATE(Dashboard!$C$4,7,1))-MAX($E70,DATE(Dashboard!$C$4,6,1)))) | Y70: =IF(OR($E70="",$F70=""),0,MAX(0,MIN($F70,DATE(Dashboard!$C$4,8,1))-MAX($E70,DATE(Dashboard!$C$4,7,1)))) | Z70: =IF(OR($E70="",$F70=""),0,MAX(0,MIN($F70,DATE(Dashboard!$C$4,9,1))-MAX($E70,DATE(Dashboard!$C$4,8,1)))) | AA70: =IF(OR($E70="",$F70=""),0,MAX(0,MIN($F70,DATE(Dashboard!$C$4,10,1))-MAX($E70,DATE(Dashboard!$C$4,9,1)))) | AB70: =IF(OR($E70="",$F70=""),0,MAX(0,MIN($F70,DATE(Dashboard!$C$4,11,1))-MAX($E70,DATE(Dashboard!$C$4,10,1)))) | AC70: =IF(OR($E70="",$F70=""),0,MAX(0,MIN($F70,DATE(Dashboard!$C$4,12,1))-MAX($E70,DATE(Dashboard!$C$4,11,1)))) | AD70: =IF(OR($E70="",$F70=""),0,MAX(0,MIN($F70,DATE(Dashboard!$C$4,13,1))-MAX($E70,DATE(Dashboard!$C$4,12,1)))) | AE70: =SUM(S70:AD70) | AF70: =Q70*AE70 | AG70: =R70*AE70 | AH70: =SUMPRODUCT(S70:AD70,--(COLUMN(S70:AD70)-COLUMN(S70)+1<=Dashboard!$N$1)) | AI70: =IF(OR(E70="",E70<TODAY()),"",E70+ROW()/100000) | AJ70: =IF(OR(F70="",F70<TODAY()),"",F70+ROW()/100000)
B71: Mountain cabin | C71: Max L. | D71: Airbnb | E71: 46304 | F71: 46308 | G71: =IF(OR(E71="",F71=""),"",F71-E71) | H71: 3 | I71: 440 | J71: 80 | K71: 15.6 | L71: =IF(E71="","",N(I71)+N(J71)-N(K71)) | N71: =IF(E71="","",IF(TODAY()<E71,"Upcoming",IF(TODAY()<F71,"Staying now",IF(M71="Yes","Checked out","Payout not received")))) | Q71: =IF(N(G71)>0,L71/G71,0) | R71: =IF(N(G71)>0,N(I71)/G71,0) | S71: =IF(OR($E71="",$F71=""),0,MAX(0,MIN($F71,DATE(Dashboard!$C$4,2,1))-MAX($E71,DATE(Dashboard!$C$4,1,1)))) | T71: =IF(OR($E71="",$F71=""),0,MAX(0,MIN($F71,DATE(Dashboard!$C$4,3,1))-MAX($E71,DATE(Dashboard!$C$4,2,1)))) | U71: =IF(OR($E71="",$F71=""),0,MAX(0,MIN($F71,DATE(Dashboard!$C$4,4,1))-MAX($E71,DATE(Dashboard!$C$4,3,1)))) | V71: =IF(OR($E71="",$F71=""),0,MAX(0,MIN($F71,DATE(Dashboard!$C$4,5,1))-MAX($E71,DATE(Dashboard!$C$4,4,1)))) | W71: =IF(OR($E71="",$F71=""),0,MAX(0,MIN($F71,DATE(Dashboard!$C$4,6,1))-MAX($E71,DATE(Dashboard!$C$4,5,1)))) | X71: =IF(OR($E71="",$F71=""),0,MAX(0,MIN($F71,DATE(Dashboard!$C$4,7,1))-MAX($E71,DATE(Dashboard!$C$4,6,1)))) | Y71: =IF(OR($E71="",$F71=""),0,MAX(0,MIN($F71,DATE(Dashboard!$C$4,8,1))-MAX($E71,DATE(Dashboard!$C$4,7,1)))) | Z71: =IF(OR($E71="",$F71=""),0,MAX(0,MIN($F71,DATE(Dashboard!$C$4,9,1))-MAX($E71,DATE(Dashboard!$C$4,8,1)))) | AA71: =IF(OR($E71="",$F71=""),0,MAX(0,MIN($F71,DATE(Dashboard!$C$4,10,1))-MAX($E71,DATE(Dashboard!$C$4,9,1)))) | AB71: =IF(OR($E71="",$F71=""),0,MAX(0,MIN($F71,DATE(Dashboard!$C$4,11,1))-MAX($E71,DATE(Dashboard!$C$4,10,1)))) | AC71: =IF(OR($E71="",$F71=""),0,MAX(0,MIN($F71,DATE(Dashboard!$C$4,12,1))-MAX($E71,DATE(Dashboard!$C$4,11,1)))) | AD71: =IF(OR($E71="",$F71=""),0,MAX(0,MIN($F71,DATE(Dashboard!$C$4,13,1))-MAX($E71,DATE(Dashboard!$C$4,12,1)))) | AE71: =SUM(S71:AD71) | AF71: =Q71*AE71 | AG71: =R71*AE71 | AH71: =SUMPRODUCT(S71:AD71,--(COLUMN(S71:AD71)-COLUMN(S71)+1<=Dashboard!$N$1)) | AI71: =IF(OR(E71="",E71<TODAY()),"",E71+ROW()/100000) | AJ71: =IF(OR(F71="",F71<TODAY()),"",F71+ROW()/100000)
G72: =IF(OR(E72="",F72=""),"",F72-E72) | L72: =IF(E72="","",N(I72)+N(J72)-N(K72)) | N72: =IF(E72="","",IF(TODAY()<E72,"Upcoming",IF(TODAY()<F72,"Staying now",IF(M72="Yes","Checked out","Payout not received")))) | Q72: =IF(N(G72)>0,L72/G72,0) | R72: =IF(N(G72)>0,N(I72)/G72,0) | S72: =IF(OR($E72="",$F72=""),0,MAX(0,MIN($F72,DATE(Dashboard!$C$4,2,1))-MAX($E72,DATE(Dashboard!$C$4,1,1)))) | T72: =IF(OR($E72="",$F72=""),0,MAX(0,MIN($F72,DATE(Dashboard!$C$4,3,1))-MAX($E72,DATE(Dashboard!$C$4,2,1)))) | U72: =IF(OR($E72="",$F72=""),0,MAX(0,MIN($F72,DATE(Dashboard!$C$4,4,1))-MAX($E72,DATE(Dashboard!$C$4,3,1)))) | V72: =IF(OR($E72="",$F72=""),0,MAX(0,MIN($F72,DATE(Dashboard!$C$4,5,1))-MAX($E72,DATE(Dashboard!$C$4,4,1)))) | W72: =IF(OR($E72="",$F72=""),0,MAX(0,MIN($F72,DATE(Dashboard!$C$4,6,1))-MAX($E72,DATE(Dashboard!$C$4,5,1)))) | X72: =IF(OR($E72="",$F72=""),0,MAX(0,MIN($F72,DATE(Dashboard!$C$4,7,1))-MAX($E72,DATE(Dashboard!$C$4,6,1)))) | Y72: =IF(OR($E72="",$F72=""),0,MAX(0,MIN($F72,DATE(Dashboard!$C$4,8,1))-MAX($E72,DATE(Dashboard!$C$4,7,1)))) | Z72: =IF(OR($E72="",$F72=""),0,MAX(0,MIN($F72,DATE(Dashboard!$C$4,9,1))-MAX($E72,DATE(Dashboard!$C$4,8,1)))) | AA72: =IF(OR($E72="",$F72=""),0,MAX(0,MIN($F72,DATE(Dashboard!$C$4,10,1))-MAX($E72,DATE(Dashboard!$C$4,9,1)))) | AB72: =IF(OR($E72="",$F72=""),0,MAX(0,MIN($F72,DATE(Dashboard!$C$4,11,1))-MAX($E72,DATE(Dashboard!$C$4,10,1)))) | AC72: =IF(OR($E72="",$F72=""),0,MAX(0,MIN($F72,DATE(Dashboard!$C$4,12,1))-MAX($E72,DATE(Dashboard!$C$4,11,1)))) | AD72: =IF(OR($E72="",$F72=""),0,MAX(0,MIN($F72,DATE(Dashboard!$C$4,13,1))-MAX($E72,DATE(Dashboard!$C$4,12,1)))) | AE72: =SUM(S72:AD72) | AF72: =Q72*AE72 | AG72: =R72*AE72 | AH72: =SUMPRODUCT(S72:AD72,--(COLUMN(S72:AD72)-COLUMN(S72)+1<=Dashboard!$N$1)) | AI72: =IF(OR(E72="",E72<TODAY()),"",E72+ROW()/100000) | AJ72: =IF(OR(F72="",F72<TODAY()),"",F72+ROW()/100000)
G73: =IF(OR(E73="",F73=""),"",F73-E73) | L73: =IF(E73="","",N(I73)+N(J73)-N(K73)) | N73: =IF(E73="","",IF(TODAY()<E73,"Upcoming",IF(TODAY()<F73,"Staying now",IF(M73="Yes","Checked out","Payout not received")))) | Q73: =IF(N(G73)>0,L73/G73,0) | R73: =IF(N(G73)>0,N(I73)/G73,0) | S73: =IF(OR($E73="",$F73=""),0,MAX(0,MIN($F73,DATE(Dashboard!$C$4,2,1))-MAX($E73,DATE(Dashboard!$C$4,1,1)))) | T73: =IF(OR($E73="",$F73=""),0,MAX(0,MIN($F73,DATE(Dashboard!$C$4,3,1))-MAX($E73,DATE(Dashboard!$C$4,2,1)))) | U73: =IF(OR($E73="",$F73=""),0,MAX(0,MIN($F73,DATE(Dashboard!$C$4,4,1))-MAX($E73,DATE(Dashboard!$C$4,3,1)))) | V73: =IF(OR($E73="",$F73=""),0,MAX(0,MIN($F73,DATE(Dashboard!$C$4,5,1))-MAX($E73,DATE(Dashboard!$C$4,4,1)))) | W73: =IF(OR($E73="",$F73=""),0,MAX(0,MIN($F73,DATE(Dashboard!$C$4,6,1))-MAX($E73,DATE(Dashboard!$C$4,5,1)))) | X73: =IF(OR($E73="",$F73=""),0,MAX(0,MIN($F73,DATE(Dashboard!$C$4,7,1))-MAX($E73,DATE(Dashboard!$C$4,6,1)))) | Y73: =IF(OR($E73="",$F73=""),0,MAX(0,MIN($F73,DATE(Dashboard!$C$4,8,1))-MAX($E73,DATE(Dashboard!$C$4,7,1)))) | Z73: =IF(OR($E73="",$F73=""),0,MAX(0,MIN($F73,DATE(Dashboard!$C$4,9,1))-MAX($E73,DATE(Dashboard!$C$4,8,1)))) | AA73: =IF(OR($E73="",$F73=""),0,MAX(0,MIN($F73,DATE(Dashboard!$C$4,10,1))-MAX($E73,DATE(Dashboard!$C$4,9,1)))) | AB73: =IF(OR($E73="",$F73=""),0,MAX(0,MIN($F73,DATE(Dashboard!$C$4,11,1))-MAX($E73,DATE(Dashboard!$C$4,10,1)))) | AC73: =IF(OR($E73="",$F73=""),0,MAX(0,MIN($F73,DATE(Dashboard!$C$4,12,1))-MAX($E73,DATE(Dashboard!$C$4,11,1)))) | AD73: =IF(OR($E73="",$F73=""),0,MAX(0,MIN($F73,DATE(Dashboard!$C$4,13,1))-MAX($E73,DATE(Dashboard!$C$4,12,1)))) | AE73: =SUM(S73:AD73) | AF73: =Q73*AE73 | AG73: =R73*AE73 | AH73: =SUMPRODUCT(S73:AD73,--(COLUMN(S73:AD73)-COLUMN(S73)+1<=Dashboard!$N$1)) | AI73: =IF(OR(E73="",E73<TODAY()),"",E73+ROW()/100000) | AJ73: =IF(OR(F73="",F73<TODAY()),"",F73+ROW()/100000)
