Workbook

Sheet Dashboard
B2: Blood sugar and medicines
B3: Readings on the left, medicines on the right.
B4: Last reading | C4: Today's average | D4: 7-day average | E4: 30-day average | G4: In range, 7 days | H4: Below, 7 days | I4: Above, 7 days | J4: Doses left today | O4: =IF(COUNT(Readings!$L$6:$L$1505)=0,"",INDEX(Readings!$G$6:$G$1505,MATCH(MAX(Readings!$L$6:$L$1505),Readings!$L$6:$L$1505,0)))
B5: =IF(COUNT(Readings!$L$6:$L$1505)=0,"",INDEX(Readings!$E$6:$E$1505,MATCH(MAX(Readings!$L$6:$L$1505),Readings!$L$6:$L$1505,0))) | C5: =IFERROR(ROUND(AVERAGEIFS(Readings!$E$6:$E$1505,Readings!$B$6:$B$1505,">="&(TODAY()-0),Readings!$B$6:$B$1505,"<="&TODAY()),1),"") | D5: =IFERROR(ROUND(AVERAGEIFS(Readings!$E$6:$E$1505,Readings!$B$6:$B$1505,">="&(TODAY()-6),Readings!$B$6:$B$1505,"<="&TODAY()),1),"") | E5: =IFERROR(ROUND(AVERAGEIFS(Readings!$E$6:$E$1505,Readings!$B$6:$B$1505,">="&(TODAY()-29),Readings!$B$6:$B$1505,"<="&TODAY()),1),"") | G5: =IFERROR(COUNTIFS(Readings!$G$6:$G$1505,"In range",Readings!$B$6:$B$1505,">="&(TODAY()-6),Readings!$B$6:$B$1505,"<="&TODAY())/(COUNTIFS(Readings!$G$6:$G$1505,"In range",Readings!$B$6:$B$1505,">="&(TODAY()-6),Readings!$B$6:$B$1505,"<="&TODAY())+COUNTIFS(Readings!$G$6:$G$1505,"Below",Readings!$B$6:$B$1505,">="&(TODAY()-6),Readings!$B$6:$B$1505,"<="&TODAY())+COUNTIFS(Readings!$G$6:$G$1505,"Above",Readings!$B$6:$B$1505,">="&(TODAY()-6),Readings!$B$6:$B$1505,"<="&TODAY())),"") | H5: =COUNTIFS(Readings!$G$6:$G$1505,"Below",Readings!$B$6:$B$1505,">="&(TODAY()-6),Readings!$B$6:$B$1505,"<="&TODAY()) | I5: =COUNTIFS(Readings!$G$6:$G$1505,"Above",Readings!$B$6:$B$1505,">="&(TODAY()-6),Readings!$B$6:$B$1505,"<="&TODAY()) | J5: =SUM(Medicines!$O$6:$O$25)
B6: =IF(COUNT(Readings!$L$6:$L$1505)=0,"",DAY(INT(MAX(Readings!$L$6:$L$1505)))&" "&CHOOSE(MONTH(INT(MAX(Readings!$L$6:$L$1505))),"Jan","Feb","Mar","Apr","May","Jun","Jul","Aug","Sep","Oct","Nov","Dec")&", "&HOUR(MAX(Readings!$L$6:$L$1505))&":"&RIGHT("0"&MINUTE(MAX(Readings!$L$6:$L$1505)),2)&IF(O4="",""," ("&LOWER(O4)&")"))
B8: Last 7 days | C8: Readings | D8: Average | E8: In range | G8: Today | H8: Medicine | I8: Dose | J8: Status
B9: Fasting | C9: =COUNTIFS(Readings!$D$6:$D$1505,B9,Readings!$B$6:$B$1505,">="&(TODAY()-6),Readings!$B$6:$B$1505,"<="&TODAY(),Readings!$E$6:$E$1505,">0") | D9: =IFERROR(ROUND(AVERAGEIFS(Readings!$E$6:$E$1505,Readings!$D$6:$D$1505,B9,Readings!$B$6:$B$1505,">="&(TODAY()-6),Readings!$B$6:$B$1505,"<="&TODAY()),1),"") | E9: =IFERROR(COUNTIFS(Readings!$D$6:$D$1505,B9,Readings!$B$6:$B$1505,">="&(TODAY()-6),Readings!$B$6:$B$1505,"<="&TODAY(),Readings!$G$6:$G$1505,"In range")/(COUNTIFS(Readings!$D$6:$D$1505,B9,Readings!$B$6:$B$1505,">="&(TODAY()-6),Readings!$B$6:$B$1505,"<="&TODAY(),Readings!$G$6:$G$1505,"In range")+COUNTIFS(Readings!$D$6:$D$1505,B9,Readings!$B$6:$B$1505,">="&(TODAY()-6),Readings!$B$6:$B$1505,"<="&TODAY(),Readings!$G$6:$G$1505,"Below")+COUNTIFS(Readings!$D$6:$D$1505,B9,Readings!$B$6:$B$1505,">="&(TODAY()-6),Readings!$B$6:$B$1505,"<="&TODAY(),Readings!$G$6:$G$1505,"Above")),"") | G9: =IF(P9="","Nothing to take today",ROUND(P9*1440,0)/1440) | H9: =IF(P9="","",INDEX(Medicines!$B$6:$B$25,Q9)) | I9: =IF(P9="","",IF(INDEX(Medicines!$C$6:$C$25,Q9)="","",INDEX(Medicines!$C$6:$C$25,Q9))) | J9: =IF(P9="","",IF(INDEX(Medicines!$T$6:$W$25,Q9,R9)<=INDEX(Medicines!$N$6:$N$25,Q9),"Taken",IF(G9<=MOD(NOW(),1),"Not taken","Later"))) | P9: =IFERROR(SMALL(Medicines!$P$6:$S$25,1),"") | Q9: =IF(P9="","",IFERROR(MATCH(P9,Medicines!$P$6:$P$25,0),IFERROR(MATCH(P9,Medicines!$Q$6:$Q$25,0),IFERROR(MATCH(P9,Medicines!$R$6:$R$25,0),MATCH(P9,Medicines!$S$6:$S$25,0))))) | R9: =IF(P9="","",IF(ISNUMBER(MATCH(P9,Medicines!$P$6:$P$25,0)),1,IF(ISNUMBER(MATCH(P9,Medicines!$Q$6:$Q$25,0)),2,IF(ISNUMBER(MATCH(P9,Medicines!$R$6:$R$25,0)),3,4))))
B10: After breakfast | C10: =COUNTIFS(Readings!$D$6:$D$1505,B10,Readings!$B$6:$B$1505,">="&(TODAY()-6),Readings!$B$6:$B$1505,"<="&TODAY(),Readings!$E$6:$E$1505,">0") | D10: =IFERROR(ROUND(AVERAGEIFS(Readings!$E$6:$E$1505,Readings!$D$6:$D$1505,B10,Readings!$B$6:$B$1505,">="&(TODAY()-6),Readings!$B$6:$B$1505,"<="&TODAY()),1),"") | E10: =IFERROR(COUNTIFS(Readings!$D$6:$D$1505,B10,Readings!$B$6:$B$1505,">="&(TODAY()-6),Readings!$B$6:$B$1505,"<="&TODAY(),Readings!$G$6:$G$1505,"In range")/(COUNTIFS(Readings!$D$6:$D$1505,B10,Readings!$B$6:$B$1505,">="&(TODAY()-6),Readings!$B$6:$B$1505,"<="&TODAY(),Readings!$G$6:$G$1505,"In range")+COUNTIFS(Readings!$D$6:$D$1505,B10,Readings!$B$6:$B$1505,">="&(TODAY()-6),Readings!$B$6:$B$1505,"<="&TODAY(),Readings!$G$6:$G$1505,"Below")+COUNTIFS(Readings!$D$6:$D$1505,B10,Readings!$B$6:$B$1505,">="&(TODAY()-6),Readings!$B$6:$B$1505,"<="&TODAY(),Readings!$G$6:$G$1505,"Above")),"") | G10: =IF(P10="","",ROUND(P10*1440,0)/1440) | H10: =IF(P10="","",INDEX(Medicines!$B$6:$B$25,Q10)) | I10: =IF(P10="","",IF(INDEX(Medicines!$C$6:$C$25,Q10)="","",INDEX(Medicines!$C$6:$C$25,Q10))) | J10: =IF(P10="","",IF(INDEX(Medicines!$T$6:$W$25,Q10,R10)<=INDEX(Medicines!$N$6:$N$25,Q10),"Taken",IF(G10<=MOD(NOW(),1),"Not taken","Later"))) | P10: =IFERROR(SMALL(Medicines!$P$6:$S$25,2),"") | Q10: =IF(P10="","",IFERROR(MATCH(P10,Medicines!$P$6:$P$25,0),IFERROR(MATCH(P10,Medicines!$Q$6:$Q$25,0),IFERROR(MATCH(P10,Medicines!$R$6:$R$25,0),MATCH(P10,Medicines!$S$6:$S$25,0))))) | R10: =IF(P10="","",IF(ISNUMBER(MATCH(P10,Medicines!$P$6:$P$25,0)),1,IF(ISNUMBER(MATCH(P10,Medicines!$Q$6:$Q$25,0)),2,IF(ISNUMBER(MATCH(P10,Medicines!$R$6:$R$25,0)),3,4))))
B11: Before lunch | C11: =COUNTIFS(Readings!$D$6:$D$1505,B11,Readings!$B$6:$B$1505,">="&(TODAY()-6),Readings!$B$6:$B$1505,"<="&TODAY(),Readings!$E$6:$E$1505,">0") | D11: =IFERROR(ROUND(AVERAGEIFS(Readings!$E$6:$E$1505,Readings!$D$6:$D$1505,B11,Readings!$B$6:$B$1505,">="&(TODAY()-6),Readings!$B$6:$B$1505,"<="&TODAY()),1),"") | E11: =IFERROR(COUNTIFS(Readings!$D$6:$D$1505,B11,Readings!$B$6:$B$1505,">="&(TODAY()-6),Readings!$B$6:$B$1505,"<="&TODAY(),Readings!$G$6:$G$1505,"In range")/(COUNTIFS(Readings!$D$6:$D$1505,B11,Readings!$B$6:$B$1505,">="&(TODAY()-6),Readings!$B$6:$B$1505,"<="&TODAY(),Readings!$G$6:$G$1505,"In range")+COUNTIFS(Readings!$D$6:$D$1505,B11,Readings!$B$6:$B$1505,">="&(TODAY()-6),Readings!$B$6:$B$1505,"<="&TODAY(),Readings!$G$6:$G$1505,"Below")+COUNTIFS(Readings!$D$6:$D$1505,B11,Readings!$B$6:$B$1505,">="&(TODAY()-6),Readings!$B$6:$B$1505,"<="&TODAY(),Readings!$G$6:$G$1505,"Above")),"") | G11: =IF(P11="","",ROUND(P11*1440,0)/1440) | H11: =IF(P11="","",INDEX(Medicines!$B$6:$B$25,Q11)) | I11: =IF(P11="","",IF(INDEX(Medicines!$C$6:$C$25,Q11)="","",INDEX(Medicines!$C$6:$C$25,Q11))) | J11: =IF(P11="","",IF(INDEX(Medicines!$T$6:$W$25,Q11,R11)<=INDEX(Medicines!$N$6:$N$25,Q11),"Taken",IF(G11<=MOD(NOW(),1),"Not taken","Later"))) | P11: =IFERROR(SMALL(Medicines!$P$6:$S$25,3),"") | Q11: =IF(P11="","",IFERROR(MATCH(P11,Medicines!$P$6:$P$25,0),IFERROR(MATCH(P11,Medicines!$Q$6:$Q$25,0),IFERROR(MATCH(P11,Medicines!$R$6:$R$25,0),MATCH(P11,Medicines!$S$6:$S$25,0))))) | R11: =IF(P11="","",IF(ISNUMBER(MATCH(P11,Medicines!$P$6:$P$25,0)),1,IF(ISNUMBER(MATCH(P11,Medicines!$Q$6:$Q$25,0)),2,IF(ISNUMBER(MATCH(P11,Medicines!$R$6:$R$25,0)),3,4))))
B12: After lunch | C12: =COUNTIFS(Readings!$D$6:$D$1505,B12,Readings!$B$6:$B$1505,">="&(TODAY()-6),Readings!$B$6:$B$1505,"<="&TODAY(),Readings!$E$6:$E$1505,">0") | D12: =IFERROR(ROUND(AVERAGEIFS(Readings!$E$6:$E$1505,Readings!$D$6:$D$1505,B12,Readings!$B$6:$B$1505,">="&(TODAY()-6),Readings!$B$6:$B$1505,"<="&TODAY()),1),"") | E12: =IFERROR(COUNTIFS(Readings!$D$6:$D$1505,B12,Readings!$B$6:$B$1505,">="&(TODAY()-6),Readings!$B$6:$B$1505,"<="&TODAY(),Readings!$G$6:$G$1505,"In range")/(COUNTIFS(Readings!$D$6:$D$1505,B12,Readings!$B$6:$B$1505,">="&(TODAY()-6),Readings!$B$6:$B$1505,"<="&TODAY(),Readings!$G$6:$G$1505,"In range")+COUNTIFS(Readings!$D$6:$D$1505,B12,Readings!$B$6:$B$1505,">="&(TODAY()-6),Readings!$B$6:$B$1505,"<="&TODAY(),Readings!$G$6:$G$1505,"Below")+COUNTIFS(Readings!$D$6:$D$1505,B12,Readings!$B$6:$B$1505,">="&(TODAY()-6),Readings!$B$6:$B$1505,"<="&TODAY(),Readings!$G$6:$G$1505,"Above")),"") | G12: =IF(P12="","",ROUND(P12*1440,0)/1440) | H12: =IF(P12="","",INDEX(Medicines!$B$6:$B$25,Q12)) | I12: =IF(P12="","",IF(INDEX(Medicines!$C$6:$C$25,Q12)="","",INDEX(Medicines!$C$6:$C$25,Q12))) | J12: =IF(P12="","",IF(INDEX(Medicines!$T$6:$W$25,Q12,R12)<=INDEX(Medicines!$N$6:$N$25,Q12),"Taken",IF(G12<=MOD(NOW(),1),"Not taken","Later"))) | P12: =IFERROR(SMALL(Medicines!$P$6:$S$25,4),"") | Q12: =IF(P12="","",IFERROR(MATCH(P12,Medicines!$P$6:$P$25,0),IFERROR(MATCH(P12,Medicines!$Q$6:$Q$25,0),IFERROR(MATCH(P12,Medicines!$R$6:$R$25,0),MATCH(P12,Medicines!$S$6:$S$25,0))))) | R12: =IF(P12="","",IF(ISNUMBER(MATCH(P12,Medicines!$P$6:$P$25,0)),1,IF(ISNUMBER(MATCH(P12,Medicines!$Q$6:$Q$25,0)),2,IF(ISNUMBER(MATCH(P12,Medicines!$R$6:$R$25,0)),3,4))))
B13: Before dinner | C13: =COUNTIFS(Readings!$D$6:$D$1505,B13,Readings!$B$6:$B$1505,">="&(TODAY()-6),Readings!$B$6:$B$1505,"<="&TODAY(),Readings!$E$6:$E$1505,">0") | D13: =IFERROR(ROUND(AVERAGEIFS(Readings!$E$6:$E$1505,Readings!$D$6:$D$1505,B13,Readings!$B$6:$B$1505,">="&(TODAY()-6),Readings!$B$6:$B$1505,"<="&TODAY()),1),"") | E13: =IFERROR(COUNTIFS(Readings!$D$6:$D$1505,B13,Readings!$B$6:$B$1505,">="&(TODAY()-6),Readings!$B$6:$B$1505,"<="&TODAY(),Readings!$G$6:$G$1505,"In range")/(COUNTIFS(Readings!$D$6:$D$1505,B13,Readings!$B$6:$B$1505,">="&(TODAY()-6),Readings!$B$6:$B$1505,"<="&TODAY(),Readings!$G$6:$G$1505,"In range")+COUNTIFS(Readings!$D$6:$D$1505,B13,Readings!$B$6:$B$1505,">="&(TODAY()-6),Readings!$B$6:$B$1505,"<="&TODAY(),Readings!$G$6:$G$1505,"Below")+COUNTIFS(Readings!$D$6:$D$1505,B13,Readings!$B$6:$B$1505,">="&(TODAY()-6),Readings!$B$6:$B$1505,"<="&TODAY(),Readings!$G$6:$G$1505,"Above")),"") | G13: =IF(P13="","",ROUND(P13*1440,0)/1440) | H13: =IF(P13="","",INDEX(Medicines!$B$6:$B$25,Q13)) | I13: =IF(P13="","",IF(INDEX(Medicines!$C$6:$C$25,Q13)="","",INDEX(Medicines!$C$6:$C$25,Q13))) | J13: =IF(P13="","",IF(INDEX(Medicines!$T$6:$W$25,Q13,R13)<=INDEX(Medicines!$N$6:$N$25,Q13),"Taken",IF(G13<=MOD(NOW(),1),"Not taken","Later"))) | P13: =IFERROR(SMALL(Medicines!$P$6:$S$25,5),"") | Q13: =IF(P13="","",IFERROR(MATCH(P13,Medicines!$P$6:$P$25,0),IFERROR(MATCH(P13,Medicines!$Q$6:$Q$25,0),IFERROR(MATCH(P13,Medicines!$R$6:$R$25,0),MATCH(P13,Medicines!$S$6:$S$25,0))))) | R13: =IF(P13="","",IF(ISNUMBER(MATCH(P13,Medicines!$P$6:$P$25,0)),1,IF(ISNUMBER(MATCH(P13,Medicines!$Q$6:$Q$25,0)),2,IF(ISNUMBER(MATCH(P13,Medicines!$R$6:$R$25,0)),3,4))))
B14: After dinner | C14: =COUNTIFS(Readings!$D$6:$D$1505,B14,Readings!$B$6:$B$1505,">="&(TODAY()-6),Readings!$B$6:$B$1505,"<="&TODAY(),Readings!$E$6:$E$1505,">0") | D14: =IFERROR(ROUND(AVERAGEIFS(Readings!$E$6:$E$1505,Readings!$D$6:$D$1505,B14,Readings!$B$6:$B$1505,">="&(TODAY()-6),Readings!$B$6:$B$1505,"<="&TODAY()),1),"") | E14: =IFERROR(COUNTIFS(Readings!$D$6:$D$1505,B14,Readings!$B$6:$B$1505,">="&(TODAY()-6),Readings!$B$6:$B$1505,"<="&TODAY(),Readings!$G$6:$G$1505,"In range")/(COUNTIFS(Readings!$D$6:$D$1505,B14,Readings!$B$6:$B$1505,">="&(TODAY()-6),Readings!$B$6:$B$1505,"<="&TODAY(),Readings!$G$6:$G$1505,"In range")+COUNTIFS(Readings!$D$6:$D$1505,B14,Readings!$B$6:$B$1505,">="&(TODAY()-6),Readings!$B$6:$B$1505,"<="&TODAY(),Readings!$G$6:$G$1505,"Below")+COUNTIFS(Readings!$D$6:$D$1505,B14,Readings!$B$6:$B$1505,">="&(TODAY()-6),Readings!$B$6:$B$1505,"<="&TODAY(),Readings!$G$6:$G$1505,"Above")),"") | G14: =IF(P14="","",ROUND(P14*1440,0)/1440) | H14: =IF(P14="","",INDEX(Medicines!$B$6:$B$25,Q14)) | I14: =IF(P14="","",IF(INDEX(Medicines!$C$6:$C$25,Q14)="","",INDEX(Medicines!$C$6:$C$25,Q14))) | J14: =IF(P14="","",IF(INDEX(Medicines!$T$6:$W$25,Q14,R14)<=INDEX(Medicines!$N$6:$N$25,Q14),"Taken",IF(G14<=MOD(NOW(),1),"Not taken","Later"))) | P14: =IFERROR(SMALL(Medicines!$P$6:$S$25,6),"") | Q14: =IF(P14="","",IFERROR(MATCH(P14,Medicines!$P$6:$P$25,0),IFERROR(MATCH(P14,Medicines!$Q$6:$Q$25,0),IFERROR(MATCH(P14,Medicines!$R$6:$R$25,0),MATCH(P14,Medicines!$S$6:$S$25,0))))) | R14: =IF(P14="","",IF(ISNUMBER(MATCH(P14,Medicines!$P$6:$P$25,0)),1,IF(ISNUMBER(MATCH(P14,Medicines!$Q$6:$Q$25,0)),2,IF(ISNUMBER(MATCH(P14,Medicines!$R$6:$R$25,0)),3,4))))
B15: Bedtime | C15: =COUNTIFS(Readings!$D$6:$D$1505,B15,Readings!$B$6:$B$1505,">="&(TODAY()-6),Readings!$B$6:$B$1505,"<="&TODAY(),Readings!$E$6:$E$1505,">0") | D15: =IFERROR(ROUND(AVERAGEIFS(Readings!$E$6:$E$1505,Readings!$D$6:$D$1505,B15,Readings!$B$6:$B$1505,">="&(TODAY()-6),Readings!$B$6:$B$1505,"<="&TODAY()),1),"") | E15: =IFERROR(COUNTIFS(Readings!$D$6:$D$1505,B15,Readings!$B$6:$B$1505,">="&(TODAY()-6),Readings!$B$6:$B$1505,"<="&TODAY(),Readings!$G$6:$G$1505,"In range")/(COUNTIFS(Readings!$D$6:$D$1505,B15,Readings!$B$6:$B$1505,">="&(TODAY()-6),Readings!$B$6:$B$1505,"<="&TODAY(),Readings!$G$6:$G$1505,"In range")+COUNTIFS(Readings!$D$6:$D$1505,B15,Readings!$B$6:$B$1505,">="&(TODAY()-6),Readings!$B$6:$B$1505,"<="&TODAY(),Readings!$G$6:$G$1505,"Below")+COUNTIFS(Readings!$D$6:$D$1505,B15,Readings!$B$6:$B$1505,">="&(TODAY()-6),Readings!$B$6:$B$1505,"<="&TODAY(),Readings!$G$6:$G$1505,"Above")),"") | G15: =IF(P15="","",ROUND(P15*1440,0)/1440) | H15: =IF(P15="","",INDEX(Medicines!$B$6:$B$25,Q15)) | I15: =IF(P15="","",IF(INDEX(Medicines!$C$6:$C$25,Q15)="","",INDEX(Medicines!$C$6:$C$25,Q15))) | J15: =IF(P15="","",IF(INDEX(Medicines!$T$6:$W$25,Q15,R15)<=INDEX(Medicines!$N$6:$N$25,Q15),"Taken",IF(G15<=MOD(NOW(),1),"Not taken","Later"))) | P15: =IFERROR(SMALL(Medicines!$P$6:$S$25,7),"") | Q15: =IF(P15="","",IFERROR(MATCH(P15,Medicines!$P$6:$P$25,0),IFERROR(MATCH(P15,Medicines!$Q$6:$Q$25,0),IFERROR(MATCH(P15,Medicines!$R$6:$R$25,0),MATCH(P15,Medicines!$S$6:$S$25,0))))) | R15: =IF(P15="","",IF(ISNUMBER(MATCH(P15,Medicines!$P$6:$P$25,0)),1,IF(ISNUMBER(MATCH(P15,Medicines!$Q$6:$Q$25,0)),2,IF(ISNUMBER(MATCH(P15,Medicines!$R$6:$R$25,0)),3,4))))
B16: Night | C16: =COUNTIFS(Readings!$D$6:$D$1505,B16,Readings!$B$6:$B$1505,">="&(TODAY()-6),Readings!$B$6:$B$1505,"<="&TODAY(),Readings!$E$6:$E$1505,">0") | D16: =IFERROR(ROUND(AVERAGEIFS(Readings!$E$6:$E$1505,Readings!$D$6:$D$1505,B16,Readings!$B$6:$B$1505,">="&(TODAY()-6),Readings!$B$6:$B$1505,"<="&TODAY()),1),"") | E16: =IFERROR(COUNTIFS(Readings!$D$6:$D$1505,B16,Readings!$B$6:$B$1505,">="&(TODAY()-6),Readings!$B$6:$B$1505,"<="&TODAY(),Readings!$G$6:$G$1505,"In range")/(COUNTIFS(Readings!$D$6:$D$1505,B16,Readings!$B$6:$B$1505,">="&(TODAY()-6),Readings!$B$6:$B$1505,"<="&TODAY(),Readings!$G$6:$G$1505,"In range")+COUNTIFS(Readings!$D$6:$D$1505,B16,Readings!$B$6:$B$1505,">="&(TODAY()-6),Readings!$B$6:$B$1505,"<="&TODAY(),Readings!$G$6:$G$1505,"Below")+COUNTIFS(Readings!$D$6:$D$1505,B16,Readings!$B$6:$B$1505,">="&(TODAY()-6),Readings!$B$6:$B$1505,"<="&TODAY(),Readings!$G$6:$G$1505,"Above")),"") | G16: =IF(P16="","",ROUND(P16*1440,0)/1440) | H16: =IF(P16="","",INDEX(Medicines!$B$6:$B$25,Q16)) | I16: =IF(P16="","",IF(INDEX(Medicines!$C$6:$C$25,Q16)="","",INDEX(Medicines!$C$6:$C$25,Q16))) | J16: =IF(P16="","",IF(INDEX(Medicines!$T$6:$W$25,Q16,R16)<=INDEX(Medicines!$N$6:$N$25,Q16),"Taken",IF(G16<=MOD(NOW(),1),"Not taken","Later"))) | P16: =IFERROR(SMALL(Medicines!$P$6:$S$25,8),"") | Q16: =IF(P16="","",IFERROR(MATCH(P16,Medicines!$P$6:$P$25,0),IFERROR(MATCH(P16,Medicines!$Q$6:$Q$25,0),IFERROR(MATCH(P16,Medicines!$R$6:$R$25,0),MATCH(P16,Medicines!$S$6:$S$25,0))))) | R16: =IF(P16="","",IF(ISNUMBER(MATCH(P16,Medicines!$P$6:$P$25,0)),1,IF(ISNUMBER(MATCH(P16,Medicines!$Q$6:$Q$25,0)),2,IF(ISNUMBER(MATCH(P16,Medicines!$R$6:$R$25,0)),3,4))))
B17: Other | C17: =COUNTIFS(Readings!$D$6:$D$1505,B17,Readings!$B$6:$B$1505,">="&(TODAY()-6),Readings!$B$6:$B$1505,"<="&TODAY(),Readings!$E$6:$E$1505,">0") | D17: =IFERROR(ROUND(AVERAGEIFS(Readings!$E$6:$E$1505,Readings!$D$6:$D$1505,B17,Readings!$B$6:$B$1505,">="&(TODAY()-6),Readings!$B$6:$B$1505,"<="&TODAY()),1),"") | E17: =IFERROR(COUNTIFS(Readings!$D$6:$D$1505,B17,Readings!$B$6:$B$1505,">="&(TODAY()-6),Readings!$B$6:$B$1505,"<="&TODAY(),Readings!$G$6:$G$1505,"In range")/(COUNTIFS(Readings!$D$6:$D$1505,B17,Readings!$B$6:$B$1505,">="&(TODAY()-6),Readings!$B$6:$B$1505,"<="&TODAY(),Readings!$G$6:$G$1505,"In range")+COUNTIFS(Readings!$D$6:$D$1505,B17,Readings!$B$6:$B$1505,">="&(TODAY()-6),Readings!$B$6:$B$1505,"<="&TODAY(),Readings!$G$6:$G$1505,"Below")+COUNTIFS(Readings!$D$6:$D$1505,B17,Readings!$B$6:$B$1505,">="&(TODAY()-6),Readings!$B$6:$B$1505,"<="&TODAY(),Readings!$G$6:$G$1505,"Above")),"") | G17: =IF(P17="","",ROUND(P17*1440,0)/1440) | H17: =IF(P17="","",INDEX(Medicines!$B$6:$B$25,Q17)) | I17: =IF(P17="","",IF(INDEX(Medicines!$C$6:$C$25,Q17)="","",INDEX(Medicines!$C$6:$C$25,Q17))) | J17: =IF(P17="","",IF(INDEX(Medicines!$T$6:$W$25,Q17,R17)<=INDEX(Medicines!$N$6:$N$25,Q17),"Taken",IF(G17<=MOD(NOW(),1),"Not taken","Later"))) | P17: =IFERROR(SMALL(Medicines!$P$6:$S$25,9),"") | Q17: =IF(P17="","",IFERROR(MATCH(P17,Medicines!$P$6:$P$25,0),IFERROR(MATCH(P17,Medicines!$Q$6:$Q$25,0),IFERROR(MATCH(P17,Medicines!$R$6:$R$25,0),MATCH(P17,Medicines!$S$6:$S$25,0))))) | R17: =IF(P17="","",IF(ISNUMBER(MATCH(P17,Medicines!$P$6:$P$25,0)),1,IF(ISNUMBER(MATCH(P17,Medicines!$Q$6:$Q$25,0)),2,IF(ISNUMBER(MATCH(P17,Medicines!$R$6:$R$25,0)),3,4))))
G18: =IF(P18="","",ROUND(P18*1440,0)/1440) | H18: =IF(P18="","",INDEX(Medicines!$B$6:$B$25,Q18)) | I18: =IF(P18="","",IF(INDEX(Medicines!$C$6:$C$25,Q18)="","",INDEX(Medicines!$C$6:$C$25,Q18))) | J18: =IF(P18="","",IF(INDEX(Medicines!$T$6:$W$25,Q18,R18)<=INDEX(Medicines!$N$6:$N$25,Q18),"Taken",IF(G18<=MOD(NOW(),1),"Not taken","Later"))) | P18: =IFERROR(SMALL(Medicines!$P$6:$S$25,10),"") | Q18: =IF(P18="","",IFERROR(MATCH(P18,Medicines!$P$6:$P$25,0),IFERROR(MATCH(P18,Medicines!$Q$6:$Q$25,0),IFERROR(MATCH(P18,Medicines!$R$6:$R$25,0),MATCH(P18,Medicines!$S$6:$S$25,0))))) | R18: =IF(P18="","",IF(ISNUMBER(MATCH(P18,Medicines!$P$6:$P$25,0)),1,IF(ISNUMBER(MATCH(P18,Medicines!$Q$6:$Q$25,0)),2,IF(ISNUMBER(MATCH(P18,Medicines!$R$6:$R$25,0)),3,4))))
B20: Last 14 days | C20: Average | D20: Lowest | E20: Highest
B21: =(TODAY()-13) | C21: =IFERROR(ROUND(AVERAGEIFS(Readings!$E$6:$E$1505,Readings!$B$6:$B$1505,B21),1),"") | D21: =IF(C21="","",IFERROR(SMALL(Readings!$O$6:$O$1505,COUNTIF(Readings!$O$6:$O$1505,"<"&B21*10000)+1)-B21*10000,"")) | E21: =IF(C21="","",IFERROR(LARGE(Readings!$O$6:$O$1505,COUNTIF(Readings!$O$6:$O$1505,">="&(B21+1)*10000)+1)-B21*10000,"")) | G21: =DAY(B21)&" "&CHOOSE(MONTH(B21),"Jan","Feb","Mar","Apr","May","Jun","Jul","Aug","Sep","Oct","Nov","Dec") | H21: =IF(C21="",NA(),C21) | I21: =IF(D21="",NA(),D21) | J21: =IF(E21="",NA(),E21)
B22: =(TODAY()-12) | C22: =IFERROR(ROUND(AVERAGEIFS(Readings!$E$6:$E$1505,Readings!$B$6:$B$1505,B22),1),"") | D22: =IF(C22="","",IFERROR(SMALL(Readings!$O$6:$O$1505,COUNTIF(Readings!$O$6:$O$1505,"<"&B22*10000)+1)-B22*10000,"")) | E22: =IF(C22="","",IFERROR(LARGE(Readings!$O$6:$O$1505,COUNTIF(Readings!$O$6:$O$1505,">="&(B22+1)*10000)+1)-B22*10000,"")) | G22: =DAY(B22)&" "&CHOOSE(MONTH(B22),"Jan","Feb","Mar","Apr","May","Jun","Jul","Aug","Sep","Oct","Nov","Dec") | H22: =IF(C22="",NA(),C22) | I22: =IF(D22="",NA(),D22) | J22: =IF(E22="",NA(),E22)
B23: =(TODAY()-11) | C23: =IFERROR(ROUND(AVERAGEIFS(Readings!$E$6:$E$1505,Readings!$B$6:$B$1505,B23),1),"") | D23: =IF(C23="","",IFERROR(SMALL(Readings!$O$6:$O$1505,COUNTIF(Readings!$O$6:$O$1505,"<"&B23*10000)+1)-B23*10000,"")) | E23: =IF(C23="","",IFERROR(LARGE(Readings!$O$6:$O$1505,COUNTIF(Readings!$O$6:$O$1505,">="&(B23+1)*10000)+1)-B23*10000,"")) | G23: =DAY(B23)&" "&CHOOSE(MONTH(B23),"Jan","Feb","Mar","Apr","May","Jun","Jul","Aug","Sep","Oct","Nov","Dec") | H23: =IF(C23="",NA(),C23) | I23: =IF(D23="",NA(),D23) | J23: =IF(E23="",NA(),E23)
B24: =(TODAY()-10) | C24: =IFERROR(ROUND(AVERAGEIFS(Readings!$E$6:$E$1505,Readings!$B$6:$B$1505,B24),1),"") | D24: =IF(C24="","",IFERROR(SMALL(Readings!$O$6:$O$1505,COUNTIF(Readings!$O$6:$O$1505,"<"&B24*10000)+1)-B24*10000,"")) | E24: =IF(C24="","",IFERROR(LARGE(Readings!$O$6:$O$1505,COUNTIF(Readings!$O$6:$O$1505,">="&(B24+1)*10000)+1)-B24*10000,"")) | G24: =DAY(B24)&" "&CHOOSE(MONTH(B24),"Jan","Feb","Mar","Apr","May","Jun","Jul","Aug","Sep","Oct","Nov","Dec") | H24: =IF(C24="",NA(),C24) | I24: =IF(D24="",NA(),D24) | J24: =IF(E24="",NA(),E24)
B25: =(TODAY()-9) | C25: =IFERROR(ROUND(AVERAGEIFS(Readings!$E$6:$E$1505,Readings!$B$6:$B$1505,B25),1),"") | D25: =IF(C25="","",IFERROR(SMALL(Readings!$O$6:$O$1505,COUNTIF(Readings!$O$6:$O$1505,"<"&B25*10000)+1)-B25*10000,"")) | E25: =IF(C25="","",IFERROR(LARGE(Readings!$O$6:$O$1505,COUNTIF(Readings!$O$6:$O$1505,">="&(B25+1)*10000)+1)-B25*10000,"")) | G25: =DAY(B25)&" "&CHOOSE(MONTH(B25),"Jan","Feb","Mar","Apr","May","Jun","Jul","Aug","Sep","Oct","Nov","Dec") | H25: =IF(C25="",NA(),C25) | I25: =IF(D25="",NA(),D25) | J25: =IF(E25="",NA(),E25)
B26: =(TODAY()-8) | C26: =IFERROR(ROUND(AVERAGEIFS(Readings!$E$6:$E$1505,Readings!$B$6:$B$1505,B26),1),"") | D26: =IF(C26="","",IFERROR(SMALL(Readings!$O$6:$O$1505,COUNTIF(Readings!$O$6:$O$1505,"<"&B26*10000)+1)-B26*10000,"")) | E26: =IF(C26="","",IFERROR(LARGE(Readings!$O$6:$O$1505,COUNTIF(Readings!$O$6:$O$1505,">="&(B26+1)*10000)+1)-B26*10000,"")) | G26: =DAY(B26)&" "&CHOOSE(MONTH(B26),"Jan","Feb","Mar","Apr","May","Jun","Jul","Aug","Sep","Oct","Nov","Dec") | H26: =IF(C26="",NA(),C26) | I26: =IF(D26="",NA(),D26) | J26: =IF(E26="",NA(),E26)
B27: =(TODAY()-7) | C27: =IFERROR(ROUND(AVERAGEIFS(Readings!$E$6:$E$1505,Readings!$B$6:$B$1505,B27),1),"") | D27: =IF(C27="","",IFERROR(SMALL(Readings!$O$6:$O$1505,COUNTIF(Readings!$O$6:$O$1505,"<"&B27*10000)+1)-B27*10000,"")) | E27: =IF(C27="","",IFERROR(LARGE(Readings!$O$6:$O$1505,COUNTIF(Readings!$O$6:$O$1505,">="&(B27+1)*10000)+1)-B27*10000,"")) | G27: =DAY(B27)&" "&CHOOSE(MONTH(B27),"Jan","Feb","Mar","Apr","May","Jun","Jul","Aug","Sep","Oct","Nov","Dec") | H27: =IF(C27="",NA(),C27) | I27: =IF(D27="",NA(),D27) | J27: =IF(E27="",NA(),E27)
B28: =(TODAY()-6) | C28: =IFERROR(ROUND(AVERAGEIFS(Readings!$E$6:$E$1505,Readings!$B$6:$B$1505,B28),1),"") | D28: =IF(C28="","",IFERROR(SMALL(Readings!$O$6:$O$1505,COUNTIF(Readings!$O$6:$O$1505,"<"&B28*10000)+1)-B28*10000,"")) | E28: =IF(C28="","",IFERROR(LARGE(Readings!$O$6:$O$1505,COUNTIF(Readings!$O$6:$O$1505,">="&(B28+1)*10000)+1)-B28*10000,"")) | G28: =DAY(B28)&" "&CHOOSE(MONTH(B28),"Jan","Feb","Mar","Apr","May","Jun","Jul","Aug","Sep","Oct","Nov","Dec") | H28: =IF(C28="",NA(),C28) | I28: =IF(D28="",NA(),D28) | J28: =IF(E28="",NA(),E28)
B29: =(TODAY()-5) | C29: =IFERROR(ROUND(AVERAGEIFS(Readings!$E$6:$E$1505,Readings!$B$6:$B$1505,B29),1),"") | D29: =IF(C29="","",IFERROR(SMALL(Readings!$O$6:$O$1505,COUNTIF(Readings!$O$6:$O$1505,"<"&B29*10000)+1)-B29*10000,"")) | E29: =IF(C29="","",IFERROR(LARGE(Readings!$O$6:$O$1505,COUNTIF(Readings!$O$6:$O$1505,">="&(B29+1)*10000)+1)-B29*10000,"")) | G29: =DAY(B29)&" "&CHOOSE(MONTH(B29),"Jan","Feb","Mar","Apr","May","Jun","Jul","Aug","Sep","Oct","Nov","Dec") | H29: =IF(C29="",NA(),C29) | I29: =IF(D29="",NA(),D29) | J29: =IF(E29="",NA(),E29)
B30: =(TODAY()-4) | C30: =IFERROR(ROUND(AVERAGEIFS(Readings!$E$6:$E$1505,Readings!$B$6:$B$1505,B30),1),"") | D30: =IF(C30="","",IFERROR(SMALL(Readings!$O$6:$O$1505,COUNTIF(Readings!$O$6:$O$1505,"<"&B30*10000)+1)-B30*10000,"")) | E30: =IF(C30="","",IFERROR(LARGE(Readings!$O$6:$O$1505,COUNTIF(Readings!$O$6:$O$1505,">="&(B30+1)*10000)+1)-B30*10000,"")) | G30: =DAY(B30)&" "&CHOOSE(MONTH(B30),"Jan","Feb","Mar","Apr","May","Jun","Jul","Aug","Sep","Oct","Nov","Dec") | H30: =IF(C30="",NA(),C30) | I30: =IF(D30="",NA(),D30) | J30: =IF(E30="",NA(),E30)
B31: =(TODAY()-3) | C31: =IFERROR(ROUND(AVERAGEIFS(Readings!$E$6:$E$1505,Readings!$B$6:$B$1505,B31),1),"") | D31: =IF(C31="","",IFERROR(SMALL(Readings!$O$6:$O$1505,COUNTIF(Readings!$O$6:$O$1505,"<"&B31*10000)+1)-B31*10000,"")) | E31: =IF(C31="","",IFERROR(LARGE(Readings!$O$6:$O$1505,COUNTIF(Readings!$O$6:$O$1505,">="&(B31+1)*10000)+1)-B31*10000,"")) | G31: =DAY(B31)&" "&CHOOSE(MONTH(B31),"Jan","Feb","Mar","Apr","May","Jun","Jul","Aug","Sep","Oct","Nov","Dec") | H31: =IF(C31="",NA(),C31) | I31: =IF(D31="",NA(),D31) | J31: =IF(E31="",NA(),E31)
B32: =(TODAY()-2) | C32: =IFERROR(ROUND(AVERAGEIFS(Readings!$E$6:$E$1505,Readings!$B$6:$B$1505,B32),1),"") | D32: =IF(C32="","",IFERROR(SMALL(Readings!$O$6:$O$1505,COUNTIF(Readings!$O$6:$O$1505,"<"&B32*10000)+1)-B32*10000,"")) | E32: =IF(C32="","",IFERROR(LARGE(Readings!$O$6:$O$1505,COUNTIF(Readings!$O$6:$O$1505,">="&(B32+1)*10000)+1)-B32*10000,"")) | G32: =DAY(B32)&" "&CHOOSE(MONTH(B32),"Jan","Feb","Mar","Apr","May","Jun","Jul","Aug","Sep","Oct","Nov","Dec") | H32: =IF(C32="",NA(),C32) | I32: =IF(D32="",NA(),D32) | J32: =IF(E32="",NA(),E32)
B33: =(TODAY()-1) | C33: =IFERROR(ROUND(AVERAGEIFS(Readings!$E$6:$E$1505,Readings!$B$6:$B$1505,B33),1),"") | D33: =IF(C33="","",IFERROR(SMALL(Readings!$O$6:$O$1505,COUNTIF(Readings!$O$6:$O$1505,"<"&B33*10000)+1)-B33*10000,"")) | E33: =IF(C33="","",IFERROR(LARGE(Readings!$O$6:$O$1505,COUNTIF(Readings!$O$6:$O$1505,">="&(B33+1)*10000)+1)-B33*10000,"")) | G33: =DAY(B33)&" "&CHOOSE(MONTH(B33),"Jan","Feb","Mar","Apr","May","Jun","Jul","Aug","Sep","Oct","Nov","Dec") | H33: =IF(C33="",NA(),C33) | I33: =IF(D33="",NA(),D33) | J33: =IF(E33="",NA(),E33)
B34: =(TODAY()-0) | C34: =IFERROR(ROUND(AVERAGEIFS(Readings!$E$6:$E$1505,Readings!$B$6:$B$1505,B34),1),"") | D34: =IF(C34="","",IFERROR(SMALL(Readings!$O$6:$O$1505,COUNTIF(Readings!$O$6:$O$1505,"<"&B34*10000)+1)-B34*10000,"")) | E34: =IF(C34="","",IFERROR(LARGE(Readings!$O$6:$O$1505,COUNTIF(Readings!$O$6:$O$1505,">="&(B34+1)*10000)+1)-B34*10000,"")) | G34: =DAY(B34)&" "&CHOOSE(MONTH(B34),"Jan","Feb","Mar","Apr","May","Jun","Jul","Aug","Sep","Oct","Nov","Dec") | H34: =IF(C34="",NA(),C34) | I34: =IF(D34="",NA(),D34) | J34: =IF(E34="",NA(),E34)

Sheet Readings
B2: Readings
B3: One line per reading. Each is marked against the range for its moment on the Settings tab.
B5: Date | C5: Time | D5: Moment | E5: Reading | F5: Notes | G5: Range
B6: 46249 | C6: 0.29513889 | D6: Fasting | E6: 122 | G6: =IF(OR(B6="",E6="",J6="",K6=""),"",IF(E6<J6,"Below",IF(E6>K6,"Above","In range"))) | J6: =IF(M6="","",IF(INDEX(Settings!$C$10:$C$18,M6)="","",INDEX(Settings!$C$10:$C$18,M6))) | K6: =IF(M6="","",IF(INDEX(Settings!$D$10:$D$18,M6)="","",INDEX(Settings!$D$10:$D$18,M6))) | L6: =IF(OR(B6="",E6=""),"",B6+MOD(N(C6),1)+ROW()/10000000) | M6: =IF(D6="","",IFERROR(MATCH(D6,Settings!$B$10:$B$18,0),"")) | N6: =IF(OR(B6="",E6="",M6=""),"",IF(AND(B6>=Settings!$C$6,B6<=Settings!$C$7),M6*10000+E6,"")) | O6: =IF(OR(B6="",E6=""),"",B6*10000+E6) | P6: =IF(N6="","",E6)
B7: 46249 | C7: 0.40625 | D7: After breakfast | E7: 187 | G7: =IF(OR(B7="",E7="",J7="",K7=""),"",IF(E7<J7,"Below",IF(E7>K7,"Above","In range"))) | J7: =IF(M7="","",IF(INDEX(Settings!$C$10:$C$18,M7)="","",INDEX(Settings!$C$10:$C$18,M7))) | K7: =IF(M7="","",IF(INDEX(Settings!$D$10:$D$18,M7)="","",INDEX(Settings!$D$10:$D$18,M7))) | L7: =IF(OR(B7="",E7=""),"",B7+MOD(N(C7),1)+ROW()/10000000) | M7: =IF(D7="","",IFERROR(MATCH(D7,Settings!$B$10:$B$18,0),"")) | N7: =IF(OR(B7="",E7="",M7=""),"",IF(AND(B7>=Settings!$C$6,B7<=Settings!$C$7),M7*10000+E7,"")) | O7: =IF(OR(B7="",E7=""),"",B7*10000+E7) | P7: =IF(N7="","",E7)
B8: 46249 | C8: 0.76041667 | D8: Before dinner | E8: 104 | G8: =IF(OR(B8="",E8="",J8="",K8=""),"",IF(E8<J8,"Below",IF(E8>K8,"Above","In range"))) | J8: =IF(M8="","",IF(INDEX(Settings!$C$10:$C$18,M8)="","",INDEX(Settings!$C$10:$C$18,M8))) | K8: =IF(M8="","",IF(INDEX(Settings!$D$10:$D$18,M8)="","",INDEX(Settings!$D$10:$D$18,M8))) | L8: =IF(OR(B8="",E8=""),"",B8+MOD(N(C8),1)+ROW()/10000000) | M8: =IF(D8="","",IFERROR(MATCH(D8,Settings!$B$10:$B$18,0),"")) | N8: =IF(OR(B8="",E8="",M8=""),"",IF(AND(B8>=Settings!$C$6,B8<=Settings!$C$7),M8*10000+E8,"")) | O8: =IF(OR(B8="",E8=""),"",B8*10000+E8) | P8: =IF(N8="","",E8)
B9: 46249 | C9: 0.86458333 | D9: After dinner | E9: 143 | G9: =IF(OR(B9="",E9="",J9="",K9=""),"",IF(E9<J9,"Below",IF(E9>K9,"Above","In range"))) | J9: =IF(M9="","",IF(INDEX(Settings!$C$10:$C$18,M9)="","",INDEX(Settings!$C$10:$C$18,M9))) | K9: =IF(M9="","",IF(INDEX(Settings!$D$10:$D$18,M9)="","",INDEX(Settings!$D$10:$D$18,M9))) | L9: =IF(OR(B9="",E9=""),"",B9+MOD(N(C9),1)+ROW()/10000000) | M9: =IF(D9="","",IFERROR(MATCH(D9,Settings!$B$10:$B$18,0),"")) | N9: =IF(OR(B9="",E9="",M9=""),"",IF(AND(B9>=Settings!$C$6,B9<=Settings!$C$7),M9*10000+E9,"")) | O9: =IF(OR(B9="",E9=""),"",B9*10000+E9) | P9: =IF(N9="","",E9)
B10: 46250 | C10: 0.30208333 | D10: Fasting | E10: 93 | G10: =IF(OR(B10="",E10="",J10="",K10=""),"",IF(E10<J10,"Below",IF(E10>K10,"Above","In range"))) | J10: =IF(M10="","",IF(INDEX(Settings!$C$10:$C$18,M10)="","",INDEX(Settings!$C$10:$C$18,M10))) | K10: =IF(M10="","",IF(INDEX(Settings!$D$10:$D$18,M10)="","",INDEX(Settings!$D$10:$D$18,M10))) | L10: =IF(OR(B10="",E10=""),"",B10+MOD(N(C10),1)+ROW()/10000000) | M10: =IF(D10="","",IFERROR(MATCH(D10,Settings!$B$10:$B$18,0),"")) | N10: =IF(OR(B10="",E10="",M10=""),"",IF(AND(B10>=Settings!$C$6,B10<=Settings!$C$7),M10*10000+E10,"")) | O10: =IF(OR(B10="",E10=""),"",B10*10000+E10) | P10: =IF(N10="","",E10)
B11: 46250 | C11: 0.40277778 | D11: After breakfast | E11: 153 | G11: =IF(OR(B11="",E11="",J11="",K11=""),"",IF(E11<J11,"Below",IF(E11>K11,"Above","In range"))) | J11: =IF(M11="","",IF(INDEX(Settings!$C$10:$C$18,M11)="","",INDEX(Settings!$C$10:$C$18,M11))) | K11: =IF(M11="","",IF(INDEX(Settings!$D$10:$D$18,M11)="","",INDEX(Settings!$D$10:$D$18,M11))) | L11: =IF(OR(B11="",E11=""),"",B11+MOD(N(C11),1)+ROW()/10000000) | M11: =IF(D11="","",IFERROR(MATCH(D11,Settings!$B$10:$B$18,0),"")) | N11: =IF(OR(B11="",E11="",M11=""),"",IF(AND(B11>=Settings!$C$6,B11<=Settings!$C$7),M11*10000+E11,"")) | O11: =IF(OR(B11="",E11=""),"",B11*10000+E11) | P11: =IF(N11="","",E11)
B12: 46250 | C12: 0.77083333 | D12: Before dinner | E12: 115 | G12: =IF(OR(B12="",E12="",J12="",K12=""),"",IF(E12<J12,"Below",IF(E12>K12,"Above","In range"))) | J12: =IF(M12="","",IF(INDEX(Settings!$C$10:$C$18,M12)="","",INDEX(Settings!$C$10:$C$18,M12))) | K12: =IF(M12="","",IF(INDEX(Settings!$D$10:$D$18,M12)="","",INDEX(Settings!$D$10:$D$18,M12))) | L12: =IF(OR(B12="",E12=""),"",B12+MOD(N(C12),1)+ROW()/10000000) | M12: =IF(D12="","",IFERROR(MATCH(D12,Settings!$B$10:$B$18,0),"")) | N12: =IF(OR(B12="",E12="",M12=""),"",IF(AND(B12>=Settings!$C$6,B12<=Settings!$C$7),M12*10000+E12,"")) | O12: =IF(OR(B12="",E12=""),"",B12*10000+E12) | P12: =IF(N12="","",E12)
B13: 46250 | C13: 0.9375 | D13: Bedtime | E13: 110 | G13: =IF(OR(B13="",E13="",J13="",K13=""),"",IF(E13<J13,"Below",IF(E13>K13,"Above","In range"))) | J13: =IF(M13="","",IF(INDEX(Settings!$C$10:$C$18,M13)="","",INDEX(Settings!$C$10:$C$18,M13))) | K13: =IF(M13="","",IF(INDEX(Settings!$D$10:$D$18,M13)="","",INDEX(Settings!$D$10:$D$18,M13))) | L13: =IF(OR(B13="",E13=""),"",B13+MOD(N(C13),1)+ROW()/10000000) | M13: =IF(D13="","",IFERROR(MATCH(D13,Settings!$B$10:$B$18,0),"")) | N13: =IF(OR(B13="",E13="",M13=""),"",IF(AND(B13>=Settings!$C$6,B13<=Settings!$C$7),M13*10000+E13,"")) | O13: =IF(OR(B13="",E13=""),"",B13*10000+E13) | P13: =IF(N13="","",E13)
B14: 46251 | C14: 0.30208333 | D14: Fasting | E14: 119 | G14: =IF(OR(B14="",E14="",J14="",K14=""),"",IF(E14<J14,"Below",IF(E14>K14,"Above","In range"))) | J14: =IF(M14="","",IF(INDEX(Settings!$C$10:$C$18,M14)="","",INDEX(Settings!$C$10:$C$18,M14))) | K14: =IF(M14="","",IF(INDEX(Settings!$D$10:$D$18,M14)="","",INDEX(Settings!$D$10:$D$18,M14))) | L14: =IF(OR(B14="",E14=""),"",B14+MOD(N(C14),1)+ROW()/10000000) | M14: =IF(D14="","",IFERROR(MATCH(D14,Settings!$B$10:$B$18,0),"")) | N14: =IF(OR(B14="",E14="",M14=""),"",IF(AND(B14>=Settings!$C$6,B14<=Settings!$C$7),M14*10000+E14,"")) | O14: =IF(OR(B14="",E14=""),"",B14*10000+E14) | P14: =IF(N14="","",E14)
B15: 46251 | C15: 0.40277778 | D15: After breakfast | E15: 163 | G15: =IF(OR(B15="",E15="",J15="",K15=""),"",IF(E15<J15,"Below",IF(E15>K15,"Above","In range"))) | J15: =IF(M15="","",IF(INDEX(Settings!$C$10:$C$18,M15)="","",INDEX(Settings!$C$10:$C$18,M15))) | K15: =IF(M15="","",IF(INDEX(Settings!$D$10:$D$18,M15)="","",INDEX(Settings!$D$10:$D$18,M15))) | L15: =IF(OR(B15="",E15=""),"",B15+MOD(N(C15),1)+ROW()/10000000) | M15: =IF(D15="","",IFERROR(MATCH(D15,Settings!$B$10:$B$18,0),"")) | N15: =IF(OR(B15="",E15="",M15=""),"",IF(AND(B15>=Settings!$C$6,B15<=Settings!$C$7),M15*10000+E15,"")) | O15: =IF(OR(B15="",E15=""),"",B15*10000+E15) | P15: =IF(N15="","",E15)
B16: 46252 | C16: 0.29861111 | D16: Fasting | E16: 118 | F16: Walked 30 min after lunch | G16: =IF(OR(B16="",E16="",J16="",K16=""),"",IF(E16<J16,"Below",IF(E16>K16,"Above","In range"))) | J16: =IF(M16="","",IF(INDEX(Settings!$C$10:$C$18,M16)="","",INDEX(Settings!$C$10:$C$18,M16))) | K16: =IF(M16="","",IF(INDEX(Settings!$D$10:$D$18,M16)="","",INDEX(Settings!$D$10:$D$18,M16))) | L16: =IF(OR(B16="",E16=""),"",B16+MOD(N(C16),1)+ROW()/10000000) | M16: =IF(D16="","",IFERROR(MATCH(D16,Settings!$B$10:$B$18,0),"")) | N16: =IF(OR(B16="",E16="",M16=""),"",IF(AND(B16>=Settings!$C$6,B16<=Settings!$C$7),M16*10000+E16,"")) | O16: =IF(OR(B16="",E16=""),"",B16*10000+E16) | P16: =IF(N16="","",E16)
B17: 46252 | C17: 0.39583333 | D17: After breakfast | E17: 132 | G17: =IF(OR(B17="",E17="",J17="",K17=""),"",IF(E17<J17,"Below",IF(E17>K17,"Above","In range"))) | J17: =IF(M17="","",IF(INDEX(Settings!$C$10:$C$18,M17)="","",INDEX(Settings!$C$10:$C$18,M17))) | K17: =IF(M17="","",IF(INDEX(Settings!$D$10:$D$18,M17)="","",INDEX(Settings!$D$10:$D$18,M17))) | L17: =IF(OR(B17="",E17=""),"",B17+MOD(N(C17),1)+ROW()/10000000) | M17: =IF(D17="","",IFERROR(MATCH(D17,Settings!$B$10:$B$18,0),"")) | N17: =IF(OR(B17="",E17="",M17=""),"",IF(AND(B17>=Settings!$C$6,B17<=Settings!$C$7),M17*10000+E17,"")) | O17: =IF(OR(B17="",E17=""),"",B17*10000+E17) | P17: =IF(N17="","",E17)
B18: 46252 | C18: 0.85416667 | D18: After dinner | E18: 154 | G18: =IF(OR(B18="",E18="",J18="",K18=""),"",IF(E18<J18,"Below",IF(E18>K18,"Above","In range"))) | J18: =IF(M18="","",IF(INDEX(Settings!$C$10:$C$18,M18)="","",INDEX(Settings!$C$10:$C$18,M18))) | K18: =IF(M18="","",IF(INDEX(Settings!$D$10:$D$18,M18)="","",INDEX(Settings!$D$10:$D$18,M18))) | L18: =IF(OR(B18="",E18=""),"",B18+MOD(N(C18),1)+ROW()/10000000) | M18: =IF(D18="","",IFERROR(MATCH(D18,Settings!$B$10:$B$18,0),"")) | N18: =IF(OR(B18="",E18="",M18=""),"",IF(AND(B18>=Settings!$C$6,B18<=Settings!$C$7),M18*10000+E18,"")) | O18: =IF(OR(B18="",E18=""),"",B18*10000+E18) | P18: =IF(N18="","",E18)
B19: 46252 | C19: 0.9375 | D19: Bedtime | E19: 150 | G19: =IF(OR(B19="",E19="",J19="",K19=""),"",IF(E19<J19,"Below",IF(E19>K19,"Above","In range"))) | J19: =IF(M19="","",IF(INDEX(Settings!$C$10:$C$18,M19)="","",INDEX(Settings!$C$10:$C$18,M19))) | K19: =IF(M19="","",IF(INDEX(Settings!$D$10:$D$18,M19)="","",INDEX(Settings!$D$10:$D$18,M19))) | L19: =IF(OR(B19="",E19=""),"",B19+MOD(N(C19),1)+ROW()/10000000) | M19: =IF(D19="","",IFERROR(MATCH(D19,Settings!$B$10:$B$18,0),"")) | N19: =IF(OR(B19="",E19="",M19=""),"",IF(AND(B19>=Settings!$C$6,B19<=Settings!$C$7),M19*10000+E19,"")) | O19: =IF(OR(B19="",E19=""),"",B19*10000+E19) | P19: =IF(N19="","",E19)
B20: 46253 | C20: 0.29861111 | D20: Fasting | E20: 106 | G20: =IF(OR(B20="",E20="",J20="",K20=""),"",IF(E20<J20,"Below",IF(E20>K20,"Above","In range"))) | J20: =IF(M20="","",IF(INDEX(Settings!$C$10:$C$18,M20)="","",INDEX(Settings!$C$10:$C$18,M20))) | K20: =IF(M20="","",IF(INDEX(Settings!$D$10:$D$18,M20)="","",INDEX(Settings!$D$10:$D$18,M20))) | L20: =IF(OR(B20="",E20=""),"",B20+MOD(N(C20),1)+ROW()/10000000) | M20: =IF(D20="","",IFERROR(MATCH(D20,Settings!$B$10:$B$18,0),"")) | N20: =IF(OR(B20="",E20="",M20=""),"",IF(AND(B20>=Settings!$C$6,B20<=Settings!$C$7),M20*10000+E20,"")) | O20: =IF(OR(B20="",E20=""),"",B20*10000+E20) | P20: =IF(N20="","",E20)
B21: 46253 | C21: 0.40625 | D21: After breakfast | E21: 181 | G21: =IF(OR(B21="",E21="",J21="",K21=""),"",IF(E21<J21,"Below",IF(E21>K21,"Above","In range"))) | J21: =IF(M21="","",IF(INDEX(Settings!$C$10:$C$18,M21)="","",INDEX(Settings!$C$10:$C$18,M21))) | K21: =IF(M21="","",IF(INDEX(Settings!$D$10:$D$18,M21)="","",INDEX(Settings!$D$10:$D$18,M21))) | L21: =IF(OR(B21="",E21=""),"",B21+MOD(N(C21),1)+ROW()/10000000) | M21: =IF(D21="","",IFERROR(MATCH(D21,Settings!$B$10:$B$18,0),"")) | N21: =IF(OR(B21="",E21="",M21=""),"",IF(AND(B21>=Settings!$C$6,B21<=Settings!$C$7),M21*10000+E21,"")) | O21: =IF(OR(B21="",E21=""),"",B21*10000+E21) | P21: =IF(N21="","",E21)
B22: 46253 | C22: 0.75 | D22: Before dinner | E22: 105 | G22: =IF(OR(B22="",E22="",J22="",K22=""),"",IF(E22<J22,"Below",IF(E22>K22,"Above","In range"))) | J22: =IF(M22="","",IF(INDEX(Settings!$C$10:$C$18,M22)="","",INDEX(Settings!$C$10:$C$18,M22))) | K22: =IF(M22="","",IF(INDEX(Settings!$D$10:$D$18,M22)="","",INDEX(Settings!$D$10:$D$18,M22))) | L22: =IF(OR(B22="",E22=""),"",B22+MOD(N(C22),1)+ROW()/10000000) | M22: =IF(D22="","",IFERROR(MATCH(D22,Settings!$B$10:$B$18,0),"")) | N22: =IF(OR(B22="",E22="",M22=""),"",IF(AND(B22>=Settings!$C$6,B22<=Settings!$C$7),M22*10000+E22,"")) | O22: =IF(OR(B22="",E22=""),"",B22*10000+E22) | P22: =IF(N22="","",E22)
B23: 46254 | C23: 0.29166667 | D23: Fasting | E23: 96 | G23: =IF(OR(B23="",E23="",J23="",K23=""),"",IF(E23<J23,"Below",IF(E23>K23,"Above","In range"))) | J23: =IF(M23="","",IF(INDEX(Settings!$C$10:$C$18,M23)="","",INDEX(Settings!$C$10:$C$18,M23))) | K23: =IF(M23="","",IF(INDEX(Settings!$D$10:$D$18,M23)="","",INDEX(Settings!$D$10:$D$18,M23))) | L23: =IF(OR(B23="",E23=""),"",B23+MOD(N(C23),1)+ROW()/10000000) | M23: =IF(D23="","",IFERROR(MATCH(D23,Settings!$B$10:$B$18,0),"")) | N23: =IF(OR(B23="",E23="",M23=""),"",IF(AND(B23>=Settings!$C$6,B23<=Settings!$C$7),M23*10000+E23,"")) | O23: =IF(OR(B23="",E23=""),"",B23*10000+E23) | P23: =IF(N23="","",E23)
B24: 46254 | C24: 0.39583333 | D24: After breakfast | E24: 180 | G24: =IF(OR(B24="",E24="",J24="",K24=""),"",IF(E24<J24,"Below",IF(E24>K24,"Above","In range"))) | J24: =IF(M24="","",IF(INDEX(Settings!$C$10:$C$18,M24)="","",INDEX(Settings!$C$10:$C$18,M24))) | K24: =IF(M24="","",IF(INDEX(Settings!$D$10:$D$18,M24)="","",INDEX(Settings!$D$10:$D$18,M24))) | L24: =IF(OR(B24="",E24=""),"",B24+MOD(N(C24),1)+ROW()/10000000) | M24: =IF(D24="","",IFERROR(MATCH(D24,Settings!$B$10:$B$18,0),"")) | N24: =IF(OR(B24="",E24="",M24=""),"",IF(AND(B24>=Settings!$C$6,B24<=Settings!$C$7),M24*10000+E24,"")) | O24: =IF(OR(B24="",E24=""),"",B24*10000+E24) | P24: =IF(N24="","",E24)
B25: 46254 | C25: 0.76041667 | D25: Before dinner | E25: 100 | G25: =IF(OR(B25="",E25="",J25="",K25=""),"",IF(E25<J25,"Below",IF(E25>K25,"Above","In range"))) | J25: =IF(M25="","",IF(INDEX(Settings!$C$10:$C$18,M25)="","",INDEX(Settings!$C$10:$C$18,M25))) | K25: =IF(M25="","",IF(INDEX(Settings!$D$10:$D$18,M25)="","",INDEX(Settings!$D$10:$D$18,M25))) | L25: =IF(OR(B25="",E25=""),"",B25+MOD(N(C25),1)+ROW()/10000000) | M25: =IF(D25="","",IFERROR(MATCH(D25,Settings!$B$10:$B$18,0),"")) | N25: =IF(OR(B25="",E25="",M25=""),"",IF(AND(B25>=Settings!$C$6,B25<=Settings!$C$7),M25*10000+E25,"")) | O25: =IF(OR(B25="",E25=""),"",B25*10000+E25) | P25: =IF(N25="","",E25)
B26: 46254 | C26: 0.85416667 | D26: After dinner | E26: 137 | G26: =IF(OR(B26="",E26="",J26="",K26=""),"",IF(E26<J26,"Below",IF(E26>K26,"Above","In range"))) | J26: =IF(M26="","",IF(INDEX(Settings!$C$10:$C$18,M26)="","",INDEX(Settings!$C$10:$C$18,M26))) | K26: =IF(M26="","",IF(INDEX(Settings!$D$10:$D$18,M26)="","",INDEX(Settings!$D$10:$D$18,M26))) | L26: =IF(OR(B26="",E26=""),"",B26+MOD(N(C26),1)+ROW()/10000000) | M26: =IF(D26="","",IFERROR(MATCH(D26,Settings!$B$10:$B$18,0),"")) | N26: =IF(OR(B26="",E26="",M26=""),"",IF(AND(B26>=Settings!$C$6,B26<=Settings!$C$7),M26*10000+E26,"")) | O26: =IF(OR(B26="",E26=""),"",B26*10000+E26) | P26: =IF(N26="","",E26)
B27: 46254 | C27: 0.92708333 | D27: Bedtime | E27: 150 | G27: =IF(OR(B27="",E27="",J27="",K27=""),"",IF(E27<J27,"Below",IF(E27>K27,"Above","In range"))) | J27: =IF(M27="","",IF(INDEX(Settings!$C$10:$C$18,M27)="","",INDEX(Settings!$C$10:$C$18,M27))) | K27: =IF(M27="","",IF(INDEX(Settings!$D$10:$D$18,M27)="","",INDEX(Settings!$D$10:$D$18,M27))) | L27: =IF(OR(B27="",E27=""),"",B27+MOD(N(C27),1)+ROW()/10000000) | M27: =IF(D27="","",IFERROR(MATCH(D27,Settings!$B$10:$B$18,0),"")) | N27: =IF(OR(B27="",E27="",M27=""),"",IF(AND(B27>=Settings!$C$6,B27<=Settings!$C$7),M27*10000+E27,"")) | O27: =IF(OR(B27="",E27=""),"",B27*10000+E27) | P27: =IF(N27="","",E27)
B28: 46255 | C28: 0.29861111 | D28: Fasting | E28: 102 | G28: =IF(OR(B28="",E28="",J28="",K28=""),"",IF(E28<J28,"Below",IF(E28>K28,"Above","In range"))) | J28: =IF(M28="","",IF(INDEX(Settings!$C$10:$C$18,M28)="","",INDEX(Settings!$C$10:$C$18,M28))) | K28: =IF(M28="","",IF(INDEX(Settings!$D$10:$D$18,M28)="","",INDEX(Settings!$D$10:$D$18,M28))) | L28: =IF(OR(B28="",E28=""),"",B28+MOD(N(C28),1)+ROW()/10000000) | M28: =IF(D28="","",IFERROR(MATCH(D28,Settings!$B$10:$B$18,0),"")) | N28: =IF(OR(B28="",E28="",M28=""),"",IF(AND(B28>=Settings!$C$6,B28<=Settings!$C$7),M28*10000+E28,"")) | O28: =IF(OR(B28="",E28=""),"",B28*10000+E28) | P28: =IF(N28="","",E28)
... B38: 46258 | C38: 0.40277778 | D38: After breakfast | E38: 180 | G38: =IF(OR(B38="",E38="",J38="",K38=""),"",IF(E38<J38,"Below",IF(E38>K38,"Above","In range"))) | J38: =IF(M38="","",IF(INDEX(Settings!$C$10:$C$18,M38)="","",INDEX(Settings!$C$10:$C$18,M38))) | K38: =IF(M38="","",IF(INDEX(Settings!$D$10:$D$18,M38)="","",INDEX(Settings!$D$10:$D$18,M38))) | L38: =IF(OR(B38="",E38=""),"",B38+MOD(N(C38),1)+ROW()/10000000) | M38: =IF(D38="","",IFERROR(MATCH(D38,Settings!$B$10:$B$18,0),"")) | N38: =IF(OR(B38="",E38="",M38=""),"",IF(AND(B38>=Settings!$C$6,B38<=Settings!$C$7),M38*10000+E38,"")) | O38: =IF(OR(B38="",E38=""),"",B38*10000+E38) | P38: =IF(N38="","",E38)
B39: 46258 | C39: 0.77083333 | D39: Before dinner | E39: 118 | F39: Pasta for dinner | G39: =IF(OR(B39="",E39="",J39="",K39=""),"",IF(E39<J39,"Below",IF(E39>K39,"Above","In range"))) | J39: =IF(M39="","",IF(INDEX(Settings!$C$10:$C$18,M39)="","",INDEX(Settings!$C$10:$C$18,M39))) | K39: =IF(M39="","",IF(INDEX(Settings!$D$10:$D$18,M39)="","",INDEX(Settings!$D$10:$D$18,M39))) | L39: =IF(OR(B39="",E39=""),"",B39+MOD(N(C39),1)+ROW()/10000000) | M39: =IF(D39="","",IFERROR(MATCH(D39,Settings!$B$10:$B$18,0),"")) | N39: =IF(OR(B39="",E39="",M39=""),"",IF(AND(B39>=Settings!$C$6,B39<=Settings!$C$7),M39*10000+E39,"")) | O39: =IF(OR(B39="",E39=""),"",B39*10000+E39) | P39: =IF(N39="","",E39)
B40: 46259 | C40: 0.29861111 | D40: Fasting | E40: 122 | G40: =IF(OR(B40="",E40="",J40="",K40=""),"",IF(E40<J40,"Below",IF(E40>K40,"Above","In range"))) | J40: =IF(M40="","",IF(INDEX(Settings!$C$10:$C$18,M40)="","",INDEX(Settings!$C$10:$C$18,M40))) | K40: =IF(M40="","",IF(INDEX(Settings!$D$10:$D$18,M40)="","",INDEX(Settings!$D$10:$D$18,M40))) | L40: =IF(OR(B40="",E40=""),"",B40+MOD(N(C40),1)+ROW()/10000000) | M40: =IF(D40="","",IFERROR(MATCH(D40,Settings!$B$10:$B$18,0),"")) | N40: =IF(OR(B40="",E40="",M40=""),"",IF(AND(B40>=Settings!$C$6,B40<=Settings!$C$7),M40*10000+E40,"")) | O40: =IF(OR(B40="",E40=""),"",B40*10000+E40) | P40: =IF(N40="","",E40)
B41: 46259 | C41: 0.39583333 | D41: After breakfast | E41: 151 | G41: =IF(OR(B41="",E41="",J41="",K41=""),"",IF(E41<J41,"Below",IF(E41>K41,"Above","In range"))) | J41: =IF(M41="","",IF(INDEX(Settings!$C$10:$C$18,M41)="","",INDEX(Settings!$C$10:$C$18,M41))) | K41: =IF(M41="","",IF(INDEX(Settings!$D$10:$D$18,M41)="","",INDEX(Settings!$D$10:$D$18,M41))) | L41: =IF(OR(B41="",E41=""),"",B41+MOD(N(C41),1)+ROW()/10000000) | M41: =IF(D41="","",IFERROR(MATCH(D41,Settings!$B$10:$B$18,0),"")) | N41: =IF(OR(B41="",E41="",M41=""),"",IF(AND(B41>=Settings!$C$6,B41<=Settings!$C$7),M41*10000+E41,"")) | O41: =IF(OR(B41="",E41=""),"",B41*10000+E41) | P41: =IF(N41="","",E41)
B42: 46259 | C42: 0.75 | D42: Before dinner | E42: 114 | G42: =IF(OR(B42="",E42="",J42="",K42=""),"",IF(E42<J42,"Below",IF(E42>K42,"Above","In range"))) | J42: =IF(M42="","",IF(INDEX(Settings!$C$10:$C$18,M42)="","",INDEX(Settings!$C$10:$C$18,M42))) | K42: =IF(M42="","",IF(INDEX(Settings!$D$10:$D$18,M42)="","",INDEX(Settings!$D$10:$D$18,M42))) | L42: =IF(OR(B42="",E42=""),"",B42+MOD(N(C42),1)+ROW()/10000000) | M42: =IF(D42="","",IFERROR(MATCH(D42,Settings!$B$10:$B$18,0),"")) | N42: =IF(OR(B42="",E42="",M42=""),"",IF(AND(B42>=Settings!$C$6,B42<=Settings!$C$7),M42*10000+E42,"")) | O42: =IF(OR(B42="",E42=""),"",B42*10000+E42) | P42: =IF(N42="","",E42)
B43: 46259 | C43: 0.9375 | D43: Bedtime | E43: 125 | G43: =IF(OR(B43="",E43="",J43="",K43=""),"",IF(E43<J43,"Below",IF(E43>K43,"Above","In range"))) | J43: =IF(M43="","",IF(INDEX(Settings!$C$10:$C$18,M43)="","",INDEX(Settings!$C$10:$C$18,M43))) | K43: =IF(M43="","",IF(INDEX(Settings!$D$10:$D$18,M43)="","",INDEX(Settings!$D$10:$D$18,M43))) | L43: =IF(OR(B43="",E43=""),"",B43+MOD(N(C43),1)+ROW()/10000000) | M43: =IF(D43="","",IFERROR(MATCH(D43,Settings!$B$10:$B$18,0),"")) | N43: =IF(OR(B43="",E43="",M43=""),"",IF(AND(B43>=Settings!$C$6,B43<=Settings!$C$7),M43*10000+E43,"")) | O43: =IF(OR(B43="",E43=""),"",B43*10000+E43) | P43: =IF(N43="","",E43)
B44: 46260 | C44: 0.30208333 | D44: Fasting | E44: 116 | G44: =IF(OR(B44="",E44="",J44="",K44=""),"",IF(E44<J44,"Below",IF(E44>K44,"Above","In range"))) | J44: =IF(M44="","",IF(INDEX(Settings!$C$10:$C$18,M44)="","",INDEX(Settings!$C$10:$C$18,M44))) | K44: =IF(M44="","",IF(INDEX(Settings!$D$10:$D$18,M44)="","",INDEX(Settings!$D$10:$D$18,M44))) | L44: =IF(OR(B44="",E44=""),"",B44+MOD(N(C44),1)+ROW()/10000000) | M44: =IF(D44="","",IFERROR(MATCH(D44,Settings!$B$10:$B$18,0),"")) | N44: =IF(OR(B44="",E44="",M44=""),"",IF(AND(B44>=Settings!$C$6,B44<=Settings!$C$7),M44*10000+E44,"")) | O44: =IF(OR(B44="",E44=""),"",B44*10000+E44) | P44: =IF(N44="","",E44)
B45: 46260 | C45: 0.40277778 | D45: After breakfast | E45: 129 | G45: =IF(OR(B45="",E45="",J45="",K45=""),"",IF(E45<J45,"Below",IF(E45>K45,"Above","In range"))) | J45: =IF(M45="","",IF(INDEX(Settings!$C$10:$C$18,M45)="","",INDEX(Settings!$C$10:$C$18,M45))) | K45: =IF(M45="","",IF(INDEX(Settings!$D$10:$D$18,M45)="","",INDEX(Settings!$D$10:$D$18,M45))) | L45: =IF(OR(B45="",E45=""),"",B45+MOD(N(C45),1)+ROW()/10000000) | M45: =IF(D45="","",IFERROR(MATCH(D45,Settings!$B$10:$B$18,0),"")) | N45: =IF(OR(B45="",E45="",M45=""),"",IF(AND(B45>=Settings!$C$6,B45<=Settings!$C$7),M45*10000+E45,"")) | O45: =IF(OR(B45="",E45=""),"",B45*10000+E45) | P45: =IF(N45="","",E45)
B46: 46260 | C46: 0.86458333 | D46: After dinner | E46: 113 | G46: =IF(OR(B46="",E46="",J46="",K46=""),"",IF(E46<J46,"Below",IF(E46>K46,"Above","In range"))) | J46: =IF(M46="","",IF(INDEX(Settings!$C$10:$C$18,M46)="","",INDEX(Settings!$C$10:$C$18,M46))) | K46: =IF(M46="","",IF(INDEX(Settings!$D$10:$D$18,M46)="","",INDEX(Settings!$D$10:$D$18,M46))) | L46: =IF(OR(B46="",E46=""),"",B46+MOD(N(C46),1)+ROW()/10000000) | M46: =IF(D46="","",IFERROR(MATCH(D46,Settings!$B$10:$B$18,0),"")) | N46: =IF(OR(B46="",E46="",M46=""),"",IF(AND(B46>=Settings!$C$6,B46<=Settings!$C$7),M46*10000+E46,"")) | O46: =IF(OR(B46="",E46=""),"",B46*10000+E46) | P46: =IF(N46="","",E46)
B47: 46261 | C47: 0.29166667 | D47: Fasting | E47: 114 | G47: =IF(OR(B47="",E47="",J47="",K47=""),"",IF(E47<J47,"Below",IF(E47>K47,"Above","In range"))) | J47: =IF(M47="","",IF(INDEX(Settings!$C$10:$C$18,M47)="","",INDEX(Settings!$C$10:$C$18,M47))) | K47: =IF(M47="","",IF(INDEX(Settings!$D$10:$D$18,M47)="","",INDEX(Settings!$D$10:$D$18,M47))) | L47: =IF(OR(B47="",E47=""),"",B47+MOD(N(C47),1)+ROW()/10000000) | M47: =IF(D47="","",IFERROR(MATCH(D47,Settings!$B$10:$B$18,0),"")) | N47: =IF(OR(B47="",E47="",M47=""),"",IF(AND(B47>=Settings!$C$6,B47<=Settings!$C$7),M47*10000+E47,"")) | O47: =IF(OR(B47="",E47=""),"",B47*10000+E47) | P47: =IF(N47="","",E47)
B48: 46261 | C48: 0.39583333 | D48: After breakfast | E48: 163 | G48: =IF(OR(B48="",E48="",J48="",K48=""),"",IF(E48<J48,"Below",IF(E48>K48,"Above","In range"))) | J48: =IF(M48="","",IF(INDEX(Settings!$C$10:$C$18,M48)="","",INDEX(Settings!$C$10:$C$18,M48))) | K48: =IF(M48="","",IF(INDEX(Settings!$D$10:$D$18,M48)="","",INDEX(Settings!$D$10:$D$18,M48))) | L48: =IF(OR(B48="",E48=""),"",B48+MOD(N(C48),1)+ROW()/10000000) | M48: =IF(D48="","",IFERROR(MATCH(D48,Settings!$B$10:$B$18,0),"")) | N48: =IF(OR(B48="",E48="",M48=""),"",IF(AND(B48>=Settings!$C$6,B48<=Settings!$C$7),M48*10000+E48,"")) | O48: =IF(OR(B48="",E48=""),"",B48*10000+E48) | P48: =IF(N48="","",E48)
B49: 46261 | C49: 0.76041667 | D49: Before dinner | E49: 125 | G49: =IF(OR(B49="",E49="",J49="",K49=""),"",IF(E49<J49,"Below",IF(E49>K49,"Above","In range"))) | J49: =IF(M49="","",IF(INDEX(Settings!$C$10:$C$18,M49)="","",INDEX(Settings!$C$10:$C$18,M49))) | K49: =IF(M49="","",IF(INDEX(Settings!$D$10:$D$18,M49)="","",INDEX(Settings!$D$10:$D$18,M49))) | L49: =IF(OR(B49="",E49=""),"",B49+MOD(N(C49),1)+ROW()/10000000) | M49: =IF(D49="","",IFERROR(MATCH(D49,Settings!$B$10:$B$18,0),"")) | N49: =IF(OR(B49="",E49="",M49=""),"",IF(AND(B49>=Settings!$C$6,B49<=Settings!$C$7),M49*10000+E49,"")) | O49: =IF(OR(B49="",E49=""),"",B49*10000+E49) | P49: =IF(N49="","",E49)
B50: 46261 | C50: 0.92708333 | D50: Bedtime | E50: 143 | G50: =IF(OR(B50="",E50="",J50="",K50=""),"",IF(E50<J50,"Below",IF(E50>K50,"Above","In range"))) | J50: =IF(M50="","",IF(INDEX(Settings!$C$10:$C$18,M50)="","",INDEX(Settings!$C$10:$C$18,M50))) | K50: =IF(M50="","",IF(INDEX(Settings!$D$10:$D$18,M50)="","",INDEX(Settings!$D$10:$D$18,M50))) | L50: =IF(OR(B50="",E50=""),"",B50+MOD(N(C50),1)+ROW()/10000000) | M50: =IF(D50="","",IFERROR(MATCH(D50,Settings!$B$10:$B$18,0),"")) | N50: =IF(OR(B50="",E50="",M50=""),"",IF(AND(B50>=Settings!$C$6,B50<=Settings!$C$7),M50*10000+E50,"")) | O50: =IF(OR(B50="",E50=""),"",B50*10000+E50) | P50: =IF(N50="","",E50)
B51: 46262 | C51: 0.29166667 | D51: Fasting | E51: 115 | G51: =IF(OR(B51="",E51="",J51="",K51=""),"",IF(E51<J51,"Below",IF(E51>K51,"Above","In range"))) | J51: =IF(M51="","",IF(INDEX(Settings!$C$10:$C$18,M51)="","",INDEX(Settings!$C$10:$C$18,M51))) | K51: =IF(M51="","",IF(INDEX(Settings!$D$10:$D$18,M51)="","",INDEX(Settings!$D$10:$D$18,M51))) | L51: =IF(OR(B51="",E51=""),"",B51+MOD(N(C51),1)+ROW()/10000000) | M51: =IF(D51="","",IFERROR(MATCH(D51,Settings!$B$10:$B$18,0),"")) | N51: =IF(OR(B51="",E51="",M51=""),"",IF(AND(B51>=Settings!$C$6,B51<=Settings!$C$7),M51*10000+E51,"")) | O51: =IF(OR(B51="",E51=""),"",B51*10000+E51) | P51: =IF(N51="","",E51)
...

Sheet Medicines
B2: Medicines
B3: What you take and when. Up to four times a day. Tick them off on the Doses tab.
B5: Medicine | C5: Dose | D5: Time 1 | E5: Time 2 | F5: Time 3 | G5: Time 4 | H5: With food | I5: Started | J5: Stopped | K5: Notes | L5: Status | M5: A day | N5: Today | O5: Left
B6: Tablet A | C6: 1 tablet | D6: 0.33333333 | E6: 0.83333333 | H6: Yes | I6: 45717 | L6: =IF(B6="","",IF(AND(J6<>"",J6<=TODAY()),"Stopped",IF(AND(I6<>"",I6>TODAY()),"Not started","Taking"))) | M6: =IF(L6<>"Taking","",COUNT(D6:G6)) | N6: =IF(B6="","",COUNTIFS(Doses!$B$6:$B$2005,TODAY(),Doses!$D$6:$D$2005,B6)) | O6: =IF(L6<>"Taking","",MAX(0,M6-N6)) | P6: =IF(OR(L6<>"Taking",D6=""),"",MOD(D6,1)+(61)/10000000) | Q6: =IF(OR(L6<>"Taking",E6=""),"",MOD(E6,1)+(62)/10000000) | R6: =IF(OR(L6<>"Taking",F6=""),"",MOD(F6,1)+(63)/10000000) | S6: =IF(OR(L6<>"Taking",G6=""),"",MOD(G6,1)+(64)/10000000) | T6: =IF(D6="","",(D6<>"")*(N(D6)<=N(D6))+(E6<>"")*(N(E6)<=N(D6))+(F6<>"")*(N(F6)<=N(D6))+(G6<>"")*(N(G6)<=N(D6))) | U6: =IF(E6="","",(D6<>"")*(N(D6)<=N(E6))+(E6<>"")*(N(E6)<=N(E6))+(F6<>"")*(N(F6)<=N(E6))+(G6<>"")*(N(G6)<=N(E6))) | V6: =IF(F6="","",(D6<>"")*(N(D6)<=N(F6))+(E6<>"")*(N(E6)<=N(F6))+(F6<>"")*(N(F6)<=N(F6))+(G6<>"")*(N(G6)<=N(F6))) | W6: =IF(G6="","",(D6<>"")*(N(D6)<=N(G6))+(E6<>"")*(N(E6)<=N(G6))+(F6<>"")*(N(F6)<=N(G6))+(G6<>"")*(N(G6)<=N(G6))) | X6: =IF(L6="Taking",ROW(),"")
B7: Tablet B | C7: 1 tablet | D7: 0.33333333 | H7: Yes | I7: 46154 | L7: =IF(B7="","",IF(AND(J7<>"",J7<=TODAY()),"Stopped",IF(AND(I7<>"",I7>TODAY()),"Not started","Taking"))) | M7: =IF(L7<>"Taking","",COUNT(D7:G7)) | N7: =IF(B7="","",COUNTIFS(Doses!$B$6:$B$2005,TODAY(),Doses!$D$6:$D$2005,B7)) | O7: =IF(L7<>"Taking","",MAX(0,M7-N7)) | P7: =IF(OR(L7<>"Taking",D7=""),"",MOD(D7,1)+(71)/10000000) | Q7: =IF(OR(L7<>"Taking",E7=""),"",MOD(E7,1)+(72)/10000000) | R7: =IF(OR(L7<>"Taking",F7=""),"",MOD(F7,1)+(73)/10000000) | S7: =IF(OR(L7<>"Taking",G7=""),"",MOD(G7,1)+(74)/10000000) | T7: =IF(D7="","",(D7<>"")*(N(D7)<=N(D7))+(E7<>"")*(N(E7)<=N(D7))+(F7<>"")*(N(F7)<=N(D7))+(G7<>"")*(N(G7)<=N(D7))) | U7: =IF(E7="","",(D7<>"")*(N(D7)<=N(E7))+(E7<>"")*(N(E7)<=N(E7))+(F7<>"")*(N(F7)<=N(E7))+(G7<>"")*(N(G7)<=N(E7))) | V7: =IF(F7="","",(D7<>"")*(N(D7)<=N(F7))+(E7<>"")*(N(E7)<=N(F7))+(F7<>"")*(N(F7)<=N(F7))+(G7<>"")*(N(G7)<=N(F7))) | W7: =IF(G7="","",(D7<>"")*(N(D7)<=N(G7))+(E7<>"")*(N(E7)<=N(G7))+(F7<>"")*(N(F7)<=N(G7))+(G7<>"")*(N(G7)<=N(G7))) | X7: =IF(L7="Taking",ROW(),"")
B8: Vitamin D | C8: 1 capsule | D8: 0.33333333 | I8: 46032 | K8: Winter months | L8: =IF(B8="","",IF(AND(J8<>"",J8<=TODAY()),"Stopped",IF(AND(I8<>"",I8>TODAY()),"Not started","Taking"))) | M8: =IF(L8<>"Taking","",COUNT(D8:G8)) | N8: =IF(B8="","",COUNTIFS(Doses!$B$6:$B$2005,TODAY(),Doses!$D$6:$D$2005,B8)) | O8: =IF(L8<>"Taking","",MAX(0,M8-N8)) | P8: =IF(OR(L8<>"Taking",D8=""),"",MOD(D8,1)+(81)/10000000) | Q8: =IF(OR(L8<>"Taking",E8=""),"",MOD(E8,1)+(82)/10000000) | R8: =IF(OR(L8<>"Taking",F8=""),"",MOD(F8,1)+(83)/10000000) | S8: =IF(OR(L8<>"Taking",G8=""),"",MOD(G8,1)+(84)/10000000) | T8: =IF(D8="","",(D8<>"")*(N(D8)<=N(D8))+(E8<>"")*(N(E8)<=N(D8))+(F8<>"")*(N(F8)<=N(D8))+(G8<>"")*(N(G8)<=N(D8))) | U8: =IF(E8="","",(D8<>"")*(N(D8)<=N(E8))+(E8<>"")*(N(E8)<=N(E8))+(F8<>"")*(N(F8)<=N(E8))+(G8<>"")*(N(G8)<=N(E8))) | V8: =IF(F8="","",(D8<>"")*(N(D8)<=N(F8))+(E8<>"")*(N(E8)<=N(F8))+(F8<>"")*(N(F8)<=N(F8))+(G8<>"")*(N(G8)<=N(F8))) | W8: =IF(G8="","",(D8<>"")*(N(D8)<=N(G8))+(E8<>"")*(N(E8)<=N(G8))+(F8<>"")*(N(F8)<=N(G8))+(G8<>"")*(N(G8)<=N(G8))) | X8: =IF(L8="Taking",ROW(),"")
B9: Tablet C | C9: 1 tablet | D9: 0.91666667 | I9: 45901 | L9: =IF(B9="","",IF(AND(J9<>"",J9<=TODAY()),"Stopped",IF(AND(I9<>"",I9>TODAY()),"Not started","Taking"))) | M9: =IF(L9<>"Taking","",COUNT(D9:G9)) | N9: =IF(B9="","",COUNTIFS(Doses!$B$6:$B$2005,TODAY(),Doses!$D$6:$D$2005,B9)) | O9: =IF(L9<>"Taking","",MAX(0,M9-N9)) | P9: =IF(OR(L9<>"Taking",D9=""),"",MOD(D9,1)+(91)/10000000) | Q9: =IF(OR(L9<>"Taking",E9=""),"",MOD(E9,1)+(92)/10000000) | R9: =IF(OR(L9<>"Taking",F9=""),"",MOD(F9,1)+(93)/10000000) | S9: =IF(OR(L9<>"Taking",G9=""),"",MOD(G9,1)+(94)/10000000) | T9: =IF(D9="","",(D9<>"")*(N(D9)<=N(D9))+(E9<>"")*(N(E9)<=N(D9))+(F9<>"")*(N(F9)<=N(D9))+(G9<>"")*(N(G9)<=N(D9))) | U9: =IF(E9="","",(D9<>"")*(N(D9)<=N(E9))+(E9<>"")*(N(E9)<=N(E9))+(F9<>"")*(N(F9)<=N(E9))+(G9<>"")*(N(G9)<=N(E9))) | V9: =IF(F9="","",(D9<>"")*(N(D9)<=N(F9))+(E9<>"")*(N(E9)<=N(F9))+(F9<>"")*(N(F9)<=N(F9))+(G9<>"")*(N(G9)<=N(F9))) | W9: =IF(G9="","",(D9<>"")*(N(D9)<=N(G9))+(E9<>"")*(N(E9)<=N(G9))+(F9<>"")*(N(F9)<=N(G9))+(G9<>"")*(N(G9)<=N(G9))) | X9: =IF(L9="Taking",ROW(),"")
B10: Old tablet | C10: 1 tablet | D10: 0.5 | H10: Yes | I10: 45717 | J10: 46279 | K10: Stopped at the last check-up | L10: =IF(B10="","",IF(AND(J10<>"",J10<=TODAY()),"Stopped",IF(AND(I10<>"",I10>TODAY()),"Not started","Taking"))) | M10: =IF(L10<>"Taking","",COUNT(D10:G10)) | N10: =IF(B10="","",COUNTIFS(Doses!$B$6:$B$2005,TODAY(),Doses!$D$6:$D$2005,B10)) | O10: =IF(L10<>"Taking","",MAX(0,M10-N10)) | P10: =IF(OR(L10<>"Taking",D10=""),"",MOD(D10,1)+(101)/10000000) | Q10: =IF(OR(L10<>"Taking",E10=""),"",MOD(E10,1)+(102)/10000000) | R10: =IF(OR(L10<>"Taking",F10=""),"",MOD(F10,1)+(103)/10000000) | S10: =IF(OR(L10<>"Taking",G10=""),"",MOD(G10,1)+(104)/10000000) | T10: =IF(D10="","",(D10<>"")*(N(D10)<=N(D10))+(E10<>"")*(N(E10)<=N(D10))+(F10<>"")*(N(F10)<=N(D10))+(G10<>"")*(N(G10)<=N(D10))) | U10: =IF(E10="","",(D10<>"")*(N(D10)<=N(E10))+(E10<>"")*(N(E10)<=N(E10))+(F10<>"")*(N(F10)<=N(E10))+(G10<>"")*(N(G10)<=N(E10))) | V10: =IF(F10="","",(D10<>"")*(N(D10)<=N(F10))+(E10<>"")*(N(E10)<=N(F10))+(F10<>"")*(N(F10)<=N(F10))+(G10<>"")*(N(G10)<=N(F10))) | W10: =IF(G10="","",(D10<>"")*(N(D10)<=N(G10))+(E10<>"")*(N(E10)<=N(G10))+(F10<>"")*(N(F10)<=N(G10))+(G10<>"")*(N(G10)<=N(G10))) | X10: =IF(L10="Taking",ROW(),"")
L11: =IF(B11="","",IF(AND(J11<>"",J11<=TODAY()),"Stopped",IF(AND(I11<>"",I11>TODAY()),"Not started","Taking"))) | M11: =IF(L11<>"Taking","",COUNT(D11:G11)) | N11: =IF(B11="","",COUNTIFS(Doses!$B$6:$B$2005,TODAY(),Doses!$D$6:$D$2005,B11)) | O11: =IF(L11<>"Taking","",MAX(0,M11-N11)) | P11: =IF(OR(L11<>"Taking",D11=""),"",MOD(D11,1)+(111)/10000000) | Q11: =IF(OR(L11<>"Taking",E11=""),"",MOD(E11,1)+(112)/10000000) | R11: =IF(OR(L11<>"Taking",F11=""),"",MOD(F11,1)+(113)/10000000) | S11: =IF(OR(L11<>"Taking",G11=""),"",MOD(G11,1)+(114)/10000000) | T11: =IF(D11="","",(D11<>"")*(N(D11)<=N(D11))+(E11<>"")*(N(E11)<=N(D11))+(F11<>"")*(N(F11)<=N(D11))+(G11<>"")*(N(G11)<=N(D11))) | U11: =IF(E11="","",(D11<>"")*(N(D11)<=N(E11))+(E11<>"")*(N(E11)<=N(E11))+(F11<>"")*(N(F11)<=N(E11))+(G11<>"")*(N(G11)<=N(E11))) | V11: =IF(F11="","",(D11<>"")*(N(D11)<=N(F11))+(E11<>"")*(N(E11)<=N(F11))+(F11<>"")*(N(F11)<=N(F11))+(G11<>"")*(N(G11)<=N(F11))) | W11: =IF(G11="","",(D11<>"")*(N(D11)<=N(G11))+(E11<>"")*(N(E11)<=N(G11))+(F11<>"")*(N(F11)<=N(G11))+(G11<>"")*(N(G11)<=N(G11))) | X11: =IF(L11="Taking",ROW(),"")
L12: =IF(B12="","",IF(AND(J12<>"",J12<=TODAY()),"Stopped",IF(AND(I12<>"",I12>TODAY()),"Not started","Taking"))) | M12: =IF(L12<>"Taking","",COUNT(D12:G12)) | N12: =IF(B12="","",COUNTIFS(Doses!$B$6:$B$2005,TODAY(),Doses!$D$6:$D$2005,B12)) | O12: =IF(L12<>"Taking","",MAX(0,M12-N12)) | P12: =IF(OR(L12<>"Taking",D12=""),"",MOD(D12,1)+(121)/10000000) | Q12: =IF(OR(L12<>"Taking",E12=""),"",MOD(E12,1)+(122)/10000000) | R12: =IF(OR(L12<>"Taking",F12=""),"",MOD(F12,1)+(123)/10000000) | S12: =IF(OR(L12<>"Taking",G12=""),"",MOD(G12,1)+(124)/10000000) | T12: =IF(D12="","",(D12<>"")*(N(D12)<=N(D12))+(E12<>"")*(N(E12)<=N(D12))+(F12<>"")*(N(F12)<=N(D12))+(G12<>"")*(N(G12)<=N(D12))) | U12: =IF(E12="","",(D12<>"")*(N(D12)<=N(E12))+(E12<>"")*(N(E12)<=N(E12))+(F12<>"")*(N(F12)<=N(E12))+(G12<>"")*(N(G12)<=N(E12))) | V12: =IF(F12="","",(D12<>"")*(N(D12)<=N(F12))+(E12<>"")*(N(E12)<=N(F12))+(F12<>"")*(N(F12)<=N(F12))+(G12<>"")*(N(G12)<=N(F12))) | W12: =IF(G12="","",(D12<>"")*(N(D12)<=N(G12))+(E12<>"")*(N(E12)<=N(G12))+(F12<>"")*(N(F12)<=N(G12))+(G12<>"")*(N(G12)<=N(G12))) | X12: =IF(L12="Taking",ROW(),"")
L13: =IF(B13="","",IF(AND(J13<>"",J13<=TODAY()),"Stopped",IF(AND(I13<>"",I13>TODAY()),"Not started","Taking"))) | M13: =IF(L13<>"Taking","",COUNT(D13:G13)) | N13: =IF(B13="","",COUNTIFS(Doses!$B$6:$B$2005,TODAY(),Doses!$D$6:$D$2005,B13)) | O13: =IF(L13<>"Taking","",MAX(0,M13-N13)) | P13: =IF(OR(L13<>"Taking",D13=""),"",MOD(D13,1)+(131)/10000000) | Q13: =IF(OR(L13<>"Taking",E13=""),"",MOD(E13,1)+(132)/10000000) | R13: =IF(OR(L13<>"Taking",F13=""),"",MOD(F13,1)+(133)/10000000) | S13: =IF(OR(L13<>"Taking",G13=""),"",MOD(G13,1)+(134)/10000000) | T13: =IF(D13="","",(D13<>"")*(N(D13)<=N(D13))+(E13<>"")*(N(E13)<=N(D13))+(F13<>"")*(N(F13)<=N(D13))+(G13<>"")*(N(G13)<=N(D13))) | U13: =IF(E13="","",(D13<>"")*(N(D13)<=N(E13))+(E13<>"")*(N(E13)<=N(E13))+(F13<>"")*(N(F13)<=N(E13))+(G13<>"")*(N(G13)<=N(E13))) | V13: =IF(F13="","",(D13<>"")*(N(D13)<=N(F13))+(E13<>"")*(N(E13)<=N(F13))+(F13<>"")*(N(F13)<=N(F13))+(G13<>"")*(N(G13)<=N(F13))) | W13: =IF(G13="","",(D13<>"")*(N(D13)<=N(G13))+(E13<>"")*(N(E13)<=N(G13))+(F13<>"")*(N(F13)<=N(G13))+(G13<>"")*(N(G13)<=N(G13))) | X13: =IF(L13="Taking",ROW(),"")
