Workbook

Sheet Dashboard
N1: =COUNTIFS(Budget!$I$6:$I$17,"Over*")
B2: Renovation dashboard | N2: =COUNTIFS(Costs!$J$6:$J$305,"Overdue*")
B3: Everything here comes from the Budget, Costs and Timeline tabs. | N3: =SUMIFS(Costs!$I$6:$I$305,Costs!$J$6:$J$305,"Overdue*")
N4: =COUNTIFS(Costs!$J$6:$J$305,"Due in*")+COUNTIFS(Costs!$J$6:$J$305,"Due today")
N5: =SUMIFS(Costs!$I$6:$I$305,Costs!$J$6:$J$305,"Due in*")+SUMIFS(Costs!$I$6:$I$305,Costs!$J$6:$J$305,"Due today")
B6: Total budget | C6: Committed | D6: Paid | E6: Still to pay | F6: Contingency left | G6: Budget committed | I6: Left to spend | N6: =ROUND(SUM(Costs!$N$6:$N$305),0)
B7: =Budget!$C$22 | C7: =(SUMIFS(Costs!$E$6:$E$305,Costs!$F$6:$F$305,"Hired")+SUMIFS(Costs!$E$6:$E$305,Costs!$F$6:$F$305,"Bought")) | D7: =(SUMIFS(Costs!$G$6:$G$305,Costs!$F$6:$F$305,"Hired")+SUMIFS(Costs!$G$6:$G$305,Costs!$F$6:$F$305,"Bought")) | E7: =C7-D7 | F7: =Budget!$C$24 | G7: =IF(B7=0,"",C7/B7) | I7: =B7-C7 | N7: =COUNTIFS(Timeline!$G$6:$G$35,"Delayed")
N8: =IFERROR(SMALL(Timeline!$E$6:$E$35,COUNTIF(Timeline!$E$6:$E$35,"<"&TODAY())+1),"")
B9: Room or area | C9: Budget | D9: Committed | E9: Paid | F9: Used | G9: Status | I9: Needs attention
B10: =IF(Budget!B6="","",Budget!B6) | C10: =IF(B10="","",Budget!C6) | D10: =IF(B10="","",Budget!D6) | E10: =IF(B10="","",Budget!E6) | F10: =IF(OR(B10="",N(C10)=0),"",REPT("█",MIN(14,MAX(0,ROUND((D10/C10)*14,0))))&REPT("░",14-MIN(14,MAX(0,ROUND((D10/C10)*14,0))))) | G10: =IF(B10="","",Budget!I6) | I10: =IF($N$1=0,"No room is over budget",IF($N$1=1,"1 room is",$N$1&" rooms are")&" over budget")
B11: =IF(Budget!B7="","",Budget!B7) | C11: =IF(B11="","",Budget!C7) | D11: =IF(B11="","",Budget!D7) | E11: =IF(B11="","",Budget!E7) | F11: =IF(OR(B11="",N(C11)=0),"",REPT("█",MIN(14,MAX(0,ROUND((D11/C11)*14,0))))&REPT("░",14-MIN(14,MAX(0,ROUND((D11/C11)*14,0))))) | G11: =IF(B11="","",Budget!I7) | I11: =IF($N$2=0,"No overdue payments",IF($N$2=1,"1 payment is",$N$2&" payments are")&" overdue: "&FIXED($N$3,2))
B12: =IF(Budget!B8="","",Budget!B8) | C12: =IF(B12="","",Budget!C8) | D12: =IF(B12="","",Budget!D8) | E12: =IF(B12="","",Budget!E8) | F12: =IF(OR(B12="",N(C12)=0),"",REPT("█",MIN(14,MAX(0,ROUND((D12/C12)*14,0))))&REPT("░",14-MIN(14,MAX(0,ROUND((D12/C12)*14,0))))) | G12: =IF(B12="","",Budget!I8) | I12: =IF($N$4=0,"Nothing due in the next 14 days",IF($N$4=1,"1 payment",$N$4&" payments")&" due in the next 14 days: "&FIXED($N$5,2))
B13: =IF(Budget!B9="","",Budget!B9) | C13: =IF(B13="","",Budget!C9) | D13: =IF(B13="","",Budget!D9) | E13: =IF(B13="","",Budget!E9) | F13: =IF(OR(B13="",N(C13)=0),"",REPT("█",MIN(14,MAX(0,ROUND((D13/C13)*14,0))))&REPT("░",14-MIN(14,MAX(0,ROUND((D13/C13)*14,0))))) | G13: =IF(B13="","",Budget!I9) | I13: =IF($N$6=0,"No quotes waiting for a decision",IF($N$6=1,"1 job is",$N$6&" jobs are")&" waiting for a decision between quotes")
B14: =IF(Budget!B10="","",Budget!B10) | C14: =IF(B14="","",Budget!C10) | D14: =IF(B14="","",Budget!D10) | E14: =IF(B14="","",Budget!E10) | F14: =IF(OR(B14="",N(C14)=0),"",REPT("█",MIN(14,MAX(0,ROUND((D14/C14)*14,0))))&REPT("░",14-MIN(14,MAX(0,ROUND((D14/C14)*14,0))))) | G14: =IF(B14="","",Budget!I10) | I14: =IF(Budget!$C$24>=0,"Contingency left: "&FIXED(Budget!$C$24,2)&" of "&FIXED(Budget!$C$21,2),"Contingency used up, over by "&FIXED(-Budget!$C$24,2))
B15: =IF(Budget!B11="","",Budget!B11) | C15: =IF(B15="","",Budget!C11) | D15: =IF(B15="","",Budget!D11) | E15: =IF(B15="","",Budget!E11) | F15: =IF(OR(B15="",N(C15)=0),"",REPT("█",MIN(14,MAX(0,ROUND((D15/C15)*14,0))))&REPT("░",14-MIN(14,MAX(0,ROUND((D15/C15)*14,0))))) | G15: =IF(B15="","",Budget!I11) | I15: =IF($N$7=0,"No delayed tasks",IF($N$7=1,"1 task is",$N$7&" tasks are")&" delayed")
B16: =IF(Budget!B12="","",Budget!B12) | C16: =IF(B16="","",Budget!C12) | D16: =IF(B16="","",Budget!D12) | E16: =IF(B16="","",Budget!E12) | F16: =IF(OR(B16="",N(C16)=0),"",REPT("█",MIN(14,MAX(0,ROUND((D16/C16)*14,0))))&REPT("░",14-MIN(14,MAX(0,ROUND((D16/C16)*14,0))))) | G16: =IF(B16="","",Budget!I12) | I16: =IF($N$8="","No tasks coming up","Next task: "&INDEX(Timeline!$B$6:$B$35,MATCH($N$8,Timeline!$E$6:$E$35,0))&IF($N$8=TODAY(),", starting today",", starts in "&($N$8-TODAY())&IF(($N$8-TODAY())=1," day"," days")))
B17: =IF(Budget!B13="","",Budget!B13) | C17: =IF(B17="","",Budget!C13) | D17: =IF(B17="","",Budget!D13) | E17: =IF(B17="","",Budget!E13) | F17: =IF(OR(B17="",N(C17)=0),"",REPT("█",MIN(14,MAX(0,ROUND((D17/C17)*14,0))))&REPT("░",14-MIN(14,MAX(0,ROUND((D17/C17)*14,0))))) | G17: =IF(B17="","",Budget!I13)
B18: =IF(Budget!B14="","",Budget!B14) | C18: =IF(B18="","",Budget!C14) | D18: =IF(B18="","",Budget!D14) | E18: =IF(B18="","",Budget!E14) | F18: =IF(OR(B18="",N(C18)=0),"",REPT("█",MIN(14,MAX(0,ROUND((D18/C18)*14,0))))&REPT("░",14-MIN(14,MAX(0,ROUND((D18/C18)*14,0))))) | G18: =IF(B18="","",Budget!I14) | I18: Next payments | J18: To | K18: Amount
B19: =IF(Budget!B15="","",Budget!B15) | C19: =IF(B19="","",Budget!C15) | D19: =IF(B19="","",Budget!D15) | E19: =IF(B19="","",Budget!E15) | F19: =IF(OR(B19="",N(C19)=0),"",REPT("█",MIN(14,MAX(0,ROUND((D19/C19)*14,0))))&REPT("░",14-MIN(14,MAX(0,ROUND((D19/C19)*14,0))))) | G19: =IF(B19="","",Budget!I15) | I19: =IF($M19="","",INT($M19)) | J19: =IF($M19="","",INDEX(Costs!$D$6:$D$305,MATCH($M19,Costs!$O$6:$O$305,0))&", "&INDEX(Costs!$C$6:$C$305,MATCH($M19,Costs!$O$6:$O$305,0))) | K19: =IF($M19="","",INDEX(Costs!$I$6:$I$305,MATCH($M19,Costs!$O$6:$O$305,0))) | M19: =IFERROR(SMALL(Costs!$O$6:$O$305,1),"")
B20: =IF(Budget!B16="","",Budget!B16) | C20: =IF(B20="","",Budget!C16) | D20: =IF(B20="","",Budget!D16) | E20: =IF(B20="","",Budget!E16) | F20: =IF(OR(B20="",N(C20)=0),"",REPT("█",MIN(14,MAX(0,ROUND((D20/C20)*14,0))))&REPT("░",14-MIN(14,MAX(0,ROUND((D20/C20)*14,0))))) | G20: =IF(B20="","",Budget!I16) | I20: =IF($M20="","",INT($M20)) | J20: =IF($M20="","",INDEX(Costs!$D$6:$D$305,MATCH($M20,Costs!$O$6:$O$305,0))&", "&INDEX(Costs!$C$6:$C$305,MATCH($M20,Costs!$O$6:$O$305,0))) | K20: =IF($M20="","",INDEX(Costs!$I$6:$I$305,MATCH($M20,Costs!$O$6:$O$305,0))) | M20: =IFERROR(SMALL(Costs!$O$6:$O$305,2),"")
B21: =IF(Budget!B17="","",Budget!B17) | C21: =IF(B21="","",Budget!C17) | D21: =IF(B21="","",Budget!D17) | E21: =IF(B21="","",Budget!E17) | F21: =IF(OR(B21="",N(C21)=0),"",REPT("█",MIN(14,MAX(0,ROUND((D21/C21)*14,0))))&REPT("░",14-MIN(14,MAX(0,ROUND((D21/C21)*14,0))))) | G21: =IF(B21="","",Budget!I17) | I21: =IF($M21="","",INT($M21)) | J21: =IF($M21="","",INDEX(Costs!$D$6:$D$305,MATCH($M21,Costs!$O$6:$O$305,0))&", "&INDEX(Costs!$C$6:$C$305,MATCH($M21,Costs!$O$6:$O$305,0))) | K21: =IF($M21="","",INDEX(Costs!$I$6:$I$305,MATCH($M21,Costs!$O$6:$O$305,0))) | M21: =IFERROR(SMALL(Costs!$O$6:$O$305,3),"")
I22: =IF($M22="","",INT($M22)) | J22: =IF($M22="","",INDEX(Costs!$D$6:$D$305,MATCH($M22,Costs!$O$6:$O$305,0))&", "&INDEX(Costs!$C$6:$C$305,MATCH($M22,Costs!$O$6:$O$305,0))) | K22: =IF($M22="","",INDEX(Costs!$I$6:$I$305,MATCH($M22,Costs!$O$6:$O$305,0))) | M22: =IFERROR(SMALL(Costs!$O$6:$O$305,4),"")
I23: =IF($M23="","",INT($M23)) | J23: =IF($M23="","",INDEX(Costs!$D$6:$D$305,MATCH($M23,Costs!$O$6:$O$305,0))&", "&INDEX(Costs!$C$6:$C$305,MATCH($M23,Costs!$O$6:$O$305,0))) | K23: =IF($M23="","",INDEX(Costs!$I$6:$I$305,MATCH($M23,Costs!$O$6:$O$305,0))) | M23: =IFERROR(SMALL(Costs!$O$6:$O$305,5),"")

Sheet Budget
B2: Budget by room
B3: Type a budget for each room or area. Committed and paid come from the Costs tab.
B4: Contingency | C4: 0.1 | D4: Money kept aside for surprises. Between 10 and 20% is usual.
B5: Room or area | C5: Budget | D5: Committed | E5: Paid | F5: Still to pay | G5: Left to commit | H5: Used | I5: Status
B6: Kitchen | C6: 18000 | D6: =IF(B6="","",SUMIFS(Costs!$E$6:$E$305,Costs!$B$6:$B$305,B6,Costs!$F$6:$F$305,"Hired")+SUMIFS(Costs!$E$6:$E$305,Costs!$B$6:$B$305,B6,Costs!$F$6:$F$305,"Bought")) | E6: =IF(B6="","",SUMIFS(Costs!$G$6:$G$305,Costs!$B$6:$B$305,B6,Costs!$F$6:$F$305,"Hired")+SUMIFS(Costs!$G$6:$G$305,Costs!$B$6:$B$305,B6,Costs!$F$6:$F$305,"Bought")) | F6: =IF(B6="","",D6-E6) | G6: =IF(B6="","",C6-D6) | H6: =IF(OR(B6="",N(C6)=0),"",REPT("█",MIN(12,MAX(0,ROUND((D6/C6)*12,0))))&REPT("░",12-MIN(12,MAX(0,ROUND((D6/C6)*12,0))))) | I6: =IF(B6="","",IF(N(C6)=0,IF(N(D6)>0,"No budget set",""),IF(D6>C6,"Over by "&FIXED(D6-C6,0),IF(D6>=0.9*C6,ROUND(D6/C6*100,0)&"% used, near the limit",ROUND(D6/C6*100,0)&"% used")))) | J6: =IF(B6="","",MAX(0,N(D6)-N(C6)))
B7: Bathroom | C7: 9000 | D7: =IF(B7="","",SUMIFS(Costs!$E$6:$E$305,Costs!$B$6:$B$305,B7,Costs!$F$6:$F$305,"Hired")+SUMIFS(Costs!$E$6:$E$305,Costs!$B$6:$B$305,B7,Costs!$F$6:$F$305,"Bought")) | E7: =IF(B7="","",SUMIFS(Costs!$G$6:$G$305,Costs!$B$6:$B$305,B7,Costs!$F$6:$F$305,"Hired")+SUMIFS(Costs!$G$6:$G$305,Costs!$B$6:$B$305,B7,Costs!$F$6:$F$305,"Bought")) | F7: =IF(B7="","",D7-E7) | G7: =IF(B7="","",C7-D7) | H7: =IF(OR(B7="",N(C7)=0),"",REPT("█",MIN(12,MAX(0,ROUND((D7/C7)*12,0))))&REPT("░",12-MIN(12,MAX(0,ROUND((D7/C7)*12,0))))) | I7: =IF(B7="","",IF(N(C7)=0,IF(N(D7)>0,"No budget set",""),IF(D7>C7,"Over by "&FIXED(D7-C7,0),IF(D7>=0.9*C7,ROUND(D7/C7*100,0)&"% used, near the limit",ROUND(D7/C7*100,0)&"% used")))) | J7: =IF(B7="","",MAX(0,N(D7)-N(C7)))
B8: Living room | C8: 4500 | D8: =IF(B8="","",SUMIFS(Costs!$E$6:$E$305,Costs!$B$6:$B$305,B8,Costs!$F$6:$F$305,"Hired")+SUMIFS(Costs!$E$6:$E$305,Costs!$B$6:$B$305,B8,Costs!$F$6:$F$305,"Bought")) | E8: =IF(B8="","",SUMIFS(Costs!$G$6:$G$305,Costs!$B$6:$B$305,B8,Costs!$F$6:$F$305,"Hired")+SUMIFS(Costs!$G$6:$G$305,Costs!$B$6:$B$305,B8,Costs!$F$6:$F$305,"Bought")) | F8: =IF(B8="","",D8-E8) | G8: =IF(B8="","",C8-D8) | H8: =IF(OR(B8="",N(C8)=0),"",REPT("█",MIN(12,MAX(0,ROUND((D8/C8)*12,0))))&REPT("░",12-MIN(12,MAX(0,ROUND((D8/C8)*12,0))))) | I8: =IF(B8="","",IF(N(C8)=0,IF(N(D8)>0,"No budget set",""),IF(D8>C8,"Over by "&FIXED(D8-C8,0),IF(D8>=0.9*C8,ROUND(D8/C8*100,0)&"% used, near the limit",ROUND(D8/C8*100,0)&"% used")))) | J8: =IF(B8="","",MAX(0,N(D8)-N(C8)))
B9: Primary bedroom | C9: 3000 | D9: =IF(B9="","",SUMIFS(Costs!$E$6:$E$305,Costs!$B$6:$B$305,B9,Costs!$F$6:$F$305,"Hired")+SUMIFS(Costs!$E$6:$E$305,Costs!$B$6:$B$305,B9,Costs!$F$6:$F$305,"Bought")) | E9: =IF(B9="","",SUMIFS(Costs!$G$6:$G$305,Costs!$B$6:$B$305,B9,Costs!$F$6:$F$305,"Hired")+SUMIFS(Costs!$G$6:$G$305,Costs!$B$6:$B$305,B9,Costs!$F$6:$F$305,"Bought")) | F9: =IF(B9="","",D9-E9) | G9: =IF(B9="","",C9-D9) | H9: =IF(OR(B9="",N(C9)=0),"",REPT("█",MIN(12,MAX(0,ROUND((D9/C9)*12,0))))&REPT("░",12-MIN(12,MAX(0,ROUND((D9/C9)*12,0))))) | I9: =IF(B9="","",IF(N(C9)=0,IF(N(D9)>0,"No budget set",""),IF(D9>C9,"Over by "&FIXED(D9-C9,0),IF(D9>=0.9*C9,ROUND(D9/C9*100,0)&"% used, near the limit",ROUND(D9/C9*100,0)&"% used")))) | J9: =IF(B9="","",MAX(0,N(D9)-N(C9)))
B10: Whole house | C10: 5000 | D10: =IF(B10="","",SUMIFS(Costs!$E$6:$E$305,Costs!$B$6:$B$305,B10,Costs!$F$6:$F$305,"Hired")+SUMIFS(Costs!$E$6:$E$305,Costs!$B$6:$B$305,B10,Costs!$F$6:$F$305,"Bought")) | E10: =IF(B10="","",SUMIFS(Costs!$G$6:$G$305,Costs!$B$6:$B$305,B10,Costs!$F$6:$F$305,"Hired")+SUMIFS(Costs!$G$6:$G$305,Costs!$B$6:$B$305,B10,Costs!$F$6:$F$305,"Bought")) | F10: =IF(B10="","",D10-E10) | G10: =IF(B10="","",C10-D10) | H10: =IF(OR(B10="",N(C10)=0),"",REPT("█",MIN(12,MAX(0,ROUND((D10/C10)*12,0))))&REPT("░",12-MIN(12,MAX(0,ROUND((D10/C10)*12,0))))) | I10: =IF(B10="","",IF(N(C10)=0,IF(N(D10)>0,"No budget set",""),IF(D10>C10,"Over by "&FIXED(D10-C10,0),IF(D10>=0.9*C10,ROUND(D10/C10*100,0)&"% used, near the limit",ROUND(D10/C10*100,0)&"% used")))) | J10: =IF(B10="","",MAX(0,N(D10)-N(C10)))
B11: Exterior | C11: 3500 | D11: =IF(B11="","",SUMIFS(Costs!$E$6:$E$305,Costs!$B$6:$B$305,B11,Costs!$F$6:$F$305,"Hired")+SUMIFS(Costs!$E$6:$E$305,Costs!$B$6:$B$305,B11,Costs!$F$6:$F$305,"Bought")) | E11: =IF(B11="","",SUMIFS(Costs!$G$6:$G$305,Costs!$B$6:$B$305,B11,Costs!$F$6:$F$305,"Hired")+SUMIFS(Costs!$G$6:$G$305,Costs!$B$6:$B$305,B11,Costs!$F$6:$F$305,"Bought")) | F11: =IF(B11="","",D11-E11) | G11: =IF(B11="","",C11-D11) | H11: =IF(OR(B11="",N(C11)=0),"",REPT("█",MIN(12,MAX(0,ROUND((D11/C11)*12,0))))&REPT("░",12-MIN(12,MAX(0,ROUND((D11/C11)*12,0))))) | I11: =IF(B11="","",IF(N(C11)=0,IF(N(D11)>0,"No budget set",""),IF(D11>C11,"Over by "&FIXED(D11-C11,0),IF(D11>=0.9*C11,ROUND(D11/C11*100,0)&"% used, near the limit",ROUND(D11/C11*100,0)&"% used")))) | J11: =IF(B11="","",MAX(0,N(D11)-N(C11)))
D12: =IF(B12="","",SUMIFS(Costs!$E$6:$E$305,Costs!$B$6:$B$305,B12,Costs!$F$6:$F$305,"Hired")+SUMIFS(Costs!$E$6:$E$305,Costs!$B$6:$B$305,B12,Costs!$F$6:$F$305,"Bought")) | E12: =IF(B12="","",SUMIFS(Costs!$G$6:$G$305,Costs!$B$6:$B$305,B12,Costs!$F$6:$F$305,"Hired")+SUMIFS(Costs!$G$6:$G$305,Costs!$B$6:$B$305,B12,Costs!$F$6:$F$305,"Bought")) | F12: =IF(B12="","",D12-E12) | G12: =IF(B12="","",C12-D12) | H12: =IF(OR(B12="",N(C12)=0),"",REPT("█",MIN(12,MAX(0,ROUND((D12/C12)*12,0))))&REPT("░",12-MIN(12,MAX(0,ROUND((D12/C12)*12,0))))) | I12: =IF(B12="","",IF(N(C12)=0,IF(N(D12)>0,"No budget set",""),IF(D12>C12,"Over by "&FIXED(D12-C12,0),IF(D12>=0.9*C12,ROUND(D12/C12*100,0)&"% used, near the limit",ROUND(D12/C12*100,0)&"% used")))) | J12: =IF(B12="","",MAX(0,N(D12)-N(C12)))
D13: =IF(B13="","",SUMIFS(Costs!$E$6:$E$305,Costs!$B$6:$B$305,B13,Costs!$F$6:$F$305,"Hired")+SUMIFS(Costs!$E$6:$E$305,Costs!$B$6:$B$305,B13,Costs!$F$6:$F$305,"Bought")) | E13: =IF(B13="","",SUMIFS(Costs!$G$6:$G$305,Costs!$B$6:$B$305,B13,Costs!$F$6:$F$305,"Hired")+SUMIFS(Costs!$G$6:$G$305,Costs!$B$6:$B$305,B13,Costs!$F$6:$F$305,"Bought")) | F13: =IF(B13="","",D13-E13) | G13: =IF(B13="","",C13-D13) | H13: =IF(OR(B13="",N(C13)=0),"",REPT("█",MIN(12,MAX(0,ROUND((D13/C13)*12,0))))&REPT("░",12-MIN(12,MAX(0,ROUND((D13/C13)*12,0))))) | I13: =IF(B13="","",IF(N(C13)=0,IF(N(D13)>0,"No budget set",""),IF(D13>C13,"Over by "&FIXED(D13-C13,0),IF(D13>=0.9*C13,ROUND(D13/C13*100,0)&"% used, near the limit",ROUND(D13/C13*100,0)&"% used")))) | J13: =IF(B13="","",MAX(0,N(D13)-N(C13)))
D14: =IF(B14="","",SUMIFS(Costs!$E$6:$E$305,Costs!$B$6:$B$305,B14,Costs!$F$6:$F$305,"Hired")+SUMIFS(Costs!$E$6:$E$305,Costs!$B$6:$B$305,B14,Costs!$F$6:$F$305,"Bought")) | E14: =IF(B14="","",SUMIFS(Costs!$G$6:$G$305,Costs!$B$6:$B$305,B14,Costs!$F$6:$F$305,"Hired")+SUMIFS(Costs!$G$6:$G$305,Costs!$B$6:$B$305,B14,Costs!$F$6:$F$305,"Bought")) | F14: =IF(B14="","",D14-E14) | G14: =IF(B14="","",C14-D14) | H14: =IF(OR(B14="",N(C14)=0),"",REPT("█",MIN(12,MAX(0,ROUND((D14/C14)*12,0))))&REPT("░",12-MIN(12,MAX(0,ROUND((D14/C14)*12,0))))) | I14: =IF(B14="","",IF(N(C14)=0,IF(N(D14)>0,"No budget set",""),IF(D14>C14,"Over by "&FIXED(D14-C14,0),IF(D14>=0.9*C14,ROUND(D14/C14*100,0)&"% used, near the limit",ROUND(D14/C14*100,0)&"% used")))) | J14: =IF(B14="","",MAX(0,N(D14)-N(C14)))
D15: =IF(B15="","",SUMIFS(Costs!$E$6:$E$305,Costs!$B$6:$B$305,B15,Costs!$F$6:$F$305,"Hired")+SUMIFS(Costs!$E$6:$E$305,Costs!$B$6:$B$305,B15,Costs!$F$6:$F$305,"Bought")) | E15: =IF(B15="","",SUMIFS(Costs!$G$6:$G$305,Costs!$B$6:$B$305,B15,Costs!$F$6:$F$305,"Hired")+SUMIFS(Costs!$G$6:$G$305,Costs!$B$6:$B$305,B15,Costs!$F$6:$F$305,"Bought")) | F15: =IF(B15="","",D15-E15) | G15: =IF(B15="","",C15-D15) | H15: =IF(OR(B15="",N(C15)=0),"",REPT("█",MIN(12,MAX(0,ROUND((D15/C15)*12,0))))&REPT("░",12-MIN(12,MAX(0,ROUND((D15/C15)*12,0))))) | I15: =IF(B15="","",IF(N(C15)=0,IF(N(D15)>0,"No budget set",""),IF(D15>C15,"Over by "&FIXED(D15-C15,0),IF(D15>=0.9*C15,ROUND(D15/C15*100,0)&"% used, near the limit",ROUND(D15/C15*100,0)&"% used")))) | J15: =IF(B15="","",MAX(0,N(D15)-N(C15)))
D16: =IF(B16="","",SUMIFS(Costs!$E$6:$E$305,Costs!$B$6:$B$305,B16,Costs!$F$6:$F$305,"Hired")+SUMIFS(Costs!$E$6:$E$305,Costs!$B$6:$B$305,B16,Costs!$F$6:$F$305,"Bought")) | E16: =IF(B16="","",SUMIFS(Costs!$G$6:$G$305,Costs!$B$6:$B$305,B16,Costs!$F$6:$F$305,"Hired")+SUMIFS(Costs!$G$6:$G$305,Costs!$B$6:$B$305,B16,Costs!$F$6:$F$305,"Bought")) | F16: =IF(B16="","",D16-E16) | G16: =IF(B16="","",C16-D16) | H16: =IF(OR(B16="",N(C16)=0),"",REPT("█",MIN(12,MAX(0,ROUND((D16/C16)*12,0))))&REPT("░",12-MIN(12,MAX(0,ROUND((D16/C16)*12,0))))) | I16: =IF(B16="","",IF(N(C16)=0,IF(N(D16)>0,"No budget set",""),IF(D16>C16,"Over by "&FIXED(D16-C16,0),IF(D16>=0.9*C16,ROUND(D16/C16*100,0)&"% used, near the limit",ROUND(D16/C16*100,0)&"% used")))) | J16: =IF(B16="","",MAX(0,N(D16)-N(C16)))
D17: =IF(B17="","",SUMIFS(Costs!$E$6:$E$305,Costs!$B$6:$B$305,B17,Costs!$F$6:$F$305,"Hired")+SUMIFS(Costs!$E$6:$E$305,Costs!$B$6:$B$305,B17,Costs!$F$6:$F$305,"Bought")) | E17: =IF(B17="","",SUMIFS(Costs!$G$6:$G$305,Costs!$B$6:$B$305,B17,Costs!$F$6:$F$305,"Hired")+SUMIFS(Costs!$G$6:$G$305,Costs!$B$6:$B$305,B17,Costs!$F$6:$F$305,"Bought")) | F17: =IF(B17="","",D17-E17) | G17: =IF(B17="","",C17-D17) | H17: =IF(OR(B17="",N(C17)=0),"",REPT("█",MIN(12,MAX(0,ROUND((D17/C17)*12,0))))&REPT("░",12-MIN(12,MAX(0,ROUND((D17/C17)*12,0))))) | I17: =IF(B17="","",IF(N(C17)=0,IF(N(D17)>0,"No budget set",""),IF(D17>C17,"Over by "&FIXED(D17-C17,0),IF(D17>=0.9*C17,ROUND(D17/C17*100,0)&"% used, near the limit",ROUND(D17/C17*100,0)&"% used")))) | J17: =IF(B17="","",MAX(0,N(D17)-N(C17)))
B18: Total | C18: =SUM(C6:C17) | D18: =SUM(D6:D17) | E18: =SUM(E6:E17) | F18: =SUM(F6:F17) | G18: =SUM(G6:G17)
B20: Room budgets | C20: =C18
B21: ="Contingency ("&ROUND(C4*100,0)&"%)" | C21: =C20*C4
B22: Total budget | C22: =C20+C21
B23: Contingency used | C23: =SUM(J6:J17)+MAX(0,(SUMIFS(Costs!$E$6:$E$305,Costs!$F$6:$F$305,"Hired")+SUMIFS(Costs!$E$6:$E$305,Costs!$F$6:$F$305,"Bought"))-D18)
B24: Contingency left | C24: =C21-C23
B26: Costs with a room that is not on this list also count against the contingency.

Sheet Costs
B2: Quotes and costs
B3: One line per quote, job or purchase. Quotes for the same job need the same job name.
B5: Room | C5: Job or item | D5: Contractor or shop | E5: Amount | F5: Stage | G5: Paid so far | H5: Next payment due | I5: Left to pay | J5: Payment status | K5: Quote check | L5: Note
B6: Kitchen | C6: Cabinets and fitting | D6: Oakline Kitchens | E6: 7900 | F6: Quote | I6: =IF(OR(E6="",AND(F6<>"Hired",F6<>"Bought")),"",E6-N(G6)) | J6: =IF(C6&E6="","",IF(F6="","Choose a stage",IF(F6="Quote","",IF(E6="","Add the amount",IF(I6<=0,"Paid",IF(H6="","Balance due, no date set",IF(H6<TODAY(),"Overdue by "&(TODAY()-H6)&IF((TODAY()-H6)=1," day"," days"),IF(H6=TODAY(),"Due today",IF((H6-TODAY())<=14,"Due in "&(H6-TODAY())&IF((H6-TODAY())=1," day"," days"),"Next payment in "&(H6-TODAY())&" days"))))))))) | K6: =IF(OR(C6="",E6=""),"",IF(COUNTIFS(Costs!$C$6:$C$305,C6,Costs!$E$6:$E$305,"<>")<2,"",IF(M6=1,"Cheapest of "&COUNTIFS(Costs!$C$6:$C$305,C6,Costs!$E$6:$E$305,"<>"),FIXED(E6-SUMIFS(Costs!$E$6:$E$305,Costs!$C$6:$C$305,C6,Costs!$M$6:$M$305,1)/COUNTIFS(Costs!$C$6:$C$305,C6,Costs!$M$6:$M$305,1),0)&" more than the cheapest"))) | M6: =IF(OR(C6="",E6=""),"",IF(COUNTIFS(Costs!$C$6:$C$305,C6,Costs!$E$6:$E$305,"<"&E6)=0,1,0)) | N6: =IF(AND(C6<>"",F6="Quote",COUNTIFS(Costs!$C$6:$C$305,C6,Costs!$F$6:$F$305,"Hired")+COUNTIFS(Costs!$C$6:$C$305,C6,Costs!$F$6:$F$305,"Bought")=0),1/COUNTIFS(Costs!$C$6:$C$305,C6,Costs!$F$6:$F$305,"Quote"),"") | O6: =IF(AND(OR(F6="Hired",F6="Bought"),N(I6)>0,H6<>""),H6+ROW()/100000,"")
B7: Kitchen | C7: Cabinets and fitting | D7: Riverside Cabinet Co | E7: 7200 | F7: Hired | G7: 2160 | H7: 46305 | I7: =IF(OR(E7="",AND(F7<>"Hired",F7<>"Bought")),"",E7-N(G7)) | J7: =IF(C7&E7="","",IF(F7="","Choose a stage",IF(F7="Quote","",IF(E7="","Add the amount",IF(I7<=0,"Paid",IF(H7="","Balance due, no date set",IF(H7<TODAY(),"Overdue by "&(TODAY()-H7)&IF((TODAY()-H7)=1," day"," days"),IF(H7=TODAY(),"Due today",IF((H7-TODAY())<=14,"Due in "&(H7-TODAY())&IF((H7-TODAY())=1," day"," days"),"Next payment in "&(H7-TODAY())&" days"))))))))) | K7: =IF(OR(C7="",E7=""),"",IF(COUNTIFS(Costs!$C$6:$C$305,C7,Costs!$E$6:$E$305,"<>")<2,"",IF(M7=1,"Cheapest of "&COUNTIFS(Costs!$C$6:$C$305,C7,Costs!$E$6:$E$305,"<>"),FIXED(E7-SUMIFS(Costs!$E$6:$E$305,Costs!$C$6:$C$305,C7,Costs!$M$6:$M$305,1)/COUNTIFS(Costs!$C$6:$C$305,C7,Costs!$M$6:$M$305,1),0)&" more than the cheapest"))) | M7: =IF(OR(C7="",E7=""),"",IF(COUNTIFS(Costs!$C$6:$C$305,C7,Costs!$E$6:$E$305,"<"&E7)=0,1,0)) | N7: =IF(AND(C7<>"",F7="Quote",COUNTIFS(Costs!$C$6:$C$305,C7,Costs!$F$6:$F$305,"Hired")+COUNTIFS(Costs!$C$6:$C$305,C7,Costs!$F$6:$F$305,"Bought")=0),1/COUNTIFS(Costs!$C$6:$C$305,C7,Costs!$F$6:$F$305,"Quote"),"") | O7: =IF(AND(OR(F7="Hired",F7="Bought"),N(I7)>0,H7<>""),H7+ROW()/100000,"")
B8: Kitchen | C8: Cabinets and fitting | D8: HomeFit Kitchens | E8: 8450 | F8: Quote | I8: =IF(OR(E8="",AND(F8<>"Hired",F8<>"Bought")),"",E8-N(G8)) | J8: =IF(C8&E8="","",IF(F8="","Choose a stage",IF(F8="Quote","",IF(E8="","Add the amount",IF(I8<=0,"Paid",IF(H8="","Balance due, no date set",IF(H8<TODAY(),"Overdue by "&(TODAY()-H8)&IF((TODAY()-H8)=1," day"," days"),IF(H8=TODAY(),"Due today",IF((H8-TODAY())<=14,"Due in "&(H8-TODAY())&IF((H8-TODAY())=1," day"," days"),"Next payment in "&(H8-TODAY())&" days"))))))))) | K8: =IF(OR(C8="",E8=""),"",IF(COUNTIFS(Costs!$C$6:$C$305,C8,Costs!$E$6:$E$305,"<>")<2,"",IF(M8=1,"Cheapest of "&COUNTIFS(Costs!$C$6:$C$305,C8,Costs!$E$6:$E$305,"<>"),FIXED(E8-SUMIFS(Costs!$E$6:$E$305,Costs!$C$6:$C$305,C8,Costs!$M$6:$M$305,1)/COUNTIFS(Costs!$C$6:$C$305,C8,Costs!$M$6:$M$305,1),0)&" more than the cheapest"))) | M8: =IF(OR(C8="",E8=""),"",IF(COUNTIFS(Costs!$C$6:$C$305,C8,Costs!$E$6:$E$305,"<"&E8)=0,1,0)) | N8: =IF(AND(C8<>"",F8="Quote",COUNTIFS(Costs!$C$6:$C$305,C8,Costs!$F$6:$F$305,"Hired")+COUNTIFS(Costs!$C$6:$C$305,C8,Costs!$F$6:$F$305,"Bought")=0),1/COUNTIFS(Costs!$C$6:$C$305,C8,Costs!$F$6:$F$305,"Quote"),"") | O8: =IF(AND(OR(F8="Hired",F8="Bought"),N(I8)>0,H8<>""),H8+ROW()/100000,"")
B9: Kitchen | C9: Quartz countertops | D9: Stone Works | E9: 2650 | F9: Bought | G9: 2650 | I9: =IF(OR(E9="",AND(F9<>"Hired",F9<>"Bought")),"",E9-N(G9)) | J9: =IF(C9&E9="","",IF(F9="","Choose a stage",IF(F9="Quote","",IF(E9="","Add the amount",IF(I9<=0,"Paid",IF(H9="","Balance due, no date set",IF(H9<TODAY(),"Overdue by "&(TODAY()-H9)&IF((TODAY()-H9)=1," day"," days"),IF(H9=TODAY(),"Due today",IF((H9-TODAY())<=14,"Due in "&(H9-TODAY())&IF((H9-TODAY())=1," day"," days"),"Next payment in "&(H9-TODAY())&" days"))))))))) | K9: =IF(OR(C9="",E9=""),"",IF(COUNTIFS(Costs!$C$6:$C$305,C9,Costs!$E$6:$E$305,"<>")<2,"",IF(M9=1,"Cheapest of "&COUNTIFS(Costs!$C$6:$C$305,C9,Costs!$E$6:$E$305,"<>"),FIXED(E9-SUMIFS(Costs!$E$6:$E$305,Costs!$C$6:$C$305,C9,Costs!$M$6:$M$305,1)/COUNTIFS(Costs!$C$6:$C$305,C9,Costs!$M$6:$M$305,1),0)&" more than the cheapest"))) | M9: =IF(OR(C9="",E9=""),"",IF(COUNTIFS(Costs!$C$6:$C$305,C9,Costs!$E$6:$E$305,"<"&E9)=0,1,0)) | N9: =IF(AND(C9<>"",F9="Quote",COUNTIFS(Costs!$C$6:$C$305,C9,Costs!$F$6:$F$305,"Hired")+COUNTIFS(Costs!$C$6:$C$305,C9,Costs!$F$6:$F$305,"Bought")=0),1/COUNTIFS(Costs!$C$6:$C$305,C9,Costs!$F$6:$F$305,"Quote"),"") | O9: =IF(AND(OR(F9="Hired",F9="Bought"),N(I9)>0,H9<>""),H9+ROW()/100000,"")
B10: Kitchen | C10: Appliances | D10: Appliance store | E10: 3100 | F10: Bought | G10: 3100 | I10: =IF(OR(E10="",AND(F10<>"Hired",F10<>"Bought")),"",E10-N(G10)) | J10: =IF(C10&E10="","",IF(F10="","Choose a stage",IF(F10="Quote","",IF(E10="","Add the amount",IF(I10<=0,"Paid",IF(H10="","Balance due, no date set",IF(H10<TODAY(),"Overdue by "&(TODAY()-H10)&IF((TODAY()-H10)=1," day"," days"),IF(H10=TODAY(),"Due today",IF((H10-TODAY())<=14,"Due in "&(H10-TODAY())&IF((H10-TODAY())=1," day"," days"),"Next payment in "&(H10-TODAY())&" days"))))))))) | K10: =IF(OR(C10="",E10=""),"",IF(COUNTIFS(Costs!$C$6:$C$305,C10,Costs!$E$6:$E$305,"<>")<2,"",IF(M10=1,"Cheapest of "&COUNTIFS(Costs!$C$6:$C$305,C10,Costs!$E$6:$E$305,"<>"),FIXED(E10-SUMIFS(Costs!$E$6:$E$305,Costs!$C$6:$C$305,C10,Costs!$M$6:$M$305,1)/COUNTIFS(Costs!$C$6:$C$305,C10,Costs!$M$6:$M$305,1),0)&" more than the cheapest"))) | M10: =IF(OR(C10="",E10=""),"",IF(COUNTIFS(Costs!$C$6:$C$305,C10,Costs!$E$6:$E$305,"<"&E10)=0,1,0)) | N10: =IF(AND(C10<>"",F10="Quote",COUNTIFS(Costs!$C$6:$C$305,C10,Costs!$F$6:$F$305,"Hired")+COUNTIFS(Costs!$C$6:$C$305,C10,Costs!$F$6:$F$305,"Bought")=0),1/COUNTIFS(Costs!$C$6:$C$305,C10,Costs!$F$6:$F$305,"Quote"),"") | O10: =IF(AND(OR(F10="Hired",F10="Bought"),N(I10)>0,H10<>""),H10+ROW()/100000,"")
B11: Kitchen | C11: Kitchen electrics | D11: Spark Electrical | E11: 1450 | F11: Hired | G11: 0 | H11: 46290 | I11: =IF(OR(E11="",AND(F11<>"Hired",F11<>"Bought")),"",E11-N(G11)) | J11: =IF(C11&E11="","",IF(F11="","Choose a stage",IF(F11="Quote","",IF(E11="","Add the amount",IF(I11<=0,"Paid",IF(H11="","Balance due, no date set",IF(H11<TODAY(),"Overdue by "&(TODAY()-H11)&IF((TODAY()-H11)=1," day"," days"),IF(H11=TODAY(),"Due today",IF((H11-TODAY())<=14,"Due in "&(H11-TODAY())&IF((H11-TODAY())=1," day"," days"),"Next payment in "&(H11-TODAY())&" days"))))))))) | K11: =IF(OR(C11="",E11=""),"",IF(COUNTIFS(Costs!$C$6:$C$305,C11,Costs!$E$6:$E$305,"<>")<2,"",IF(M11=1,"Cheapest of "&COUNTIFS(Costs!$C$6:$C$305,C11,Costs!$E$6:$E$305,"<>"),FIXED(E11-SUMIFS(Costs!$E$6:$E$305,Costs!$C$6:$C$305,C11,Costs!$M$6:$M$305,1)/COUNTIFS(Costs!$C$6:$C$305,C11,Costs!$M$6:$M$305,1),0)&" more than the cheapest"))) | M11: =IF(OR(C11="",E11=""),"",IF(COUNTIFS(Costs!$C$6:$C$305,C11,Costs!$E$6:$E$305,"<"&E11)=0,1,0)) | N11: =IF(AND(C11<>"",F11="Quote",COUNTIFS(Costs!$C$6:$C$305,C11,Costs!$F$6:$F$305,"Hired")+COUNTIFS(Costs!$C$6:$C$305,C11,Costs!$F$6:$F$305,"Bought")=0),1/COUNTIFS(Costs!$C$6:$C$305,C11,Costs!$F$6:$F$305,"Quote"),"") | O11: =IF(AND(OR(F11="Hired",F11="Bought"),N(I11)>0,H11<>""),H11+ROW()/100000,"")
B12: Bathroom | C12: Bathroom remodel | D12: Blue Tap Plumbing | E12: 6800 | F12: Hired | G12: 2000 | H12: 46313 | I12: =IF(OR(E12="",AND(F12<>"Hired",F12<>"Bought")),"",E12-N(G12)) | J12: =IF(C12&E12="","",IF(F12="","Choose a stage",IF(F12="Quote","",IF(E12="","Add the amount",IF(I12<=0,"Paid",IF(H12="","Balance due, no date set",IF(H12<TODAY(),"Overdue by "&(TODAY()-H12)&IF((TODAY()-H12)=1," day"," days"),IF(H12=TODAY(),"Due today",IF((H12-TODAY())<=14,"Due in "&(H12-TODAY())&IF((H12-TODAY())=1," day"," days"),"Next payment in "&(H12-TODAY())&" days"))))))))) | K12: =IF(OR(C12="",E12=""),"",IF(COUNTIFS(Costs!$C$6:$C$305,C12,Costs!$E$6:$E$305,"<>")<2,"",IF(M12=1,"Cheapest of "&COUNTIFS(Costs!$C$6:$C$305,C12,Costs!$E$6:$E$305,"<>"),FIXED(E12-SUMIFS(Costs!$E$6:$E$305,Costs!$C$6:$C$305,C12,Costs!$M$6:$M$305,1)/COUNTIFS(Costs!$C$6:$C$305,C12,Costs!$M$6:$M$305,1),0)&" more than the cheapest"))) | M12: =IF(OR(C12="",E12=""),"",IF(COUNTIFS(Costs!$C$6:$C$305,C12,Costs!$E$6:$E$305,"<"&E12)=0,1,0)) | N12: =IF(AND(C12<>"",F12="Quote",COUNTIFS(Costs!$C$6:$C$305,C12,Costs!$F$6:$F$305,"Hired")+COUNTIFS(Costs!$C$6:$C$305,C12,Costs!$F$6:$F$305,"Bought")=0),1/COUNTIFS(Costs!$C$6:$C$305,C12,Costs!$F$6:$F$305,"Quote"),"") | O12: =IF(AND(OR(F12="Hired",F12="Bought"),N(I12)>0,H12<>""),H12+ROW()/100000,"")
B13: Bathroom | C13: Bathroom remodel | D13: Clearwater Baths | E13: 7450 | F13: Quote | I13: =IF(OR(E13="",AND(F13<>"Hired",F13<>"Bought")),"",E13-N(G13)) | J13: =IF(C13&E13="","",IF(F13="","Choose a stage",IF(F13="Quote","",IF(E13="","Add the amount",IF(I13<=0,"Paid",IF(H13="","Balance due, no date set",IF(H13<TODAY(),"Overdue by "&(TODAY()-H13)&IF((TODAY()-H13)=1," day"," days"),IF(H13=TODAY(),"Due today",IF((H13-TODAY())<=14,"Due in "&(H13-TODAY())&IF((H13-TODAY())=1," day"," days"),"Next payment in "&(H13-TODAY())&" days"))))))))) | K13: =IF(OR(C13="",E13=""),"",IF(COUNTIFS(Costs!$C$6:$C$305,C13,Costs!$E$6:$E$305,"<>")<2,"",IF(M13=1,"Cheapest of "&COUNTIFS(Costs!$C$6:$C$305,C13,Costs!$E$6:$E$305,"<>"),FIXED(E13-SUMIFS(Costs!$E$6:$E$305,Costs!$C$6:$C$305,C13,Costs!$M$6:$M$305,1)/COUNTIFS(Costs!$C$6:$C$305,C13,Costs!$M$6:$M$305,1),0)&" more than the cheapest"))) | M13: =IF(OR(C13="",E13=""),"",IF(COUNTIFS(Costs!$C$6:$C$305,C13,Costs!$E$6:$E$305,"<"&E13)=0,1,0)) | N13: =IF(AND(C13<>"",F13="Quote",COUNTIFS(Costs!$C$6:$C$305,C13,Costs!$F$6:$F$305,"Hired")+COUNTIFS(Costs!$C$6:$C$305,C13,Costs!$F$6:$F$305,"Bought")=0),1/COUNTIFS(Costs!$C$6:$C$305,C13,Costs!$F$6:$F$305,"Quote"),"") | O13: =IF(AND(OR(F13="Hired",F13="Bought"),N(I13)>0,H13<>""),H13+ROW()/100000,"")
B14: Bathroom | C14: Tiles | D14: Tile shop | E14: 1380 | F14: Bought | G14: 1380 | I14: =IF(OR(E14="",AND(F14<>"Hired",F14<>"Bought")),"",E14-N(G14)) | J14: =IF(C14&E14="","",IF(F14="","Choose a stage",IF(F14="Quote","",IF(E14="","Add the amount",IF(I14<=0,"Paid",IF(H14="","Balance due, no date set",IF(H14<TODAY(),"Overdue by "&(TODAY()-H14)&IF((TODAY()-H14)=1," day"," days"),IF(H14=TODAY(),"Due today",IF((H14-TODAY())<=14,"Due in "&(H14-TODAY())&IF((H14-TODAY())=1," day"," days"),"Next payment in "&(H14-TODAY())&" days"))))))))) | K14: =IF(OR(C14="",E14=""),"",IF(COUNTIFS(Costs!$C$6:$C$305,C14,Costs!$E$6:$E$305,"<>")<2,"",IF(M14=1,"Cheapest of "&COUNTIFS(Costs!$C$6:$C$305,C14,Costs!$E$6:$E$305,"<>"),FIXED(E14-SUMIFS(Costs!$E$6:$E$305,Costs!$C$6:$C$305,C14,Costs!$M$6:$M$305,1)/COUNTIFS(Costs!$C$6:$C$305,C14,Costs!$M$6:$M$305,1),0)&" more than the cheapest"))) | M14: =IF(OR(C14="",E14=""),"",IF(COUNTIFS(Costs!$C$6:$C$305,C14,Costs!$E$6:$E$305,"<"&E14)=0,1,0)) | N14: =IF(AND(C14<>"",F14="Quote",COUNTIFS(Costs!$C$6:$C$305,C14,Costs!$F$6:$F$305,"Hired")+COUNTIFS(Costs!$C$6:$C$305,C14,Costs!$F$6:$F$305,"Bought")=0),1/COUNTIFS(Costs!$C$6:$C$305,C14,Costs!$F$6:$F$305,"Quote"),"") | O14: =IF(AND(OR(F14="Hired",F14="Bought"),N(I14)>0,H14<>""),H14+ROW()/100000,"")
B15: Bathroom | C15: Vanity, toilet and shower | D15: Bathroom store | E15: 2150 | F15: Bought | G15: 1000 | H15: 46299 | I15: =IF(OR(E15="",AND(F15<>"Hired",F15<>"Bought")),"",E15-N(G15)) | J15: =IF(C15&E15="","",IF(F15="","Choose a stage",IF(F15="Quote","",IF(E15="","Add the amount",IF(I15<=0,"Paid",IF(H15="","Balance due, no date set",IF(H15<TODAY(),"Overdue by "&(TODAY()-H15)&IF((TODAY()-H15)=1," day"," days"),IF(H15=TODAY(),"Due today",IF((H15-TODAY())<=14,"Due in "&(H15-TODAY())&IF((H15-TODAY())=1," day"," days"),"Next payment in "&(H15-TODAY())&" days"))))))))) | K15: =IF(OR(C15="",E15=""),"",IF(COUNTIFS(Costs!$C$6:$C$305,C15,Costs!$E$6:$E$305,"<>")<2,"",IF(M15=1,"Cheapest of "&COUNTIFS(Costs!$C$6:$C$305,C15,Costs!$E$6:$E$305,"<>"),FIXED(E15-SUMIFS(Costs!$E$6:$E$305,Costs!$C$6:$C$305,C15,Costs!$M$6:$M$305,1)/COUNTIFS(Costs!$C$6:$C$305,C15,Costs!$M$6:$M$305,1),0)&" more than the cheapest"))) | M15: =IF(OR(C15="",E15=""),"",IF(COUNTIFS(Costs!$C$6:$C$305,C15,Costs!$E$6:$E$305,"<"&E15)=0,1,0)) | N15: =IF(AND(C15<>"",F15="Quote",COUNTIFS(Costs!$C$6:$C$305,C15,Costs!$F$6:$F$305,"Hired")+COUNTIFS(Costs!$C$6:$C$305,C15,Costs!$F$6:$F$305,"Bought")=0),1/COUNTIFS(Costs!$C$6:$C$305,C15,Costs!$F$6:$F$305,"Quote"),"") | O15: =IF(AND(OR(F15="Hired",F15="Bought"),N(I15)>0,H15<>""),H15+ROW()/100000,"")
B16: Living room | C16: Oak flooring | D16: Floor Masters | E16: 2900 | F16: Hired | G16: 0 | H16: 46328 | I16: =IF(OR(E16="",AND(F16<>"Hired",F16<>"Bought")),"",E16-N(G16)) | J16: =IF(C16&E16="","",IF(F16="","Choose a stage",IF(F16="Quote","",IF(E16="","Add the amount",IF(I16<=0,"Paid",IF(H16="","Balance due, no date set",IF(H16<TODAY(),"Overdue by "&(TODAY()-H16)&IF((TODAY()-H16)=1," day"," days"),IF(H16=TODAY(),"Due today",IF((H16-TODAY())<=14,"Due in "&(H16-TODAY())&IF((H16-TODAY())=1," day"," days"),"Next payment in "&(H16-TODAY())&" days"))))))))) | K16: =IF(OR(C16="",E16=""),"",IF(COUNTIFS(Costs!$C$6:$C$305,C16,Costs!$E$6:$E$305,"<>")<2,"",IF(M16=1,"Cheapest of "&COUNTIFS(Costs!$C$6:$C$305,C16,Costs!$E$6:$E$305,"<>"),FIXED(E16-SUMIFS(Costs!$E$6:$E$305,Costs!$C$6:$C$305,C16,Costs!$M$6:$M$305,1)/COUNTIFS(Costs!$C$6:$C$305,C16,Costs!$M$6:$M$305,1),0)&" more than the cheapest"))) | M16: =IF(OR(C16="",E16=""),"",IF(COUNTIFS(Costs!$C$6:$C$305,C16,Costs!$E$6:$E$305,"<"&E16)=0,1,0)) | N16: =IF(AND(C16<>"",F16="Quote",COUNTIFS(Costs!$C$6:$C$305,C16,Costs!$F$6:$F$305,"Hired")+COUNTIFS(Costs!$C$6:$C$305,C16,Costs!$F$6:$F$305,"Bought")=0),1/COUNTIFS(Costs!$C$6:$C$305,C16,Costs!$F$6:$F$305,"Quote"),"") | O16: =IF(AND(OR(F16="Hired",F16="Bought"),N(I16)>0,H16<>""),H16+ROW()/100000,"")
B17: Living room | C17: Painting | D17: Fresh Coat Painters | E17: 1100 | F17: Quote | I17: =IF(OR(E17="",AND(F17<>"Hired",F17<>"Bought")),"",E17-N(G17)) | J17: =IF(C17&E17="","",IF(F17="","Choose a stage",IF(F17="Quote","",IF(E17="","Add the amount",IF(I17<=0,"Paid",IF(H17="","Balance due, no date set",IF(H17<TODAY(),"Overdue by "&(TODAY()-H17)&IF((TODAY()-H17)=1," day"," days"),IF(H17=TODAY(),"Due today",IF((H17-TODAY())<=14,"Due in "&(H17-TODAY())&IF((H17-TODAY())=1," day"," days"),"Next payment in "&(H17-TODAY())&" days"))))))))) | K17: =IF(OR(C17="",E17=""),"",IF(COUNTIFS(Costs!$C$6:$C$305,C17,Costs!$E$6:$E$305,"<>")<2,"",IF(M17=1,"Cheapest of "&COUNTIFS(Costs!$C$6:$C$305,C17,Costs!$E$6:$E$305,"<>"),FIXED(E17-SUMIFS(Costs!$E$6:$E$305,Costs!$C$6:$C$305,C17,Costs!$M$6:$M$305,1)/COUNTIFS(Costs!$C$6:$C$305,C17,Costs!$M$6:$M$305,1),0)&" more than the cheapest"))) | M17: =IF(OR(C17="",E17=""),"",IF(COUNTIFS(Costs!$C$6:$C$305,C17,Costs!$E$6:$E$305,"<"&E17)=0,1,0)) | N17: =IF(AND(C17<>"",F17="Quote",COUNTIFS(Costs!$C$6:$C$305,C17,Costs!$F$6:$F$305,"Hired")+COUNTIFS(Costs!$C$6:$C$305,C17,Costs!$F$6:$F$305,"Bought")=0),1/COUNTIFS(Costs!$C$6:$C$305,C17,Costs!$F$6:$F$305,"Quote"),"") | O17: =IF(AND(OR(F17="Hired",F17="Bought"),N(I17)>0,H17<>""),H17+ROW()/100000,"")
B18: Living room | C18: Painting | D18: Local painter | E18: 950 | F18: Quote | I18: =IF(OR(E18="",AND(F18<>"Hired",F18<>"Bought")),"",E18-N(G18)) | J18: =IF(C18&E18="","",IF(F18="","Choose a stage",IF(F18="Quote","",IF(E18="","Add the amount",IF(I18<=0,"Paid",IF(H18="","Balance due, no date set",IF(H18<TODAY(),"Overdue by "&(TODAY()-H18)&IF((TODAY()-H18)=1," day"," days"),IF(H18=TODAY(),"Due today",IF((H18-TODAY())<=14,"Due in "&(H18-TODAY())&IF((H18-TODAY())=1," day"," days"),"Next payment in "&(H18-TODAY())&" days"))))))))) | K18: =IF(OR(C18="",E18=""),"",IF(COUNTIFS(Costs!$C$6:$C$305,C18,Costs!$E$6:$E$305,"<>")<2,"",IF(M18=1,"Cheapest of "&COUNTIFS(Costs!$C$6:$C$305,C18,Costs!$E$6:$E$305,"<>"),FIXED(E18-SUMIFS(Costs!$E$6:$E$305,Costs!$C$6:$C$305,C18,Costs!$M$6:$M$305,1)/COUNTIFS(Costs!$C$6:$C$305,C18,Costs!$M$6:$M$305,1),0)&" more than the cheapest"))) | M18: =IF(OR(C18="",E18=""),"",IF(COUNTIFS(Costs!$C$6:$C$305,C18,Costs!$E$6:$E$305,"<"&E18)=0,1,0)) | N18: =IF(AND(C18<>"",F18="Quote",COUNTIFS(Costs!$C$6:$C$305,C18,Costs!$F$6:$F$305,"Hired")+COUNTIFS(Costs!$C$6:$C$305,C18,Costs!$F$6:$F$305,"Bought")=0),1/COUNTIFS(Costs!$C$6:$C$305,C18,Costs!$F$6:$F$305,"Quote"),"") | O18: =IF(AND(OR(F18="Hired",F18="Bought"),N(I18)>0,H18<>""),H18+ROW()/100000,"")
B19: Primary bedroom | C19: Built-in closet | D19: Riverside Cabinet Co | E19: 2400 | F19: Quote | I19: =IF(OR(E19="",AND(F19<>"Hired",F19<>"Bought")),"",E19-N(G19)) | J19: =IF(C19&E19="","",IF(F19="","Choose a stage",IF(F19="Quote","",IF(E19="","Add the amount",IF(I19<=0,"Paid",IF(H19="","Balance due, no date set",IF(H19<TODAY(),"Overdue by "&(TODAY()-H19)&IF((TODAY()-H19)=1," day"," days"),IF(H19=TODAY(),"Due today",IF((H19-TODAY())<=14,"Due in "&(H19-TODAY())&IF((H19-TODAY())=1," day"," days"),"Next payment in "&(H19-TODAY())&" days"))))))))) | K19: =IF(OR(C19="",E19=""),"",IF(COUNTIFS(Costs!$C$6:$C$305,C19,Costs!$E$6:$E$305,"<>")<2,"",IF(M19=1,"Cheapest of "&COUNTIFS(Costs!$C$6:$C$305,C19,Costs!$E$6:$E$305,"<>"),FIXED(E19-SUMIFS(Costs!$E$6:$E$305,Costs!$C$6:$C$305,C19,Costs!$M$6:$M$305,1)/COUNTIFS(Costs!$C$6:$C$305,C19,Costs!$M$6:$M$305,1),0)&" more than the cheapest"))) | M19: =IF(OR(C19="",E19=""),"",IF(COUNTIFS(Costs!$C$6:$C$305,C19,Costs!$E$6:$E$305,"<"&E19)=0,1,0)) | N19: =IF(AND(C19<>"",F19="Quote",COUNTIFS(Costs!$C$6:$C$305,C19,Costs!$F$6:$F$305,"Hired")+COUNTIFS(Costs!$C$6:$C$305,C19,Costs!$F$6:$F$305,"Bought")=0),1/COUNTIFS(Costs!$C$6:$C$305,C19,Costs!$F$6:$F$305,"Quote"),"") | O19: =IF(AND(OR(F19="Hired",F19="Bought"),N(I19)>0,H19<>""),H19+ROW()/100000,"")
B20: Primary bedroom | C20: Built-in closet | D20: Closet Studio | E20: 2150 | F20: Quote | I20: =IF(OR(E20="",AND(F20<>"Hired",F20<>"Bought")),"",E20-N(G20)) | J20: =IF(C20&E20="","",IF(F20="","Choose a stage",IF(F20="Quote","",IF(E20="","Add the amount",IF(I20<=0,"Paid",IF(H20="","Balance due, no date set",IF(H20<TODAY(),"Overdue by "&(TODAY()-H20)&IF((TODAY()-H20)=1," day"," days"),IF(H20=TODAY(),"Due today",IF((H20-TODAY())<=14,"Due in "&(H20-TODAY())&IF((H20-TODAY())=1," day"," days"),"Next payment in "&(H20-TODAY())&" days"))))))))) | K20: =IF(OR(C20="",E20=""),"",IF(COUNTIFS(Costs!$C$6:$C$305,C20,Costs!$E$6:$E$305,"<>")<2,"",IF(M20=1,"Cheapest of "&COUNTIFS(Costs!$C$6:$C$305,C20,Costs!$E$6:$E$305,"<>"),FIXED(E20-SUMIFS(Costs!$E$6:$E$305,Costs!$C$6:$C$305,C20,Costs!$M$6:$M$305,1)/COUNTIFS(Costs!$C$6:$C$305,C20,Costs!$M$6:$M$305,1),0)&" more than the cheapest"))) | M20: =IF(OR(C20="",E20=""),"",IF(COUNTIFS(Costs!$C$6:$C$305,C20,Costs!$E$6:$E$305,"<"&E20)=0,1,0)) | N20: =IF(AND(C20<>"",F20="Quote",COUNTIFS(Costs!$C$6:$C$305,C20,Costs!$F$6:$F$305,"Hired")+COUNTIFS(Costs!$C$6:$C$305,C20,Costs!$F$6:$F$305,"Bought")=0),1/COUNTIFS(Costs!$C$6:$C$305,C20,Costs!$F$6:$F$305,"Quote"),"") | O20: =IF(AND(OR(F20="Hired",F20="Bought"),N(I20)>0,H20<>""),H20+ROW()/100000,"")
B21: Whole house | C21: Building permit | D21: Building department | E21: 450 | F21: Bought | G21: 450 | I21: =IF(OR(E21="",AND(F21<>"Hired",F21<>"Bought")),"",E21-N(G21)) | J21: =IF(C21&E21="","",IF(F21="","Choose a stage",IF(F21="Quote","",IF(E21="","Add the amount",IF(I21<=0,"Paid",IF(H21="","Balance due, no date set",IF(H21<TODAY(),"Overdue by "&(TODAY()-H21)&IF((TODAY()-H21)=1," day"," days"),IF(H21=TODAY(),"Due today",IF((H21-TODAY())<=14,"Due in "&(H21-TODAY())&IF((H21-TODAY())=1," day"," days"),"Next payment in "&(H21-TODAY())&" days"))))))))) | K21: =IF(OR(C21="",E21=""),"",IF(COUNTIFS(Costs!$C$6:$C$305,C21,Costs!$E$6:$E$305,"<>")<2,"",IF(M21=1,"Cheapest of "&COUNTIFS(Costs!$C$6:$C$305,C21,Costs!$E$6:$E$305,"<>"),FIXED(E21-SUMIFS(Costs!$E$6:$E$305,Costs!$C$6:$C$305,C21,Costs!$M$6:$M$305,1)/COUNTIFS(Costs!$C$6:$C$305,C21,Costs!$M$6:$M$305,1),0)&" more than the cheapest"))) | M21: =IF(OR(C21="",E21=""),"",IF(COUNTIFS(Costs!$C$6:$C$305,C21,Costs!$E$6:$E$305,"<"&E21)=0,1,0)) | N21: =IF(AND(C21<>"",F21="Quote",COUNTIFS(Costs!$C$6:$C$305,C21,Costs!$F$6:$F$305,"Hired")+COUNTIFS(Costs!$C$6:$C$305,C21,Costs!$F$6:$F$305,"Bought")=0),1/COUNTIFS(Costs!$C$6:$C$305,C21,Costs!$F$6:$F$305,"Quote"),"") | O21: =IF(AND(OR(F21="Hired",F21="Bought"),N(I21)>0,H21<>""),H21+ROW()/100000,"")
B22: Whole house | C22: Dumpster rental | D22: Waste hauler | E22: 380 | F22: Hired | G22: 380 | I22: =IF(OR(E22="",AND(F22<>"Hired",F22<>"Bought")),"",E22-N(G22)) | J22: =IF(C22&E22="","",IF(F22="","Choose a stage",IF(F22="Quote","",IF(E22="","Add the amount",IF(I22<=0,"Paid",IF(H22="","Balance due, no date set",IF(H22<TODAY(),"Overdue by "&(TODAY()-H22)&IF((TODAY()-H22)=1," day"," days"),IF(H22=TODAY(),"Due today",IF((H22-TODAY())<=14,"Due in "&(H22-TODAY())&IF((H22-TODAY())=1," day"," days"),"Next payment in "&(H22-TODAY())&" days"))))))))) | K22: =IF(OR(C22="",E22=""),"",IF(COUNTIFS(Costs!$C$6:$C$305,C22,Costs!$E$6:$E$305,"<>")<2,"",IF(M22=1,"Cheapest of "&COUNTIFS(Costs!$C$6:$C$305,C22,Costs!$E$6:$E$305,"<>"),FIXED(E22-SUMIFS(Costs!$E$6:$E$305,Costs!$C$6:$C$305,C22,Costs!$M$6:$M$305,1)/COUNTIFS(Costs!$C$6:$C$305,C22,Costs!$M$6:$M$305,1),0)&" more than the cheapest"))) | M22: =IF(OR(C22="",E22=""),"",IF(COUNTIFS(Costs!$C$6:$C$305,C22,Costs!$E$6:$E$305,"<"&E22)=0,1,0)) | N22: =IF(AND(C22<>"",F22="Quote",COUNTIFS(Costs!$C$6:$C$305,C22,Costs!$F$6:$F$305,"Hired")+COUNTIFS(Costs!$C$6:$C$305,C22,Costs!$F$6:$F$305,"Bought")=0),1/COUNTIFS(Costs!$C$6:$C$305,C22,Costs!$F$6:$F$305,"Quote"),"") | O22: =IF(AND(OR(F22="Hired",F22="Bought"),N(I22)>0,H22<>""),H22+ROW()/100000,"")
B23: Whole house | C23: Partial rewire | D23: Spark Electrical | E23: 3900 | F23: Hired | G23: 1950 | H23: 46302 | I23: =IF(OR(E23="",AND(F23<>"Hired",F23<>"Bought")),"",E23-N(G23)) | J23: =IF(C23&E23="","",IF(F23="","Choose a stage",IF(F23="Quote","",IF(E23="","Add the amount",IF(I23<=0,"Paid",IF(H23="","Balance due, no date set",IF(H23<TODAY(),"Overdue by "&(TODAY()-H23)&IF((TODAY()-H23)=1," day"," days"),IF(H23=TODAY(),"Due today",IF((H23-TODAY())<=14,"Due in "&(H23-TODAY())&IF((H23-TODAY())=1," day"," days"),"Next payment in "&(H23-TODAY())&" days"))))))))) | K23: =IF(OR(C23="",E23=""),"",IF(COUNTIFS(Costs!$C$6:$C$305,C23,Costs!$E$6:$E$305,"<>")<2,"",IF(M23=1,"Cheapest of "&COUNTIFS(Costs!$C$6:$C$305,C23,Costs!$E$6:$E$305,"<>"),FIXED(E23-SUMIFS(Costs!$E$6:$E$305,Costs!$C$6:$C$305,C23,Costs!$M$6:$M$305,1)/COUNTIFS(Costs!$C$6:$C$305,C23,Costs!$M$6:$M$305,1),0)&" more than the cheapest"))) | M23: =IF(OR(C23="",E23=""),"",IF(COUNTIFS(Costs!$C$6:$C$305,C23,Costs!$E$6:$E$305,"<"&E23)=0,1,0)) | N23: =IF(AND(C23<>"",F23="Quote",COUNTIFS(Costs!$C$6:$C$305,C23,Costs!$F$6:$F$305,"Hired")+COUNTIFS(Costs!$C$6:$C$305,C23,Costs!$F$6:$F$305,"Bought")=0),1/COUNTIFS(Costs!$C$6:$C$305,C23,Costs!$F$6:$F$305,"Quote"),"") | O23: =IF(AND(OR(F23="Hired",F23="Bought"),N(I23)>0,H23<>""),H23+ROW()/100000,"")
B24: Exterior | C24: Fence repair | D24: Garden and Fence Co | E24: 1250 | F24: Quote | I24: =IF(OR(E24="",AND(F24<>"Hired",F24<>"Bought")),"",E24-N(G24)) | J24: =IF(C24&E24="","",IF(F24="","Choose a stage",IF(F24="Quote","",IF(E24="","Add the amount",IF(I24<=0,"Paid",IF(H24="","Balance due, no date set",IF(H24<TODAY(),"Overdue by "&(TODAY()-H24)&IF((TODAY()-H24)=1," day"," days"),IF(H24=TODAY(),"Due today",IF((H24-TODAY())<=14,"Due in "&(H24-TODAY())&IF((H24-TODAY())=1," day"," days"),"Next payment in "&(H24-TODAY())&" days"))))))))) | K24: =IF(OR(C24="",E24=""),"",IF(COUNTIFS(Costs!$C$6:$C$305,C24,Costs!$E$6:$E$305,"<>")<2,"",IF(M24=1,"Cheapest of "&COUNTIFS(Costs!$C$6:$C$305,C24,Costs!$E$6:$E$305,"<>"),FIXED(E24-SUMIFS(Costs!$E$6:$E$305,Costs!$C$6:$C$305,C24,Costs!$M$6:$M$305,1)/COUNTIFS(Costs!$C$6:$C$305,C24,Costs!$M$6:$M$305,1),0)&" more than the cheapest"))) | M24: =IF(OR(C24="",E24=""),"",IF(COUNTIFS(Costs!$C$6:$C$305,C24,Costs!$E$6:$E$305,"<"&E24)=0,1,0)) | N24: =IF(AND(C24<>"",F24="Quote",COUNTIFS(Costs!$C$6:$C$305,C24,Costs!$F$6:$F$305,"Hired")+COUNTIFS(Costs!$C$6:$C$305,C24,Costs!$F$6:$F$305,"Bought")=0),1/COUNTIFS(Costs!$C$6:$C$305,C24,Costs!$F$6:$F$305,"Quote"),"") | O24: =IF(AND(OR(F24="Hired",F24="Bought"),N(I24)>0,H24<>""),H24+ROW()/100000,"")
B25: Exterior | C25: Fence repair | D25: Green Yard Services | E25: 1480 | F25: Quote | I25: =IF(OR(E25="",AND(F25<>"Hired",F25<>"Bought")),"",E25-N(G25)) | J25: =IF(C25&E25="","",IF(F25="","Choose a stage",IF(F25="Quote","",IF(E25="","Add the amount",IF(I25<=0,"Paid",IF(H25="","Balance due, no date set",IF(H25<TODAY(),"Overdue by "&(TODAY()-H25)&IF((TODAY()-H25)=1," day"," days"),IF(H25=TODAY(),"Due today",IF((H25-TODAY())<=14,"Due in "&(H25-TODAY())&IF((H25-TODAY())=1," day"," days"),"Next payment in "&(H25-TODAY())&" days"))))))))) | K25: =IF(OR(C25="",E25=""),"",IF(COUNTIFS(Costs!$C$6:$C$305,C25,Costs!$E$6:$E$305,"<>")<2,"",IF(M25=1,"Cheapest of "&COUNTIFS(Costs!$C$6:$C$305,C25,Costs!$E$6:$E$305,"<>"),FIXED(E25-SUMIFS(Costs!$E$6:$E$305,Costs!$C$6:$C$305,C25,Costs!$M$6:$M$305,1)/COUNTIFS(Costs!$C$6:$C$305,C25,Costs!$M$6:$M$305,1),0)&" more than the cheapest"))) | M25: =IF(OR(C25="",E25=""),"",IF(COUNTIFS(Costs!$C$6:$C$305,C25,Costs!$E$6:$E$305,"<"&E25)=0,1,0)) | N25: =IF(AND(C25<>"",F25="Quote",COUNTIFS(Costs!$C$6:$C$305,C25,Costs!$F$6:$F$305,"Hired")+COUNTIFS(Costs!$C$6:$C$305,C25,Costs!$F$6:$F$305,"Bought")=0),1/COUNTIFS(Costs!$C$6:$C$305,C25,Costs!$F$6:$F$305,"Quote"),"") | O25: =IF(AND(OR(F25="Hired",F25="Bought"),N(I25)>0,H25<>""),H25+ROW()/100000,"")
I26: =IF(OR(E26="",AND(F26<>"Hired",F26<>"Bought")),"",E26-N(G26)) | J26: =IF(C26&E26="","",IF(F26="","Choose a stage",IF(F26="Quote","",IF(E26="","Add the amount",IF(I26<=0,"Paid",IF(H26="","Balance due, no date set",IF(H26<TODAY(),"Overdue by "&(TODAY()-H26)&IF((TODAY()-H26)=1," day"," days"),IF(H26=TODAY(),"Due today",IF((H26-TODAY())<=14,"Due in "&(H26-TODAY())&IF((H26-TODAY())=1," day"," days"),"Next payment in "&(H26-TODAY())&" days"))))))))) | K26: =IF(OR(C26="",E26=""),"",IF(COUNTIFS(Costs!$C$6:$C$305,C26,Costs!$E$6:$E$305,"<>")<2,"",IF(M26=1,"Cheapest of "&COUNTIFS(Costs!$C$6:$C$305,C26,Costs!$E$6:$E$305,"<>"),FIXED(E26-SUMIFS(Costs!$E$6:$E$305,Costs!$C$6:$C$305,C26,Costs!$M$6:$M$305,1)/COUNTIFS(Costs!$C$6:$C$305,C26,Costs!$M$6:$M$305,1),0)&" more than the cheapest"))) | M26: =IF(OR(C26="",E26=""),"",IF(COUNTIFS(Costs!$C$6:$C$305,C26,Costs!$E$6:$E$305,"<"&E26)=0,1,0)) | N26: =IF(AND(C26<>"",F26="Quote",COUNTIFS(Costs!$C$6:$C$305,C26,Costs!$F$6:$F$305,"Hired")+COUNTIFS(Costs!$C$6:$C$305,C26,Costs!$F$6:$F$305,"Bought")=0),1/COUNTIFS(Costs!$C$6:$C$305,C26,Costs!$F$6:$F$305,"Quote"),"") | O26: =IF(AND(OR(F26="Hired",F26="Bought"),N(I26)>0,H26<>""),H26+ROW()/100000,"")
I27: =IF(OR(E27="",AND(F27<>"Hired",F27<>"Bought")),"",E27-N(G27)) | J27: =IF(C27&E27="","",IF(F27="","Choose a stage",IF(F27="Quote","",IF(E27="","Add the amount",IF(I27<=0,"Paid",IF(H27="","Balance due, no date set",IF(H27<TODAY(),"Overdue by "&(TODAY()-H27)&IF((TODAY()-H27)=1," day"," days"),IF(H27=TODAY(),"Due today",IF((H27-TODAY())<=14,"Due in "&(H27-TODAY())&IF((H27-TODAY())=1," day"," days"),"Next payment in "&(H27-TODAY())&" days"))))))))) | K27: =IF(OR(C27="",E27=""),"",IF(COUNTIFS(Costs!$C$6:$C$305,C27,Costs!$E$6:$E$305,"<>")<2,"",IF(M27=1,"Cheapest of "&COUNTIFS(Costs!$C$6:$C$305,C27,Costs!$E$6:$E$305,"<>"),FIXED(E27-SUMIFS(Costs!$E$6:$E$305,Costs!$C$6:$C$305,C27,Costs!$M$6:$M$305,1)/COUNTIFS(Costs!$C$6:$C$305,C27,Costs!$M$6:$M$305,1),0)&" more than the cheapest"))) | M27: =IF(OR(C27="",E27=""),"",IF(COUNTIFS(Costs!$C$6:$C$305,C27,Costs!$E$6:$E$305,"<"&E27)=0,1,0)) | N27: =IF(AND(C27<>"",F27="Quote",COUNTIFS(Costs!$C$6:$C$305,C27,Costs!$F$6:$F$305,"Hired")+COUNTIFS(Costs!$C$6:$C$305,C27,Costs!$F$6:$F$305,"Bought")=0),1/COUNTIFS(Costs!$C$6:$C$305,C27,Costs!$F$6:$F$305,"Quote"),"") | O27: =IF(AND(OR(F27="Hired",F27="Bought"),N(I27)>0,H27<>""),H27+ROW()/100000,"")
I28: =IF(OR(E28="",AND(F28<>"Hired",F28<>"Bought")),"",E28-N(G28)) | J28: =IF(C28&E28="","",IF(F28="","Choose a stage",IF(F28="Quote","",IF(E28="","Add the amount",IF(I28<=0,"Paid",IF(H28="","Balance due, no date set",IF(H28<TODAY(),"Overdue by "&(TODAY()-H28)&IF((TODAY()-H28)=1," day"," days"),IF(H28=TODAY(),"Due today",IF((H28-TODAY())<=14,"Due in "&(H28-TODAY())&IF((H28-TODAY())=1," day"," days"),"Next payment in "&(H28-TODAY())&" days"))))))))) | K28: =IF(OR(C28="",E28=""),"",IF(COUNTIFS(Costs!$C$6:$C$305,C28,Costs!$E$6:$E$305,"<>")<2,"",IF(M28=1,"Cheapest of "&COUNTIFS(Costs!$C$6:$C$305,C28,Costs!$E$6:$E$305,"<>"),FIXED(E28-SUMIFS(Costs!$E$6:$E$305,Costs!$C$6:$C$305,C28,Costs!$M$6:$M$305,1)/COUNTIFS(Costs!$C$6:$C$305,C28,Costs!$M$6:$M$305,1),0)&" more than the cheapest"))) | M28: =IF(OR(C28="",E28=""),"",IF(COUNTIFS(Costs!$C$6:$C$305,C28,Costs!$E$6:$E$305,"<"&E28)=0,1,0)) | N28: =IF(AND(C28<>"",F28="Quote",COUNTIFS(Costs!$C$6:$C$305,C28,Costs!$F$6:$F$305,"Hired")+COUNTIFS(Costs!$C$6:$C$305,C28,Costs!$F$6:$F$305,"Bought")=0),1/COUNTIFS(Costs!$C$6:$C$305,C28,Costs!$F$6:$F$305,"Quote"),"") | O28: =IF(AND(OR(F28="Hired",F28="Bought"),N(I28)>0,H28<>""),H28+ROW()/100000,"")
I29: =IF(OR(E29="",AND(F29<>"Hired",F29<>"Bought")),"",E29-N(G29)) | J29: =IF(C29&E29="","",IF(F29="","Choose a stage",IF(F29="Quote","",IF(E29="","Add the amount",IF(I29<=0,"Paid",IF(H29="","Balance due, no date set",IF(H29<TODAY(),"Overdue by "&(TODAY()-H29)&IF((TODAY()-H29)=1," day"," days"),IF(H29=TODAY(),"Due today",IF((H29-TODAY())<=14,"Due in "&(H29-TODAY())&IF((H29-TODAY())=1," day"," days"),"Next payment in "&(H29-TODAY())&" days"))))))))) | K29: =IF(OR(C29="",E29=""),"",IF(COUNTIFS(Costs!$C$6:$C$305,C29,Costs!$E$6:$E$305,"<>")<2,"",IF(M29=1,"Cheapest of "&COUNTIFS(Costs!$C$6:$C$305,C29,Costs!$E$6:$E$305,"<>"),FIXED(E29-SUMIFS(Costs!$E$6:$E$305,Costs!$C$6:$C$305,C29,Costs!$M$6:$M$305,1)/COUNTIFS(Costs!$C$6:$C$305,C29,Costs!$M$6:$M$305,1),0)&" more than the cheapest"))) | M29: =IF(OR(C29="",E29=""),"",IF(COUNTIFS(Costs!$C$6:$C$305,C29,Costs!$E$6:$E$305,"<"&E29)=0,1,0)) | N29: =IF(AND(C29<>"",F29="Quote",COUNTIFS(Costs!$C$6:$C$305,C29,Costs!$F$6:$F$305,"Hired")+COUNTIFS(Costs!$C$6:$C$305,C29,Costs!$F$6:$F$305,"Bought")=0),1/COUNTIFS(Costs!$C$6:$C$305,C29,Costs!$F$6:$F$305,"Quote"),"") | O29: =IF(AND(OR(F29="Hired",F29="Bought"),N(I29)>0,H29<>""),H29+ROW()/100000,"")
I30: =IF(OR(E30="",AND(F30<>"Hired",F30<>"Bought")),"",E30-N(G30)) | J30: =IF(C30&E30="","",IF(F30="","Choose a stage",IF(F30="Quote","",IF(E30="","Add the amount",IF(I30<=0,"Paid",IF(H30="","Balance due, no date set",IF(H30<TODAY(),"Overdue by "&(TODAY()-H30)&IF((TODAY()-H30)=1," day"," days"),IF(H30=TODAY(),"Due today",IF((H30-TODAY())<=14,"Due in "&(H30-TODAY())&IF((H30-TODAY())=1," day"," days"),"Next payment in "&(H30-TODAY())&" days"))))))))) | K30: =IF(OR(C30="",E30=""),"",IF(COUNTIFS(Costs!$C$6:$C$305,C30,Costs!$E$6:$E$305,"<>")<2,"",IF(M30=1,"Cheapest of "&COUNTIFS(Costs!$C$6:$C$305,C30,Costs!$E$6:$E$305,"<>"),FIXED(E30-SUMIFS(Costs!$E$6:$E$305,Costs!$C$6:$C$305,C30,Costs!$M$6:$M$305,1)/COUNTIFS(Costs!$C$6:$C$305,C30,Costs!$M$6:$M$305,1),0)&" more than the cheapest"))) | M30: =IF(OR(C30="",E30=""),"",IF(COUNTIFS(Costs!$C$6:$C$305,C30,Costs!$E$6:$E$305,"<"&E30)=0,1,0)) | N30: =IF(AND(C30<>"",F30="Quote",COUNTIFS(Costs!$C$6:$C$305,C30,Costs!$F$6:$F$305,"Hired")+COUNTIFS(Costs!$C$6:$C$305,C30,Costs!$F$6:$F$305,"Bought")=0),1/COUNTIFS(Costs!$C$6:$C$305,C30,Costs!$F$6:$F$305,"Quote"),"") | O30: =IF(AND(OR(F30="Hired",F30="Bought"),N(I30)>0,H30<>""),H30+ROW()/100000,"")
I31: =IF(OR(E31="",AND(F31<>"Hired",F31<>"Bought")),"",E31-N(G31)) | J31: =IF(C31&E31="","",IF(F31="","Choose a stage",IF(F31="Quote","",IF(E31="","Add the amount",IF(I31<=0,"Paid",IF(H31="","Balance due, no date set",IF(H31<TODAY(),"Overdue by "&(TODAY()-H31)&IF((TODAY()-H31)=1," day"," days"),IF(H31=TODAY(),"Due today",IF((H31-TODAY())<=14,"Due in "&(H31-TODAY())&IF((H31-TODAY())=1," day"," days"),"Next payment in "&(H31-TODAY())&" days"))))))))) | K31: =IF(OR(C31="",E31=""),"",IF(COUNTIFS(Costs!$C$6:$C$305,C31,Costs!$E$6:$E$305,"<>")<2,"",IF(M31=1,"Cheapest of "&COUNTIFS(Costs!$C$6:$C$305,C31,Costs!$E$6:$E$305,"<>"),FIXED(E31-SUMIFS(Costs!$E$6:$E$305,Costs!$C$6:$C$305,C31,Costs!$M$6:$M$305,1)/COUNTIFS(Costs!$C$6:$C$305,C31,Costs!$M$6:$M$305,1),0)&" more than the cheapest"))) | M31: =IF(OR(C31="",E31=""),"",IF(COUNTIFS(Costs!$C$6:$C$305,C31,Costs!$E$6:$E$305,"<"&E31)=0,1,0)) | N31: =IF(AND(C31<>"",F31="Quote",COUNTIFS(Costs!$C$6:$C$305,C31,Costs!$F$6:$F$305,"Hired")+COUNTIFS(Costs!$C$6:$C$305,C31,Costs!$F$6:$F$305,"Bought")=0),1/COUNTIFS(Costs!$C$6:$C$305,C31,Costs!$F$6:$F$305,"Quote"),"") | O31: =IF(AND(OR(F31="Hired",F31="Bought"),N(I31)>0,H31<>""),H31+ROW()/100000,"")
I32: =IF(OR(E32="",AND(F32<>"Hired",F32<>"Bought")),"",E32-N(G32)) | J32: =IF(C32&E32="","",IF(F32="","Choose a stage",IF(F32="Quote","",IF(E32="","Add the amount",IF(I32<=0,"Paid",IF(H32="","Balance due, no date set",IF(H32<TODAY(),"Overdue by "&(TODAY()-H32)&IF((TODAY()-H32)=1," day"," days"),IF(H32=TODAY(),"Due today",IF((H32-TODAY())<=14,"Due in "&(H32-TODAY())&IF((H32-TODAY())=1," day"," days"),"Next payment in "&(H32-TODAY())&" days"))))))))) | K32: =IF(OR(C32="",E32=""),"",IF(COUNTIFS(Costs!$C$6:$C$305,C32,Costs!$E$6:$E$305,"<>")<2,"",IF(M32=1,"Cheapest of "&COUNTIFS(Costs!$C$6:$C$305,C32,Costs!$E$6:$E$305,"<>"),FIXED(E32-SUMIFS(Costs!$E$6:$E$305,Costs!$C$6:$C$305,C32,Costs!$M$6:$M$305,1)/COUNTIFS(Costs!$C$6:$C$305,C32,Costs!$M$6:$M$305,1),0)&" more than the cheapest"))) | M32: =IF(OR(C32="",E32=""),"",IF(COUNTIFS(Costs!$C$6:$C$305,C32,Costs!$E$6:$E$305,"<"&E32)=0,1,0)) | N32: =IF(AND(C32<>"",F32="Quote",COUNTIFS(Costs!$C$6:$C$305,C32,Costs!$F$6:$F$305,"Hired")+COUNTIFS(Costs!$C$6:$C$305,C32,Costs!$F$6:$F$305,"Bought")=0),1/COUNTIFS(Costs!$C$6:$C$305,C32,Costs!$F$6:$F$305,"Quote"),"") | O32: =IF(AND(OR(F32="Hired",F32="Bought"),N(I32)>0,H32<>""),H32+ROW()/100000,"")
I33: =IF(OR(E33="",AND(F33<>"Hired",F33<>"Bought")),"",E33-N(G33)) | J33: =IF(C33&E33="","",IF(F33="","Choose a stage",IF(F33="Quote","",IF(E33="","Add the amount",IF(I33<=0,"Paid",IF(H33="","Balance due, no date set",IF(H33<TODAY(),"Overdue by "&(TODAY()-H33)&IF((TODAY()-H33)=1," day"," days"),IF(H33=TODAY(),"Due today",IF((H33-TODAY())<=14,"Due in "&(H33-TODAY())&IF((H33-TODAY())=1," day"," days"),"Next payment in "&(H33-TODAY())&" days"))))))))) | K33: =IF(OR(C33="",E33=""),"",IF(COUNTIFS(Costs!$C$6:$C$305,C33,Costs!$E$6:$E$305,"<>")<2,"",IF(M33=1,"Cheapest of "&COUNTIFS(Costs!$C$6:$C$305,C33,Costs!$E$6:$E$305,"<>"),FIXED(E33-SUMIFS(Costs!$E$6:$E$305,Costs!$C$6:$C$305,C33,Costs!$M$6:$M$305,1)/COUNTIFS(Costs!$C$6:$C$305,C33,Costs!$M$6:$M$305,1),0)&" more than the cheapest"))) | M33: =IF(OR(C33="",E33=""),"",IF(COUNTIFS(Costs!$C$6:$C$305,C33,Costs!$E$6:$E$305,"<"&E33)=0,1,0)) | N33: =IF(AND(C33<>"",F33="Quote",COUNTIFS(Costs!$C$6:$C$305,C33,Costs!$F$6:$F$305,"Hired")+COUNTIFS(Costs!$C$6:$C$305,C33,Costs!$F$6:$F$305,"Bought")=0),1/COUNTIFS(Costs!$C$6:$C$305,C33,Costs!$F$6:$F$305,"Quote"),"") | O33: =IF(AND(OR(F33="Hired",F33="Bought"),N(I33)>0,H33<>""),H33+ROW()/100000,"")
I34: =IF(OR(E34="",AND(F34<>"Hired",F34<>"Bought")),"",E34-N(G34)) | J34: =IF(C34&E34="","",IF(F34="","Choose a stage",IF(F34="Quote","",IF(E34="","Add the amount",IF(I34<=0,"Paid",IF(H34="","Balance due, no date set",IF(H34<TODAY(),"Overdue by "&(TODAY()-H34)&IF((TODAY()-H34)=1," day"," days"),IF(H34=TODAY(),"Due today",IF((H34-TODAY())<=14,"Due in "&(H34-TODAY())&IF((H34-TODAY())=1," day"," days"),"Next payment in "&(H34-TODAY())&" days"))))))))) | K34: =IF(OR(C34="",E34=""),"",IF(COUNTIFS(Costs!$C$6:$C$305,C34,Costs!$E$6:$E$305,"<>")<2,"",IF(M34=1,"Cheapest of "&COUNTIFS(Costs!$C$6:$C$305,C34,Costs!$E$6:$E$305,"<>"),FIXED(E34-SUMIFS(Costs!$E$6:$E$305,Costs!$C$6:$C$305,C34,Costs!$M$6:$M$305,1)/COUNTIFS(Costs!$C$6:$C$305,C34,Costs!$M$6:$M$305,1),0)&" more than the cheapest"))) | M34: =IF(OR(C34="",E34=""),"",IF(COUNTIFS(Costs!$C$6:$C$305,C34,Costs!$E$6:$E$305,"<"&E34)=0,1,0)) | N34: =IF(AND(C34<>"",F34="Quote",COUNTIFS(Costs!$C$6:$C$305,C34,Costs!$F$6:$F$305,"Hired")+COUNTIFS(Costs!$C$6:$C$305,C34,Costs!$F$6:$F$305,"Bought")=0),1/COUNTIFS(Costs!$C$6:$C$305,C34,Costs!$F$6:$F$305,"Quote"),"") | O34: =IF(AND(OR(F34="Hired",F34="Bought"),N(I34)>0,H34<>""),H34+ROW()/100000,"")
I35: =IF(OR(E35="",AND(F35<>"Hired",F35<>"Bought")),"",E35-N(G35)) | J35: =IF(C35&E35="","",IF(F35="","Choose a stage",IF(F35="Quote","",IF(E35="","Add the amount",IF(I35<=0,"Paid",IF(H35="","Balance due, no date set",IF(H35<TODAY(),"Overdue by "&(TODAY()-H35)&IF((TODAY()-H35)=1," day"," days"),IF(H35=TODAY(),"Due today",IF((H35-TODAY())<=14,"Due in "&(H35-TODAY())&IF((H35-TODAY())=1," day"," days"),"Next payment in "&(H35-TODAY())&" days"))))))))) | K35: =IF(OR(C35="",E35=""),"",IF(COUNTIFS(Costs!$C$6:$C$305,C35,Costs!$E$6:$E$305,"<>")<2,"",IF(M35=1,"Cheapest of "&COUNTIFS(Costs!$C$6:$C$305,C35,Costs!$E$6:$E$305,"<>"),FIXED(E35-SUMIFS(Costs!$E$6:$E$305,Costs!$C$6:$C$305,C35,Costs!$M$6:$M$305,1)/COUNTIFS(Costs!$C$6:$C$305,C35,Costs!$M$6:$M$305,1),0)&" more than the cheapest"))) | M35: =IF(OR(C35="",E35=""),"",IF(COUNTIFS(Costs!$C$6:$C$305,C35,Costs!$E$6:$E$305,"<"&E35)=0,1,0)) | N35: =IF(AND(C35<>"",F35="Quote",COUNTIFS(Costs!$C$6:$C$305,C35,Costs!$F$6:$F$305,"Hired")+COUNTIFS(Costs!$C$6:$C$305,C35,Costs!$F$6:$F$305,"Bought")=0),1/COUNTIFS(Costs!$C$6:$C$305,C35,Costs!$F$6:$F$305,"Quote"),"") | O35: =IF(AND(OR(F35="Hired",F35="Bought"),N(I35)>0,H35<>""),H35+ROW()/100000,"")
I36: =IF(OR(E36="",AND(F36<>"Hired",F36<>"Bought")),"",E36-N(G36)) | J36: =IF(C36&E36="","",IF(F36="","Choose a stage",IF(F36="Quote","",IF(E36="","Add the amount",IF(I36<=0,"Paid",IF(H36="","Balance due, no date set",IF(H36<TODAY(),"Overdue by "&(TODAY()-H36)&IF((TODAY()-H36)=1," day"," days"),IF(H36=TODAY(),"Due today",IF((H36-TODAY())<=14,"Due in "&(H36-TODAY())&IF((H36-TODAY())=1," day"," days"),"Next payment in "&(H36-TODAY())&" days"))))))))) | K36: =IF(OR(C36="",E36=""),"",IF(COUNTIFS(Costs!$C$6:$C$305,C36,Costs!$E$6:$E$305,"<>")<2,"",IF(M36=1,"Cheapest of "&COUNTIFS(Costs!$C$6:$C$305,C36,Costs!$E$6:$E$305,"<>"),FIXED(E36-SUMIFS(Costs!$E$6:$E$305,Costs!$C$6:$C$305,C36,Costs!$M$6:$M$305,1)/COUNTIFS(Costs!$C$6:$C$305,C36,Costs!$M$6:$M$305,1),0)&" more than the cheapest"))) | M36: =IF(OR(C36="",E36=""),"",IF(COUNTIFS(Costs!$C$6:$C$305,C36,Costs!$E$6:$E$305,"<"&E36)=0,1,0)) | N36: =IF(AND(C36<>"",F36="Quote",COUNTIFS(Costs!$C$6:$C$305,C36,Costs!$F$6:$F$305,"Hired")+COUNTIFS(Costs!$C$6:$C$305,C36,Costs!$F$6:$F$305,"Bought")=0),1/COUNTIFS(Costs!$C$6:$C$305,C36,Costs!$F$6:$F$305,"Quote"),"") | O36: =IF(AND(OR(F36="Hired",F36="Bought"),N(I36)>0,H36<>""),H36+ROW()/100000,"")
I37: =IF(OR(E37="",AND(F37<>"Hired",F37<>"Bought")),"",E37-N(G37)) | J37: =IF(C37&E37="","",IF(F37="","Choose a stage",IF(F37="Quote","",IF(E37="","Add the amount",IF(I37<=0,"Paid",IF(H37="","Balance due, no date set",IF(H37<TODAY(),"Overdue by "&(TODAY()-H37)&IF((TODAY()-H37)=1," day"," days"),IF(H37=TODAY(),"Due today",IF((H37-TODAY())<=14,"Due in "&(H37-TODAY())&IF((H37-TODAY())=1," day"," days"),"Next payment in "&(H37-TODAY())&" days"))))))))) | K37: =IF(OR(C37="",E37=""),"",IF(COUNTIFS(Costs!$C$6:$C$305,C37,Costs!$E$6:$E$305,"<>")<2,"",IF(M37=1,"Cheapest of "&COUNTIFS(Costs!$C$6:$C$305,C37,Costs!$E$6:$E$305,"<>"),FIXED(E37-SUMIFS(Costs!$E$6:$E$305,Costs!$C$6:$C$305,C37,Costs!$M$6:$M$305,1)/COUNTIFS(Costs!$C$6:$C$305,C37,Costs!$M$6:$M$305,1),0)&" more than the cheapest"))) | M37: =IF(OR(C37="",E37=""),"",IF(COUNTIFS(Costs!$C$6:$C$305,C37,Costs!$E$6:$E$305,"<"&E37)=0,1,0)) | N37: =IF(AND(C37<>"",F37="Quote",COUNTIFS(Costs!$C$6:$C$305,C37,Costs!$F$6:$F$305,"Hired")+COUNTIFS(Costs!$C$6:$C$305,C37,Costs!$F$6:$F$305,"Bought")=0),1/COUNTIFS(Costs!$C$6:$C$305,C37,Costs!$F$6:$F$305,"Quote"),"") | O37: =IF(AND(OR(F37="Hired",F37="Bought"),N(I37)>0,H37<>""),H37+ROW()/100000,"")
... I305: =IF(OR(E305="",AND(F305<>"Hired",F305<>"Bought")),"",E305-N(G305)) | J305: =IF(C305&E305="","",IF(F305="","Choose a stage",IF(F305="Quote","",IF(E305="","Add the amount",IF(I305<=0,"Paid",IF(H305="","Balance due, no date set",IF(H305<TODAY(),"Overdue by "&(TODAY()-H305)&IF((TODAY()-H305)=1," day"," days"),IF(H305=TODAY(),"Due today",IF((H305-TODAY())<=14,"Due in "&(H305-TODAY())&IF((H305-TODAY())=1," day"," days"),"Next payment in "&(H305-TODAY())&" days"))))))))) | K305: =IF(OR(C305="",E305=""),"",IF(COUNTIFS(Costs!$C$6:$C$305,C305,Costs!$E$6:$E$305,"<>")<2,"",IF(M305=1,"Cheapest of "&COUNTIFS(Costs!$C$6:$C$305,C305,Costs!$E$6:$E$305,"<>"),FIXED(E305-SUMIFS(Costs!$E$6:$E$305,Costs!$C$6:$C$305,C305,Costs!$M$6:$M$305,1)/COUNTIFS(Costs!$C$6:$C$305,C305,Costs!$M$6:$M$305,1),0)&" more than the cheapest"))) | M305: =IF(OR(C305="",E305=""),"",IF(COUNTIFS(Costs!$C$6:$C$305,C305,Costs!$E$6:$E$305,"<"&E305)=0,1,0)) | N305: =IF(AND(C305<>"",F305="Quote",COUNTIFS(Costs!$C$6:$C$305,C305,Costs!$F$6:$F$305,"Hired")+COUNTIFS(Costs!$C$6:$C$305,C305,Costs!$F$6:$F$305,"Bought")=0),1/COUNTIFS(Costs!$C$6:$C$305,C305,Costs!$F$6:$F$305,"Quote"),"") | O305: =IF(AND(OR(F305="Hired",F305="Bought"),N(I305)>0,H305<>""),H305+ROW()/100000,"")

Sheet Timeline
B2: Timeline
B3: One line per task. The coloured bars follow the start and end dates, one column per week.
B4: Project start | C4: 46265
B5: Task | C5: Room | D5: Who | E5: Start | F5: End | G5: Status | H5: =$C$4-WEEKDAY($C$4,3) | I5: =H5+7 | J5: =I5+7 | K5: =J5+7 | L5: =K5+7 | M5: =L5+7 | N5: =M5+7 | O5: =N5+7 | P5: =O5+7 | ... W5: =V5+7
B6: Demolition | C6: Whole house | D6: Us | E6: 46269 | F6: 46273 | G6: Done
B7: Partial rewire | C7: Whole house | D7: Spark Electrical | E7: 46274 | F7: 46283 | G7: Done
B8: Kitchen electrics | C8: Kitchen | D8: Spark Electrical | E8: 46284 | F8: 46288 | G8: Done
B9: Bathroom remodel | C9: Bathroom | D9: Blue Tap Plumbing | E9: 46287 | F9: 46305 | G9: In progress
B10: Cabinets and fitting | C10: Kitchen | D10: Riverside Cabinet Co | E10: 46291 | F10: 46302 | G10: In progress
B11: Drywall repair in the hall | C11: Whole house | D11: Handyman | E11: 46289 | F11: 46296 | G11: Delayed
B12: Quartz countertops | C12: Kitchen | D12: Stone Works | E12: 46303 | F12: 46309 | G12: Planned
