Workbook

Sheet Dashboard
N1: =IFERROR(INDEX(Paychecks!$E$6:$E$58,MATCH($C$4,Paychecks!$B$6:$B$58,0)),"")
B2: Paycheck budget | N2: =MATCH($C$4,Paychecks!$B$6:$B$58,0)
B3: Pick a paycheck to see the bills it covers and what is left to spend.
B4: Paycheck of | C4: =IF(COUNTIF(Paychecks!$B$6:$B$58,"<="&TODAY())=0,INDEX(Paychecks!$B$6:$B$58,1),INDEX(Paychecks!$B$6:$B$58,COUNTIF(Paychecks!$B$6:$B$58,"<="&TODAY()))) | D4: The paycheck you are on today is picked for you. Choose another date to plan ahead.
B6: Paycheck | C6: Bills to pay from it | D6: Savings | E6: Days | F6: Left to spend | G6: Per day | I6: This paycheck
B7: =IFERROR(INDEX(Paychecks!$C$6:$C$58,$N$2),"") | C7: =IFERROR(INDEX(Paychecks!$F$6:$F$58,$N$2),"") | D7: =IFERROR(INDEX(Paychecks!$G$6:$G$58,$N$2),"") | E7: =IFERROR(INDEX(Paychecks!$I$6:$I$58,$N$2),"") | F7: =IFERROR(INDEX(Paychecks!$H$6:$H$58,$N$2),"") | G7: =IFERROR(INDEX(Paychecks!$J$6:$J$58,$N$2),"") | I7: =IFERROR(INDEX(Paychecks!$K$6:$K$58,$N$2),"")
B9: Due | C9: Bill | D9: Amount | E9: Autopay | F9: Category | I9: The 12 months | J9: Total
B10: =IF($M10="","",INT($M10)) | C10: =IF($M10="","",INDEX(Bills!$B$6:$B$55,MATCH($M10,Bills!$AK$6:$AK$55,0))) | D10: =IF($M10="","",INDEX(Bills!$C$6:$C$55,MATCH($M10,Bills!$AK$6:$AK$55,0))) | E10: =IF($M10="","",INDEX(Bills!$G$6:$G$55,MATCH($M10,Bills!$AK$6:$AK$55,0))) | F10: =IF($M10="","",INDEX(Bills!$F$6:$F$55,MATCH($M10,Bills!$AK$6:$AK$55,0))) | I10: Paychecks | J10: =COUNTIFS(Paychecks!$B$6:$B$58,">0") | M10: =IFERROR(SMALL(Bills!$AK$6:$AK$55,1),"")
B11: =IF($M11="","",INT($M11)) | C11: =IF($M11="","",INDEX(Bills!$B$6:$B$55,MATCH($M11,Bills!$AK$6:$AK$55,0))) | D11: =IF($M11="","",INDEX(Bills!$C$6:$C$55,MATCH($M11,Bills!$AK$6:$AK$55,0))) | E11: =IF($M11="","",INDEX(Bills!$G$6:$G$55,MATCH($M11,Bills!$AK$6:$AK$55,0))) | F11: =IF($M11="","",INDEX(Bills!$F$6:$F$55,MATCH($M11,Bills!$AK$6:$AK$55,0))) | I11: Income | J11: =SUM(Paychecks!$C$6:$C$58) | M11: =IFERROR(SMALL(Bills!$AK$6:$AK$55,2),"")
B12: =IF($M12="","",INT($M12)) | C12: =IF($M12="","",INDEX(Bills!$B$6:$B$55,MATCH($M12,Bills!$AK$6:$AK$55,0))) | D12: =IF($M12="","",INDEX(Bills!$C$6:$C$55,MATCH($M12,Bills!$AK$6:$AK$55,0))) | E12: =IF($M12="","",INDEX(Bills!$G$6:$G$55,MATCH($M12,Bills!$AK$6:$AK$55,0))) | F12: =IF($M12="","",INDEX(Bills!$F$6:$F$55,MATCH($M12,Bills!$AK$6:$AK$55,0))) | I12: Bills | J12: =SUM(Paychecks!$F$6:$F$58) | M12: =IFERROR(SMALL(Bills!$AK$6:$AK$55,3),"")
B13: =IF($M13="","",INT($M13)) | C13: =IF($M13="","",INDEX(Bills!$B$6:$B$55,MATCH($M13,Bills!$AK$6:$AK$55,0))) | D13: =IF($M13="","",INDEX(Bills!$C$6:$C$55,MATCH($M13,Bills!$AK$6:$AK$55,0))) | E13: =IF($M13="","",INDEX(Bills!$G$6:$G$55,MATCH($M13,Bills!$AK$6:$AK$55,0))) | F13: =IF($M13="","",INDEX(Bills!$F$6:$F$55,MATCH($M13,Bills!$AK$6:$AK$55,0))) | I13: Savings | J13: =SUM(Paychecks!$G$6:$G$58) | M13: =IFERROR(SMALL(Bills!$AK$6:$AK$55,4),"")
B14: =IF($M14="","",INT($M14)) | C14: =IF($M14="","",INDEX(Bills!$B$6:$B$55,MATCH($M14,Bills!$AK$6:$AK$55,0))) | D14: =IF($M14="","",INDEX(Bills!$C$6:$C$55,MATCH($M14,Bills!$AK$6:$AK$55,0))) | E14: =IF($M14="","",INDEX(Bills!$G$6:$G$55,MATCH($M14,Bills!$AK$6:$AK$55,0))) | F14: =IF($M14="","",INDEX(Bills!$F$6:$F$55,MATCH($M14,Bills!$AK$6:$AK$55,0))) | I14: Left to spend | J14: =SUM(Paychecks!$H$6:$H$58) | M14: =IFERROR(SMALL(Bills!$AK$6:$AK$55,5),"")
B15: =IF($M15="","",INT($M15)) | C15: =IF($M15="","",INDEX(Bills!$B$6:$B$55,MATCH($M15,Bills!$AK$6:$AK$55,0))) | D15: =IF($M15="","",INDEX(Bills!$C$6:$C$55,MATCH($M15,Bills!$AK$6:$AK$55,0))) | E15: =IF($M15="","",INDEX(Bills!$G$6:$G$55,MATCH($M15,Bills!$AK$6:$AK$55,0))) | F15: =IF($M15="","",INDEX(Bills!$F$6:$F$55,MATCH($M15,Bills!$AK$6:$AK$55,0))) | I15: Tight paychecks | J15: =COUNTIFS(Paychecks!$K$6:$K$58,"Tight") | M15: =IFERROR(SMALL(Bills!$AK$6:$AK$55,6),"")
B16: =IF($M16="","",INT($M16)) | C16: =IF($M16="","",INDEX(Bills!$B$6:$B$55,MATCH($M16,Bills!$AK$6:$AK$55,0))) | D16: =IF($M16="","",INDEX(Bills!$C$6:$C$55,MATCH($M16,Bills!$AK$6:$AK$55,0))) | E16: =IF($M16="","",INDEX(Bills!$G$6:$G$55,MATCH($M16,Bills!$AK$6:$AK$55,0))) | F16: =IF($M16="","",INDEX(Bills!$F$6:$F$55,MATCH($M16,Bills!$AK$6:$AK$55,0))) | I16: Short paychecks | J16: =COUNTIFS(Paychecks!$K$6:$K$58,"Short*") | M16: =IFERROR(SMALL(Bills!$AK$6:$AK$55,7),"")
B17: =IF($M17="","",INT($M17)) | C17: =IF($M17="","",INDEX(Bills!$B$6:$B$55,MATCH($M17,Bills!$AK$6:$AK$55,0))) | D17: =IF($M17="","",INDEX(Bills!$C$6:$C$55,MATCH($M17,Bills!$AK$6:$AK$55,0))) | E17: =IF($M17="","",INDEX(Bills!$G$6:$G$55,MATCH($M17,Bills!$AK$6:$AK$55,0))) | F17: =IF($M17="","",INDEX(Bills!$F$6:$F$55,MATCH($M17,Bills!$AK$6:$AK$55,0))) | M17: =IFERROR(SMALL(Bills!$AK$6:$AK$55,8),"")
B18: =IF($M18="","",INT($M18)) | C18: =IF($M18="","",INDEX(Bills!$B$6:$B$55,MATCH($M18,Bills!$AK$6:$AK$55,0))) | D18: =IF($M18="","",INDEX(Bills!$C$6:$C$55,MATCH($M18,Bills!$AK$6:$AK$55,0))) | E18: =IF($M18="","",INDEX(Bills!$G$6:$G$55,MATCH($M18,Bills!$AK$6:$AK$55,0))) | F18: =IF($M18="","",INDEX(Bills!$F$6:$F$55,MATCH($M18,Bills!$AK$6:$AK$55,0))) | I18: =IF(COUNTIFS(Paychecks!$B$6:$B$58,">"&TODAY(),Paychecks!$K$6:$K$58,"Tight")+COUNTIFS(Paychecks!$B$6:$B$58,">"&TODAY(),Paychecks!$K$6:$K$58,"Short*")=0,"No tight or short paychecks ahead",COUNTIFS(Paychecks!$B$6:$B$58,">"&TODAY(),Paychecks!$K$6:$K$58,"Tight")+COUNTIFS(Paychecks!$B$6:$B$58,">"&TODAY(),Paychecks!$K$6:$K$58,"Short*")&IF(COUNTIFS(Paychecks!$B$6:$B$58,">"&TODAY(),Paychecks!$K$6:$K$58,"Tight")+COUNTIFS(Paychecks!$B$6:$B$58,">"&TODAY(),Paychecks!$K$6:$K$58,"Short*")=1," paycheck ahead is"," paychecks ahead are")&" tight or short. The Paychecks tab shows which.") | M18: =IFERROR(SMALL(Bills!$AK$6:$AK$55,9),"")
B19: =IF($M19="","",INT($M19)) | C19: =IF($M19="","",INDEX(Bills!$B$6:$B$55,MATCH($M19,Bills!$AK$6:$AK$55,0))) | D19: =IF($M19="","",INDEX(Bills!$C$6:$C$55,MATCH($M19,Bills!$AK$6:$AK$55,0))) | E19: =IF($M19="","",INDEX(Bills!$G$6:$G$55,MATCH($M19,Bills!$AK$6:$AK$55,0))) | F19: =IF($M19="","",INDEX(Bills!$F$6:$F$55,MATCH($M19,Bills!$AK$6:$AK$55,0))) | M19: =IFERROR(SMALL(Bills!$AK$6:$AK$55,10),"")
B20: =IF($M20="","",INT($M20)) | C20: =IF($M20="","",INDEX(Bills!$B$6:$B$55,MATCH($M20,Bills!$AK$6:$AK$55,0))) | D20: =IF($M20="","",INDEX(Bills!$C$6:$C$55,MATCH($M20,Bills!$AK$6:$AK$55,0))) | E20: =IF($M20="","",INDEX(Bills!$G$6:$G$55,MATCH($M20,Bills!$AK$6:$AK$55,0))) | F20: =IF($M20="","",INDEX(Bills!$F$6:$F$55,MATCH($M20,Bills!$AK$6:$AK$55,0))) | M20: =IFERROR(SMALL(Bills!$AK$6:$AK$55,11),"")
B21: =IF($M21="","",INT($M21)) | C21: =IF($M21="","",INDEX(Bills!$B$6:$B$55,MATCH($M21,Bills!$AK$6:$AK$55,0))) | D21: =IF($M21="","",INDEX(Bills!$C$6:$C$55,MATCH($M21,Bills!$AK$6:$AK$55,0))) | E21: =IF($M21="","",INDEX(Bills!$G$6:$G$55,MATCH($M21,Bills!$AK$6:$AK$55,0))) | F21: =IF($M21="","",INDEX(Bills!$F$6:$F$55,MATCH($M21,Bills!$AK$6:$AK$55,0))) | M21: =IFERROR(SMALL(Bills!$AK$6:$AK$55,12),"")
B22: =IF($N$1="","","The next payday comes "&E7&" days after this one.")

Sheet Settings
B2: Settings
B3: How you are paid. The Paychecks tab lists your paydays from these.
B5: How often you are paid | C5: Every 2 weeks | E5: Weekly, every 2 weeks, twice a month or monthly
B6: First payday | C6: 46024 | E6: The first payday of the 12 months you want to plan
B7: Second payday of the month | C7: 15 | E7: Only for twice a month: the day of the second payday
B8: Usual paycheck | C8: 1850 | E8: What you usually receive, after tax
B9: Savings from each paycheck | C9: 150 | E9: Moved to savings before you spend
B10: Tight when less than this per day | C10: 20 | E10: A paycheck turns orange below this amount per day

Sheet Bills
B2: Bills
B3: Each bill once, with the day of the month it is due. Each one goes on the paycheck before it.
B5: Bill | C5: Amount | D5: Due day | E5: Only in month | F5: Category | G5: Autopay? | H5: Note
B6: Rent | C6: 1200 | D6: 1 | F6: Housing | G6: No | J6: =IF(OR(B6="",D6=""),"",DATE(YEAR(Settings!$C$6),MONTH(Settings!$C$6)+0,MIN(D6,DAY(EOMONTH(DATE(YEAR(Settings!$C$6),MONTH(Settings!$C$6)+0,1),0))))) | K6: =IF(OR(B6="",D6=""),"",DATE(YEAR(Settings!$C$6),MONTH(Settings!$C$6)+1,MIN(D6,DAY(EOMONTH(DATE(YEAR(Settings!$C$6),MONTH(Settings!$C$6)+1,1),0))))) | L6: =IF(OR(B6="",D6=""),"",DATE(YEAR(Settings!$C$6),MONTH(Settings!$C$6)+2,MIN(D6,DAY(EOMONTH(DATE(YEAR(Settings!$C$6),MONTH(Settings!$C$6)+2,1),0))))) | M6: =IF(OR(B6="",D6=""),"",DATE(YEAR(Settings!$C$6),MONTH(Settings!$C$6)+3,MIN(D6,DAY(EOMONTH(DATE(YEAR(Settings!$C$6),MONTH(Settings!$C$6)+3,1),0))))) | N6: =IF(OR(B6="",D6=""),"",DATE(YEAR(Settings!$C$6),MONTH(Settings!$C$6)+4,MIN(D6,DAY(EOMONTH(DATE(YEAR(Settings!$C$6),MONTH(Settings!$C$6)+4,1),0))))) | O6: =IF(OR(B6="",D6=""),"",DATE(YEAR(Settings!$C$6),MONTH(Settings!$C$6)+5,MIN(D6,DAY(EOMONTH(DATE(YEAR(Settings!$C$6),MONTH(Settings!$C$6)+5,1),0))))) | P6: =IF(OR(B6="",D6=""),"",DATE(YEAR(Settings!$C$6),MONTH(Settings!$C$6)+6,MIN(D6,DAY(EOMONTH(DATE(YEAR(Settings!$C$6),MONTH(Settings!$C$6)+6,1),0))))) | Q6: =IF(OR(B6="",D6=""),"",DATE(YEAR(Settings!$C$6),MONTH(Settings!$C$6)+7,MIN(D6,DAY(EOMONTH(DATE(YEAR(Settings!$C$6),MONTH(Settings!$C$6)+7,1),0))))) | R6: =IF(OR(B6="",D6=""),"",DATE(YEAR(Settings!$C$6),MONTH(Settings!$C$6)+8,MIN(D6,DAY(EOMONTH(DATE(YEAR(Settings!$C$6),MONTH(Settings!$C$6)+8,1),0))))) | S6: =IF(OR(B6="",D6=""),"",DATE(YEAR(Settings!$C$6),MONTH(Settings!$C$6)+9,MIN(D6,DAY(EOMONTH(DATE(YEAR(Settings!$C$6),MONTH(Settings!$C$6)+9,1),0))))) | T6: =IF(OR(B6="",D6=""),"",DATE(YEAR(Settings!$C$6),MONTH(Settings!$C$6)+10,MIN(D6,DAY(EOMONTH(DATE(YEAR(Settings!$C$6),MONTH(Settings!$C$6)+10,1),0))))) | U6: =IF(OR(B6="",D6=""),"",DATE(YEAR(Settings!$C$6),MONTH(Settings!$C$6)+11,MIN(D6,DAY(EOMONTH(DATE(YEAR(Settings!$C$6),MONTH(Settings!$C$6)+11,1),0))))) | V6: =IF(OR(B6="",D6=""),"",DATE(YEAR(Settings!$C$6),MONTH(Settings!$C$6)+12,MIN(D6,DAY(EOMONTH(DATE(YEAR(Settings!$C$6),MONTH(Settings!$C$6)+12,1),0))))) | W6: =IF(OR(B6="",D6=""),0,IF(OR(E6="",E6=MONTH(DATE(YEAR(Settings!$C$6),MONTH(Settings!$C$6)+0,1))),N(C6),0)) | X6: =IF(OR(B6="",D6=""),0,IF(OR(E6="",E6=MONTH(DATE(YEAR(Settings!$C$6),MONTH(Settings!$C$6)+1,1))),N(C6),0)) | Y6: =IF(OR(B6="",D6=""),0,IF(OR(E6="",E6=MONTH(DATE(YEAR(Settings!$C$6),MONTH(Settings!$C$6)+2,1))),N(C6),0)) | Z6: =IF(OR(B6="",D6=""),0,IF(OR(E6="",E6=MONTH(DATE(YEAR(Settings!$C$6),MONTH(Settings!$C$6)+3,1))),N(C6),0)) | AA6: =IF(OR(B6="",D6=""),0,IF(OR(E6="",E6=MONTH(DATE(YEAR(Settings!$C$6),MONTH(Settings!$C$6)+4,1))),N(C6),0)) | AB6: =IF(OR(B6="",D6=""),0,IF(OR(E6="",E6=MONTH(DATE(YEAR(Settings!$C$6),MONTH(Settings!$C$6)+5,1))),N(C6),0)) | AC6: =IF(OR(B6="",D6=""),0,IF(OR(E6="",E6=MONTH(DATE(YEAR(Settings!$C$6),MONTH(Settings!$C$6)+6,1))),N(C6),0)) | AD6: =IF(OR(B6="",D6=""),0,IF(OR(E6="",E6=MONTH(DATE(YEAR(Settings!$C$6),MONTH(Settings!$C$6)+7,1))),N(C6),0)) | AE6: =IF(OR(B6="",D6=""),0,IF(OR(E6="",E6=MONTH(DATE(YEAR(Settings!$C$6),MONTH(Settings!$C$6)+8,1))),N(C6),0)) | AF6: =IF(OR(B6="",D6=""),0,IF(OR(E6="",E6=MONTH(DATE(YEAR(Settings!$C$6),MONTH(Settings!$C$6)+9,1))),N(C6),0)) | AG6: =IF(OR(B6="",D6=""),0,IF(OR(E6="",E6=MONTH(DATE(YEAR(Settings!$C$6),MONTH(Settings!$C$6)+10,1))),N(C6),0)) | AH6: =IF(OR(B6="",D6=""),0,IF(OR(E6="",E6=MONTH(DATE(YEAR(Settings!$C$6),MONTH(Settings!$C$6)+11,1))),N(C6),0)) | AI6: =IF(OR(B6="",D6=""),0,IF(OR(E6="",E6=MONTH(DATE(YEAR(Settings!$C$6),MONTH(Settings!$C$6)+12,1))),N(C6),0)) | AJ6: =IF(B6="","",SUMIFS(J6:V6,J6:V6,">="&Dashboard!$C$4,J6:V6,"<"&Dashboard!$N$1,W6:AI6,">0")) | AK6: =IF(N(AJ6)=0,"",AJ6+ROW()/100000)
B7: Car payment | C7: 285 | D7: 5 | F7: Transport | G7: Yes | J7: =IF(OR(B7="",D7=""),"",DATE(YEAR(Settings!$C$6),MONTH(Settings!$C$6)+0,MIN(D7,DAY(EOMONTH(DATE(YEAR(Settings!$C$6),MONTH(Settings!$C$6)+0,1),0))))) | K7: =IF(OR(B7="",D7=""),"",DATE(YEAR(Settings!$C$6),MONTH(Settings!$C$6)+1,MIN(D7,DAY(EOMONTH(DATE(YEAR(Settings!$C$6),MONTH(Settings!$C$6)+1,1),0))))) | L7: =IF(OR(B7="",D7=""),"",DATE(YEAR(Settings!$C$6),MONTH(Settings!$C$6)+2,MIN(D7,DAY(EOMONTH(DATE(YEAR(Settings!$C$6),MONTH(Settings!$C$6)+2,1),0))))) | M7: =IF(OR(B7="",D7=""),"",DATE(YEAR(Settings!$C$6),MONTH(Settings!$C$6)+3,MIN(D7,DAY(EOMONTH(DATE(YEAR(Settings!$C$6),MONTH(Settings!$C$6)+3,1),0))))) | N7: =IF(OR(B7="",D7=""),"",DATE(YEAR(Settings!$C$6),MONTH(Settings!$C$6)+4,MIN(D7,DAY(EOMONTH(DATE(YEAR(Settings!$C$6),MONTH(Settings!$C$6)+4,1),0))))) | O7: =IF(OR(B7="",D7=""),"",DATE(YEAR(Settings!$C$6),MONTH(Settings!$C$6)+5,MIN(D7,DAY(EOMONTH(DATE(YEAR(Settings!$C$6),MONTH(Settings!$C$6)+5,1),0))))) | P7: =IF(OR(B7="",D7=""),"",DATE(YEAR(Settings!$C$6),MONTH(Settings!$C$6)+6,MIN(D7,DAY(EOMONTH(DATE(YEAR(Settings!$C$6),MONTH(Settings!$C$6)+6,1),0))))) | Q7: =IF(OR(B7="",D7=""),"",DATE(YEAR(Settings!$C$6),MONTH(Settings!$C$6)+7,MIN(D7,DAY(EOMONTH(DATE(YEAR(Settings!$C$6),MONTH(Settings!$C$6)+7,1),0))))) | R7: =IF(OR(B7="",D7=""),"",DATE(YEAR(Settings!$C$6),MONTH(Settings!$C$6)+8,MIN(D7,DAY(EOMONTH(DATE(YEAR(Settings!$C$6),MONTH(Settings!$C$6)+8,1),0))))) | S7: =IF(OR(B7="",D7=""),"",DATE(YEAR(Settings!$C$6),MONTH(Settings!$C$6)+9,MIN(D7,DAY(EOMONTH(DATE(YEAR(Settings!$C$6),MONTH(Settings!$C$6)+9,1),0))))) | T7: =IF(OR(B7="",D7=""),"",DATE(YEAR(Settings!$C$6),MONTH(Settings!$C$6)+10,MIN(D7,DAY(EOMONTH(DATE(YEAR(Settings!$C$6),MONTH(Settings!$C$6)+10,1),0))))) | U7: =IF(OR(B7="",D7=""),"",DATE(YEAR(Settings!$C$6),MONTH(Settings!$C$6)+11,MIN(D7,DAY(EOMONTH(DATE(YEAR(Settings!$C$6),MONTH(Settings!$C$6)+11,1),0))))) | V7: =IF(OR(B7="",D7=""),"",DATE(YEAR(Settings!$C$6),MONTH(Settings!$C$6)+12,MIN(D7,DAY(EOMONTH(DATE(YEAR(Settings!$C$6),MONTH(Settings!$C$6)+12,1),0))))) | W7: =IF(OR(B7="",D7=""),0,IF(OR(E7="",E7=MONTH(DATE(YEAR(Settings!$C$6),MONTH(Settings!$C$6)+0,1))),N(C7),0)) | X7: =IF(OR(B7="",D7=""),0,IF(OR(E7="",E7=MONTH(DATE(YEAR(Settings!$C$6),MONTH(Settings!$C$6)+1,1))),N(C7),0)) | Y7: =IF(OR(B7="",D7=""),0,IF(OR(E7="",E7=MONTH(DATE(YEAR(Settings!$C$6),MONTH(Settings!$C$6)+2,1))),N(C7),0)) | Z7: =IF(OR(B7="",D7=""),0,IF(OR(E7="",E7=MONTH(DATE(YEAR(Settings!$C$6),MONTH(Settings!$C$6)+3,1))),N(C7),0)) | AA7: =IF(OR(B7="",D7=""),0,IF(OR(E7="",E7=MONTH(DATE(YEAR(Settings!$C$6),MONTH(Settings!$C$6)+4,1))),N(C7),0)) | AB7: =IF(OR(B7="",D7=""),0,IF(OR(E7="",E7=MONTH(DATE(YEAR(Settings!$C$6),MONTH(Settings!$C$6)+5,1))),N(C7),0)) | AC7: =IF(OR(B7="",D7=""),0,IF(OR(E7="",E7=MONTH(DATE(YEAR(Settings!$C$6),MONTH(Settings!$C$6)+6,1))),N(C7),0)) | AD7: =IF(OR(B7="",D7=""),0,IF(OR(E7="",E7=MONTH(DATE(YEAR(Settings!$C$6),MONTH(Settings!$C$6)+7,1))),N(C7),0)) | AE7: =IF(OR(B7="",D7=""),0,IF(OR(E7="",E7=MONTH(DATE(YEAR(Settings!$C$6),MONTH(Settings!$C$6)+8,1))),N(C7),0)) | AF7: =IF(OR(B7="",D7=""),0,IF(OR(E7="",E7=MONTH(DATE(YEAR(Settings!$C$6),MONTH(Settings!$C$6)+9,1))),N(C7),0)) | AG7: =IF(OR(B7="",D7=""),0,IF(OR(E7="",E7=MONTH(DATE(YEAR(Settings!$C$6),MONTH(Settings!$C$6)+10,1))),N(C7),0)) | AH7: =IF(OR(B7="",D7=""),0,IF(OR(E7="",E7=MONTH(DATE(YEAR(Settings!$C$6),MONTH(Settings!$C$6)+11,1))),N(C7),0)) | AI7: =IF(OR(B7="",D7=""),0,IF(OR(E7="",E7=MONTH(DATE(YEAR(Settings!$C$6),MONTH(Settings!$C$6)+12,1))),N(C7),0)) | AJ7: =IF(B7="","",SUMIFS(J7:V7,J7:V7,">="&Dashboard!$C$4,J7:V7,"<"&Dashboard!$N$1,W7:AI7,">0")) | AK7: =IF(N(AJ7)=0,"",AJ7+ROW()/100000)
B8: Phone | C8: 45 | D8: 12 | F8: Utilities | G8: Yes | J8: =IF(OR(B8="",D8=""),"",DATE(YEAR(Settings!$C$6),MONTH(Settings!$C$6)+0,MIN(D8,DAY(EOMONTH(DATE(YEAR(Settings!$C$6),MONTH(Settings!$C$6)+0,1),0))))) | K8: =IF(OR(B8="",D8=""),"",DATE(YEAR(Settings!$C$6),MONTH(Settings!$C$6)+1,MIN(D8,DAY(EOMONTH(DATE(YEAR(Settings!$C$6),MONTH(Settings!$C$6)+1,1),0))))) | L8: =IF(OR(B8="",D8=""),"",DATE(YEAR(Settings!$C$6),MONTH(Settings!$C$6)+2,MIN(D8,DAY(EOMONTH(DATE(YEAR(Settings!$C$6),MONTH(Settings!$C$6)+2,1),0))))) | M8: =IF(OR(B8="",D8=""),"",DATE(YEAR(Settings!$C$6),MONTH(Settings!$C$6)+3,MIN(D8,DAY(EOMONTH(DATE(YEAR(Settings!$C$6),MONTH(Settings!$C$6)+3,1),0))))) | N8: =IF(OR(B8="",D8=""),"",DATE(YEAR(Settings!$C$6),MONTH(Settings!$C$6)+4,MIN(D8,DAY(EOMONTH(DATE(YEAR(Settings!$C$6),MONTH(Settings!$C$6)+4,1),0))))) | O8: =IF(OR(B8="",D8=""),"",DATE(YEAR(Settings!$C$6),MONTH(Settings!$C$6)+5,MIN(D8,DAY(EOMONTH(DATE(YEAR(Settings!$C$6),MONTH(Settings!$C$6)+5,1),0))))) | P8: =IF(OR(B8="",D8=""),"",DATE(YEAR(Settings!$C$6),MONTH(Settings!$C$6)+6,MIN(D8,DAY(EOMONTH(DATE(YEAR(Settings!$C$6),MONTH(Settings!$C$6)+6,1),0))))) | Q8: =IF(OR(B8="",D8=""),"",DATE(YEAR(Settings!$C$6),MONTH(Settings!$C$6)+7,MIN(D8,DAY(EOMONTH(DATE(YEAR(Settings!$C$6),MONTH(Settings!$C$6)+7,1),0))))) | R8: =IF(OR(B8="",D8=""),"",DATE(YEAR(Settings!$C$6),MONTH(Settings!$C$6)+8,MIN(D8,DAY(EOMONTH(DATE(YEAR(Settings!$C$6),MONTH(Settings!$C$6)+8,1),0))))) | S8: =IF(OR(B8="",D8=""),"",DATE(YEAR(Settings!$C$6),MONTH(Settings!$C$6)+9,MIN(D8,DAY(EOMONTH(DATE(YEAR(Settings!$C$6),MONTH(Settings!$C$6)+9,1),0))))) | T8: =IF(OR(B8="",D8=""),"",DATE(YEAR(Settings!$C$6),MONTH(Settings!$C$6)+10,MIN(D8,DAY(EOMONTH(DATE(YEAR(Settings!$C$6),MONTH(Settings!$C$6)+10,1),0))))) | U8: =IF(OR(B8="",D8=""),"",DATE(YEAR(Settings!$C$6),MONTH(Settings!$C$6)+11,MIN(D8,DAY(EOMONTH(DATE(YEAR(Settings!$C$6),MONTH(Settings!$C$6)+11,1),0))))) | V8: =IF(OR(B8="",D8=""),"",DATE(YEAR(Settings!$C$6),MONTH(Settings!$C$6)+12,MIN(D8,DAY(EOMONTH(DATE(YEAR(Settings!$C$6),MONTH(Settings!$C$6)+12,1),0))))) | W8: =IF(OR(B8="",D8=""),0,IF(OR(E8="",E8=MONTH(DATE(YEAR(Settings!$C$6),MONTH(Settings!$C$6)+0,1))),N(C8),0)) | X8: =IF(OR(B8="",D8=""),0,IF(OR(E8="",E8=MONTH(DATE(YEAR(Settings!$C$6),MONTH(Settings!$C$6)+1,1))),N(C8),0)) | Y8: =IF(OR(B8="",D8=""),0,IF(OR(E8="",E8=MONTH(DATE(YEAR(Settings!$C$6),MONTH(Settings!$C$6)+2,1))),N(C8),0)) | Z8: =IF(OR(B8="",D8=""),0,IF(OR(E8="",E8=MONTH(DATE(YEAR(Settings!$C$6),MONTH(Settings!$C$6)+3,1))),N(C8),0)) | AA8: =IF(OR(B8="",D8=""),0,IF(OR(E8="",E8=MONTH(DATE(YEAR(Settings!$C$6),MONTH(Settings!$C$6)+4,1))),N(C8),0)) | AB8: =IF(OR(B8="",D8=""),0,IF(OR(E8="",E8=MONTH(DATE(YEAR(Settings!$C$6),MONTH(Settings!$C$6)+5,1))),N(C8),0)) | AC8: =IF(OR(B8="",D8=""),0,IF(OR(E8="",E8=MONTH(DATE(YEAR(Settings!$C$6),MONTH(Settings!$C$6)+6,1))),N(C8),0)) | AD8: =IF(OR(B8="",D8=""),0,IF(OR(E8="",E8=MONTH(DATE(YEAR(Settings!$C$6),MONTH(Settings!$C$6)+7,1))),N(C8),0)) | AE8: =IF(OR(B8="",D8=""),0,IF(OR(E8="",E8=MONTH(DATE(YEAR(Settings!$C$6),MONTH(Settings!$C$6)+8,1))),N(C8),0)) | AF8: =IF(OR(B8="",D8=""),0,IF(OR(E8="",E8=MONTH(DATE(YEAR(Settings!$C$6),MONTH(Settings!$C$6)+9,1))),N(C8),0)) | AG8: =IF(OR(B8="",D8=""),0,IF(OR(E8="",E8=MONTH(DATE(YEAR(Settings!$C$6),MONTH(Settings!$C$6)+10,1))),N(C8),0)) | AH8: =IF(OR(B8="",D8=""),0,IF(OR(E8="",E8=MONTH(DATE(YEAR(Settings!$C$6),MONTH(Settings!$C$6)+11,1))),N(C8),0)) | AI8: =IF(OR(B8="",D8=""),0,IF(OR(E8="",E8=MONTH(DATE(YEAR(Settings!$C$6),MONTH(Settings!$C$6)+12,1))),N(C8),0)) | AJ8: =IF(B8="","",SUMIFS(J8:V8,J8:V8,">="&Dashboard!$C$4,J8:V8,"<"&Dashboard!$N$1,W8:AI8,">0")) | AK8: =IF(N(AJ8)=0,"",AJ8+ROW()/100000)
B9: Water | C9: 40 | D9: 15 | F9: Utilities | G9: No | J9: =IF(OR(B9="",D9=""),"",DATE(YEAR(Settings!$C$6),MONTH(Settings!$C$6)+0,MIN(D9,DAY(EOMONTH(DATE(YEAR(Settings!$C$6),MONTH(Settings!$C$6)+0,1),0))))) | K9: =IF(OR(B9="",D9=""),"",DATE(YEAR(Settings!$C$6),MONTH(Settings!$C$6)+1,MIN(D9,DAY(EOMONTH(DATE(YEAR(Settings!$C$6),MONTH(Settings!$C$6)+1,1),0))))) | L9: =IF(OR(B9="",D9=""),"",DATE(YEAR(Settings!$C$6),MONTH(Settings!$C$6)+2,MIN(D9,DAY(EOMONTH(DATE(YEAR(Settings!$C$6),MONTH(Settings!$C$6)+2,1),0))))) | M9: =IF(OR(B9="",D9=""),"",DATE(YEAR(Settings!$C$6),MONTH(Settings!$C$6)+3,MIN(D9,DAY(EOMONTH(DATE(YEAR(Settings!$C$6),MONTH(Settings!$C$6)+3,1),0))))) | N9: =IF(OR(B9="",D9=""),"",DATE(YEAR(Settings!$C$6),MONTH(Settings!$C$6)+4,MIN(D9,DAY(EOMONTH(DATE(YEAR(Settings!$C$6),MONTH(Settings!$C$6)+4,1),0))))) | O9: =IF(OR(B9="",D9=""),"",DATE(YEAR(Settings!$C$6),MONTH(Settings!$C$6)+5,MIN(D9,DAY(EOMONTH(DATE(YEAR(Settings!$C$6),MONTH(Settings!$C$6)+5,1),0))))) | P9: =IF(OR(B9="",D9=""),"",DATE(YEAR(Settings!$C$6),MONTH(Settings!$C$6)+6,MIN(D9,DAY(EOMONTH(DATE(YEAR(Settings!$C$6),MONTH(Settings!$C$6)+6,1),0))))) | Q9: =IF(OR(B9="",D9=""),"",DATE(YEAR(Settings!$C$6),MONTH(Settings!$C$6)+7,MIN(D9,DAY(EOMONTH(DATE(YEAR(Settings!$C$6),MONTH(Settings!$C$6)+7,1),0))))) | R9: =IF(OR(B9="",D9=""),"",DATE(YEAR(Settings!$C$6),MONTH(Settings!$C$6)+8,MIN(D9,DAY(EOMONTH(DATE(YEAR(Settings!$C$6),MONTH(Settings!$C$6)+8,1),0))))) | S9: =IF(OR(B9="",D9=""),"",DATE(YEAR(Settings!$C$6),MONTH(Settings!$C$6)+9,MIN(D9,DAY(EOMONTH(DATE(YEAR(Settings!$C$6),MONTH(Settings!$C$6)+9,1),0))))) | T9: =IF(OR(B9="",D9=""),"",DATE(YEAR(Settings!$C$6),MONTH(Settings!$C$6)+10,MIN(D9,DAY(EOMONTH(DATE(YEAR(Settings!$C$6),MONTH(Settings!$C$6)+10,1),0))))) | U9: =IF(OR(B9="",D9=""),"",DATE(YEAR(Settings!$C$6),MONTH(Settings!$C$6)+11,MIN(D9,DAY(EOMONTH(DATE(YEAR(Settings!$C$6),MONTH(Settings!$C$6)+11,1),0))))) | V9: =IF(OR(B9="",D9=""),"",DATE(YEAR(Settings!$C$6),MONTH(Settings!$C$6)+12,MIN(D9,DAY(EOMONTH(DATE(YEAR(Settings!$C$6),MONTH(Settings!$C$6)+12,1),0))))) | W9: =IF(OR(B9="",D9=""),0,IF(OR(E9="",E9=MONTH(DATE(YEAR(Settings!$C$6),MONTH(Settings!$C$6)+0,1))),N(C9),0)) | X9: =IF(OR(B9="",D9=""),0,IF(OR(E9="",E9=MONTH(DATE(YEAR(Settings!$C$6),MONTH(Settings!$C$6)+1,1))),N(C9),0)) | Y9: =IF(OR(B9="",D9=""),0,IF(OR(E9="",E9=MONTH(DATE(YEAR(Settings!$C$6),MONTH(Settings!$C$6)+2,1))),N(C9),0)) | Z9: =IF(OR(B9="",D9=""),0,IF(OR(E9="",E9=MONTH(DATE(YEAR(Settings!$C$6),MONTH(Settings!$C$6)+3,1))),N(C9),0)) | AA9: =IF(OR(B9="",D9=""),0,IF(OR(E9="",E9=MONTH(DATE(YEAR(Settings!$C$6),MONTH(Settings!$C$6)+4,1))),N(C9),0)) | AB9: =IF(OR(B9="",D9=""),0,IF(OR(E9="",E9=MONTH(DATE(YEAR(Settings!$C$6),MONTH(Settings!$C$6)+5,1))),N(C9),0)) | AC9: =IF(OR(B9="",D9=""),0,IF(OR(E9="",E9=MONTH(DATE(YEAR(Settings!$C$6),MONTH(Settings!$C$6)+6,1))),N(C9),0)) | AD9: =IF(OR(B9="",D9=""),0,IF(OR(E9="",E9=MONTH(DATE(YEAR(Settings!$C$6),MONTH(Settings!$C$6)+7,1))),N(C9),0)) | AE9: =IF(OR(B9="",D9=""),0,IF(OR(E9="",E9=MONTH(DATE(YEAR(Settings!$C$6),MONTH(Settings!$C$6)+8,1))),N(C9),0)) | AF9: =IF(OR(B9="",D9=""),0,IF(OR(E9="",E9=MONTH(DATE(YEAR(Settings!$C$6),MONTH(Settings!$C$6)+9,1))),N(C9),0)) | AG9: =IF(OR(B9="",D9=""),0,IF(OR(E9="",E9=MONTH(DATE(YEAR(Settings!$C$6),MONTH(Settings!$C$6)+10,1))),N(C9),0)) | AH9: =IF(OR(B9="",D9=""),0,IF(OR(E9="",E9=MONTH(DATE(YEAR(Settings!$C$6),MONTH(Settings!$C$6)+11,1))),N(C9),0)) | AI9: =IF(OR(B9="",D9=""),0,IF(OR(E9="",E9=MONTH(DATE(YEAR(Settings!$C$6),MONTH(Settings!$C$6)+12,1))),N(C9),0)) | AJ9: =IF(B9="","",SUMIFS(J9:V9,J9:V9,">="&Dashboard!$C$4,J9:V9,"<"&Dashboard!$N$1,W9:AI9,">0")) | AK9: =IF(N(AJ9)=0,"",AJ9+ROW()/100000)
B10: Internet | C10: 60 | D10: 18 | F10: Utilities | G10: Yes | J10: =IF(OR(B10="",D10=""),"",DATE(YEAR(Settings!$C$6),MONTH(Settings!$C$6)+0,MIN(D10,DAY(EOMONTH(DATE(YEAR(Settings!$C$6),MONTH(Settings!$C$6)+0,1),0))))) | K10: =IF(OR(B10="",D10=""),"",DATE(YEAR(Settings!$C$6),MONTH(Settings!$C$6)+1,MIN(D10,DAY(EOMONTH(DATE(YEAR(Settings!$C$6),MONTH(Settings!$C$6)+1,1),0))))) | L10: =IF(OR(B10="",D10=""),"",DATE(YEAR(Settings!$C$6),MONTH(Settings!$C$6)+2,MIN(D10,DAY(EOMONTH(DATE(YEAR(Settings!$C$6),MONTH(Settings!$C$6)+2,1),0))))) | M10: =IF(OR(B10="",D10=""),"",DATE(YEAR(Settings!$C$6),MONTH(Settings!$C$6)+3,MIN(D10,DAY(EOMONTH(DATE(YEAR(Settings!$C$6),MONTH(Settings!$C$6)+3,1),0))))) | N10: =IF(OR(B10="",D10=""),"",DATE(YEAR(Settings!$C$6),MONTH(Settings!$C$6)+4,MIN(D10,DAY(EOMONTH(DATE(YEAR(Settings!$C$6),MONTH(Settings!$C$6)+4,1),0))))) | O10: =IF(OR(B10="",D10=""),"",DATE(YEAR(Settings!$C$6),MONTH(Settings!$C$6)+5,MIN(D10,DAY(EOMONTH(DATE(YEAR(Settings!$C$6),MONTH(Settings!$C$6)+5,1),0))))) | P10: =IF(OR(B10="",D10=""),"",DATE(YEAR(Settings!$C$6),MONTH(Settings!$C$6)+6,MIN(D10,DAY(EOMONTH(DATE(YEAR(Settings!$C$6),MONTH(Settings!$C$6)+6,1),0))))) | Q10: =IF(OR(B10="",D10=""),"",DATE(YEAR(Settings!$C$6),MONTH(Settings!$C$6)+7,MIN(D10,DAY(EOMONTH(DATE(YEAR(Settings!$C$6),MONTH(Settings!$C$6)+7,1),0))))) | R10: =IF(OR(B10="",D10=""),"",DATE(YEAR(Settings!$C$6),MONTH(Settings!$C$6)+8,MIN(D10,DAY(EOMONTH(DATE(YEAR(Settings!$C$6),MONTH(Settings!$C$6)+8,1),0))))) | S10: =IF(OR(B10="",D10=""),"",DATE(YEAR(Settings!$C$6),MONTH(Settings!$C$6)+9,MIN(D10,DAY(EOMONTH(DATE(YEAR(Settings!$C$6),MONTH(Settings!$C$6)+9,1),0))))) | T10: =IF(OR(B10="",D10=""),"",DATE(YEAR(Settings!$C$6),MONTH(Settings!$C$6)+10,MIN(D10,DAY(EOMONTH(DATE(YEAR(Settings!$C$6),MONTH(Settings!$C$6)+10,1),0))))) | U10: =IF(OR(B10="",D10=""),"",DATE(YEAR(Settings!$C$6),MONTH(Settings!$C$6)+11,MIN(D10,DAY(EOMONTH(DATE(YEAR(Settings!$C$6),MONTH(Settings!$C$6)+11,1),0))))) | V10: =IF(OR(B10="",D10=""),"",DATE(YEAR(Settings!$C$6),MONTH(Settings!$C$6)+12,MIN(D10,DAY(EOMONTH(DATE(YEAR(Settings!$C$6),MONTH(Settings!$C$6)+12,1),0))))) | W10: =IF(OR(B10="",D10=""),0,IF(OR(E10="",E10=MONTH(DATE(YEAR(Settings!$C$6),MONTH(Settings!$C$6)+0,1))),N(C10),0)) | X10: =IF(OR(B10="",D10=""),0,IF(OR(E10="",E10=MONTH(DATE(YEAR(Settings!$C$6),MONTH(Settings!$C$6)+1,1))),N(C10),0)) | Y10: =IF(OR(B10="",D10=""),0,IF(OR(E10="",E10=MONTH(DATE(YEAR(Settings!$C$6),MONTH(Settings!$C$6)+2,1))),N(C10),0)) | Z10: =IF(OR(B10="",D10=""),0,IF(OR(E10="",E10=MONTH(DATE(YEAR(Settings!$C$6),MONTH(Settings!$C$6)+3,1))),N(C10),0)) | AA10: =IF(OR(B10="",D10=""),0,IF(OR(E10="",E10=MONTH(DATE(YEAR(Settings!$C$6),MONTH(Settings!$C$6)+4,1))),N(C10),0)) | AB10: =IF(OR(B10="",D10=""),0,IF(OR(E10="",E10=MONTH(DATE(YEAR(Settings!$C$6),MONTH(Settings!$C$6)+5,1))),N(C10),0)) | AC10: =IF(OR(B10="",D10=""),0,IF(OR(E10="",E10=MONTH(DATE(YEAR(Settings!$C$6),MONTH(Settings!$C$6)+6,1))),N(C10),0)) | AD10: =IF(OR(B10="",D10=""),0,IF(OR(E10="",E10=MONTH(DATE(YEAR(Settings!$C$6),MONTH(Settings!$C$6)+7,1))),N(C10),0)) | AE10: =IF(OR(B10="",D10=""),0,IF(OR(E10="",E10=MONTH(DATE(YEAR(Settings!$C$6),MONTH(Settings!$C$6)+8,1))),N(C10),0)) | AF10: =IF(OR(B10="",D10=""),0,IF(OR(E10="",E10=MONTH(DATE(YEAR(Settings!$C$6),MONTH(Settings!$C$6)+9,1))),N(C10),0)) | AG10: =IF(OR(B10="",D10=""),0,IF(OR(E10="",E10=MONTH(DATE(YEAR(Settings!$C$6),MONTH(Settings!$C$6)+10,1))),N(C10),0)) | AH10: =IF(OR(B10="",D10=""),0,IF(OR(E10="",E10=MONTH(DATE(YEAR(Settings!$C$6),MONTH(Settings!$C$6)+11,1))),N(C10),0)) | AI10: =IF(OR(B10="",D10=""),0,IF(OR(E10="",E10=MONTH(DATE(YEAR(Settings!$C$6),MONTH(Settings!$C$6)+12,1))),N(C10),0)) | AJ10: =IF(B10="","",SUMIFS(J10:V10,J10:V10,">="&Dashboard!$C$4,J10:V10,"<"&Dashboard!$N$1,W10:AI10,">0")) | AK10: =IF(N(AJ10)=0,"",AJ10+ROW()/100000)
B11: Electricity | C11: 95 | D11: 20 | F11: Utilities | G11: No | J11: =IF(OR(B11="",D11=""),"",DATE(YEAR(Settings!$C$6),MONTH(Settings!$C$6)+0,MIN(D11,DAY(EOMONTH(DATE(YEAR(Settings!$C$6),MONTH(Settings!$C$6)+0,1),0))))) | K11: =IF(OR(B11="",D11=""),"",DATE(YEAR(Settings!$C$6),MONTH(Settings!$C$6)+1,MIN(D11,DAY(EOMONTH(DATE(YEAR(Settings!$C$6),MONTH(Settings!$C$6)+1,1),0))))) | L11: =IF(OR(B11="",D11=""),"",DATE(YEAR(Settings!$C$6),MONTH(Settings!$C$6)+2,MIN(D11,DAY(EOMONTH(DATE(YEAR(Settings!$C$6),MONTH(Settings!$C$6)+2,1),0))))) | M11: =IF(OR(B11="",D11=""),"",DATE(YEAR(Settings!$C$6),MONTH(Settings!$C$6)+3,MIN(D11,DAY(EOMONTH(DATE(YEAR(Settings!$C$6),MONTH(Settings!$C$6)+3,1),0))))) | N11: =IF(OR(B11="",D11=""),"",DATE(YEAR(Settings!$C$6),MONTH(Settings!$C$6)+4,MIN(D11,DAY(EOMONTH(DATE(YEAR(Settings!$C$6),MONTH(Settings!$C$6)+4,1),0))))) | O11: =IF(OR(B11="",D11=""),"",DATE(YEAR(Settings!$C$6),MONTH(Settings!$C$6)+5,MIN(D11,DAY(EOMONTH(DATE(YEAR(Settings!$C$6),MONTH(Settings!$C$6)+5,1),0))))) | P11: =IF(OR(B11="",D11=""),"",DATE(YEAR(Settings!$C$6),MONTH(Settings!$C$6)+6,MIN(D11,DAY(EOMONTH(DATE(YEAR(Settings!$C$6),MONTH(Settings!$C$6)+6,1),0))))) | Q11: =IF(OR(B11="",D11=""),"",DATE(YEAR(Settings!$C$6),MONTH(Settings!$C$6)+7,MIN(D11,DAY(EOMONTH(DATE(YEAR(Settings!$C$6),MONTH(Settings!$C$6)+7,1),0))))) | R11: =IF(OR(B11="",D11=""),"",DATE(YEAR(Settings!$C$6),MONTH(Settings!$C$6)+8,MIN(D11,DAY(EOMONTH(DATE(YEAR(Settings!$C$6),MONTH(Settings!$C$6)+8,1),0))))) | S11: =IF(OR(B11="",D11=""),"",DATE(YEAR(Settings!$C$6),MONTH(Settings!$C$6)+9,MIN(D11,DAY(EOMONTH(DATE(YEAR(Settings!$C$6),MONTH(Settings!$C$6)+9,1),0))))) | T11: =IF(OR(B11="",D11=""),"",DATE(YEAR(Settings!$C$6),MONTH(Settings!$C$6)+10,MIN(D11,DAY(EOMONTH(DATE(YEAR(Settings!$C$6),MONTH(Settings!$C$6)+10,1),0))))) | U11: =IF(OR(B11="",D11=""),"",DATE(YEAR(Settings!$C$6),MONTH(Settings!$C$6)+11,MIN(D11,DAY(EOMONTH(DATE(YEAR(Settings!$C$6),MONTH(Settings!$C$6)+11,1),0))))) | V11: =IF(OR(B11="",D11=""),"",DATE(YEAR(Settings!$C$6),MONTH(Settings!$C$6)+12,MIN(D11,DAY(EOMONTH(DATE(YEAR(Settings!$C$6),MONTH(Settings!$C$6)+12,1),0))))) | W11: =IF(OR(B11="",D11=""),0,IF(OR(E11="",E11=MONTH(DATE(YEAR(Settings!$C$6),MONTH(Settings!$C$6)+0,1))),N(C11),0)) | X11: =IF(OR(B11="",D11=""),0,IF(OR(E11="",E11=MONTH(DATE(YEAR(Settings!$C$6),MONTH(Settings!$C$6)+1,1))),N(C11),0)) | Y11: =IF(OR(B11="",D11=""),0,IF(OR(E11="",E11=MONTH(DATE(YEAR(Settings!$C$6),MONTH(Settings!$C$6)+2,1))),N(C11),0)) | Z11: =IF(OR(B11="",D11=""),0,IF(OR(E11="",E11=MONTH(DATE(YEAR(Settings!$C$6),MONTH(Settings!$C$6)+3,1))),N(C11),0)) | AA11: =IF(OR(B11="",D11=""),0,IF(OR(E11="",E11=MONTH(DATE(YEAR(Settings!$C$6),MONTH(Settings!$C$6)+4,1))),N(C11),0)) | AB11: =IF(OR(B11="",D11=""),0,IF(OR(E11="",E11=MONTH(DATE(YEAR(Settings!$C$6),MONTH(Settings!$C$6)+5,1))),N(C11),0)) | AC11: =IF(OR(B11="",D11=""),0,IF(OR(E11="",E11=MONTH(DATE(YEAR(Settings!$C$6),MONTH(Settings!$C$6)+6,1))),N(C11),0)) | AD11: =IF(OR(B11="",D11=""),0,IF(OR(E11="",E11=MONTH(DATE(YEAR(Settings!$C$6),MONTH(Settings!$C$6)+7,1))),N(C11),0)) | AE11: =IF(OR(B11="",D11=""),0,IF(OR(E11="",E11=MONTH(DATE(YEAR(Settings!$C$6),MONTH(Settings!$C$6)+8,1))),N(C11),0)) | AF11: =IF(OR(B11="",D11=""),0,IF(OR(E11="",E11=MONTH(DATE(YEAR(Settings!$C$6),MONTH(Settings!$C$6)+9,1))),N(C11),0)) | AG11: =IF(OR(B11="",D11=""),0,IF(OR(E11="",E11=MONTH(DATE(YEAR(Settings!$C$6),MONTH(Settings!$C$6)+10,1))),N(C11),0)) | AH11: =IF(OR(B11="",D11=""),0,IF(OR(E11="",E11=MONTH(DATE(YEAR(Settings!$C$6),MONTH(Settings!$C$6)+11,1))),N(C11),0)) | AI11: =IF(OR(B11="",D11=""),0,IF(OR(E11="",E11=MONTH(DATE(YEAR(Settings!$C$6),MONTH(Settings!$C$6)+12,1))),N(C11),0)) | AJ11: =IF(B11="","",SUMIFS(J11:V11,J11:V11,">="&Dashboard!$C$4,J11:V11,"<"&Dashboard!$N$1,W11:AI11,">0")) | AK11: =IF(N(AJ11)=0,"",AJ11+ROW()/100000)
B12: Car insurance | C12: 110 | D12: 22 | F12: Insurance | G12: Yes | J12: =IF(OR(B12="",D12=""),"",DATE(YEAR(Settings!$C$6),MONTH(Settings!$C$6)+0,MIN(D12,DAY(EOMONTH(DATE(YEAR(Settings!$C$6),MONTH(Settings!$C$6)+0,1),0))))) | K12: =IF(OR(B12="",D12=""),"",DATE(YEAR(Settings!$C$6),MONTH(Settings!$C$6)+1,MIN(D12,DAY(EOMONTH(DATE(YEAR(Settings!$C$6),MONTH(Settings!$C$6)+1,1),0))))) | L12: =IF(OR(B12="",D12=""),"",DATE(YEAR(Settings!$C$6),MONTH(Settings!$C$6)+2,MIN(D12,DAY(EOMONTH(DATE(YEAR(Settings!$C$6),MONTH(Settings!$C$6)+2,1),0))))) | M12: =IF(OR(B12="",D12=""),"",DATE(YEAR(Settings!$C$6),MONTH(Settings!$C$6)+3,MIN(D12,DAY(EOMONTH(DATE(YEAR(Settings!$C$6),MONTH(Settings!$C$6)+3,1),0))))) | N12: =IF(OR(B12="",D12=""),"",DATE(YEAR(Settings!$C$6),MONTH(Settings!$C$6)+4,MIN(D12,DAY(EOMONTH(DATE(YEAR(Settings!$C$6),MONTH(Settings!$C$6)+4,1),0))))) | O12: =IF(OR(B12="",D12=""),"",DATE(YEAR(Settings!$C$6),MONTH(Settings!$C$6)+5,MIN(D12,DAY(EOMONTH(DATE(YEAR(Settings!$C$6),MONTH(Settings!$C$6)+5,1),0))))) | P12: =IF(OR(B12="",D12=""),"",DATE(YEAR(Settings!$C$6),MONTH(Settings!$C$6)+6,MIN(D12,DAY(EOMONTH(DATE(YEAR(Settings!$C$6),MONTH(Settings!$C$6)+6,1),0))))) | Q12: =IF(OR(B12="",D12=""),"",DATE(YEAR(Settings!$C$6),MONTH(Settings!$C$6)+7,MIN(D12,DAY(EOMONTH(DATE(YEAR(Settings!$C$6),MONTH(Settings!$C$6)+7,1),0))))) | R12: =IF(OR(B12="",D12=""),"",DATE(YEAR(Settings!$C$6),MONTH(Settings!$C$6)+8,MIN(D12,DAY(EOMONTH(DATE(YEAR(Settings!$C$6),MONTH(Settings!$C$6)+8,1),0))))) | S12: =IF(OR(B12="",D12=""),"",DATE(YEAR(Settings!$C$6),MONTH(Settings!$C$6)+9,MIN(D12,DAY(EOMONTH(DATE(YEAR(Settings!$C$6),MONTH(Settings!$C$6)+9,1),0))))) | T12: =IF(OR(B12="",D12=""),"",DATE(YEAR(Settings!$C$6),MONTH(Settings!$C$6)+10,MIN(D12,DAY(EOMONTH(DATE(YEAR(Settings!$C$6),MONTH(Settings!$C$6)+10,1),0))))) | U12: =IF(OR(B12="",D12=""),"",DATE(YEAR(Settings!$C$6),MONTH(Settings!$C$6)+11,MIN(D12,DAY(EOMONTH(DATE(YEAR(Settings!$C$6),MONTH(Settings!$C$6)+11,1),0))))) | V12: =IF(OR(B12="",D12=""),"",DATE(YEAR(Settings!$C$6),MONTH(Settings!$C$6)+12,MIN(D12,DAY(EOMONTH(DATE(YEAR(Settings!$C$6),MONTH(Settings!$C$6)+12,1),0))))) | W12: =IF(OR(B12="",D12=""),0,IF(OR(E12="",E12=MONTH(DATE(YEAR(Settings!$C$6),MONTH(Settings!$C$6)+0,1))),N(C12),0)) | X12: =IF(OR(B12="",D12=""),0,IF(OR(E12="",E12=MONTH(DATE(YEAR(Settings!$C$6),MONTH(Settings!$C$6)+1,1))),N(C12),0)) | Y12: =IF(OR(B12="",D12=""),0,IF(OR(E12="",E12=MONTH(DATE(YEAR(Settings!$C$6),MONTH(Settings!$C$6)+2,1))),N(C12),0)) | Z12: =IF(OR(B12="",D12=""),0,IF(OR(E12="",E12=MONTH(DATE(YEAR(Settings!$C$6),MONTH(Settings!$C$6)+3,1))),N(C12),0)) | AA12: =IF(OR(B12="",D12=""),0,IF(OR(E12="",E12=MONTH(DATE(YEAR(Settings!$C$6),MONTH(Settings!$C$6)+4,1))),N(C12),0)) | AB12: =IF(OR(B12="",D12=""),0,IF(OR(E12="",E12=MONTH(DATE(YEAR(Settings!$C$6),MONTH(Settings!$C$6)+5,1))),N(C12),0)) | AC12: =IF(OR(B12="",D12=""),0,IF(OR(E12="",E12=MONTH(DATE(YEAR(Settings!$C$6),MONTH(Settings!$C$6)+6,1))),N(C12),0)) | AD12: =IF(OR(B12="",D12=""),0,IF(OR(E12="",E12=MONTH(DATE(YEAR(Settings!$C$6),MONTH(Settings!$C$6)+7,1))),N(C12),0)) | AE12: =IF(OR(B12="",D12=""),0,IF(OR(E12="",E12=MONTH(DATE(YEAR(Settings!$C$6),MONTH(Settings!$C$6)+8,1))),N(C12),0)) | AF12: =IF(OR(B12="",D12=""),0,IF(OR(E12="",E12=MONTH(DATE(YEAR(Settings!$C$6),MONTH(Settings!$C$6)+9,1))),N(C12),0)) | AG12: =IF(OR(B12="",D12=""),0,IF(OR(E12="",E12=MONTH(DATE(YEAR(Settings!$C$6),MONTH(Settings!$C$6)+10,1))),N(C12),0)) | AH12: =IF(OR(B12="",D12=""),0,IF(OR(E12="",E12=MONTH(DATE(YEAR(Settings!$C$6),MONTH(Settings!$C$6)+11,1))),N(C12),0)) | AI12: =IF(OR(B12="",D12=""),0,IF(OR(E12="",E12=MONTH(DATE(YEAR(Settings!$C$6),MONTH(Settings!$C$6)+12,1))),N(C12),0)) | AJ12: =IF(B12="","",SUMIFS(J12:V12,J12:V12,">="&Dashboard!$C$4,J12:V12,"<"&Dashboard!$N$1,W12:AI12,">0")) | AK12: =IF(N(AJ12)=0,"",AJ12+ROW()/100000)
B13: Streaming | C13: 16 | D13: 25 | F13: Fun | G13: Yes | J13: =IF(OR(B13="",D13=""),"",DATE(YEAR(Settings!$C$6),MONTH(Settings!$C$6)+0,MIN(D13,DAY(EOMONTH(DATE(YEAR(Settings!$C$6),MONTH(Settings!$C$6)+0,1),0))))) | K13: =IF(OR(B13="",D13=""),"",DATE(YEAR(Settings!$C$6),MONTH(Settings!$C$6)+1,MIN(D13,DAY(EOMONTH(DATE(YEAR(Settings!$C$6),MONTH(Settings!$C$6)+1,1),0))))) | L13: =IF(OR(B13="",D13=""),"",DATE(YEAR(Settings!$C$6),MONTH(Settings!$C$6)+2,MIN(D13,DAY(EOMONTH(DATE(YEAR(Settings!$C$6),MONTH(Settings!$C$6)+2,1),0))))) | M13: =IF(OR(B13="",D13=""),"",DATE(YEAR(Settings!$C$6),MONTH(Settings!$C$6)+3,MIN(D13,DAY(EOMONTH(DATE(YEAR(Settings!$C$6),MONTH(Settings!$C$6)+3,1),0))))) | N13: =IF(OR(B13="",D13=""),"",DATE(YEAR(Settings!$C$6),MONTH(Settings!$C$6)+4,MIN(D13,DAY(EOMONTH(DATE(YEAR(Settings!$C$6),MONTH(Settings!$C$6)+4,1),0))))) | O13: =IF(OR(B13="",D13=""),"",DATE(YEAR(Settings!$C$6),MONTH(Settings!$C$6)+5,MIN(D13,DAY(EOMONTH(DATE(YEAR(Settings!$C$6),MONTH(Settings!$C$6)+5,1),0))))) | P13: =IF(OR(B13="",D13=""),"",DATE(YEAR(Settings!$C$6),MONTH(Settings!$C$6)+6,MIN(D13,DAY(EOMONTH(DATE(YEAR(Settings!$C$6),MONTH(Settings!$C$6)+6,1),0))))) | Q13: =IF(OR(B13="",D13=""),"",DATE(YEAR(Settings!$C$6),MONTH(Settings!$C$6)+7,MIN(D13,DAY(EOMONTH(DATE(YEAR(Settings!$C$6),MONTH(Settings!$C$6)+7,1),0))))) | R13: =IF(OR(B13="",D13=""),"",DATE(YEAR(Settings!$C$6),MONTH(Settings!$C$6)+8,MIN(D13,DAY(EOMONTH(DATE(YEAR(Settings!$C$6),MONTH(Settings!$C$6)+8,1),0))))) | S13: =IF(OR(B13="",D13=""),"",DATE(YEAR(Settings!$C$6),MONTH(Settings!$C$6)+9,MIN(D13,DAY(EOMONTH(DATE(YEAR(Settings!$C$6),MONTH(Settings!$C$6)+9,1),0))))) | T13: =IF(OR(B13="",D13=""),"",DATE(YEAR(Settings!$C$6),MONTH(Settings!$C$6)+10,MIN(D13,DAY(EOMONTH(DATE(YEAR(Settings!$C$6),MONTH(Settings!$C$6)+10,1),0))))) | U13: =IF(OR(B13="",D13=""),"",DATE(YEAR(Settings!$C$6),MONTH(Settings!$C$6)+11,MIN(D13,DAY(EOMONTH(DATE(YEAR(Settings!$C$6),MONTH(Settings!$C$6)+11,1),0))))) | V13: =IF(OR(B13="",D13=""),"",DATE(YEAR(Settings!$C$6),MONTH(Settings!$C$6)+12,MIN(D13,DAY(EOMONTH(DATE(YEAR(Settings!$C$6),MONTH(Settings!$C$6)+12,1),0))))) | W13: =IF(OR(B13="",D13=""),0,IF(OR(E13="",E13=MONTH(DATE(YEAR(Settings!$C$6),MONTH(Settings!$C$6)+0,1))),N(C13),0)) | X13: =IF(OR(B13="",D13=""),0,IF(OR(E13="",E13=MONTH(DATE(YEAR(Settings!$C$6),MONTH(Settings!$C$6)+1,1))),N(C13),0)) | Y13: =IF(OR(B13="",D13=""),0,IF(OR(E13="",E13=MONTH(DATE(YEAR(Settings!$C$6),MONTH(Settings!$C$6)+2,1))),N(C13),0)) | Z13: =IF(OR(B13="",D13=""),0,IF(OR(E13="",E13=MONTH(DATE(YEAR(Settings!$C$6),MONTH(Settings!$C$6)+3,1))),N(C13),0)) | AA13: =IF(OR(B13="",D13=""),0,IF(OR(E13="",E13=MONTH(DATE(YEAR(Settings!$C$6),MONTH(Settings!$C$6)+4,1))),N(C13),0)) | AB13: =IF(OR(B13="",D13=""),0,IF(OR(E13="",E13=MONTH(DATE(YEAR(Settings!$C$6),MONTH(Settings!$C$6)+5,1))),N(C13),0)) | AC13: =IF(OR(B13="",D13=""),0,IF(OR(E13="",E13=MONTH(DATE(YEAR(Settings!$C$6),MONTH(Settings!$C$6)+6,1))),N(C13),0)) | AD13: =IF(OR(B13="",D13=""),0,IF(OR(E13="",E13=MONTH(DATE(YEAR(Settings!$C$6),MONTH(Settings!$C$6)+7,1))),N(C13),0)) | AE13: =IF(OR(B13="",D13=""),0,IF(OR(E13="",E13=MONTH(DATE(YEAR(Settings!$C$6),MONTH(Settings!$C$6)+8,1))),N(C13),0)) | AF13: =IF(OR(B13="",D13=""),0,IF(OR(E13="",E13=MONTH(DATE(YEAR(Settings!$C$6),MONTH(Settings!$C$6)+9,1))),N(C13),0)) | AG13: =IF(OR(B13="",D13=""),0,IF(OR(E13="",E13=MONTH(DATE(YEAR(Settings!$C$6),MONTH(Settings!$C$6)+10,1))),N(C13),0)) | AH13: =IF(OR(B13="",D13=""),0,IF(OR(E13="",E13=MONTH(DATE(YEAR(Settings!$C$6),MONTH(Settings!$C$6)+11,1))),N(C13),0)) | AI13: =IF(OR(B13="",D13=""),0,IF(OR(E13="",E13=MONTH(DATE(YEAR(Settings!$C$6),MONTH(Settings!$C$6)+12,1))),N(C13),0)) | AJ13: =IF(B13="","",SUMIFS(J13:V13,J13:V13,">="&Dashboard!$C$4,J13:V13,"<"&Dashboard!$N$1,W13:AI13,">0")) | AK13: =IF(N(AJ13)=0,"",AJ13+ROW()/100000)
B14: Gym | C14: 35 | D14: 27 | F14: Health | G14: Yes | J14: =IF(OR(B14="",D14=""),"",DATE(YEAR(Settings!$C$6),MONTH(Settings!$C$6)+0,MIN(D14,DAY(EOMONTH(DATE(YEAR(Settings!$C$6),MONTH(Settings!$C$6)+0,1),0))))) | K14: =IF(OR(B14="",D14=""),"",DATE(YEAR(Settings!$C$6),MONTH(Settings!$C$6)+1,MIN(D14,DAY(EOMONTH(DATE(YEAR(Settings!$C$6),MONTH(Settings!$C$6)+1,1),0))))) | L14: =IF(OR(B14="",D14=""),"",DATE(YEAR(Settings!$C$6),MONTH(Settings!$C$6)+2,MIN(D14,DAY(EOMONTH(DATE(YEAR(Settings!$C$6),MONTH(Settings!$C$6)+2,1),0))))) | M14: =IF(OR(B14="",D14=""),"",DATE(YEAR(Settings!$C$6),MONTH(Settings!$C$6)+3,MIN(D14,DAY(EOMONTH(DATE(YEAR(Settings!$C$6),MONTH(Settings!$C$6)+3,1),0))))) | N14: =IF(OR(B14="",D14=""),"",DATE(YEAR(Settings!$C$6),MONTH(Settings!$C$6)+4,MIN(D14,DAY(EOMONTH(DATE(YEAR(Settings!$C$6),MONTH(Settings!$C$6)+4,1),0))))) | O14: =IF(OR(B14="",D14=""),"",DATE(YEAR(Settings!$C$6),MONTH(Settings!$C$6)+5,MIN(D14,DAY(EOMONTH(DATE(YEAR(Settings!$C$6),MONTH(Settings!$C$6)+5,1),0))))) | P14: =IF(OR(B14="",D14=""),"",DATE(YEAR(Settings!$C$6),MONTH(Settings!$C$6)+6,MIN(D14,DAY(EOMONTH(DATE(YEAR(Settings!$C$6),MONTH(Settings!$C$6)+6,1),0))))) | Q14: =IF(OR(B14="",D14=""),"",DATE(YEAR(Settings!$C$6),MONTH(Settings!$C$6)+7,MIN(D14,DAY(EOMONTH(DATE(YEAR(Settings!$C$6),MONTH(Settings!$C$6)+7,1),0))))) | R14: =IF(OR(B14="",D14=""),"",DATE(YEAR(Settings!$C$6),MONTH(Settings!$C$6)+8,MIN(D14,DAY(EOMONTH(DATE(YEAR(Settings!$C$6),MONTH(Settings!$C$6)+8,1),0))))) | S14: =IF(OR(B14="",D14=""),"",DATE(YEAR(Settings!$C$6),MONTH(Settings!$C$6)+9,MIN(D14,DAY(EOMONTH(DATE(YEAR(Settings!$C$6),MONTH(Settings!$C$6)+9,1),0))))) | T14: =IF(OR(B14="",D14=""),"",DATE(YEAR(Settings!$C$6),MONTH(Settings!$C$6)+10,MIN(D14,DAY(EOMONTH(DATE(YEAR(Settings!$C$6),MONTH(Settings!$C$6)+10,1),0))))) | U14: =IF(OR(B14="",D14=""),"",DATE(YEAR(Settings!$C$6),MONTH(Settings!$C$6)+11,MIN(D14,DAY(EOMONTH(DATE(YEAR(Settings!$C$6),MONTH(Settings!$C$6)+11,1),0))))) | V14: =IF(OR(B14="",D14=""),"",DATE(YEAR(Settings!$C$6),MONTH(Settings!$C$6)+12,MIN(D14,DAY(EOMONTH(DATE(YEAR(Settings!$C$6),MONTH(Settings!$C$6)+12,1),0))))) | W14: =IF(OR(B14="",D14=""),0,IF(OR(E14="",E14=MONTH(DATE(YEAR(Settings!$C$6),MONTH(Settings!$C$6)+0,1))),N(C14),0)) | X14: =IF(OR(B14="",D14=""),0,IF(OR(E14="",E14=MONTH(DATE(YEAR(Settings!$C$6),MONTH(Settings!$C$6)+1,1))),N(C14),0)) | Y14: =IF(OR(B14="",D14=""),0,IF(OR(E14="",E14=MONTH(DATE(YEAR(Settings!$C$6),MONTH(Settings!$C$6)+2,1))),N(C14),0)) | Z14: =IF(OR(B14="",D14=""),0,IF(OR(E14="",E14=MONTH(DATE(YEAR(Settings!$C$6),MONTH(Settings!$C$6)+3,1))),N(C14),0)) | AA14: =IF(OR(B14="",D14=""),0,IF(OR(E14="",E14=MONTH(DATE(YEAR(Settings!$C$6),MONTH(Settings!$C$6)+4,1))),N(C14),0)) | AB14: =IF(OR(B14="",D14=""),0,IF(OR(E14="",E14=MONTH(DATE(YEAR(Settings!$C$6),MONTH(Settings!$C$6)+5,1))),N(C14),0)) | AC14: =IF(OR(B14="",D14=""),0,IF(OR(E14="",E14=MONTH(DATE(YEAR(Settings!$C$6),MONTH(Settings!$C$6)+6,1))),N(C14),0)) | AD14: =IF(OR(B14="",D14=""),0,IF(OR(E14="",E14=MONTH(DATE(YEAR(Settings!$C$6),MONTH(Settings!$C$6)+7,1))),N(C14),0)) | AE14: =IF(OR(B14="",D14=""),0,IF(OR(E14="",E14=MONTH(DATE(YEAR(Settings!$C$6),MONTH(Settings!$C$6)+8,1))),N(C14),0)) | AF14: =IF(OR(B14="",D14=""),0,IF(OR(E14="",E14=MONTH(DATE(YEAR(Settings!$C$6),MONTH(Settings!$C$6)+9,1))),N(C14),0)) | AG14: =IF(OR(B14="",D14=""),0,IF(OR(E14="",E14=MONTH(DATE(YEAR(Settings!$C$6),MONTH(Settings!$C$6)+10,1))),N(C14),0)) | AH14: =IF(OR(B14="",D14=""),0,IF(OR(E14="",E14=MONTH(DATE(YEAR(Settings!$C$6),MONTH(Settings!$C$6)+11,1))),N(C14),0)) | AI14: =IF(OR(B14="",D14=""),0,IF(OR(E14="",E14=MONTH(DATE(YEAR(Settings!$C$6),MONTH(Settings!$C$6)+12,1))),N(C14),0)) | AJ14: =IF(B14="","",SUMIFS(J14:V14,J14:V14,">="&Dashboard!$C$4,J14:V14,"<"&Dashboard!$N$1,W14:AI14,">0")) | AK14: =IF(N(AJ14)=0,"",AJ14+ROW()/100000)
B15: Credit card minimum | C15: 75 | D15: 28 | F15: Debt | G15: No | J15: =IF(OR(B15="",D15=""),"",DATE(YEAR(Settings!$C$6),MONTH(Settings!$C$6)+0,MIN(D15,DAY(EOMONTH(DATE(YEAR(Settings!$C$6),MONTH(Settings!$C$6)+0,1),0))))) | K15: =IF(OR(B15="",D15=""),"",DATE(YEAR(Settings!$C$6),MONTH(Settings!$C$6)+1,MIN(D15,DAY(EOMONTH(DATE(YEAR(Settings!$C$6),MONTH(Settings!$C$6)+1,1),0))))) | L15: =IF(OR(B15="",D15=""),"",DATE(YEAR(Settings!$C$6),MONTH(Settings!$C$6)+2,MIN(D15,DAY(EOMONTH(DATE(YEAR(Settings!$C$6),MONTH(Settings!$C$6)+2,1),0))))) | M15: =IF(OR(B15="",D15=""),"",DATE(YEAR(Settings!$C$6),MONTH(Settings!$C$6)+3,MIN(D15,DAY(EOMONTH(DATE(YEAR(Settings!$C$6),MONTH(Settings!$C$6)+3,1),0))))) | N15: =IF(OR(B15="",D15=""),"",DATE(YEAR(Settings!$C$6),MONTH(Settings!$C$6)+4,MIN(D15,DAY(EOMONTH(DATE(YEAR(Settings!$C$6),MONTH(Settings!$C$6)+4,1),0))))) | O15: =IF(OR(B15="",D15=""),"",DATE(YEAR(Settings!$C$6),MONTH(Settings!$C$6)+5,MIN(D15,DAY(EOMONTH(DATE(YEAR(Settings!$C$6),MONTH(Settings!$C$6)+5,1),0))))) | P15: =IF(OR(B15="",D15=""),"",DATE(YEAR(Settings!$C$6),MONTH(Settings!$C$6)+6,MIN(D15,DAY(EOMONTH(DATE(YEAR(Settings!$C$6),MONTH(Settings!$C$6)+6,1),0))))) | Q15: =IF(OR(B15="",D15=""),"",DATE(YEAR(Settings!$C$6),MONTH(Settings!$C$6)+7,MIN(D15,DAY(EOMONTH(DATE(YEAR(Settings!$C$6),MONTH(Settings!$C$6)+7,1),0))))) | R15: =IF(OR(B15="",D15=""),"",DATE(YEAR(Settings!$C$6),MONTH(Settings!$C$6)+8,MIN(D15,DAY(EOMONTH(DATE(YEAR(Settings!$C$6),MONTH(Settings!$C$6)+8,1),0))))) | S15: =IF(OR(B15="",D15=""),"",DATE(YEAR(Settings!$C$6),MONTH(Settings!$C$6)+9,MIN(D15,DAY(EOMONTH(DATE(YEAR(Settings!$C$6),MONTH(Settings!$C$6)+9,1),0))))) | T15: =IF(OR(B15="",D15=""),"",DATE(YEAR(Settings!$C$6),MONTH(Settings!$C$6)+10,MIN(D15,DAY(EOMONTH(DATE(YEAR(Settings!$C$6),MONTH(Settings!$C$6)+10,1),0))))) | U15: =IF(OR(B15="",D15=""),"",DATE(YEAR(Settings!$C$6),MONTH(Settings!$C$6)+11,MIN(D15,DAY(EOMONTH(DATE(YEAR(Settings!$C$6),MONTH(Settings!$C$6)+11,1),0))))) | V15: =IF(OR(B15="",D15=""),"",DATE(YEAR(Settings!$C$6),MONTH(Settings!$C$6)+12,MIN(D15,DAY(EOMONTH(DATE(YEAR(Settings!$C$6),MONTH(Settings!$C$6)+12,1),0))))) | W15: =IF(OR(B15="",D15=""),0,IF(OR(E15="",E15=MONTH(DATE(YEAR(Settings!$C$6),MONTH(Settings!$C$6)+0,1))),N(C15),0)) | X15: =IF(OR(B15="",D15=""),0,IF(OR(E15="",E15=MONTH(DATE(YEAR(Settings!$C$6),MONTH(Settings!$C$6)+1,1))),N(C15),0)) | Y15: =IF(OR(B15="",D15=""),0,IF(OR(E15="",E15=MONTH(DATE(YEAR(Settings!$C$6),MONTH(Settings!$C$6)+2,1))),N(C15),0)) | Z15: =IF(OR(B15="",D15=""),0,IF(OR(E15="",E15=MONTH(DATE(YEAR(Settings!$C$6),MONTH(Settings!$C$6)+3,1))),N(C15),0)) | AA15: =IF(OR(B15="",D15=""),0,IF(OR(E15="",E15=MONTH(DATE(YEAR(Settings!$C$6),MONTH(Settings!$C$6)+4,1))),N(C15),0)) | AB15: =IF(OR(B15="",D15=""),0,IF(OR(E15="",E15=MONTH(DATE(YEAR(Settings!$C$6),MONTH(Settings!$C$6)+5,1))),N(C15),0)) | AC15: =IF(OR(B15="",D15=""),0,IF(OR(E15="",E15=MONTH(DATE(YEAR(Settings!$C$6),MONTH(Settings!$C$6)+6,1))),N(C15),0)) | AD15: =IF(OR(B15="",D15=""),0,IF(OR(E15="",E15=MONTH(DATE(YEAR(Settings!$C$6),MONTH(Settings!$C$6)+7,1))),N(C15),0)) | AE15: =IF(OR(B15="",D15=""),0,IF(OR(E15="",E15=MONTH(DATE(YEAR(Settings!$C$6),MONTH(Settings!$C$6)+8,1))),N(C15),0)) | AF15: =IF(OR(B15="",D15=""),0,IF(OR(E15="",E15=MONTH(DATE(YEAR(Settings!$C$6),MONTH(Settings!$C$6)+9,1))),N(C15),0)) | AG15: =IF(OR(B15="",D15=""),0,IF(OR(E15="",E15=MONTH(DATE(YEAR(Settings!$C$6),MONTH(Settings!$C$6)+10,1))),N(C15),0)) | AH15: =IF(OR(B15="",D15=""),0,IF(OR(E15="",E15=MONTH(DATE(YEAR(Settings!$C$6),MONTH(Settings!$C$6)+11,1))),N(C15),0)) | AI15: =IF(OR(B15="",D15=""),0,IF(OR(E15="",E15=MONTH(DATE(YEAR(Settings!$C$6),MONTH(Settings!$C$6)+12,1))),N(C15),0)) | AJ15: =IF(B15="","",SUMIFS(J15:V15,J15:V15,">="&Dashboard!$C$4,J15:V15,"<"&Dashboard!$N$1,W15:AI15,">0")) | AK15: =IF(N(AJ15)=0,"",AJ15+ROW()/100000)
B16: Renters insurance | C16: 180 | D16: 10 | E16: 3 | F16: Insurance | G16: No | H16: Once a year, in March | J16: =IF(OR(B16="",D16=""),"",DATE(YEAR(Settings!$C$6),MONTH(Settings!$C$6)+0,MIN(D16,DAY(EOMONTH(DATE(YEAR(Settings!$C$6),MONTH(Settings!$C$6)+0,1),0))))) | K16: =IF(OR(B16="",D16=""),"",DATE(YEAR(Settings!$C$6),MONTH(Settings!$C$6)+1,MIN(D16,DAY(EOMONTH(DATE(YEAR(Settings!$C$6),MONTH(Settings!$C$6)+1,1),0))))) | L16: =IF(OR(B16="",D16=""),"",DATE(YEAR(Settings!$C$6),MONTH(Settings!$C$6)+2,MIN(D16,DAY(EOMONTH(DATE(YEAR(Settings!$C$6),MONTH(Settings!$C$6)+2,1),0))))) | M16: =IF(OR(B16="",D16=""),"",DATE(YEAR(Settings!$C$6),MONTH(Settings!$C$6)+3,MIN(D16,DAY(EOMONTH(DATE(YEAR(Settings!$C$6),MONTH(Settings!$C$6)+3,1),0))))) | N16: =IF(OR(B16="",D16=""),"",DATE(YEAR(Settings!$C$6),MONTH(Settings!$C$6)+4,MIN(D16,DAY(EOMONTH(DATE(YEAR(Settings!$C$6),MONTH(Settings!$C$6)+4,1),0))))) | O16: =IF(OR(B16="",D16=""),"",DATE(YEAR(Settings!$C$6),MONTH(Settings!$C$6)+5,MIN(D16,DAY(EOMONTH(DATE(YEAR(Settings!$C$6),MONTH(Settings!$C$6)+5,1),0))))) | P16: =IF(OR(B16="",D16=""),"",DATE(YEAR(Settings!$C$6),MONTH(Settings!$C$6)+6,MIN(D16,DAY(EOMONTH(DATE(YEAR(Settings!$C$6),MONTH(Settings!$C$6)+6,1),0))))) | Q16: =IF(OR(B16="",D16=""),"",DATE(YEAR(Settings!$C$6),MONTH(Settings!$C$6)+7,MIN(D16,DAY(EOMONTH(DATE(YEAR(Settings!$C$6),MONTH(Settings!$C$6)+7,1),0))))) | R16: =IF(OR(B16="",D16=""),"",DATE(YEAR(Settings!$C$6),MONTH(Settings!$C$6)+8,MIN(D16,DAY(EOMONTH(DATE(YEAR(Settings!$C$6),MONTH(Settings!$C$6)+8,1),0))))) | S16: =IF(OR(B16="",D16=""),"",DATE(YEAR(Settings!$C$6),MONTH(Settings!$C$6)+9,MIN(D16,DAY(EOMONTH(DATE(YEAR(Settings!$C$6),MONTH(Settings!$C$6)+9,1),0))))) | T16: =IF(OR(B16="",D16=""),"",DATE(YEAR(Settings!$C$6),MONTH(Settings!$C$6)+10,MIN(D16,DAY(EOMONTH(DATE(YEAR(Settings!$C$6),MONTH(Settings!$C$6)+10,1),0))))) | U16: =IF(OR(B16="",D16=""),"",DATE(YEAR(Settings!$C$6),MONTH(Settings!$C$6)+11,MIN(D16,DAY(EOMONTH(DATE(YEAR(Settings!$C$6),MONTH(Settings!$C$6)+11,1),0))))) | V16: =IF(OR(B16="",D16=""),"",DATE(YEAR(Settings!$C$6),MONTH(Settings!$C$6)+12,MIN(D16,DAY(EOMONTH(DATE(YEAR(Settings!$C$6),MONTH(Settings!$C$6)+12,1),0))))) | W16: =IF(OR(B16="",D16=""),0,IF(OR(E16="",E16=MONTH(DATE(YEAR(Settings!$C$6),MONTH(Settings!$C$6)+0,1))),N(C16),0)) | X16: =IF(OR(B16="",D16=""),0,IF(OR(E16="",E16=MONTH(DATE(YEAR(Settings!$C$6),MONTH(Settings!$C$6)+1,1))),N(C16),0)) | Y16: =IF(OR(B16="",D16=""),0,IF(OR(E16="",E16=MONTH(DATE(YEAR(Settings!$C$6),MONTH(Settings!$C$6)+2,1))),N(C16),0)) | Z16: =IF(OR(B16="",D16=""),0,IF(OR(E16="",E16=MONTH(DATE(YEAR(Settings!$C$6),MONTH(Settings!$C$6)+3,1))),N(C16),0)) | AA16: =IF(OR(B16="",D16=""),0,IF(OR(E16="",E16=MONTH(DATE(YEAR(Settings!$C$6),MONTH(Settings!$C$6)+4,1))),N(C16),0)) | AB16: =IF(OR(B16="",D16=""),0,IF(OR(E16="",E16=MONTH(DATE(YEAR(Settings!$C$6),MONTH(Settings!$C$6)+5,1))),N(C16),0)) | AC16: =IF(OR(B16="",D16=""),0,IF(OR(E16="",E16=MONTH(DATE(YEAR(Settings!$C$6),MONTH(Settings!$C$6)+6,1))),N(C16),0)) | AD16: =IF(OR(B16="",D16=""),0,IF(OR(E16="",E16=MONTH(DATE(YEAR(Settings!$C$6),MONTH(Settings!$C$6)+7,1))),N(C16),0)) | AE16: =IF(OR(B16="",D16=""),0,IF(OR(E16="",E16=MONTH(DATE(YEAR(Settings!$C$6),MONTH(Settings!$C$6)+8,1))),N(C16),0)) | AF16: =IF(OR(B16="",D16=""),0,IF(OR(E16="",E16=MONTH(DATE(YEAR(Settings!$C$6),MONTH(Settings!$C$6)+9,1))),N(C16),0)) | AG16: =IF(OR(B16="",D16=""),0,IF(OR(E16="",E16=MONTH(DATE(YEAR(Settings!$C$6),MONTH(Settings!$C$6)+10,1))),N(C16),0)) | AH16: =IF(OR(B16="",D16=""),0,IF(OR(E16="",E16=MONTH(DATE(YEAR(Settings!$C$6),MONTH(Settings!$C$6)+11,1))),N(C16),0)) | AI16: =IF(OR(B16="",D16=""),0,IF(OR(E16="",E16=MONTH(DATE(YEAR(Settings!$C$6),MONTH(Settings!$C$6)+12,1))),N(C16),0)) | AJ16: =IF(B16="","",SUMIFS(J16:V16,J16:V16,">="&Dashboard!$C$4,J16:V16,"<"&Dashboard!$N$1,W16:AI16,">0")) | AK16: =IF(N(AJ16)=0,"",AJ16+ROW()/100000)
J17: =IF(OR(B17="",D17=""),"",DATE(YEAR(Settings!$C$6),MONTH(Settings!$C$6)+0,MIN(D17,DAY(EOMONTH(DATE(YEAR(Settings!$C$6),MONTH(Settings!$C$6)+0,1),0))))) | K17: =IF(OR(B17="",D17=""),"",DATE(YEAR(Settings!$C$6),MONTH(Settings!$C$6)+1,MIN(D17,DAY(EOMONTH(DATE(YEAR(Settings!$C$6),MONTH(Settings!$C$6)+1,1),0))))) | L17: =IF(OR(B17="",D17=""),"",DATE(YEAR(Settings!$C$6),MONTH(Settings!$C$6)+2,MIN(D17,DAY(EOMONTH(DATE(YEAR(Settings!$C$6),MONTH(Settings!$C$6)+2,1),0))))) | M17: =IF(OR(B17="",D17=""),"",DATE(YEAR(Settings!$C$6),MONTH(Settings!$C$6)+3,MIN(D17,DAY(EOMONTH(DATE(YEAR(Settings!$C$6),MONTH(Settings!$C$6)+3,1),0))))) | N17: =IF(OR(B17="",D17=""),"",DATE(YEAR(Settings!$C$6),MONTH(Settings!$C$6)+4,MIN(D17,DAY(EOMONTH(DATE(YEAR(Settings!$C$6),MONTH(Settings!$C$6)+4,1),0))))) | O17: =IF(OR(B17="",D17=""),"",DATE(YEAR(Settings!$C$6),MONTH(Settings!$C$6)+5,MIN(D17,DAY(EOMONTH(DATE(YEAR(Settings!$C$6),MONTH(Settings!$C$6)+5,1),0))))) | P17: =IF(OR(B17="",D17=""),"",DATE(YEAR(Settings!$C$6),MONTH(Settings!$C$6)+6,MIN(D17,DAY(EOMONTH(DATE(YEAR(Settings!$C$6),MONTH(Settings!$C$6)+6,1),0))))) | Q17: =IF(OR(B17="",D17=""),"",DATE(YEAR(Settings!$C$6),MONTH(Settings!$C$6)+7,MIN(D17,DAY(EOMONTH(DATE(YEAR(Settings!$C$6),MONTH(Settings!$C$6)+7,1),0))))) | R17: =IF(OR(B17="",D17=""),"",DATE(YEAR(Settings!$C$6),MONTH(Settings!$C$6)+8,MIN(D17,DAY(EOMONTH(DATE(YEAR(Settings!$C$6),MONTH(Settings!$C$6)+8,1),0))))) | S17: =IF(OR(B17="",D17=""),"",DATE(YEAR(Settings!$C$6),MONTH(Settings!$C$6)+9,MIN(D17,DAY(EOMONTH(DATE(YEAR(Settings!$C$6),MONTH(Settings!$C$6)+9,1),0))))) | T17: =IF(OR(B17="",D17=""),"",DATE(YEAR(Settings!$C$6),MONTH(Settings!$C$6)+10,MIN(D17,DAY(EOMONTH(DATE(YEAR(Settings!$C$6),MONTH(Settings!$C$6)+10,1),0))))) | U17: =IF(OR(B17="",D17=""),"",DATE(YEAR(Settings!$C$6),MONTH(Settings!$C$6)+11,MIN(D17,DAY(EOMONTH(DATE(YEAR(Settings!$C$6),MONTH(Settings!$C$6)+11,1),0))))) | V17: =IF(OR(B17="",D17=""),"",DATE(YEAR(Settings!$C$6),MONTH(Settings!$C$6)+12,MIN(D17,DAY(EOMONTH(DATE(YEAR(Settings!$C$6),MONTH(Settings!$C$6)+12,1),0))))) | W17: =IF(OR(B17="",D17=""),0,IF(OR(E17="",E17=MONTH(DATE(YEAR(Settings!$C$6),MONTH(Settings!$C$6)+0,1))),N(C17),0)) | X17: =IF(OR(B17="",D17=""),0,IF(OR(E17="",E17=MONTH(DATE(YEAR(Settings!$C$6),MONTH(Settings!$C$6)+1,1))),N(C17),0)) | Y17: =IF(OR(B17="",D17=""),0,IF(OR(E17="",E17=MONTH(DATE(YEAR(Settings!$C$6),MONTH(Settings!$C$6)+2,1))),N(C17),0)) | Z17: =IF(OR(B17="",D17=""),0,IF(OR(E17="",E17=MONTH(DATE(YEAR(Settings!$C$6),MONTH(Settings!$C$6)+3,1))),N(C17),0)) | AA17: =IF(OR(B17="",D17=""),0,IF(OR(E17="",E17=MONTH(DATE(YEAR(Settings!$C$6),MONTH(Settings!$C$6)+4,1))),N(C17),0)) | AB17: =IF(OR(B17="",D17=""),0,IF(OR(E17="",E17=MONTH(DATE(YEAR(Settings!$C$6),MONTH(Settings!$C$6)+5,1))),N(C17),0)) | AC17: =IF(OR(B17="",D17=""),0,IF(OR(E17="",E17=MONTH(DATE(YEAR(Settings!$C$6),MONTH(Settings!$C$6)+6,1))),N(C17),0)) | AD17: =IF(OR(B17="",D17=""),0,IF(OR(E17="",E17=MONTH(DATE(YEAR(Settings!$C$6),MONTH(Settings!$C$6)+7,1))),N(C17),0)) | AE17: =IF(OR(B17="",D17=""),0,IF(OR(E17="",E17=MONTH(DATE(YEAR(Settings!$C$6),MONTH(Settings!$C$6)+8,1))),N(C17),0)) | AF17: =IF(OR(B17="",D17=""),0,IF(OR(E17="",E17=MONTH(DATE(YEAR(Settings!$C$6),MONTH(Settings!$C$6)+9,1))),N(C17),0)) | AG17: =IF(OR(B17="",D17=""),0,IF(OR(E17="",E17=MONTH(DATE(YEAR(Settings!$C$6),MONTH(Settings!$C$6)+10,1))),N(C17),0)) | AH17: =IF(OR(B17="",D17=""),0,IF(OR(E17="",E17=MONTH(DATE(YEAR(Settings!$C$6),MONTH(Settings!$C$6)+11,1))),N(C17),0)) | AI17: =IF(OR(B17="",D17=""),0,IF(OR(E17="",E17=MONTH(DATE(YEAR(Settings!$C$6),MONTH(Settings!$C$6)+12,1))),N(C17),0)) | AJ17: =IF(B17="","",SUMIFS(J17:V17,J17:V17,">="&Dashboard!$C$4,J17:V17,"<"&Dashboard!$N$1,W17:AI17,">0")) | AK17: =IF(N(AJ17)=0,"",AJ17+ROW()/100000)
J18: =IF(OR(B18="",D18=""),"",DATE(YEAR(Settings!$C$6),MONTH(Settings!$C$6)+0,MIN(D18,DAY(EOMONTH(DATE(YEAR(Settings!$C$6),MONTH(Settings!$C$6)+0,1),0))))) | K18: =IF(OR(B18="",D18=""),"",DATE(YEAR(Settings!$C$6),MONTH(Settings!$C$6)+1,MIN(D18,DAY(EOMONTH(DATE(YEAR(Settings!$C$6),MONTH(Settings!$C$6)+1,1),0))))) | L18: =IF(OR(B18="",D18=""),"",DATE(YEAR(Settings!$C$6),MONTH(Settings!$C$6)+2,MIN(D18,DAY(EOMONTH(DATE(YEAR(Settings!$C$6),MONTH(Settings!$C$6)+2,1),0))))) | M18: =IF(OR(B18="",D18=""),"",DATE(YEAR(Settings!$C$6),MONTH(Settings!$C$6)+3,MIN(D18,DAY(EOMONTH(DATE(YEAR(Settings!$C$6),MONTH(Settings!$C$6)+3,1),0))))) | N18: =IF(OR(B18="",D18=""),"",DATE(YEAR(Settings!$C$6),MONTH(Settings!$C$6)+4,MIN(D18,DAY(EOMONTH(DATE(YEAR(Settings!$C$6),MONTH(Settings!$C$6)+4,1),0))))) | O18: =IF(OR(B18="",D18=""),"",DATE(YEAR(Settings!$C$6),MONTH(Settings!$C$6)+5,MIN(D18,DAY(EOMONTH(DATE(YEAR(Settings!$C$6),MONTH(Settings!$C$6)+5,1),0))))) | P18: =IF(OR(B18="",D18=""),"",DATE(YEAR(Settings!$C$6),MONTH(Settings!$C$6)+6,MIN(D18,DAY(EOMONTH(DATE(YEAR(Settings!$C$6),MONTH(Settings!$C$6)+6,1),0))))) | Q18: =IF(OR(B18="",D18=""),"",DATE(YEAR(Settings!$C$6),MONTH(Settings!$C$6)+7,MIN(D18,DAY(EOMONTH(DATE(YEAR(Settings!$C$6),MONTH(Settings!$C$6)+7,1),0))))) | R18: =IF(OR(B18="",D18=""),"",DATE(YEAR(Settings!$C$6),MONTH(Settings!$C$6)+8,MIN(D18,DAY(EOMONTH(DATE(YEAR(Settings!$C$6),MONTH(Settings!$C$6)+8,1),0))))) | S18: =IF(OR(B18="",D18=""),"",DATE(YEAR(Settings!$C$6),MONTH(Settings!$C$6)+9,MIN(D18,DAY(EOMONTH(DATE(YEAR(Settings!$C$6),MONTH(Settings!$C$6)+9,1),0))))) | T18: =IF(OR(B18="",D18=""),"",DATE(YEAR(Settings!$C$6),MONTH(Settings!$C$6)+10,MIN(D18,DAY(EOMONTH(DATE(YEAR(Settings!$C$6),MONTH(Settings!$C$6)+10,1),0))))) | U18: =IF(OR(B18="",D18=""),"",DATE(YEAR(Settings!$C$6),MONTH(Settings!$C$6)+11,MIN(D18,DAY(EOMONTH(DATE(YEAR(Settings!$C$6),MONTH(Settings!$C$6)+11,1),0))))) | V18: =IF(OR(B18="",D18=""),"",DATE(YEAR(Settings!$C$6),MONTH(Settings!$C$6)+12,MIN(D18,DAY(EOMONTH(DATE(YEAR(Settings!$C$6),MONTH(Settings!$C$6)+12,1),0))))) | W18: =IF(OR(B18="",D18=""),0,IF(OR(E18="",E18=MONTH(DATE(YEAR(Settings!$C$6),MONTH(Settings!$C$6)+0,1))),N(C18),0)) | X18: =IF(OR(B18="",D18=""),0,IF(OR(E18="",E18=MONTH(DATE(YEAR(Settings!$C$6),MONTH(Settings!$C$6)+1,1))),N(C18),0)) | Y18: =IF(OR(B18="",D18=""),0,IF(OR(E18="",E18=MONTH(DATE(YEAR(Settings!$C$6),MONTH(Settings!$C$6)+2,1))),N(C18),0)) | Z18: =IF(OR(B18="",D18=""),0,IF(OR(E18="",E18=MONTH(DATE(YEAR(Settings!$C$6),MONTH(Settings!$C$6)+3,1))),N(C18),0)) | AA18: =IF(OR(B18="",D18=""),0,IF(OR(E18="",E18=MONTH(DATE(YEAR(Settings!$C$6),MONTH(Settings!$C$6)+4,1))),N(C18),0)) | AB18: =IF(OR(B18="",D18=""),0,IF(OR(E18="",E18=MONTH(DATE(YEAR(Settings!$C$6),MONTH(Settings!$C$6)+5,1))),N(C18),0)) | AC18: =IF(OR(B18="",D18=""),0,IF(OR(E18="",E18=MONTH(DATE(YEAR(Settings!$C$6),MONTH(Settings!$C$6)+6,1))),N(C18),0)) | AD18: =IF(OR(B18="",D18=""),0,IF(OR(E18="",E18=MONTH(DATE(YEAR(Settings!$C$6),MONTH(Settings!$C$6)+7,1))),N(C18),0)) | AE18: =IF(OR(B18="",D18=""),0,IF(OR(E18="",E18=MONTH(DATE(YEAR(Settings!$C$6),MONTH(Settings!$C$6)+8,1))),N(C18),0)) | AF18: =IF(OR(B18="",D18=""),0,IF(OR(E18="",E18=MONTH(DATE(YEAR(Settings!$C$6),MONTH(Settings!$C$6)+9,1))),N(C18),0)) | AG18: =IF(OR(B18="",D18=""),0,IF(OR(E18="",E18=MONTH(DATE(YEAR(Settings!$C$6),MONTH(Settings!$C$6)+10,1))),N(C18),0)) | AH18: =IF(OR(B18="",D18=""),0,IF(OR(E18="",E18=MONTH(DATE(YEAR(Settings!$C$6),MONTH(Settings!$C$6)+11,1))),N(C18),0)) | AI18: =IF(OR(B18="",D18=""),0,IF(OR(E18="",E18=MONTH(DATE(YEAR(Settings!$C$6),MONTH(Settings!$C$6)+12,1))),N(C18),0)) | AJ18: =IF(B18="","",SUMIFS(J18:V18,J18:V18,">="&Dashboard!$C$4,J18:V18,"<"&Dashboard!$N$1,W18:AI18,">0")) | AK18: =IF(N(AJ18)=0,"",AJ18+ROW()/100000)
