Workbook

Sheet Dashboard
V1: =DATE(YEAR(Settings!$C$6),MONTH(Settings!$C$6),1)
B2: Cash envelopes | V2: =DATE(YEAR(Settings!$C$6),MONTH(Settings!$C$6)+1,1)-1
B3: =CHOOSE(MONTH(V1),"January","February","March","April","May","June","July","August","September","October","November","December")&" "&YEAR(V1)&": what went into each envelope, what came out, and what is left."
B4: In your envelopes | C4: Stuffed | D4: Spent | E4: Left to spend | F4: In sinking funds | G4: Low now | J4: Plan per payday | K4: Last payday
B5: =SUM(Envelopes!$L$6:$L$21) | C5: =SUM(D8:D23) | D5: =SUM(E8:E23) | E5: =SUMIFS(G8:G23,Q8:Q23,"Spending") | F5: =SUMIFS(G8:G23,Q8:Q23,"Sinking fund") | G5: =COUNTIF(Envelopes!$M$6:$M$21,"Low") | J5: =SUM(Envelopes!$D$6:$D$21) | K5: =IF(COUNT(Paydays!$B$6:$B$205)=0,"",MAX(Paydays!$B$6:$B$205))
B7: Envelope | C7: Carried in | D7: Stuffed | E7: Spent | F7: Moved | G7: Left | H7: Used | J7: Sinking fund | K7: Target | L7: Saved | N7: By | O7: Per payday
B8: =IF(Envelopes!$B$6="","",Envelopes!$B$6) | C8: =IF(B8="","",N(Envelopes!$H$6)+SUMIFS(Paydays!$E$6:$E$205,Paydays!$W$6:$W$205,">0",Paydays!$W$6:$W$205,"<"&Dashboard!$V$1)-SUMIFS(Spending!$D$6:$D$1005,Spending!$C$6:$C$1005,Envelopes!$B$6,Spending!$I$6:$I$1005,1,Spending!$H$6:$H$1005,"<"&Dashboard!$V$1)+SUMIFS(Spending!$D$6:$D$1005,Spending!$F$6:$F$1005,Envelopes!$B$6,Spending!$J$6:$J$1005,1,Spending!$H$6:$H$1005,"<"&Dashboard!$V$1)-SUMIFS(Spending!$D$6:$D$1005,Spending!$C$6:$C$1005,Envelopes!$B$6,Spending!$J$6:$J$1005,1,Spending!$H$6:$H$1005,"<"&Dashboard!$V$1)) | D8: =IF(B8="","",SUMIFS(Paydays!$E$6:$E$205,Paydays!$W$6:$W$205,">0",Paydays!$W$6:$W$205,">="&Dashboard!$V$1,Paydays!$W$6:$W$205,"<="&Dashboard!$V$2)) | E8: =IF(B8="","",SUMIFS(Spending!$D$6:$D$1005,Spending!$C$6:$C$1005,Envelopes!$B$6,Spending!$I$6:$I$1005,1,Spending!$H$6:$H$1005,">="&Dashboard!$V$1,Spending!$H$6:$H$1005,"<="&Dashboard!$V$2)) | F8: =IF(B8="","",SUMIFS(Spending!$D$6:$D$1005,Spending!$F$6:$F$1005,Envelopes!$B$6,Spending!$J$6:$J$1005,1,Spending!$H$6:$H$1005,">="&Dashboard!$V$1,Spending!$H$6:$H$1005,"<="&Dashboard!$V$2)-SUMIFS(Spending!$D$6:$D$1005,Spending!$C$6:$C$1005,Envelopes!$B$6,Spending!$J$6:$J$1005,1,Spending!$H$6:$H$1005,">="&Dashboard!$V$1,Spending!$H$6:$H$1005,"<="&Dashboard!$V$2)) | G8: =IF(B8="","",C8+D8-E8+F8) | H8: =IF(B8="","",IF(C8+D8+MAX(0,F8)<=0,"",REPT("█",MIN(10,MAX(0,ROUND((E8/(C8+D8+MAX(0,F8)))*10,0))))&REPT("░",10-MIN(10,MAX(0,ROUND((E8/(C8+D8+MAX(0,F8)))*10,0)))))) | J8: =IF(S8="","",INDEX(Envelopes!$B$1:$B$21,S8)) | K8: =IF(S8="","",IF(N(INDEX(Envelopes!$F$1:$F$21,S8))=0,"",INDEX(Envelopes!$F$1:$F$21,S8))) | L8: =IF(S8="","",INDEX(Envelopes!$L$1:$L$21,S8)) | M8: =IF(OR(S8="",K8=""),"",REPT("█",MIN(10,MAX(0,ROUND((L8/K8)*10,0))))&REPT("░",10-MIN(10,MAX(0,ROUND((L8/K8)*10,0))))) | N8: =IF(S8="","",IF(INDEX(Envelopes!$G$1:$G$21,S8)="","",INDEX(Envelopes!$G$1:$G$21,S8))) | O8: =IF(S8="","",IF(INDEX(Envelopes!$M$1:$M$21,S8)="Reached","Reached",IF(INDEX(Envelopes!$N$1:$N$21,S8)="","",INDEX(Envelopes!$N$1:$N$21,S8)))) | Q8: =IF(B8="","",IF(Envelopes!$C$6="Sinking fund","Sinking fund","Spending")) | R8: =IF(B8="","",Envelopes!$M$6) | S8: =IFERROR(SMALL(Envelopes!$P$6:$P$21,1),"")
B9: =IF(Envelopes!$B$7="","",Envelopes!$B$7) | C9: =IF(B9="","",N(Envelopes!$H$7)+SUMIFS(Paydays!$F$6:$F$205,Paydays!$W$6:$W$205,">0",Paydays!$W$6:$W$205,"<"&Dashboard!$V$1)-SUMIFS(Spending!$D$6:$D$1005,Spending!$C$6:$C$1005,Envelopes!$B$7,Spending!$I$6:$I$1005,1,Spending!$H$6:$H$1005,"<"&Dashboard!$V$1)+SUMIFS(Spending!$D$6:$D$1005,Spending!$F$6:$F$1005,Envelopes!$B$7,Spending!$J$6:$J$1005,1,Spending!$H$6:$H$1005,"<"&Dashboard!$V$1)-SUMIFS(Spending!$D$6:$D$1005,Spending!$C$6:$C$1005,Envelopes!$B$7,Spending!$J$6:$J$1005,1,Spending!$H$6:$H$1005,"<"&Dashboard!$V$1)) | D9: =IF(B9="","",SUMIFS(Paydays!$F$6:$F$205,Paydays!$W$6:$W$205,">0",Paydays!$W$6:$W$205,">="&Dashboard!$V$1,Paydays!$W$6:$W$205,"<="&Dashboard!$V$2)) | E9: =IF(B9="","",SUMIFS(Spending!$D$6:$D$1005,Spending!$C$6:$C$1005,Envelopes!$B$7,Spending!$I$6:$I$1005,1,Spending!$H$6:$H$1005,">="&Dashboard!$V$1,Spending!$H$6:$H$1005,"<="&Dashboard!$V$2)) | F9: =IF(B9="","",SUMIFS(Spending!$D$6:$D$1005,Spending!$F$6:$F$1005,Envelopes!$B$7,Spending!$J$6:$J$1005,1,Spending!$H$6:$H$1005,">="&Dashboard!$V$1,Spending!$H$6:$H$1005,"<="&Dashboard!$V$2)-SUMIFS(Spending!$D$6:$D$1005,Spending!$C$6:$C$1005,Envelopes!$B$7,Spending!$J$6:$J$1005,1,Spending!$H$6:$H$1005,">="&Dashboard!$V$1,Spending!$H$6:$H$1005,"<="&Dashboard!$V$2)) | G9: =IF(B9="","",C9+D9-E9+F9) | H9: =IF(B9="","",IF(C9+D9+MAX(0,F9)<=0,"",REPT("█",MIN(10,MAX(0,ROUND((E9/(C9+D9+MAX(0,F9)))*10,0))))&REPT("░",10-MIN(10,MAX(0,ROUND((E9/(C9+D9+MAX(0,F9)))*10,0)))))) | J9: =IF(S9="","",INDEX(Envelopes!$B$1:$B$21,S9)) | K9: =IF(S9="","",IF(N(INDEX(Envelopes!$F$1:$F$21,S9))=0,"",INDEX(Envelopes!$F$1:$F$21,S9))) | L9: =IF(S9="","",INDEX(Envelopes!$L$1:$L$21,S9)) | M9: =IF(OR(S9="",K9=""),"",REPT("█",MIN(10,MAX(0,ROUND((L9/K9)*10,0))))&REPT("░",10-MIN(10,MAX(0,ROUND((L9/K9)*10,0))))) | N9: =IF(S9="","",IF(INDEX(Envelopes!$G$1:$G$21,S9)="","",INDEX(Envelopes!$G$1:$G$21,S9))) | O9: =IF(S9="","",IF(INDEX(Envelopes!$M$1:$M$21,S9)="Reached","Reached",IF(INDEX(Envelopes!$N$1:$N$21,S9)="","",INDEX(Envelopes!$N$1:$N$21,S9)))) | Q9: =IF(B9="","",IF(Envelopes!$C$7="Sinking fund","Sinking fund","Spending")) | R9: =IF(B9="","",Envelopes!$M$7) | S9: =IFERROR(SMALL(Envelopes!$P$6:$P$21,2),"")
B10: =IF(Envelopes!$B$8="","",Envelopes!$B$8) | C10: =IF(B10="","",N(Envelopes!$H$8)+SUMIFS(Paydays!$G$6:$G$205,Paydays!$W$6:$W$205,">0",Paydays!$W$6:$W$205,"<"&Dashboard!$V$1)-SUMIFS(Spending!$D$6:$D$1005,Spending!$C$6:$C$1005,Envelopes!$B$8,Spending!$I$6:$I$1005,1,Spending!$H$6:$H$1005,"<"&Dashboard!$V$1)+SUMIFS(Spending!$D$6:$D$1005,Spending!$F$6:$F$1005,Envelopes!$B$8,Spending!$J$6:$J$1005,1,Spending!$H$6:$H$1005,"<"&Dashboard!$V$1)-SUMIFS(Spending!$D$6:$D$1005,Spending!$C$6:$C$1005,Envelopes!$B$8,Spending!$J$6:$J$1005,1,Spending!$H$6:$H$1005,"<"&Dashboard!$V$1)) | D10: =IF(B10="","",SUMIFS(Paydays!$G$6:$G$205,Paydays!$W$6:$W$205,">0",Paydays!$W$6:$W$205,">="&Dashboard!$V$1,Paydays!$W$6:$W$205,"<="&Dashboard!$V$2)) | E10: =IF(B10="","",SUMIFS(Spending!$D$6:$D$1005,Spending!$C$6:$C$1005,Envelopes!$B$8,Spending!$I$6:$I$1005,1,Spending!$H$6:$H$1005,">="&Dashboard!$V$1,Spending!$H$6:$H$1005,"<="&Dashboard!$V$2)) | F10: =IF(B10="","",SUMIFS(Spending!$D$6:$D$1005,Spending!$F$6:$F$1005,Envelopes!$B$8,Spending!$J$6:$J$1005,1,Spending!$H$6:$H$1005,">="&Dashboard!$V$1,Spending!$H$6:$H$1005,"<="&Dashboard!$V$2)-SUMIFS(Spending!$D$6:$D$1005,Spending!$C$6:$C$1005,Envelopes!$B$8,Spending!$J$6:$J$1005,1,Spending!$H$6:$H$1005,">="&Dashboard!$V$1,Spending!$H$6:$H$1005,"<="&Dashboard!$V$2)) | G10: =IF(B10="","",C10+D10-E10+F10) | H10: =IF(B10="","",IF(C10+D10+MAX(0,F10)<=0,"",REPT("█",MIN(10,MAX(0,ROUND((E10/(C10+D10+MAX(0,F10)))*10,0))))&REPT("░",10-MIN(10,MAX(0,ROUND((E10/(C10+D10+MAX(0,F10)))*10,0)))))) | J10: =IF(S10="","",INDEX(Envelopes!$B$1:$B$21,S10)) | K10: =IF(S10="","",IF(N(INDEX(Envelopes!$F$1:$F$21,S10))=0,"",INDEX(Envelopes!$F$1:$F$21,S10))) | L10: =IF(S10="","",INDEX(Envelopes!$L$1:$L$21,S10)) | M10: =IF(OR(S10="",K10=""),"",REPT("█",MIN(10,MAX(0,ROUND((L10/K10)*10,0))))&REPT("░",10-MIN(10,MAX(0,ROUND((L10/K10)*10,0))))) | N10: =IF(S10="","",IF(INDEX(Envelopes!$G$1:$G$21,S10)="","",INDEX(Envelopes!$G$1:$G$21,S10))) | O10: =IF(S10="","",IF(INDEX(Envelopes!$M$1:$M$21,S10)="Reached","Reached",IF(INDEX(Envelopes!$N$1:$N$21,S10)="","",INDEX(Envelopes!$N$1:$N$21,S10)))) | Q10: =IF(B10="","",IF(Envelopes!$C$8="Sinking fund","Sinking fund","Spending")) | R10: =IF(B10="","",Envelopes!$M$8) | S10: =IFERROR(SMALL(Envelopes!$P$6:$P$21,3),"")
B11: =IF(Envelopes!$B$9="","",Envelopes!$B$9) | C11: =IF(B11="","",N(Envelopes!$H$9)+SUMIFS(Paydays!$H$6:$H$205,Paydays!$W$6:$W$205,">0",Paydays!$W$6:$W$205,"<"&Dashboard!$V$1)-SUMIFS(Spending!$D$6:$D$1005,Spending!$C$6:$C$1005,Envelopes!$B$9,Spending!$I$6:$I$1005,1,Spending!$H$6:$H$1005,"<"&Dashboard!$V$1)+SUMIFS(Spending!$D$6:$D$1005,Spending!$F$6:$F$1005,Envelopes!$B$9,Spending!$J$6:$J$1005,1,Spending!$H$6:$H$1005,"<"&Dashboard!$V$1)-SUMIFS(Spending!$D$6:$D$1005,Spending!$C$6:$C$1005,Envelopes!$B$9,Spending!$J$6:$J$1005,1,Spending!$H$6:$H$1005,"<"&Dashboard!$V$1)) | D11: =IF(B11="","",SUMIFS(Paydays!$H$6:$H$205,Paydays!$W$6:$W$205,">0",Paydays!$W$6:$W$205,">="&Dashboard!$V$1,Paydays!$W$6:$W$205,"<="&Dashboard!$V$2)) | E11: =IF(B11="","",SUMIFS(Spending!$D$6:$D$1005,Spending!$C$6:$C$1005,Envelopes!$B$9,Spending!$I$6:$I$1005,1,Spending!$H$6:$H$1005,">="&Dashboard!$V$1,Spending!$H$6:$H$1005,"<="&Dashboard!$V$2)) | F11: =IF(B11="","",SUMIFS(Spending!$D$6:$D$1005,Spending!$F$6:$F$1005,Envelopes!$B$9,Spending!$J$6:$J$1005,1,Spending!$H$6:$H$1005,">="&Dashboard!$V$1,Spending!$H$6:$H$1005,"<="&Dashboard!$V$2)-SUMIFS(Spending!$D$6:$D$1005,Spending!$C$6:$C$1005,Envelopes!$B$9,Spending!$J$6:$J$1005,1,Spending!$H$6:$H$1005,">="&Dashboard!$V$1,Spending!$H$6:$H$1005,"<="&Dashboard!$V$2)) | G11: =IF(B11="","",C11+D11-E11+F11) | H11: =IF(B11="","",IF(C11+D11+MAX(0,F11)<=0,"",REPT("█",MIN(10,MAX(0,ROUND((E11/(C11+D11+MAX(0,F11)))*10,0))))&REPT("░",10-MIN(10,MAX(0,ROUND((E11/(C11+D11+MAX(0,F11)))*10,0)))))) | J11: =IF(S11="","",INDEX(Envelopes!$B$1:$B$21,S11)) | K11: =IF(S11="","",IF(N(INDEX(Envelopes!$F$1:$F$21,S11))=0,"",INDEX(Envelopes!$F$1:$F$21,S11))) | L11: =IF(S11="","",INDEX(Envelopes!$L$1:$L$21,S11)) | M11: =IF(OR(S11="",K11=""),"",REPT("█",MIN(10,MAX(0,ROUND((L11/K11)*10,0))))&REPT("░",10-MIN(10,MAX(0,ROUND((L11/K11)*10,0))))) | N11: =IF(S11="","",IF(INDEX(Envelopes!$G$1:$G$21,S11)="","",INDEX(Envelopes!$G$1:$G$21,S11))) | O11: =IF(S11="","",IF(INDEX(Envelopes!$M$1:$M$21,S11)="Reached","Reached",IF(INDEX(Envelopes!$N$1:$N$21,S11)="","",INDEX(Envelopes!$N$1:$N$21,S11)))) | Q11: =IF(B11="","",IF(Envelopes!$C$9="Sinking fund","Sinking fund","Spending")) | R11: =IF(B11="","",Envelopes!$M$9) | S11: =IFERROR(SMALL(Envelopes!$P$6:$P$21,4),"")
B12: =IF(Envelopes!$B$10="","",Envelopes!$B$10) | C12: =IF(B12="","",N(Envelopes!$H$10)+SUMIFS(Paydays!$I$6:$I$205,Paydays!$W$6:$W$205,">0",Paydays!$W$6:$W$205,"<"&Dashboard!$V$1)-SUMIFS(Spending!$D$6:$D$1005,Spending!$C$6:$C$1005,Envelopes!$B$10,Spending!$I$6:$I$1005,1,Spending!$H$6:$H$1005,"<"&Dashboard!$V$1)+SUMIFS(Spending!$D$6:$D$1005,Spending!$F$6:$F$1005,Envelopes!$B$10,Spending!$J$6:$J$1005,1,Spending!$H$6:$H$1005,"<"&Dashboard!$V$1)-SUMIFS(Spending!$D$6:$D$1005,Spending!$C$6:$C$1005,Envelopes!$B$10,Spending!$J$6:$J$1005,1,Spending!$H$6:$H$1005,"<"&Dashboard!$V$1)) | D12: =IF(B12="","",SUMIFS(Paydays!$I$6:$I$205,Paydays!$W$6:$W$205,">0",Paydays!$W$6:$W$205,">="&Dashboard!$V$1,Paydays!$W$6:$W$205,"<="&Dashboard!$V$2)) | E12: =IF(B12="","",SUMIFS(Spending!$D$6:$D$1005,Spending!$C$6:$C$1005,Envelopes!$B$10,Spending!$I$6:$I$1005,1,Spending!$H$6:$H$1005,">="&Dashboard!$V$1,Spending!$H$6:$H$1005,"<="&Dashboard!$V$2)) | F12: =IF(B12="","",SUMIFS(Spending!$D$6:$D$1005,Spending!$F$6:$F$1005,Envelopes!$B$10,Spending!$J$6:$J$1005,1,Spending!$H$6:$H$1005,">="&Dashboard!$V$1,Spending!$H$6:$H$1005,"<="&Dashboard!$V$2)-SUMIFS(Spending!$D$6:$D$1005,Spending!$C$6:$C$1005,Envelopes!$B$10,Spending!$J$6:$J$1005,1,Spending!$H$6:$H$1005,">="&Dashboard!$V$1,Spending!$H$6:$H$1005,"<="&Dashboard!$V$2)) | G12: =IF(B12="","",C12+D12-E12+F12) | H12: =IF(B12="","",IF(C12+D12+MAX(0,F12)<=0,"",REPT("█",MIN(10,MAX(0,ROUND((E12/(C12+D12+MAX(0,F12)))*10,0))))&REPT("░",10-MIN(10,MAX(0,ROUND((E12/(C12+D12+MAX(0,F12)))*10,0)))))) | J12: =IF(S12="","",INDEX(Envelopes!$B$1:$B$21,S12)) | K12: =IF(S12="","",IF(N(INDEX(Envelopes!$F$1:$F$21,S12))=0,"",INDEX(Envelopes!$F$1:$F$21,S12))) | L12: =IF(S12="","",INDEX(Envelopes!$L$1:$L$21,S12)) | M12: =IF(OR(S12="",K12=""),"",REPT("█",MIN(10,MAX(0,ROUND((L12/K12)*10,0))))&REPT("░",10-MIN(10,MAX(0,ROUND((L12/K12)*10,0))))) | N12: =IF(S12="","",IF(INDEX(Envelopes!$G$1:$G$21,S12)="","",INDEX(Envelopes!$G$1:$G$21,S12))) | O12: =IF(S12="","",IF(INDEX(Envelopes!$M$1:$M$21,S12)="Reached","Reached",IF(INDEX(Envelopes!$N$1:$N$21,S12)="","",INDEX(Envelopes!$N$1:$N$21,S12)))) | Q12: =IF(B12="","",IF(Envelopes!$C$10="Sinking fund","Sinking fund","Spending")) | R12: =IF(B12="","",Envelopes!$M$10) | S12: =IFERROR(SMALL(Envelopes!$P$6:$P$21,5),"")
B13: =IF(Envelopes!$B$11="","",Envelopes!$B$11) | C13: =IF(B13="","",N(Envelopes!$H$11)+SUMIFS(Paydays!$J$6:$J$205,Paydays!$W$6:$W$205,">0",Paydays!$W$6:$W$205,"<"&Dashboard!$V$1)-SUMIFS(Spending!$D$6:$D$1005,Spending!$C$6:$C$1005,Envelopes!$B$11,Spending!$I$6:$I$1005,1,Spending!$H$6:$H$1005,"<"&Dashboard!$V$1)+SUMIFS(Spending!$D$6:$D$1005,Spending!$F$6:$F$1005,Envelopes!$B$11,Spending!$J$6:$J$1005,1,Spending!$H$6:$H$1005,"<"&Dashboard!$V$1)-SUMIFS(Spending!$D$6:$D$1005,Spending!$C$6:$C$1005,Envelopes!$B$11,Spending!$J$6:$J$1005,1,Spending!$H$6:$H$1005,"<"&Dashboard!$V$1)) | D13: =IF(B13="","",SUMIFS(Paydays!$J$6:$J$205,Paydays!$W$6:$W$205,">0",Paydays!$W$6:$W$205,">="&Dashboard!$V$1,Paydays!$W$6:$W$205,"<="&Dashboard!$V$2)) | E13: =IF(B13="","",SUMIFS(Spending!$D$6:$D$1005,Spending!$C$6:$C$1005,Envelopes!$B$11,Spending!$I$6:$I$1005,1,Spending!$H$6:$H$1005,">="&Dashboard!$V$1,Spending!$H$6:$H$1005,"<="&Dashboard!$V$2)) | F13: =IF(B13="","",SUMIFS(Spending!$D$6:$D$1005,Spending!$F$6:$F$1005,Envelopes!$B$11,Spending!$J$6:$J$1005,1,Spending!$H$6:$H$1005,">="&Dashboard!$V$1,Spending!$H$6:$H$1005,"<="&Dashboard!$V$2)-SUMIFS(Spending!$D$6:$D$1005,Spending!$C$6:$C$1005,Envelopes!$B$11,Spending!$J$6:$J$1005,1,Spending!$H$6:$H$1005,">="&Dashboard!$V$1,Spending!$H$6:$H$1005,"<="&Dashboard!$V$2)) | G13: =IF(B13="","",C13+D13-E13+F13) | H13: =IF(B13="","",IF(C13+D13+MAX(0,F13)<=0,"",REPT("█",MIN(10,MAX(0,ROUND((E13/(C13+D13+MAX(0,F13)))*10,0))))&REPT("░",10-MIN(10,MAX(0,ROUND((E13/(C13+D13+MAX(0,F13)))*10,0)))))) | J13: =IF(S13="","",INDEX(Envelopes!$B$1:$B$21,S13)) | K13: =IF(S13="","",IF(N(INDEX(Envelopes!$F$1:$F$21,S13))=0,"",INDEX(Envelopes!$F$1:$F$21,S13))) | L13: =IF(S13="","",INDEX(Envelopes!$L$1:$L$21,S13)) | M13: =IF(OR(S13="",K13=""),"",REPT("█",MIN(10,MAX(0,ROUND((L13/K13)*10,0))))&REPT("░",10-MIN(10,MAX(0,ROUND((L13/K13)*10,0))))) | N13: =IF(S13="","",IF(INDEX(Envelopes!$G$1:$G$21,S13)="","",INDEX(Envelopes!$G$1:$G$21,S13))) | O13: =IF(S13="","",IF(INDEX(Envelopes!$M$1:$M$21,S13)="Reached","Reached",IF(INDEX(Envelopes!$N$1:$N$21,S13)="","",INDEX(Envelopes!$N$1:$N$21,S13)))) | Q13: =IF(B13="","",IF(Envelopes!$C$11="Sinking fund","Sinking fund","Spending")) | R13: =IF(B13="","",Envelopes!$M$11) | S13: =IFERROR(SMALL(Envelopes!$P$6:$P$21,6),"")
B14: =IF(Envelopes!$B$12="","",Envelopes!$B$12) | C14: =IF(B14="","",N(Envelopes!$H$12)+SUMIFS(Paydays!$K$6:$K$205,Paydays!$W$6:$W$205,">0",Paydays!$W$6:$W$205,"<"&Dashboard!$V$1)-SUMIFS(Spending!$D$6:$D$1005,Spending!$C$6:$C$1005,Envelopes!$B$12,Spending!$I$6:$I$1005,1,Spending!$H$6:$H$1005,"<"&Dashboard!$V$1)+SUMIFS(Spending!$D$6:$D$1005,Spending!$F$6:$F$1005,Envelopes!$B$12,Spending!$J$6:$J$1005,1,Spending!$H$6:$H$1005,"<"&Dashboard!$V$1)-SUMIFS(Spending!$D$6:$D$1005,Spending!$C$6:$C$1005,Envelopes!$B$12,Spending!$J$6:$J$1005,1,Spending!$H$6:$H$1005,"<"&Dashboard!$V$1)) | D14: =IF(B14="","",SUMIFS(Paydays!$K$6:$K$205,Paydays!$W$6:$W$205,">0",Paydays!$W$6:$W$205,">="&Dashboard!$V$1,Paydays!$W$6:$W$205,"<="&Dashboard!$V$2)) | E14: =IF(B14="","",SUMIFS(Spending!$D$6:$D$1005,Spending!$C$6:$C$1005,Envelopes!$B$12,Spending!$I$6:$I$1005,1,Spending!$H$6:$H$1005,">="&Dashboard!$V$1,Spending!$H$6:$H$1005,"<="&Dashboard!$V$2)) | F14: =IF(B14="","",SUMIFS(Spending!$D$6:$D$1005,Spending!$F$6:$F$1005,Envelopes!$B$12,Spending!$J$6:$J$1005,1,Spending!$H$6:$H$1005,">="&Dashboard!$V$1,Spending!$H$6:$H$1005,"<="&Dashboard!$V$2)-SUMIFS(Spending!$D$6:$D$1005,Spending!$C$6:$C$1005,Envelopes!$B$12,Spending!$J$6:$J$1005,1,Spending!$H$6:$H$1005,">="&Dashboard!$V$1,Spending!$H$6:$H$1005,"<="&Dashboard!$V$2)) | G14: =IF(B14="","",C14+D14-E14+F14) | H14: =IF(B14="","",IF(C14+D14+MAX(0,F14)<=0,"",REPT("█",MIN(10,MAX(0,ROUND((E14/(C14+D14+MAX(0,F14)))*10,0))))&REPT("░",10-MIN(10,MAX(0,ROUND((E14/(C14+D14+MAX(0,F14)))*10,0)))))) | J14: =IF(S14="","",INDEX(Envelopes!$B$1:$B$21,S14)) | K14: =IF(S14="","",IF(N(INDEX(Envelopes!$F$1:$F$21,S14))=0,"",INDEX(Envelopes!$F$1:$F$21,S14))) | L14: =IF(S14="","",INDEX(Envelopes!$L$1:$L$21,S14)) | M14: =IF(OR(S14="",K14=""),"",REPT("█",MIN(10,MAX(0,ROUND((L14/K14)*10,0))))&REPT("░",10-MIN(10,MAX(0,ROUND((L14/K14)*10,0))))) | N14: =IF(S14="","",IF(INDEX(Envelopes!$G$1:$G$21,S14)="","",INDEX(Envelopes!$G$1:$G$21,S14))) | O14: =IF(S14="","",IF(INDEX(Envelopes!$M$1:$M$21,S14)="Reached","Reached",IF(INDEX(Envelopes!$N$1:$N$21,S14)="","",INDEX(Envelopes!$N$1:$N$21,S14)))) | Q14: =IF(B14="","",IF(Envelopes!$C$12="Sinking fund","Sinking fund","Spending")) | R14: =IF(B14="","",Envelopes!$M$12) | S14: =IFERROR(SMALL(Envelopes!$P$6:$P$21,7),"")
B15: =IF(Envelopes!$B$13="","",Envelopes!$B$13) | C15: =IF(B15="","",N(Envelopes!$H$13)+SUMIFS(Paydays!$L$6:$L$205,Paydays!$W$6:$W$205,">0",Paydays!$W$6:$W$205,"<"&Dashboard!$V$1)-SUMIFS(Spending!$D$6:$D$1005,Spending!$C$6:$C$1005,Envelopes!$B$13,Spending!$I$6:$I$1005,1,Spending!$H$6:$H$1005,"<"&Dashboard!$V$1)+SUMIFS(Spending!$D$6:$D$1005,Spending!$F$6:$F$1005,Envelopes!$B$13,Spending!$J$6:$J$1005,1,Spending!$H$6:$H$1005,"<"&Dashboard!$V$1)-SUMIFS(Spending!$D$6:$D$1005,Spending!$C$6:$C$1005,Envelopes!$B$13,Spending!$J$6:$J$1005,1,Spending!$H$6:$H$1005,"<"&Dashboard!$V$1)) | D15: =IF(B15="","",SUMIFS(Paydays!$L$6:$L$205,Paydays!$W$6:$W$205,">0",Paydays!$W$6:$W$205,">="&Dashboard!$V$1,Paydays!$W$6:$W$205,"<="&Dashboard!$V$2)) | E15: =IF(B15="","",SUMIFS(Spending!$D$6:$D$1005,Spending!$C$6:$C$1005,Envelopes!$B$13,Spending!$I$6:$I$1005,1,Spending!$H$6:$H$1005,">="&Dashboard!$V$1,Spending!$H$6:$H$1005,"<="&Dashboard!$V$2)) | F15: =IF(B15="","",SUMIFS(Spending!$D$6:$D$1005,Spending!$F$6:$F$1005,Envelopes!$B$13,Spending!$J$6:$J$1005,1,Spending!$H$6:$H$1005,">="&Dashboard!$V$1,Spending!$H$6:$H$1005,"<="&Dashboard!$V$2)-SUMIFS(Spending!$D$6:$D$1005,Spending!$C$6:$C$1005,Envelopes!$B$13,Spending!$J$6:$J$1005,1,Spending!$H$6:$H$1005,">="&Dashboard!$V$1,Spending!$H$6:$H$1005,"<="&Dashboard!$V$2)) | G15: =IF(B15="","",C15+D15-E15+F15) | H15: =IF(B15="","",IF(C15+D15+MAX(0,F15)<=0,"",REPT("█",MIN(10,MAX(0,ROUND((E15/(C15+D15+MAX(0,F15)))*10,0))))&REPT("░",10-MIN(10,MAX(0,ROUND((E15/(C15+D15+MAX(0,F15)))*10,0)))))) | J15: =IF(S15="","",INDEX(Envelopes!$B$1:$B$21,S15)) | K15: =IF(S15="","",IF(N(INDEX(Envelopes!$F$1:$F$21,S15))=0,"",INDEX(Envelopes!$F$1:$F$21,S15))) | L15: =IF(S15="","",INDEX(Envelopes!$L$1:$L$21,S15)) | M15: =IF(OR(S15="",K15=""),"",REPT("█",MIN(10,MAX(0,ROUND((L15/K15)*10,0))))&REPT("░",10-MIN(10,MAX(0,ROUND((L15/K15)*10,0))))) | N15: =IF(S15="","",IF(INDEX(Envelopes!$G$1:$G$21,S15)="","",INDEX(Envelopes!$G$1:$G$21,S15))) | O15: =IF(S15="","",IF(INDEX(Envelopes!$M$1:$M$21,S15)="Reached","Reached",IF(INDEX(Envelopes!$N$1:$N$21,S15)="","",INDEX(Envelopes!$N$1:$N$21,S15)))) | Q15: =IF(B15="","",IF(Envelopes!$C$13="Sinking fund","Sinking fund","Spending")) | R15: =IF(B15="","",Envelopes!$M$13) | S15: =IFERROR(SMALL(Envelopes!$P$6:$P$21,8),"")
B16: =IF(Envelopes!$B$14="","",Envelopes!$B$14) | C16: =IF(B16="","",N(Envelopes!$H$14)+SUMIFS(Paydays!$M$6:$M$205,Paydays!$W$6:$W$205,">0",Paydays!$W$6:$W$205,"<"&Dashboard!$V$1)-SUMIFS(Spending!$D$6:$D$1005,Spending!$C$6:$C$1005,Envelopes!$B$14,Spending!$I$6:$I$1005,1,Spending!$H$6:$H$1005,"<"&Dashboard!$V$1)+SUMIFS(Spending!$D$6:$D$1005,Spending!$F$6:$F$1005,Envelopes!$B$14,Spending!$J$6:$J$1005,1,Spending!$H$6:$H$1005,"<"&Dashboard!$V$1)-SUMIFS(Spending!$D$6:$D$1005,Spending!$C$6:$C$1005,Envelopes!$B$14,Spending!$J$6:$J$1005,1,Spending!$H$6:$H$1005,"<"&Dashboard!$V$1)) | D16: =IF(B16="","",SUMIFS(Paydays!$M$6:$M$205,Paydays!$W$6:$W$205,">0",Paydays!$W$6:$W$205,">="&Dashboard!$V$1,Paydays!$W$6:$W$205,"<="&Dashboard!$V$2)) | E16: =IF(B16="","",SUMIFS(Spending!$D$6:$D$1005,Spending!$C$6:$C$1005,Envelopes!$B$14,Spending!$I$6:$I$1005,1,Spending!$H$6:$H$1005,">="&Dashboard!$V$1,Spending!$H$6:$H$1005,"<="&Dashboard!$V$2)) | F16: =IF(B16="","",SUMIFS(Spending!$D$6:$D$1005,Spending!$F$6:$F$1005,Envelopes!$B$14,Spending!$J$6:$J$1005,1,Spending!$H$6:$H$1005,">="&Dashboard!$V$1,Spending!$H$6:$H$1005,"<="&Dashboard!$V$2)-SUMIFS(Spending!$D$6:$D$1005,Spending!$C$6:$C$1005,Envelopes!$B$14,Spending!$J$6:$J$1005,1,Spending!$H$6:$H$1005,">="&Dashboard!$V$1,Spending!$H$6:$H$1005,"<="&Dashboard!$V$2)) | G16: =IF(B16="","",C16+D16-E16+F16) | H16: =IF(B16="","",IF(C16+D16+MAX(0,F16)<=0,"",REPT("█",MIN(10,MAX(0,ROUND((E16/(C16+D16+MAX(0,F16)))*10,0))))&REPT("░",10-MIN(10,MAX(0,ROUND((E16/(C16+D16+MAX(0,F16)))*10,0)))))) | Q16: =IF(B16="","",IF(Envelopes!$C$14="Sinking fund","Sinking fund","Spending")) | R16: =IF(B16="","",Envelopes!$M$14)
B17: =IF(Envelopes!$B$15="","",Envelopes!$B$15) | C17: =IF(B17="","",N(Envelopes!$H$15)+SUMIFS(Paydays!$N$6:$N$205,Paydays!$W$6:$W$205,">0",Paydays!$W$6:$W$205,"<"&Dashboard!$V$1)-SUMIFS(Spending!$D$6:$D$1005,Spending!$C$6:$C$1005,Envelopes!$B$15,Spending!$I$6:$I$1005,1,Spending!$H$6:$H$1005,"<"&Dashboard!$V$1)+SUMIFS(Spending!$D$6:$D$1005,Spending!$F$6:$F$1005,Envelopes!$B$15,Spending!$J$6:$J$1005,1,Spending!$H$6:$H$1005,"<"&Dashboard!$V$1)-SUMIFS(Spending!$D$6:$D$1005,Spending!$C$6:$C$1005,Envelopes!$B$15,Spending!$J$6:$J$1005,1,Spending!$H$6:$H$1005,"<"&Dashboard!$V$1)) | D17: =IF(B17="","",SUMIFS(Paydays!$N$6:$N$205,Paydays!$W$6:$W$205,">0",Paydays!$W$6:$W$205,">="&Dashboard!$V$1,Paydays!$W$6:$W$205,"<="&Dashboard!$V$2)) | E17: =IF(B17="","",SUMIFS(Spending!$D$6:$D$1005,Spending!$C$6:$C$1005,Envelopes!$B$15,Spending!$I$6:$I$1005,1,Spending!$H$6:$H$1005,">="&Dashboard!$V$1,Spending!$H$6:$H$1005,"<="&Dashboard!$V$2)) | F17: =IF(B17="","",SUMIFS(Spending!$D$6:$D$1005,Spending!$F$6:$F$1005,Envelopes!$B$15,Spending!$J$6:$J$1005,1,Spending!$H$6:$H$1005,">="&Dashboard!$V$1,Spending!$H$6:$H$1005,"<="&Dashboard!$V$2)-SUMIFS(Spending!$D$6:$D$1005,Spending!$C$6:$C$1005,Envelopes!$B$15,Spending!$J$6:$J$1005,1,Spending!$H$6:$H$1005,">="&Dashboard!$V$1,Spending!$H$6:$H$1005,"<="&Dashboard!$V$2)) | G17: =IF(B17="","",C17+D17-E17+F17) | H17: =IF(B17="","",IF(C17+D17+MAX(0,F17)<=0,"",REPT("█",MIN(10,MAX(0,ROUND((E17/(C17+D17+MAX(0,F17)))*10,0))))&REPT("░",10-MIN(10,MAX(0,ROUND((E17/(C17+D17+MAX(0,F17)))*10,0)))))) | J17: Latest spending | K17: Date | L17: Envelope | M17: Amount | Q17: =IF(B17="","",IF(Envelopes!$C$15="Sinking fund","Sinking fund","Spending")) | R17: =IF(B17="","",Envelopes!$M$15)
B18: =IF(Envelopes!$B$16="","",Envelopes!$B$16) | C18: =IF(B18="","",N(Envelopes!$H$16)+SUMIFS(Paydays!$O$6:$O$205,Paydays!$W$6:$W$205,">0",Paydays!$W$6:$W$205,"<"&Dashboard!$V$1)-SUMIFS(Spending!$D$6:$D$1005,Spending!$C$6:$C$1005,Envelopes!$B$16,Spending!$I$6:$I$1005,1,Spending!$H$6:$H$1005,"<"&Dashboard!$V$1)+SUMIFS(Spending!$D$6:$D$1005,Spending!$F$6:$F$1005,Envelopes!$B$16,Spending!$J$6:$J$1005,1,Spending!$H$6:$H$1005,"<"&Dashboard!$V$1)-SUMIFS(Spending!$D$6:$D$1005,Spending!$C$6:$C$1005,Envelopes!$B$16,Spending!$J$6:$J$1005,1,Spending!$H$6:$H$1005,"<"&Dashboard!$V$1)) | D18: =IF(B18="","",SUMIFS(Paydays!$O$6:$O$205,Paydays!$W$6:$W$205,">0",Paydays!$W$6:$W$205,">="&Dashboard!$V$1,Paydays!$W$6:$W$205,"<="&Dashboard!$V$2)) | E18: =IF(B18="","",SUMIFS(Spending!$D$6:$D$1005,Spending!$C$6:$C$1005,Envelopes!$B$16,Spending!$I$6:$I$1005,1,Spending!$H$6:$H$1005,">="&Dashboard!$V$1,Spending!$H$6:$H$1005,"<="&Dashboard!$V$2)) | F18: =IF(B18="","",SUMIFS(Spending!$D$6:$D$1005,Spending!$F$6:$F$1005,Envelopes!$B$16,Spending!$J$6:$J$1005,1,Spending!$H$6:$H$1005,">="&Dashboard!$V$1,Spending!$H$6:$H$1005,"<="&Dashboard!$V$2)-SUMIFS(Spending!$D$6:$D$1005,Spending!$C$6:$C$1005,Envelopes!$B$16,Spending!$J$6:$J$1005,1,Spending!$H$6:$H$1005,">="&Dashboard!$V$1,Spending!$H$6:$H$1005,"<="&Dashboard!$V$2)) | G18: =IF(B18="","",C18+D18-E18+F18) | H18: =IF(B18="","",IF(C18+D18+MAX(0,F18)<=0,"",REPT("█",MIN(10,MAX(0,ROUND((E18/(C18+D18+MAX(0,F18)))*10,0))))&REPT("░",10-MIN(10,MAX(0,ROUND((E18/(C18+D18+MAX(0,F18)))*10,0)))))) | J18: =IF(T18="","",IF(INDEX(Spending!$E$1:$E$1005,MOD(T18,10000))="","",INDEX(Spending!$E$1:$E$1005,MOD(T18,10000)))) | K18: =IF(T18="","",INDEX(Spending!$B$1:$B$1005,MOD(T18,10000))) | L18: =IF(T18="","",INDEX(Spending!$C$1:$C$1005,MOD(T18,10000))) | M18: =IF(T18="","",INDEX(Spending!$D$1:$D$1005,MOD(T18,10000))) | Q18: =IF(B18="","",IF(Envelopes!$C$16="Sinking fund","Sinking fund","Spending")) | R18: =IF(B18="","",Envelopes!$M$16) | T18: =IFERROR(LARGE(Spending!$K$6:$K$1005,1),"")
B19: =IF(Envelopes!$B$17="","",Envelopes!$B$17) | C19: =IF(B19="","",N(Envelopes!$H$17)+SUMIFS(Paydays!$P$6:$P$205,Paydays!$W$6:$W$205,">0",Paydays!$W$6:$W$205,"<"&Dashboard!$V$1)-SUMIFS(Spending!$D$6:$D$1005,Spending!$C$6:$C$1005,Envelopes!$B$17,Spending!$I$6:$I$1005,1,Spending!$H$6:$H$1005,"<"&Dashboard!$V$1)+SUMIFS(Spending!$D$6:$D$1005,Spending!$F$6:$F$1005,Envelopes!$B$17,Spending!$J$6:$J$1005,1,Spending!$H$6:$H$1005,"<"&Dashboard!$V$1)-SUMIFS(Spending!$D$6:$D$1005,Spending!$C$6:$C$1005,Envelopes!$B$17,Spending!$J$6:$J$1005,1,Spending!$H$6:$H$1005,"<"&Dashboard!$V$1)) | D19: =IF(B19="","",SUMIFS(Paydays!$P$6:$P$205,Paydays!$W$6:$W$205,">0",Paydays!$W$6:$W$205,">="&Dashboard!$V$1,Paydays!$W$6:$W$205,"<="&Dashboard!$V$2)) | E19: =IF(B19="","",SUMIFS(Spending!$D$6:$D$1005,Spending!$C$6:$C$1005,Envelopes!$B$17,Spending!$I$6:$I$1005,1,Spending!$H$6:$H$1005,">="&Dashboard!$V$1,Spending!$H$6:$H$1005,"<="&Dashboard!$V$2)) | F19: =IF(B19="","",SUMIFS(Spending!$D$6:$D$1005,Spending!$F$6:$F$1005,Envelopes!$B$17,Spending!$J$6:$J$1005,1,Spending!$H$6:$H$1005,">="&Dashboard!$V$1,Spending!$H$6:$H$1005,"<="&Dashboard!$V$2)-SUMIFS(Spending!$D$6:$D$1005,Spending!$C$6:$C$1005,Envelopes!$B$17,Spending!$J$6:$J$1005,1,Spending!$H$6:$H$1005,">="&Dashboard!$V$1,Spending!$H$6:$H$1005,"<="&Dashboard!$V$2)) | G19: =IF(B19="","",C19+D19-E19+F19) | H19: =IF(B19="","",IF(C19+D19+MAX(0,F19)<=0,"",REPT("█",MIN(10,MAX(0,ROUND((E19/(C19+D19+MAX(0,F19)))*10,0))))&REPT("░",10-MIN(10,MAX(0,ROUND((E19/(C19+D19+MAX(0,F19)))*10,0)))))) | J19: =IF(T19="","",IF(INDEX(Spending!$E$1:$E$1005,MOD(T19,10000))="","",INDEX(Spending!$E$1:$E$1005,MOD(T19,10000)))) | K19: =IF(T19="","",INDEX(Spending!$B$1:$B$1005,MOD(T19,10000))) | L19: =IF(T19="","",INDEX(Spending!$C$1:$C$1005,MOD(T19,10000))) | M19: =IF(T19="","",INDEX(Spending!$D$1:$D$1005,MOD(T19,10000))) | Q19: =IF(B19="","",IF(Envelopes!$C$17="Sinking fund","Sinking fund","Spending")) | R19: =IF(B19="","",Envelopes!$M$17) | T19: =IFERROR(LARGE(Spending!$K$6:$K$1005,2),"")
B20: =IF(Envelopes!$B$18="","",Envelopes!$B$18) | C20: =IF(B20="","",N(Envelopes!$H$18)+SUMIFS(Paydays!$Q$6:$Q$205,Paydays!$W$6:$W$205,">0",Paydays!$W$6:$W$205,"<"&Dashboard!$V$1)-SUMIFS(Spending!$D$6:$D$1005,Spending!$C$6:$C$1005,Envelopes!$B$18,Spending!$I$6:$I$1005,1,Spending!$H$6:$H$1005,"<"&Dashboard!$V$1)+SUMIFS(Spending!$D$6:$D$1005,Spending!$F$6:$F$1005,Envelopes!$B$18,Spending!$J$6:$J$1005,1,Spending!$H$6:$H$1005,"<"&Dashboard!$V$1)-SUMIFS(Spending!$D$6:$D$1005,Spending!$C$6:$C$1005,Envelopes!$B$18,Spending!$J$6:$J$1005,1,Spending!$H$6:$H$1005,"<"&Dashboard!$V$1)) | D20: =IF(B20="","",SUMIFS(Paydays!$Q$6:$Q$205,Paydays!$W$6:$W$205,">0",Paydays!$W$6:$W$205,">="&Dashboard!$V$1,Paydays!$W$6:$W$205,"<="&Dashboard!$V$2)) | E20: =IF(B20="","",SUMIFS(Spending!$D$6:$D$1005,Spending!$C$6:$C$1005,Envelopes!$B$18,Spending!$I$6:$I$1005,1,Spending!$H$6:$H$1005,">="&Dashboard!$V$1,Spending!$H$6:$H$1005,"<="&Dashboard!$V$2)) | F20: =IF(B20="","",SUMIFS(Spending!$D$6:$D$1005,Spending!$F$6:$F$1005,Envelopes!$B$18,Spending!$J$6:$J$1005,1,Spending!$H$6:$H$1005,">="&Dashboard!$V$1,Spending!$H$6:$H$1005,"<="&Dashboard!$V$2)-SUMIFS(Spending!$D$6:$D$1005,Spending!$C$6:$C$1005,Envelopes!$B$18,Spending!$J$6:$J$1005,1,Spending!$H$6:$H$1005,">="&Dashboard!$V$1,Spending!$H$6:$H$1005,"<="&Dashboard!$V$2)) | G20: =IF(B20="","",C20+D20-E20+F20) | H20: =IF(B20="","",IF(C20+D20+MAX(0,F20)<=0,"",REPT("█",MIN(10,MAX(0,ROUND((E20/(C20+D20+MAX(0,F20)))*10,0))))&REPT("░",10-MIN(10,MAX(0,ROUND((E20/(C20+D20+MAX(0,F20)))*10,0)))))) | J20: =IF(T20="","",IF(INDEX(Spending!$E$1:$E$1005,MOD(T20,10000))="","",INDEX(Spending!$E$1:$E$1005,MOD(T20,10000)))) | K20: =IF(T20="","",INDEX(Spending!$B$1:$B$1005,MOD(T20,10000))) | L20: =IF(T20="","",INDEX(Spending!$C$1:$C$1005,MOD(T20,10000))) | M20: =IF(T20="","",INDEX(Spending!$D$1:$D$1005,MOD(T20,10000))) | Q20: =IF(B20="","",IF(Envelopes!$C$18="Sinking fund","Sinking fund","Spending")) | R20: =IF(B20="","",Envelopes!$M$18) | T20: =IFERROR(LARGE(Spending!$K$6:$K$1005,3),"")
B21: =IF(Envelopes!$B$19="","",Envelopes!$B$19) | C21: =IF(B21="","",N(Envelopes!$H$19)+SUMIFS(Paydays!$R$6:$R$205,Paydays!$W$6:$W$205,">0",Paydays!$W$6:$W$205,"<"&Dashboard!$V$1)-SUMIFS(Spending!$D$6:$D$1005,Spending!$C$6:$C$1005,Envelopes!$B$19,Spending!$I$6:$I$1005,1,Spending!$H$6:$H$1005,"<"&Dashboard!$V$1)+SUMIFS(Spending!$D$6:$D$1005,Spending!$F$6:$F$1005,Envelopes!$B$19,Spending!$J$6:$J$1005,1,Spending!$H$6:$H$1005,"<"&Dashboard!$V$1)-SUMIFS(Spending!$D$6:$D$1005,Spending!$C$6:$C$1005,Envelopes!$B$19,Spending!$J$6:$J$1005,1,Spending!$H$6:$H$1005,"<"&Dashboard!$V$1)) | D21: =IF(B21="","",SUMIFS(Paydays!$R$6:$R$205,Paydays!$W$6:$W$205,">0",Paydays!$W$6:$W$205,">="&Dashboard!$V$1,Paydays!$W$6:$W$205,"<="&Dashboard!$V$2)) | E21: =IF(B21="","",SUMIFS(Spending!$D$6:$D$1005,Spending!$C$6:$C$1005,Envelopes!$B$19,Spending!$I$6:$I$1005,1,Spending!$H$6:$H$1005,">="&Dashboard!$V$1,Spending!$H$6:$H$1005,"<="&Dashboard!$V$2)) | F21: =IF(B21="","",SUMIFS(Spending!$D$6:$D$1005,Spending!$F$6:$F$1005,Envelopes!$B$19,Spending!$J$6:$J$1005,1,Spending!$H$6:$H$1005,">="&Dashboard!$V$1,Spending!$H$6:$H$1005,"<="&Dashboard!$V$2)-SUMIFS(Spending!$D$6:$D$1005,Spending!$C$6:$C$1005,Envelopes!$B$19,Spending!$J$6:$J$1005,1,Spending!$H$6:$H$1005,">="&Dashboard!$V$1,Spending!$H$6:$H$1005,"<="&Dashboard!$V$2)) | G21: =IF(B21="","",C21+D21-E21+F21) | H21: =IF(B21="","",IF(C21+D21+MAX(0,F21)<=0,"",REPT("█",MIN(10,MAX(0,ROUND((E21/(C21+D21+MAX(0,F21)))*10,0))))&REPT("░",10-MIN(10,MAX(0,ROUND((E21/(C21+D21+MAX(0,F21)))*10,0)))))) | J21: =IF(T21="","",IF(INDEX(Spending!$E$1:$E$1005,MOD(T21,10000))="","",INDEX(Spending!$E$1:$E$1005,MOD(T21,10000)))) | K21: =IF(T21="","",INDEX(Spending!$B$1:$B$1005,MOD(T21,10000))) | L21: =IF(T21="","",INDEX(Spending!$C$1:$C$1005,MOD(T21,10000))) | M21: =IF(T21="","",INDEX(Spending!$D$1:$D$1005,MOD(T21,10000))) | Q21: =IF(B21="","",IF(Envelopes!$C$19="Sinking fund","Sinking fund","Spending")) | R21: =IF(B21="","",Envelopes!$M$19) | T21: =IFERROR(LARGE(Spending!$K$6:$K$1005,4),"")
B22: =IF(Envelopes!$B$20="","",Envelopes!$B$20) | C22: =IF(B22="","",N(Envelopes!$H$20)+SUMIFS(Paydays!$S$6:$S$205,Paydays!$W$6:$W$205,">0",Paydays!$W$6:$W$205,"<"&Dashboard!$V$1)-SUMIFS(Spending!$D$6:$D$1005,Spending!$C$6:$C$1005,Envelopes!$B$20,Spending!$I$6:$I$1005,1,Spending!$H$6:$H$1005,"<"&Dashboard!$V$1)+SUMIFS(Spending!$D$6:$D$1005,Spending!$F$6:$F$1005,Envelopes!$B$20,Spending!$J$6:$J$1005,1,Spending!$H$6:$H$1005,"<"&Dashboard!$V$1)-SUMIFS(Spending!$D$6:$D$1005,Spending!$C$6:$C$1005,Envelopes!$B$20,Spending!$J$6:$J$1005,1,Spending!$H$6:$H$1005,"<"&Dashboard!$V$1)) | D22: =IF(B22="","",SUMIFS(Paydays!$S$6:$S$205,Paydays!$W$6:$W$205,">0",Paydays!$W$6:$W$205,">="&Dashboard!$V$1,Paydays!$W$6:$W$205,"<="&Dashboard!$V$2)) | E22: =IF(B22="","",SUMIFS(Spending!$D$6:$D$1005,Spending!$C$6:$C$1005,Envelopes!$B$20,Spending!$I$6:$I$1005,1,Spending!$H$6:$H$1005,">="&Dashboard!$V$1,Spending!$H$6:$H$1005,"<="&Dashboard!$V$2)) | F22: =IF(B22="","",SUMIFS(Spending!$D$6:$D$1005,Spending!$F$6:$F$1005,Envelopes!$B$20,Spending!$J$6:$J$1005,1,Spending!$H$6:$H$1005,">="&Dashboard!$V$1,Spending!$H$6:$H$1005,"<="&Dashboard!$V$2)-SUMIFS(Spending!$D$6:$D$1005,Spending!$C$6:$C$1005,Envelopes!$B$20,Spending!$J$6:$J$1005,1,Spending!$H$6:$H$1005,">="&Dashboard!$V$1,Spending!$H$6:$H$1005,"<="&Dashboard!$V$2)) | G22: =IF(B22="","",C22+D22-E22+F22) | H22: =IF(B22="","",IF(C22+D22+MAX(0,F22)<=0,"",REPT("█",MIN(10,MAX(0,ROUND((E22/(C22+D22+MAX(0,F22)))*10,0))))&REPT("░",10-MIN(10,MAX(0,ROUND((E22/(C22+D22+MAX(0,F22)))*10,0)))))) | J22: =IF(T22="","",IF(INDEX(Spending!$E$1:$E$1005,MOD(T22,10000))="","",INDEX(Spending!$E$1:$E$1005,MOD(T22,10000)))) | K22: =IF(T22="","",INDEX(Spending!$B$1:$B$1005,MOD(T22,10000))) | L22: =IF(T22="","",INDEX(Spending!$C$1:$C$1005,MOD(T22,10000))) | M22: =IF(T22="","",INDEX(Spending!$D$1:$D$1005,MOD(T22,10000))) | Q22: =IF(B22="","",IF(Envelopes!$C$20="Sinking fund","Sinking fund","Spending")) | R22: =IF(B22="","",Envelopes!$M$20) | T22: =IFERROR(LARGE(Spending!$K$6:$K$1005,5),"")
B23: =IF(Envelopes!$B$21="","",Envelopes!$B$21) | C23: =IF(B23="","",N(Envelopes!$H$21)+SUMIFS(Paydays!$T$6:$T$205,Paydays!$W$6:$W$205,">0",Paydays!$W$6:$W$205,"<"&Dashboard!$V$1)-SUMIFS(Spending!$D$6:$D$1005,Spending!$C$6:$C$1005,Envelopes!$B$21,Spending!$I$6:$I$1005,1,Spending!$H$6:$H$1005,"<"&Dashboard!$V$1)+SUMIFS(Spending!$D$6:$D$1005,Spending!$F$6:$F$1005,Envelopes!$B$21,Spending!$J$6:$J$1005,1,Spending!$H$6:$H$1005,"<"&Dashboard!$V$1)-SUMIFS(Spending!$D$6:$D$1005,Spending!$C$6:$C$1005,Envelopes!$B$21,Spending!$J$6:$J$1005,1,Spending!$H$6:$H$1005,"<"&Dashboard!$V$1)) | D23: =IF(B23="","",SUMIFS(Paydays!$T$6:$T$205,Paydays!$W$6:$W$205,">0",Paydays!$W$6:$W$205,">="&Dashboard!$V$1,Paydays!$W$6:$W$205,"<="&Dashboard!$V$2)) | E23: =IF(B23="","",SUMIFS(Spending!$D$6:$D$1005,Spending!$C$6:$C$1005,Envelopes!$B$21,Spending!$I$6:$I$1005,1,Spending!$H$6:$H$1005,">="&Dashboard!$V$1,Spending!$H$6:$H$1005,"<="&Dashboard!$V$2)) | F23: =IF(B23="","",SUMIFS(Spending!$D$6:$D$1005,Spending!$F$6:$F$1005,Envelopes!$B$21,Spending!$J$6:$J$1005,1,Spending!$H$6:$H$1005,">="&Dashboard!$V$1,Spending!$H$6:$H$1005,"<="&Dashboard!$V$2)-SUMIFS(Spending!$D$6:$D$1005,Spending!$C$6:$C$1005,Envelopes!$B$21,Spending!$J$6:$J$1005,1,Spending!$H$6:$H$1005,">="&Dashboard!$V$1,Spending!$H$6:$H$1005,"<="&Dashboard!$V$2)) | G23: =IF(B23="","",C23+D23-E23+F23) | H23: =IF(B23="","",IF(C23+D23+MAX(0,F23)<=0,"",REPT("█",MIN(10,MAX(0,ROUND((E23/(C23+D23+MAX(0,F23)))*10,0))))&REPT("░",10-MIN(10,MAX(0,ROUND((E23/(C23+D23+MAX(0,F23)))*10,0)))))) | J23: =IF(T23="","",IF(INDEX(Spending!$E$1:$E$1005,MOD(T23,10000))="","",INDEX(Spending!$E$1:$E$1005,MOD(T23,10000)))) | K23: =IF(T23="","",INDEX(Spending!$B$1:$B$1005,MOD(T23,10000))) | L23: =IF(T23="","",INDEX(Spending!$C$1:$C$1005,MOD(T23,10000))) | M23: =IF(T23="","",INDEX(Spending!$D$1:$D$1005,MOD(T23,10000))) | Q23: =IF(B23="","",IF(Envelopes!$C$21="Sinking fund","Sinking fund","Spending")) | R23: =IF(B23="","",Envelopes!$M$21) | T23: =IFERROR(LARGE(Spending!$K$6:$K$1005,6),"")
J24: =IF(T24="","",IF(INDEX(Spending!$E$1:$E$1005,MOD(T24,10000))="","",INDEX(Spending!$E$1:$E$1005,MOD(T24,10000)))) | K24: =IF(T24="","",INDEX(Spending!$B$1:$B$1005,MOD(T24,10000))) | L24: =IF(T24="","",INDEX(Spending!$C$1:$C$1005,MOD(T24,10000))) | M24: =IF(T24="","",INDEX(Spending!$D$1:$D$1005,MOD(T24,10000))) | T24: =IFERROR(LARGE(Spending!$K$6:$K$1005,7),"")
J25: =IF(T25="","",IF(INDEX(Spending!$E$1:$E$1005,MOD(T25,10000))="","",INDEX(Spending!$E$1:$E$1005,MOD(T25,10000)))) | K25: =IF(T25="","",INDEX(Spending!$B$1:$B$1005,MOD(T25,10000))) | L25: =IF(T25="","",INDEX(Spending!$C$1:$C$1005,MOD(T25,10000))) | M25: =IF(T25="","",INDEX(Spending!$D$1:$D$1005,MOD(T25,10000))) | T25: =IFERROR(LARGE(Spending!$K$6:$K$1005,8),"")
B26: Month | C26: Stuffed | D26: Spent
B27: Jan | C27: =SUMIFS(Paydays!$D$6:$D$205,Paydays!$W$6:$W$205,">="&DATE(YEAR(Dashboard!$V$1),1,1),Paydays!$W$6:$W$205,"<="&DATE(YEAR(Dashboard!$V$1),2,1)-1) | D27: =SUMIFS(Spending!$D$6:$D$1005,Spending!$I$6:$I$1005,1,Spending!$H$6:$H$1005,">="&DATE(YEAR(Dashboard!$V$1),1,1),Spending!$H$6:$H$1005,"<="&DATE(YEAR(Dashboard!$V$1),2,1)-1)
B28: Feb | C28: =SUMIFS(Paydays!$D$6:$D$205,Paydays!$W$6:$W$205,">="&DATE(YEAR(Dashboard!$V$1),2,1),Paydays!$W$6:$W$205,"<="&DATE(YEAR(Dashboard!$V$1),3,1)-1) | D28: =SUMIFS(Spending!$D$6:$D$1005,Spending!$I$6:$I$1005,1,Spending!$H$6:$H$1005,">="&DATE(YEAR(Dashboard!$V$1),2,1),Spending!$H$6:$H$1005,"<="&DATE(YEAR(Dashboard!$V$1),3,1)-1)
B29: Mar | C29: =SUMIFS(Paydays!$D$6:$D$205,Paydays!$W$6:$W$205,">="&DATE(YEAR(Dashboard!$V$1),3,1),Paydays!$W$6:$W$205,"<="&DATE(YEAR(Dashboard!$V$1),4,1)-1) | D29: =SUMIFS(Spending!$D$6:$D$1005,Spending!$I$6:$I$1005,1,Spending!$H$6:$H$1005,">="&DATE(YEAR(Dashboard!$V$1),3,1),Spending!$H$6:$H$1005,"<="&DATE(YEAR(Dashboard!$V$1),4,1)-1)
B30: Apr | C30: =SUMIFS(Paydays!$D$6:$D$205,Paydays!$W$6:$W$205,">="&DATE(YEAR(Dashboard!$V$1),4,1),Paydays!$W$6:$W$205,"<="&DATE(YEAR(Dashboard!$V$1),5,1)-1) | D30: =SUMIFS(Spending!$D$6:$D$1005,Spending!$I$6:$I$1005,1,Spending!$H$6:$H$1005,">="&DATE(YEAR(Dashboard!$V$1),4,1),Spending!$H$6:$H$1005,"<="&DATE(YEAR(Dashboard!$V$1),5,1)-1)
B31: May | C31: =SUMIFS(Paydays!$D$6:$D$205,Paydays!$W$6:$W$205,">="&DATE(YEAR(Dashboard!$V$1),5,1),Paydays!$W$6:$W$205,"<="&DATE(YEAR(Dashboard!$V$1),6,1)-1) | D31: =SUMIFS(Spending!$D$6:$D$1005,Spending!$I$6:$I$1005,1,Spending!$H$6:$H$1005,">="&DATE(YEAR(Dashboard!$V$1),5,1),Spending!$H$6:$H$1005,"<="&DATE(YEAR(Dashboard!$V$1),6,1)-1)
B32: Jun | C32: =SUMIFS(Paydays!$D$6:$D$205,Paydays!$W$6:$W$205,">="&DATE(YEAR(Dashboard!$V$1),6,1),Paydays!$W$6:$W$205,"<="&DATE(YEAR(Dashboard!$V$1),7,1)-1) | D32: =SUMIFS(Spending!$D$6:$D$1005,Spending!$I$6:$I$1005,1,Spending!$H$6:$H$1005,">="&DATE(YEAR(Dashboard!$V$1),6,1),Spending!$H$6:$H$1005,"<="&DATE(YEAR(Dashboard!$V$1),7,1)-1)
B33: Jul | C33: =SUMIFS(Paydays!$D$6:$D$205,Paydays!$W$6:$W$205,">="&DATE(YEAR(Dashboard!$V$1),7,1),Paydays!$W$6:$W$205,"<="&DATE(YEAR(Dashboard!$V$1),8,1)-1) | D33: =SUMIFS(Spending!$D$6:$D$1005,Spending!$I$6:$I$1005,1,Spending!$H$6:$H$1005,">="&DATE(YEAR(Dashboard!$V$1),7,1),Spending!$H$6:$H$1005,"<="&DATE(YEAR(Dashboard!$V$1),8,1)-1)
B34: Aug | C34: =SUMIFS(Paydays!$D$6:$D$205,Paydays!$W$6:$W$205,">="&DATE(YEAR(Dashboard!$V$1),8,1),Paydays!$W$6:$W$205,"<="&DATE(YEAR(Dashboard!$V$1),9,1)-1) | D34: =SUMIFS(Spending!$D$6:$D$1005,Spending!$I$6:$I$1005,1,Spending!$H$6:$H$1005,">="&DATE(YEAR(Dashboard!$V$1),8,1),Spending!$H$6:$H$1005,"<="&DATE(YEAR(Dashboard!$V$1),9,1)-1)
B35: Sep | C35: =SUMIFS(Paydays!$D$6:$D$205,Paydays!$W$6:$W$205,">="&DATE(YEAR(Dashboard!$V$1),9,1),Paydays!$W$6:$W$205,"<="&DATE(YEAR(Dashboard!$V$1),10,1)-1) | D35: =SUMIFS(Spending!$D$6:$D$1005,Spending!$I$6:$I$1005,1,Spending!$H$6:$H$1005,">="&DATE(YEAR(Dashboard!$V$1),9,1),Spending!$H$6:$H$1005,"<="&DATE(YEAR(Dashboard!$V$1),10,1)-1)
B36: Oct | C36: =SUMIFS(Paydays!$D$6:$D$205,Paydays!$W$6:$W$205,">="&DATE(YEAR(Dashboard!$V$1),10,1),Paydays!$W$6:$W$205,"<="&DATE(YEAR(Dashboard!$V$1),11,1)-1) | D36: =SUMIFS(Spending!$D$6:$D$1005,Spending!$I$6:$I$1005,1,Spending!$H$6:$H$1005,">="&DATE(YEAR(Dashboard!$V$1),10,1),Spending!$H$6:$H$1005,"<="&DATE(YEAR(Dashboard!$V$1),11,1)-1)
B37: Nov | C37: =SUMIFS(Paydays!$D$6:$D$205,Paydays!$W$6:$W$205,">="&DATE(YEAR(Dashboard!$V$1),11,1),Paydays!$W$6:$W$205,"<="&DATE(YEAR(Dashboard!$V$1),12,1)-1) | D37: =SUMIFS(Spending!$D$6:$D$1005,Spending!$I$6:$I$1005,1,Spending!$H$6:$H$1005,">="&DATE(YEAR(Dashboard!$V$1),11,1),Spending!$H$6:$H$1005,"<="&DATE(YEAR(Dashboard!$V$1),12,1)-1)
B38: Dec | C38: =SUMIFS(Paydays!$D$6:$D$205,Paydays!$W$6:$W$205,">="&DATE(YEAR(Dashboard!$V$1),12,1),Paydays!$W$6:$W$205,"<="&DATE(YEAR(Dashboard!$V$1),13,1)-1) | D38: =SUMIFS(Spending!$D$6:$D$1005,Spending!$I$6:$I$1005,1,Spending!$H$6:$H$1005,">="&DATE(YEAR(Dashboard!$V$1),12,1),Spending!$H$6:$H$1005,"<="&DATE(YEAR(Dashboard!$V$1),13,1)-1)

Sheet Paydays
B2: Paydays
B3: Each payday, what goes into each envelope. The plan row above the names shows your usual amounts.
D4: Plan | E4: =IF(Envelopes!$B$6="","",N(Envelopes!$D$6)) | F4: =IF(Envelopes!$B$7="","",N(Envelopes!$D$7)) | G4: =IF(Envelopes!$B$8="","",N(Envelopes!$D$8)) | H4: =IF(Envelopes!$B$9="","",N(Envelopes!$D$9)) | I4: =IF(Envelopes!$B$10="","",N(Envelopes!$D$10)) | J4: =IF(Envelopes!$B$11="","",N(Envelopes!$D$11)) | K4: =IF(Envelopes!$B$12="","",N(Envelopes!$D$12)) | L4: =IF(Envelopes!$B$13="","",N(Envelopes!$D$13)) | M4: =IF(Envelopes!$B$14="","",N(Envelopes!$D$14)) | N4: =IF(Envelopes!$B$15="","",N(Envelopes!$D$15)) | O4: =IF(Envelopes!$B$16="","",N(Envelopes!$D$16)) | P4: =IF(Envelopes!$B$17="","",N(Envelopes!$D$17)) | Q4: =IF(Envelopes!$B$18="","",N(Envelopes!$D$18)) | R4: =IF(Envelopes!$B$19="","",N(Envelopes!$D$19)) | S4: =IF(Envelopes!$B$20="","",N(Envelopes!$D$20)) | T4: =IF(Envelopes!$B$21="","",N(Envelopes!$D$21))
B5: Payday | C5: Paycheck | D5: Stuffed | E5: =IF(Envelopes!$B$6="","",Envelopes!$B$6) | F5: =IF(Envelopes!$B$7="","",Envelopes!$B$7) | G5: =IF(Envelopes!$B$8="","",Envelopes!$B$8) | H5: =IF(Envelopes!$B$9="","",Envelopes!$B$9) | I5: =IF(Envelopes!$B$10="","",Envelopes!$B$10) | J5: =IF(Envelopes!$B$11="","",Envelopes!$B$11) | K5: =IF(Envelopes!$B$12="","",Envelopes!$B$12) | L5: =IF(Envelopes!$B$13="","",Envelopes!$B$13) | M5: =IF(Envelopes!$B$14="","",Envelopes!$B$14) | N5: =IF(Envelopes!$B$15="","",Envelopes!$B$15) | O5: =IF(Envelopes!$B$16="","",Envelopes!$B$16) | P5: =IF(Envelopes!$B$17="","",Envelopes!$B$17) | Q5: =IF(Envelopes!$B$18="","",Envelopes!$B$18) | R5: =IF(Envelopes!$B$19="","",Envelopes!$B$19) | S5: =IF(Envelopes!$B$20="","",Envelopes!$B$20) | T5: =IF(Envelopes!$B$21="","",Envelopes!$B$21) | U5: Not in envelopes | V5: Check
B6: 45989 | C6: 1480 | D6: =IF(AND(B6="",SUMPRODUCT((E6:T6<>"")*1)=0),"",SUMPRODUCT((E$5:T$5<>"")*1,E6:T6)) | E6: 180 | F6: 60 | G6: 40 | H6: 30 | I6: 25 | J6: 30 | K6: 35 | L6: 25 | M6: 20 | N6: 40 | O6: 15 | P6: 50 | U6: =IF(OR(NOT(ISNUMBER(C6)),D6=""),"",C6-D6) | V6: =IF(AND(B6="",C6="",SUMPRODUCT((E6:T6<>"")*1)=0),"",IF(NOT(ISNUMBER(B6)),"Needs a date",IF(SUMPRODUCT((E6:T6<>"")*(1-ISNUMBER(E6:T6)))>0,"Amount not a number",IF(SUMPRODUCT((E$5:T$5="")*(E6:T6<>""))>0,"Amount under no envelope",IF(COUNTIF(E6:T6,"<0")>0,"Amount below zero",IF(AND(ISNUMBER(C6),N(D6)>C6),"More than the paycheck","")))))) | W6: =IF(ISNUMBER(B6),INT(B6),0)
B7: 46003 | C7: 1480 | D7: =IF(AND(B7="",SUMPRODUCT((E7:T7<>"")*1)=0),"",SUMPRODUCT((E$5:T$5<>"")*1,E7:T7)) | E7: 180 | F7: 60 | G7: 40 | H7: 30 | I7: 25 | J7: 30 | K7: 35 | L7: 25 | M7: 20 | N7: 40 | O7: 15 | P7: 50 | U7: =IF(OR(NOT(ISNUMBER(C7)),D7=""),"",C7-D7) | V7: =IF(AND(B7="",C7="",SUMPRODUCT((E7:T7<>"")*1)=0),"",IF(NOT(ISNUMBER(B7)),"Needs a date",IF(SUMPRODUCT((E7:T7<>"")*(1-ISNUMBER(E7:T7)))>0,"Amount not a number",IF(SUMPRODUCT((E$5:T$5="")*(E7:T7<>""))>0,"Amount under no envelope",IF(COUNTIF(E7:T7,"<0")>0,"Amount below zero",IF(AND(ISNUMBER(C7),N(D7)>C7),"More than the paycheck","")))))) | W7: =IF(ISNUMBER(B7),INT(B7),0)
B8: 46017 | C8: 1480 | D8: =IF(AND(B8="",SUMPRODUCT((E8:T8<>"")*1)=0),"",SUMPRODUCT((E$5:T$5<>"")*1,E8:T8)) | E8: 180 | F8: 60 | G8: 40 | H8: 30 | I8: 25 | J8: 30 | K8: 35 | L8: 25 | M8: 20 | N8: 40 | O8: 15 | P8: 50 | U8: =IF(OR(NOT(ISNUMBER(C8)),D8=""),"",C8-D8) | V8: =IF(AND(B8="",C8="",SUMPRODUCT((E8:T8<>"")*1)=0),"",IF(NOT(ISNUMBER(B8)),"Needs a date",IF(SUMPRODUCT((E8:T8<>"")*(1-ISNUMBER(E8:T8)))>0,"Amount not a number",IF(SUMPRODUCT((E$5:T$5="")*(E8:T8<>""))>0,"Amount under no envelope",IF(COUNTIF(E8:T8,"<0")>0,"Amount below zero",IF(AND(ISNUMBER(C8),N(D8)>C8),"More than the paycheck","")))))) | W8: =IF(ISNUMBER(B8),INT(B8),0)
B9: 46031 | C9: 1480 | D9: =IF(AND(B9="",SUMPRODUCT((E9:T9<>"")*1)=0),"",SUMPRODUCT((E$5:T$5<>"")*1,E9:T9)) | E9: 180 | F9: 60 | G9: 40 | H9: 30 | I9: 25 | J9: 30 | K9: 35 | L9: 25 | M9: 20 | N9: 40 | O9: 15 | P9: 50 | U9: =IF(OR(NOT(ISNUMBER(C9)),D9=""),"",C9-D9) | V9: =IF(AND(B9="",C9="",SUMPRODUCT((E9:T9<>"")*1)=0),"",IF(NOT(ISNUMBER(B9)),"Needs a date",IF(SUMPRODUCT((E9:T9<>"")*(1-ISNUMBER(E9:T9)))>0,"Amount not a number",IF(SUMPRODUCT((E$5:T$5="")*(E9:T9<>""))>0,"Amount under no envelope",IF(COUNTIF(E9:T9,"<0")>0,"Amount below zero",IF(AND(ISNUMBER(C9),N(D9)>C9),"More than the paycheck","")))))) | W9: =IF(ISNUMBER(B9),INT(B9),0)
B10: 46045 | C10: 1480 | D10: =IF(AND(B10="",SUMPRODUCT((E10:T10<>"")*1)=0),"",SUMPRODUCT((E$5:T$5<>"")*1,E10:T10)) | E10: 180 | F10: 60 | G10: 40 | H10: 30 | I10: 25 | J10: 30 | K10: 35 | L10: 25 | M10: 20 | N10: 40 | O10: 15 | P10: 50 | U10: =IF(OR(NOT(ISNUMBER(C10)),D10=""),"",C10-D10) | V10: =IF(AND(B10="",C10="",SUMPRODUCT((E10:T10<>"")*1)=0),"",IF(NOT(ISNUMBER(B10)),"Needs a date",IF(SUMPRODUCT((E10:T10<>"")*(1-ISNUMBER(E10:T10)))>0,"Amount not a number",IF(SUMPRODUCT((E$5:T$5="")*(E10:T10<>""))>0,"Amount under no envelope",IF(COUNTIF(E10:T10,"<0")>0,"Amount below zero",IF(AND(ISNUMBER(C10),N(D10)>C10),"More than the paycheck","")))))) | W10: =IF(ISNUMBER(B10),INT(B10),0)
B11: 46059 | C11: 1480 | D11: =IF(AND(B11="",SUMPRODUCT((E11:T11<>"")*1)=0),"",SUMPRODUCT((E$5:T$5<>"")*1,E11:T11)) | E11: 180 | F11: 60 | G11: 40 | H11: 30 | I11: 25 | J11: 30 | K11: 35 | L11: 25 | M11: 20 | N11: 40 | O11: 15 | P11: 50 | U11: =IF(OR(NOT(ISNUMBER(C11)),D11=""),"",C11-D11) | V11: =IF(AND(B11="",C11="",SUMPRODUCT((E11:T11<>"")*1)=0),"",IF(NOT(ISNUMBER(B11)),"Needs a date",IF(SUMPRODUCT((E11:T11<>"")*(1-ISNUMBER(E11:T11)))>0,"Amount not a number",IF(SUMPRODUCT((E$5:T$5="")*(E11:T11<>""))>0,"Amount under no envelope",IF(COUNTIF(E11:T11,"<0")>0,"Amount below zero",IF(AND(ISNUMBER(C11),N(D11)>C11),"More than the paycheck","")))))) | W11: =IF(ISNUMBER(B11),INT(B11),0)
B12: 46073 | C12: 1480 | D12: =IF(AND(B12="",SUMPRODUCT((E12:T12<>"")*1)=0),"",SUMPRODUCT((E$5:T$5<>"")*1,E12:T12)) | E12: 180 | F12: 60 | G12: 40 | H12: 30 | I12: 25 | J12: 30 | K12: 35 | L12: 25 | M12: 20 | N12: 40 | O12: 15 | P12: 50 | U12: =IF(OR(NOT(ISNUMBER(C12)),D12=""),"",C12-D12) | V12: =IF(AND(B12="",C12="",SUMPRODUCT((E12:T12<>"")*1)=0),"",IF(NOT(ISNUMBER(B12)),"Needs a date",IF(SUMPRODUCT((E12:T12<>"")*(1-ISNUMBER(E12:T12)))>0,"Amount not a number",IF(SUMPRODUCT((E$5:T$5="")*(E12:T12<>""))>0,"Amount under no envelope",IF(COUNTIF(E12:T12,"<0")>0,"Amount below zero",IF(AND(ISNUMBER(C12),N(D12)>C12),"More than the paycheck","")))))) | W12: =IF(ISNUMBER(B12),INT(B12),0)
B13: 46087 | C13: 1480 | D13: =IF(AND(B13="",SUMPRODUCT((E13:T13<>"")*1)=0),"",SUMPRODUCT((E$5:T$5<>"")*1,E13:T13)) | E13: 180 | F13: 60 | G13: 40 | H13: 30 | I13: 25 | J13: 30 | K13: 35 | L13: 25 | M13: 20 | N13: 40 | O13: 15 | P13: 50 | U13: =IF(OR(NOT(ISNUMBER(C13)),D13=""),"",C13-D13) | V13: =IF(AND(B13="",C13="",SUMPRODUCT((E13:T13<>"")*1)=0),"",IF(NOT(ISNUMBER(B13)),"Needs a date",IF(SUMPRODUCT((E13:T13<>"")*(1-ISNUMBER(E13:T13)))>0,"Amount not a number",IF(SUMPRODUCT((E$5:T$5="")*(E13:T13<>""))>0,"Amount under no envelope",IF(COUNTIF(E13:T13,"<0")>0,"Amount below zero",IF(AND(ISNUMBER(C13),N(D13)>C13),"More than the paycheck","")))))) | W13: =IF(ISNUMBER(B13),INT(B13),0)
B14: 46101 | C14: 1480 | D14: =IF(AND(B14="",SUMPRODUCT((E14:T14<>"")*1)=0),"",SUMPRODUCT((E$5:T$5<>"")*1,E14:T14)) | E14: 180 | F14: 60 | G14: 40 | H14: 30 | I14: 25 | J14: 30 | K14: 35 | L14: 25 | M14: 20 | N14: 40 | O14: 15 | P14: 50 | U14: =IF(OR(NOT(ISNUMBER(C14)),D14=""),"",C14-D14) | V14: =IF(AND(B14="",C14="",SUMPRODUCT((E14:T14<>"")*1)=0),"",IF(NOT(ISNUMBER(B14)),"Needs a date",IF(SUMPRODUCT((E14:T14<>"")*(1-ISNUMBER(E14:T14)))>0,"Amount not a number",IF(SUMPRODUCT((E$5:T$5="")*(E14:T14<>""))>0,"Amount under no envelope",IF(COUNTIF(E14:T14,"<0")>0,"Amount below zero",IF(AND(ISNUMBER(C14),N(D14)>C14),"More than the paycheck","")))))) | W14: =IF(ISNUMBER(B14),INT(B14),0)
B15: 46115 | C15: 1780 | D15: =IF(AND(B15="",SUMPRODUCT((E15:T15<>"")*1)=0),"",SUMPRODUCT((E$5:T$5<>"")*1,E15:T15)) | E15: 180 | F15: 60 | G15: 40 | H15: 30 | I15: 25 | J15: 30 | K15: 35 | L15: 25 | M15: 20 | N15: 140 | O15: 15 | P15: 150 | U15: =IF(OR(NOT(ISNUMBER(C15)),D15=""),"",C15-D15) | V15: =IF(AND(B15="",C15="",SUMPRODUCT((E15:T15<>"")*1)=0),"",IF(NOT(ISNUMBER(B15)),"Needs a date",IF(SUMPRODUCT((E15:T15<>"")*(1-ISNUMBER(E15:T15)))>0,"Amount not a number",IF(SUMPRODUCT((E$5:T$5="")*(E15:T15<>""))>0,"Amount under no envelope",IF(COUNTIF(E15:T15,"<0")>0,"Amount below zero",IF(AND(ISNUMBER(C15),N(D15)>C15),"More than the paycheck","")))))) | W15: =IF(ISNUMBER(B15),INT(B15),0)
B16: 46129 | C16: 1480 | D16: =IF(AND(B16="",SUMPRODUCT((E16:T16<>"")*1)=0),"",SUMPRODUCT((E$5:T$5<>"")*1,E16:T16)) | E16: 180 | F16: 60 | G16: 40 | H16: 30 | I16: 25 | J16: 30 | K16: 35 | L16: 25 | M16: 20 | N16: 40 | O16: 15 | P16: 50 | U16: =IF(OR(NOT(ISNUMBER(C16)),D16=""),"",C16-D16) | V16: =IF(AND(B16="",C16="",SUMPRODUCT((E16:T16<>"")*1)=0),"",IF(NOT(ISNUMBER(B16)),"Needs a date",IF(SUMPRODUCT((E16:T16<>"")*(1-ISNUMBER(E16:T16)))>0,"Amount not a number",IF(SUMPRODUCT((E$5:T$5="")*(E16:T16<>""))>0,"Amount under no envelope",IF(COUNTIF(E16:T16,"<0")>0,"Amount below zero",IF(AND(ISNUMBER(C16),N(D16)>C16),"More than the paycheck","")))))) | W16: =IF(ISNUMBER(B16),INT(B16),0)
B17: 46143 | C17: 1480 | D17: =IF(AND(B17="",SUMPRODUCT((E17:T17<>"")*1)=0),"",SUMPRODUCT((E$5:T$5<>"")*1,E17:T17)) | E17: 180 | F17: 60 | G17: 40 | H17: 30 | I17: 25 | J17: 30 | K17: 35 | L17: 25 | M17: 20 | N17: 40 | O17: 15 | P17: 50 | U17: =IF(OR(NOT(ISNUMBER(C17)),D17=""),"",C17-D17) | V17: =IF(AND(B17="",C17="",SUMPRODUCT((E17:T17<>"")*1)=0),"",IF(NOT(ISNUMBER(B17)),"Needs a date",IF(SUMPRODUCT((E17:T17<>"")*(1-ISNUMBER(E17:T17)))>0,"Amount not a number",IF(SUMPRODUCT((E$5:T$5="")*(E17:T17<>""))>0,"Amount under no envelope",IF(COUNTIF(E17:T17,"<0")>0,"Amount below zero",IF(AND(ISNUMBER(C17),N(D17)>C17),"More than the paycheck","")))))) | W17: =IF(ISNUMBER(B17),INT(B17),0)
... B27: 46283 | C27: 1480 | D27: =IF(AND(B27="",SUMPRODUCT((E27:T27<>"")*1)=0),"",SUMPRODUCT((E$5:T$5<>"")*1,E27:T27)) | E27: 180 | F27: 62.5 | G27: 40 | H27: 33 | I27: 25 | J27: 30 | K27: 35 | L27: 25 | M27: 20 | N27: 40 | O27: 15 | P27: 50 | U27: =IF(OR(NOT(ISNUMBER(C27)),D27=""),"",C27-D27) | V27: =IF(AND(B27="",C27="",SUMPRODUCT((E27:T27<>"")*1)=0),"",IF(NOT(ISNUMBER(B27)),"Needs a date",IF(SUMPRODUCT((E27:T27<>"")*(1-ISNUMBER(E27:T27)))>0,"Amount not a number",IF(SUMPRODUCT((E$5:T$5="")*(E27:T27<>""))>0,"Amount under no envelope",IF(COUNTIF(E27:T27,"<0")>0,"Amount below zero",IF(AND(ISNUMBER(C27),N(D27)>C27),"More than the paycheck","")))))) | W27: =IF(ISNUMBER(B27),INT(B27),0)
D28: =IF(AND(B28="",SUMPRODUCT((E28:T28<>"")*1)=0),"",SUMPRODUCT((E$5:T$5<>"")*1,E28:T28)) | U28: =IF(OR(NOT(ISNUMBER(C28)),D28=""),"",C28-D28) | V28: =IF(AND(B28="",C28="",SUMPRODUCT((E28:T28<>"")*1)=0),"",IF(NOT(ISNUMBER(B28)),"Needs a date",IF(SUMPRODUCT((E28:T28<>"")*(1-ISNUMBER(E28:T28)))>0,"Amount not a number",IF(SUMPRODUCT((E$5:T$5="")*(E28:T28<>""))>0,"Amount under no envelope",IF(COUNTIF(E28:T28,"<0")>0,"Amount below zero",IF(AND(ISNUMBER(C28),N(D28)>C28),"More than the paycheck","")))))) | W28: =IF(ISNUMBER(B28),INT(B28),0)
D29: =IF(AND(B29="",SUMPRODUCT((E29:T29<>"")*1)=0),"",SUMPRODUCT((E$5:T$5<>"")*1,E29:T29)) | U29: =IF(OR(NOT(ISNUMBER(C29)),D29=""),"",C29-D29) | V29: =IF(AND(B29="",C29="",SUMPRODUCT((E29:T29<>"")*1)=0),"",IF(NOT(ISNUMBER(B29)),"Needs a date",IF(SUMPRODUCT((E29:T29<>"")*(1-ISNUMBER(E29:T29)))>0,"Amount not a number",IF(SUMPRODUCT((E$5:T$5="")*(E29:T29<>""))>0,"Amount under no envelope",IF(COUNTIF(E29:T29,"<0")>0,"Amount below zero",IF(AND(ISNUMBER(C29),N(D29)>C29),"More than the paycheck","")))))) | W29: =IF(ISNUMBER(B29),INT(B29),0)
D30: =IF(AND(B30="",SUMPRODUCT((E30:T30<>"")*1)=0),"",SUMPRODUCT((E$5:T$5<>"")*1,E30:T30)) | U30: =IF(OR(NOT(ISNUMBER(C30)),D30=""),"",C30-D30) | V30: =IF(AND(B30="",C30="",SUMPRODUCT((E30:T30<>"")*1)=0),"",IF(NOT(ISNUMBER(B30)),"Needs a date",IF(SUMPRODUCT((E30:T30<>"")*(1-ISNUMBER(E30:T30)))>0,"Amount not a number",IF(SUMPRODUCT((E$5:T$5="")*(E30:T30<>""))>0,"Amount under no envelope",IF(COUNTIF(E30:T30,"<0")>0,"Amount below zero",IF(AND(ISNUMBER(C30),N(D30)>C30),"More than the paycheck","")))))) | W30: =IF(ISNUMBER(B30),INT(B30),0)
D31: =IF(AND(B31="",SUMPRODUCT((E31:T31<>"")*1)=0),"",SUMPRODUCT((E$5:T$5<>"")*1,E31:T31)) | U31: =IF(OR(NOT(ISNUMBER(C31)),D31=""),"",C31-D31) | V31: =IF(AND(B31="",C31="",SUMPRODUCT((E31:T31<>"")*1)=0),"",IF(NOT(ISNUMBER(B31)),"Needs a date",IF(SUMPRODUCT((E31:T31<>"")*(1-ISNUMBER(E31:T31)))>0,"Amount not a number",IF(SUMPRODUCT((E$5:T$5="")*(E31:T31<>""))>0,"Amount under no envelope",IF(COUNTIF(E31:T31,"<0")>0,"Amount below zero",IF(AND(ISNUMBER(C31),N(D31)>C31),"More than the paycheck","")))))) | W31: =IF(ISNUMBER(B31),INT(B31),0)
D32: =IF(AND(B32="",SUMPRODUCT((E32:T32<>"")*1)=0),"",SUMPRODUCT((E$5:T$5<>"")*1,E32:T32)) | U32: =IF(OR(NOT(ISNUMBER(C32)),D32=""),"",C32-D32) | V32: =IF(AND(B32="",C32="",SUMPRODUCT((E32:T32<>"")*1)=0),"",IF(NOT(ISNUMBER(B32)),"Needs a date",IF(SUMPRODUCT((E32:T32<>"")*(1-ISNUMBER(E32:T32)))>0,"Amount not a number",IF(SUMPRODUCT((E$5:T$5="")*(E32:T32<>""))>0,"Amount under no envelope",IF(COUNTIF(E32:T32,"<0")>0,"Amount below zero",IF(AND(ISNUMBER(C32),N(D32)>C32),"More than the paycheck","")))))) | W32: =IF(ISNUMBER(B32),INT(B32),0)
D33: =IF(AND(B33="",SUMPRODUCT((E33:T33<>"")*1)=0),"",SUMPRODUCT((E$5:T$5<>"")*1,E33:T33)) | U33: =IF(OR(NOT(ISNUMBER(C33)),D33=""),"",C33-D33) | V33: =IF(AND(B33="",C33="",SUMPRODUCT((E33:T33<>"")*1)=0),"",IF(NOT(ISNUMBER(B33)),"Needs a date",IF(SUMPRODUCT((E33:T33<>"")*(1-ISNUMBER(E33:T33)))>0,"Amount not a number",IF(SUMPRODUCT((E$5:T$5="")*(E33:T33<>""))>0,"Amount under no envelope",IF(COUNTIF(E33:T33,"<0")>0,"Amount below zero",IF(AND(ISNUMBER(C33),N(D33)>C33),"More than the paycheck","")))))) | W33: =IF(ISNUMBER(B33),INT(B33),0)
D34: =IF(AND(B34="",SUMPRODUCT((E34:T34<>"")*1)=0),"",SUMPRODUCT((E$5:T$5<>"")*1,E34:T34)) | U34: =IF(OR(NOT(ISNUMBER(C34)),D34=""),"",C34-D34) | V34: =IF(AND(B34="",C34="",SUMPRODUCT((E34:T34<>"")*1)=0),"",IF(NOT(ISNUMBER(B34)),"Needs a date",IF(SUMPRODUCT((E34:T34<>"")*(1-ISNUMBER(E34:T34)))>0,"Amount not a number",IF(SUMPRODUCT((E$5:T$5="")*(E34:T34<>""))>0,"Amount under no envelope",IF(COUNTIF(E34:T34,"<0")>0,"Amount below zero",IF(AND(ISNUMBER(C34),N(D34)>C34),"More than the paycheck","")))))) | W34: =IF(ISNUMBER(B34),INT(B34),0)
D35: =IF(AND(B35="",SUMPRODUCT((E35:T35<>"")*1)=0),"",SUMPRODUCT((E$5:T$5<>"")*1,E35:T35)) | U35: =IF(OR(NOT(ISNUMBER(C35)),D35=""),"",C35-D35) | V35: =IF(AND(B35="",C35="",SUMPRODUCT((E35:T35<>"")*1)=0),"",IF(NOT(ISNUMBER(B35)),"Needs a date",IF(SUMPRODUCT((E35:T35<>"")*(1-ISNUMBER(E35:T35)))>0,"Amount not a number",IF(SUMPRODUCT((E$5:T$5="")*(E35:T35<>""))>0,"Amount under no envelope",IF(COUNTIF(E35:T35,"<0")>0,"Amount below zero",IF(AND(ISNUMBER(C35),N(D35)>C35),"More than the paycheck","")))))) | W35: =IF(ISNUMBER(B35),INT(B35),0)
D36: =IF(AND(B36="",SUMPRODUCT((E36:T36<>"")*1)=0),"",SUMPRODUCT((E$5:T$5<>"")*1,E36:T36)) | U36: =IF(OR(NOT(ISNUMBER(C36)),D36=""),"",C36-D36) | V36: =IF(AND(B36="",C36="",SUMPRODUCT((E36:T36<>"")*1)=0),"",IF(NOT(ISNUMBER(B36)),"Needs a date",IF(SUMPRODUCT((E36:T36<>"")*(1-ISNUMBER(E36:T36)))>0,"Amount not a number",IF(SUMPRODUCT((E$5:T$5="")*(E36:T36<>""))>0,"Amount under no envelope",IF(COUNTIF(E36:T36,"<0")>0,"Amount below zero",IF(AND(ISNUMBER(C36),N(D36)>C36),"More than the paycheck","")))))) | W36: =IF(ISNUMBER(B36),INT(B36),0)
D37: =IF(AND(B37="",SUMPRODUCT((E37:T37<>"")*1)=0),"",SUMPRODUCT((E$5:T$5<>"")*1,E37:T37)) | U37: =IF(OR(NOT(ISNUMBER(C37)),D37=""),"",C37-D37) | V37: =IF(AND(B37="",C37="",SUMPRODUCT((E37:T37<>"")*1)=0),"",IF(NOT(ISNUMBER(B37)),"Needs a date",IF(SUMPRODUCT((E37:T37<>"")*(1-ISNUMBER(E37:T37)))>0,"Amount not a number",IF(SUMPRODUCT((E$5:T$5="")*(E37:T37<>""))>0,"Amount under no envelope",IF(COUNTIF(E37:T37,"<0")>0,"Amount below zero",IF(AND(ISNUMBER(C37),N(D37)>C37),"More than the paycheck","")))))) | W37: =IF(ISNUMBER(B37),INT(B37),0)
D38: =IF(AND(B38="",SUMPRODUCT((E38:T38<>"")*1)=0),"",SUMPRODUCT((E$5:T$5<>"")*1,E38:T38)) | U38: =IF(OR(NOT(ISNUMBER(C38)),D38=""),"",C38-D38) | V38: =IF(AND(B38="",C38="",SUMPRODUCT((E38:T38<>"")*1)=0),"",IF(NOT(ISNUMBER(B38)),"Needs a date",IF(SUMPRODUCT((E38:T38<>"")*(1-ISNUMBER(E38:T38)))>0,"Amount not a number",IF(SUMPRODUCT((E$5:T$5="")*(E38:T38<>""))>0,"Amount under no envelope",IF(COUNTIF(E38:T38,"<0")>0,"Amount below zero",IF(AND(ISNUMBER(C38),N(D38)>C38),"More than the paycheck","")))))) | W38: =IF(ISNUMBER(B38),INT(B38),0)
D39: =IF(AND(B39="",SUMPRODUCT((E39:T39<>"")*1)=0),"",SUMPRODUCT((E$5:T$5<>"")*1,E39:T39)) | U39: =IF(OR(NOT(ISNUMBER(C39)),D39=""),"",C39-D39) | V39: =IF(AND(B39="",C39="",SUMPRODUCT((E39:T39<>"")*1)=0),"",IF(NOT(ISNUMBER(B39)),"Needs a date",IF(SUMPRODUCT((E39:T39<>"")*(1-ISNUMBER(E39:T39)))>0,"Amount not a number",IF(SUMPRODUCT((E$5:T$5="")*(E39:T39<>""))>0,"Amount under no envelope",IF(COUNTIF(E39:T39,"<0")>0,"Amount below zero",IF(AND(ISNUMBER(C39),N(D39)>C39),"More than the paycheck","")))))) | W39: =IF(ISNUMBER(B39),INT(B39),0)
... D205: =IF(AND(B205="",SUMPRODUCT((E205:T205<>"")*1)=0),"",SUMPRODUCT((E$5:T$5<>"")*1,E205:T205)) | U205: =IF(OR(NOT(ISNUMBER(C205)),D205=""),"",C205-D205) | V205: =IF(AND(B205="",C205="",SUMPRODUCT((E205:T205<>"")*1)=0),"",IF(NOT(ISNUMBER(B205)),"Needs a date",IF(SUMPRODUCT((E205:T205<>"")*(1-ISNUMBER(E205:T205)))>0,"Amount not a number",IF(SUMPRODUCT((E$5:T$5="")*(E205:T205<>""))>0,"Amount under no envelope",IF(COUNTIF(E205:T205,"<0")>0,"Amount below zero",IF(AND(ISNUMBER(C205),N(D205)>C205),"More than the paycheck","")))))) | W205: =IF(ISNUMBER(B205),INT(B205),0)

Sheet Spending
B2: Spending
B3: Each time you spend cash from an envelope. To move cash to another envelope, pick it under Moved to.
B5: Date | C5: Envelope | D5: Amount | E5: What | F5: Moved to | G5: Check
B6: 45991 | C6: Personal care | D6: 24.65 | E6: Pharmacy | G6: =IF(AND(C6="",D6=""),"",IF(NOT(ISNUMBER(B6)),"Needs a date",IF(NOT(ISNUMBER(D6)),"Needs the amount",IF(C6="","Needs an envelope",IF(COUNTIF(Envelopes!$B$6:$B$21,C6)=0,"Not on Envelopes",IF(F6="",IF(D6=0,"Needs the amount",""),IF(COUNTIF(Envelopes!$B$6:$B$21,F6)=0,"Moved to: not on Envelopes",IF(D6<=0,"A move needs an amount",IF(F6=C6,"Moved to the same envelope",""))))))))) | H6: =IF(ISNUMBER(B6),INT(B6),0) | I6: =IF(AND(H6>0,ISNUMBER(D6),COUNTIF(Envelopes!$B$6:$B$21,C6)>0,F6=""),1,0) | J6: =IF(AND(H6>0,ISNUMBER(D6),COUNTIF(Envelopes!$B$6:$B$21,C6)>0,F6<>"",COUNTIF(Envelopes!$B$6:$B$21,F6)>0),1,0) | K6: =IF(I6=1,H6*10000+ROW(),"")
B7: 45991 | C7: Kids | D7: 32.59 | E7: Swimming | G7: =IF(AND(C7="",D7=""),"",IF(NOT(ISNUMBER(B7)),"Needs a date",IF(NOT(ISNUMBER(D7)),"Needs the amount",IF(C7="","Needs an envelope",IF(COUNTIF(Envelopes!$B$6:$B$21,C7)=0,"Not on Envelopes",IF(F7="",IF(D7=0,"Needs the amount",""),IF(COUNTIF(Envelopes!$B$6:$B$21,F7)=0,"Moved to: not on Envelopes",IF(D7<=0,"A move needs an amount",IF(F7=C7,"Moved to the same envelope",""))))))))) | H7: =IF(ISNUMBER(B7),INT(B7),0) | I7: =IF(AND(H7>0,ISNUMBER(D7),COUNTIF(Envelopes!$B$6:$B$21,C7)>0,F7=""),1,0) | J7: =IF(AND(H7>0,ISNUMBER(D7),COUNTIF(Envelopes!$B$6:$B$21,C7)>0,F7<>"",COUNTIF(Envelopes!$B$6:$B$21,F7)>0),1,0) | K7: =IF(I7=1,H7*10000+ROW(),"")
B8: 45992 | C8: Groceries | D8: 43.59 | E8: Supermarket | G8: =IF(AND(C8="",D8=""),"",IF(NOT(ISNUMBER(B8)),"Needs a date",IF(NOT(ISNUMBER(D8)),"Needs the amount",IF(C8="","Needs an envelope",IF(COUNTIF(Envelopes!$B$6:$B$21,C8)=0,"Not on Envelopes",IF(F8="",IF(D8=0,"Needs the amount",""),IF(COUNTIF(Envelopes!$B$6:$B$21,F8)=0,"Moved to: not on Envelopes",IF(D8<=0,"A move needs an amount",IF(F8=C8,"Moved to the same envelope",""))))))))) | H8: =IF(ISNUMBER(B8),INT(B8),0) | I8: =IF(AND(H8>0,ISNUMBER(D8),COUNTIF(Envelopes!$B$6:$B$21,C8)>0,F8=""),1,0) | J8: =IF(AND(H8>0,ISNUMBER(D8),COUNTIF(Envelopes!$B$6:$B$21,C8)>0,F8<>"",COUNTIF(Envelopes!$B$6:$B$21,F8)>0),1,0) | K8: =IF(I8=1,H8*10000+ROW(),"")
