Workbook

Sheet Dashboard
B2: Software and tools
B3: What the tools cost on the left, what needs a look on the right.
B4: Per month | C4: Per year | D4: Tools in use | E4: Per person a month | G4: ="Due in the next "&N(Settings!$C$5)&" days" | H4: Unused seats | I4: Unused a year | J4: To remove
B5: =SUM(Tools!$O$6:$O$105) | C5: =SUM(Tools!$P$6:$P$105) | D5: =COUNTIFS(Tools!$B$6:$B$105,"<>",Tools!$T$6:$T$105,"<>Cancelled") | E5: =IF(COUNTIF(Team!$H$6:$H$105,"Active")=0,"",SUM(Tools!$O$6:$O$105)/COUNTIF(Team!$H$6:$H$105,"Active")) | G5: =SUMIFS(Tools!$N$6:$N$105,Tools!$Q$6:$Q$105,">="&TODAY(),Tools!$Q$6:$Q$105,"<="&(TODAY()+N(Settings!$C$5))) | H5: =SUM(Tools!$S$6:$S$105) | I5: =SUM(Tools!$Y$6:$Y$105) | J5: =COUNTIF(Access!$H$6:$H$405,"Remove now")
B8: Coming up | C8: Charge on | D8: Amount | E8: Cancel by | G8: Needs a look | H8: Status | I8: Owner | J8: Per month
B9: =IF(O9="","Nothing to pay",INDEX(Tools!$B$6:$B$105,MATCH(O9,Tools!$V$6:$V$105,0))) | C9: =IF(O9="","",INT(O9)) | D9: =IF(O9="","",INDEX(Tools!$N$6:$N$105,MATCH(O9,Tools!$V$6:$V$105,0))) | E9: =IF(O9="","",IF(N(INDEX(Tools!$K$6:$K$105,MATCH(O9,Tools!$V$6:$V$105,0)))=0,"",INDEX(Tools!$R$6:$R$105,MATCH(O9,Tools!$V$6:$V$105,0)))) | G9: =IF(P9="","Nothing needs a look",INDEX(Tools!$B$6:$B$105,P9-5)) | H9: =IF(P9="","",INDEX(Tools!$T$6:$T$105,P9-5)) | I9: =IF(P9="","",IF(INDEX(Tools!$D$6:$D$105,P9-5)="","",INDEX(Tools!$D$6:$D$105,P9-5))) | J9: =IF(P9="","",INDEX(Tools!$O$6:$O$105,P9-5)) | O9: =IFERROR(SMALL(Tools!$V$6:$V$105,1),"") | P9: =IFERROR(SMALL(Tools!$X$6:$X$105,1),"")
B10: =IF(O10="","",INDEX(Tools!$B$6:$B$105,MATCH(O10,Tools!$V$6:$V$105,0))) | C10: =IF(O10="","",INT(O10)) | D10: =IF(O10="","",INDEX(Tools!$N$6:$N$105,MATCH(O10,Tools!$V$6:$V$105,0))) | E10: =IF(O10="","",IF(N(INDEX(Tools!$K$6:$K$105,MATCH(O10,Tools!$V$6:$V$105,0)))=0,"",INDEX(Tools!$R$6:$R$105,MATCH(O10,Tools!$V$6:$V$105,0)))) | G10: =IF(P10="","",INDEX(Tools!$B$6:$B$105,P10-5)) | H10: =IF(P10="","",INDEX(Tools!$T$6:$T$105,P10-5)) | I10: =IF(P10="","",IF(INDEX(Tools!$D$6:$D$105,P10-5)="","",INDEX(Tools!$D$6:$D$105,P10-5))) | J10: =IF(P10="","",INDEX(Tools!$O$6:$O$105,P10-5)) | O10: =IFERROR(SMALL(Tools!$V$6:$V$105,2),"") | P10: =IFERROR(SMALL(Tools!$X$6:$X$105,2),"")
B11: =IF(O11="","",INDEX(Tools!$B$6:$B$105,MATCH(O11,Tools!$V$6:$V$105,0))) | C11: =IF(O11="","",INT(O11)) | D11: =IF(O11="","",INDEX(Tools!$N$6:$N$105,MATCH(O11,Tools!$V$6:$V$105,0))) | E11: =IF(O11="","",IF(N(INDEX(Tools!$K$6:$K$105,MATCH(O11,Tools!$V$6:$V$105,0)))=0,"",INDEX(Tools!$R$6:$R$105,MATCH(O11,Tools!$V$6:$V$105,0)))) | G11: =IF(P11="","",INDEX(Tools!$B$6:$B$105,P11-5)) | H11: =IF(P11="","",INDEX(Tools!$T$6:$T$105,P11-5)) | I11: =IF(P11="","",IF(INDEX(Tools!$D$6:$D$105,P11-5)="","",INDEX(Tools!$D$6:$D$105,P11-5))) | J11: =IF(P11="","",INDEX(Tools!$O$6:$O$105,P11-5)) | O11: =IFERROR(SMALL(Tools!$V$6:$V$105,3),"") | P11: =IFERROR(SMALL(Tools!$X$6:$X$105,3),"")
B12: =IF(O12="","",INDEX(Tools!$B$6:$B$105,MATCH(O12,Tools!$V$6:$V$105,0))) | C12: =IF(O12="","",INT(O12)) | D12: =IF(O12="","",INDEX(Tools!$N$6:$N$105,MATCH(O12,Tools!$V$6:$V$105,0))) | E12: =IF(O12="","",IF(N(INDEX(Tools!$K$6:$K$105,MATCH(O12,Tools!$V$6:$V$105,0)))=0,"",INDEX(Tools!$R$6:$R$105,MATCH(O12,Tools!$V$6:$V$105,0)))) | G12: =IF(P12="","",INDEX(Tools!$B$6:$B$105,P12-5)) | H12: =IF(P12="","",INDEX(Tools!$T$6:$T$105,P12-5)) | I12: =IF(P12="","",IF(INDEX(Tools!$D$6:$D$105,P12-5)="","",INDEX(Tools!$D$6:$D$105,P12-5))) | J12: =IF(P12="","",INDEX(Tools!$O$6:$O$105,P12-5)) | O12: =IFERROR(SMALL(Tools!$V$6:$V$105,4),"") | P12: =IFERROR(SMALL(Tools!$X$6:$X$105,4),"")
B13: =IF(O13="","",INDEX(Tools!$B$6:$B$105,MATCH(O13,Tools!$V$6:$V$105,0))) | C13: =IF(O13="","",INT(O13)) | D13: =IF(O13="","",INDEX(Tools!$N$6:$N$105,MATCH(O13,Tools!$V$6:$V$105,0))) | E13: =IF(O13="","",IF(N(INDEX(Tools!$K$6:$K$105,MATCH(O13,Tools!$V$6:$V$105,0)))=0,"",INDEX(Tools!$R$6:$R$105,MATCH(O13,Tools!$V$6:$V$105,0)))) | G13: =IF(P13="","",INDEX(Tools!$B$6:$B$105,P13-5)) | H13: =IF(P13="","",INDEX(Tools!$T$6:$T$105,P13-5)) | I13: =IF(P13="","",IF(INDEX(Tools!$D$6:$D$105,P13-5)="","",INDEX(Tools!$D$6:$D$105,P13-5))) | J13: =IF(P13="","",INDEX(Tools!$O$6:$O$105,P13-5)) | O13: =IFERROR(SMALL(Tools!$V$6:$V$105,5),"") | P13: =IFERROR(SMALL(Tools!$X$6:$X$105,5),"")
B14: =IF(O14="","",INDEX(Tools!$B$6:$B$105,MATCH(O14,Tools!$V$6:$V$105,0))) | C14: =IF(O14="","",INT(O14)) | D14: =IF(O14="","",INDEX(Tools!$N$6:$N$105,MATCH(O14,Tools!$V$6:$V$105,0))) | E14: =IF(O14="","",IF(N(INDEX(Tools!$K$6:$K$105,MATCH(O14,Tools!$V$6:$V$105,0)))=0,"",INDEX(Tools!$R$6:$R$105,MATCH(O14,Tools!$V$6:$V$105,0)))) | G14: =IF(P14="","",INDEX(Tools!$B$6:$B$105,P14-5)) | H14: =IF(P14="","",INDEX(Tools!$T$6:$T$105,P14-5)) | I14: =IF(P14="","",IF(INDEX(Tools!$D$6:$D$105,P14-5)="","",INDEX(Tools!$D$6:$D$105,P14-5))) | J14: =IF(P14="","",INDEX(Tools!$O$6:$O$105,P14-5)) | O14: =IFERROR(SMALL(Tools!$V$6:$V$105,6),"") | P14: =IFERROR(SMALL(Tools!$X$6:$X$105,6),"")
B15: =IF(O15="","",INDEX(Tools!$B$6:$B$105,MATCH(O15,Tools!$V$6:$V$105,0))) | C15: =IF(O15="","",INT(O15)) | D15: =IF(O15="","",INDEX(Tools!$N$6:$N$105,MATCH(O15,Tools!$V$6:$V$105,0))) | E15: =IF(O15="","",IF(N(INDEX(Tools!$K$6:$K$105,MATCH(O15,Tools!$V$6:$V$105,0)))=0,"",INDEX(Tools!$R$6:$R$105,MATCH(O15,Tools!$V$6:$V$105,0)))) | G15: =IF(P15="","",INDEX(Tools!$B$6:$B$105,P15-5)) | H15: =IF(P15="","",INDEX(Tools!$T$6:$T$105,P15-5)) | I15: =IF(P15="","",IF(INDEX(Tools!$D$6:$D$105,P15-5)="","",INDEX(Tools!$D$6:$D$105,P15-5))) | J15: =IF(P15="","",INDEX(Tools!$O$6:$O$105,P15-5)) | O15: =IFERROR(SMALL(Tools!$V$6:$V$105,7),"") | P15: =IFERROR(SMALL(Tools!$X$6:$X$105,7),"")
B16: =IF(O16="","",INDEX(Tools!$B$6:$B$105,MATCH(O16,Tools!$V$6:$V$105,0))) | C16: =IF(O16="","",INT(O16)) | D16: =IF(O16="","",INDEX(Tools!$N$6:$N$105,MATCH(O16,Tools!$V$6:$V$105,0))) | E16: =IF(O16="","",IF(N(INDEX(Tools!$K$6:$K$105,MATCH(O16,Tools!$V$6:$V$105,0)))=0,"",INDEX(Tools!$R$6:$R$105,MATCH(O16,Tools!$V$6:$V$105,0)))) | G16: =IF(P16="","",INDEX(Tools!$B$6:$B$105,P16-5)) | H16: =IF(P16="","",INDEX(Tools!$T$6:$T$105,P16-5)) | I16: =IF(P16="","",IF(INDEX(Tools!$D$6:$D$105,P16-5)="","",INDEX(Tools!$D$6:$D$105,P16-5))) | J16: =IF(P16="","",INDEX(Tools!$O$6:$O$105,P16-5)) | O16: =IFERROR(SMALL(Tools!$V$6:$V$105,8),"") | P16: =IFERROR(SMALL(Tools!$X$6:$X$105,8),"")
B17: =IF(O17="","",INDEX(Tools!$B$6:$B$105,MATCH(O17,Tools!$V$6:$V$105,0))) | C17: =IF(O17="","",INT(O17)) | D17: =IF(O17="","",INDEX(Tools!$N$6:$N$105,MATCH(O17,Tools!$V$6:$V$105,0))) | E17: =IF(O17="","",IF(N(INDEX(Tools!$K$6:$K$105,MATCH(O17,Tools!$V$6:$V$105,0)))=0,"",INDEX(Tools!$R$6:$R$105,MATCH(O17,Tools!$V$6:$V$105,0)))) | G17: =IF(P17="","",INDEX(Tools!$B$6:$B$105,P17-5)) | H17: =IF(P17="","",INDEX(Tools!$T$6:$T$105,P17-5)) | I17: =IF(P17="","",IF(INDEX(Tools!$D$6:$D$105,P17-5)="","",INDEX(Tools!$D$6:$D$105,P17-5))) | J17: =IF(P17="","",INDEX(Tools!$O$6:$O$105,P17-5)) | O17: =IFERROR(SMALL(Tools!$V$6:$V$105,9),"") | P17: =IFERROR(SMALL(Tools!$X$6:$X$105,9),"")
B18: =IF(O18="","",INDEX(Tools!$B$6:$B$105,MATCH(O18,Tools!$V$6:$V$105,0))) | C18: =IF(O18="","",INT(O18)) | D18: =IF(O18="","",INDEX(Tools!$N$6:$N$105,MATCH(O18,Tools!$V$6:$V$105,0))) | E18: =IF(O18="","",IF(N(INDEX(Tools!$K$6:$K$105,MATCH(O18,Tools!$V$6:$V$105,0)))=0,"",INDEX(Tools!$R$6:$R$105,MATCH(O18,Tools!$V$6:$V$105,0)))) | G18: =IF(P18="","",INDEX(Tools!$B$6:$B$105,P18-5)) | H18: =IF(P18="","",INDEX(Tools!$T$6:$T$105,P18-5)) | I18: =IF(P18="","",IF(INDEX(Tools!$D$6:$D$105,P18-5)="","",INDEX(Tools!$D$6:$D$105,P18-5))) | J18: =IF(P18="","",INDEX(Tools!$O$6:$O$105,P18-5)) | O18: =IFERROR(SMALL(Tools!$V$6:$V$105,10),"") | P18: =IFERROR(SMALL(Tools!$X$6:$X$105,10),"")
B21: By category | C21: Tools | D21: Per month | E21: Per year | G21: Access to remove | H21: Tool | I21: Left on | J21: Role
B22: =IF(Settings!$B$10="","",Settings!$B$10) | C22: =IF(B22="","",COUNTIFS(Tools!$C$6:$C$105,B22,Tools!$T$6:$T$105,"<>Cancelled")) | D22: =IF(B22="","",SUMIFS(Tools!$O$6:$O$105,Tools!$C$6:$C$105,B22)) | E22: =IF(B22="","",D22*12) | G22: =IF(Q22="","Nobody to remove",INDEX(Access!$B$6:$B$405,Q22-5)) | H22: =IF(Q22="","",INDEX(Access!$C$6:$C$405,Q22-5)) | I22: =IF(Q22="","",INDEX(Access!$I$6:$I$405,Q22-5)) | J22: =IF(Q22="","",IF(INDEX(Access!$D$6:$D$405,Q22-5)="","",INDEX(Access!$D$6:$D$405,Q22-5))) | Q22: =IFERROR(SMALL(Access!$K$6:$K$405,1),"")
B23: =IF(Settings!$B$11="","",Settings!$B$11) | C23: =IF(B23="","",COUNTIFS(Tools!$C$6:$C$105,B23,Tools!$T$6:$T$105,"<>Cancelled")) | D23: =IF(B23="","",SUMIFS(Tools!$O$6:$O$105,Tools!$C$6:$C$105,B23)) | E23: =IF(B23="","",D23*12) | G23: =IF(Q23="","",INDEX(Access!$B$6:$B$405,Q23-5)) | H23: =IF(Q23="","",INDEX(Access!$C$6:$C$405,Q23-5)) | I23: =IF(Q23="","",INDEX(Access!$I$6:$I$405,Q23-5)) | J23: =IF(Q23="","",IF(INDEX(Access!$D$6:$D$405,Q23-5)="","",INDEX(Access!$D$6:$D$405,Q23-5))) | Q23: =IFERROR(SMALL(Access!$K$6:$K$405,2),"")
B24: =IF(Settings!$B$12="","",Settings!$B$12) | C24: =IF(B24="","",COUNTIFS(Tools!$C$6:$C$105,B24,Tools!$T$6:$T$105,"<>Cancelled")) | D24: =IF(B24="","",SUMIFS(Tools!$O$6:$O$105,Tools!$C$6:$C$105,B24)) | E24: =IF(B24="","",D24*12) | G24: =IF(Q24="","",INDEX(Access!$B$6:$B$405,Q24-5)) | H24: =IF(Q24="","",INDEX(Access!$C$6:$C$405,Q24-5)) | I24: =IF(Q24="","",INDEX(Access!$I$6:$I$405,Q24-5)) | J24: =IF(Q24="","",IF(INDEX(Access!$D$6:$D$405,Q24-5)="","",INDEX(Access!$D$6:$D$405,Q24-5))) | Q24: =IFERROR(SMALL(Access!$K$6:$K$405,3),"")
B25: =IF(Settings!$B$13="","",Settings!$B$13) | C25: =IF(B25="","",COUNTIFS(Tools!$C$6:$C$105,B25,Tools!$T$6:$T$105,"<>Cancelled")) | D25: =IF(B25="","",SUMIFS(Tools!$O$6:$O$105,Tools!$C$6:$C$105,B25)) | E25: =IF(B25="","",D25*12) | G25: =IF(Q25="","",INDEX(Access!$B$6:$B$405,Q25-5)) | H25: =IF(Q25="","",INDEX(Access!$C$6:$C$405,Q25-5)) | I25: =IF(Q25="","",INDEX(Access!$I$6:$I$405,Q25-5)) | J25: =IF(Q25="","",IF(INDEX(Access!$D$6:$D$405,Q25-5)="","",INDEX(Access!$D$6:$D$405,Q25-5))) | Q25: =IFERROR(SMALL(Access!$K$6:$K$405,4),"")
B26: =IF(Settings!$B$14="","",Settings!$B$14) | C26: =IF(B26="","",COUNTIFS(Tools!$C$6:$C$105,B26,Tools!$T$6:$T$105,"<>Cancelled")) | D26: =IF(B26="","",SUMIFS(Tools!$O$6:$O$105,Tools!$C$6:$C$105,B26)) | E26: =IF(B26="","",D26*12) | G26: =IF(Q26="","",INDEX(Access!$B$6:$B$405,Q26-5)) | H26: =IF(Q26="","",INDEX(Access!$C$6:$C$405,Q26-5)) | I26: =IF(Q26="","",INDEX(Access!$I$6:$I$405,Q26-5)) | J26: =IF(Q26="","",IF(INDEX(Access!$D$6:$D$405,Q26-5)="","",INDEX(Access!$D$6:$D$405,Q26-5))) | Q26: =IFERROR(SMALL(Access!$K$6:$K$405,5),"")
B27: =IF(Settings!$B$15="","",Settings!$B$15) | C27: =IF(B27="","",COUNTIFS(Tools!$C$6:$C$105,B27,Tools!$T$6:$T$105,"<>Cancelled")) | D27: =IF(B27="","",SUMIFS(Tools!$O$6:$O$105,Tools!$C$6:$C$105,B27)) | E27: =IF(B27="","",D27*12) | G27: =IF(Q27="","",INDEX(Access!$B$6:$B$405,Q27-5)) | H27: =IF(Q27="","",INDEX(Access!$C$6:$C$405,Q27-5)) | I27: =IF(Q27="","",INDEX(Access!$I$6:$I$405,Q27-5)) | J27: =IF(Q27="","",IF(INDEX(Access!$D$6:$D$405,Q27-5)="","",INDEX(Access!$D$6:$D$405,Q27-5))) | Q27: =IFERROR(SMALL(Access!$K$6:$K$405,6),"")
B28: =IF(Settings!$B$16="","",Settings!$B$16) | C28: =IF(B28="","",COUNTIFS(Tools!$C$6:$C$105,B28,Tools!$T$6:$T$105,"<>Cancelled")) | D28: =IF(B28="","",SUMIFS(Tools!$O$6:$O$105,Tools!$C$6:$C$105,B28)) | E28: =IF(B28="","",D28*12) | G28: =IF(Q28="","",INDEX(Access!$B$6:$B$405,Q28-5)) | H28: =IF(Q28="","",INDEX(Access!$C$6:$C$405,Q28-5)) | I28: =IF(Q28="","",INDEX(Access!$I$6:$I$405,Q28-5)) | J28: =IF(Q28="","",IF(INDEX(Access!$D$6:$D$405,Q28-5)="","",INDEX(Access!$D$6:$D$405,Q28-5))) | Q28: =IFERROR(SMALL(Access!$K$6:$K$405,7),"")
B29: =IF(Settings!$B$17="","",Settings!$B$17) | C29: =IF(B29="","",COUNTIFS(Tools!$C$6:$C$105,B29,Tools!$T$6:$T$105,"<>Cancelled")) | D29: =IF(B29="","",SUMIFS(Tools!$O$6:$O$105,Tools!$C$6:$C$105,B29)) | E29: =IF(B29="","",D29*12) | G29: =IF(Q29="","",INDEX(Access!$B$6:$B$405,Q29-5)) | H29: =IF(Q29="","",INDEX(Access!$C$6:$C$405,Q29-5)) | I29: =IF(Q29="","",INDEX(Access!$I$6:$I$405,Q29-5)) | J29: =IF(Q29="","",IF(INDEX(Access!$D$6:$D$405,Q29-5)="","",INDEX(Access!$D$6:$D$405,Q29-5))) | Q29: =IFERROR(SMALL(Access!$K$6:$K$405,8),"")
B30: =IF(Settings!$B$18="","",Settings!$B$18) | C30: =IF(B30="","",COUNTIFS(Tools!$C$6:$C$105,B30,Tools!$T$6:$T$105,"<>Cancelled")) | D30: =IF(B30="","",SUMIFS(Tools!$O$6:$O$105,Tools!$C$6:$C$105,B30)) | E30: =IF(B30="","",D30*12)
B31: =IF(Settings!$B$19="","",Settings!$B$19) | C31: =IF(B31="","",COUNTIFS(Tools!$C$6:$C$105,B31,Tools!$T$6:$T$105,"<>Cancelled")) | D31: =IF(B31="","",SUMIFS(Tools!$O$6:$O$105,Tools!$C$6:$C$105,B31)) | E31: =IF(B31="","",D31*12)
B32: =IF(Settings!$B$20="","",Settings!$B$20) | C32: =IF(B32="","",COUNTIFS(Tools!$C$6:$C$105,B32,Tools!$T$6:$T$105,"<>Cancelled")) | D32: =IF(B32="","",SUMIFS(Tools!$O$6:$O$105,Tools!$C$6:$C$105,B32)) | E32: =IF(B32="","",D32*12)
B33: =IF(Settings!$B$21="","",Settings!$B$21) | C33: =IF(B33="","",COUNTIFS(Tools!$C$6:$C$105,B33,Tools!$T$6:$T$105,"<>Cancelled")) | D33: =IF(B33="","",SUMIFS(Tools!$O$6:$O$105,Tools!$C$6:$C$105,B33)) | E33: =IF(B33="","",D33*12)
B34: =IF(ROUND(D34,6)=0,"","Not on the list") | D34: =SUM(Tools!$O$6:$O$105)-SUM(D22:D33) | E34: =D34*12

Sheet Tools
B2: Tools
B3: Every tool the business pays for. The next charge moves on by itself after each renewal.
B5: Tool | C5: Category | D5: Owner | E5: Billing | F5: Price | G5: Per seat | H5: Seats | I5: Paid with | J5: Renews on | K5: Notice (days) | L5: Cancelled on | M5: Seats used | N5: Each charge | O5: Per month | P5: Per year | Q5: Next charge | R5: Cancel by | S5: Unused | T5: Status
B6: Email and docs | C6: Office | D6: Ana | E6: Monthly | F6: 12 | G6: x | H6: 8 | I6: Business card A | J6: 46298 | M6: =IF(B6="","",SUMIFS(Access!$G$6:$G$405,Access!$C$6:$C$405,B6)) | N6: =IF(B6="","",IF(G6<>"",N(F6)*IF(H6="",M6,N(H6)),N(F6))) | O6: =IF(B6="","",IF(AND(L6<>"",L6<=TODAY()),0,N6/U6)) | P6: =IF(B6="","",O6*12) | Q6: =IF(OR(B6="",J6=""),"",IF(AND(L6<>"",IF(J6>=TODAY(),J6,IF(EDATE(J6,INT(DATEDIF(J6,TODAY(),"m")/U6)*U6)>=TODAY(),EDATE(J6,INT(DATEDIF(J6,TODAY(),"m")/U6)*U6),EDATE(J6,INT(DATEDIF(J6,TODAY(),"m")/U6)*U6+U6)))>=L6),"",IF(J6>=TODAY(),J6,IF(EDATE(J6,INT(DATEDIF(J6,TODAY(),"m")/U6)*U6)>=TODAY(),EDATE(J6,INT(DATEDIF(J6,TODAY(),"m")/U6)*U6),EDATE(J6,INT(DATEDIF(J6,TODAY(),"m")/U6)*U6+U6))))) | R6: =IF(Q6="","",Q6-N(K6)) | S6: =IF(OR(B6="",G6="",H6="",AND(L6<>"",L6<=TODAY())),"",MAX(0,N(H6)-N(M6))) | T6: =IF(B6="","",IF(AND(L6<>"",L6<=TODAY()),"Cancelled",IF(L6<>"","Ends "&DAY(L6)&" "&CHOOSE(MONTH(L6),"Jan","Feb","Mar","Apr","May","Jun","Jul","Aug","Sep","Oct","Nov","Dec"),IF(AND(Q6<>"",W6<>"",W6<Q6),"Card expires",IF(AND(Q6<>"",E6<>"Monthly",N(K6)>0,R6>=TODAY(),R6-TODAY()<=N(Settings!$C$5)),"Cancel by "&DAY(R6)&" "&CHOOSE(MONTH(R6),"Jan","Feb","Mar","Apr","May","Jun","Jul","Aug","Sep","Oct","Nov","Dec"),IF(AND(Q6<>"",E6<>"Monthly",Q6-TODAY()<=N(Settings!$C$5)),"Renews "&DAY(Q6)&" "&CHOOSE(MONTH(Q6),"Jan","Feb","Mar","Apr","May","Jun","Jul","Aug","Sep","Oct","Nov","Dec"),IF(N(S6)>0,S6&IF(S6=1," unused seat"," unused seats"),"Active"))))))) | U6: =IF(E6="Quarterly",3,IF(E6="Yearly",12,1)) | V6: =IF(Q6="","",Q6+ROW()/10000000) | W6: =IFERROR(IF(INDEX(Cards!$D$6:$D$25,MATCH(I6,Cards!$B$6:$B$25,0))="","",INDEX(Cards!$D$6:$D$25,MATCH(I6,Cards!$B$6:$B$25,0))),"") | X6: =IF(OR(T6="",T6="Active",T6="Cancelled"),"",ROW()) | Y6: =IF(N(S6)=0,0,S6*N(F6)*12/U6)
B7: Team chat | C7: Communication | D7: Grace | E7: Monthly | F7: 8.75 | G7: x | H7: 10 | I7: Business card A | J7: 46277 | M7: =IF(B7="","",SUMIFS(Access!$G$6:$G$405,Access!$C$6:$C$405,B7)) | N7: =IF(B7="","",IF(G7<>"",N(F7)*IF(H7="",M7,N(H7)),N(F7))) | O7: =IF(B7="","",IF(AND(L7<>"",L7<=TODAY()),0,N7/U7)) | P7: =IF(B7="","",O7*12) | Q7: =IF(OR(B7="",J7=""),"",IF(AND(L7<>"",IF(J7>=TODAY(),J7,IF(EDATE(J7,INT(DATEDIF(J7,TODAY(),"m")/U7)*U7)>=TODAY(),EDATE(J7,INT(DATEDIF(J7,TODAY(),"m")/U7)*U7),EDATE(J7,INT(DATEDIF(J7,TODAY(),"m")/U7)*U7+U7)))>=L7),"",IF(J7>=TODAY(),J7,IF(EDATE(J7,INT(DATEDIF(J7,TODAY(),"m")/U7)*U7)>=TODAY(),EDATE(J7,INT(DATEDIF(J7,TODAY(),"m")/U7)*U7),EDATE(J7,INT(DATEDIF(J7,TODAY(),"m")/U7)*U7+U7))))) | R7: =IF(Q7="","",Q7-N(K7)) | S7: =IF(OR(B7="",G7="",H7="",AND(L7<>"",L7<=TODAY())),"",MAX(0,N(H7)-N(M7))) | T7: =IF(B7="","",IF(AND(L7<>"",L7<=TODAY()),"Cancelled",IF(L7<>"","Ends "&DAY(L7)&" "&CHOOSE(MONTH(L7),"Jan","Feb","Mar","Apr","May","Jun","Jul","Aug","Sep","Oct","Nov","Dec"),IF(AND(Q7<>"",W7<>"",W7<Q7),"Card expires",IF(AND(Q7<>"",E7<>"Monthly",N(K7)>0,R7>=TODAY(),R7-TODAY()<=N(Settings!$C$5)),"Cancel by "&DAY(R7)&" "&CHOOSE(MONTH(R7),"Jan","Feb","Mar","Apr","May","Jun","Jul","Aug","Sep","Oct","Nov","Dec"),IF(AND(Q7<>"",E7<>"Monthly",Q7-TODAY()<=N(Settings!$C$5)),"Renews "&DAY(Q7)&" "&CHOOSE(MONTH(Q7),"Jan","Feb","Mar","Apr","May","Jun","Jul","Aug","Sep","Oct","Nov","Dec"),IF(N(S7)>0,S7&IF(S7=1," unused seat"," unused seats"),"Active"))))))) | U7: =IF(E7="Quarterly",3,IF(E7="Yearly",12,1)) | V7: =IF(Q7="","",Q7+ROW()/10000000) | W7: =IFERROR(IF(INDEX(Cards!$D$6:$D$25,MATCH(I7,Cards!$B$6:$B$25,0))="","",INDEX(Cards!$D$6:$D$25,MATCH(I7,Cards!$B$6:$B$25,0))),"") | X7: =IF(OR(T7="",T7="Active",T7="Cancelled"),"",ROW()) | Y7: =IF(N(S7)=0,0,S7*N(F7)*12/U7)
B8: Video calls | C8: Communication | D8: Grace | E8: Yearly | F8: 149.9 | I8: Business card B | J8: 46419 | M8: =IF(B8="","",SUMIFS(Access!$G$6:$G$405,Access!$C$6:$C$405,B8)) | N8: =IF(B8="","",IF(G8<>"",N(F8)*IF(H8="",M8,N(H8)),N(F8))) | O8: =IF(B8="","",IF(AND(L8<>"",L8<=TODAY()),0,N8/U8)) | P8: =IF(B8="","",O8*12) | Q8: =IF(OR(B8="",J8=""),"",IF(AND(L8<>"",IF(J8>=TODAY(),J8,IF(EDATE(J8,INT(DATEDIF(J8,TODAY(),"m")/U8)*U8)>=TODAY(),EDATE(J8,INT(DATEDIF(J8,TODAY(),"m")/U8)*U8),EDATE(J8,INT(DATEDIF(J8,TODAY(),"m")/U8)*U8+U8)))>=L8),"",IF(J8>=TODAY(),J8,IF(EDATE(J8,INT(DATEDIF(J8,TODAY(),"m")/U8)*U8)>=TODAY(),EDATE(J8,INT(DATEDIF(J8,TODAY(),"m")/U8)*U8),EDATE(J8,INT(DATEDIF(J8,TODAY(),"m")/U8)*U8+U8))))) | R8: =IF(Q8="","",Q8-N(K8)) | S8: =IF(OR(B8="",G8="",H8="",AND(L8<>"",L8<=TODAY())),"",MAX(0,N(H8)-N(M8))) | T8: =IF(B8="","",IF(AND(L8<>"",L8<=TODAY()),"Cancelled",IF(L8<>"","Ends "&DAY(L8)&" "&CHOOSE(MONTH(L8),"Jan","Feb","Mar","Apr","May","Jun","Jul","Aug","Sep","Oct","Nov","Dec"),IF(AND(Q8<>"",W8<>"",W8<Q8),"Card expires",IF(AND(Q8<>"",E8<>"Monthly",N(K8)>0,R8>=TODAY(),R8-TODAY()<=N(Settings!$C$5)),"Cancel by "&DAY(R8)&" "&CHOOSE(MONTH(R8),"Jan","Feb","Mar","Apr","May","Jun","Jul","Aug","Sep","Oct","Nov","Dec"),IF(AND(Q8<>"",E8<>"Monthly",Q8-TODAY()<=N(Settings!$C$5)),"Renews "&DAY(Q8)&" "&CHOOSE(MONTH(Q8),"Jan","Feb","Mar","Apr","May","Jun","Jul","Aug","Sep","Oct","Nov","Dec"),IF(N(S8)>0,S8&IF(S8=1," unused seat"," unused seats"),"Active"))))))) | U8: =IF(E8="Quarterly",3,IF(E8="Yearly",12,1)) | V8: =IF(Q8="","",Q8+ROW()/10000000) | W8: =IFERROR(IF(INDEX(Cards!$D$6:$D$25,MATCH(I8,Cards!$B$6:$B$25,0))="","",INDEX(Cards!$D$6:$D$25,MATCH(I8,Cards!$B$6:$B$25,0))),"") | X8: =IF(OR(T8="",T8="Active",T8="Cancelled"),"",ROW()) | Y8: =IF(N(S8)=0,0,S8*N(F8)*12/U8)
B9: Design suite | C9: Design | D9: Ben | E9: Yearly | F9: 659.88 | G9: x | H9: 3 | I9: Business card B | J9: 46315 | K9: 14 | M9: =IF(B9="","",SUMIFS(Access!$G$6:$G$405,Access!$C$6:$C$405,B9)) | N9: =IF(B9="","",IF(G9<>"",N(F9)*IF(H9="",M9,N(H9)),N(F9))) | O9: =IF(B9="","",IF(AND(L9<>"",L9<=TODAY()),0,N9/U9)) | P9: =IF(B9="","",O9*12) | Q9: =IF(OR(B9="",J9=""),"",IF(AND(L9<>"",IF(J9>=TODAY(),J9,IF(EDATE(J9,INT(DATEDIF(J9,TODAY(),"m")/U9)*U9)>=TODAY(),EDATE(J9,INT(DATEDIF(J9,TODAY(),"m")/U9)*U9),EDATE(J9,INT(DATEDIF(J9,TODAY(),"m")/U9)*U9+U9)))>=L9),"",IF(J9>=TODAY(),J9,IF(EDATE(J9,INT(DATEDIF(J9,TODAY(),"m")/U9)*U9)>=TODAY(),EDATE(J9,INT(DATEDIF(J9,TODAY(),"m")/U9)*U9),EDATE(J9,INT(DATEDIF(J9,TODAY(),"m")/U9)*U9+U9))))) | R9: =IF(Q9="","",Q9-N(K9)) | S9: =IF(OR(B9="",G9="",H9="",AND(L9<>"",L9<=TODAY())),"",MAX(0,N(H9)-N(M9))) | T9: =IF(B9="","",IF(AND(L9<>"",L9<=TODAY()),"Cancelled",IF(L9<>"","Ends "&DAY(L9)&" "&CHOOSE(MONTH(L9),"Jan","Feb","Mar","Apr","May","Jun","Jul","Aug","Sep","Oct","Nov","Dec"),IF(AND(Q9<>"",W9<>"",W9<Q9),"Card expires",IF(AND(Q9<>"",E9<>"Monthly",N(K9)>0,R9>=TODAY(),R9-TODAY()<=N(Settings!$C$5)),"Cancel by "&DAY(R9)&" "&CHOOSE(MONTH(R9),"Jan","Feb","Mar","Apr","May","Jun","Jul","Aug","Sep","Oct","Nov","Dec"),IF(AND(Q9<>"",E9<>"Monthly",Q9-TODAY()<=N(Settings!$C$5)),"Renews "&DAY(Q9)&" "&CHOOSE(MONTH(Q9),"Jan","Feb","Mar","Apr","May","Jun","Jul","Aug","Sep","Oct","Nov","Dec"),IF(N(S9)>0,S9&IF(S9=1," unused seat"," unused seats"),"Active"))))))) | U9: =IF(E9="Quarterly",3,IF(E9="Yearly",12,1)) | V9: =IF(Q9="","",Q9+ROW()/10000000) | W9: =IFERROR(IF(INDEX(Cards!$D$6:$D$25,MATCH(I9,Cards!$B$6:$B$25,0))="","",INDEX(Cards!$D$6:$D$25,MATCH(I9,Cards!$B$6:$B$25,0))),"") | X9: =IF(OR(T9="",T9="Active",T9="Cancelled"),"",ROW()) | Y9: =IF(N(S9)=0,0,S9*N(F9)*12/U9)
B10: Stock photos | C10: Design | D10: Chloe | E10: Monthly | F10: 29 | I10: Business card A | J10: 46303 | M10: =IF(B10="","",SUMIFS(Access!$G$6:$G$405,Access!$C$6:$C$405,B10)) | N10: =IF(B10="","",IF(G10<>"",N(F10)*IF(H10="",M10,N(H10)),N(F10))) | O10: =IF(B10="","",IF(AND(L10<>"",L10<=TODAY()),0,N10/U10)) | P10: =IF(B10="","",O10*12) | Q10: =IF(OR(B10="",J10=""),"",IF(AND(L10<>"",IF(J10>=TODAY(),J10,IF(EDATE(J10,INT(DATEDIF(J10,TODAY(),"m")/U10)*U10)>=TODAY(),EDATE(J10,INT(DATEDIF(J10,TODAY(),"m")/U10)*U10),EDATE(J10,INT(DATEDIF(J10,TODAY(),"m")/U10)*U10+U10)))>=L10),"",IF(J10>=TODAY(),J10,IF(EDATE(J10,INT(DATEDIF(J10,TODAY(),"m")/U10)*U10)>=TODAY(),EDATE(J10,INT(DATEDIF(J10,TODAY(),"m")/U10)*U10),EDATE(J10,INT(DATEDIF(J10,TODAY(),"m")/U10)*U10+U10))))) | R10: =IF(Q10="","",Q10-N(K10)) | S10: =IF(OR(B10="",G10="",H10="",AND(L10<>"",L10<=TODAY())),"",MAX(0,N(H10)-N(M10))) | T10: =IF(B10="","",IF(AND(L10<>"",L10<=TODAY()),"Cancelled",IF(L10<>"","Ends "&DAY(L10)&" "&CHOOSE(MONTH(L10),"Jan","Feb","Mar","Apr","May","Jun","Jul","Aug","Sep","Oct","Nov","Dec"),IF(AND(Q10<>"",W10<>"",W10<Q10),"Card expires",IF(AND(Q10<>"",E10<>"Monthly",N(K10)>0,R10>=TODAY(),R10-TODAY()<=N(Settings!$C$5)),"Cancel by "&DAY(R10)&" "&CHOOSE(MONTH(R10),"Jan","Feb","Mar","Apr","May","Jun","Jul","Aug","Sep","Oct","Nov","Dec"),IF(AND(Q10<>"",E10<>"Monthly",Q10-TODAY()<=N(Settings!$C$5)),"Renews "&DAY(Q10)&" "&CHOOSE(MONTH(Q10),"Jan","Feb","Mar","Apr","May","Jun","Jul","Aug","Sep","Oct","Nov","Dec"),IF(N(S10)>0,S10&IF(S10=1," unused seat"," unused seats"),"Active"))))))) | U10: =IF(E10="Quarterly",3,IF(E10="Yearly",12,1)) | V10: =IF(Q10="","",Q10+ROW()/10000000) | W10: =IFERROR(IF(INDEX(Cards!$D$6:$D$25,MATCH(I10,Cards!$B$6:$B$25,0))="","",INDEX(Cards!$D$6:$D$25,MATCH(I10,Cards!$B$6:$B$25,0))),"") | X10: =IF(OR(T10="",T10="Active",T10="Cancelled"),"",ROW()) | Y10: =IF(N(S10)=0,0,S10*N(F10)*12/U10)
B11: Accounting | C11: Finance | D11: Ana | E11: Monthly | F11: 55 | I11: Business card A | J11: 46296 | M11: =IF(B11="","",SUMIFS(Access!$G$6:$G$405,Access!$C$6:$C$405,B11)) | N11: =IF(B11="","",IF(G11<>"",N(F11)*IF(H11="",M11,N(H11)),N(F11))) | O11: =IF(B11="","",IF(AND(L11<>"",L11<=TODAY()),0,N11/U11)) | P11: =IF(B11="","",O11*12) | Q11: =IF(OR(B11="",J11=""),"",IF(AND(L11<>"",IF(J11>=TODAY(),J11,IF(EDATE(J11,INT(DATEDIF(J11,TODAY(),"m")/U11)*U11)>=TODAY(),EDATE(J11,INT(DATEDIF(J11,TODAY(),"m")/U11)*U11),EDATE(J11,INT(DATEDIF(J11,TODAY(),"m")/U11)*U11+U11)))>=L11),"",IF(J11>=TODAY(),J11,IF(EDATE(J11,INT(DATEDIF(J11,TODAY(),"m")/U11)*U11)>=TODAY(),EDATE(J11,INT(DATEDIF(J11,TODAY(),"m")/U11)*U11),EDATE(J11,INT(DATEDIF(J11,TODAY(),"m")/U11)*U11+U11))))) | R11: =IF(Q11="","",Q11-N(K11)) | S11: =IF(OR(B11="",G11="",H11="",AND(L11<>"",L11<=TODAY())),"",MAX(0,N(H11)-N(M11))) | T11: =IF(B11="","",IF(AND(L11<>"",L11<=TODAY()),"Cancelled",IF(L11<>"","Ends "&DAY(L11)&" "&CHOOSE(MONTH(L11),"Jan","Feb","Mar","Apr","May","Jun","Jul","Aug","Sep","Oct","Nov","Dec"),IF(AND(Q11<>"",W11<>"",W11<Q11),"Card expires",IF(AND(Q11<>"",E11<>"Monthly",N(K11)>0,R11>=TODAY(),R11-TODAY()<=N(Settings!$C$5)),"Cancel by "&DAY(R11)&" "&CHOOSE(MONTH(R11),"Jan","Feb","Mar","Apr","May","Jun","Jul","Aug","Sep","Oct","Nov","Dec"),IF(AND(Q11<>"",E11<>"Monthly",Q11-TODAY()<=N(Settings!$C$5)),"Renews "&DAY(Q11)&" "&CHOOSE(MONTH(Q11),"Jan","Feb","Mar","Apr","May","Jun","Jul","Aug","Sep","Oct","Nov","Dec"),IF(N(S11)>0,S11&IF(S11=1," unused seat"," unused seats"),"Active"))))))) | U11: =IF(E11="Quarterly",3,IF(E11="Yearly",12,1)) | V11: =IF(Q11="","",Q11+ROW()/10000000) | W11: =IFERROR(IF(INDEX(Cards!$D$6:$D$25,MATCH(I11,Cards!$B$6:$B$25,0))="","",INDEX(Cards!$D$6:$D$25,MATCH(I11,Cards!$B$6:$B$25,0))),"") | X11: =IF(OR(T11="",T11="Active",T11="Cancelled"),"",ROW()) | Y11: =IF(N(S11)=0,0,S11*N(F11)*12/U11)
B12: Website builder | C12: Website | D12: Ella | E12: Yearly | F12: 276 | I12: Debit card C | J12: 46461 | K12: 30 | M12: =IF(B12="","",SUMIFS(Access!$G$6:$G$405,Access!$C$6:$C$405,B12)) | N12: =IF(B12="","",IF(G12<>"",N(F12)*IF(H12="",M12,N(H12)),N(F12))) | O12: =IF(B12="","",IF(AND(L12<>"",L12<=TODAY()),0,N12/U12)) | P12: =IF(B12="","",O12*12) | Q12: =IF(OR(B12="",J12=""),"",IF(AND(L12<>"",IF(J12>=TODAY(),J12,IF(EDATE(J12,INT(DATEDIF(J12,TODAY(),"m")/U12)*U12)>=TODAY(),EDATE(J12,INT(DATEDIF(J12,TODAY(),"m")/U12)*U12),EDATE(J12,INT(DATEDIF(J12,TODAY(),"m")/U12)*U12+U12)))>=L12),"",IF(J12>=TODAY(),J12,IF(EDATE(J12,INT(DATEDIF(J12,TODAY(),"m")/U12)*U12)>=TODAY(),EDATE(J12,INT(DATEDIF(J12,TODAY(),"m")/U12)*U12),EDATE(J12,INT(DATEDIF(J12,TODAY(),"m")/U12)*U12+U12))))) | R12: =IF(Q12="","",Q12-N(K12)) | S12: =IF(OR(B12="",G12="",H12="",AND(L12<>"",L12<=TODAY())),"",MAX(0,N(H12)-N(M12))) | T12: =IF(B12="","",IF(AND(L12<>"",L12<=TODAY()),"Cancelled",IF(L12<>"","Ends "&DAY(L12)&" "&CHOOSE(MONTH(L12),"Jan","Feb","Mar","Apr","May","Jun","Jul","Aug","Sep","Oct","Nov","Dec"),IF(AND(Q12<>"",W12<>"",W12<Q12),"Card expires",IF(AND(Q12<>"",E12<>"Monthly",N(K12)>0,R12>=TODAY(),R12-TODAY()<=N(Settings!$C$5)),"Cancel by "&DAY(R12)&" "&CHOOSE(MONTH(R12),"Jan","Feb","Mar","Apr","May","Jun","Jul","Aug","Sep","Oct","Nov","Dec"),IF(AND(Q12<>"",E12<>"Monthly",Q12-TODAY()<=N(Settings!$C$5)),"Renews "&DAY(Q12)&" "&CHOOSE(MONTH(Q12),"Jan","Feb","Mar","Apr","May","Jun","Jul","Aug","Sep","Oct","Nov","Dec"),IF(N(S12)>0,S12&IF(S12=1," unused seat"," unused seats"),"Active"))))))) | U12: =IF(E12="Quarterly",3,IF(E12="Yearly",12,1)) | V12: =IF(Q12="","",Q12+ROW()/10000000) | W12: =IFERROR(IF(INDEX(Cards!$D$6:$D$25,MATCH(I12,Cards!$B$6:$B$25,0))="","",INDEX(Cards!$D$6:$D$25,MATCH(I12,Cards!$B$6:$B$25,0))),"") | X12: =IF(OR(T12="",T12="Active",T12="Cancelled"),"",ROW()) | Y12: =IF(N(S12)=0,0,S12*N(F12)*12/U12)
B13: Domain names | C13: Website | D13: Dev | E13: Yearly | F13: 38 | I13: Debit card C | J13: 46358 | M13: =IF(B13="","",SUMIFS(Access!$G$6:$G$405,Access!$C$6:$C$405,B13)) | N13: =IF(B13="","",IF(G13<>"",N(F13)*IF(H13="",M13,N(H13)),N(F13))) | O13: =IF(B13="","",IF(AND(L13<>"",L13<=TODAY()),0,N13/U13)) | P13: =IF(B13="","",O13*12) | Q13: =IF(OR(B13="",J13=""),"",IF(AND(L13<>"",IF(J13>=TODAY(),J13,IF(EDATE(J13,INT(DATEDIF(J13,TODAY(),"m")/U13)*U13)>=TODAY(),EDATE(J13,INT(DATEDIF(J13,TODAY(),"m")/U13)*U13),EDATE(J13,INT(DATEDIF(J13,TODAY(),"m")/U13)*U13+U13)))>=L13),"",IF(J13>=TODAY(),J13,IF(EDATE(J13,INT(DATEDIF(J13,TODAY(),"m")/U13)*U13)>=TODAY(),EDATE(J13,INT(DATEDIF(J13,TODAY(),"m")/U13)*U13),EDATE(J13,INT(DATEDIF(J13,TODAY(),"m")/U13)*U13+U13))))) | R13: =IF(Q13="","",Q13-N(K13)) | S13: =IF(OR(B13="",G13="",H13="",AND(L13<>"",L13<=TODAY())),"",MAX(0,N(H13)-N(M13))) | T13: =IF(B13="","",IF(AND(L13<>"",L13<=TODAY()),"Cancelled",IF(L13<>"","Ends "&DAY(L13)&" "&CHOOSE(MONTH(L13),"Jan","Feb","Mar","Apr","May","Jun","Jul","Aug","Sep","Oct","Nov","Dec"),IF(AND(Q13<>"",W13<>"",W13<Q13),"Card expires",IF(AND(Q13<>"",E13<>"Monthly",N(K13)>0,R13>=TODAY(),R13-TODAY()<=N(Settings!$C$5)),"Cancel by "&DAY(R13)&" "&CHOOSE(MONTH(R13),"Jan","Feb","Mar","Apr","May","Jun","Jul","Aug","Sep","Oct","Nov","Dec"),IF(AND(Q13<>"",E13<>"Monthly",Q13-TODAY()<=N(Settings!$C$5)),"Renews "&DAY(Q13)&" "&CHOOSE(MONTH(Q13),"Jan","Feb","Mar","Apr","May","Jun","Jul","Aug","Sep","Oct","Nov","Dec"),IF(N(S13)>0,S13&IF(S13=1," unused seat"," unused seats"),"Active"))))))) | U13: =IF(E13="Quarterly",3,IF(E13="Yearly",12,1)) | V13: =IF(Q13="","",Q13+ROW()/10000000) | W13: =IFERROR(IF(INDEX(Cards!$D$6:$D$25,MATCH(I13,Cards!$B$6:$B$25,0))="","",INDEX(Cards!$D$6:$D$25,MATCH(I13,Cards!$B$6:$B$25,0))),"") | X13: =IF(OR(T13="",T13="Active",T13="Cancelled"),"",ROW()) | Y13: =IF(N(S13)=0,0,S13*N(F13)*12/U13)
B14: CRM | C14: Sales | D14: Finn | E14: Monthly | F14: 49 | G14: x | H14: 3 | I14: Business card A | J14: 46310 | M14: =IF(B14="","",SUMIFS(Access!$G$6:$G$405,Access!$C$6:$C$405,B14)) | N14: =IF(B14="","",IF(G14<>"",N(F14)*IF(H14="",M14,N(H14)),N(F14))) | O14: =IF(B14="","",IF(AND(L14<>"",L14<=TODAY()),0,N14/U14)) | P14: =IF(B14="","",O14*12) | Q14: =IF(OR(B14="",J14=""),"",IF(AND(L14<>"",IF(J14>=TODAY(),J14,IF(EDATE(J14,INT(DATEDIF(J14,TODAY(),"m")/U14)*U14)>=TODAY(),EDATE(J14,INT(DATEDIF(J14,TODAY(),"m")/U14)*U14),EDATE(J14,INT(DATEDIF(J14,TODAY(),"m")/U14)*U14+U14)))>=L14),"",IF(J14>=TODAY(),J14,IF(EDATE(J14,INT(DATEDIF(J14,TODAY(),"m")/U14)*U14)>=TODAY(),EDATE(J14,INT(DATEDIF(J14,TODAY(),"m")/U14)*U14),EDATE(J14,INT(DATEDIF(J14,TODAY(),"m")/U14)*U14+U14))))) | R14: =IF(Q14="","",Q14-N(K14)) | S14: =IF(OR(B14="",G14="",H14="",AND(L14<>"",L14<=TODAY())),"",MAX(0,N(H14)-N(M14))) | T14: =IF(B14="","",IF(AND(L14<>"",L14<=TODAY()),"Cancelled",IF(L14<>"","Ends "&DAY(L14)&" "&CHOOSE(MONTH(L14),"Jan","Feb","Mar","Apr","May","Jun","Jul","Aug","Sep","Oct","Nov","Dec"),IF(AND(Q14<>"",W14<>"",W14<Q14),"Card expires",IF(AND(Q14<>"",E14<>"Monthly",N(K14)>0,R14>=TODAY(),R14-TODAY()<=N(Settings!$C$5)),"Cancel by "&DAY(R14)&" "&CHOOSE(MONTH(R14),"Jan","Feb","Mar","Apr","May","Jun","Jul","Aug","Sep","Oct","Nov","Dec"),IF(AND(Q14<>"",E14<>"Monthly",Q14-TODAY()<=N(Settings!$C$5)),"Renews "&DAY(Q14)&" "&CHOOSE(MONTH(Q14),"Jan","Feb","Mar","Apr","May","Jun","Jul","Aug","Sep","Oct","Nov","Dec"),IF(N(S14)>0,S14&IF(S14=1," unused seat"," unused seats"),"Active"))))))) | U14: =IF(E14="Quarterly",3,IF(E14="Yearly",12,1)) | V14: =IF(Q14="","",Q14+ROW()/10000000) | W14: =IFERROR(IF(INDEX(Cards!$D$6:$D$25,MATCH(I14,Cards!$B$6:$B$25,0))="","",INDEX(Cards!$D$6:$D$25,MATCH(I14,Cards!$B$6:$B$25,0))),"") | X14: =IF(OR(T14="",T14="Active",T14="Cancelled"),"",ROW()) | Y14: =IF(N(S14)=0,0,S14*N(F14)*12/U14)
B15: Newsletter | C15: Marketing | D15: Ella | E15: Monthly | F15: 45 | I15: Business card A | J15: 46304 | M15: =IF(B15="","",SUMIFS(Access!$G$6:$G$405,Access!$C$6:$C$405,B15)) | N15: =IF(B15="","",IF(G15<>"",N(F15)*IF(H15="",M15,N(H15)),N(F15))) | O15: =IF(B15="","",IF(AND(L15<>"",L15<=TODAY()),0,N15/U15)) | P15: =IF(B15="","",O15*12) | Q15: =IF(OR(B15="",J15=""),"",IF(AND(L15<>"",IF(J15>=TODAY(),J15,IF(EDATE(J15,INT(DATEDIF(J15,TODAY(),"m")/U15)*U15)>=TODAY(),EDATE(J15,INT(DATEDIF(J15,TODAY(),"m")/U15)*U15),EDATE(J15,INT(DATEDIF(J15,TODAY(),"m")/U15)*U15+U15)))>=L15),"",IF(J15>=TODAY(),J15,IF(EDATE(J15,INT(DATEDIF(J15,TODAY(),"m")/U15)*U15)>=TODAY(),EDATE(J15,INT(DATEDIF(J15,TODAY(),"m")/U15)*U15),EDATE(J15,INT(DATEDIF(J15,TODAY(),"m")/U15)*U15+U15))))) | R15: =IF(Q15="","",Q15-N(K15)) | S15: =IF(OR(B15="",G15="",H15="",AND(L15<>"",L15<=TODAY())),"",MAX(0,N(H15)-N(M15))) | T15: =IF(B15="","",IF(AND(L15<>"",L15<=TODAY()),"Cancelled",IF(L15<>"","Ends "&DAY(L15)&" "&CHOOSE(MONTH(L15),"Jan","Feb","Mar","Apr","May","Jun","Jul","Aug","Sep","Oct","Nov","Dec"),IF(AND(Q15<>"",W15<>"",W15<Q15),"Card expires",IF(AND(Q15<>"",E15<>"Monthly",N(K15)>0,R15>=TODAY(),R15-TODAY()<=N(Settings!$C$5)),"Cancel by "&DAY(R15)&" "&CHOOSE(MONTH(R15),"Jan","Feb","Mar","Apr","May","Jun","Jul","Aug","Sep","Oct","Nov","Dec"),IF(AND(Q15<>"",E15<>"Monthly",Q15-TODAY()<=N(Settings!$C$5)),"Renews "&DAY(Q15)&" "&CHOOSE(MONTH(Q15),"Jan","Feb","Mar","Apr","May","Jun","Jul","Aug","Sep","Oct","Nov","Dec"),IF(N(S15)>0,S15&IF(S15=1," unused seat"," unused seats"),"Active"))))))) | U15: =IF(E15="Quarterly",3,IF(E15="Yearly",12,1)) | V15: =IF(Q15="","",Q15+ROW()/10000000) | W15: =IFERROR(IF(INDEX(Cards!$D$6:$D$25,MATCH(I15,Cards!$B$6:$B$25,0))="","",INDEX(Cards!$D$6:$D$25,MATCH(I15,Cards!$B$6:$B$25,0))),"") | X15: =IF(OR(T15="",T15="Active",T15="Cancelled"),"",ROW()) | Y15: =IF(N(S15)=0,0,S15*N(F15)*12/U15)
B16: Project board | C16: Operations | D16: Grace | E16: Monthly | F16: 10 | G16: x | H16: 8 | I16: Business card A | J16: 46313 | M16: =IF(B16="","",SUMIFS(Access!$G$6:$G$405,Access!$C$6:$C$405,B16)) | N16: =IF(B16="","",IF(G16<>"",N(F16)*IF(H16="",M16,N(H16)),N(F16))) | O16: =IF(B16="","",IF(AND(L16<>"",L16<=TODAY()),0,N16/U16)) | P16: =IF(B16="","",O16*12) | Q16: =IF(OR(B16="",J16=""),"",IF(AND(L16<>"",IF(J16>=TODAY(),J16,IF(EDATE(J16,INT(DATEDIF(J16,TODAY(),"m")/U16)*U16)>=TODAY(),EDATE(J16,INT(DATEDIF(J16,TODAY(),"m")/U16)*U16),EDATE(J16,INT(DATEDIF(J16,TODAY(),"m")/U16)*U16+U16)))>=L16),"",IF(J16>=TODAY(),J16,IF(EDATE(J16,INT(DATEDIF(J16,TODAY(),"m")/U16)*U16)>=TODAY(),EDATE(J16,INT(DATEDIF(J16,TODAY(),"m")/U16)*U16),EDATE(J16,INT(DATEDIF(J16,TODAY(),"m")/U16)*U16+U16))))) | R16: =IF(Q16="","",Q16-N(K16)) | S16: =IF(OR(B16="",G16="",H16="",AND(L16<>"",L16<=TODAY())),"",MAX(0,N(H16)-N(M16))) | T16: =IF(B16="","",IF(AND(L16<>"",L16<=TODAY()),"Cancelled",IF(L16<>"","Ends "&DAY(L16)&" "&CHOOSE(MONTH(L16),"Jan","Feb","Mar","Apr","May","Jun","Jul","Aug","Sep","Oct","Nov","Dec"),IF(AND(Q16<>"",W16<>"",W16<Q16),"Card expires",IF(AND(Q16<>"",E16<>"Monthly",N(K16)>0,R16>=TODAY(),R16-TODAY()<=N(Settings!$C$5)),"Cancel by "&DAY(R16)&" "&CHOOSE(MONTH(R16),"Jan","Feb","Mar","Apr","May","Jun","Jul","Aug","Sep","Oct","Nov","Dec"),IF(AND(Q16<>"",E16<>"Monthly",Q16-TODAY()<=N(Settings!$C$5)),"Renews "&DAY(Q16)&" "&CHOOSE(MONTH(Q16),"Jan","Feb","Mar","Apr","May","Jun","Jul","Aug","Sep","Oct","Nov","Dec"),IF(N(S16)>0,S16&IF(S16=1," unused seat"," unused seats"),"Active"))))))) | U16: =IF(E16="Quarterly",3,IF(E16="Yearly",12,1)) | V16: =IF(Q16="","",Q16+ROW()/10000000) | W16: =IFERROR(IF(INDEX(Cards!$D$6:$D$25,MATCH(I16,Cards!$B$6:$B$25,0))="","",INDEX(Cards!$D$6:$D$25,MATCH(I16,Cards!$B$6:$B$25,0))),"") | X16: =IF(OR(T16="",T16="Active",T16="Cancelled"),"",ROW()) | Y16: =IF(N(S16)=0,0,S16*N(F16)*12/U16)
B17: Password manager | C17: Security | D17: Dev | E17: Yearly | F17: 48 | G17: x | H17: 8 | I17: Business card B | J17: 46508 | M17: =IF(B17="","",SUMIFS(Access!$G$6:$G$405,Access!$C$6:$C$405,B17)) | N17: =IF(B17="","",IF(G17<>"",N(F17)*IF(H17="",M17,N(H17)),N(F17))) | O17: =IF(B17="","",IF(AND(L17<>"",L17<=TODAY()),0,N17/U17)) | P17: =IF(B17="","",O17*12) | Q17: =IF(OR(B17="",J17=""),"",IF(AND(L17<>"",IF(J17>=TODAY(),J17,IF(EDATE(J17,INT(DATEDIF(J17,TODAY(),"m")/U17)*U17)>=TODAY(),EDATE(J17,INT(DATEDIF(J17,TODAY(),"m")/U17)*U17),EDATE(J17,INT(DATEDIF(J17,TODAY(),"m")/U17)*U17+U17)))>=L17),"",IF(J17>=TODAY(),J17,IF(EDATE(J17,INT(DATEDIF(J17,TODAY(),"m")/U17)*U17)>=TODAY(),EDATE(J17,INT(DATEDIF(J17,TODAY(),"m")/U17)*U17),EDATE(J17,INT(DATEDIF(J17,TODAY(),"m")/U17)*U17+U17))))) | R17: =IF(Q17="","",Q17-N(K17)) | S17: =IF(OR(B17="",G17="",H17="",AND(L17<>"",L17<=TODAY())),"",MAX(0,N(H17)-N(M17))) | T17: =IF(B17="","",IF(AND(L17<>"",L17<=TODAY()),"Cancelled",IF(L17<>"","Ends "&DAY(L17)&" "&CHOOSE(MONTH(L17),"Jan","Feb","Mar","Apr","May","Jun","Jul","Aug","Sep","Oct","Nov","Dec"),IF(AND(Q17<>"",W17<>"",W17<Q17),"Card expires",IF(AND(Q17<>"",E17<>"Monthly",N(K17)>0,R17>=TODAY(),R17-TODAY()<=N(Settings!$C$5)),"Cancel by "&DAY(R17)&" "&CHOOSE(MONTH(R17),"Jan","Feb","Mar","Apr","May","Jun","Jul","Aug","Sep","Oct","Nov","Dec"),IF(AND(Q17<>"",E17<>"Monthly",Q17-TODAY()<=N(Settings!$C$5)),"Renews "&DAY(Q17)&" "&CHOOSE(MONTH(Q17),"Jan","Feb","Mar","Apr","May","Jun","Jul","Aug","Sep","Oct","Nov","Dec"),IF(N(S17)>0,S17&IF(S17=1," unused seat"," unused seats"),"Active"))))))) | U17: =IF(E17="Quarterly",3,IF(E17="Yearly",12,1)) | V17: =IF(Q17="","",Q17+ROW()/10000000) | W17: =IFERROR(IF(INDEX(Cards!$D$6:$D$25,MATCH(I17,Cards!$B$6:$B$25,0))="","",INDEX(Cards!$D$6:$D$25,MATCH(I17,Cards!$B$6:$B$25,0))),"") | X17: =IF(OR(T17="",T17="Active",T17="Cancelled"),"",ROW()) | Y17: =IF(N(S17)=0,0,S17*N(F17)*12/U17)
B18: Cloud storage | C18: Office | D18: Dev | E18: Yearly | F18: 120 | I18: Business card A | J18: 46336 | M18: =IF(B18="","",SUMIFS(Access!$G$6:$G$405,Access!$C$6:$C$405,B18)) | N18: =IF(B18="","",IF(G18<>"",N(F18)*IF(H18="",M18,N(H18)),N(F18))) | O18: =IF(B18="","",IF(AND(L18<>"",L18<=TODAY()),0,N18/U18)) | P18: =IF(B18="","",O18*12) | Q18: =IF(OR(B18="",J18=""),"",IF(AND(L18<>"",IF(J18>=TODAY(),J18,IF(EDATE(J18,INT(DATEDIF(J18,TODAY(),"m")/U18)*U18)>=TODAY(),EDATE(J18,INT(DATEDIF(J18,TODAY(),"m")/U18)*U18),EDATE(J18,INT(DATEDIF(J18,TODAY(),"m")/U18)*U18+U18)))>=L18),"",IF(J18>=TODAY(),J18,IF(EDATE(J18,INT(DATEDIF(J18,TODAY(),"m")/U18)*U18)>=TODAY(),EDATE(J18,INT(DATEDIF(J18,TODAY(),"m")/U18)*U18),EDATE(J18,INT(DATEDIF(J18,TODAY(),"m")/U18)*U18+U18))))) | R18: =IF(Q18="","",Q18-N(K18)) | S18: =IF(OR(B18="",G18="",H18="",AND(L18<>"",L18<=TODAY())),"",MAX(0,N(H18)-N(M18))) | T18: =IF(B18="","",IF(AND(L18<>"",L18<=TODAY()),"Cancelled",IF(L18<>"","Ends "&DAY(L18)&" "&CHOOSE(MONTH(L18),"Jan","Feb","Mar","Apr","May","Jun","Jul","Aug","Sep","Oct","Nov","Dec"),IF(AND(Q18<>"",W18<>"",W18<Q18),"Card expires",IF(AND(Q18<>"",E18<>"Monthly",N(K18)>0,R18>=TODAY(),R18-TODAY()<=N(Settings!$C$5)),"Cancel by "&DAY(R18)&" "&CHOOSE(MONTH(R18),"Jan","Feb","Mar","Apr","May","Jun","Jul","Aug","Sep","Oct","Nov","Dec"),IF(AND(Q18<>"",E18<>"Monthly",Q18-TODAY()<=N(Settings!$C$5)),"Renews "&DAY(Q18)&" "&CHOOSE(MONTH(Q18),"Jan","Feb","Mar","Apr","May","Jun","Jul","Aug","Sep","Oct","Nov","Dec"),IF(N(S18)>0,S18&IF(S18=1," unused seat"," unused seats"),"Active"))))))) | U18: =IF(E18="Quarterly",3,IF(E18="Yearly",12,1)) | V18: =IF(Q18="","",Q18+ROW()/10000000) | W18: =IFERROR(IF(INDEX(Cards!$D$6:$D$25,MATCH(I18,Cards!$B$6:$B$25,0))="","",INDEX(Cards!$D$6:$D$25,MATCH(I18,Cards!$B$6:$B$25,0))),"") | X18: =IF(OR(T18="",T18="Active",T18="Cancelled"),"",ROW()) | Y18: =IF(N(S18)=0,0,S18*N(F18)*12/U18)
B19: Scheduling | C19: Operations | D19: Grace | E19: Quarterly | F19: 36 | I19: Business card A | J19: 46213 | M19: =IF(B19="","",SUMIFS(Access!$G$6:$G$405,Access!$C$6:$C$405,B19)) | N19: =IF(B19="","",IF(G19<>"",N(F19)*IF(H19="",M19,N(H19)),N(F19))) | O19: =IF(B19="","",IF(AND(L19<>"",L19<=TODAY()),0,N19/U19)) | P19: =IF(B19="","",O19*12) | Q19: =IF(OR(B19="",J19=""),"",IF(AND(L19<>"",IF(J19>=TODAY(),J19,IF(EDATE(J19,INT(DATEDIF(J19,TODAY(),"m")/U19)*U19)>=TODAY(),EDATE(J19,INT(DATEDIF(J19,TODAY(),"m")/U19)*U19),EDATE(J19,INT(DATEDIF(J19,TODAY(),"m")/U19)*U19+U19)))>=L19),"",IF(J19>=TODAY(),J19,IF(EDATE(J19,INT(DATEDIF(J19,TODAY(),"m")/U19)*U19)>=TODAY(),EDATE(J19,INT(DATEDIF(J19,TODAY(),"m")/U19)*U19),EDATE(J19,INT(DATEDIF(J19,TODAY(),"m")/U19)*U19+U19))))) | R19: =IF(Q19="","",Q19-N(K19)) | S19: =IF(OR(B19="",G19="",H19="",AND(L19<>"",L19<=TODAY())),"",MAX(0,N(H19)-N(M19))) | T19: =IF(B19="","",IF(AND(L19<>"",L19<=TODAY()),"Cancelled",IF(L19<>"","Ends "&DAY(L19)&" "&CHOOSE(MONTH(L19),"Jan","Feb","Mar","Apr","May","Jun","Jul","Aug","Sep","Oct","Nov","Dec"),IF(AND(Q19<>"",W19<>"",W19<Q19),"Card expires",IF(AND(Q19<>"",E19<>"Monthly",N(K19)>0,R19>=TODAY(),R19-TODAY()<=N(Settings!$C$5)),"Cancel by "&DAY(R19)&" "&CHOOSE(MONTH(R19),"Jan","Feb","Mar","Apr","May","Jun","Jul","Aug","Sep","Oct","Nov","Dec"),IF(AND(Q19<>"",E19<>"Monthly",Q19-TODAY()<=N(Settings!$C$5)),"Renews "&DAY(Q19)&" "&CHOOSE(MONTH(Q19),"Jan","Feb","Mar","Apr","May","Jun","Jul","Aug","Sep","Oct","Nov","Dec"),IF(N(S19)>0,S19&IF(S19=1," unused seat"," unused seats"),"Active"))))))) | U19: =IF(E19="Quarterly",3,IF(E19="Yearly",12,1)) | V19: =IF(Q19="","",Q19+ROW()/10000000) | W19: =IFERROR(IF(INDEX(Cards!$D$6:$D$25,MATCH(I19,Cards!$B$6:$B$25,0))="","",INDEX(Cards!$D$6:$D$25,MATCH(I19,Cards!$B$6:$B$25,0))),"") | X19: =IF(OR(T19="",T19="Active",T19="Cancelled"),"",ROW()) | Y19: =IF(N(S19)=0,0,S19*N(F19)*12/U19)
B20: E-signature | C20: Operations | D20: Ana | E20: Monthly | F20: 25 | I20: Business card A | J20: 46280 | L20: 46280 | M20: =IF(B20="","",SUMIFS(Access!$G$6:$G$405,Access!$C$6:$C$405,B20)) | N20: =IF(B20="","",IF(G20<>"",N(F20)*IF(H20="",M20,N(H20)),N(F20))) | O20: =IF(B20="","",IF(AND(L20<>"",L20<=TODAY()),0,N20/U20)) | P20: =IF(B20="","",O20*12) | Q20: =IF(OR(B20="",J20=""),"",IF(AND(L20<>"",IF(J20>=TODAY(),J20,IF(EDATE(J20,INT(DATEDIF(J20,TODAY(),"m")/U20)*U20)>=TODAY(),EDATE(J20,INT(DATEDIF(J20,TODAY(),"m")/U20)*U20),EDATE(J20,INT(DATEDIF(J20,TODAY(),"m")/U20)*U20+U20)))>=L20),"",IF(J20>=TODAY(),J20,IF(EDATE(J20,INT(DATEDIF(J20,TODAY(),"m")/U20)*U20)>=TODAY(),EDATE(J20,INT(DATEDIF(J20,TODAY(),"m")/U20)*U20),EDATE(J20,INT(DATEDIF(J20,TODAY(),"m")/U20)*U20+U20))))) | R20: =IF(Q20="","",Q20-N(K20)) | S20: =IF(OR(B20="",G20="",H20="",AND(L20<>"",L20<=TODAY())),"",MAX(0,N(H20)-N(M20))) | T20: =IF(B20="","",IF(AND(L20<>"",L20<=TODAY()),"Cancelled",IF(L20<>"","Ends "&DAY(L20)&" "&CHOOSE(MONTH(L20),"Jan","Feb","Mar","Apr","May","Jun","Jul","Aug","Sep","Oct","Nov","Dec"),IF(AND(Q20<>"",W20<>"",W20<Q20),"Card expires",IF(AND(Q20<>"",E20<>"Monthly",N(K20)>0,R20>=TODAY(),R20-TODAY()<=N(Settings!$C$5)),"Cancel by "&DAY(R20)&" "&CHOOSE(MONTH(R20),"Jan","Feb","Mar","Apr","May","Jun","Jul","Aug","Sep","Oct","Nov","Dec"),IF(AND(Q20<>"",E20<>"Monthly",Q20-TODAY()<=N(Settings!$C$5)),"Renews "&DAY(Q20)&" "&CHOOSE(MONTH(Q20),"Jan","Feb","Mar","Apr","May","Jun","Jul","Aug","Sep","Oct","Nov","Dec"),IF(N(S20)>0,S20&IF(S20=1," unused seat"," unused seats"),"Active"))))))) | U20: =IF(E20="Quarterly",3,IF(E20="Yearly",12,1)) | V20: =IF(Q20="","",Q20+ROW()/10000000) | W20: =IFERROR(IF(INDEX(Cards!$D$6:$D$25,MATCH(I20,Cards!$B$6:$B$25,0))="","",INDEX(Cards!$D$6:$D$25,MATCH(I20,Cards!$B$6:$B$25,0))),"") | X20: =IF(OR(T20="",T20="Active",T20="Cancelled"),"",ROW()) | Y20: =IF(N(S20)=0,0,S20*N(F20)*12/U20)
B21: AI writing assistant | C21: Marketing | D21: Ella | E21: Monthly | F21: 20 | G21: x | H21: 2 | I21: Business card A | J21: 46300 | L21: 46326 | M21: =IF(B21="","",SUMIFS(Access!$G$6:$G$405,Access!$C$6:$C$405,B21)) | N21: =IF(B21="","",IF(G21<>"",N(F21)*IF(H21="",M21,N(H21)),N(F21))) | O21: =IF(B21="","",IF(AND(L21<>"",L21<=TODAY()),0,N21/U21)) | P21: =IF(B21="","",O21*12) | Q21: =IF(OR(B21="",J21=""),"",IF(AND(L21<>"",IF(J21>=TODAY(),J21,IF(EDATE(J21,INT(DATEDIF(J21,TODAY(),"m")/U21)*U21)>=TODAY(),EDATE(J21,INT(DATEDIF(J21,TODAY(),"m")/U21)*U21),EDATE(J21,INT(DATEDIF(J21,TODAY(),"m")/U21)*U21+U21)))>=L21),"",IF(J21>=TODAY(),J21,IF(EDATE(J21,INT(DATEDIF(J21,TODAY(),"m")/U21)*U21)>=TODAY(),EDATE(J21,INT(DATEDIF(J21,TODAY(),"m")/U21)*U21),EDATE(J21,INT(DATEDIF(J21,TODAY(),"m")/U21)*U21+U21))))) | R21: =IF(Q21="","",Q21-N(K21)) | S21: =IF(OR(B21="",G21="",H21="",AND(L21<>"",L21<=TODAY())),"",MAX(0,N(H21)-N(M21))) | T21: =IF(B21="","",IF(AND(L21<>"",L21<=TODAY()),"Cancelled",IF(L21<>"","Ends "&DAY(L21)&" "&CHOOSE(MONTH(L21),"Jan","Feb","Mar","Apr","May","Jun","Jul","Aug","Sep","Oct","Nov","Dec"),IF(AND(Q21<>"",W21<>"",W21<Q21),"Card expires",IF(AND(Q21<>"",E21<>"Monthly",N(K21)>0,R21>=TODAY(),R21-TODAY()<=N(Settings!$C$5)),"Cancel by "&DAY(R21)&" "&CHOOSE(MONTH(R21),"Jan","Feb","Mar","Apr","May","Jun","Jul","Aug","Sep","Oct","Nov","Dec"),IF(AND(Q21<>"",E21<>"Monthly",Q21-TODAY()<=N(Settings!$C$5)),"Renews "&DAY(Q21)&" "&CHOOSE(MONTH(Q21),"Jan","Feb","Mar","Apr","May","Jun","Jul","Aug","Sep","Oct","Nov","Dec"),IF(N(S21)>0,S21&IF(S21=1," unused seat"," unused seats"),"Active"))))))) | U21: =IF(E21="Quarterly",3,IF(E21="Yearly",12,1)) | V21: =IF(Q21="","",Q21+ROW()/10000000) | W21: =IFERROR(IF(INDEX(Cards!$D$6:$D$25,MATCH(I21,Cards!$B$6:$B$25,0))="","",INDEX(Cards!$D$6:$D$25,MATCH(I21,Cards!$B$6:$B$25,0))),"") | X21: =IF(OR(T21="",T21="Active",T21="Cancelled"),"",ROW()) | Y21: =IF(N(S21)=0,0,S21*N(F21)*12/U21)
M22: =IF(B22="","",SUMIFS(Access!$G$6:$G$405,Access!$C$6:$C$405,B22)) | N22: =IF(B22="","",IF(G22<>"",N(F22)*IF(H22="",M22,N(H22)),N(F22))) | O22: =IF(B22="","",IF(AND(L22<>"",L22<=TODAY()),0,N22/U22)) | P22: =IF(B22="","",O22*12) | Q22: =IF(OR(B22="",J22=""),"",IF(AND(L22<>"",IF(J22>=TODAY(),J22,IF(EDATE(J22,INT(DATEDIF(J22,TODAY(),"m")/U22)*U22)>=TODAY(),EDATE(J22,INT(DATEDIF(J22,TODAY(),"m")/U22)*U22),EDATE(J22,INT(DATEDIF(J22,TODAY(),"m")/U22)*U22+U22)))>=L22),"",IF(J22>=TODAY(),J22,IF(EDATE(J22,INT(DATEDIF(J22,TODAY(),"m")/U22)*U22)>=TODAY(),EDATE(J22,INT(DATEDIF(J22,TODAY(),"m")/U22)*U22),EDATE(J22,INT(DATEDIF(J22,TODAY(),"m")/U22)*U22+U22))))) | R22: =IF(Q22="","",Q22-N(K22)) | S22: =IF(OR(B22="",G22="",H22="",AND(L22<>"",L22<=TODAY())),"",MAX(0,N(H22)-N(M22))) | T22: =IF(B22="","",IF(AND(L22<>"",L22<=TODAY()),"Cancelled",IF(L22<>"","Ends "&DAY(L22)&" "&CHOOSE(MONTH(L22),"Jan","Feb","Mar","Apr","May","Jun","Jul","Aug","Sep","Oct","Nov","Dec"),IF(AND(Q22<>"",W22<>"",W22<Q22),"Card expires",IF(AND(Q22<>"",E22<>"Monthly",N(K22)>0,R22>=TODAY(),R22-TODAY()<=N(Settings!$C$5)),"Cancel by "&DAY(R22)&" "&CHOOSE(MONTH(R22),"Jan","Feb","Mar","Apr","May","Jun","Jul","Aug","Sep","Oct","Nov","Dec"),IF(AND(Q22<>"",E22<>"Monthly",Q22-TODAY()<=N(Settings!$C$5)),"Renews "&DAY(Q22)&" "&CHOOSE(MONTH(Q22),"Jan","Feb","Mar","Apr","May","Jun","Jul","Aug","Sep","Oct","Nov","Dec"),IF(N(S22)>0,S22&IF(S22=1," unused seat"," unused seats"),"Active"))))))) | U22: =IF(E22="Quarterly",3,IF(E22="Yearly",12,1)) | V22: =IF(Q22="","",Q22+ROW()/10000000) | W22: =IFERROR(IF(INDEX(Cards!$D$6:$D$25,MATCH(I22,Cards!$B$6:$B$25,0))="","",INDEX(Cards!$D$6:$D$25,MATCH(I22,Cards!$B$6:$B$25,0))),"") | X22: =IF(OR(T22="",T22="Active",T22="Cancelled"),"",ROW()) | Y22: =IF(N(S22)=0,0,S22*N(F22)*12/U22)
M23: =IF(B23="","",SUMIFS(Access!$G$6:$G$405,Access!$C$6:$C$405,B23)) | N23: =IF(B23="","",IF(G23<>"",N(F23)*IF(H23="",M23,N(H23)),N(F23))) | O23: =IF(B23="","",IF(AND(L23<>"",L23<=TODAY()),0,N23/U23)) | P23: =IF(B23="","",O23*12) | Q23: =IF(OR(B23="",J23=""),"",IF(AND(L23<>"",IF(J23>=TODAY(),J23,IF(EDATE(J23,INT(DATEDIF(J23,TODAY(),"m")/U23)*U23)>=TODAY(),EDATE(J23,INT(DATEDIF(J23,TODAY(),"m")/U23)*U23),EDATE(J23,INT(DATEDIF(J23,TODAY(),"m")/U23)*U23+U23)))>=L23),"",IF(J23>=TODAY(),J23,IF(EDATE(J23,INT(DATEDIF(J23,TODAY(),"m")/U23)*U23)>=TODAY(),EDATE(J23,INT(DATEDIF(J23,TODAY(),"m")/U23)*U23),EDATE(J23,INT(DATEDIF(J23,TODAY(),"m")/U23)*U23+U23))))) | R23: =IF(Q23="","",Q23-N(K23)) | S23: =IF(OR(B23="",G23="",H23="",AND(L23<>"",L23<=TODAY())),"",MAX(0,N(H23)-N(M23))) | T23: =IF(B23="","",IF(AND(L23<>"",L23<=TODAY()),"Cancelled",IF(L23<>"","Ends "&DAY(L23)&" "&CHOOSE(MONTH(L23),"Jan","Feb","Mar","Apr","May","Jun","Jul","Aug","Sep","Oct","Nov","Dec"),IF(AND(Q23<>"",W23<>"",W23<Q23),"Card expires",IF(AND(Q23<>"",E23<>"Monthly",N(K23)>0,R23>=TODAY(),R23-TODAY()<=N(Settings!$C$5)),"Cancel by "&DAY(R23)&" "&CHOOSE(MONTH(R23),"Jan","Feb","Mar","Apr","May","Jun","Jul","Aug","Sep","Oct","Nov","Dec"),IF(AND(Q23<>"",E23<>"Monthly",Q23-TODAY()<=N(Settings!$C$5)),"Renews "&DAY(Q23)&" "&CHOOSE(MONTH(Q23),"Jan","Feb","Mar","Apr","May","Jun","Jul","Aug","Sep","Oct","Nov","Dec"),IF(N(S23)>0,S23&IF(S23=1," unused seat"," unused seats"),"Active"))))))) | U23: =IF(E23="Quarterly",3,IF(E23="Yearly",12,1)) | V23: =IF(Q23="","",Q23+ROW()/10000000) | W23: =IFERROR(IF(INDEX(Cards!$D$6:$D$25,MATCH(I23,Cards!$B$6:$B$25,0))="","",INDEX(Cards!$D$6:$D$25,MATCH(I23,Cards!$B$6:$B$25,0))),"") | X23: =IF(OR(T23="",T23="Active",T23="Cancelled"),"",ROW()) | Y23: =IF(N(S23)=0,0,S23*N(F23)*12/U23)
M24: =IF(B24="","",SUMIFS(Access!$G$6:$G$405,Access!$C$6:$C$405,B24)) | N24: =IF(B24="","",IF(G24<>"",N(F24)*IF(H24="",M24,N(H24)),N(F24))) | O24: =IF(B24="","",IF(AND(L24<>"",L24<=TODAY()),0,N24/U24)) | P24: =IF(B24="","",O24*12) | Q24: =IF(OR(B24="",J24=""),"",IF(AND(L24<>"",IF(J24>=TODAY(),J24,IF(EDATE(J24,INT(DATEDIF(J24,TODAY(),"m")/U24)*U24)>=TODAY(),EDATE(J24,INT(DATEDIF(J24,TODAY(),"m")/U24)*U24),EDATE(J24,INT(DATEDIF(J24,TODAY(),"m")/U24)*U24+U24)))>=L24),"",IF(J24>=TODAY(),J24,IF(EDATE(J24,INT(DATEDIF(J24,TODAY(),"m")/U24)*U24)>=TODAY(),EDATE(J24,INT(DATEDIF(J24,TODAY(),"m")/U24)*U24),EDATE(J24,INT(DATEDIF(J24,TODAY(),"m")/U24)*U24+U24))))) | R24: =IF(Q24="","",Q24-N(K24)) | S24: =IF(OR(B24="",G24="",H24="",AND(L24<>"",L24<=TODAY())),"",MAX(0,N(H24)-N(M24))) | T24: =IF(B24="","",IF(AND(L24<>"",L24<=TODAY()),"Cancelled",IF(L24<>"","Ends "&DAY(L24)&" "&CHOOSE(MONTH(L24),"Jan","Feb","Mar","Apr","May","Jun","Jul","Aug","Sep","Oct","Nov","Dec"),IF(AND(Q24<>"",W24<>"",W24<Q24),"Card expires",IF(AND(Q24<>"",E24<>"Monthly",N(K24)>0,R24>=TODAY(),R24-TODAY()<=N(Settings!$C$5)),"Cancel by "&DAY(R24)&" "&CHOOSE(MONTH(R24),"Jan","Feb","Mar","Apr","May","Jun","Jul","Aug","Sep","Oct","Nov","Dec"),IF(AND(Q24<>"",E24<>"Monthly",Q24-TODAY()<=N(Settings!$C$5)),"Renews "&DAY(Q24)&" "&CHOOSE(MONTH(Q24),"Jan","Feb","Mar","Apr","May","Jun","Jul","Aug","Sep","Oct","Nov","Dec"),IF(N(S24)>0,S24&IF(S24=1," unused seat"," unused seats"),"Active"))))))) | U24: =IF(E24="Quarterly",3,IF(E24="Yearly",12,1)) | V24: =IF(Q24="","",Q24+ROW()/10000000) | W24: =IFERROR(IF(INDEX(Cards!$D$6:$D$25,MATCH(I24,Cards!$B$6:$B$25,0))="","",INDEX(Cards!$D$6:$D$25,MATCH(I24,Cards!$B$6:$B$25,0))),"") | X24: =IF(OR(T24="",T24="Active",T24="Cancelled"),"",ROW()) | Y24: =IF(N(S24)=0,0,S24*N(F24)*12/U24)
M25: =IF(B25="","",SUMIFS(Access!$G$6:$G$405,Access!$C$6:$C$405,B25)) | N25: =IF(B25="","",IF(G25<>"",N(F25)*IF(H25="",M25,N(H25)),N(F25))) | O25: =IF(B25="","",IF(AND(L25<>"",L25<=TODAY()),0,N25/U25)) | P25: =IF(B25="","",O25*12) | Q25: =IF(OR(B25="",J25=""),"",IF(AND(L25<>"",IF(J25>=TODAY(),J25,IF(EDATE(J25,INT(DATEDIF(J25,TODAY(),"m")/U25)*U25)>=TODAY(),EDATE(J25,INT(DATEDIF(J25,TODAY(),"m")/U25)*U25),EDATE(J25,INT(DATEDIF(J25,TODAY(),"m")/U25)*U25+U25)))>=L25),"",IF(J25>=TODAY(),J25,IF(EDATE(J25,INT(DATEDIF(J25,TODAY(),"m")/U25)*U25)>=TODAY(),EDATE(J25,INT(DATEDIF(J25,TODAY(),"m")/U25)*U25),EDATE(J25,INT(DATEDIF(J25,TODAY(),"m")/U25)*U25+U25))))) | R25: =IF(Q25="","",Q25-N(K25)) | S25: =IF(OR(B25="",G25="",H25="",AND(L25<>"",L25<=TODAY())),"",MAX(0,N(H25)-N(M25))) | T25: =IF(B25="","",IF(AND(L25<>"",L25<=TODAY()),"Cancelled",IF(L25<>"","Ends "&DAY(L25)&" "&CHOOSE(MONTH(L25),"Jan","Feb","Mar","Apr","May","Jun","Jul","Aug","Sep","Oct","Nov","Dec"),IF(AND(Q25<>"",W25<>"",W25<Q25),"Card expires",IF(AND(Q25<>"",E25<>"Monthly",N(K25)>0,R25>=TODAY(),R25-TODAY()<=N(Settings!$C$5)),"Cancel by "&DAY(R25)&" "&CHOOSE(MONTH(R25),"Jan","Feb","Mar","Apr","May","Jun","Jul","Aug","Sep","Oct","Nov","Dec"),IF(AND(Q25<>"",E25<>"Monthly",Q25-TODAY()<=N(Settings!$C$5)),"Renews "&DAY(Q25)&" "&CHOOSE(MONTH(Q25),"Jan","Feb","Mar","Apr","May","Jun","Jul","Aug","Sep","Oct","Nov","Dec"),IF(N(S25)>0,S25&IF(S25=1," unused seat"," unused seats"),"Active"))))))) | U25: =IF(E25="Quarterly",3,IF(E25="Yearly",12,1)) | V25: =IF(Q25="","",Q25+ROW()/10000000) | W25: =IFERROR(IF(INDEX(Cards!$D$6:$D$25,MATCH(I25,Cards!$B$6:$B$25,0))="","",INDEX(Cards!$D$6:$D$25,MATCH(I25,Cards!$B$6:$B$25,0))),"") | X25: =IF(OR(T25="",T25="Active",T25="Cancelled"),"",ROW()) | Y25: =IF(N(S25)=0,0,S25*N(F25)*12/U25)
M26: =IF(B26="","",SUMIFS(Access!$G$6:$G$405,Access!$C$6:$C$405,B26)) | N26: =IF(B26="","",IF(G26<>"",N(F26)*IF(H26="",M26,N(H26)),N(F26))) | O26: =IF(B26="","",IF(AND(L26<>"",L26<=TODAY()),0,N26/U26)) | P26: =IF(B26="","",O26*12) | Q26: =IF(OR(B26="",J26=""),"",IF(AND(L26<>"",IF(J26>=TODAY(),J26,IF(EDATE(J26,INT(DATEDIF(J26,TODAY(),"m")/U26)*U26)>=TODAY(),EDATE(J26,INT(DATEDIF(J26,TODAY(),"m")/U26)*U26),EDATE(J26,INT(DATEDIF(J26,TODAY(),"m")/U26)*U26+U26)))>=L26),"",IF(J26>=TODAY(),J26,IF(EDATE(J26,INT(DATEDIF(J26,TODAY(),"m")/U26)*U26)>=TODAY(),EDATE(J26,INT(DATEDIF(J26,TODAY(),"m")/U26)*U26),EDATE(J26,INT(DATEDIF(J26,TODAY(),"m")/U26)*U26+U26))))) | R26: =IF(Q26="","",Q26-N(K26)) | S26: =IF(OR(B26="",G26="",H26="",AND(L26<>"",L26<=TODAY())),"",MAX(0,N(H26)-N(M26))) | T26: =IF(B26="","",IF(AND(L26<>"",L26<=TODAY()),"Cancelled",IF(L26<>"","Ends "&DAY(L26)&" "&CHOOSE(MONTH(L26),"Jan","Feb","Mar","Apr","May","Jun","Jul","Aug","Sep","Oct","Nov","Dec"),IF(AND(Q26<>"",W26<>"",W26<Q26),"Card expires",IF(AND(Q26<>"",E26<>"Monthly",N(K26)>0,R26>=TODAY(),R26-TODAY()<=N(Settings!$C$5)),"Cancel by "&DAY(R26)&" "&CHOOSE(MONTH(R26),"Jan","Feb","Mar","Apr","May","Jun","Jul","Aug","Sep","Oct","Nov","Dec"),IF(AND(Q26<>"",E26<>"Monthly",Q26-TODAY()<=N(Settings!$C$5)),"Renews "&DAY(Q26)&" "&CHOOSE(MONTH(Q26),"Jan","Feb","Mar","Apr","May","Jun","Jul","Aug","Sep","Oct","Nov","Dec"),IF(N(S26)>0,S26&IF(S26=1," unused seat"," unused seats"),"Active"))))))) | U26: =IF(E26="Quarterly",3,IF(E26="Yearly",12,1)) | V26: =IF(Q26="","",Q26+ROW()/10000000) | W26: =IFERROR(IF(INDEX(Cards!$D$6:$D$25,MATCH(I26,Cards!$B$6:$B$25,0))="","",INDEX(Cards!$D$6:$D$25,MATCH(I26,Cards!$B$6:$B$25,0))),"") | X26: =IF(OR(T26="",T26="Active",T26="Cancelled"),"",ROW()) | Y26: =IF(N(S26)=0,0,S26*N(F26)*12/U26)
M27: =IF(B27="","",SUMIFS(Access!$G$6:$G$405,Access!$C$6:$C$405,B27)) | N27: =IF(B27="","",IF(G27<>"",N(F27)*IF(H27="",M27,N(H27)),N(F27))) | O27: =IF(B27="","",IF(AND(L27<>"",L27<=TODAY()),0,N27/U27)) | P27: =IF(B27="","",O27*12) | Q27: =IF(OR(B27="",J27=""),"",IF(AND(L27<>"",IF(J27>=TODAY(),J27,IF(EDATE(J27,INT(DATEDIF(J27,TODAY(),"m")/U27)*U27)>=TODAY(),EDATE(J27,INT(DATEDIF(J27,TODAY(),"m")/U27)*U27),EDATE(J27,INT(DATEDIF(J27,TODAY(),"m")/U27)*U27+U27)))>=L27),"",IF(J27>=TODAY(),J27,IF(EDATE(J27,INT(DATEDIF(J27,TODAY(),"m")/U27)*U27)>=TODAY(),EDATE(J27,INT(DATEDIF(J27,TODAY(),"m")/U27)*U27),EDATE(J27,INT(DATEDIF(J27,TODAY(),"m")/U27)*U27+U27))))) | R27: =IF(Q27="","",Q27-N(K27)) | S27: =IF(OR(B27="",G27="",H27="",AND(L27<>"",L27<=TODAY())),"",MAX(0,N(H27)-N(M27))) | T27: =IF(B27="","",IF(AND(L27<>"",L27<=TODAY()),"Cancelled",IF(L27<>"","Ends "&DAY(L27)&" "&CHOOSE(MONTH(L27),"Jan","Feb","Mar","Apr","May","Jun","Jul","Aug","Sep","Oct","Nov","Dec"),IF(AND(Q27<>"",W27<>"",W27<Q27),"Card expires",IF(AND(Q27<>"",E27<>"Monthly",N(K27)>0,R27>=TODAY(),R27-TODAY()<=N(Settings!$C$5)),"Cancel by "&DAY(R27)&" "&CHOOSE(MONTH(R27),"Jan","Feb","Mar","Apr","May","Jun","Jul","Aug","Sep","Oct","Nov","Dec"),IF(AND(Q27<>"",E27<>"Monthly",Q27-TODAY()<=N(Settings!$C$5)),"Renews "&DAY(Q27)&" "&CHOOSE(MONTH(Q27),"Jan","Feb","Mar","Apr","May","Jun","Jul","Aug","Sep","Oct","Nov","Dec"),IF(N(S27)>0,S27&IF(S27=1," unused seat"," unused seats"),"Active"))))))) | U27: =IF(E27="Quarterly",3,IF(E27="Yearly",12,1)) | V27: =IF(Q27="","",Q27+ROW()/10000000) | W27: =IFERROR(IF(INDEX(Cards!$D$6:$D$25,MATCH(I27,Cards!$B$6:$B$25,0))="","",INDEX(Cards!$D$6:$D$25,MATCH(I27,Cards!$B$6:$B$25,0))),"") | X27: =IF(OR(T27="",T27="Active",T27="Cancelled"),"",ROW()) | Y27: =IF(N(S27)=0,0,S27*N(F27)*12/U27)
M28: =IF(B28="","",SUMIFS(Access!$G$6:$G$405,Access!$C$6:$C$405,B28)) | N28: =IF(B28="","",IF(G28<>"",N(F28)*IF(H28="",M28,N(H28)),N(F28))) | O28: =IF(B28="","",IF(AND(L28<>"",L28<=TODAY()),0,N28/U28)) | P28: =IF(B28="","",O28*12) | Q28: =IF(OR(B28="",J28=""),"",IF(AND(L28<>"",IF(J28>=TODAY(),J28,IF(EDATE(J28,INT(DATEDIF(J28,TODAY(),"m")/U28)*U28)>=TODAY(),EDATE(J28,INT(DATEDIF(J28,TODAY(),"m")/U28)*U28),EDATE(J28,INT(DATEDIF(J28,TODAY(),"m")/U28)*U28+U28)))>=L28),"",IF(J28>=TODAY(),J28,IF(EDATE(J28,INT(DATEDIF(J28,TODAY(),"m")/U28)*U28)>=TODAY(),EDATE(J28,INT(DATEDIF(J28,TODAY(),"m")/U28)*U28),EDATE(J28,INT(DATEDIF(J28,TODAY(),"m")/U28)*U28+U28))))) | R28: =IF(Q28="","",Q28-N(K28)) | S28: =IF(OR(B28="",G28="",H28="",AND(L28<>"",L28<=TODAY())),"",MAX(0,N(H28)-N(M28))) | T28: =IF(B28="","",IF(AND(L28<>"",L28<=TODAY()),"Cancelled",IF(L28<>"","Ends "&DAY(L28)&" "&CHOOSE(MONTH(L28),"Jan","Feb","Mar","Apr","May","Jun","Jul","Aug","Sep","Oct","Nov","Dec"),IF(AND(Q28<>"",W28<>"",W28<Q28),"Card expires",IF(AND(Q28<>"",E28<>"Monthly",N(K28)>0,R28>=TODAY(),R28-TODAY()<=N(Settings!$C$5)),"Cancel by "&DAY(R28)&" "&CHOOSE(MONTH(R28),"Jan","Feb","Mar","Apr","May","Jun","Jul","Aug","Sep","Oct","Nov","Dec"),IF(AND(Q28<>"",E28<>"Monthly",Q28-TODAY()<=N(Settings!$C$5)),"Renews "&DAY(Q28)&" "&CHOOSE(MONTH(Q28),"Jan","Feb","Mar","Apr","May","Jun","Jul","Aug","Sep","Oct","Nov","Dec"),IF(N(S28)>0,S28&IF(S28=1," unused seat"," unused seats"),"Active"))))))) | U28: =IF(E28="Quarterly",3,IF(E28="Yearly",12,1)) | V28: =IF(Q28="","",Q28+ROW()/10000000) | W28: =IFERROR(IF(INDEX(Cards!$D$6:$D$25,MATCH(I28,Cards!$B$6:$B$25,0))="","",INDEX(Cards!$D$6:$D$25,MATCH(I28,Cards!$B$6:$B$25,0))),"") | X28: =IF(OR(T28="",T28="Active",T28="Cancelled"),"",ROW()) | Y28: =IF(N(S28)=0,0,S28*N(F28)*12/U28)
M29: =IF(B29="","",SUMIFS(Access!$G$6:$G$405,Access!$C$6:$C$405,B29)) | N29: =IF(B29="","",IF(G29<>"",N(F29)*IF(H29="",M29,N(H29)),N(F29))) | O29: =IF(B29="","",IF(AND(L29<>"",L29<=TODAY()),0,N29/U29)) | P29: =IF(B29="","",O29*12) | Q29: =IF(OR(B29="",J29=""),"",IF(AND(L29<>"",IF(J29>=TODAY(),J29,IF(EDATE(J29,INT(DATEDIF(J29,TODAY(),"m")/U29)*U29)>=TODAY(),EDATE(J29,INT(DATEDIF(J29,TODAY(),"m")/U29)*U29),EDATE(J29,INT(DATEDIF(J29,TODAY(),"m")/U29)*U29+U29)))>=L29),"",IF(J29>=TODAY(),J29,IF(EDATE(J29,INT(DATEDIF(J29,TODAY(),"m")/U29)*U29)>=TODAY(),EDATE(J29,INT(DATEDIF(J29,TODAY(),"m")/U29)*U29),EDATE(J29,INT(DATEDIF(J29,TODAY(),"m")/U29)*U29+U29))))) | R29: =IF(Q29="","",Q29-N(K29)) | S29: =IF(OR(B29="",G29="",H29="",AND(L29<>"",L29<=TODAY())),"",MAX(0,N(H29)-N(M29))) | T29: =IF(B29="","",IF(AND(L29<>"",L29<=TODAY()),"Cancelled",IF(L29<>"","Ends "&DAY(L29)&" "&CHOOSE(MONTH(L29),"Jan","Feb","Mar","Apr","May","Jun","Jul","Aug","Sep","Oct","Nov","Dec"),IF(AND(Q29<>"",W29<>"",W29<Q29),"Card expires",IF(AND(Q29<>"",E29<>"Monthly",N(K29)>0,R29>=TODAY(),R29-TODAY()<=N(Settings!$C$5)),"Cancel by "&DAY(R29)&" "&CHOOSE(MONTH(R29),"Jan","Feb","Mar","Apr","May","Jun","Jul","Aug","Sep","Oct","Nov","Dec"),IF(AND(Q29<>"",E29<>"Monthly",Q29-TODAY()<=N(Settings!$C$5)),"Renews "&DAY(Q29)&" "&CHOOSE(MONTH(Q29),"Jan","Feb","Mar","Apr","May","Jun","Jul","Aug","Sep","Oct","Nov","Dec"),IF(N(S29)>0,S29&IF(S29=1," unused seat"," unused seats"),"Active"))))))) | U29: =IF(E29="Quarterly",3,IF(E29="Yearly",12,1)) | V29: =IF(Q29="","",Q29+ROW()/10000000) | W29: =IFERROR(IF(INDEX(Cards!$D$6:$D$25,MATCH(I29,Cards!$B$6:$B$25,0))="","",INDEX(Cards!$D$6:$D$25,MATCH(I29,Cards!$B$6:$B$25,0))),"") | X29: =IF(OR(T29="",T29="Active",T29="Cancelled"),"",ROW()) | Y29: =IF(N(S29)=0,0,S29*N(F29)*12/U29)
M30: =IF(B30="","",SUMIFS(Access!$G$6:$G$405,Access!$C$6:$C$405,B30)) | N30: =IF(B30="","",IF(G30<>"",N(F30)*IF(H30="",M30,N(H30)),N(F30))) | O30: =IF(B30="","",IF(AND(L30<>"",L30<=TODAY()),0,N30/U30)) | P30: =IF(B30="","",O30*12) | Q30: =IF(OR(B30="",J30=""),"",IF(AND(L30<>"",IF(J30>=TODAY(),J30,IF(EDATE(J30,INT(DATEDIF(J30,TODAY(),"m")/U30)*U30)>=TODAY(),EDATE(J30,INT(DATEDIF(J30,TODAY(),"m")/U30)*U30),EDATE(J30,INT(DATEDIF(J30,TODAY(),"m")/U30)*U30+U30)))>=L30),"",IF(J30>=TODAY(),J30,IF(EDATE(J30,INT(DATEDIF(J30,TODAY(),"m")/U30)*U30)>=TODAY(),EDATE(J30,INT(DATEDIF(J30,TODAY(),"m")/U30)*U30),EDATE(J30,INT(DATEDIF(J30,TODAY(),"m")/U30)*U30+U30))))) | R30: =IF(Q30="","",Q30-N(K30)) | S30: =IF(OR(B30="",G30="",H30="",AND(L30<>"",L30<=TODAY())),"",MAX(0,N(H30)-N(M30))) | T30: =IF(B30="","",IF(AND(L30<>"",L30<=TODAY()),"Cancelled",IF(L30<>"","Ends "&DAY(L30)&" "&CHOOSE(MONTH(L30),"Jan","Feb","Mar","Apr","May","Jun","Jul","Aug","Sep","Oct","Nov","Dec"),IF(AND(Q30<>"",W30<>"",W30<Q30),"Card expires",IF(AND(Q30<>"",E30<>"Monthly",N(K30)>0,R30>=TODAY(),R30-TODAY()<=N(Settings!$C$5)),"Cancel by "&DAY(R30)&" "&CHOOSE(MONTH(R30),"Jan","Feb","Mar","Apr","May","Jun","Jul","Aug","Sep","Oct","Nov","Dec"),IF(AND(Q30<>"",E30<>"Monthly",Q30-TODAY()<=N(Settings!$C$5)),"Renews "&DAY(Q30)&" "&CHOOSE(MONTH(Q30),"Jan","Feb","Mar","Apr","May","Jun","Jul","Aug","Sep","Oct","Nov","Dec"),IF(N(S30)>0,S30&IF(S30=1," unused seat"," unused seats"),"Active"))))))) | U30: =IF(E30="Quarterly",3,IF(E30="Yearly",12,1)) | V30: =IF(Q30="","",Q30+ROW()/10000000) | W30: =IFERROR(IF(INDEX(Cards!$D$6:$D$25,MATCH(I30,Cards!$B$6:$B$25,0))="","",INDEX(Cards!$D$6:$D$25,MATCH(I30,Cards!$B$6:$B$25,0))),"") | X30: =IF(OR(T30="",T30="Active",T30="Cancelled"),"",ROW()) | Y30: =IF(N(S30)=0,0,S30*N(F30)*12/U30)
